Workbook

Sheet ★참조은 피벗( 냉동)3438600
A1: 10/19 | B1: 열 레이블
A2: 10/20 납품 | B2: 당과점)냉동옥수수타르트
A3: BGF로지스부산 | B3: 6000
A4: 총합계 | B4: 6000

Sheet 당과점)냉동옥수수타르트
A2: =TODAY() -> 46314 | B2: BGF 냉동 참조은 □
A3: ='★참조은 피벗( 냉동)3438600'!A2 -> 10/20 납품 | B3: 입수 | C3: 당과점)냉동옥수수타르트 | D3: 박스 | E3: 센터명 | F3: 낱개
A4: BGF로지스강릉 | B4: 60 | C4: =IFERROR(VLOOKUP(A4,'★참조은 피벗( 냉동)3438600'!A:SE,2,FALSE),0) -> 0 | D4: =IFERROR(ROUNDDOWN(C4/B4,0),"") -> 0 | E4: 강릉 | F4: =IFERROR(C4-(D4*B4),"") -> 0
A5: BGF로지스서귀포 | B5: =$B$4 -> 60 | C5: =IFERROR(VLOOKUP(A5,'★참조은 피벗( 냉동)3438600'!A:SE,2,FALSE),0) -> 0 | D5: =IFERROR(ROUNDDOWN(C5/B5,0),"") -> 0 | E5: 서귀포 | F5: =IFERROR(C5-(D5*B5),"") -> 0
A6: BGF로지스제주 | B6: =$B$4 -> 60 | C6: =IFERROR(VLOOKUP(A6,'★참조은 피벗( 냉동)3438600'!A:SE,2,FALSE),0) -> 0 | D6: =IFERROR(ROUNDDOWN(C6/B6,0),"") -> 0 | E6: 제주 | F6: =IFERROR(C6-(D6*B6),"") -> 0
A7: BGF로지스안성 | B7: =$B$4 -> 60 | C7: =IFERROR(VLOOKUP(A7,'★참조은 피벗( 냉동)3438600'!A:SE,2,FALSE),0) -> 0 | D7: =IFERROR(ROUNDDOWN(C7/B7,0),"") -> 0 | E7: 안성 | F7: =IFERROR(C7-(D7*B7),"") -> 0
A8: 화인로지텍 | B8: =$B$4 -> 60 | C8: =IFERROR(VLOOKUP(A8,'★참조은 피벗( 냉동)3438600'!A:SE,2,FALSE),0) -> 0 | D8: =IFERROR(ROUNDDOWN(C8/B8,0),"") -> 0 | E8: 화인 | F8: =IFERROR(C8-(D8*B8),"") -> 0
A9: BGF로지스진천 | B9: =$B$4 -> 60 | C9: =IFERROR(VLOOKUP(A9,'★참조은 피벗( 냉동)3438600'!A:SE,2,FALSE),0) -> 0 | D9: =IFERROR(ROUNDDOWN(C9/B9,0),"") -> 0 | E9: 진천 | F9: =IFERROR(C9-(D9*B9),"") -> 0
A10: BGF로지스서인천1 | B10: =$B$4 -> 60 | C10: =IFERROR(VLOOKUP(A10,'★참조은 피벗( 냉동)3438600'!A:SE,2,FALSE),0) -> 0 | D10: =IFERROR(ROUNDDOWN(C10/B10,0),"") -> 0 | E10: 서인천1 | F10: =IFERROR(C10-(D10*B10),"") -> 0
A11: BGF로지스서인천2 | B11: =$B$4 -> 60 | C11: =IFERROR(VLOOKUP(A11,'★참조은 피벗( 냉동)3438600'!A:SE,2,FALSE),0) -> 0 | D11: =IFERROR(ROUNDDOWN(C11/B11,0),"") -> 0 | E11: 서인천2 | F11: =IFERROR(C11-(D11*B11),"") -> 0
A12: 아신 | B12: =$B$4 -> 60 | C12: =IFERROR(VLOOKUP(A12,'★참조은 피벗( 냉동)3438600'!A:SE,2,FALSE),0) -> 0 | D12: =IFERROR(ROUNDDOWN(C12/B12,0),"") -> 0 | E12: 아신 | F12: =IFERROR(C12-(D12*B12),"") -> 0
A13: 씨제이오산 | B13: =$B$4 -> 60 | C13: =IFERROR(VLOOKUP(A13,'★참조은 피벗( 냉동)3438600'!A:SE,2,FALSE),0) -> 0 | D13: =IFERROR(ROUNDDOWN(C13/B13,0),"") -> 0 | E13: 오산 | F13: =IFERROR(C13-(D13*B13),"") -> 0
A14: 씨제이군포 | B14: =$B$4 -> 60 | C14: =IFERROR(VLOOKUP(A14,'★참조은 피벗( 냉동)3438600'!A:SE,2,FALSE),0) -> 0 | D14: =IFERROR(ROUNDDOWN(C14/B14,0),"") -> 0 | E14: 군포 | F14: =IFERROR(C14-(D14*B14),"") -> 0
A15: BGF로지스광주 | B15: =$B$4 -> 60 | C15: =IFERROR(VLOOKUP(A15,'★참조은 피벗( 냉동)3438600'!A:SE,2,FALSE),0) -> 0 | D15: =IFERROR(ROUNDDOWN(C15/B15,0),"") -> 0 | E15: 광주 | F15: =IFERROR(C15-(D15*B15),"") -> 0
A16: BGF로지스검단 | B16: =$B$4 -> 60 | C16: =IFERROR(VLOOKUP(A16,'★참조은 피벗( 냉동)3438600'!A:SE,2,FALSE),0) -> 0 | D16: =IFERROR(ROUNDDOWN(C16/B16,0),"") -> 0 | E16: 검단 | F16: =IFERROR(C16-(D16*B16),"") -> 0
... A20: 동부로지스 | B20: =$B$4 -> 60 | C20: =IFERROR(VLOOKUP(A20,'★참조은 피벗( 냉동)3438600'!A:SE,2,FALSE),0) -> 0 | D20: =IFERROR(ROUNDDOWN(C20/B20,0),"") -> 0 | E20: 동부 | F20: =IFERROR(C20-(D20*B20),"") -> 0
A22: 수도권 합계 | B22: =$B$4 -> 60 | C22: =SUM(C4:C20) -> 0 | D22: =IFERROR(ROUNDDOWN(C22/B22,0),"") -> 0 | F22: =IFERROR(C22-(D22*B22),"") -> 0
A24: 엑소후레쉬양산 | B24: =$B$4 -> 60 | C24: =IFERROR(VLOOKUP(A24,'★참조은 피벗( 냉동)3438600'!A:SE,2,FALSE),0) -> 0 | D24: =IFERROR(ROUNDDOWN(C24/B24,0),"") -> 0 | E24: 양산 | F24: =IFERROR(C24-(D24*B24),"") -> 0
A25: 극동로지스 | B25: =$B$4 -> 60 | C25: =IFERROR(VLOOKUP(A25,'★참조은 피벗( 냉동)3438600'!A:SE,2,FALSE),0) -> 0 | D25: =IFERROR(ROUNDDOWN(C25/B25,0),"") -> 0 | E25: 극동김해 | F25: =IFERROR(C25-(D25*B25),"") -> 0
A26: 김해물류 | B26: =$B$4 -> 60 | C26: =IFERROR(VLOOKUP(A26,'★참조은 피벗( 냉동)3438600'!A:SE,2,FALSE),0) -> 0 | D26: =IFERROR(ROUNDDOWN(C26/B26,0),"") -> 0 | E26: 김해 | F26: =IFERROR(C26-(D26*B26),"") -> 0
A27: BGF로지스부산 | B27: =$B$4 -> 60 | C27: =IFERROR(VLOOKUP(A27,'★참조은 피벗( 냉동)3438600'!A:SE,2,FALSE),0) -> 6000 | D27: =IFERROR(ROUNDDOWN(C27/B27,0),"") -> 100 | E27: 부산 | F27: =IFERROR(C27-(D27*B27),"") -> 0
A28: BGF로지스진주 | B28: =$B$4 -> 60 | C28: =IFERROR(VLOOKUP(A28,'★참조은 피벗( 냉동)3438600'!A:SE,2,FALSE),0) -> 0 | D28: =IFERROR(ROUNDDOWN(C28/B28,0),"") -> 0 | E28: 진주 | F28: =IFERROR(C28-(D28*B28),"") -> 0
A30: 경남(김해)합계 | B30: =$B$4 -> 60 | C30: =SUM(C24:C28) -> 6000 | D30: =IFERROR(ROUNDDOWN(C30/B30,0),"") -> 100 | F30: =IFERROR(C30-(D30*B30),"") -> 0
A32: 씨제이경산 | B32: =$B$4 -> 60 | C32: =IFERROR(VLOOKUP(A32,'★참조은 피벗( 냉동)3438600'!A:SE,2,FALSE),0) -> 0 | D32: =IFERROR(ROUNDDOWN(C32/B32,0),"") -> 0 | E32: 경산 | F32: =IFERROR(C32-(D32*B32),"") -> 0
A33: BGF로지스대구 | B33: =$B$4 -> 60 | C33: =IFERROR(VLOOKUP(A33,'★참조은 피벗( 냉동)3438600'!A:SE,2,FALSE),0) -> 0 | D33: =IFERROR(ROUNDDOWN(C33/B33,0),"") -> 0 | E33: 대구 | F33: =IFERROR(C33-(D33*B33),"") -> 0
A35: 경북(칠곡)합계 | B35: =$B$4 -> 60 | C35: =SUM(C32:C33) -> 0 | D35: =IFERROR(ROUNDDOWN(C35/B35,0),"") -> 0 | F35: =IFERROR(C35-(D35*B35),"") -> 0
A37: BGF로지스나주 | B37: =$B$4 -> 60 | C37: =IFERROR(VLOOKUP(A37,'★참조은 피벗( 냉동)3438600'!A:SE,2,FALSE),0) -> 0 | D37: =IFERROR(ROUNDDOWN(C37/B37,0),"") -> 0 | E37: 나주 | F37: =IFERROR(C37-(D37*B37),"") -> 0
A38: 하이로지스 | B38: =$B$4 -> 60 | C38: =IFERROR(VLOOKUP(A38,'★참조은 피벗( 냉동)3438600'!A:SE,2,FALSE),0) -> 0 | D38: =IFERROR(ROUNDDOWN(C38/B38,0),"") -> 0 | E38: 완주 | F38: =IFERROR(C38-(D38*B38),"") -> 0
A39: 씨제이김제 | B39: =$B$4 -> 60 | C39: =IFERROR(VLOOKUP(A39,'★참조은 피벗( 냉동)3438600'!A:SE,2,FALSE),0) -> 0 | D39: =IFERROR(ROUNDDOWN(C39/B39,0),"") -> 0 | E39: 김제 | F39: =IFERROR(C39-(D39*B39),"") -> 0
A41: 호남권 합계 | B41: =$B$4 -> 60 | C41: =SUM(C37:C39) -> 0 | D41: =IFERROR(ROUNDDOWN(C41/B41,0),"") -> 0 | F41: =IFERROR(C41-(D41*B41),"") -> 0
A43: 총합계 | B43: =$B$4 -> 60 | C43: =SUM(C4:C20,C37:C39,C32:C33,C24:C28) -> 6000 | D43: =IFERROR(ROUNDDOWN(C43/B43,0),"") -> 100 | F43: =IFERROR(C43-(D43*B43),"") -> 0
A44: 총 박스/총 낱개수량 | B44: □ | D44: =SUM(D4:D20,D37:D39,D32:D33,D24:D28) -> 100 | F44: =SUM(F4:F20,F37:F39,F32:F33,F24:F28) -> 0
C45: =C22+C30+C35+C41 -> 6000
C46: =C45=C43 -> TRUE

Sheet 참조은)끼리치즈타르트
A2: =TODAY() -> 46314 | B2: BGF 냉동 참조은 □
A3: ='★참조은 피벗( 냉동)3438600'!A2 -> 10/20 납품 | B3: 입수 | C3: 참조은)끼리치즈타르트 | D3: 박스 | E3: 센터명 | F3: 낱개
A4: BGF로지스강릉 | B4: 60 | C4: =IFERROR(VLOOKUP(A4,'★참조은 피벗( 냉동)3438600'!A:SE,3,FALSE),0) -> 0 | D4: =IFERROR(ROUNDDOWN(C4/B4,0),"") -> 0 | E4: 강릉 | F4: =IFERROR(C4-(D4*B4),"") -> 0
A5: BGF로지스서귀포 | B5: =$B$4 -> 60 | C5: =IFERROR(VLOOKUP(A5,'★참조은 피벗( 냉동)3438600'!A:SE,3,FALSE),0) -> 0 | D5: =IFERROR(ROUNDDOWN(C5/B5,0),"") -> 0 | E5: 서귀포 | F5: =IFERROR(C5-(D5*B5),"") -> 0
A6: BGF로지스제주 | B6: =$B$4 -> 60 | C6: =IFERROR(VLOOKUP(A6,'★참조은 피벗( 냉동)3438600'!A:SE,3,FALSE),0) -> 0 | D6: =IFERROR(ROUNDDOWN(C6/B6,0),"") -> 0 | E6: 제주 | F6: =IFERROR(C6-(D6*B6),"") -> 0
A7: BGF로지스안성 | B7: =$B$4 -> 60 | C7: =IFERROR(VLOOKUP(A7,'★참조은 피벗( 냉동)3438600'!A:SE,3,FALSE),0) -> 0 | D7: =IFERROR(ROUNDDOWN(C7/B7,0),"") -> 0 | E7: 안성 | F7: =IFERROR(C7-(D7*B7),"") -> 0
A8: 화인로지텍 | B8: =$B$4 -> 60 | C8: =IFERROR(VLOOKUP(A8,'★참조은 피벗( 냉동)3438600'!A:SE,3,FALSE),0) -> 0 | D8: =IFERROR(ROUNDDOWN(C8/B8,0),"") -> 0 | E8: 화인 | F8: =IFERROR(C8-(D8*B8),"") -> 0
A9: BGF로지스진천 | B9: =$B$4 -> 60 | C9: =IFERROR(VLOOKUP(A9,'★참조은 피벗( 냉동)3438600'!A:SE,3,FALSE),0) -> 0 | D9: =IFERROR(ROUNDDOWN(C9/B9,0),"") -> 0 | E9: 진천 | F9: =IFERROR(C9-(D9*B9),"") -> 0
A10: BGF로지스서인천1 | B10: =$B$4 -> 60 | C10: =IFERROR(VLOOKUP(A10,'★참조은 피벗( 냉동)3438600'!A:SE,3,FALSE),0) -> 0 | D10: =IFERROR(ROUNDDOWN(C10/B10,0),"") -> 0 | E10: 서인천1 | F10: =IFERROR(C10-(D10*B10),"") -> 0
A11: BGF로지스서인천2 | B11: =$B$4 -> 60 | C11: =IFERROR(VLOOKUP(A11,'★참조은 피벗( 냉동)3438600'!A:SE,3,FALSE),0) -> 0 | D11: =IFERROR(ROUNDDOWN(C11/B11,0),"") -> 0 | E11: 서인천2 | F11: =IFERROR(C11-(D11*B11),"") -> 0
A12: 아신 | B12: =$B$4 -> 60 | C12: =IFERROR(VLOOKUP(A12,'★참조은 피벗( 냉동)3438600'!A:SE,3,FALSE),0) -> 0 | D12: =IFERROR(ROUNDDOWN(C12/B12,0),"") -> 0 | E12: 아신 | F12: =IFERROR(C12-(D12*B12),"") -> 0
A13: 씨제이오산 | B13: =$B$4 -> 60 | C13: =IFERROR(VLOOKUP(A13,'★참조은 피벗( 냉동)3438600'!A:SE,3,FALSE),0) -> 0 | D13: =IFERROR(ROUNDDOWN(C13/B13,0),"") -> 0 | E13: 오산 | F13: =IFERROR(C13-(D13*B13),"") -> 0
A14: 씨제이군포 | B14: =$B$4 -> 60 | C14: =IFERROR(VLOOKUP(A14,'★참조은 피벗( 냉동)3438600'!A:SE,3,FALSE),0) -> 0 | D14: =IFERROR(ROUNDDOWN(C14/B14,0),"") -> 0 | E14: 군포 | F14: =IFERROR(C14-(D14*B14),"") -> 0
A15: BGF로지스광주 | B15: =$B$4 -> 60 | C15: =IFERROR(VLOOKUP(A15,'★참조은 피벗( 냉동)3438600'!A:SE,3,FALSE),0) -> 0 | D15: =IFERROR(ROUNDDOWN(C15/B15,0),"") -> 0 | E15: 광주 | F15: =IFERROR(C15-(D15*B15),"") -> 0
A16: BGF로지스검단 | B16: =$B$4 -> 60 | C16: =IFERROR(VLOOKUP(A16,'★참조은 피벗( 냉동)3438600'!A:SE,3,FALSE),0) -> 0 | D16: =IFERROR(ROUNDDOWN(C16/B16,0),"") -> 0 | E16: 검단 | F16: =IFERROR(C16-(D16*B16),"") -> 0
... A20: 동부로지스 | B20: =$B$4 -> 60 | C20: =IFERROR(VLOOKUP(A20,'★참조은 피벗( 냉동)3438600'!A:SE,3,FALSE),0) -> 0 | D20: =IFERROR(ROUNDDOWN(C20/B20,0),"") -> 0 | E20: 동부 | F20: =IFERROR(C20-(D20*B20),"") -> 0
A22: 수도권 합계 | B22: =$B$4 -> 60 | C22: =SUM(C4:C20) -> 0 | D22: =IFERROR(ROUNDDOWN(C22/B22,0),"") -> 0 | F22: =IFERROR(C22-(D22*B22),"") -> 0
A24: 엑소후레쉬양산 | B24: =$B$4 -> 60 | C24: =IFERROR(VLOOKUP(A24,'★참조은 피벗( 냉동)3438600'!A:SE,3,FALSE),0) -> 0 | D24: =IFERROR(ROUNDDOWN(C24/B24,0),"") -> 0 | E24: 양산 | F24: =IFERROR(C24-(D24*B24),"") -> 0
A25: 극동로지스 | B25: =$B$4 -> 60 | C25: =IFERROR(VLOOKUP(A25,'★참조은 피벗( 냉동)3438600'!A:SE,3,FALSE),0) -> 0 | D25: =IFERROR(ROUNDDOWN(C25/B25,0),"") -> 0 | E25: 극동김해 | F25: =IFERROR(C25-(D25*B25),"") -> 0
A26: 김해물류 | B26: =$B$4 -> 60 | C26: =IFERROR(VLOOKUP(A26,'★참조은 피벗( 냉동)3438600'!A:SE,3,FALSE),0) -> 0 | D26: =IFERROR(ROUNDDOWN(C26/B26,0),"") -> 0 | E26: 김해 | F26: =IFERROR(C26-(D26*B26),"") -> 0
A27: BGF로지스부산 | B27: =$B$4 -> 60 | C27: =IFERROR(VLOOKUP(A27,'★참조은 피벗( 냉동)3438600'!A:SE,3,FALSE),0) -> 0 | D27: =IFERROR(ROUNDDOWN(C27/B27,0),"") -> 0 | E27: 부산 | F27: =IFERROR(C27-(D27*B27),"") -> 0
A28: BGF로지스진주 | B28: =$B$4 -> 60 | C28: =IFERROR(VLOOKUP(A28,'★참조은 피벗( 냉동)3438600'!A:SE,3,FALSE),0) -> 0 | D28: =IFERROR(ROUNDDOWN(C28/B28,0),"") -> 0 | E28: 진주 | F28: =IFERROR(C28-(D28*B28),"") -> 0
A30: 경남(김해)합계 | B30: =$B$4 -> 60 | C30: =SUM(C24:C28) -> 0 | D30: =IFERROR(ROUNDDOWN(C30/B30,0),"") -> 0 | F30: =IFERROR(C30-(D30*B30),"") -> 0
A32: 씨제이경산 | B32: =$B$4 -> 60 | C32: =IFERROR(VLOOKUP(A32,'★참조은 피벗( 냉동)3438600'!A:SE,3,FALSE),0) -> 0 | D32: =IFERROR(ROUNDDOWN(C32/B32,0),"") -> 0 | E32: 경산 | F32: =IFERROR(C32-(D32*B32),"") -> 0
A33: BGF로지스대구 | B33: =$B$4 -> 60 | C33: =IFERROR(VLOOKUP(A33,'★참조은 피벗( 냉동)3438600'!A:SE,3,FALSE),0) -> 0 | D33: =IFERROR(ROUNDDOWN(C33/B33,0),"") -> 0 | E33: 대구 | F33: =IFERROR(C33-(D33*B33),"") -> 0
A35: 경북(칠곡)합계 | B35: =$B$4 -> 60 | C35: =SUM(C32:C33) -> 0 | D35: =IFERROR(ROUNDDOWN(C35/B35,0),"") -> 0 | F35: =IFERROR(C35-(D35*B35),"") -> 0
A37: BGF로지스나주 | B37: =$B$4 -> 60 | C37: =IFERROR(VLOOKUP(A37,'★참조은 피벗( 냉동)3438600'!A:SE,3,FALSE),0) -> 0 | D37: =IFERROR(ROUNDDOWN(C37/B37,0),"") -> 0 | E37: 나주 | F37: =IFERROR(C37-(D37*B37),"") -> 0
A38: 하이로지스 | B38: =$B$4 -> 60 | C38: =IFERROR(VLOOKUP(A38,'★참조은 피벗( 냉동)3438600'!A:SE,3,FALSE),0) -> 0 | D38: =IFERROR(ROUNDDOWN(C38/B38,0),"") -> 0 | E38: 완주 | F38: =IFERROR(C38-(D38*B38),"") -> 0
A39: 씨제이김제 | B39: =$B$4 -> 60 | C39: =IFERROR(VLOOKUP(A39,'★참조은 피벗( 냉동)3438600'!A:SE,3,FALSE),0) -> 0 | D39: =IFERROR(ROUNDDOWN(C39/B39,0),"") -> 0 | E39: 김제 | F39: =IFERROR(C39-(D39*B39),"") -> 0
A41: 호남권 합계 | B41: =$B$4 -> 60 | C41: =SUM(C37:C39) -> 0 | D41: =IFERROR(ROUNDDOWN(C41/B41,0),"") -> 0 | F41: =IFERROR(C41-(D41*B41),"") -> 0
A43: 총합계 | B43: =$B$4 -> 60 | C43: =SUM(C4:C20,C37:C39,C32:C33,C24:C28) -> 0 | D43: =IFERROR(ROUNDDOWN(C43/B43,0),"") -> 0 | F43: =IFERROR(C43-(D43*B43),"") -> 0
A44: 총 박스/총 낱개수량 | B44: □ | D44: =SUM(D4:D20,D37:D39,D32:D33,D24:D28) -> 0 | F44: =SUM(F4:F20,F37:F39,F32:F33,F24:F28) -> 0
C45: =C22+C30+C35+C41 -> 0
C46: =C45=C43 -> TRUE

Sheet ★참조은 피벗( 냉동) (3546200)
A1: 10/19 | D1: 열 레이블
A2: 10/20 납품 | D2: 특)뉴욕베이글플레인
A3: BGF로지스진주 | D3: 48
A4: 총합계 | D4: 48

Sheet 특)뉴욕베이글블루베리
A2: =TODAY() -> 46314 | B2: BGF 냉동 참조은 □
A3: ='★참조은 피벗( 냉동) (3546200)'!A2 -> 10/20 납품 | B3: 입수 | C3: 특)뉴욕베이글블루베리 | D3: 박스 | E3: 센터명 | F3: 낱개
A4: BGF로지스강릉 | B4: 48 | C4: =IFERROR(VLOOKUP(A4,'★참조은 피벗( 냉동) (3546200)'!A:TH,2,FALSE),0) -> 0 | D4: =IFERROR(ROUNDDOWN(C4/B4,0),"") -> 0 | E4: 강릉 | F4: =IFERROR(C4-(D4*B4),"") -> 0
A5: BGF로지스서귀포 | B5: =$B$4 -> 48 | C5: =IFERROR(VLOOKUP(A5,'★참조은 피벗( 냉동) (3546200)'!A:TH,2,FALSE),0) -> 0 | D5: =IFERROR(ROUNDDOWN(C5/B5,0),"") -> 0 | E5: 서귀포 | F5: =IFERROR(C5-(D5*B5),"") -> 0
A6: BGF로지스제주 | B6: =$B$4 -> 48 | C6: =IFERROR(VLOOKUP(A6,'★참조은 피벗( 냉동) (3546200)'!A:TH,2,FALSE),0) -> 0 | D6: =IFERROR(ROUNDDOWN(C6/B6,0),"") -> 0 | E6: 제주 | F6: =IFERROR(C6-(D6*B6),"") -> 0
A7: BGF로지스안성 | B7: =$B$4 -> 48 | C7: =IFERROR(VLOOKUP(A7,'★참조은 피벗( 냉동) (3546200)'!A:TH,2,FALSE),0) -> 0 | D7: =IFERROR(ROUNDDOWN(C7/B7,0),"") -> 0 | E7: 안성 | F7: =IFERROR(C7-(D7*B7),"") -> 0
A8: 화인로지텍 | B8: =$B$4 -> 48 | C8: =IFERROR(VLOOKUP(A8,'★참조은 피벗( 냉동) (3546200)'!A:TH,2,FALSE),0) -> 0 | D8: =IFERROR(ROUNDDOWN(C8/B8,0),"") -> 0 | E8: 화인 | F8: =IFERROR(C8-(D8*B8),"") -> 0
A9: BGF로지스진천 | B9: =$B$4 -> 48 | C9: =IFERROR(VLOOKUP(A9,'★참조은 피벗( 냉동) (3546200)'!A:TH,2,FALSE),0) -> 0 | D9: =IFERROR(ROUNDDOWN(C9/B9,0),"") -> 0 | E9: 진천 | F9: =IFERROR(C9-(D9*B9),"") -> 0
A10: BGF로지스서인천1 | B10: =$B$4 -> 48 | C10: =IFERROR(VLOOKUP(A10,'★참조은 피벗( 냉동) (3546200)'!A:TH,2,FALSE),0) -> 0 | D10: =IFERROR(ROUNDDOWN(C10/B10,0),"") -> 0 | E10: 서인천1 | F10: =IFERROR(C10-(D10*B10),"") -> 0
A11: BGF로지스서인천2 | B11: =$B$4 -> 48 | C11: =IFERROR(VLOOKUP(A11,'★참조은 피벗( 냉동) (3546200)'!A:TH,2,FALSE),0) -> 0 | D11: =IFERROR(ROUNDDOWN(C11/B11,0),"") -> 0 | E11: 서인천2 | F11: =IFERROR(C11-(D11*B11),"") -> 0
A12: 아신 | B12: =$B$4 -> 48 | C12: =IFERROR(VLOOKUP(A12,'★참조은 피벗( 냉동) (3546200)'!A:TH,2,FALSE),0) -> 0 | D12: =IFERROR(ROUNDDOWN(C12/B12,0),"") -> 0 | E12: 아신 | F12: =IFERROR(C12-(D12*B12),"") -> 0
A13: 씨제이오산 | B13: =$B$4 -> 48 | C13: =IFERROR(VLOOKUP(A13,'★참조은 피벗( 냉동) (3546200)'!A:TH,2,FALSE),0) -> 0 | D13: =IFERROR(ROUNDDOWN(C13/B13,0),"") -> 0 | E13: 오산 | F13: =IFERROR(C13-(D13*B13),"") -> 0
A14: 씨제이군포 | B14: =$B$4 -> 48 | C14: =IFERROR(VLOOKUP(A14,'★참조은 피벗( 냉동) (3546200)'!A:TH,2,FALSE),0) -> 0 | D14: =IFERROR(ROUNDDOWN(C14/B14,0),"") -> 0 | E14: 군포 | F14: =IFERROR(C14-(D14*B14),"") -> 0
A15: BGF로지스광주 | B15: =$B$4 -> 48 | C15: =IFERROR(VLOOKUP(A15,'★참조은 피벗( 냉동) (3546200)'!A:TH,2,FALSE),0) -> 0 | D15: =IFERROR(ROUNDDOWN(C15/B15,0),"") -> 0 | E15: 광주 | F15: =IFERROR(C15-(D15*B15),"") -> 0
A16: BGF로지스검단 | B16: =$B$4 -> 48 | C16: =IFERROR(VLOOKUP(A16,'★참조은 피벗( 냉동) (3546200)'!A:TH,2,FALSE),0) -> 0 | D16: =IFERROR(ROUNDDOWN(C16/B16,0),"") -> 0 | E16: 검단 | F16: =IFERROR(C16-(D16*B16),"") -> 0
... A20: 동부로지스 | B20: =$B$4 -> 48 | C20: =IFERROR(VLOOKUP(A20,'★참조은 피벗( 냉동) (3546200)'!A:TH,2,FALSE),0) -> 0 | D20: =IFERROR(ROUNDDOWN(C20/B20,0),"") -> 0 | E20: 동부 | F20: =IFERROR(C20-(D20*B20),"") -> 0
A22: 수도권 합계 | B22: =$B$4 -> 48 | C22: =SUM(C4:C20) -> 0 | D22: =IFERROR(ROUNDDOWN(C22/B22,0),"") -> 0 | F22: =IFERROR(C22-(D22*B22),"") -> 0
A24: 엑소후레쉬양산 | B24: =$B$4 -> 48 | C24: =IFERROR(VLOOKUP(A24,'★참조은 피벗( 냉동) (3546200)'!A:TH,2,FALSE),0) -> 0 | D24: =IFERROR(ROUNDDOWN(C24/B24,0),"") -> 0 | E24: 양산 | F24: =IFERROR(C24-(D24*B24),"") -> 0
A25: 극동로지스 | B25: =$B$4 -> 48 | C25: =IFERROR(VLOOKUP(A25,'★참조은 피벗( 냉동) (3546200)'!A:TH,2,FALSE),0) -> 0 | D25: =IFERROR(ROUNDDOWN(C25/B25,0),"") -> 0 | E25: 극동김해 | F25: =IFERROR(C25-(D25*B25),"") -> 0
A26: 김해물류 | B26: =$B$4 -> 48 | C26: =IFERROR(VLOOKUP(A26,'★참조은 피벗( 냉동) (3546200)'!A:TH,2,FALSE),0) -> 0 | D26: =IFERROR(ROUNDDOWN(C26/B26,0),"") -> 0 | E26: 김해 | F26: =IFERROR(C26-(D26*B26),"") -> 0
A27: BGF로지스부산 | B27: =$B$4 -> 48 | C27: =IFERROR(VLOOKUP(A27,'★참조은 피벗( 냉동) (3546200)'!A:TH,2,FALSE),0) -> 0 | D27: =IFERROR(ROUNDDOWN(C27/B27,0),"") -> 0 | E27: 부산 | F27: =IFERROR(C27-(D27*B27),"") -> 0
A28: BGF로지스진주 | B28: =$B$4 -> 48 | C28: =IFERROR(VLOOKUP(A28,'★참조은 피벗( 냉동) (3546200)'!A:TH,2,FALSE),0) -> 0 | D28: =IFERROR(ROUNDDOWN(C28/B28,0),"") -> 0 | E28: 진주 | F28: =IFERROR(C28-(D28*B28),"") -> 0
A30: 경남(김해)합계 | B30: =$B$4 -> 48 | C30: =SUM(C24:C28) -> 0 | D30: =IFERROR(ROUNDDOWN(C30/B30,0),"") -> 0 | F30: =IFERROR(C30-(D30*B30),"") -> 0
A32: 씨제이경산 | B32: =$B$4 -> 48 | C32: =IFERROR(VLOOKUP(A32,'★참조은 피벗( 냉동) (3546200)'!A:TH,2,FALSE),0) -> 0 | D32: =IFERROR(ROUNDDOWN(C32/B32,0),"") -> 0 | E32: 경산 | F32: =IFERROR(C32-(D32*B32),"") -> 0
A33: BGF로지스대구 | B33: =$B$4 -> 48 | C33: =IFERROR(VLOOKUP(A33,'★참조은 피벗( 냉동) (3546200)'!A:TH,2,FALSE),0) -> 0 | D33: =IFERROR(ROUNDDOWN(C33/B33,0),"") -> 0 | E33: 대구 | F33: =IFERROR(C33-(D33*B33),"") -> 0
A35: 경북(칠곡)합계 | B35: =$B$4 -> 48 | C35: =SUM(C32:C33) -> 0 | D35: =IFERROR(ROUNDDOWN(C35/B35,0),"") -> 0 | F35: =IFERROR(C35-(D35*B35),"") -> 0
A37: BGF로지스나주 | B37: =$B$4 -> 48 | C37: =IFERROR(VLOOKUP(A37,'★참조은 피벗( 냉동) (3546200)'!A:TH,2,FALSE),0) -> 0 | D37: =IFERROR(ROUNDDOWN(C37/B37,0),"") -> 0 | E37: 나주 | F37: =IFERROR(C37-(D37*B37),"") -> 0
A38: 하이로지스 | B38: =$B$4 -> 48 | C38: =IFERROR(VLOOKUP(A38,'★참조은 피벗( 냉동) (3546200)'!A:TH,2,FALSE),0) -> 0 | D38: =IFERROR(ROUNDDOWN(C38/B38,0),"") -> 0 | E38: 완주 | F38: =IFERROR(C38-(D38*B38),"") -> 0
A39: 씨제이김제 | B39: =$B$4 -> 48 | C39: =IFERROR(VLOOKUP(A39,'★참조은 피벗( 냉동) (3546200)'!A:TH,2,FALSE),0) -> 0 | D39: =IFERROR(ROUNDDOWN(C39/B39,0),"") -> 0 | E39: 김제 | F39: =IFERROR(C39-(D39*B39),"") -> 0
A41: 호남권 합계 | B41: =$B$4 -> 48 | C41: =SUM(C37:C39) -> 0 | D41: =IFERROR(ROUNDDOWN(C41/B41,0),"") -> 0 | F41: =IFERROR(C41-(D41*B41),"") -> 0
A43: 총합계 | B43: =$B$4 -> 48 | C43: =SUM(C4:C20,C37:C39,C32:C33,C24:C28) -> 0 | D43: =IFERROR(ROUNDDOWN(C43/B43,0),"") -> 0 | F43: =IFERROR(C43-(D43*B43),"") -> 0
A44: 총 박스/총 낱개수량 | B44: □ | D44: =SUM(D4:D20,D37:D39,D32:D33,D24:D28) -> 0 | F44: =SUM(F4:F20,F37:F39,F32:F33,F24:F28) -> 0
C45: =C22+C30+C35+C41 -> 0
C46: =C45=C43 -> TRUE

Sheet 특)뉴욕베이글쿠앤크
A2: =TODAY() -> 46314 | B2: BGF 냉동 참조은 □
A3: ='★참조은 피벗( 냉동) (3546200)'!A2 -> 10/20 납품 | B3: 입수 | C3: 특)뉴욕베이글쿠앤크 | D3: 박스 | E3: 센터명 | F3: 낱개
A4: BGF로지스강릉 | B4: 48 | C4: =IFERROR(VLOOKUP(A4,'★참조은 피벗( 냉동) (3546200)'!A:TH,3,FALSE),0) -> 0 | D4: =IFERROR(ROUNDDOWN(C4/B4,0),"") -> 0 | E4: 강릉 | F4: =IFERROR(C4-(D4*B4),"") -> 0
A5: BGF로지스서귀포 | B5: =$B$4 -> 48 | C5: =IFERROR(VLOOKUP(A5,'★참조은 피벗( 냉동) (3546200)'!A:TH,3,FALSE),0) -> 0 | D5: =IFERROR(ROUNDDOWN(C5/B5,0),"") -> 0 | E5: 서귀포 | F5: =IFERROR(C5-(D5*B5),"") -> 0
A6: BGF로지스제주 | B6: =$B$4 -> 48 | C6: =IFERROR(VLOOKUP(A6,'★참조은 피벗( 냉동) (3546200)'!A:TH,3,FALSE),0) -> 0 | D6: =IFERROR(ROUNDDOWN(C6/B6,0),"") -> 0 | E6: 제주 | F6: =IFERROR(C6-(D6*B6),"") -> 0
A7: BGF로지스안성 | B7: =$B$4 -> 48 | C7: =IFERROR(VLOOKUP(A7,'★참조은 피벗( 냉동) (3546200)'!A:TH,3,FALSE),0) -> 0 | D7: =IFERROR(ROUNDDOWN(C7/B7,0),"") -> 0 | E7: 안성 | F7: =IFERROR(C7-(D7*B7),"") -> 0
A8: 화인로지텍 | B8: =$B$4 -> 48 | C8: =IFERROR(VLOOKUP(A8,'★참조은 피벗( 냉동) (3546200)'!A:TH,3,FALSE),0) -> 0 | D8: =IFERROR(ROUNDDOWN(C8/B8,0),"") -> 0 | E8: 화인 | F8: =IFERROR(C8-(D8*B8),"") -> 0
A9: BGF로지스진천 | B9: =$B$4 -> 48 | C9: =IFERROR(VLOOKUP(A9,'★참조은 피벗( 냉동) (3546200)'!A:TH,3,FALSE),0) -> 0 | D9: =IFERROR(ROUNDDOWN(C9/B9,0),"") -> 0 | E9: 진천 | F9: =IFERROR(C9-(D9*B9),"") -> 0
A10: BGF로지스서인천1 | B10: =$B$4 -> 48 | C10: =IFERROR(VLOOKUP(A10,'★참조은 피벗( 냉동) (3546200)'!A:TH,3,FALSE),0) -> 0 | D10: =IFERROR(ROUNDDOWN(C10/B10,0),"") -> 0 | E10: 서인천1 | F10: =IFERROR(C10-(D10*B10),"") -> 0
A11: BGF로지스서인천2 | B11: =$B$4 -> 48 | C11: =IFERROR(VLOOKUP(A11,'★참조은 피벗( 냉동) (3546200)'!A:TH,3,FALSE),0) -> 0 | D11: =IFERROR(ROUNDDOWN(C11/B11,0),"") -> 0 | E11: 서인천2 | F11: =IFERROR(C11-(D11*B11),"") -> 0
A12: 아신 | B12: =$B$4 -> 48 | C12: =IFERROR(VLOOKUP(A12,'★참조은 피벗( 냉동) (3546200)'!A:TH,3,FALSE),0) -> 0 | D12: =IFERROR(ROUNDDOWN(C12/B12,0),"") -> 0 | E12: 아신 | F12: =IFERROR(C12-(D12*B12),"") -> 0
A13: 씨제이오산 | B13: =$B$4 -> 48 | C13: =IFERROR(VLOOKUP(A13,'★참조은 피벗( 냉동) (3546200)'!A:TH,3,FALSE),0) -> 0 | D13: =IFERROR(ROUNDDOWN(C13/B13,0),"") -> 0 | E13: 오산 | F13: =IFERROR(C13-(D13*B13),"") -> 0
A14: 씨제이군포 | B14: =$B$4 -> 48 | C14: =IFERROR(VLOOKUP(A14,'★참조은 피벗( 냉동) (3546200)'!A:TH,3,FALSE),0) -> 0 | D14: =IFERROR(ROUNDDOWN(C14/B14,0),"") -> 0 | E14: 군포 | F14: =IFERROR(C14-(D14*B14),"") -> 0
A15: BGF로지스광주 | B15: =$B$4 -> 48 | C15: =IFERROR(VLOOKUP(A15,'★참조은 피벗( 냉동) (3546200)'!A:TH,3,FALSE),0) -> 0 | D15: =IFERROR(ROUNDDOWN(C15/B15,0),"") -> 0 | E15: 광주 | F15: =IFERROR(C15-(D15*B15),"") -> 0
A16: BGF로지스검단 | B16: =$B$4 -> 48 | C16: =IFERROR(VLOOKUP(A16,'★참조은 피벗( 냉동) (3546200)'!A:TH,3,FALSE),0) -> 0 | D16: =IFERROR(ROUNDDOWN(C16/B16,0),"") -> 0 | E16: 검단 | F16: =IFERROR(C16-(D16*B16),"") -> 0
... A20: 동부로지스 | B20: =$B$4 -> 48 | C20: =IFERROR(VLOOKUP(A20,'★참조은 피벗( 냉동) (3546200)'!A:TH,3,FALSE),0) -> 0 | D20: =IFERROR(ROUNDDOWN(C20/B20,0),"") -> 0 | E20: 동부 | F20: =IFERROR(C20-(D20*B20),"") -> 0
A22: 수도권 합계 | B22: =$B$4 -> 48 | C22: =SUM(C4:C20) -> 0 | D22: =IFERROR(ROUNDDOWN(C22/B22,0),"") -> 0 | F22: =IFERROR(C22-(D22*B22),"") -> 0
A24: 엑소후레쉬양산 | B24: =$B$4 -> 48 | C24: =IFERROR(VLOOKUP(A24,'★참조은 피벗( 냉동) (3546200)'!A:TH,3,FALSE),0) -> 0 | D24: =IFERROR(ROUNDDOWN(C24/B24,0),"") -> 0 | E24: 양산 | F24: =IFERROR(C24-(D24*B24),"") -> 0
A25: 극동로지스 | B25: =$B$4 -> 48 | C25: =IFERROR(VLOOKUP(A25,'★참조은 피벗( 냉동) (3546200)'!A:TH,3,FALSE),0) -> 0 | D25: =IFERROR(ROUNDDOWN(C25/B25,0),"") -> 0 | E25: 극동김해 | F25: =IFERROR(C25-(D25*B25),"") -> 0
A26: 김해물류 | B26: =$B$4 -> 48 | C26: =IFERROR(VLOOKUP(A26,'★참조은 피벗( 냉동) (3546200)'!A:TH,3,FALSE),0) -> 0 | D26: =IFERROR(ROUNDDOWN(C26/B26,0),"") -> 0 | E26: 김해 | F26: =IFERROR(C26-(D26*B26),"") -> 0
A27: BGF로지스부산 | B27: =$B$4 -> 48 | C27: =IFERROR(VLOOKUP(A27,'★참조은 피벗( 냉동) (3546200)'!A:TH,3,FALSE),0) -> 0 | D27: =IFERROR(ROUNDDOWN(C27/B27,0),"") -> 0 | E27: 부산 | F27: =IFERROR(C27-(D27*B27),"") -> 0
A28: BGF로지스진주 | B28: =$B$4 -> 48 | C28: =IFERROR(VLOOKUP(A28,'★참조은 피벗( 냉동) (3546200)'!A:TH,3,FALSE),0) -> 0 | D28: =IFERROR(ROUNDDOWN(C28/B28,0),"") -> 0 | E28: 진주 | F28: =IFERROR(C28-(D28*B28),"") -> 0
A30: 경남(김해)합계 | B30: =$B$4 -> 48 | C30: =SUM(C24:C28) -> 0 | D30: =IFERROR(ROUNDDOWN(C30/B30,0),"") -> 0 | F30: =IFERROR(C30-(D30*B30),"") -> 0
A32: 씨제이경산 | B32: =$B$4 -> 48 | C32: =IFERROR(VLOOKUP(A32,'★참조은 피벗( 냉동) (3546200)'!A:TH,3,FALSE),0) -> 0 | D32: =IFERROR(ROUNDDOWN(C32/B32,0),"") -> 0 | E32: 경산 | F32: =IFERROR(C32-(D32*B32),"") -> 0
A33: BGF로지스대구 | B33: =$B$4 -> 48 | C33: =IFERROR(VLOOKUP(A33,'★참조은 피벗( 냉동) (3546200)'!A:TH,3,FALSE),0) -> 0 | D33: =IFERROR(ROUNDDOWN(C33/B33,0),"") -> 0 | E33: 대구 | F33: =IFERROR(C33-(D33*B33),"") -> 0
A35: 경북(칠곡)합계 | B35: =$B$4 -> 48 | C35: =SUM(C32:C33) -> 0 | D35: =IFERROR(ROUNDDOWN(C35/B35,0),"") -> 0 | F35: =IFERROR(C35-(D35*B35),"") -> 0
A37: BGF로지스나주 | B37: =$B$4 -> 48 | C37: =IFERROR(VLOOKUP(A37,'★참조은 피벗( 냉동) (3546200)'!A:TH,3,FALSE),0) -> 0 | D37: =IFERROR(ROUNDDOWN(C37/B37,0),"") -> 0 | E37: 나주 | F37: =IFERROR(C37-(D37*B37),"") -> 0
A38: 하이로지스 | B38: =$B$4 -> 48 | C38: =IFERROR(VLOOKUP(A38,'★참조은 피벗( 냉동) (3546200)'!A:TH,3,FALSE),0) -> 0 | D38: =IFERROR(ROUNDDOWN(C38/B38,0),"") -> 0 | E38: 완주 | F38: =IFERROR(C38-(D38*B38),"") -> 0
A39: 씨제이김제 | B39: =$B$4 -> 48 | C39: =IFERROR(VLOOKUP(A39,'★참조은 피벗( 냉동) (3546200)'!A:TH,3,FALSE),0) -> 0 | D39: =IFERROR(ROUNDDOWN(C39/B39,0),"") -> 0 | E39: 김제 | F39: =IFERROR(C39-(D39*B39),"") -> 0
A41: 호남권 합계 | B41: =$B$4 -> 48 | C41: =SUM(C37:C39) -> 0 | D41: =IFERROR(ROUNDDOWN(C41/B41,0),"") -> 0 | F41: =IFERROR(C41-(D41*B41),"") -> 0
A43: 총합계 | B43: =$B$4 -> 48 | C43: =SUM(C4:C20,C37:C39,C32:C33,C24:C28) -> 0 | D43: =IFERROR(ROUNDDOWN(C43/B43,0),"") -> 0 | F43: =IFERROR(C43-(D43*B43),"") -> 0
A44: 총 박스/총 낱개수량 | B44: □ | D44: =SUM(D4:D20,D37:D39,D32:D33,D24:D28) -> 0 | F44: =SUM(F4:F20,F37:F39,F32:F33,F24:F28) -> 0
C45: =C22+C30+C35+C41 -> 0
C46: =C45=C43 -> TRUE

Sheet 특)뉴욕베이글플레인
A2: =TODAY() -> 46314 | B2: BGF 냉동 참조은 □
A3: ='★참조은 피벗( 냉동) (3546200)'!A2 -> 10/20 납품 | B3: 입수 | C3: 특)뉴욕베이글플레인 | D3: 박스 | E3: 센터명 | F3: 낱개
A4: BGF로지스강릉 | B4: 48 | C4: =IFERROR(VLOOKUP(A4,'★참조은 피벗( 냉동) (3546200)'!A:TH,4,FALSE),0) -> 0 | D4: =IFERROR(ROUNDDOWN(C4/B4,0),"") -> 0 | E4: 강릉 | F4: =IFERROR(C4-(D4*B4),"") -> 0
A5: BGF로지스서귀포 | B5: =$B$4 -> 48 | C5: =IFERROR(VLOOKUP(A5,'★참조은 피벗( 냉동) (3546200)'!A:TH,4,FALSE),0) -> 0 | D5: =IFERROR(ROUNDDOWN(C5/B5,0),"") -> 0 | E5: 서귀포 | F5: =IFERROR(C5-(D5*B5),"") -> 0
A6: BGF로지스제주 | B6: =$B$4 -> 48 | C6: =IFERROR(VLOOKUP(A6,'★참조은 피벗( 냉동) (3546200)'!A:TH,4,FALSE),0) -> 0 | D6: =IFERROR(ROUNDDOWN(C6/B6,0),"") -> 0 | E6: 제주 | F6: =IFERROR(C6-(D6*B6),"") -> 0
A7: BGF로지스안성 | B7: =$B$4 -> 48 | C7: =IFERROR(VLOOKUP(A7,'★참조은 피벗( 냉동) (3546200)'!A:TH,4,FALSE),0) -> 0 | D7: =IFERROR(ROUNDDOWN(C7/B7,0),"") -> 0 | E7: 안성 | F7: =IFERROR(C7-(D7*B7),"") -> 0
A8: 화인로지텍 | B8: =$B$4 -> 48 | C8: =IFERROR(VLOOKUP(A8,'★참조은 피벗( 냉동) (3546200)'!A:TH,4,FALSE),0) -> 0 | D8: =IFERROR(ROUNDDOWN(C8/B8,0),"") -> 0 | E8: 화인 | F8: =IFERROR(C8-(D8*B8),"") -> 0
A9: BGF로지스진천 | B9: =$B$4 -> 48 | C9: =IFERROR(VLOOKUP(A9,'★참조은 피벗( 냉동) (3546200)'!A:TH,4,FALSE),0) -> 0 | D9: =IFERROR(ROUNDDOWN(C9/B9,0),"") -> 0 | E9: 진천 | F9: =IFERROR(C9-(D9*B9),"") -> 0
A10: BGF로지스서인천1 | B10: =$B$4 -> 48 | C10: =IFERROR(VLOOKUP(A10,'★참조은 피벗( 냉동) (3546200)'!A:TH,4,FALSE),0) -> 0 | D10: =IFERROR(ROUNDDOWN(C10/B10,0),"") -> 0 | E10: 서인천1 | F10: =IFERROR(C10-(D10*B10),"") -> 0
A11: BGF로지스서인천2 | B11: =$B$4 -> 48 | C11: =IFERROR(VLOOKUP(A11,'★참조은 피벗( 냉동) (3546200)'!A:TH,4,FALSE),0) -> 0 | D11: =IFERROR(ROUNDDOWN(C11/B11,0),"") -> 0 | E11: 서인천2 | F11: =IFERROR(C11-(D11*B11),"") -> 0
A12: 아신 | B12: =$B$4 -> 48 | C12: =IFERROR(VLOOKUP(A12,'★참조은 피벗( 냉동) (3546200)'!A:TH,4,FALSE),0) -> 0 | D12: =IFERROR(ROUNDDOWN(C12/B12,0),"") -> 0 | E12: 아신 | F12: =IFERROR(C12-(D12*B12),"") -> 0
A13: 씨제이오산 | B13: =$B$4 -> 48 | C13: =IFERROR(VLOOKUP(A13,'★참조은 피벗( 냉동) (3546200)'!A:TH,4,FALSE),0) -> 0 | D13: =IFERROR(ROUNDDOWN(C13/B13,0),"") -> 0 | E13: 오산 | F13: =IFERROR(C13-(D13*B13),"") -> 0
A14: 씨제이군포 | B14: =$B$4 -> 48 | C14: =IFERROR(VLOOKUP(A14,'★참조은 피벗( 냉동) (3546200)'!A:TH,4,FALSE),0) -> 0 | D14: =IFERROR(ROUNDDOWN(C14/B14,0),"") -> 0 | E14: 군포 | F14: =IFERROR(C14-(D14*B14),"") -> 0
A15: BGF로지스광주 | B15: =$B$4 -> 48 | C15: =IFERROR(VLOOKUP(A15,'★참조은 피벗( 냉동) (3546200)'!A:TH,4,FALSE),0) -> 0 | D15: =IFERROR(ROUNDDOWN(C15/B15,0),"") -> 0 | E15: 광주 | F15: =IFERROR(C15-(D15*B15),"") -> 0
A16: BGF로지스검단 | B16: =$B$4 -> 48 | C16: =IFERROR(VLOOKUP(A16,'★참조은 피벗( 냉동) (3546200)'!A:TH,4,FALSE),0) -> 0 | D16: =IFERROR(ROUNDDOWN(C16/B16,0),"") -> 0 | E16: 검단 | F16: =IFERROR(C16-(D16*B16),"") -> 0
... A20: 동부로지스 | B20: =$B$4 -> 48 | C20: =IFERROR(VLOOKUP(A20,'★참조은 피벗( 냉동) (3546200)'!A:TH,4,FALSE),0) -> 0 | D20: =IFERROR(ROUNDDOWN(C20/B20,0),"") -> 0 | E20: 동부 | F20: =IFERROR(C20-(D20*B20),"") -> 0
A22: 수도권 합계 | B22: =$B$4 -> 48 | C22: =SUM(C4:C20) -> 0 | D22: =IFERROR(ROUNDDOWN(C22/B22,0),"") -> 0 | F22: =IFERROR(C22-(D22*B22),"") -> 0
A24: 엑소후레쉬양산 | B24: =$B$4 -> 48 | C24: =IFERROR(VLOOKUP(A24,'★참조은 피벗( 냉동) (3546200)'!A:TH,4,FALSE),0) -> 0 | D24: =IFERROR(ROUNDDOWN(C24/B24,0),"") -> 0 | E24: 양산 | F24: =IFERROR(C24-(D24*B24),"") -> 0
A25: 극동로지스 | B25: =$B$4 -> 48 | C25: =IFERROR(VLOOKUP(A25,'★참조은 피벗( 냉동) (3546200)'!A:TH,4,FALSE),0) -> 0 | D25: =IFERROR(ROUNDDOWN(C25/B25,0),"") -> 0 | E25: 극동김해 | F25: =IFERROR(C25-(D25*B25),"") -> 0
A26: 김해물류 | B26: =$B$4 -> 48 | C26: =IFERROR(VLOOKUP(A26,'★참조은 피벗( 냉동) (3546200)'!A:TH,4,FALSE),0) -> 0 | D26: =IFERROR(ROUNDDOWN(C26/B26,0),"") -> 0 | E26: 김해 | F26: =IFERROR(C26-(D26*B26),"") -> 0
A27: BGF로지스부산 | B27: =$B$4 -> 48 | C27: =IFERROR(VLOOKUP(A27,'★참조은 피벗( 냉동) (3546200)'!A:TH,4,FALSE),0) -> 0 | D27: =IFERROR(ROUNDDOWN(C27/B27,0),"") -> 0 | E27: 부산 | F27: =IFERROR(C27-(D27*B27),"") -> 0
A28: BGF로지스진주 | B28: =$B$4 -> 48 | C28: =IFERROR(VLOOKUP(A28,'★참조은 피벗( 냉동) (3546200)'!A:TH,4,FALSE),0) -> 48 | D28: =IFERROR(ROUNDDOWN(C28/B28,0),"") -> 1 | E28: 진주 | F28: =IFERROR(C28-(D28*B28),"") -> 0
A30: 경남(김해)합계 | B30: =$B$4 -> 48 | C30: =SUM(C24:C28) -> 48 | D30: =IFERROR(ROUNDDOWN(C30/B30,0),"") -> 1 | F30: =IFERROR(C30-(D30*B30),"") -> 0
A32: 씨제이경산 | B32: =$B$4 -> 48 | C32: =IFERROR(VLOOKUP(A32,'★참조은 피벗( 냉동) (3546200)'!A:TH,4,FALSE),0) -> 0 | D32: =IFERROR(ROUNDDOWN(C32/B32,0),"") -> 0 | E32: 경산 | F32: =IFERROR(C32-(D32*B32),"") -> 0
A33: BGF로지스대구 | B33: =$B$4 -> 48 | C33: =IFERROR(VLOOKUP(A33,'★참조은 피벗( 냉동) (3546200)'!A:TH,4,FALSE),0) -> 0 | D33: =IFERROR(ROUNDDOWN(C33/B33,0),"") -> 0 | E33: 대구 | F33: =IFERROR(C33-(D33*B33),"") -> 0
A35: 경북(칠곡)합계 | B35: =$B$4 -> 48 | C35: =SUM(C32:C33) -> 0 | D35: =IFERROR(ROUNDDOWN(C35/B35,0),"") -> 0 | F35: =IFERROR(C35-(D35*B35),"") -> 0
A37: BGF로지스나주 | B37: =$B$4 -> 48 | C37: =IFERROR(VLOOKUP(A37,'★참조은 피벗( 냉동) (3546200)'!A:TH,4,FALSE),0) -> 0 | D37: =IFERROR(ROUNDDOWN(C37/B37,0),"") -> 0 | E37: 나주 | F37: =IFERROR(C37-(D37*B37),"") -> 0
A38: 하이로지스 | B38: =$B$4 -> 48 | C38: =IFERROR(VLOOKUP(A38,'★참조은 피벗( 냉동) (3546200)'!A:TH,4,FALSE),0) -> 0 | D38: =IFERROR(ROUNDDOWN(C38/B38,0),"") -> 0 | E38: 완주 | F38: =IFERROR(C38-(D38*B38),"") -> 0
A39: 씨제이김제 | B39: =$B$4 -> 48 | C39: =IFERROR(VLOOKUP(A39,'★참조은 피벗( 냉동) (3546200)'!A:TH,4,FALSE),0) -> 0 | D39: =IFERROR(ROUNDDOWN(C39/B39,0),"") -> 0 | E39: 김제 | F39: =IFERROR(C39-(D39*B39),"") -> 0
A41: 호남권 합계 | B41: =$B$4 -> 48 | C41: =SUM(C37:C39) -> 0 | D41: =IFERROR(ROUNDDOWN(C41/B41,0),"") -> 0 | F41: =IFERROR(C41-(D41*B41),"") -> 0
A43: 총합계 | B43: =$B$4 -> 48 | C43: =SUM(C4:C20,C37:C39,C32:C33,C24:C28) -> 48 | D43: =IFERROR(ROUNDDOWN(C43/B43,0),"") -> 1 | F43: =IFERROR(C43-(D43*B43),"") -> 0
A44: 총 박스/총 낱개수량 | B44: □ | D44: =SUM(D4:D20,D37:D39,D32:D33,D24:D28) -> 1 | F44: =SUM(F4:F20,F37:F39,F32:F33,F24:F28) -> 0
C45: =C22+C30+C35+C41 -> 48
C46: =C45=C43 -> TRUE

Sheet 특)뉴욕베이글피넛버터
A2: =TODAY() -> 46314 | B2: BGF 냉동 참조은 □
A3: ='★참조은 피벗( 냉동) (3546200)'!A2 -> 10/20 납품 | B3: 입수 | C3: 특)뉴욕베이글피넛버터 | D3: 박스 | E3: 센터명 | F3: 낱개
A4: BGF로지스강릉 | B4: 48 | C4: =IFERROR(VLOOKUP(A4,'★참조은 피벗( 냉동) (3546200)'!A:TH,5,FALSE),0) -> 0 | D4: =IFERROR(ROUNDDOWN(C4/B4,0),"") -> 0 | E4: 강릉 | F4: =IFERROR(C4-(D4*B4),"") -> 0
A5: BGF로지스서귀포 | B5: =$B$4 -> 48 | C5: =IFERROR(VLOOKUP(A5,'★참조은 피벗( 냉동) (3546200)'!A:TH,5,FALSE),0) -> 0 | D5: =IFERROR(ROUNDDOWN(C5/B5,0),"") -> 0 | E5: 서귀포 | F5: =IFERROR(C5-(D5*B5),"") -> 0
A6: BGF로지스제주 | B6: =$B$4 -> 48 | C6: =IFERROR(VLOOKUP(A6,'★참조은 피벗( 냉동) (3546200)'!A:TH,5,FALSE),0) -> 0 | D6: =IFERROR(ROUNDDOWN(C6/B6,0),"") -> 0 | E6: 제주 | F6: =IFERROR(C6-(D6*B6),"") -> 0
A7: BGF로지스안성 | B7: =$B$4 -> 48 | C7: =IFERROR(VLOOKUP(A7,'★참조은 피벗( 냉동) (3546200)'!A:TH,5,FALSE),0) -> 0 | D7: =IFERROR(ROUNDDOWN(C7/B7,0),"") -> 0 | E7: 안성 | F7: =IFERROR(C7-(D7*B7),"") -> 0
A8: 화인로지텍 | B8: =$B$4 -> 48 | C8: =IFERROR(VLOOKUP(A8,'★참조은 피벗( 냉동) (3546200)'!A:TH,5,FALSE),0) -> 0 | D8: =IFERROR(ROUNDDOWN(C8/B8,0),"") -> 0 | E8: 화인 | F8: =IFERROR(C8-(D8*B8),"") -> 0
A9: BGF로지스진천 | B9: =$B$4 -> 48 | C9: =IFERROR(VLOOKUP(A9,'★참조은 피벗( 냉동) (3546200)'!A:TH,5,FALSE),0) -> 0 | D9: =IFERROR(ROUNDDOWN(C9/B9,0),"") -> 0 | E9: 진천 | F9: =IFERROR(C9-(D9*B9),"") -> 0
A10: BGF로지스서인천1 | B10: =$B$4 -> 48 | C10: =IFERROR(VLOOKUP(A10,'★참조은 피벗( 냉동) (3546200)'!A:TH,5,FALSE),0) -> 0 | D10: =IFERROR(ROUNDDOWN(C10/B10,0),"") -> 0 | E10: 서인천1 | F10: =IFERROR(C10-(D10*B10),"") -> 0
A11: BGF로지스서인천2 | B11: =$B$4 -> 48 | C11: =IFERROR(VLOOKUP(A11,'★참조은 피벗( 냉동) (3546200)'!A:TH,5,FALSE),0) -> 0 | D11: =IFERROR(ROUNDDOWN(C11/B11,0),"") -> 0 | E11: 서인천2 | F11: =IFERROR(C11-(D11*B11),"") -> 0
A12: 아신 | B12: =$B$4 -> 48 | C12: =IFERROR(VLOOKUP(A12,'★참조은 피벗( 냉동) (3546200)'!A:TH,5,FALSE),0) -> 0 | D12: =IFERROR(ROUNDDOWN(C12/B12,0),"") -> 0 | E12: 아신 | F12: =IFERROR(C12-(D12*B12),"") -> 0
A13: 씨제이오산 | B13: =$B$4 -> 48 | C13: =IFERROR(VLOOKUP(A13,'★참조은 피벗( 냉동) (3546200)'!A:TH,5,FALSE),0) -> 0 | D13: =IFERROR(ROUNDDOWN(C13/B13,0),"") -> 0 | E13: 오산 | F13: =IFERROR(C13-(D13*B13),"") -> 0
A14: 씨제이군포 | B14: =$B$4 -> 48 | C14: =IFERROR(VLOOKUP(A14,'★참조은 피벗( 냉동) (3546200)'!A:TH,5,FALSE),0) -> 0 | D14: =IFERROR(ROUNDDOWN(C14/B14,0),"") -> 0 | E14: 군포 | F14: =IFERROR(C14-(D14*B14),"") -> 0
A15: BGF로지스광주 | B15: =$B$4 -> 48 | C15: =IFERROR(VLOOKUP(A15,'★참조은 피벗( 냉동) (3546200)'!A:TH,5,FALSE),0) -> 0 | D15: =IFERROR(ROUNDDOWN(C15/B15,0),"") -> 0 | E15: 광주 | F15: =IFERROR(C15-(D15*B15),"") -> 0
A16: BGF로지스검단 | B16: =$B$4 -> 48 | C16: =IFERROR(VLOOKUP(A16,'★참조은 피벗( 냉동) (3546200)'!A:TH,5,FALSE),0) -> 0 | D16: =IFERROR(ROUNDDOWN(C16/B16,0),"") -> 0 | E16: 검단 | F16: =IFERROR(C16-(D16*B16),"") -> 0
... A20: 동부로지스 | B20: =$B$4 -> 48 | C20: =IFERROR(VLOOKUP(A20,'★참조은 피벗( 냉동) (3546200)'!A:TH,5,FALSE),0) -> 0 | D20: =IFERROR(ROUNDDOWN(C20/B20,0),"") -> 0 | E20: 동부 | F20: =IFERROR(C20-(D20*B20),"") -> 0
A22: 수도권 합계 | B22: =$B$4 -> 48 | C22: =SUM(C4:C20) -> 0 | D22: =IFERROR(ROUNDDOWN(C22/B22,0),"") -> 0 | F22: =IFERROR(C22-(D22*B22),"") -> 0
A24: 엑소후레쉬양산 | B24: =$B$4 -> 48 | C24: =IFERROR(VLOOKUP(A24,'★참조은 피벗( 냉동) (3546200)'!A:TH,5,FALSE),0) -> 0 | D24: =IFERROR(ROUNDDOWN(C24/B24,0),"") -> 0 | E24: 양산 | F24: =IFERROR(C24-(D24*B24),"") -> 0
A25: 극동로지스 | B25: =$B$4 -> 48 | C25: =IFERROR(VLOOKUP(A25,'★참조은 피벗( 냉동) (3546200)'!A:TH,5,FALSE),0) -> 0 | D25: =IFERROR(ROUNDDOWN(C25/B25,0),"") -> 0 | E25: 극동김해 | F25: =IFERROR(C25-(D25*B25),"") -> 0
A26: 김해물류 | B26: =$B$4 -> 48 | C26: =IFERROR(VLOOKUP(A26,'★참조은 피벗( 냉동) (3546200)'!A:TH,5,FALSE),0) -> 0 | D26: =IFERROR(ROUNDDOWN(C26/B26,0),"") -> 0 | E26: 김해 | F26: =IFERROR(C26-(D26*B26),"") -> 0
A27: BGF로지스부산 | B27: =$B$4 -> 48 | C27: =IFERROR(VLOOKUP(A27,'★참조은 피벗( 냉동) (3546200)'!A:TH,5,FALSE),0) -> 0 | D27: =IFERROR(ROUNDDOWN(C27/B27,0),"") -> 0 | E27: 부산 | F27: =IFERROR(C27-(D27*B27),"") -> 0
A28: BGF로지스진주 | B28: =$B$4 -> 48 | C28: =IFERROR(VLOOKUP(A28,'★참조은 피벗( 냉동) (3546200)'!A:TH,5,FALSE),0) -> 0 | D28: =IFERROR(ROUNDDOWN(C28/B28,0),"") -> 0 | E28: 진주 | F28: =IFERROR(C28-(D28*B28),"") -> 0
A30: 경남(김해)합계 | B30: =$B$4 -> 48 | C30: =SUM(C24:C28) -> 0 | D30: =IFERROR(ROUNDDOWN(C30/B30,0),"") -> 0 | F30: =IFERROR(C30-(D30*B30),"") -> 0
A32: 씨제이경산 | B32: =$B$4 -> 48 | C32: =IFERROR(VLOOKUP(A32,'★참조은 피벗( 냉동) (3546200)'!A:TH,5,FALSE),0) -> 0 | D32: =IFERROR(ROUNDDOWN(C32/B32,0),"") -> 0 | E32: 경산 | F32: =IFERROR(C32-(D32*B32),"") -> 0
A33: BGF로지스대구 | B33: =$B$4 -> 48 | C33: =IFERROR(VLOOKUP(A33,'★참조은 피벗( 냉동) (3546200)'!A:TH,5,FALSE),0) -> 0 | D33: =IFERROR(ROUNDDOWN(C33/B33,0),"") -> 0 | E33: 대구 | F33: =IFERROR(C33-(D33*B33),"") -> 0
A35: 경북(칠곡)합계 | B35: =$B$4 -> 48 | C35: =SUM(C32:C33) -> 0 | D35: =IFERROR(ROUNDDOWN(C35/B35,0),"") -> 0 | F35: =IFERROR(C35-(D35*B35),"") -> 0
A37: BGF로지스나주 | B37: =$B$4 -> 48 | C37: =IFERROR(VLOOKUP(A37,'★참조은 피벗( 냉동) (3546200)'!A:TH,5,FALSE),0) -> 0 | D37: =IFERROR(ROUNDDOWN(C37/B37,0),"") -> 0 | E37: 나주 | F37: =IFERROR(C37-(D37*B37),"") -> 0
A38: 하이로지스 | B38: =$B$4 -> 48 | C38: =IFERROR(VLOOKUP(A38,'★참조은 피벗( 냉동) (3546200)'!A:TH,5,FALSE),0) -> 0 | D38: =IFERROR(ROUNDDOWN(C38/B38,0),"") -> 0 | E38: 완주 | F38: =IFERROR(C38-(D38*B38),"") -> 0
A39: 씨제이김제 | B39: =$B$4 -> 48 | C39: =IFERROR(VLOOKUP(A39,'★참조은 피벗( 냉동) (3546200)'!A:TH,5,FALSE),0) -> 0 | D39: =IFERROR(ROUNDDOWN(C39/B39,0),"") -> 0 | E39: 김제 | F39: =IFERROR(C39-(D39*B39),"") -> 0
A41: 호남권 합계 | B41: =$B$4 -> 48 | C41: =SUM(C37:C39) -> 0 | D41: =IFERROR(ROUNDDOWN(C41/B41,0),"") -> 0 | F41: =IFERROR(C41-(D41*B41),"") -> 0
A43: 총합계 | B43: =$B$4 -> 48 | C43: =SUM(C4:C20,C37:C39,C32:C33,C24:C28) -> 0 | D43: =IFERROR(ROUNDDOWN(C43/B43,0),"") -> 0 | F43: =IFERROR(C43-(D43*B43),"") -> 0
A44: 총 박스/총 낱개수량 | B44: □ | D44: =SUM(D4:D20,D37:D39,D32:D33,D24:D28) -> 0 | F44: =SUM(F4:F20,F37:F39,F32:F33,F24:F28) -> 0
C45: =C22+C30+C35+C41 -> 0
C46: =C45=C43 -> TRUE

Sheet 스위트조이 피벗
A1: 10/19 | C1: 열 레이블
A2: 10/20 납품 | C2: 스위트)아이스딸기바 | D2: 스위트)아이스복숭아바 | E2: 스위트)아이스파인애플바 | F2: 스위트)아이스포도바 | H2: 스위트)토이스토리아이스 | I2: 총합계
A3: BGF로지스검단 | D3: 72 | I3: 72
A4: BGF로지스광주 | C4: 108 | D4: 48 | E4: 60 | F4: 60 | I4: 276
A5: BGF로지스나주 | C5: 84 | D5: 48 | E5: 12 | H5: 24 | I5: 168
A6: BGF로지스대구 | C6: 144 | D6: 24 | E6: 36 | I6: 204
A7: BGF로지스부산 | D7: 84 | I7: 84
A8: BGF로지스서귀포 | F8: 24 | I8: 24
A9: BGF로지스서인천1 | C9: 72 | D9: 204 | E9: 12 | F9: 48 | I9: 336
A10: BGF로지스서인천2 | C10: 72 | D10: 60 | E10: 12 | F10: 60 | I10: 204
A11: BGF로지스아산 | D11: 24 | F11: 36 | I11: 60
A12: BGF로지스안성 | C12: 60 | D12: 48 | E12: 12 | I12: 120
A13: BGF로지스양주 | C13: 72 | D13: 24 | F13: 60 | I13: 156
A14: BGF로지스제주 | C14: 48 | D14: 12 | I14: 60
A15: BGF로지스진천 | C15: 24 | D15: 12 | E15: 12 | I15: 48
A16: 극동로지스 | D16: 12 | I16: 12
A17: 동부로지스 | D17: 12 | I17: 12
A18: 씨제이경산 | D18: 24 | E18: 12 | I18: 36
A19: 씨제이군포 | C19: 12 | E19: 12 | F19: 12 | I19: 36
A20: 씨제이오산 | D20: 12 | F20: 12 | I20: 24
A21: 아신 | D21: 12 | I21: 12
A22: 엑소후레쉬양산 | C22: 24 | D22: 12 | F22: 24 | I22: 60
A23: 하이로지스 | D23: 12 | I23: 12
A24: 화인로지텍 | C24: 12 | D24: 12 | E24: 12 | I24: 36
A25: 총합계 | C25: 732 | D25: 768 | E25: 192 | F25: 336 | H25: 24 | I25: 2052

Sheet 스위트)미니언즈스탬프바
A2: =TODAY() -> 46314 | B2: BGF 스위트조이 □ 냉동
A3: ='스위트조이 피벗'!A2 -> 10/20 납품 | B3: 입수 | C3: 스위트)미니언즈스탬프바 | D3: 박스 | E3: 센터명 | F3: 낱개 | G3: 파렛트 수량 | H3: 1P=135BOX
A4: BGF로지스강릉 | B4: 24 | C4: =IFERROR(VLOOKUP(A4,'스위트조이 피벗'!A:TK,2,FALSE),0) -> 0 | D4: =IFERROR(ROUNDDOWN(C4/B4,0),"") -> 0 | E4: 강릉 | F4: =IFERROR(C4-(D4*B4),"") -> 0 | G4: 1P
A5: BGF로지스서귀포 | B5: =$B$4 -> 24 | C5: =IFERROR(VLOOKUP(A5,'스위트조이 피벗'!A:TK,2,FALSE),0) -> 0 | D5: =IFERROR(ROUNDDOWN(C5/B5,0),"") -> 0 | E5: 서귀포 | F5: =IFERROR(C5-(D5*B5),"") -> 0 | G5: 1P
A6: BGF로지스제주 | B6: =$B$4 -> 24 | C6: =IFERROR(VLOOKUP(A6,'스위트조이 피벗'!A:TK,2,FALSE),0) -> 0 | D6: =IFERROR(ROUNDDOWN(C6/B6,0),"") -> 0 | E6: 제주 | F6: =IFERROR(C6-(D6*B6),"") -> 0 | G6: 1P
A7: BGF로지스안성 | B7: =$B$4 -> 24 | C7: =IFERROR(VLOOKUP(A7,'스위트조이 피벗'!A:TK,2,FALSE),0) -> 0 | D7: =IFERROR(ROUNDDOWN(C7/B7,0),"") -> 0 | E7: 안성 | F7: =IFERROR(C7-(D7*B7),"") -> 0 | G7: 1P
A8: 화인로지텍 | B8: =$B$4 -> 24 | C8: =IFERROR(VLOOKUP(A8,'스위트조이 피벗'!A:TK,2,FALSE),0) -> 0 | D8: =IFERROR(ROUNDDOWN(C8/B8,0),"") -> 0 | E8: 화인 | F8: =IFERROR(C8-(D8*B8),"") -> 0 | G8: 1P
A9: BGF로지스진천 | B9: =$B$4 -> 24 | C9: =IFERROR(VLOOKUP(A9,'스위트조이 피벗'!A:TK,2,FALSE),0) -> 0 | D9: =IFERROR(ROUNDDOWN(C9/B9,0),"") -> 0 | E9: 진천 | F9: =IFERROR(C9-(D9*B9),"") -> 0 | G9: 2P
A10: BGF로지스서인천1 | B10: =$B$4 -> 24 | C10: =IFERROR(VLOOKUP(A10,'스위트조이 피벗'!A:TK,2,FALSE),0) -> 0 | D10: =IFERROR(ROUNDDOWN(C10/B10,0),"") -> 0 | E10: 서인천1 | F10: =IFERROR(C10-(D10*B10),"") -> 0 | G10: 2P
A11: BGF로지스서인천2 | B11: =$B$4 -> 24 | C11: =IFERROR(VLOOKUP(A11,'스위트조이 피벗'!A:TK,2,FALSE),0) -> 0 | D11: =IFERROR(ROUNDDOWN(C11/B11,0),"") -> 0 | E11: 서인천2 | F11: =IFERROR(C11-(D11*B11),"") -> 0 | G11: 2P
A12: 아신 | B12: =$B$4 -> 24 | C12: =IFERROR(VLOOKUP(A12,'스위트조이 피벗'!A:TK,2,FALSE),0) -> 0 | D12: =IFERROR(ROUNDDOWN(C12/B12,0),"") -> 0 | E12: 아신 | F12: =IFERROR(C12-(D12*B12),"") -> 0 | G12: 2P
A13: 씨제이오산 | B13: =$B$4 -> 24 | C13: =IFERROR(VLOOKUP(A13,'스위트조이 피벗'!A:TK,2,FALSE),0) -> 0 | D13: =IFERROR(ROUNDDOWN(C13/B13,0),"") -> 0 | E13: 오산 | F13: =IFERROR(C13-(D13*B13),"") -> 0 | G13: 2P
A14: 씨제이군포 | B14: =$B$4 -> 24 | C14: =IFERROR(VLOOKUP(A14,'스위트조이 피벗'!A:TK,2,FALSE),0) -> 0 | D14: =IFERROR(ROUNDDOWN(C14/B14,0),"") -> 0 | E14: 군포 | F14: =IFERROR(C14-(D14*B14),"") -> 0 | G14: 2P
A15: BGF로지스광주 | B15: =$B$4 -> 24 | C15: =IFERROR(VLOOKUP(A15,'스위트조이 피벗'!A:TK,2,FALSE),0) -> 0 | D15: =IFERROR(ROUNDDOWN(C15/B15,0),"") -> 0 | E15: 광주 | F15: =IFERROR(C15-(D15*B15),"") -> 0 | G15: 2P
A16: BGF로지스검단 | B16: =$B$4 -> 24 | C16: =IFERROR(VLOOKUP(A16,'스위트조이 피벗'!A:TK,2,FALSE),0) -> 0 | D16: =IFERROR(ROUNDDOWN(C16/B16,0),"") -> 0 | E16: 검단 | F16: =IFERROR(C16-(D16*B16),"") -> 0 | G16: 3P
... A20: 동부로지스 | B20: =$B$4 -> 24 | C20: =IFERROR(VLOOKUP(A20,'스위트조이 피벗'!A:TK,2,FALSE),0) -> 0 | D20: =IFERROR(ROUNDDOWN(C20/B20,0),"") -> 0 | E20: 동부 | F20: =IFERROR(C20-(D20*B20),"") -> 0 | G20: 1P
A22: 수도권 합계 | B22: =$B$4 -> 24 | C22: =SUM(C4:C20) -> 0 | D22: =IFERROR(ROUNDDOWN(C22/B22,0),"") -> 0 | F22: =IFERROR(C22-(D22*B22),"") -> 0
A24: 엑소후레쉬양산 | B24: =$B$4 -> 24 | C24: =IFERROR(VLOOKUP(A24,'스위트조이 피벗'!A:TK,2,FALSE),0) -> 0 | D24: =IFERROR(ROUNDDOWN(C24/B24,0),"") -> 0 | E24: 양산 | F24: =IFERROR(C24-(D24*B24),"") -> 0 | G24: 2P
A25: 극동로지스 | B25: =$B$4 -> 24 | C25: =IFERROR(VLOOKUP(A25,'스위트조이 피벗'!A:TK,2,FALSE),0) -> 0 | D25: =IFERROR(ROUNDDOWN(C25/B25,0),"") -> 0 | E25: 극동김해 | F25: =IFERROR(C25-(D25*B25),"") -> 0 | G25: 1P
A26: 김해물류 | B26: =$B$4 -> 24 | C26: =IFERROR(VLOOKUP(A26,'스위트조이 피벗'!A:TK,2,FALSE),0) -> 0 | D26: =IFERROR(ROUNDDOWN(C26/B26,0),"") -> 0 | E26: 김해 | F26: =IFERROR(C26-(D26*B26),"") -> 0 | G26: 1P
A27: BGF로지스부산 | B27: =$B$4 -> 24 | C27: =IFERROR(VLOOKUP(A27,'스위트조이 피벗'!A:TK,2,FALSE),0) -> 0 | D27: =IFERROR(ROUNDDOWN(C27/B27,0),"") -> 0 | E27: 부산 | F27: =IFERROR(C27-(D27*B27),"") -> 0 | G27: 1P
A28: BGF로지스진주 | B28: =$B$4 -> 24 | C28: =IFERROR(VLOOKUP(A28,'스위트조이 피벗'!A:TK,2,FALSE),0) -> 0 | D28: =IFERROR(ROUNDDOWN(C28/B28,0),"") -> 0 | E28: 진주 | F28: =IFERROR(C28-(D28*B28),"") -> 0 | G28: 2P
A30: 경남(김해)합계 | B30: =$B$4 -> 24 | C30: =SUM(C24:C28) -> 0 | D30: =IFERROR(ROUNDDOWN(C30/B30,0),"") -> 0 | F30: =IFERROR(C30-(D30*B30),"") -> 0
A32: 씨제이경산 | B32: =$B$4 -> 24 | C32: =IFERROR(VLOOKUP(A32,'스위트조이 피벗'!A:TK,2,FALSE),0) -> 0 | D32: =IFERROR(ROUNDDOWN(C32/B32,0),"") -> 0 | E32: 경산 | F32: =IFERROR(C32-(D32*B32),"") -> 0 | G32: 2P
A33: BGF로지스대구 | B33: =$B$4 -> 24 | C33: =IFERROR(VLOOKUP(A33,'스위트조이 피벗'!A:TK,2,FALSE),0) -> 0 | D33: =IFERROR(ROUNDDOWN(C33/B33,0),"") -> 0 | E33: 대구 | F33: =IFERROR(C33-(D33*B33),"") -> 0 | G33: 2P
A35: 경북(칠곡)합계 | B35: =$B$4 -> 24 | C35: =SUM(C32:C33) -> 0 | D35: =IFERROR(ROUNDDOWN(C35/B35,0),"") -> 0 | F35: =IFERROR(C35-(D35*B35),"") -> 0
A37: BGF로지스나주 | B37: =$B$4 -> 24 | C37: =IFERROR(VLOOKUP(A37,'스위트조이 피벗'!A:TK,2,FALSE),0) -> 0 | D37: =IFERROR(ROUNDDOWN(C37/B37,0),"") -> 0 | E37: 나주 | F37: =IFERROR(C37-(D37*B37),"") -> 0 | G37: 2P
A38: 하이로지스 | B38: =$B$4 -> 24 | C38: =IFERROR(VLOOKUP(A38,'스위트조이 피벗'!A:TK,2,FALSE),0) -> 0 | D38: =IFERROR(ROUNDDOWN(C38/B38,0),"") -> 0 | E38: 완주 | F38: =IFERROR(C38-(D38*B38),"") -> 0 | G38: 1P
A39: 씨제이김제 | B39: =$B$4 -> 24 | C39: =IFERROR(VLOOKUP(A39,'스위트조이 피벗'!A:TK,2,FALSE),0) -> 0 | D39: =IFERROR(ROUNDDOWN(C39/B39,0),"") -> 0 | E39: 김제 | F39: =IFERROR(C39-(D39*B39),"") -> 0 | G39: 1P
A41: 호남권 합계 | B41: =$B$4 -> 24 | C41: =SUM(C37:C39) -> 0 | D41: =IFERROR(ROUNDDOWN(C41/B41,0),"") -> 0 | F41: =IFERROR(C41-(D41*B41),"") -> 0
A43: 총합계 | B43: =$B$4 -> 24 | C43: =SUM(C4:C20,C37:C39,C32:C33,C24:C28) -> 0 | D43: =IFERROR(ROUNDDOWN(C43/B43,0),"") -> 0 | F43: =IFERROR(C43-(D43*B43),"") -> 0
A44: 총 박스/총 낱개수량 | B44: □ | D44: =SUM(D4:D20,D37:D39,D32:D33,D24:D28) -> 0 | F44: =SUM(F4:F20,F37:F39,F32:F33,F24:F28) -> 0
C45: =C22+C30+C35+C41 -> 0
C46: =C45=C43 -> TRUE

Sheet 스위트)아이스딸기바
A2: =TODAY() -> 46314 | B2: BGF 스위트조이 □ 냉동
A3: ='스위트조이 피벗'!A2 -> 10/20 납품 | B3: 입수 | C3: 스위트)아이스딸기바 | D3: 박스 | E3: 센터명 | F3: 낱개
A4: BGF로지스강릉 | B4: 12 | C4: =IFERROR(VLOOKUP(A4,'스위트조이 피벗'!A:TK,3,FALSE),0) -> 0 | D4: =IFERROR(ROUNDDOWN(C4/B4,0),"") -> 0 | E4: 강릉 | F4: =IFERROR(C4-(D4*B4),"") -> 0
A5: BGF로지스서귀포 | B5: =$B$4 -> 12 | C5: =IFERROR(VLOOKUP(A5,'스위트조이 피벗'!A:TK,3,FALSE),0) -> 0 | D5: =IFERROR(ROUNDDOWN(C5/B5,0),"") -> 0 | E5: 서귀포 | F5: =IFERROR(C5-(D5*B5),"") -> 0
A6: BGF로지스제주 | B6: =$B$4 -> 12 | C6: =IFERROR(VLOOKUP(A6,'스위트조이 피벗'!A:TK,3,FALSE),0) -> 48 | D6: =IFERROR(ROUNDDOWN(C6/B6,0),"") -> 4 | E6: 제주 | F6: =IFERROR(C6-(D6*B6),"") -> 0
A7: BGF로지스안성 | B7: =$B$4 -> 12 | C7: =IFERROR(VLOOKUP(A7,'스위트조이 피벗'!A:TK,3,FALSE),0) -> 60 | D7: =IFERROR(ROUNDDOWN(C7/B7,0),"") -> 5 | E7: 안성 | F7: =IFERROR(C7-(D7*B7),"") -> 0
A8: 화인로지텍 | B8: =$B$4 -> 12 | C8: =IFERROR(VLOOKUP(A8,'스위트조이 피벗'!A:TK,3,FALSE),0) -> 12 | D8: =IFERROR(ROUNDDOWN(C8/B8,0),"") -> 1 | E8: 화인 | F8: =IFERROR(C8-(D8*B8),"") -> 0
A9: BGF로지스진천 | B9: =$B$4 -> 12 | C9: =IFERROR(VLOOKUP(A9,'스위트조이 피벗'!A:TK,3,FALSE),0) -> 24 | D9: =IFERROR(ROUNDDOWN(C9/B9,0),"") -> 2 | E9: 진천 | F9: =IFERROR(C9-(D9*B9),"") -> 0
A10: BGF로지스서인천1 | B10: =$B$4 -> 12 | C10: =IFERROR(VLOOKUP(A10,'스위트조이 피벗'!A:TK,3,FALSE),0) -> 72 | D10: =IFERROR(ROUNDDOWN(C10/B10,0),"") -> 6 | E10: 서인천1 | F10: =IFERROR(C10-(D10*B10),"") -> 0
A11: BGF로지스서인천2 | B11: =$B$4 -> 12 | C11: =IFERROR(VLOOKUP(A11,'스위트조이 피벗'!A:TK,3,FALSE),0) -> 72 | D11: =IFERROR(ROUNDDOWN(C11/B11,0),"") -> 6 | E11: 서인천2 | F11: =IFERROR(C11-(D11*B11),"") -> 0
A12: 아신 | B12: =$B$4 -> 12 | C12: =IFERROR(VLOOKUP(A12,'스위트조이 피벗'!A:TK,3,FALSE),0) -> 0 | D12: =IFERROR(ROUNDDOWN(C12/B12,0),"") -> 0 | E12: 아신 | F12: =IFERROR(C12-(D12*B12),"") -> 0
A13: 씨제이오산 | B13: =$B$4 -> 12 | C13: =IFERROR(VLOOKUP(A13,'스위트조이 피벗'!A:TK,3,FALSE),0) -> 0 | D13: =IFERROR(ROUNDDOWN(C13/B13,0),"") -> 0 | E13: 오산 | F13: =IFERROR(C13-(D13*B13),"") -> 0
A14: 씨제이군포 | B14: =$B$4 -> 12 | C14: =IFERROR(VLOOKUP(A14,'스위트조이 피벗'!A:TK,3,FALSE),0) -> 12 | D14: =IFERROR(ROUNDDOWN(C14/B14,0),"") -> 1 | E14: 군포 | F14: =IFERROR(C14-(D14*B14),"") -> 0
A15: BGF로지스광주 | B15: =$B$4 -> 12 | C15: =IFERROR(VLOOKUP(A15,'스위트조이 피벗'!A:TK,3,FALSE),0) -> 108 | D15: =IFERROR(ROUNDDOWN(C15/B15,0),"") -> 9 | E15: 광주 | F15: =IFERROR(C15-(D15*B15),"") -> 0
A16: BGF로지스검단 | B16: =$B$4 -> 12 | C16: =IFERROR(VLOOKUP(A16,'스위트조이 피벗'!A:TK,3,FALSE),0) -> 0 | D16: =IFERROR(ROUNDDOWN(C16/B16,0),"") -> 0 | E16: 검단 | F16: =IFERROR(C16-(D16*B16),"") -> 0
... A20: 동부로지스 | B20: =$B$4 -> 12 | C20: =IFERROR(VLOOKUP(A20,'스위트조이 피벗'!A:TK,3,FALSE),0) -> 0 | D20: =IFERROR(ROUNDDOWN(C20/B20,0),"") -> 0 | E20: 동부 | F20: =IFERROR(C20-(D20*B20),"") -> 0
A22: 수도권 합계 | B22: =$B$4 -> 12 | C22: =SUM(C4:C20) -> 480 | D22: =IFERROR(ROUNDDOWN(C22/B22,0),"") -> 40 | F22: =IFERROR(C22-(D22*B22),"") -> 0
A24: 엑소후레쉬양산 | B24: =$B$4 -> 12 | C24: =IFERROR(VLOOKUP(A24,'스위트조이 피벗'!A:TK,3,FALSE),0) -> 24 | D24: =IFERROR(ROUNDDOWN(C24/B24,0),"") -> 2 | E24: 양산 | F24: =IFERROR(C24-(D24*B24),"") -> 0
A25: 극동로지스 | B25: =$B$4 -> 12 | C25: =IFERROR(VLOOKUP(A25,'스위트조이 피벗'!A:TK,3,FALSE),0) -> 0 | D25: =IFERROR(ROUNDDOWN(C25/B25,0),"") -> 0 | E25: 극동김해 | F25: =IFERROR(C25-(D25*B25),"") -> 0
A26: 김해물류 | B26: =$B$4 -> 12 | C26: =IFERROR(VLOOKUP(A26,'스위트조이 피벗'!A:TK,3,FALSE),0) -> 0 | D26: =IFERROR(ROUNDDOWN(C26/B26,0),"") -> 0 | E26: 김해 | F26: =IFERROR(C26-(D26*B26),"") -> 0
A27: BGF로지스부산 | B27: =$B$4 -> 12 | C27: =IFERROR(VLOOKUP(A27,'스위트조이 피벗'!A:TK,3,FALSE),0) -> 0 | D27: =IFERROR(ROUNDDOWN(C27/B27,0),"") -> 0 | E27: 부산 | F27: =IFERROR(C27-(D27*B27),"") -> 0
A28: BGF로지스진주 | B28: =$B$4 -> 12 | C28: =IFERROR(VLOOKUP(A28,'스위트조이 피벗'!A:TK,3,FALSE),0) -> 0 | D28: =IFERROR(ROUNDDOWN(C28/B28,0),"") -> 0 | E28: 진주 | F28: =IFERROR(C28-(D28*B28),"") -> 0
A30: 경남(김해)합계 | B30: =$B$4 -> 12 | C30: =SUM(C24:C28) -> 24 | D30: =IFERROR(ROUNDDOWN(C30/B30,0),"") -> 2 | F30: =IFERROR(C30-(D30*B30),"") -> 0
A32: 씨제이경산 | B32: =$B$4 -> 12 | C32: =IFERROR(VLOOKUP(A32,'스위트조이 피벗'!A:TK,3,FALSE),0) -> 0 | D32: =IFERROR(ROUNDDOWN(C32/B32,0),"") -> 0 | E32: 경산 | F32: =IFERROR(C32-(D32*B32),"") -> 0
A33: BGF로지스대구 | B33: =$B$4 -> 12 | C33: =IFERROR(VLOOKUP(A33,'스위트조이 피벗'!A:TK,3,FALSE),0) -> 144 | D33: =IFERROR(ROUNDDOWN(C33/B33,0),"") -> 12 | E33: 대구 | F33: =IFERROR(C33-(D33*B33),"") -> 0
A35: 경북(칠곡)합계 | B35: =$B$4 -> 12 | C35: =SUM(C32:C33) -> 144 | D35: =IFERROR(ROUNDDOWN(C35/B35,0),"") -> 12 | F35: =IFERROR(C35-(D35*B35),"") -> 0
A37: BGF로지스나주 | B37: =$B$4 -> 12 | C37: =IFERROR(VLOOKUP(A37,'스위트조이 피벗'!A:TK,3,FALSE),0) -> 84 | D37: =IFERROR(ROUNDDOWN(C37/B37,0),"") -> 7 | E37: 나주 | F37: =IFERROR(C37-(D37*B37),"") -> 0
A38: 하이로지스 | B38: =$B$4 -> 12 | C38: =IFERROR(VLOOKUP(A38,'스위트조이 피벗'!A:TK,3,FALSE),0) -> 0 | D38: =IFERROR(ROUNDDOWN(C38/B38,0),"") -> 0 | E38: 완주 | F38: =IFERROR(C38-(D38*B38),"") -> 0
A39: 씨제이김제 | B39: =$B$4 -> 12 | C39: =IFERROR(VLOOKUP(A39,'스위트조이 피벗'!A:TK,3,FALSE),0) -> 0 | D39: =IFERROR(ROUNDDOWN(C39/B39,0),"") -> 0 | E39: 김제 | F39: =IFERROR(C39-(D39*B39),"") -> 0
A41: 호남권 합계 | B41: =$B$4 -> 12 | C41: =SUM(C37:C39) -> 84 | D41: =IFERROR(ROUNDDOWN(C41/B41,0),"") -> 7 | F41: =IFERROR(C41-(D41*B41),"") -> 0
A43: 총합계 | B43: =$B$4 -> 12 | C43: =SUM(C4:C20,C37:C39,C32:C33,C24:C28) -> 732 | D43: =IFERROR(ROUNDDOWN(C43/B43,0),"") -> 61 | F43: =IFERROR(C43-(D43*B43),"") -> 0
A44: 총 박스/총 낱개수량 | B44: □ | D44: =SUM(D4:D20,D37:D39,D32:D33,D24:D28) -> 61 | F44: =SUM(F4:F20,F37:F39,F32:F33,F24:F28) -> 0
C45: =C22+C30+C35+C41 -> 732
C46: =C45=C43 -> TRUE

Sheet 스위트)아이스복숭아바
A2: =TODAY() -> 46314 | B2: BGF 스위트조이 □ 냉동
A3: ='스위트조이 피벗'!A2 -> 10/20 납품 | B3: 입수 | C3: 스위트)아이스복숭아바 | D3: 박스 | E3: 센터명 | F3: 낱개
A4: BGF로지스강릉 | B4: 12 | C4: =IFERROR(VLOOKUP(A4,'스위트조이 피벗'!A:TK,4,FALSE),0) -> 0 | D4: =IFERROR(ROUNDDOWN(C4/B4,0),"") -> 0 | E4: 강릉 | F4: =IFERROR(C4-(D4*B4),"") -> 0
A5: BGF로지스서귀포 | B5: =$B$4 -> 12 | C5: =IFERROR(VLOOKUP(A5,'스위트조이 피벗'!A:TK,4,FALSE),0) -> 0 | D5: =IFERROR(ROUNDDOWN(C5/B5,0),"") -> 0 | E5: 서귀포 | F5: =IFERROR(C5-(D5*B5),"") -> 0
A6: BGF로지스제주 | B6: =$B$4 -> 12 | C6: =IFERROR(VLOOKUP(A6,'스위트조이 피벗'!A:TK,4,FALSE),0) -> 12 | D6: =IFERROR(ROUNDDOWN(C6/B6,0),"") -> 1 | E6: 제주 | F6: =IFERROR(C6-(D6*B6),"") -> 0
A7: BGF로지스안성 | B7: =$B$4 -> 12 | C7: =IFERROR(VLOOKUP(A7,'스위트조이 피벗'!A:TK,4,FALSE),0) -> 48 | D7: =IFERROR(ROUNDDOWN(C7/B7,0),"") -> 4 | E7: 안성 | F7: =IFERROR(C7-(D7*B7),"") -> 0
A8: 화인로지텍 | B8: =$B$4 -> 12 | C8: =IFERROR(VLOOKUP(A8,'스위트조이 피벗'!A:TK,4,FALSE),0) -> 12 | D8: =IFERROR(ROUNDDOWN(C8/B8,0),"") -> 1 | E8: 화인 | F8: =IFERROR(C8-(D8*B8),"") -> 0
A9: BGF로지스진천 | B9: =$B$4 -> 12 | C9: =IFERROR(VLOOKUP(A9,'스위트조이 피벗'!A:TK,4,FALSE),0) -> 12 | D9: =IFERROR(ROUNDDOWN(C9/B9,0),"") -> 1 | E9: 진천 | F9: =IFERROR(C9-(D9*B9),"") -> 0
A10: BGF로지스서인천1 | B10: =$B$4 -> 12 | C10: =IFERROR(VLOOKUP(A10,'스위트조이 피벗'!A:TK,4,FALSE),0) -> 204 | D10: =IFERROR(ROUNDDOWN(C10/B10,0),"") -> 17 | E10: 서인천1 | F10: =IFERROR(C10-(D10*B10),"") -> 0
A11: BGF로지스서인천2 | B11: =$B$4 -> 12 | C11: =IFERROR(VLOOKUP(A11,'스위트조이 피벗'!A:TK,4,FALSE),0) -> 60 | D11: =IFERROR(ROUNDDOWN(C11/B11,0),"") -> 5 | E11: 서인천2 | F11: =IFERROR(C11-(D11*B11),"") -> 0
A12: 아신 | B12: =$B$4 -> 12 | C12: =IFERROR(VLOOKUP(A12,'스위트조이 피벗'!A:TK,4,FALSE),0) -> 12 | D12: =IFERROR(ROUNDDOWN(C12/B12,0),"") -> 1 | E12: 아신 | F12: =IFERROR(C12-(D12*B12),"") -> 0
A13: 씨제이오산 | B13: =$B$4 -> 12 | C13: =IFERROR(VLOOKUP(A13,'스위트조이 피벗'!A:TK,4,FALSE),0) -> 12 | D13: =IFERROR(ROUNDDOWN(C13/B13,0),"") -> 1 | E13: 오산 | F13: =IFERROR(C13-(D13*B13),"") -> 0
A14: 씨제이군포 | B14: =$B$4 -> 12 | C14: =IFERROR(VLOOKUP(A14,'스위트조이 피벗'!A:TK,4,FALSE),0) -> 0 | D14: =IFERROR(ROUNDDOWN(C14/B14,0),"") -> 0 | E14: 군포 | F14: =IFERROR(C14-(D14*B14),"") -> 0
A15: BGF로지스광주 | B15: =$B$4 -> 12 | C15: =IFERROR(VLOOKUP(A15,'스위트조이 피벗'!A:TK,4,FALSE),0) -> 48 | D15: =IFERROR(ROUNDDOWN(C15/B15,0),"") -> 4 | E15: 광주 | F15: =IFERROR(C15-(D15*B15),"") -> 0
A16: BGF로지스검단 | B16: =$B$4 -> 12 | C16: =IFERROR(VLOOKUP(A16,'스위트조이 피벗'!A:TK,4,FALSE),0) -> 72 | D16: =IFERROR(ROUNDDOWN(C16/B16,0),"") -> 6 | E16: 검단 | F16: =IFERROR(C16-(D16*B16),"") -> 0
... A20: 동부로지스 | B20: =$B$4 -> 12 | C20: =IFERROR(VLOOKUP(A20,'스위트조이 피벗'!A:TK,4,FALSE),0) -> 12 | D20: =IFERROR(ROUNDDOWN(C20/B20,0),"") -> 1 | E20: 동부 | F20: =IFERROR(C20-(D20*B20),"") -> 0
A22: 수도권 합계 | B22: =$B$4 -> 12 | C22: =SUM(C4:C20) -> 552 | D22: =IFERROR(ROUNDDOWN(C22/B22,0),"") -> 46 | F22: =IFERROR(C22-(D22*B22),"") -> 0
A24: 엑소후레쉬양산 | B24: =$B$4 -> 12 | C24: =IFERROR(VLOOKUP(A24,'스위트조이 피벗'!A:TK,4,FALSE),0) -> 12 | D24: =IFERROR(ROUNDDOWN(C24/B24,0),"") -> 1 | E24: 양산 | F24: =IFERROR(C24-(D24*B24),"") -> 0
A25: 극동로지스 | B25: =$B$4 -> 12 | C25: =IFERROR(VLOOKUP(A25,'스위트조이 피벗'!A:TK,4,FALSE),0) -> 12 | D25: =IFERROR(ROUNDDOWN(C25/B25,0),"") -> 1 | E25: 극동김해 | F25: =IFERROR(C25-(D25*B25),"") -> 0
A26: 김해물류 | B26: =$B$4 -> 12 | C26: =IFERROR(VLOOKUP(A26,'스위트조이 피벗'!A:TK,4,FALSE),0) -> 0 | D26: =IFERROR(ROUNDDOWN(C26/B26,0),"") -> 0 | E26: 김해 | F26: =IFERROR(C26-(D26*B26),"") -> 0
A27: BGF로지스부산 | B27: =$B$4 -> 12 | C27: =IFERROR(VLOOKUP(A27,'스위트조이 피벗'!A:TK,4,FALSE),0) -> 84 | D27: =IFERROR(ROUNDDOWN(C27/B27,0),"") -> 7 | E27: 부산 | F27: =IFERROR(C27-(D27*B27),"") -> 0
A28: BGF로지스진주 | B28: =$B$4 -> 12 | C28: =IFERROR(VLOOKUP(A28,'스위트조이 피벗'!A:TK,4,FALSE),0) -> 0 | D28: =IFERROR(ROUNDDOWN(C28/B28,0),"") -> 0 | E28: 진주 | F28: =IFERROR(C28-(D28*B28),"") -> 0
A30: 경남(김해)합계 | B30: =$B$4 -> 12 | C30: =SUM(C24:C28) -> 108 | D30: =IFERROR(ROUNDDOWN(C30/B30,0),"") -> 9 | F30: =IFERROR(C30-(D30*B30),"") -> 0
A32: 씨제이경산 | B32: =$B$4 -> 12 | C32: =IFERROR(VLOOKUP(A32,'스위트조이 피벗'!A:TK,4,FALSE),0) -> 24 | D32: =IFERROR(ROUNDDOWN(C32/B32,0),"") -> 2 | E32: 경산 | F32: =IFERROR(C32-(D32*B32),"") -> 0
A33: BGF로지스대구 | B33: =$B$4 -> 12 | C33: =IFERROR(VLOOKUP(A33,'스위트조이 피벗'!A:TK,4,FALSE),0) -> 24 | D33: =IFERROR(ROUNDDOWN(C33/B33,0),"") -> 2 | E33: 대구 | F33: =IFERROR(C33-(D33*B33),"") -> 0
A35: 경북(칠곡)합계 | B35: =$B$4 -> 12 | C35: =SUM(C32:C33) -> 48 | D35: =IFERROR(ROUNDDOWN(C35/B35,0),"") -> 4 | F35: =IFERROR(C35-(D35*B35),"") -> 0
A37: BGF로지스나주 | B37: =$B$4 -> 12 | C37: =IFERROR(VLOOKUP(A37,'스위트조이 피벗'!A:TK,4,FALSE),0) -> 48 | D37: =IFERROR(ROUNDDOWN(C37/B37,0),"") -> 4 | E37: 나주 | F37: =IFERROR(C37-(D37*B37),"") -> 0
A38: 하이로지스 | B38: =$B$4 -> 12 | C38: =IFERROR(VLOOKUP(A38,'스위트조이 피벗'!A:TK,4,FALSE),0) -> 12 | D38: =IFERROR(ROUNDDOWN(C38/B38,0),"") -> 1 | E38: 완주 | F38: =IFERROR(C38-(D38*B38),"") -> 0
A39: 씨제이김제 | B39: =$B$4 -> 12 | C39: =IFERROR(VLOOKUP(A39,'스위트조이 피벗'!A:TK,4,FALSE),0) -> 0 | D39: =IFERROR(ROUNDDOWN(C39/B39,0),"") -> 0 | E39: 김제 | F39: =IFERROR(C39-(D39*B39),"") -> 0
A41: 호남권 합계 | B41: =$B$4 -> 12 | C41: =SUM(C37:C39) -> 60 | D41: =IFERROR(ROUNDDOWN(C41/B41,0),"") -> 5 | F41: =IFERROR(C41-(D41*B41),"") -> 0
A43: 총합계 | B43: =$B$4 -> 12 | C43: =SUM(C4:C20,C37:C39,C32:C33,C24:C28) -> 768 | D43: =IFERROR(ROUNDDOWN(C43/B43,0),"") -> 64 | F43: =IFERROR(C43-(D43*B43),"") -> 0
A44: 총 박스/총 낱개수량 | B44: □ | D44: =SUM(D4:D20,D37:D39,D32:D33,D24:D28) -> 64 | F44: =SUM(F4:F20,F37:F39,F32:F33,F24:F28) -> 0
C45: =C22+C30+C35+C41 -> 768
C46: =C45=C43 -> TRUE

Sheet 스위트)아이스파인애플바
A2: =TODAY() -> 46314 | B2: BGF 스위트조이 □ 냉동
A3: ='스위트조이 피벗'!A2 -> 10/20 납품 | B3: 입수 | C3: 스위트)아이스파인애플바 | D3: 박스 | E3: 센터명 | F3: 낱개
A4: BGF로지스강릉 | B4: 12 | C4: =IFERROR(VLOOKUP(A4,'스위트조이 피벗'!A:TK,5,FALSE),0) -> 0 | D4: =IFERROR(ROUNDDOWN(C4/B4,0),"") -> 0 | E4: 강릉 | F4: =IFERROR(C4-(D4*B4),"") -> 0
A5: BGF로지스서귀포 | B5: =$B$4 -> 12 | C5: =IFERROR(VLOOKUP(A5,'스위트조이 피벗'!A:TK,5,FALSE),0) -> 0 | D5: =IFERROR(ROUNDDOWN(C5/B5,0),"") -> 0 | E5: 서귀포 | F5: =IFERROR(C5-(D5*B5),"") -> 0
A6: BGF로지스제주 | B6: =$B$4 -> 12 | C6: =IFERROR(VLOOKUP(A6,'스위트조이 피벗'!A:TK,5,FALSE),0) -> 0 | D6: =IFERROR(ROUNDDOWN(C6/B6,0),"") -> 0 | E6: 제주 | F6: =IFERROR(C6-(D6*B6),"") -> 0
A7: BGF로지스안성 | B7: =$B$4 -> 12 | C7: =IFERROR(VLOOKUP(A7,'스위트조이 피벗'!A:TK,5,FALSE),0) -> 12 | D7: =IFERROR(ROUNDDOWN(C7/B7,0),"") -> 1 | E7: 안성 | F7: =IFERROR(C7-(D7*B7),"") -> 0
A8: 화인로지텍 | B8: =$B$4 -> 12 | C8: =IFERROR(VLOOKUP(A8,'스위트조이 피벗'!A:TK,5,FALSE),0) -> 12 | D8: =IFERROR(ROUNDDOWN(C8/B8,0),"") -> 1 | E8: 화인 | F8: =IFERROR(C8-(D8*B8),"") -> 0
A9: BGF로지스진천 | B9: =$B$4 -> 12 | C9: =IFERROR(VLOOKUP(A9,'스위트조이 피벗'!A:TK,5,FALSE),0) -> 12 | D9: =IFERROR(ROUNDDOWN(C9/B9,0),"") -> 1 | E9: 진천 | F9: =IFERROR(C9-(D9*B9),"") -> 0
A10: BGF로지스서인천1 | B10: =$B$4 -> 12 | C10: =IFERROR(VLOOKUP(A10,'스위트조이 피벗'!A:TK,5,FALSE),0) -> 12 | D10: =IFERROR(ROUNDDOWN(C10/B10,0),"") -> 1 | E10: 서인천1 | F10: =IFERROR(C10-(D10*B10),"") -> 0
A11: BGF로지스서인천2 | B11: =$B$4 -> 12 | C11: =IFERROR(VLOOKUP(A11,'스위트조이 피벗'!A:TK,5,FALSE),0) -> 12 | D11: =IFERROR(ROUNDDOWN(C11/B11,0),"") -> 1 | E11: 서인천2 | F11: =IFERROR(C11-(D11*B11),"") -> 0
A12: 아신 | B12: =$B$4 -> 12 | C12: =IFERROR(VLOOKUP(A12,'스위트조이 피벗'!A:TK,5,FALSE),0) -> 0 | D12: =IFERROR(ROUNDDOWN(C12/B12,0),"") -> 0 | E12: 아신 | F12: =IFERROR(C12-(D12*B12),"") -> 0
A13: 씨제이오산 | B13: =$B$4 -> 12 | C13: =IFERROR(VLOOKUP(A13,'스위트조이 피벗'!A:TK,5,FALSE),0) -> 0 | D13: =IFERROR(ROUNDDOWN(C13/B13,0),"") -> 0 | E13: 오산 | F13: =IFERROR(C13-(D13*B13),"") -> 0
A14: 씨제이군포 | B14: =$B$4 -> 12 | C14: =IFERROR(VLOOKUP(A14,'스위트조이 피벗'!A:TK,5,FALSE),0) -> 12 | D14: =IFERROR(ROUNDDOWN(C14/B14,0),"") -> 1 | E14: 군포 | F14: =IFERROR(C14-(D14*B14),"") -> 0
A15: BGF로지스광주 | B15: =$B$4 -> 12 | C15: =IFERROR(VLOOKUP(A15,'스위트조이 피벗'!A:TK,5,FALSE),0) -> 60 | D15: =IFERROR(ROUNDDOWN(C15/B15,0),"") -> 5 | E15: 광주 | F15: =IFERROR(C15-(D15*B15),"") -> 0
A16: BGF로지스검단 | B16: =$B$4 -> 12 | C16: =IFERROR(VLOOKUP(A16,'스위트조이 피벗'!A:TK,5,FALSE),0) -> 0 | D16: =IFERROR(ROUNDDOWN(C16/B16,0),"") -> 0 | E16: 검단 | F16: =IFERROR(C16-(D16*B16),"") -> 0
... A20: 동부로지스 | B20: =$B$4 -> 12 | C20: =IFERROR(VLOOKUP(A20,'스위트조이 피벗'!A:TK,5,FALSE),0) -> 0 | D20: =IFERROR(ROUNDDOWN(C20/B20,0),"") -> 0 | E20: 동부 | F20: =IFERROR(C20-(D20*B20),"") -> 0
A22: 수도권 합계 | B22: =$B$4 -> 12 | C22: =SUM(C4:C20) -> 132 | D22: =IFERROR(ROUNDDOWN(C22/B22,0),"") -> 11 | F22: =IFERROR(C22-(D22*B22),"") -> 0
A24: 엑소후레쉬양산 | B24: =$B$4 -> 12 | C24: =IFERROR(VLOOKUP(A24,'스위트조이 피벗'!A:TK,5,FALSE),0) -> 0 | D24: =IFERROR(ROUNDDOWN(C24/B24,0),"") -> 0 | E24: 양산 | F24: =IFERROR(C24-(D24*B24),"") -> 0
A25: 극동로지스 | B25: =$B$4 -> 12 | C25: =IFERROR(VLOOKUP(A25,'스위트조이 피벗'!A:TK,5,FALSE),0) -> 0 | D25: =IFERROR(ROUNDDOWN(C25/B25,0),"") -> 0 | E25: 극동김해 | F25: =IFERROR(C25-(D25*B25),"") -> 0
A26: 김해물류 | B26: =$B$4 -> 12 | C26: =IFERROR(VLOOKUP(A26,'스위트조이 피벗'!A:TK,5,FALSE),0) -> 0 | D26: =IFERROR(ROUNDDOWN(C26/B26,0),"") -> 0 | E26: 김해 | F26: =IFERROR(C26-(D26*B26),"") -> 0
A27: BGF로지스부산 | B27: =$B$4 -> 12 | C27: =IFERROR(VLOOKUP(A27,'스위트조이 피벗'!A:TK,5,FALSE),0) -> 0 | D27: =IFERROR(ROUNDDOWN(C27/B27,0),"") -> 0 | E27: 부산 | F27: =IFERROR(C27-(D27*B27),"") -> 0
A28: BGF로지스진주 | B28: =$B$4 -> 12 | C28: =IFERROR(VLOOKUP(A28,'스위트조이 피벗'!A:TK,5,FALSE),0) -> 0 | D28: =IFERROR(ROUNDDOWN(C28/B28,0),"") -> 0 | E28: 진주 | F28: =IFERROR(C28-(D28*B28),"") -> 0
A30: 경남(김해)합계 | B30: =$B$4 -> 12 | C30: =SUM(C24:C28) -> 0 | D30: =IFERROR(ROUNDDOWN(C30/B30,0),"") -> 0 | F30: =IFERROR(C30-(D30*B30),"") -> 0
A32: 씨제이경산 | B32: =$B$4 -> 12 | C32: =IFERROR(VLOOKUP(A32,'스위트조이 피벗'!A:TK,5,FALSE),0) -> 12 | D32: =IFERROR(ROUNDDOWN(C32/B32,0),"") -> 1 | E32: 경산 | F32: =IFERROR(C32-(D32*B32),"") -> 0
A33: BGF로지스대구 | B33: =$B$4 -> 12 | C33: =IFERROR(VLOOKUP(A33,'스위트조이 피벗'!A:TK,5,FALSE),0) -> 36 | D33: =IFERROR(ROUNDDOWN(C33/B33,0),"") -> 3 | E33: 대구 | F33: =IFERROR(C33-(D33*B33),"") -> 0
A35: 경북(칠곡)합계 | B35: =$B$4 -> 12 | C35: =SUM(C32:C33) -> 48 | D35: =IFERROR(ROUNDDOWN(C35/B35,0),"") -> 4 | F35: =IFERROR(C35-(D35*B35),"") -> 0
A37: BGF로지스나주 | B37: =$B$4 -> 12 | C37: =IFERROR(VLOOKUP(A37,'스위트조이 피벗'!A:TK,5,FALSE),0) -> 12 | D37: =IFERROR(ROUNDDOWN(C37/B37,0),"") -> 1 | E37: 나주 | F37: =IFERROR(C37-(D37*B37),"") -> 0
A38: 하이로지스 | B38: =$B$4 -> 12 | C38: =IFERROR(VLOOKUP(A38,'스위트조이 피벗'!A:TK,5,FALSE),0) -> 0 | D38: =IFERROR(ROUNDDOWN(C38/B38,0),"") -> 0 | E38: 완주 | F38: =IFERROR(C38-(D38*B38),"") -> 0
A39: 씨제이김제 | B39: =$B$4 -> 12 | C39: =IFERROR(VLOOKUP(A39,'스위트조이 피벗'!A:TK,5,FALSE),0) -> 0 | D39: =IFERROR(ROUNDDOWN(C39/B39,0),"") -> 0 | E39: 김제 | F39: =IFERROR(C39-(D39*B39),"") -> 0
A41: 호남권 합계 | B41: =$B$4 -> 12 | C41: =SUM(C37:C39) -> 12 | D41: =IFERROR(ROUNDDOWN(C41/B41,0),"") -> 1 | F41: =IFERROR(C41-(D41*B41),"") -> 0
A43: 총합계 | B43: =$B$4 -> 12 | C43: =SUM(C4:C20,C37:C39,C32:C33,C24:C28) -> 192 | D43: =IFERROR(ROUNDDOWN(C43/B43,0),"") -> 16 | F43: =IFERROR(C43-(D43*B43),"") -> 0
A44: 총 박스/총 낱개수량 | B44: □ | D44: =SUM(D4:D20,D37:D39,D32:D33,D24:D28) -> 16 | F44: =SUM(F4:F20,F37:F39,F32:F33,F24:F28) -> 0
C45: =C22+C30+C35+C41 -> 192
C46: =C45=C43 -> TRUE

Sheet 스위트)아이스포도바
A2: =TODAY() -> 46314 | B2: BGF 스위트조이 □ 냉동
A3: ='스위트조이 피벗'!A2 -> 10/20 납품 | B3: 입수 | C3: 스위트)아이스포도바 | D3: 박스 | E3: 센터명 | F3: 낱개
A4: BGF로지스강릉 | B4: 12 | C4: =IFERROR(VLOOKUP(A4,'스위트조이 피벗'!A:TK,6,FALSE),0) -> 0 | D4: =IFERROR(ROUNDDOWN(C4/B4,0),"") -> 0 | E4: 강릉 | F4: =IFERROR(C4-(D4*B4),"") -> 0
A5: BGF로지스서귀포 | B5: =$B$4 -> 12 | C5: =IFERROR(VLOOKUP(A5,'스위트조이 피벗'!A:TK,6,FALSE),0) -> 24 | D5: =IFERROR(ROUNDDOWN(C5/B5,0),"") -> 2 | E5: 서귀포 | F5: =IFERROR(C5-(D5*B5),"") -> 0
A6: BGF로지스제주 | B6: =$B$4 -> 12 | C6: =IFERROR(VLOOKUP(A6,'스위트조이 피벗'!A:TK,6,FALSE),0) -> 0 | D6: =IFERROR(ROUNDDOWN(C6/B6,0),"") -> 0 | E6: 제주 | F6: =IFERROR(C6-(D6*B6),"") -> 0
A7: BGF로지스안성 | B7: =$B$4 -> 12 | C7: =IFERROR(VLOOKUP(A7,'스위트조이 피벗'!A:TK,6,FALSE),0) -> 0 | D7: =IFERROR(ROUNDDOWN(C7/B7,0),"") -> 0 | E7: 안성 | F7: =IFERROR(C7-(D7*B7),"") -> 0
A8: 화인로지텍 | B8: =$B$4 -> 12 | C8: =IFERROR(VLOOKUP(A8,'스위트조이 피벗'!A:TK,6,FALSE),0) -> 0 | D8: =IFERROR(ROUNDDOWN(C8/B8,0),"") -> 0 | E8: 화인 | F8: =IFERROR(C8-(D8*B8),"") -> 0
A9: BGF로지스진천 | B9: =$B$4 -> 12 | C9: =IFERROR(VLOOKUP(A9,'스위트조이 피벗'!A:TK,6,FALSE),0) -> 0 | D9: =IFERROR(ROUNDDOWN(C9/B9,0),"") -> 0 | E9: 진천 | F9: =IFERROR(C9-(D9*B9),"") -> 0
