Workbook

Sheet 참조은 피벗
A1: 10/19 | B1: 열 레이블
A2: 행 레이블 | B2: 참조은)그릭복숭아모찌롤 | C2: 참조은)두바이쫀득초코 | D2: 참조은)말차모찌롤케익 | E2: 참조은)생초코파이 | F2: 참조은)생초코파이쿠앤크 | G2: 참조은)우유모찌롤케익 | H2: 참조은)초코모찌롤케익 | I2: 총합계
A3: BGF로지스강릉 | B3: 28 | C3: 4 | D3: 7 | E3: 11 | F3: 9 | G3: 20 | H3: 22 | I3: 101
A4: BGF로지스검단 | B4: 223 | C4: 125 | D4: 110 | E4: 167 | F4: 81 | G4: 266 | H4: 235 | I4: 1207
A5: BGF로지스광주 | B5: 206 | C5: 51 | D5: 88 | E5: 188 | F5: 78 | G5: 210 | H5: 185 | I5: 1006
A6: BGF로지스나주 | B6: 124 | C6: 9 | D6: 31 | E6: 52 | F6: 29 | G6: 104 | H6: 103 | I6: 452
A7: BGF로지스대구 | B7: 91 | C7: 15 | D7: 28 | E7: 63 | F7: 27 | G7: 84 | H7: 77 | I7: 385
A8: BGF로지스부산 | B8: 112 | C8: 29 | D8: 95 | E8: 60 | F8: 34 | G8: 167 | H8: 102 | I8: 599
A9: BGF로지스서귀포 | B9: 23 | C9: 8 | D9: 5 | E9: 25 | F9: 9 | G9: 24 | H9: 16 | I9: 110
A10: BGF로지스서인천1 | B10: 144 | C10: 53 | D10: 44 | E10: 113 | F10: 36 | G10: 141 | H10: 111 | I10: 642
A11: BGF로지스서인천2 | B11: 152 | C11: 82 | D11: 41 | E11: 122 | F11: 45 | G11: 109 | H11: 116 | I11: 667
A12: BGF로지스아산 | B12: 79 | C12: 10 | D12: 27 | E12: 26 | F12: 14 | G12: 65 | H12: 70 | I12: 291
A13: BGF로지스안성 | B13: 90 | C13: 17 | D13: 41 | E13: 39 | F13: 27 | G13: 68 | H13: 80 | I13: 362
A14: BGF로지스양주 | B14: 56 | C14: 14 | D14: 16 | E14: 38 | F14: 16 | G14: 46 | H14: 56 | I14: 242
... A29: 총합계 | B29: 2652 | C29: 650 | D29: 977 | E29: 1707 | F29: 839 | G29: 2517 | H29: 2302 | I29: 11644

Sheet 참조은)그릭복숭아모찌롤
A2: =TODAY() -> 46314 | B2: 참조은 □
A3: 행 레이블 | B3: 입수 | C3: 참조은)그릭복숭아모찌롤 | D3: 박스 | E3: 센터명 | F3: 낱개
A4: BGF로지스강릉 | B4: 45 | C4: =IFERROR(VLOOKUP(A4,'참조은 피벗'!A:SF,2,FALSE),0) -> 28 | D4: =IFERROR(ROUNDDOWN(C4/B4,0),"") -> 0 | E4: 강릉 | F4: =IFERROR(C4-(D4*B4),"") -> 28
A5: BGF로지스검단 | B5: =$B$4 -> 45 | C5: =IFERROR(VLOOKUP(A5,'참조은 피벗'!A:SF,2,FALSE),0) -> 223 | D5: =IFERROR(ROUNDDOWN(C5/B5,0),"") -> 4 | E5: 검단 | F5: =IFERROR(C5-(D5*B5),"") -> 43
A6: BGF로지스서인천1 | B6: =$B$4 -> 45 | C6: =IFERROR(VLOOKUP(A6,'참조은 피벗'!A:SF,2,FALSE),0) -> 144 | D6: =IFERROR(ROUNDDOWN(C6/B6,0),"") -> 3 | E6: 서인천1 | F6: =IFERROR(C6-(D6*B6),"") -> 9
A7: BGF로지스서인천2 | B7: =$B$4 -> 45 | C7: =IFERROR(VLOOKUP(A7,'참조은 피벗'!A:SF,2,FALSE),0) -> 152 | D7: =IFERROR(ROUNDDOWN(C7/B7,0),"") -> 3 | E7: 서인천2 | F7: =IFERROR(C7-(D7*B7),"") -> 17
A8: BGF로지스진천 | B8: =$B$4 -> 45 | C8: =IFERROR(VLOOKUP(A8,'참조은 피벗'!A:SF,2,FALSE),0) -> 95 | D8: =IFERROR(ROUNDDOWN(C8/B8,0),"") -> 2 | E8: 진천 | F8: =IFERROR(C8-(D8*B8),"") -> 5
A9: BGF로지스안성 | B9: =$B$4 -> 45 | C9: =IFERROR(VLOOKUP(A9,'참조은 피벗'!A:SF,2,FALSE),0) -> 90 | D9: =IFERROR(ROUNDDOWN(C9/B9,0),"") -> 2 | E9: 안성 | F9: =IFERROR(C9-(D9*B9),"") -> 0
A10: BGF로지스아산 | B10: =$B$4 -> 45 | C10: =IFERROR(VLOOKUP(A10,'참조은 피벗'!A:SF,2,FALSE),0) -> 79 | D10: =IFERROR(ROUNDDOWN(C10/B10,0),"") -> 1 | E10: 아산 | F10: =IFERROR(C10-(D10*B10),"") -> 34
A11: 화인로지텍 | B11: =$B$4 -> 45 | C11: =IFERROR(VLOOKUP(A11,'참조은 피벗'!A:SF,2,FALSE),0) -> 94 | D11: =IFERROR(ROUNDDOWN(C11/B11,0),"") -> 2 | E11: 화인 | F11: =IFERROR(C11-(D11*B11),"") -> 4
A12: 아신 | B12: =$B$4 -> 45 | C12: =IFERROR(VLOOKUP(A12,'참조은 피벗'!A:SF,2,FALSE),0) -> 126 | D12: =IFERROR(ROUNDDOWN(C12/B12,0),"") -> 2 | E12: 아신 | F12: =IFERROR(C12-(D12*B12),"") -> 36
A13: 씨제이오산 | B13: =$B$4 -> 45 | C13: =IFERROR(VLOOKUP(A13,'참조은 피벗'!A:SF,2,FALSE),0) -> 128 | D13: =IFERROR(ROUNDDOWN(C13/B13,0),"") -> 2 | E13: 오산 | F13: =IFERROR(C13-(D13*B13),"") -> 38
A14: 씨제이군포 | B14: =$B$4 -> 45 | C14: =IFERROR(VLOOKUP(A14,'참조은 피벗'!A:SF,2,FALSE),0) -> 175 | D14: =IFERROR(ROUNDDOWN(C14/B14,0),"") -> 3 | E14: 군포 | F14: =IFERROR(C14-(D14*B14),"") -> 40
A15: BGF로지스광주 | B15: =$B$4 -> 45 | C15: =IFERROR(VLOOKUP(A15,'참조은 피벗'!A:SF,2,FALSE),0) -> 206 | D15: =IFERROR(ROUNDDOWN(C15/B15,0),"") -> 4 | E15: 광주 | F15: =IFERROR(C15-(D15*B15),"") -> 26
A16: BGF로지스양주 | B16: =$B$4 -> 45 | C16: =IFERROR(VLOOKUP(A16,'참조은 피벗'!A:SF,2,FALSE),0) -> 56 | D16: =IFERROR(ROUNDDOWN(C16/B16,0),"") -> 1 | E16: 양주 | F16: =IFERROR(C16-(D16*B16),"") -> 11
... A18: 동부로지스 | B18: =$B$4 -> 45 | C18: =IFERROR(VLOOKUP(A18,'참조은 피벗'!A:SF,2,FALSE),0) -> 54 | D18: =IFERROR(ROUNDDOWN(C18/B18,0),"") -> 1 | E18: 동부 | F18: =IFERROR(C18-(D18*B18),"") -> 9
A20: 수도권 합계 | B20: =$B$4 -> 45 | C20: =SUM(C4:C18) -> 1712 | D20: =IFERROR(ROUNDDOWN(C20/B20,0),"") -> 38 | F20: =IFERROR(C20-(D20*B20),"") -> 2
A22: 엑소후레쉬양산 | B22: =$B$4 -> 45 | C22: =IFERROR(VLOOKUP(A22,'참조은 피벗'!A:SF,2,FALSE),0) -> 149 | D22: =IFERROR(ROUNDDOWN(C22/B22,0),"") -> 3 | E22: 양산 | F22: =IFERROR(C22-(D22*B22),"") -> 14
A23: 극동로지스 | B23: =$B$4 -> 45 | C23: =IFERROR(VLOOKUP(A23,'참조은 피벗'!A:SF,2,FALSE),0) -> 87 | D23: =IFERROR(ROUNDDOWN(C23/B23,0),"") -> 1 | E23: 극동 | F23: =IFERROR(C23-(D23*B23),"") -> 42
A24: 김해물류 | B24: =$B$4 -> 45 | C24: =IFERROR(VLOOKUP(A24,'참조은 피벗'!A:SF,2,FALSE),0) -> 0 | D24: =IFERROR(ROUNDDOWN(C24/B24,0),"") -> 0 | E24: 김해 | F24: =IFERROR(C24-(D24*B24),"") -> 0
A25: BGF로지스부산 | B25: =$B$4 -> 45 | C25: =IFERROR(VLOOKUP(A25,'참조은 피벗'!A:SF,2,FALSE),0) -> 112 | D25: =IFERROR(ROUNDDOWN(C25/B25,0),"") -> 2 | E25: 부산 | F25: =IFERROR(C25-(D25*B25),"") -> 22
A26: BGF로지스진주 | B26: =$B$4 -> 45 | C26: =IFERROR(VLOOKUP(A26,'참조은 피벗'!A:SF,2,FALSE),0) -> 75 | D26: =IFERROR(ROUNDDOWN(C26/B26,0),"") -> 1 | E26: 진주 | F26: =IFERROR(C26-(D26*B26),"") -> 30
A28: 경남(김해)합계 | B28: =$B$4 -> 45 | C28: =SUM(C22:C26) -> 423 | D28: =IFERROR(ROUNDDOWN(C28/B28,0),"") -> 9 | F28: =IFERROR(C28-(D28*B28),"") -> 18
A30: 씨제이경산 | B30: =$B$4 -> 45 | C30: =IFERROR(VLOOKUP(A30,'참조은 피벗'!A:SF,2,FALSE),0) -> 97 | D30: =IFERROR(ROUNDDOWN(C30/B30,0),"") -> 2 | E30: 경산 | F30: =IFERROR(C30-(D30*B30),"") -> 7
A31: BGF로지스대구 | B31: =$B$4 -> 45 | C31: =IFERROR(VLOOKUP(A31,'참조은 피벗'!A:SF,2,FALSE),0) -> 91 | D31: =IFERROR(ROUNDDOWN(C31/B31,0),"") -> 2 | E31: 대구 | F31: =IFERROR(C31-(D31*B31),"") -> 1
A33: 경북(칠곡)합계 | B33: =$B$4 -> 45 | C33: =SUM(C30:C31) -> 188 | D33: =IFERROR(ROUNDDOWN(C33/B33,0),"") -> 4 | F33: =IFERROR(C33-(D33*B33),"") -> 8
A35: BGF로지스나주 | B35: =$B$4 -> 45 | C35: =IFERROR(VLOOKUP(A35,'참조은 피벗'!A:SF,2,FALSE),0) -> 124 | D35: =IFERROR(ROUNDDOWN(C35/B35,0),"") -> 2 | E35: 나주 | F35: =IFERROR(C35-(D35*B35),"") -> 34
A36: 하이로지스 | B36: =$B$4 -> 45 | C36: =IFERROR(VLOOKUP(A36,'참조은 피벗'!A:SF,2,FALSE),0) -> 90 | D36: =IFERROR(ROUNDDOWN(C36/B36,0),"") -> 2 | E36: 하이 | F36: =IFERROR(C36-(D36*B36),"") -> 0
A37: 씨제이김제 | B37: =$B$4 -> 45 | C37: =IFERROR(VLOOKUP(A37,'참조은 피벗'!A:SF,2,FALSE),0) -> 60 | D37: =IFERROR(ROUNDDOWN(C37/B37,0),"") -> 1 | E37: 김제 | F37: =IFERROR(C37-(D37*B37),"") -> 15
A39: 호남권 합계 | B39: =$B$4 -> 45 | C39: =SUM(C35:C37) -> 274 | D39: =IFERROR(ROUNDDOWN(C39/B39,0),"") -> 6 | F39: =IFERROR(C39-(D39*B39),"") -> 4
A41: BGF로지스서귀포 | B41: =$B$4 -> 45 | C41: =IFERROR(VLOOKUP(A41,'참조은 피벗'!A:SF,2,FALSE),0) -> 23 | D41: =IFERROR(ROUNDDOWN(C41/B41,0),"") -> 0 | E41: 서귀포 | F41: =IFERROR(C41-(D41*B41),"") -> 23
A42: BGF로지스제주 | B42: =$B$4 -> 45 | C42: =IFERROR(VLOOKUP(A42,'참조은 피벗'!A:SF,2,FALSE),0) -> 32 | D42: =IFERROR(ROUNDDOWN(C42/B42,0),"") -> 0 | E42: 제주 | F42: =IFERROR(C42-(D42*B42),"") -> 32
A44: 제주권 합계 | B44: =$B$4 -> 45 | C44: =SUM(C41:C42) -> 55 | D44: =IFERROR(ROUNDDOWN(C44/B44,0),"") -> 1 | F44: =IFERROR(C44-(D44*B44),"") -> 10
A46: 총합계 | B46: =$B$4 -> 45 | C46: =SUM(C4:C18,C35:C37,C30:C31,C22:C26,C41:C42) -> 2652 | D46: =IFERROR(ROUNDDOWN(C46/B46,0),"") -> 58 | F46: =IFERROR(C46-(D46*B46),"") -> 42 | G46: 소분박스 | H46: 소분낱개
A47: 총 박스/총 낱개수량 | B47: □ | D47: =SUM(D4:D18,D35:D37,D30:D31,D22:D26,D41:D42) -> 47 | F47: =SUM(F4:F18,F35:F37,F30:F31,F22:F26,F41:F42) -> 537 | G47: =IFERROR(ROUNDDOWN(F47/B35,0),"") -> 11 | H47: =IFERROR(F47-(G47*B35),"") -> 42
C48: =C20+C28+C33+C39+C44 -> 2652 | H48: □
C49: =C48=C46 -> TRUE

Sheet 참조은)두바이쫀득초코
A2: =TODAY() -> 46314 | B2: 참조은 □
A3: 행 레이블 | B3: 입수 | C3: 참조은)두바이쫀득초코 | D3: 박스 | E3: 센터명 | F3: 낱개
A4: BGF로지스강릉 | B4: 48 | C4: =IFERROR(VLOOKUP(A4,'참조은 피벗'!A:SF,3,FALSE),0) -> 4 | D4: =IFERROR(ROUNDDOWN(C4/B4,0),"") -> 0 | E4: 강릉 | F4: =IFERROR(C4-(D4*B4),"") -> 4
A5: BGF로지스검단 | B5: =$B$4 -> 48 | C5: =IFERROR(VLOOKUP(A5,'참조은 피벗'!A:SF,3,FALSE),0) -> 125 | D5: =IFERROR(ROUNDDOWN(C5/B5,0),"") -> 2 | E5: 검단 | F5: =IFERROR(C5-(D5*B5),"") -> 29
A6: BGF로지스서인천1 | B6: =$B$4 -> 48 | C6: =IFERROR(VLOOKUP(A6,'참조은 피벗'!A:SF,3,FALSE),0) -> 53 | D6: =IFERROR(ROUNDDOWN(C6/B6,0),"") -> 1 | E6: 서인천1 | F6: =IFERROR(C6-(D6*B6),"") -> 5
A7: BGF로지스서인천2 | B7: =$B$4 -> 48 | C7: =IFERROR(VLOOKUP(A7,'참조은 피벗'!A:SF,3,FALSE),0) -> 82 | D7: =IFERROR(ROUNDDOWN(C7/B7,0),"") -> 1 | E7: 서인천2 | F7: =IFERROR(C7-(D7*B7),"") -> 34
A8: BGF로지스진천 | B8: =$B$4 -> 48 | C8: =IFERROR(VLOOKUP(A8,'참조은 피벗'!A:SF,3,FALSE),0) -> 17 | D8: =IFERROR(ROUNDDOWN(C8/B8,0),"") -> 0 | E8: 진천 | F8: =IFERROR(C8-(D8*B8),"") -> 17
A9: BGF로지스안성 | B9: =$B$4 -> 48 | C9: =IFERROR(VLOOKUP(A9,'참조은 피벗'!A:SF,3,FALSE),0) -> 17 | D9: =IFERROR(ROUNDDOWN(C9/B9,0),"") -> 0 | E9: 안성 | F9: =IFERROR(C9-(D9*B9),"") -> 17
A10: BGF로지스아산 | B10: =$B$4 -> 48 | C10: =IFERROR(VLOOKUP(A10,'참조은 피벗'!A:SF,3,FALSE),0) -> 10 | D10: =IFERROR(ROUNDDOWN(C10/B10,0),"") -> 0 | E10: 아산 | F10: =IFERROR(C10-(D10*B10),"") -> 10
A11: 화인로지텍 | B11: =$B$4 -> 48 | C11: =IFERROR(VLOOKUP(A11,'참조은 피벗'!A:SF,3,FALSE),0) -> 13 | D11: =IFERROR(ROUNDDOWN(C11/B11,0),"") -> 0 | E11: 화인 | F11: =IFERROR(C11-(D11*B11),"") -> 13
A12: 아신 | B12: =$B$4 -> 48 | C12: =IFERROR(VLOOKUP(A12,'참조은 피벗'!A:SF,3,FALSE),0) -> 16 | D12: =IFERROR(ROUNDDOWN(C12/B12,0),"") -> 0 | E12: 아신 | F12: =IFERROR(C12-(D12*B12),"") -> 16
A13: 씨제이오산 | B13: =$B$4 -> 48 | C13: =IFERROR(VLOOKUP(A13,'참조은 피벗'!A:SF,3,FALSE),0) -> 40 | D13: =IFERROR(ROUNDDOWN(C13/B13,0),"") -> 0 | E13: 오산 | F13: =IFERROR(C13-(D13*B13),"") -> 40
A14: 씨제이군포 | B14: =$B$4 -> 48 | C14: =IFERROR(VLOOKUP(A14,'참조은 피벗'!A:SF,3,FALSE),0) -> 23 | D14: =IFERROR(ROUNDDOWN(C14/B14,0),"") -> 0 | E14: 군포 | F14: =IFERROR(C14-(D14*B14),"") -> 23
A15: BGF로지스광주 | B15: =$B$4 -> 48 | C15: =IFERROR(VLOOKUP(A15,'참조은 피벗'!A:SF,3,FALSE),0) -> 51 | D15: =IFERROR(ROUNDDOWN(C15/B15,0),"") -> 1 | E15: 광주 | F15: =IFERROR(C15-(D15*B15),"") -> 3
A16: BGF로지스양주 | B16: =$B$4 -> 48 | C16: =IFERROR(VLOOKUP(A16,'참조은 피벗'!A:SF,3,FALSE),0) -> 14 | D16: =IFERROR(ROUNDDOWN(C16/B16,0),"") -> 0 | E16: 양주 | F16: =IFERROR(C16-(D16*B16),"") -> 14
... A18: 동부로지스 | B18: =$B$4 -> 48 | C18: =IFERROR(VLOOKUP(A18,'참조은 피벗'!A:SF,3,FALSE),0) -> 15 | D18: =IFERROR(ROUNDDOWN(C18/B18,0),"") -> 0 | E18: 동부 | F18: =IFERROR(C18-(D18*B18),"") -> 15
A20: 수도권 합계 | B20: =$B$4 -> 48 | C20: =SUM(C4:C18) -> 485 | D20: =IFERROR(ROUNDDOWN(C20/B20,0),"") -> 10 | F20: =IFERROR(C20-(D20*B20),"") -> 5
A22: 엑소후레쉬양산 | B22: =$B$4 -> 48 | C22: =IFERROR(VLOOKUP(A22,'참조은 피벗'!A:SF,3,FALSE),0) -> 19 | D22: =IFERROR(ROUNDDOWN(C22/B22,0),"") -> 0 | E22: 양산 | F22: =IFERROR(C22-(D22*B22),"") -> 19
A23: 극동로지스 | B23: =$B$4 -> 48 | C23: =IFERROR(VLOOKUP(A23,'참조은 피벗'!A:SF,3,FALSE),0) -> 23 | D23: =IFERROR(ROUNDDOWN(C23/B23,0),"") -> 0 | E23: 극동 | F23: =IFERROR(C23-(D23*B23),"") -> 23
A24: 김해물류 | B24: =$B$4 -> 48 | C24: =IFERROR(VLOOKUP(A24,'참조은 피벗'!A:SF,3,FALSE),0) -> 0 | D24: =IFERROR(ROUNDDOWN(C24/B24,0),"") -> 0 | E24: 김해 | F24: =IFERROR(C24-(D24*B24),"") -> 0
A25: BGF로지스부산 | B25: =$B$4 -> 48 | C25: =IFERROR(VLOOKUP(A25,'참조은 피벗'!A:SF,3,FALSE),0) -> 29 | D25: =IFERROR(ROUNDDOWN(C25/B25,0),"") -> 0 | E25: 부산 | F25: =IFERROR(C25-(D25*B25),"") -> 29
A26: BGF로지스진주 | B26: =$B$4 -> 48 | C26: =IFERROR(VLOOKUP(A26,'참조은 피벗'!A:SF,3,FALSE),0) -> 17 | D26: =IFERROR(ROUNDDOWN(C26/B26,0),"") -> 0 | E26: 진주 | F26: =IFERROR(C26-(D26*B26),"") -> 17
A28: 경남(김해)합계 | B28: =$B$4 -> 48 | C28: =SUM(C22:C26) -> 88 | D28: =IFERROR(ROUNDDOWN(C28/B28,0),"") -> 1 | F28: =IFERROR(C28-(D28*B28),"") -> 40
A30: 씨제이경산 | B30: =$B$4 -> 48 | C30: =IFERROR(VLOOKUP(A30,'참조은 피벗'!A:SF,3,FALSE),0) -> 19 | D30: =IFERROR(ROUNDDOWN(C30/B30,0),"") -> 0 | E30: 경산 | F30: =IFERROR(C30-(D30*B30),"") -> 19
A31: BGF로지스대구 | B31: =$B$4 -> 48 | C31: =IFERROR(VLOOKUP(A31,'참조은 피벗'!A:SF,3,FALSE),0) -> 15 | D31: =IFERROR(ROUNDDOWN(C31/B31,0),"") -> 0 | E31: 대구 | F31: =IFERROR(C31-(D31*B31),"") -> 15
A33: 경북(칠곡)합계 | B33: =$B$4 -> 48 | C33: =SUM(C30:C31) -> 34 | D33: =IFERROR(ROUNDDOWN(C33/B33,0),"") -> 0 | F33: =IFERROR(C33-(D33*B33),"") -> 34
A35: BGF로지스나주 | B35: =$B$4 -> 48 | C35: =IFERROR(VLOOKUP(A35,'참조은 피벗'!A:SF,3,FALSE),0) -> 9 | D35: =IFERROR(ROUNDDOWN(C35/B35,0),"") -> 0 | E35: 나주 | F35: =IFERROR(C35-(D35*B35),"") -> 9
A36: 하이로지스 | B36: =$B$4 -> 48 | C36: =IFERROR(VLOOKUP(A36,'참조은 피벗'!A:SF,3,FALSE),0) -> 12 | D36: =IFERROR(ROUNDDOWN(C36/B36,0),"") -> 0 | E36: 하이 | F36: =IFERROR(C36-(D36*B36),"") -> 12
A37: 씨제이김제 | B37: =$B$4 -> 48 | C37: =IFERROR(VLOOKUP(A37,'참조은 피벗'!A:SF,3,FALSE),0) -> 7 | D37: =IFERROR(ROUNDDOWN(C37/B37,0),"") -> 0 | E37: 김제 | F37: =IFERROR(C37-(D37*B37),"") -> 7
A39: 호남권 합계 | B39: =$B$4 -> 48 | C39: =SUM(C35:C37) -> 28 | D39: =IFERROR(ROUNDDOWN(C39/B39,0),"") -> 0 | F39: =IFERROR(C39-(D39*B39),"") -> 28
A41: BGF로지스서귀포 | B41: =$B$4 -> 48 | C41: =IFERROR(VLOOKUP(A41,'참조은 피벗'!A:SF,3,FALSE),0) -> 8 | D41: =IFERROR(ROUNDDOWN(C41/B41,0),"") -> 0 | E41: 서귀포 | F41: =IFERROR(C41-(D41*B41),"") -> 8
A42: BGF로지스제주 | B42: =$B$4 -> 48 | C42: =IFERROR(VLOOKUP(A42,'참조은 피벗'!A:SF,3,FALSE),0) -> 7 | D42: =IFERROR(ROUNDDOWN(C42/B42,0),"") -> 0 | E42: 제주 | F42: =IFERROR(C42-(D42*B42),"") -> 7
A44: 제주권 합계 | B44: =$B$4 -> 48 | C44: =SUM(C41:C42) -> 15 | D44: =IFERROR(ROUNDDOWN(C44/B44,0),"") -> 0 | F44: =IFERROR(C44-(D44*B44),"") -> 15
A46: 총합계 | B46: =$B$4 -> 48 | C46: =SUM(C4:C18,C35:C37,C30:C31,C22:C26,C41:C42) -> 650 | D46: =IFERROR(ROUNDDOWN(C46/B46,0),"") -> 13 | F46: =IFERROR(C46-(D46*B46),"") -> 26 | G46: 소분박스 | H46: 소분낱개
A47: 총 박스/총 낱개수량 | B47: □ | D47: =SUM(D4:D18,D35:D37,D30:D31,D22:D26,D41:D42) -> 5 | F47: =SUM(F4:F18,F35:F37,F30:F31,F22:F26,F41:F42) -> 410 | G47: =IFERROR(ROUNDDOWN(F47/B35,0),"") -> 8 | H47: =IFERROR(F47-(G47*B35),"") -> 26
C48: =C20+C28+C33+C39+C44 -> 650 | H48: □
C49: =C48=C46 -> TRUE

Sheet 참조은)말차모찌롤케익
A2: =TODAY() -> 46314 | B2: 참조은 □
A3: 행 레이블 | B3: 입수 | C3: 참조은)말차모찌롤케익 | D3: 박스 | E3: 센터명 | F3: 낱개
A4: BGF로지스강릉 | B4: 45 | C4: =IFERROR(VLOOKUP(A4,'참조은 피벗'!A:SF,4,FALSE),0) -> 7 | D4: =IFERROR(ROUNDDOWN(C4/B4,0),"") -> 0 | E4: 강릉 | F4: =IFERROR(C4-(D4*B4),"") -> 7
A5: BGF로지스검단 | B5: =$B$4 -> 45 | C5: =IFERROR(VLOOKUP(A5,'참조은 피벗'!A:SF,4,FALSE),0) -> 110 | D5: =IFERROR(ROUNDDOWN(C5/B5,0),"") -> 2 | E5: 검단 | F5: =IFERROR(C5-(D5*B5),"") -> 20
A6: BGF로지스서인천1 | B6: =$B$4 -> 45 | C6: =IFERROR(VLOOKUP(A6,'참조은 피벗'!A:SF,4,FALSE),0) -> 44 | D6: =IFERROR(ROUNDDOWN(C6/B6,0),"") -> 0 | E6: 서인천1 | F6: =IFERROR(C6-(D6*B6),"") -> 44
A7: BGF로지스서인천2 | B7: =$B$4 -> 45 | C7: =IFERROR(VLOOKUP(A7,'참조은 피벗'!A:SF,4,FALSE),0) -> 41 | D7: =IFERROR(ROUNDDOWN(C7/B7,0),"") -> 0 | E7: 서인천2 | F7: =IFERROR(C7-(D7*B7),"") -> 41
A8: BGF로지스진천 | B8: =$B$4 -> 45 | C8: =IFERROR(VLOOKUP(A8,'참조은 피벗'!A:SF,4,FALSE),0) -> 23 | D8: =IFERROR(ROUNDDOWN(C8/B8,0),"") -> 0 | E8: 진천 | F8: =IFERROR(C8-(D8*B8),"") -> 23
A9: BGF로지스안성 | B9: =$B$4 -> 45 | C9: =IFERROR(VLOOKUP(A9,'참조은 피벗'!A:SF,4,FALSE),0) -> 41 | D9: =IFERROR(ROUNDDOWN(C9/B9,0),"") -> 0 | E9: 안성 | F9: =IFERROR(C9-(D9*B9),"") -> 41
A10: BGF로지스아산 | B10: =$B$4 -> 45 | C10: =IFERROR(VLOOKUP(A10,'참조은 피벗'!A:SF,4,FALSE),0) -> 27 | D10: =IFERROR(ROUNDDOWN(C10/B10,0),"") -> 0 | E10: 아산 | F10: =IFERROR(C10-(D10*B10),"") -> 27
A11: 화인로지텍 | B11: =$B$4 -> 45 | C11: =IFERROR(VLOOKUP(A11,'참조은 피벗'!A:SF,4,FALSE),0) -> 43 | D11: =IFERROR(ROUNDDOWN(C11/B11,0),"") -> 0 | E11: 화인 | F11: =IFERROR(C11-(D11*B11),"") -> 43
A12: 아신 | B12: =$B$4 -> 45 | C12: =IFERROR(VLOOKUP(A12,'참조은 피벗'!A:SF,4,FALSE),0) -> 42 | D12: =IFERROR(ROUNDDOWN(C12/B12,0),"") -> 0 | E12: 아신 | F12: =IFERROR(C12-(D12*B12),"") -> 42
A13: 씨제이오산 | B13: =$B$4 -> 45 | C13: =IFERROR(VLOOKUP(A13,'참조은 피벗'!A:SF,4,FALSE),0) -> 35 | D13: =IFERROR(ROUNDDOWN(C13/B13,0),"") -> 0 | E13: 오산 | F13: =IFERROR(C13-(D13*B13),"") -> 35
A14: 씨제이군포 | B14: =$B$4 -> 45 | C14: =IFERROR(VLOOKUP(A14,'참조은 피벗'!A:SF,4,FALSE),0) -> 62 | D14: =IFERROR(ROUNDDOWN(C14/B14,0),"") -> 1 | E14: 군포 | F14: =IFERROR(C14-(D14*B14),"") -> 17
A15: BGF로지스광주 | B15: =$B$4 -> 45 | C15: =IFERROR(VLOOKUP(A15,'참조은 피벗'!A:SF,4,FALSE),0) -> 88 | D15: =IFERROR(ROUNDDOWN(C15/B15,0),"") -> 1 | E15: 광주 | F15: =IFERROR(C15-(D15*B15),"") -> 43
A16: BGF로지스양주 | B16: =$B$4 -> 45 | C16: =IFERROR(VLOOKUP(A16,'참조은 피벗'!A:SF,4,FALSE),0) -> 16 | D16: =IFERROR(ROUNDDOWN(C16/B16,0),"") -> 0 | E16: 양주 | F16: =IFERROR(C16-(D16*B16),"") -> 16
... A18: 동부로지스 | B18: =$B$4 -> 45 | C18: =IFERROR(VLOOKUP(A18,'참조은 피벗'!A:SF,4,FALSE),0) -> 22 | D18: =IFERROR(ROUNDDOWN(C18/B18,0),"") -> 0 | E18: 동부 | F18: =IFERROR(C18-(D18*B18),"") -> 22
A20: 수도권 합계 | B20: =$B$4 -> 45 | C20: =SUM(C4:C18) -> 621 | D20: =IFERROR(ROUNDDOWN(C20/B20,0),"") -> 13 | F20: =IFERROR(C20-(D20*B20),"") -> 36
A22: 엑소후레쉬양산 | B22: =$B$4 -> 45 | C22: =IFERROR(VLOOKUP(A22,'참조은 피벗'!A:SF,4,FALSE),0) -> 44 | D22: =IFERROR(ROUNDDOWN(C22/B22,0),"") -> 0 | E22: 양산 | F22: =IFERROR(C22-(D22*B22),"") -> 44
A23: 극동로지스 | B23: =$B$4 -> 45 | C23: =IFERROR(VLOOKUP(A23,'참조은 피벗'!A:SF,4,FALSE),0) -> 36 | D23: =IFERROR(ROUNDDOWN(C23/B23,0),"") -> 0 | E23: 극동 | F23: =IFERROR(C23-(D23*B23),"") -> 36
A24: 김해물류 | B24: =$B$4 -> 45 | C24: =IFERROR(VLOOKUP(A24,'참조은 피벗'!A:SF,4,FALSE),0) -> 0 | D24: =IFERROR(ROUNDDOWN(C24/B24,0),"") -> 0 | E24: 김해 | F24: =IFERROR(C24-(D24*B24),"") -> 0
A25: BGF로지스부산 | B25: =$B$4 -> 45 | C25: =IFERROR(VLOOKUP(A25,'참조은 피벗'!A:SF,4,FALSE),0) -> 95 | D25: =IFERROR(ROUNDDOWN(C25/B25,0),"") -> 2 | E25: 부산 | F25: =IFERROR(C25-(D25*B25),"") -> 5
A26: BGF로지스진주 | B26: =$B$4 -> 45 | C26: =IFERROR(VLOOKUP(A26,'참조은 피벗'!A:SF,4,FALSE),0) -> 19 | D26: =IFERROR(ROUNDDOWN(C26/B26,0),"") -> 0 | E26: 진주 | F26: =IFERROR(C26-(D26*B26),"") -> 19
A28: 경남(김해)합계 | B28: =$B$4 -> 45 | C28: =SUM(C22:C26) -> 194 | D28: =IFERROR(ROUNDDOWN(C28/B28,0),"") -> 4 | F28: =IFERROR(C28-(D28*B28),"") -> 14
A30: 씨제이경산 | B30: =$B$4 -> 45 | C30: =IFERROR(VLOOKUP(A30,'참조은 피벗'!A:SF,4,FALSE),0) -> 38 | D30: =IFERROR(ROUNDDOWN(C30/B30,0),"") -> 0 | E30: 경산 | F30: =IFERROR(C30-(D30*B30),"") -> 38
A31: BGF로지스대구 | B31: =$B$4 -> 45 | C31: =IFERROR(VLOOKUP(A31,'참조은 피벗'!A:SF,4,FALSE),0) -> 28 | D31: =IFERROR(ROUNDDOWN(C31/B31,0),"") -> 0 | E31: 대구 | F31: =IFERROR(C31-(D31*B31),"") -> 28
A33: 경북(칠곡)합계 | B33: =$B$4 -> 45 | C33: =SUM(C30:C31) -> 66 | D33: =IFERROR(ROUNDDOWN(C33/B33,0),"") -> 1 | F33: =IFERROR(C33-(D33*B33),"") -> 21
A35: BGF로지스나주 | B35: =$B$4 -> 45 | C35: =IFERROR(VLOOKUP(A35,'참조은 피벗'!A:SF,4,FALSE),0) -> 31 | D35: =IFERROR(ROUNDDOWN(C35/B35,0),"") -> 0 | E35: 나주 | F35: =IFERROR(C35-(D35*B35),"") -> 31
A36: 하이로지스 | B36: =$B$4 -> 45 | C36: =IFERROR(VLOOKUP(A36,'참조은 피벗'!A:SF,4,FALSE),0) -> 28 | D36: =IFERROR(ROUNDDOWN(C36/B36,0),"") -> 0 | E36: 하이 | F36: =IFERROR(C36-(D36*B36),"") -> 28
A37: 씨제이김제 | B37: =$B$4 -> 45 | C37: =IFERROR(VLOOKUP(A37,'참조은 피벗'!A:SF,4,FALSE),0) -> 26 | D37: =IFERROR(ROUNDDOWN(C37/B37,0),"") -> 0 | E37: 김제 | F37: =IFERROR(C37-(D37*B37),"") -> 26
A39: 호남권 합계 | B39: =$B$4 -> 45 | C39: =SUM(C35:C37) -> 85 | D39: =IFERROR(ROUNDDOWN(C39/B39,0),"") -> 1 | F39: =IFERROR(C39-(D39*B39),"") -> 40
A41: BGF로지스서귀포 | B41: =$B$4 -> 45 | C41: =IFERROR(VLOOKUP(A41,'참조은 피벗'!A:SF,4,FALSE),0) -> 5 | D41: =IFERROR(ROUNDDOWN(C41/B41,0),"") -> 0 | E41: 서귀포 | F41: =IFERROR(C41-(D41*B41),"") -> 5
A42: BGF로지스제주 | B42: =$B$4 -> 45 | C42: =IFERROR(VLOOKUP(A42,'참조은 피벗'!A:SF,4,FALSE),0) -> 6 | D42: =IFERROR(ROUNDDOWN(C42/B42,0),"") -> 0 | E42: 제주 | F42: =IFERROR(C42-(D42*B42),"") -> 6
A44: 제주권 합계 | B44: =$B$4 -> 45 | C44: =SUM(C41:C42) -> 11 | D44: =IFERROR(ROUNDDOWN(C44/B44,0),"") -> 0 | F44: =IFERROR(C44-(D44*B44),"") -> 11
A46: 총합계 | B46: =$B$4 -> 45 | C46: =SUM(C4:C18,C35:C37,C30:C31,C22:C26,C41:C42) -> 977 | D46: =IFERROR(ROUNDDOWN(C46/B46,0),"") -> 21 | F46: =IFERROR(C46-(D46*B46),"") -> 32 | G46: 소분박스 | H46: 소분낱개
A47: 총 박스/총 낱개수량 | B47: □ | D47: =SUM(D4:D18,D35:D37,D30:D31,D22:D26,D41:D42) -> 6 | F47: =SUM(F4:F18,F35:F37,F30:F31,F22:F26,F41:F42) -> 707 | G47: =IFERROR(ROUNDDOWN(F47/B35,0),"") -> 15 | H47: =IFERROR(F47-(G47*B35),"") -> 32
C48: =C20+C28+C33+C39+C44 -> 977 | H48: □
C49: =C48=C46 -> TRUE

Sheet 참조은)생초코파이
A2: =TODAY() -> 46314 | B2: 참조은 □
A3: 행 레이블 | B3: 입수 | C3: 참조은)생초코파이 | D3: 박스 | E3: 센터명 | F3: 낱개
A4: BGF로지스강릉 | B4: 30 | C4: =IFERROR(VLOOKUP(A4,'참조은 피벗'!A:SF,5,FALSE),0) -> 11 | D4: =IFERROR(ROUNDDOWN(C4/B4,0),"") -> 0 | E4: 강릉 | F4: =IFERROR(C4-(D4*B4),"") -> 11
A5: BGF로지스검단 | B5: =$B$4 -> 30 | C5: =IFERROR(VLOOKUP(A5,'참조은 피벗'!A:SF,5,FALSE),0) -> 167 | D5: =IFERROR(ROUNDDOWN(C5/B5,0),"") -> 5 | E5: 검단 | F5: =IFERROR(C5-(D5*B5),"") -> 17
A6: BGF로지스서인천1 | B6: =$B$4 -> 30 | C6: =IFERROR(VLOOKUP(A6,'참조은 피벗'!A:SF,5,FALSE),0) -> 113 | D6: =IFERROR(ROUNDDOWN(C6/B6,0),"") -> 3 | E6: 서인천1 | F6: =IFERROR(C6-(D6*B6),"") -> 23
A7: BGF로지스서인천2 | B7: =$B$4 -> 30 | C7: =IFERROR(VLOOKUP(A7,'참조은 피벗'!A:SF,5,FALSE),0) -> 122 | D7: =IFERROR(ROUNDDOWN(C7/B7,0),"") -> 4 | E7: 서인천2 | F7: =IFERROR(C7-(D7*B7),"") -> 2
A8: BGF로지스진천 | B8: =$B$4 -> 30 | C8: =IFERROR(VLOOKUP(A8,'참조은 피벗'!A:SF,5,FALSE),0) -> 42 | D8: =IFERROR(ROUNDDOWN(C8/B8,0),"") -> 1 | E8: 진천 | F8: =IFERROR(C8-(D8*B8),"") -> 12
A9: BGF로지스안성 | B9: =$B$4 -> 30 | C9: =IFERROR(VLOOKUP(A9,'참조은 피벗'!A:SF,5,FALSE),0) -> 39 | D9: =IFERROR(ROUNDDOWN(C9/B9,0),"") -> 1 | E9: 안성 | F9: =IFERROR(C9-(D9*B9),"") -> 9
A10: BGF로지스아산 | B10: =$B$4 -> 30 | C10: =IFERROR(VLOOKUP(A10,'참조은 피벗'!A:SF,5,FALSE),0) -> 26 | D10: =IFERROR(ROUNDDOWN(C10/B10,0),"") -> 0 | E10: 아산 | F10: =IFERROR(C10-(D10*B10),"") -> 26
A11: 화인로지텍 | B11: =$B$4 -> 30 | C11: =IFERROR(VLOOKUP(A11,'참조은 피벗'!A:SF,5,FALSE),0) -> 76 | D11: =IFERROR(ROUNDDOWN(C11/B11,0),"") -> 2 | E11: 화인 | F11: =IFERROR(C11-(D11*B11),"") -> 16
A12: 아신 | B12: =$B$4 -> 30 | C12: =IFERROR(VLOOKUP(A12,'참조은 피벗'!A:SF,5,FALSE),0) -> 86 | D12: =IFERROR(ROUNDDOWN(C12/B12,0),"") -> 2 | E12: 아신 | F12: =IFERROR(C12-(D12*B12),"") -> 26
A13: 씨제이오산 | B13: =$B$4 -> 30 | C13: =IFERROR(VLOOKUP(A13,'참조은 피벗'!A:SF,5,FALSE),0) -> 92 | D13: =IFERROR(ROUNDDOWN(C13/B13,0),"") -> 3 | E13: 오산 | F13: =IFERROR(C13-(D13*B13),"") -> 2
A14: 씨제이군포 | B14: =$B$4 -> 30 | C14: =IFERROR(VLOOKUP(A14,'참조은 피벗'!A:SF,5,FALSE),0) -> 96 | D14: =IFERROR(ROUNDDOWN(C14/B14,0),"") -> 3 | E14: 군포 | F14: =IFERROR(C14-(D14*B14),"") -> 6
A15: BGF로지스광주 | B15: =$B$4 -> 30 | C15: =IFERROR(VLOOKUP(A15,'참조은 피벗'!A:SF,5,FALSE),0) -> 188 | D15: =IFERROR(ROUNDDOWN(C15/B15,0),"") -> 6 | E15: 광주 | F15: =IFERROR(C15-(D15*B15),"") -> 8
A16: BGF로지스양주 | B16: =$B$4 -> 30 | C16: =IFERROR(VLOOKUP(A16,'참조은 피벗'!A:SF,5,FALSE),0) -> 38 | D16: =IFERROR(ROUNDDOWN(C16/B16,0),"") -> 1 | E16: 양주 | F16: =IFERROR(C16-(D16*B16),"") -> 8
... A18: 동부로지스 | B18: =$B$4 -> 30 | C18: =IFERROR(VLOOKUP(A18,'참조은 피벗'!A:SF,5,FALSE),0) -> 33 | D18: =IFERROR(ROUNDDOWN(C18/B18,0),"") -> 1 | E18: 동부 | F18: =IFERROR(C18-(D18*B18),"") -> 3
A20: 수도권 합계 | B20: =$B$4 -> 30 | C20: =SUM(C4:C18) -> 1156 | D20: =IFERROR(ROUNDDOWN(C20/B20,0),"") -> 38 | F20: =IFERROR(C20-(D20*B20),"") -> 16
A22: 엑소후레쉬양산 | B22: =$B$4 -> 30 | C22: =IFERROR(VLOOKUP(A22,'참조은 피벗'!A:SF,5,FALSE),0) -> 87 | D22: =IFERROR(ROUNDDOWN(C22/B22,0),"") -> 2 | E22: 양산 | F22: =IFERROR(C22-(D22*B22),"") -> 27
A23: 극동로지스 | B23: =$B$4 -> 30 | C23: =IFERROR(VLOOKUP(A23,'참조은 피벗'!A:SF,5,FALSE),0) -> 49 | D23: =IFERROR(ROUNDDOWN(C23/B23,0),"") -> 1 | E23: 극동 | F23: =IFERROR(C23-(D23*B23),"") -> 19
A24: 김해물류 | B24: =$B$4 -> 30 | C24: =IFERROR(VLOOKUP(A24,'참조은 피벗'!A:SF,5,FALSE),0) -> 0 | D24: =IFERROR(ROUNDDOWN(C24/B24,0),"") -> 0 | E24: 김해 | F24: =IFERROR(C24-(D24*B24),"") -> 0
A25: BGF로지스부산 | B25: =$B$4 -> 30 | C25: =IFERROR(VLOOKUP(A25,'참조은 피벗'!A:SF,5,FALSE),0) -> 60 | D25: =IFERROR(ROUNDDOWN(C25/B25,0),"") -> 2 | E25: 부산 | F25: =IFERROR(C25-(D25*B25),"") -> 0
A26: BGF로지스진주 | B26: =$B$4 -> 30 | C26: =IFERROR(VLOOKUP(A26,'참조은 피벗'!A:SF,5,FALSE),0) -> 35 | D26: =IFERROR(ROUNDDOWN(C26/B26,0),"") -> 1 | E26: 진주 | F26: =IFERROR(C26-(D26*B26),"") -> 5
A28: 경남(김해)합계 | B28: =$B$4 -> 30 | C28: =SUM(C22:C26) -> 231 | D28: =IFERROR(ROUNDDOWN(C28/B28,0),"") -> 7 | F28: =IFERROR(C28-(D28*B28),"") -> 21
A30: 씨제이경산 | B30: =$B$4 -> 30 | C30: =IFERROR(VLOOKUP(A30,'참조은 피벗'!A:SF,5,FALSE),0) -> 67 | D30: =IFERROR(ROUNDDOWN(C30/B30,0),"") -> 2 | E30: 경산 | F30: =IFERROR(C30-(D30*B30),"") -> 7
A31: BGF로지스대구 | B31: =$B$4 -> 30 | C31: =IFERROR(VLOOKUP(A31,'참조은 피벗'!A:SF,5,FALSE),0) -> 63 | D31: =IFERROR(ROUNDDOWN(C31/B31,0),"") -> 2 | E31: 대구 | F31: =IFERROR(C31-(D31*B31),"") -> 3
A33: 경북(칠곡)합계 | B33: =$B$4 -> 30 | C33: =SUM(C30:C31) -> 130 | D33: =IFERROR(ROUNDDOWN(C33/B33,0),"") -> 4 | F33: =IFERROR(C33-(D33*B33),"") -> 10
A35: BGF로지스나주 | B35: =$B$4 -> 30 | C35: =IFERROR(VLOOKUP(A35,'참조은 피벗'!A:SF,5,FALSE),0) -> 52 | D35: =IFERROR(ROUNDDOWN(C35/B35,0),"") -> 1 | E35: 나주 | F35: =IFERROR(C35-(D35*B35),"") -> 22
A36: 하이로지스 | B36: =$B$4 -> 30 | C36: =IFERROR(VLOOKUP(A36,'참조은 피벗'!A:SF,5,FALSE),0) -> 46 | D36: =IFERROR(ROUNDDOWN(C36/B36,0),"") -> 1 | E36: 하이 | F36: =IFERROR(C36-(D36*B36),"") -> 16
A37: 씨제이김제 | B37: =$B$4 -> 30 | C37: =IFERROR(VLOOKUP(A37,'참조은 피벗'!A:SF,5,FALSE),0) -> 35 | D37: =IFERROR(ROUNDDOWN(C37/B37,0),"") -> 1 | E37: 김제 | F37: =IFERROR(C37-(D37*B37),"") -> 5
A39: 호남권 합계 | B39: =$B$4 -> 30 | C39: =SUM(C35:C37) -> 133 | D39: =IFERROR(ROUNDDOWN(C39/B39,0),"") -> 4 | F39: =IFERROR(C39-(D39*B39),"") -> 13
A41: BGF로지스서귀포 | B41: =$B$4 -> 30 | C41: =IFERROR(VLOOKUP(A41,'참조은 피벗'!A:SF,5,FALSE),0) -> 25 | D41: =IFERROR(ROUNDDOWN(C41/B41,0),"") -> 0 | E41: 서귀포 | F41: =IFERROR(C41-(D41*B41),"") -> 25
A42: BGF로지스제주 | B42: =$B$4 -> 30 | C42: =IFERROR(VLOOKUP(A42,'참조은 피벗'!A:SF,5,FALSE),0) -> 32 | D42: =IFERROR(ROUNDDOWN(C42/B42,0),"") -> 1 | E42: 제주 | F42: =IFERROR(C42-(D42*B42),"") -> 2
A44: 제주권 합계 | B44: =$B$4 -> 30 | C44: =SUM(C41:C42) -> 57 | D44: =IFERROR(ROUNDDOWN(C44/B44,0),"") -> 1 | F44: =IFERROR(C44-(D44*B44),"") -> 27
A46: 총합계 | B46: =$B$4 -> 30 | C46: =SUM(C4:C18,C35:C37,C30:C31,C22:C26,C41:C42) -> 1707 | D46: =IFERROR(ROUNDDOWN(C46/B46,0),"") -> 56 | F46: =IFERROR(C46-(D46*B46),"") -> 27 | G46: 소분박스 | H46: 소분낱개
A47: 총 박스/총 낱개수량 | B47: □ | D47: =SUM(D4:D18,D35:D37,D30:D31,D22:D26,D41:D42) -> 46 | F47: =SUM(F4:F18,F35:F37,F30:F31,F22:F26,F41:F42) -> 327 | G47: =IFERROR(ROUNDDOWN(F47/B35,0),"") -> 10 | H47: =IFERROR(F47-(G47*B35),"") -> 27
C48: =C20+C28+C33+C39+C44 -> 1707 | H48: □
C49: =C48=C46 -> TRUE

Sheet 참조은)생초코파이쿠앤크
A2: =TODAY() -> 46314 | B2: 참조은 □
A3: 행 레이블 | B3: 입수 | C3: 참조은)생초코파이 쿠앤크 | D3: 박스 | E3: 센터명 | F3: 낱개
A4: BGF로지스강릉 | B4: 30 | C4: =IFERROR(VLOOKUP(A4,'참조은 피벗'!A:SF,6,FALSE),0) -> 9 | D4: =IFERROR(ROUNDDOWN(C4/B4,0),"") -> 0 | E4: 강릉 | F4: =IFERROR(C4-(D4*B4),"") -> 9
A5: BGF로지스검단 | B5: =$B$4 -> 30 | C5: =IFERROR(VLOOKUP(A5,'참조은 피벗'!A:SF,6,FALSE),0) -> 81 | D5: =IFERROR(ROUNDDOWN(C5/B5,0),"") -> 2 | E5: 검단 | F5: =IFERROR(C5-(D5*B5),"") -> 21
A6: BGF로지스서인천1 | B6: =$B$4 -> 30 | C6: =IFERROR(VLOOKUP(A6,'참조은 피벗'!A:SF,6,FALSE),0) -> 36 | D6: =IFERROR(ROUNDDOWN(C6/B6,0),"") -> 1 | E6: 서인천1 | F6: =IFERROR(C6-(D6*B6),"") -> 6
A7: BGF로지스서인천2 | B7: =$B$4 -> 30 | C7: =IFERROR(VLOOKUP(A7,'참조은 피벗'!A:SF,6,FALSE),0) -> 45 | D7: =IFERROR(ROUNDDOWN(C7/B7,0),"") -> 1 | E7: 서인천2 | F7: =IFERROR(C7-(D7*B7),"") -> 15
A8: BGF로지스진천 | B8: =$B$4 -> 30 | C8: =IFERROR(VLOOKUP(A8,'참조은 피벗'!A:SF,6,FALSE),0) -> 32 | D8: =IFERROR(ROUNDDOWN(C8/B8,0),"") -> 1 | E8: 진천 | F8: =IFERROR(C8-(D8*B8),"") -> 2
A9: BGF로지스안성 | B9: =$B$4 -> 30 | C9: =IFERROR(VLOOKUP(A9,'참조은 피벗'!A:SF,6,FALSE),0) -> 27 | D9: =IFERROR(ROUNDDOWN(C9/B9,0),"") -> 0 | E9: 안성 | F9: =IFERROR(C9-(D9*B9),"") -> 27
A10: BGF로지스아산 | B10: =$B$4 -> 30 | C10: =IFERROR(VLOOKUP(A10,'참조은 피벗'!A:SF,6,FALSE),0) -> 14 | D10: =IFERROR(ROUNDDOWN(C10/B10,0),"") -> 0 | E10: 아산 | F10: =IFERROR(C10-(D10*B10),"") -> 14
A11: 화인로지텍 | B11: =$B$4 -> 30 | C11: =IFERROR(VLOOKUP(A11,'참조은 피벗'!A:SF,6,FALSE),0) -> 32 | D11: =IFERROR(ROUNDDOWN(C11/B11,0),"") -> 1 | E11: 화인 | F11: =IFERROR(C11-(D11*B11),"") -> 2
A12: 아신 | B12: =$B$4 -> 30 | C12: =IFERROR(VLOOKUP(A12,'참조은 피벗'!A:SF,6,FALSE),0) -> 47 | D12: =IFERROR(ROUNDDOWN(C12/B12,0),"") -> 1 | E12: 아신 | F12: =IFERROR(C12-(D12*B12),"") -> 17
A13: 씨제이오산 | B13: =$B$4 -> 30 | C13: =IFERROR(VLOOKUP(A13,'참조은 피벗'!A:SF,6,FALSE),0) -> 54 | D13: =IFERROR(ROUNDDOWN(C13/B13,0),"") -> 1 | E13: 오산 | F13: =IFERROR(C13-(D13*B13),"") -> 24
A14: 씨제이군포 | B14: =$B$4 -> 30 | C14: =IFERROR(VLOOKUP(A14,'참조은 피벗'!A:SF,6,FALSE),0) -> 53 | D14: =IFERROR(ROUNDDOWN(C14/B14,0),"") -> 1 | E14: 군포 | F14: =IFERROR(C14-(D14*B14),"") -> 23
A15: BGF로지스광주 | B15: =$B$4 -> 30 | C15: =IFERROR(VLOOKUP(A15,'참조은 피벗'!A:SF,6,FALSE),0) -> 78 | D15: =IFERROR(ROUNDDOWN(C15/B15,0),"") -> 2 | E15: 광주 | F15: =IFERROR(C15-(D15*B15),"") -> 18
A16: BGF로지스양주 | B16: =$B$4 -> 30 | C16: =IFERROR(VLOOKUP(A16,'참조은 피벗'!A:SF,6,FALSE),0) -> 16 | D16: =IFERROR(ROUNDDOWN(C16/B16,0),"") -> 0 | E16: 양주 | F16: =IFERROR(C16-(D16*B16),"") -> 16
... A18: 동부로지스 | B18: =$B$4 -> 30 | C18: =IFERROR(VLOOKUP(A18,'참조은 피벗'!A:SF,6,FALSE),0) -> 20 | D18: =IFERROR(ROUNDDOWN(C18/B18,0),"") -> 0 | E18: 동부 | F18: =IFERROR(C18-(D18*B18),"") -> 20
A20: 수도권 합계 | B20: =$B$4 -> 30 | C20: =SUM(C4:C18) -> 554 | D20: =IFERROR(ROUNDDOWN(C20/B20,0),"") -> 18 | F20: =IFERROR(C20-(D20*B20),"") -> 14
A22: 엑소후레쉬양산 | B22: =$B$4 -> 30 | C22: =IFERROR(VLOOKUP(A22,'참조은 피벗'!A:SF,6,FALSE),0) -> 47 | D22: =IFERROR(ROUNDDOWN(C22/B22,0),"") -> 1 | E22: 양산 | F22: =IFERROR(C22-(D22*B22),"") -> 17
A23: 극동로지스 | B23: =$B$4 -> 30 | C23: =IFERROR(VLOOKUP(A23,'참조은 피벗'!A:SF,6,FALSE),0) -> 29 | D23: =IFERROR(ROUNDDOWN(C23/B23,0),"") -> 0 | E23: 극동 | F23: =IFERROR(C23-(D23*B23),"") -> 29
A24: 김해물류 | B24: =$B$4 -> 30 | C24: =IFERROR(VLOOKUP(A24,'참조은 피벗'!A:SF,6,FALSE),0) -> 0 | D24: =IFERROR(ROUNDDOWN(C24/B24,0),"") -> 0 | E24: 김해 | F24: =IFERROR(C24-(D24*B24),"") -> 0
A25: BGF로지스부산 | B25: =$B$4 -> 30 | C25: =IFERROR(VLOOKUP(A25,'참조은 피벗'!A:SF,6,FALSE),0) -> 34 | D25: =IFERROR(ROUNDDOWN(C25/B25,0),"") -> 1 | E25: 부산 | F25: =IFERROR(C25-(D25*B25),"") -> 4
A26: BGF로지스진주 | B26: =$B$4 -> 30 | C26: =IFERROR(VLOOKUP(A26,'참조은 피벗'!A:SF,6,FALSE),0) -> 15 | D26: =IFERROR(ROUNDDOWN(C26/B26,0),"") -> 0 | E26: 진주 | F26: =IFERROR(C26-(D26*B26),"") -> 15
A28: 경남(김해)합계 | B28: =$B$4 -> 30 | C28: =SUM(C22:C26) -> 125 | D28: =IFERROR(ROUNDDOWN(C28/B28,0),"") -> 4 | F28: =IFERROR(C28-(D28*B28),"") -> 5
A30: 씨제이경산 | B30: =$B$4 -> 30 | C30: =IFERROR(VLOOKUP(A30,'참조은 피벗'!A:SF,6,FALSE),0) -> 44 | D30: =IFERROR(ROUNDDOWN(C30/B30,0),"") -> 1 | E30: 경산 | F30: =IFERROR(C30-(D30*B30),"") -> 14
A31: BGF로지스대구 | B31: =$B$4 -> 30 | C31: =IFERROR(VLOOKUP(A31,'참조은 피벗'!A:SF,6,FALSE),0) -> 27 | D31: =IFERROR(ROUNDDOWN(C31/B31,0),"") -> 0 | E31: 대구 | F31: =IFERROR(C31-(D31*B31),"") -> 27
A33: 경북(칠곡)합계 | B33: =$B$4 -> 30 | C33: =SUM(C30:C31) -> 71 | D33: =IFERROR(ROUNDDOWN(C33/B33,0),"") -> 2 | F33: =IFERROR(C33-(D33*B33),"") -> 11
A35: BGF로지스나주 | B35: =$B$4 -> 30 | C35: =IFERROR(VLOOKUP(A35,'참조은 피벗'!A:SF,6,FALSE),0) -> 29 | D35: =IFERROR(ROUNDDOWN(C35/B35,0),"") -> 0 | E35: 나주 | F35: =IFERROR(C35-(D35*B35),"") -> 29
A36: 하이로지스 | B36: =$B$4 -> 30 | C36: =IFERROR(VLOOKUP(A36,'참조은 피벗'!A:SF,6,FALSE),0) -> 28 | D36: =IFERROR(ROUNDDOWN(C36/B36,0),"") -> 0 | E36: 하이 | F36: =IFERROR(C36-(D36*B36),"") -> 28
A37: 씨제이김제 | B37: =$B$4 -> 30 | C37: =IFERROR(VLOOKUP(A37,'참조은 피벗'!A:SF,6,FALSE),0) -> 15 | D37: =IFERROR(ROUNDDOWN(C37/B37,0),"") -> 0 | E37: 김제 | F37: =IFERROR(C37-(D37*B37),"") -> 15
A39: 호남권 합계 | B39: =$B$4 -> 30 | C39: =SUM(C35:C37) -> 72 | D39: =IFERROR(ROUNDDOWN(C39/B39,0),"") -> 2 | F39: =IFERROR(C39-(D39*B39),"") -> 12
A41: BGF로지스서귀포 | B41: =$B$4 -> 30 | C41: =IFERROR(VLOOKUP(A41,'참조은 피벗'!A:SF,6,FALSE),0) -> 9 | D41: =IFERROR(ROUNDDOWN(C41/B41,0),"") -> 0 | E41: 서귀포 | F41: =IFERROR(C41-(D41*B41),"") -> 9
A42: BGF로지스제주 | B42: =$B$4 -> 30 | C42: =IFERROR(VLOOKUP(A42,'참조은 피벗'!A:SF,6,FALSE),0) -> 8 | D42: =IFERROR(ROUNDDOWN(C42/B42,0),"") -> 0 | E42: 제주 | F42: =IFERROR(C42-(D42*B42),"") -> 8
A44: 제주권 합계 | B44: =$B$4 -> 30 | C44: =SUM(C41:C42) -> 17 | D44: =IFERROR(ROUNDDOWN(C44/B44,0),"") -> 0 | F44: =IFERROR(C44-(D44*B44),"") -> 17
A46: 총합계 | B46: =$B$4 -> 30 | C46: =SUM(C4:C18,C35:C37,C30:C31,C22:C26,C41:C42) -> 839 | D46: =IFERROR(ROUNDDOWN(C46/B46,0),"") -> 27 | F46: =IFERROR(C46-(D46*B46),"") -> 29 | G46: 소분박스 | H46: 소분낱개
A47: 총 박스/총 낱개수량 | B47: □ | D47: =SUM(D4:D18,D35:D37,D30:D31,D22:D26,D41:D42) -> 14 | F47: =SUM(F4:F18,F35:F37,F30:F31,F22:F26,F41:F42) -> 419 | G47: =IFERROR(ROUNDDOWN(F47/B35,0),"") -> 13 | H47: =IFERROR(F47-(G47*B35),"") -> 29
C48: =C20+C28+C33+C39+C44 -> 839 | H48: □
C49: =C48=C46 -> TRUE

Sheet 참조은)우유모찌롤케익
A2: =TODAY() -> 46314 | B2: 참조은 □
A3: 행 레이블 | B3: 입수 | C3: 참조은)우유모찌롤케익 | D3: 박스 | E3: 센터명 | F3: 낱개
A4: BGF로지스강릉 | B4: 45 | C4: =IFERROR(VLOOKUP(A4,'참조은 피벗'!A:SF,7,FALSE),0) -> 20 | D4: =IFERROR(ROUNDDOWN(C4/B4,0),"") -> 0 | E4: 강릉 | F4: =IFERROR(C4-(D4*B4),"") -> 20
A5: BGF로지스검단 | B5: =$B$4 -> 45 | C5: =IFERROR(VLOOKUP(A5,'참조은 피벗'!A:SF,7,FALSE),0) -> 266 | D5: =IFERROR(ROUNDDOWN(C5/B5,0),"") -> 5 | E5: 검단 | F5: =IFERROR(C5-(D5*B5),"") -> 41
A6: BGF로지스서인천1 | B6: =$B$4 -> 45 | C6: =IFERROR(VLOOKUP(A6,'참조은 피벗'!A:SF,7,FALSE),0) -> 141 | D6: =IFERROR(ROUNDDOWN(C6/B6,0),"") -> 3 | E6: 서인천1 | F6: =IFERROR(C6-(D6*B6),"") -> 6
A7: BGF로지스서인천2 | B7: =$B$4 -> 45 | C7: =IFERROR(VLOOKUP(A7,'참조은 피벗'!A:SF,7,FALSE),0) -> 109 | D7: =IFERROR(ROUNDDOWN(C7/B7,0),"") -> 2 | E7: 서인천2 | F7: =IFERROR(C7-(D7*B7),"") -> 19
A8: BGF로지스진천 | B8: =$B$4 -> 45 | C8: =IFERROR(VLOOKUP(A8,'참조은 피벗'!A:SF,7,FALSE),0) -> 87 | D8: =IFERROR(ROUNDDOWN(C8/B8,0),"") -> 1 | E8: 진천 | F8: =IFERROR(C8-(D8*B8),"") -> 42
A9: BGF로지스안성 | B9: =$B$4 -> 45 | C9: =IFERROR(VLOOKUP(A9,'참조은 피벗'!A:SF,7,FALSE),0) -> 68 | D9: =IFERROR(ROUNDDOWN(C9/B9,0),"") -> 1 | E9: 안성 | F9: =IFERROR(C9-(D9*B9),"") -> 23
A10: BGF로지스아산 | B10: =$B$4 -> 45 | C10: =IFERROR(VLOOKUP(A10,'참조은 피벗'!A:SF,7,FALSE),0) -> 65 | D10: =IFERROR(ROUNDDOWN(C10/B10,0),"") -> 1 | E10: 아산 | F10: =IFERROR(C10-(D10*B10),"") -> 20
A11: 화인로지텍 | B11: =$B$4 -> 45 | C11: =IFERROR(VLOOKUP(A11,'참조은 피벗'!A:SF,7,FALSE),0) -> 93 | D11: =IFERROR(ROUNDDOWN(C11/B11,0),"") -> 2 | E11: 화인 | F11: =IFERROR(C11-(D11*B11),"") -> 3
A12: 아신 | B12: =$B$4 -> 45 | C12: =IFERROR(VLOOKUP(A12,'참조은 피벗'!A:SF,7,FALSE),0) -> 145 | D12: =IFERROR(ROUNDDOWN(C12/B12,0),"") -> 3 | E12: 아신 | F12: =IFERROR(C12-(D12*B12),"") -> 10
A13: 씨제이오산 | B13: =$B$4 -> 45 | C13: =IFERROR(VLOOKUP(A13,'참조은 피벗'!A:SF,7,FALSE),0) -> 119 | D13: =IFERROR(ROUNDDOWN(C13/B13,0),"") -> 2 | E13: 오산 | F13: =IFERROR(C13-(D13*B13),"") -> 29
A14: 씨제이군포 | B14: =$B$4 -> 45 | C14: =IFERROR(VLOOKUP(A14,'참조은 피벗'!A:SF,7,FALSE),0) -> 172 | D14: =IFERROR(ROUNDDOWN(C14/B14,0),"") -> 3 | E14: 군포 | F14: =IFERROR(C14-(D14*B14),"") -> 37
A15: BGF로지스광주 | B15: =$B$4 -> 45 | C15: =IFERROR(VLOOKUP(A15,'참조은 피벗'!A:SF,7,FALSE),0) -> 210 | D15: =IFERROR(ROUNDDOWN(C15/B15,0),"") -> 4 | E15: 광주 | F15: =IFERROR(C15-(D15*B15),"") -> 30
A16: BGF로지스양주 | B16: =$B$4 -> 45 | C16: =IFERROR(VLOOKUP(A16,'참조은 피벗'!A:SF,7,FALSE),0) -> 46 | D16: =IFERROR(ROUNDDOWN(C16/B16,0),"") -> 1 | E16: 양주 | F16: =IFERROR(C16-(D16*B16),"") -> 1
... A18: 동부로지스 | B18: =$B$4 -> 45 | C18: =IFERROR(VLOOKUP(A18,'참조은 피벗'!A:SF,7,FALSE),0) -> 53 | D18: =IFERROR(ROUNDDOWN(C18/B18,0),"") -> 1 | E18: 동부 | F18: =IFERROR(C18-(D18*B18),"") -> 8
A20: 수도권 합계 | B20: =$B$4 -> 45 | C20: =SUM(C4:C18) -> 1638 | D20: =IFERROR(ROUNDDOWN(C20/B20,0),"") -> 36 | F20: =IFERROR(C20-(D20*B20),"") -> 18
A22: 엑소후레쉬양산 | B22: =$B$4 -> 45 | C22: =IFERROR(VLOOKUP(A22,'참조은 피벗'!A:SF,7,FALSE),0) -> 116 | D22: =IFERROR(ROUNDDOWN(C22/B22,0),"") -> 2 | E22: 양산 | F22: =IFERROR(C22-(D22*B22),"") -> 26
A23: 극동로지스 | B23: =$B$4 -> 45 | C23: =IFERROR(VLOOKUP(A23,'참조은 피벗'!A:SF,7,FALSE),0) -> 76 | D23: =IFERROR(ROUNDDOWN(C23/B23,0),"") -> 1 | E23: 극동 | F23: =IFERROR(C23-(D23*B23),"") -> 31
A24: 김해물류 | B24: =$B$4 -> 45 | C24: =IFERROR(VLOOKUP(A24,'참조은 피벗'!A:SF,7,FALSE),0) -> 0 | D24: =IFERROR(ROUNDDOWN(C24/B24,0),"") -> 0 | E24: 김해 | F24: =IFERROR(C24-(D24*B24),"") -> 0
A25: BGF로지스부산 | B25: =$B$4 -> 45 | C25: =IFERROR(VLOOKUP(A25,'참조은 피벗'!A:SF,7,FALSE),0) -> 167 | D25: =IFERROR(ROUNDDOWN(C25/B25,0),"") -> 3 | E25: 부산 | F25: =IFERROR(C25-(D25*B25),"") -> 32
A26: BGF로지스진주 | B26: =$B$4 -> 45 | C26: =IFERROR(VLOOKUP(A26,'참조은 피벗'!A:SF,7,FALSE),0) -> 61 | D26: =IFERROR(ROUNDDOWN(C26/B26,0),"") -> 1 | E26: 진주 | F26: =IFERROR(C26-(D26*B26),"") -> 16
A28: 경남(김해)합계 | B28: =$B$4 -> 45 | C28: =SUM(C22:C26) -> 420 | D28: =IFERROR(ROUNDDOWN(C28/B28,0),"") -> 9 | F28: =IFERROR(C28-(D28*B28),"") -> 15
A30: 씨제이경산 | B30: =$B$4 -> 45 | C30: =IFERROR(VLOOKUP(A30,'참조은 피벗'!A:SF,7,FALSE),0) -> 88 | D30: =IFERROR(ROUNDDOWN(C30/B30,0),"") -> 1 | E30: 경산 | F30: =IFERROR(C30-(D30*B30),"") -> 43
A31: BGF로지스대구 | B31: =$B$4 -> 45 | C31: =IFERROR(VLOOKUP(A31,'참조은 피벗'!A:SF,7,FALSE),0) -> 84 | D31: =IFERROR(ROUNDDOWN(C31/B31,0),"") -> 1 | E31: 대구 | F31: =IFERROR(C31-(D31*B31),"") -> 39
A33: 경북(칠곡)합계 | B33: =$B$4 -> 45 | C33: =SUM(C30:C31) -> 172 | D33: =IFERROR(ROUNDDOWN(C33/B33,0),"") -> 3 | F33: =IFERROR(C33-(D33*B33),"") -> 37
A35: BGF로지스나주 | B35: =$B$4 -> 45 | C35: =IFERROR(VLOOKUP(A35,'참조은 피벗'!A:SF,7,FALSE),0) -> 104 | D35: =IFERROR(ROUNDDOWN(C35/B35,0),"") -> 2 | E35: 나주 | F35: =IFERROR(C35-(D35*B35),"") -> 14
A36: 하이로지스 | B36: =$B$4 -> 45 | C36: =IFERROR(VLOOKUP(A36,'참조은 피벗'!A:SF,7,FALSE),0) -> 69 | D36: =IFERROR(ROUNDDOWN(C36/B36,0),"") -> 1 | E36: 하이 | F36: =IFERROR(C36-(D36*B36),"") -> 24
A37: 씨제이김제 | B37: =$B$4 -> 45 | C37: =IFERROR(VLOOKUP(A37,'참조은 피벗'!A:SF,7,FALSE),0) -> 59 | D37: =IFERROR(ROUNDDOWN(C37/B37,0),"") -> 1 | E37: 김제 | F37: =IFERROR(C37-(D37*B37),"") -> 14
A39: 호남권 합계 | B39: =$B$4 -> 45 | C39: =SUM(C35:C37) -> 232 | D39: =IFERROR(ROUNDDOWN(C39/B39,0),"") -> 5 | F39: =IFERROR(C39-(D39*B39),"") -> 7
A41: BGF로지스서귀포 | B41: =$B$4 -> 45 | C41: =IFERROR(VLOOKUP(A41,'참조은 피벗'!A:SF,7,FALSE),0) -> 24 | D41: =IFERROR(ROUNDDOWN(C41/B41,0),"") -> 0 | E41: 서귀포 | F41: =IFERROR(C41-(D41*B41),"") -> 24
A42: BGF로지스제주 | B42: =$B$4 -> 45 | C42: =IFERROR(VLOOKUP(A42,'참조은 피벗'!A:SF,7,FALSE),0) -> 31 | D42: =IFERROR(ROUNDDOWN(C42/B42,0),"") -> 0 | E42: 제주 | F42: =IFERROR(C42-(D42*B42),"") -> 31
A44: 제주권 합계 | B44: =$B$4 -> 45 | C44: =SUM(C41:C42) -> 55 | D44: =IFERROR(ROUNDDOWN(C44/B44,0),"") -> 1 | F44: =IFERROR(C44-(D44*B44),"") -> 10
A46: 총합계 | B46: =$B$4 -> 45 | C46: =SUM(C4:C18,C35:C37,C30:C31,C22:C26,C41:C42) -> 2517 | D46: =IFERROR(ROUNDDOWN(C46/B46,0),"") -> 55 | F46: =IFERROR(C46-(D46*B46),"") -> 42 | G46: 소분박스 | H46: 소분낱개
A47: 총 박스/총 낱개수량 | B47: □ | D47: =SUM(D4:D18,D35:D37,D30:D31,D22:D26,D41:D42) -> 42 | F47: =SUM(F4:F18,F35:F37,F30:F31,F22:F26,F41:F42) -> 627 | G47: =IFERROR(ROUNDDOWN(F47/B35,0),"") -> 13 | H47: =IFERROR(F47-(G47*B35),"") -> 42
C48: =C20+C28+C33+C39+C44 -> 2517 | H48: □
C49: =C48=C46 -> TRUE

Sheet 참조은)초코모찌롤케익
A2: =TODAY() -> 46314 | B2: 참조은 □
A3: 행 레이블 | B3: 입수 | C3: 참조은)초코모찌롤케익 | D3: 박스 | E3: 센터명 | F3: 낱개
A4: BGF로지스강릉 | B4: 45 | C4: =IFERROR(VLOOKUP(A4,'참조은 피벗'!A:SF,8,FALSE),0) -> 22 | D4: =IFERROR(ROUNDDOWN(C4/B4,0),"") -> 0 | E4: 강릉 | F4: =IFERROR(C4-(D4*B4),"") -> 22
A5: BGF로지스검단 | B5: =$B$4 -> 45 | C5: =IFERROR(VLOOKUP(A5,'참조은 피벗'!A:SF,8,FALSE),0) -> 235 | D5: =IFERROR(ROUNDDOWN(C5/B5,0),"") -> 5 | E5: 검단 | F5: =IFERROR(C5-(D5*B5),"") -> 10
A6: BGF로지스서인천1 | B6: =$B$4 -> 45 | C6: =IFERROR(VLOOKUP(A6,'참조은 피벗'!A:SF,8,FALSE),0) -> 111 | D6: =IFERROR(ROUNDDOWN(C6/B6,0),"") -> 2 | E6: 서인천1 | F6: =IFERROR(C6-(D6*B6),"") -> 21
A7: BGF로지스서인천2 | B7: =$B$4 -> 45 | C7: =IFERROR(VLOOKUP(A7,'참조은 피벗'!A:SF,8,FALSE),0) -> 116 | D7: =IFERROR(ROUNDDOWN(C7/B7,0),"") -> 2 | E7: 서인천2 | F7: =IFERROR(C7-(D7*B7),"") -> 26
A8: BGF로지스진천 | B8: =$B$4 -> 45 | C8: =IFERROR(VLOOKUP(A8,'참조은 피벗'!A:SF,8,FALSE),0) -> 89 | D8: =IFERROR(ROUNDDOWN(C8/B8,0),"") -> 1 | E8: 진천 | F8: =IFERROR(C8-(D8*B8),"") -> 44
A9: BGF로지스안성 | B9: =$B$4 -> 45 | C9: =IFERROR(VLOOKUP(A9,'참조은 피벗'!A:SF,8,FALSE),0) -> 80 | D9: =IFERROR(ROUNDDOWN(C9/B9,0),"") -> 1 | E9: 안성 | F9: =IFERROR(C9-(D9*B9),"") -> 35
A10: BGF로지스아산 | B10: =$B$4 -> 45 | C10: =IFERROR(VLOOKUP(A10,'참조은 피벗'!A:SF,8,FALSE),0) -> 70 | D10: =IFERROR(ROUNDDOWN(C10/B10,0),"") -> 1 | E10: 아산 | F10: =IFERROR(C10-(D10*B10),"") -> 25
A11: 화인로지텍 | B11: =$B$4 -> 45 | C11: =IFERROR(VLOOKUP(A11,'참조은 피벗'!A:SF,8,FALSE),0) -> 95 | D11: =IFERROR(ROUNDDOWN(C11/B11,0),"") -> 2 | E11: 화인 | F11: =IFERROR(C11-(D11*B11),"") -> 5
A12: 아신 | B12: =$B$4 -> 45 | C12: =IFERROR(VLOOKUP(A12,'참조은 피벗'!A:SF,8,FALSE),0) -> 116 | D12: =IFERROR(ROUNDDOWN(C12/B12,0),"") -> 2 | E12: 아신 | F12: =IFERROR(C12-(D12*B12),"") -> 26
A13: 씨제이오산 | B13: =$B$4 -> 45 | C13: =IFERROR(VLOOKUP(A13,'참조은 피벗'!A:SF,8,FALSE),0) -> 104 | D13: =IFERROR(ROUNDDOWN(C13/B13,0),"") -> 2 | E13: 오산 | F13: =IFERROR(C13-(D13*B13),"") -> 14
A14: 씨제이군포 | B14: =$B$4 -> 45 | C14: =IFERROR(VLOOKUP(A14,'참조은 피벗'!A:SF,8,FALSE),0) -> 129 | D14: =IFERROR(ROUNDDOWN(C14/B14,0),"") -> 2 | E14: 군포 | F14: =IFERROR(C14-(D14*B14),"") -> 39
A15: BGF로지스광주 | B15: =$B$4 -> 45 | C15: =IFERROR(VLOOKUP(A15,'참조은 피벗'!A:SF,8,FALSE),0) -> 185 | D15: =IFERROR(ROUNDDOWN(C15/B15,0),"") -> 4 | E15: 광주 | F15: =IFERROR(C15-(D15*B15),"") -> 5
A16: BGF로지스양주 | B16: =$B$4 -> 45 | C16: =IFERROR(VLOOKUP(A16,'참조은 피벗'!A:SF,8,FALSE),0) -> 56 | D16: =IFERROR(ROUNDDOWN(C16/B16,0),"") -> 1 | E16: 양주 | F16: =IFERROR(C16-(D16*B16),"") -> 11
... A18: 동부로지스 | B18: =$B$4 -> 45 | C18: =IFERROR(VLOOKUP(A18,'참조은 피벗'!A:SF,8,FALSE),0) -> 54 | D18: =IFERROR(ROUNDDOWN(C18/B18,0),"") -> 1 | E18: 동부 | F18: =IFERROR(C18-(D18*B18),"") -> 9
A20: 수도권 합계 | B20: =$B$4 -> 45 | C20: =SUM(C4:C18) -> 1518 | D20: =IFERROR(ROUNDDOWN(C20/B20,0),"") -> 33 | F20: =IFERROR(C20-(D20*B20),"") -> 33
A22: 엑소후레쉬양산 | B22: =$B$4 -> 45 | C22: =IFERROR(VLOOKUP(A22,'참조은 피벗'!A:SF,8,FALSE),0) -> 120 | D22: =IFERROR(ROUNDDOWN(C22/B22,0),"") -> 2 | E22: 양산 | F22: =IFERROR(C22-(D22*B22),"") -> 30
A23: 극동로지스 | B23: =$B$4 -> 45 | C23: =IFERROR(VLOOKUP(A23,'참조은 피벗'!A:SF,8,FALSE),0) -> 66 | D23: =IFERROR(ROUNDDOWN(C23/B23,0),"") -> 1 | E23: 극동 | F23: =IFERROR(C23-(D23*B23),"") -> 21
A24: 김해물류 | B24: =$B$4 -> 45 | C24: =IFERROR(VLOOKUP(A24,'참조은 피벗'!A:SF,8,FALSE),0) -> 0 | D24: =IFERROR(ROUNDDOWN(C24/B24,0),"") -> 0 | E24: 김해 | F24: =IFERROR(C24-(D24*B24),"") -> 0
A25: BGF로지스부산 | B25: =$B$4 -> 45 | C25: =IFERROR(VLOOKUP(A25,'참조은 피벗'!A:SF,8,FALSE),0) -> 102 | D25: =IFERROR(ROUNDDOWN(C25/B25,0),"") -> 2 | E25: 부산 | F25: =IFERROR(C25-(D25*B25),"") -> 12
A26: BGF로지스진주 | B26: =$B$4 -> 45 | C26: =IFERROR(VLOOKUP(A26,'참조은 피벗'!A:SF,8,FALSE),0) -> 45 | D26: =IFERROR(ROUNDDOWN(C26/B26,0),"") -> 1 | E26: 진주 | F26: =IFERROR(C26-(D26*B26),"") -> 0
A28: 경남(김해)합계 | B28: =$B$4 -> 45 | C28: =SUM(C22:C26) -> 333 | D28: =IFERROR(ROUNDDOWN(C28/B28,0),"") -> 7 | F28: =IFERROR(C28-(D28*B28),"") -> 18
A30: 씨제이경산 | B30: =$B$4 -> 45 | C30: =IFERROR(VLOOKUP(A30,'참조은 피벗'!A:SF,8,FALSE),0) -> 93 | D30: =IFERROR(ROUNDDOWN(C30/B30,0),"") -> 2 | E30: 경산 | F30: =IFERROR(C30-(D30*B30),"") -> 3
A31: BGF로지스대구 | B31: =$B$4 -> 45 | C31: =IFERROR(VLOOKUP(A31,'참조은 피벗'!A:SF,8,FALSE),0) -> 77 | D31: =IFERROR(ROUNDDOWN(C31/B31,0),"") -> 1 | E31: 대구 | F31: =IFERROR(C31-(D31*B31),"") -> 32
A33: 경북(칠곡)합계 | B33: =$B$4 -> 45 | C33: =SUM(C30:C31) -> 170 | D33: =IFERROR(ROUNDDOWN(C33/B33,0),"") -> 3 | F33: =IFERROR(C33-(D33*B33),"") -> 35
A35: BGF로지스나주 | B35: =$B$4 -> 45 | C35: =IFERROR(VLOOKUP(A35,'참조은 피벗'!A:SF,8,FALSE),0) -> 103 | D35: =IFERROR(ROUNDDOWN(C35/B35,0),"") -> 2 | E35: 나주 | F35: =IFERROR(C35-(D35*B35),"") -> 13
A36: 하이로지스 | B36: =$B$4 -> 45 | C36: =IFERROR(VLOOKUP(A36,'참조은 피벗'!A:SF,8,FALSE),0) -> 70 | D36: =IFERROR(ROUNDDOWN(C36/B36,0),"") -> 1 | E36: 하이 | F36: =IFERROR(C36-(D36*B36),"") -> 25
A37: 씨제이김제 | B37: =$B$4 -> 45 | C37: =IFERROR(VLOOKUP(A37,'참조은 피벗'!A:SF,8,FALSE),0) -> 61 | D37: =IFERROR(ROUNDDOWN(C37/B37,0),"") -> 1 | E37: 김제 | F37: =IFERROR(C37-(D37*B37),"") -> 16
A39: 호남권 합계 | B39: =$B$4 -> 45 | C39: =SUM(C35:C37) -> 234 | D39: =IFERROR(ROUNDDOWN(C39/B39,0),"") -> 5 | F39: =IFERROR(C39-(D39*B39),"") -> 9
A41: BGF로지스서귀포 | B41: =$B$4 -> 45 | C41: =IFERROR(VLOOKUP(A41,'참조은 피벗'!A:SF,8,FALSE),0) -> 16 | D41: =IFERROR(ROUNDDOWN(C41/B41,0),"") -> 0 | E41: 서귀포 | F41: =IFERROR(C41-(D41*B41),"") -> 16
A42: BGF로지스제주 | B42: =$B$4 -> 45 | C42: =IFERROR(VLOOKUP(A42,'참조은 피벗'!A:SF,8,FALSE),0) -> 31 | D42: =IFERROR(ROUNDDOWN(C42/B42,0),"") -> 0 | E42: 제주 | F42: =IFERROR(C42-(D42*B42),"") -> 31
A44: 제주권 합계 | B44: =$B$4 -> 45 | C44: =SUM(C41:C42) -> 47 | D44: =IFERROR(ROUNDDOWN(C44/B44,0),"") -> 1 | F44: =IFERROR(C44-(D44*B44),"") -> 2
A46: 총합계 | B46: =$B$4 -> 45 | C46: =SUM(C4:C18,C35:C37,C30:C31,C22:C26,C41:C42) -> 2302 | D46: =IFERROR(ROUNDDOWN(C46/B46,0),"") -> 51 | F46: =IFERROR(C46-(D46*B46),"") -> 7 | G46: 소분박스 | H46: 소분낱개
A47: 총 박스/총 낱개수량 | B47: □ | D47: =SUM(D4:D18,D35:D37,D30:D31,D22:D26,D41:D42) -> 40 | F47: =SUM(F4:F18,F35:F37,F30:F31,F22:F26,F41:F42) -> 502 | G47: =IFERROR(ROUNDDOWN(F47/B35,0),"") -> 11 | H47: =IFERROR(F47-(G47*B35),"") -> 7
C48: =C20+C28+C33+C39+C44 -> 2302 | H48: □
C49: =C48=C46 -> TRUE

Sheet 참조은 피벗(냉장 베이글)
A1: 10/19 | B1: 열 레이블
A2: 행 레이블 | B2: KH)뉴욕베이글블루베리 | C2: KH)뉴욕베이글쿠앤크 | D2: KH)뉴욕베이글플레인 | E2: kH)뉴욕베이글피넛버터 | F2: 총합계
A3: BGF로지스강릉 | B3: 10 | C3: 4 | D3: 2 | E3: 2 | F3: 18
A4: BGF로지스검단 | B4: 27 | C4: 13 | D4: 20 | E4: 5 | F4: 65
A5: BGF로지스광주 | B5: 18 | C5: 10 | D5: 17 | E5: 5 | F5: 50
A6: BGF로지스나주 | B6: 7 | C6: 4 | D6: 11 | E6: 8 | F6: 30
A7: BGF로지스대구 | B7: 6 | C7: 8 | D7: 14 | E7: 10 | F7: 38
A8: BGF로지스부산 | B8: 21 | D8: 11 | E8: 12 | F8: 44
A9: BGF로지스서귀포 | B9: 6 | C9: 1 | D9: 6 | E9: 2 | F9: 15
A10: BGF로지스서인천1 | B10: 8 | C10: 5 | D10: 4 | E10: 3 | F10: 20
A11: BGF로지스서인천2 | B11: 9 | C11: 7 | D11: 8 | E11: 1 | F11: 25
A12: BGF로지스아산 | B12: 13 | C12: 7 | D12: 10 | E12: 5 | F12: 35
A13: BGF로지스안성 | B13: 12 | C13: 14 | D13: 14 | E13: 6 | F13: 46
A14: BGF로지스양주 | B14: 1 | C14: 3 | D14: 8 | E14: 5 | F14: 17
A15: BGF로지스제주 | B15: 5 | C15: 4 | D15: 5 | E15: 2 | F15: 16
A16: BGF로지스진주 | B16: 5 | C16: 5 | D16: 8 | E16: 7 | F16: 25
A17: BGF로지스진천 | B17: 13 | C17: 8 | D17: 10 | E17: 8 | F17: 39
A18: BGF로지스화성 | B18: 8 | C18: 6 | D18: 13 | E18: 12 | F18: 39
A19: 극동로지스 | B19: 7 | C19: 7 | D19: 17 | E19: 13 | F19: 44
A20: 동부로지스 | B20: 11 | C20: 9 | D20: 10 | E20: 5 | F20: 35
... A29: 총합계 | B29: 288 | C29: 158 | D29: 280 | E29: 176 | F29: 902

Sheet KH)뉴욕베이글블루베리
A2: =TODAY() -> 46314 | B2: 참조은 □
A3: 행 레이블 | B3: 입수 | C3: KH)뉴욕베이글블루베리 | D3: 박스 | E3: 센터명 | F3: 낱개
A4: BGF로지스강릉 | B4: 48 | C4: =IFERROR(VLOOKUP(A4,'참조은 피벗(냉장 베이글)'!A:SD,2,FALSE),0) -> 10 | D4: =IFERROR(ROUNDDOWN(C4/B4,0),"") -> 0 | E4: 강릉 | F4: =IFERROR(C4-(D4*B4),"") -> 10
A5: BGF로지스검단 | B5: =$B$4 -> 48 | C5: =IFERROR(VLOOKUP(A5,'참조은 피벗(냉장 베이글)'!A:SD,2,FALSE),0) -> 27 | D5: =IFERROR(ROUNDDOWN(C5/B5,0),"") -> 0 | E5: 검단 | F5: =IFERROR(C5-(D5*B5),"") -> 27
A6: BGF로지스서인천1 | B6: =$B$4 -> 48 | C6: =IFERROR(VLOOKUP(A6,'참조은 피벗(냉장 베이글)'!A:SD,2,FALSE),0) -> 8 | D6: =IFERROR(ROUNDDOWN(C6/B6,0),"") -> 0 | E6: 서인천1 | F6: =IFERROR(C6-(D6*B6),"") -> 8
A7: BGF로지스서인천2 | B7: =$B$4 -> 48 | C7: =IFERROR(VLOOKUP(A7,'참조은 피벗(냉장 베이글)'!A:SD,2,FALSE),0) -> 9 | D7: =IFERROR(ROUNDDOWN(C7/B7,0),"") -> 0 | E7: 서인천2 | F7: =IFERROR(C7-(D7*B7),"") -> 9
A8: BGF로지스진천 | B8: =$B$4 -> 48 | C8: =IFERROR(VLOOKUP(A8,'참조은 피벗(냉장 베이글)'!A:SD,2,FALSE),0) -> 13 | D8: =IFERROR(ROUNDDOWN(C8/B8,0),"") -> 0 | E8: 진천 | F8: =IFERROR(C8-(D8*B8),"") -> 13
A9: BGF로지스안성 | B9: =$B$4 -> 48 | C9: =IFERROR(VLOOKUP(A9,'참조은 피벗(냉장 베이글)'!A:SD,2,FALSE),0) -> 12 | D9: =IFERROR(ROUNDDOWN(C9/B9,0),"") -> 0 | E9: 안성 | F9: =IFERROR(C9-(D9*B9),"") -> 12
A10: BGF로지스아산 | B10: =$B$4 -> 48 | C10: =IFERROR(VLOOKUP(A10,'참조은 피벗(냉장 베이글)'!A:SD,2,FALSE),0) -> 13 | D10: =IFERROR(ROUNDDOWN(C10/B10,0),"") -> 0 | E10: 아산 | F10: =IFERROR(C10-(D10*B10),"") -> 13
A11: 화인로지텍 | B11: =$B$4 -> 48 | C11: =IFERROR(VLOOKUP(A11,'참조은 피벗(냉장 베이글)'!A:SD,2,FALSE),0) -> 13 | D11: =IFERROR(ROUNDDOWN(C11/B11,0),"") -> 0 | E11: 화인 | F11: =IFERROR(C11-(D11*B11),"") -> 13
A12: 아신 | B12: =$B$4 -> 48 | C12: =IFERROR(VLOOKUP(A12,'참조은 피벗(냉장 베이글)'!A:SD,2,FALSE),0) -> 10 | D12: =IFERROR(ROUNDDOWN(C12/B12,0),"") -> 0 | E12: 아신 | F12: =IFERROR(C12-(D12*B12),"") -> 10
A13: 씨제이오산 | B13: =$B$4 -> 48 | C13: =IFERROR(VLOOKUP(A13,'참조은 피벗(냉장 베이글)'!A:SD,2,FALSE),0) -> 8 | D13: =IFERROR(ROUNDDOWN(C13/B13,0),"") -> 0 | E13: 오산 | F13: =IFERROR(C13-(D13*B13),"") -> 8
A14: 씨제이군포 | B14: =$B$4 -> 48 | C14: =IFERROR(VLOOKUP(A14,'참조은 피벗(냉장 베이글)'!A:SD,2,FALSE),0) -> 25 | D14: =IFERROR(ROUNDDOWN(C14/B14,0),"") -> 0 | E14: 군포 | F14: =IFERROR(C14-(D14*B14),"") -> 25
A15: BGF로지스광주 | B15: =$B$4 -> 48 | C15: =IFERROR(VLOOKUP(A15,'참조은 피벗(냉장 베이글)'!A:SD,2,FALSE),0) -> 18 | D15: =IFERROR(ROUNDDOWN(C15/B15,0),"") -> 0 | E15: 광주 | F15: =IFERROR(C15-(D15*B15),"") -> 18
A16: BGF로지스양주 | B16: =$B$4 -> 48 | C16: =IFERROR(VLOOKUP(A16,'참조은 피벗(냉장 베이글)'!A:SD,2,FALSE),0) -> 1 | D16: =IFERROR(ROUNDDOWN(C16/B16,0),"") -> 0 | E16: 양주 | F16: =IFERROR(C16-(D16*B16),"") -> 1
... A18: 동부로지스 | B18: =$B$4 -> 48 | C18: =IFERROR(VLOOKUP(A18,'참조은 피벗(냉장 베이글)'!A:SD,2,FALSE),0) -> 11 | D18: =IFERROR(ROUNDDOWN(C18/B18,0),"") -> 0 | E18: 동부 | F18: =IFERROR(C18-(D18*B18),"") -> 11
A20: 수도권 합계 | B20: =$B$4 -> 48 | C20: =SUM(C4:C18) -> 186 | D20: =IFERROR(ROUNDDOWN(C20/B20,0),"") -> 3 | F20: =IFERROR(C20-(D20*B20),"") -> 42
A22: 엑소후레쉬양산 | B22: =$B$4 -> 48 | C22: =IFERROR(VLOOKUP(A22,'참조은 피벗(냉장 베이글)'!A:SD,2,FALSE),0) -> 17 | D22: =IFERROR(ROUNDDOWN(C22/B22,0),"") -> 0 | E22: 양산 | F22: =IFERROR(C22-(D22*B22),"") -> 17
A23: 극동로지스 | B23: =$B$4 -> 48 | C23: =IFERROR(VLOOKUP(A23,'참조은 피벗(냉장 베이글)'!A:SD,2,FALSE),0) -> 7 | D23: =IFERROR(ROUNDDOWN(C23/B23,0),"") -> 0 | E23: 극동 | F23: =IFERROR(C23-(D23*B23),"") -> 7
A24: 김해물류 | B24: =$B$4 -> 48 | C24: =IFERROR(VLOOKUP(A24,'참조은 피벗(냉장 베이글)'!A:SD,2,FALSE),0) -> 0 | D24: =IFERROR(ROUNDDOWN(C24/B24,0),"") -> 0 | E24: 김해 | F24: =IFERROR(C24-(D24*B24),"") -> 0
A25: BGF로지스부산 | B25: =$B$4 -> 48 | C25: =IFERROR(VLOOKUP(A25,'참조은 피벗(냉장 베이글)'!A:SD,2,FALSE),0) -> 21 | D25: =IFERROR(ROUNDDOWN(C25/B25,0),"") -> 0 | E25: 부산 | F25: =IFERROR(C25-(D25*B25),"") -> 21
A26: BGF로지스진주 | B26: =$B$4 -> 48 | C26: =IFERROR(VLOOKUP(A26,'참조은 피벗(냉장 베이글)'!A:SD,2,FALSE),0) -> 5 | D26: =IFERROR(ROUNDDOWN(C26/B26,0),"") -> 0 | E26: 진주 | F26: =IFERROR(C26-(D26*B26),"") -> 5
A28: 경남(김해)합계 | B28: =$B$4 -> 48 | C28: =SUM(C22:C26) -> 50 | D28: =IFERROR(ROUNDDOWN(C28/B28,0),"") -> 1 | F28: =IFERROR(C28-(D28*B28),"") -> 2
A30: 씨제이경산 | B30: =$B$4 -> 48 | C30: =IFERROR(VLOOKUP(A30,'참조은 피벗(냉장 베이글)'!A:SD,2,FALSE),0) -> 11 | D30: =IFERROR(ROUNDDOWN(C30/B30,0),"") -> 0 | E30: 경산 | F30: =IFERROR(C30-(D30*B30),"") -> 11
A31: BGF로지스대구 | B31: =$B$4 -> 48 | C31: =IFERROR(VLOOKUP(A31,'참조은 피벗(냉장 베이글)'!A:SD,2,FALSE),0) -> 6 | D31: =IFERROR(ROUNDDOWN(C31/B31,0),"") -> 0 | E31: 대구 | F31: =IFERROR(C31-(D31*B31),"") -> 6
A33: 경북(칠곡)합계 | B33: =$B$4 -> 48 | C33: =SUM(C30:C31) -> 17 | D33: =IFERROR(ROUNDDOWN(C33/B33,0),"") -> 0 | F33: =IFERROR(C33-(D33*B33),"") -> 17
A35: BGF로지스나주 | B35: =$B$4 -> 48 | C35: =IFERROR(VLOOKUP(A35,'참조은 피벗(냉장 베이글)'!A:SD,2,FALSE),0) -> 7 | D35: =IFERROR(ROUNDDOWN(C35/B35,0),"") -> 0 | E35: 나주 | F35: =IFERROR(C35-(D35*B35),"") -> 7
A36: 하이로지스 | B36: =$B$4 -> 48 | C36: =IFERROR(VLOOKUP(A36,'참조은 피벗(냉장 베이글)'!A:SD,2,FALSE),0) -> 8 | D36: =IFERROR(ROUNDDOWN(C36/B36,0),"") -> 0 | E36: 하이 | F36: =IFERROR(C36-(D36*B36),"") -> 8
A37: 씨제이김제 | B37: =$B$4 -> 48 | C37: =IFERROR(VLOOKUP(A37,'참조은 피벗(냉장 베이글)'!A:SD,2,FALSE),0) -> 9 | D37: =IFERROR(ROUNDDOWN(C37/B37,0),"") -> 0 | E37: 김제 | F37: =IFERROR(C37-(D37*B37),"") -> 9
A39: 호남권 합계 | B39: =$B$4 -> 48 | C39: =SUM(C35:C37) -> 24 | D39: =IFERROR(ROUNDDOWN(C39/B39,0),"") -> 0 | F39: =IFERROR(C39-(D39*B39),"") -> 24
A41: BGF로지스서귀포 | B41: =$B$4 -> 48 | C41: =IFERROR(VLOOKUP(A41,'참조은 피벗(냉장 베이글)'!A:SD,2,FALSE),0) -> 6 | D41: =IFERROR(ROUNDDOWN(C41/B41,0),"") -> 0 | E41: 서귀포 | F41: =IFERROR(C41-(D41*B41),"") -> 6
A42: BGF로지스제주 | B42: =$B$4 -> 48 | C42: =IFERROR(VLOOKUP(A42,'참조은 피벗(냉장 베이글)'!A:SD,2,FALSE),0) -> 5 | D42: =IFERROR(ROUNDDOWN(C42/B42,0),"") -> 0 | E42: 제주 | F42: =IFERROR(C42-(D42*B42),"") -> 5
A44: 제주권 합계 | B44: =$B$4 -> 48 | C44: =SUM(C41:C42) -> 11 | D44: =IFERROR(ROUNDDOWN(C44/B44,0),"") -> 0 | F44: =IFERROR(C44-(D44*B44),"") -> 11
A46: 총합계 | B46: =$B$4 -> 48 | C46: =SUM(C4:C18,C35:C37,C30:C31,C22:C26,C41:C42) -> 288 | D46: =IFERROR(ROUNDDOWN(C46/B46,0),"") -> 6 | F46: =IFERROR(C46-(D46*B46),"") -> 0 | G46: 소분박스 | H46: 소분낱개
A47: 총 박스/총 낱개수량 | B47: □ | D47: =SUM(D4:D18,D35:D37,D30:D31,D22:D26,D41:D42) -> 0 | F47: =SUM(F4:F18,F35:F37,F30:F31,F22:F26,F41:F42) -> 288 | G47: =IFERROR(ROUNDDOWN(F47/B35,0),"") -> 6 | H47: =IFERROR(F47-(G47*B35),"") -> 0
C48: =C20+C28+C33+C39+C44 -> 288 | H48: □
C49: =C48=C46 -> TRUE

Sheet KH)뉴욕베이글쿠앤크
A2: =TODAY() -> 46314 | B2: 참조은 □
A3: 행 레이블 | B3: 입수 | C3: KH)뉴욕베이글쿠앤크 | D3: 박스 | E3: 센터명 | F3: 낱개
A4: BGF로지스강릉 | B4: 48 | C4: =IFERROR(VLOOKUP(A4,'참조은 피벗(냉장 베이글)'!A:SD,3,FALSE),0) -> 4 | D4: =IFERROR(ROUNDDOWN(C4/B4,0),"") -> 0 | E4: 강릉 | F4: =IFERROR(C4-(D4*B4),"") -> 4
A5: BGF로지스검단 | B5: =$B$4 -> 48 | C5: =IFERROR(VLOOKUP(A5,'참조은 피벗(냉장 베이글)'!A:SD,3,FALSE),0) -> 13 | D5: =IFERROR(ROUNDDOWN(C5/B5,0),"") -> 0 | E5: 검단 | F5: =IFERROR(C5-(D5*B5),"") -> 13
A6: BGF로지스서인천1 | B6: =$B$4 -> 48 | C6: =IFERROR(VLOOKUP(A6,'참조은 피벗(냉장 베이글)'!A:SD,3,FALSE),0) -> 5 | D6: =IFERROR(ROUNDDOWN(C6/B6,0),"") -> 0 | E6: 서인천1 | F6: =IFERROR(C6-(D6*B6),"") -> 5
A7: BGF로지스서인천2 | B7: =$B$4 -> 48 | C7: =IFERROR(VLOOKUP(A7,'참조은 피벗(냉장 베이글)'!A:SD,3,FALSE),0) -> 7 | D7: =IFERROR(ROUNDDOWN(C7/B7,0),"") -> 0 | E7: 서인천2 | F7: =IFERROR(C7-(D7*B7),"") -> 7
A8: BGF로지스진천 | B8: =$B$4 -> 48 | C8: =IFERROR(VLOOKUP(A8,'참조은 피벗(냉장 베이글)'!A:SD,3,FALSE),0) -> 8 | D8: =IFERROR(ROUNDDOWN(C8/B8,0),"") -> 0 | E8: 진천 | F8: =IFERROR(C8-(D8*B8),"") -> 8
A9: BGF로지스안성 | B9: =$B$4 -> 48 | C9: =IFERROR(VLOOKUP(A9,'참조은 피벗(냉장 베이글)'!A:SD,3,FALSE),0) -> 14 | D9: =IFERROR(ROUNDDOWN(C9/B9,0),"") -> 0 | E9: 안성 | F9: =IFERROR(C9-(D9*B9),"") -> 14
A10: BGF로지스아산 | B10: =$B$4 -> 48 | C10: =IFERROR(VLOOKUP(A10,'참조은 피벗(냉장 베이글)'!A:SD,3,FALSE),0) -> 7 | D10: =IFERROR(ROUNDDOWN(C10/B10,0),"") -> 0 | E10: 아산 | F10: =IFERROR(C10-(D10*B10),"") -> 7
A11: 화인로지텍 | B11: =$B$4 -> 48 | C11: =IFERROR(VLOOKUP(A11,'참조은 피벗(냉장 베이글)'!A:SD,3,FALSE),0) -> 4 | D11: =IFERROR(ROUNDDOWN(C11/B11,0),"") -> 0 | E11: 화인 | F11: =IFERROR(C11-(D11*B11),"") -> 4
A12: 아신 | B12: =$B$4 -> 48 | C12: =IFERROR(VLOOKUP(A12,'참조은 피벗(냉장 베이글)'!A:SD,3,FALSE),0) -> 1 | D12: =IFERROR(ROUNDDOWN(C12/B12,0),"") -> 0 | E12: 아신 | F12: =IFERROR(C12-(D12*B12),"") -> 1
A13: 씨제이오산 | B13: =$B$4 -> 48 | C13: =IFERROR(VLOOKUP(A13,'참조은 피벗(냉장 베이글)'!A:SD,3,FALSE),0) -> 5 | D13: =IFERROR(ROUNDDOWN(C13/B13,0),"") -> 0 | E13: 오산 | F13: =IFERROR(C13-(D13*B13),"") -> 5
A14: 씨제이군포 | B14: =$B$4 -> 48 | C14: =IFERROR(VLOOKUP(A14,'참조은 피벗(냉장 베이글)'!A:SD,3,FALSE),0) -> 12 | D14: =IFERROR(ROUNDDOWN(C14/B14,0),"") -> 0 | E14: 군포 | F14: =IFERROR(C14-(D14*B14),"") -> 12
A15: BGF로지스광주 | B15: =$B$4 -> 48 | C15: =IFERROR(VLOOKUP(A15,'참조은 피벗(냉장 베이글)'!A:SD,3,FALSE),0) -> 10 | D15: =IFERROR(ROUNDDOWN(C15/B15,0),"") -> 0 | E15: 광주 | F15: =IFERROR(C15-(D15*B15),"") -> 10
A16: BGF로지스양주 | B16: =$B$4 -> 48 | C16: =IFERROR(VLOOKUP(A16,'참조은 피벗(냉장 베이글)'!A:SD,3,FALSE),0) -> 3 | D16: =IFERROR(ROUNDDOWN(C16/B16,0),"") -> 0 | E16: 양주 | F16: =IFERROR(C16-(D16*B16),"") -> 3
... A18: 동부로지스 | B18: =$B$4 -> 48 | C18: =IFERROR(VLOOKUP(A18,'참조은 피벗(냉장 베이글)'!A:SD,3,FALSE),0) -> 9 | D18: =IFERROR(ROUNDDOWN(C18/B18,0),"") -> 0 | E18: 동부 | F18: =IFERROR(C18-(D18*B18),"") -> 9
A20: 수도권 합계 | B20: =$B$4 -> 48 | C20: =SUM(C4:C18) -> 108 | D20: =IFERROR(ROUNDDOWN(C20/B20,0),"") -> 2 | F20: =IFERROR(C20-(D20*B20),"") -> 12
A22: 엑소후레쉬양산 | B22: =$B$4 -> 48 | C22: =IFERROR(VLOOKUP(A22,'참조은 피벗(냉장 베이글)'!A:SD,3,FALSE),0) -> 6 | D22: =IFERROR(ROUNDDOWN(C22/B22,0),"") -> 0 | E22: 양산 | F22: =IFERROR(C22-(D22*B22),"") -> 6
A23: 극동로지스 | B23: =$B$4 -> 48 | C23: =IFERROR(VLOOKUP(A23,'참조은 피벗(냉장 베이글)'!A:SD,3,FALSE),0) -> 7 | D23: =IFERROR(ROUNDDOWN(C23/B23,0),"") -> 0 | E23: 극동 | F23: =IFERROR(C23-(D23*B23),"") -> 7
A24: 김해물류 | B24: =$B$4 -> 48 | C24: =IFERROR(VLOOKUP(A24,'참조은 피벗(냉장 베이글)'!A:SD,3,FALSE),0) -> 0 | D24: =IFERROR(ROUNDDOWN(C24/B24,0),"") -> 0 | E24: 김해 | F24: =IFERROR(C24-(D24*B24),"") -> 0
A25: BGF로지스부산 | B25: =$B$4 -> 48 | C25: =IFERROR(VLOOKUP(A25,'참조은 피벗(냉장 베이글)'!A:SD,3,FALSE),0) -> 0 | D25: =IFERROR(ROUNDDOWN(C25/B25,0),"") -> 0 | E25: 부산 | F25: =IFERROR(C25-(D25*B25),"") -> 0
A26: BGF로지스진주 | B26: =$B$4 -> 48 | C26: =IFERROR(VLOOKUP(A26,'참조은 피벗(냉장 베이글)'!A:SD,3,FALSE),0) -> 5 | D26: =IFERROR(ROUNDDOWN(C26/B26,0),"") -> 0 | E26: 진주 | F26: =IFERROR(C26-(D26*B26),"") -> 5
A28: 경남(김해)합계 | B28: =$B$4 -> 48 | C28: =SUM(C22:C26) -> 18 | D28: =IFERROR(ROUNDDOWN(C28/B28,0),"") -> 0 | F28: =IFERROR(C28-(D28*B28),"") -> 18
A30: 씨제이경산 | B30: =$B$4 -> 48 | C30: =IFERROR(VLOOKUP(A30,'참조은 피벗(냉장 베이글)'!A:SD,3,FALSE),0) -> 4 | D30: =IFERROR(ROUNDDOWN(C30/B30,0),"") -> 0 | E30: 경산 | F30: =IFERROR(C30-(D30*B30),"") -> 4
A31: BGF로지스대구 | B31: =$B$4 -> 48 | C31: =IFERROR(VLOOKUP(A31,'참조은 피벗(냉장 베이글)'!A:SD,3,FALSE),0) -> 8 | D31: =IFERROR(ROUNDDOWN(C31/B31,0),"") -> 0 | E31: 대구 | F31: =IFERROR(C31-(D31*B31),"") -> 8
A33: 경북(칠곡)합계 | B33: =$B$4 -> 48 | C33: =SUM(C30:C31) -> 12 | D33: =IFERROR(ROUNDDOWN(C33/B33,0),"") -> 0 | F33: =IFERROR(C33-(D33*B33),"") -> 12
A35: BGF로지스나주 | B35: =$B$4 -> 48 | C35: =IFERROR(VLOOKUP(A35,'참조은 피벗(냉장 베이글)'!A:SD,3,FALSE),0) -> 4 | D35: =IFERROR(ROUNDDOWN(C35/B35,0),"") -> 0 | E35: 나주 | F35: =IFERROR(C35-(D35*B35),"") -> 4
A36: 하이로지스 | B36: =$B$4 -> 48 | C36: =IFERROR(VLOOKUP(A36,'참조은 피벗(냉장 베이글)'!A:SD,3,FALSE),0) -> 7 | D36: =IFERROR(ROUNDDOWN(C36/B36,0),"") -> 0 | E36: 하이 | F36: =IFERROR(C36-(D36*B36),"") -> 7
A37: 씨제이김제 | B37: =$B$4 -> 48 | C37: =IFERROR(VLOOKUP(A37,'참조은 피벗(냉장 베이글)'!A:SD,3,FALSE),0) -> 4 | D37: =IFERROR(ROUNDDOWN(C37/B37,0),"") -> 0 | E37: 김제 | F37: =IFERROR(C37-(D37*B37),"") -> 4
A39: 호남권 합계 | B39: =$B$4 -> 48 | C39: =SUM(C35:C37) -> 15 | D39: =IFERROR(ROUNDDOWN(C39/B39,0),"") -> 0 | F39: =IFERROR(C39-(D39*B39),"") -> 15
A41: BGF로지스서귀포 | B41: =$B$4 -> 48 | C41: =IFERROR(VLOOKUP(A41,'참조은 피벗(냉장 베이글)'!A:SD,3,FALSE),0) -> 1 | D41: =IFERROR(ROUNDDOWN(C41/B41,0),"") -> 0 | E41: 서귀포 | F41: =IFERROR(C41-(D41*B41),"") -> 1
A42: BGF로지스제주 | B42: =$B$4 -> 48 | C42: =IFERROR(VLOOKUP(A42,'참조은 피벗(냉장 베이글)'!A:SD,3,FALSE),0) -> 4 | D42: =IFERROR(ROUNDDOWN(C42/B42,0),"") -> 0 | E42: 제주 | F42: =IFERROR(C42-(D42*B42),"") -> 4
A44: 제주권 합계 | B44: =$B$4 -> 48 | C44: =SUM(C41:C42) -> 5 | D44: =IFERROR(ROUNDDOWN(C44/B44,0),"") -> 0 | F44: =IFERROR(C44-(D44*B44),"") -> 5
A46: 총합계 | B46: =$B$4 -> 48 | C46: =SUM(C4:C18,C35:C37,C30:C31,C22:C26,C41:C42) -> 158 | D46: =IFERROR(ROUNDDOWN(C46/B46,0),"") -> 3 | F46: =IFERROR(C46-(D46*B46),"") -> 14 | G46: 소분박스 | H46: 소분낱개
A47: 총 박스/총 낱개수량 | B47: □ | D47: =SUM(D4:D18,D35:D37,D30:D31,D22:D26,D41:D42) -> 0 | F47: =SUM(F4:F18,F35:F37,F30:F31,F22:F26,F41:F42) -> 158 | G47: =IFERROR(ROUNDDOWN(F47/B35,0),"") -> 3 | H47: =IFERROR(F47-(G47*B35),"") -> 14
C48: =C20+C28+C33+C39+C44 -> 158 | H48: □
C49: =C48=C46 -> TRUE

Sheet KH)뉴욕베이글플레인
A2: =TODAY() -> 46314 | B2: 참조은 □
A3: 행 레이블 | B3: 입수 | C3: KH)뉴욕베이글플레인 | D3: 박스 | E3: 센터명 | F3: 낱개
A4: BGF로지스강릉 | B4: 48 | C4: =IFERROR(VLOOKUP(A4,'참조은 피벗(냉장 베이글)'!A:SD,4,FALSE),0) -> 2 | D4: =IFERROR(ROUNDDOWN(C4/B4,0),"") -> 0 | E4: 강릉 | F4: =IFERROR(C4-(D4*B4),"") -> 2
A5: BGF로지스검단 | B5: =$B$4 -> 48 | C5: =IFERROR(VLOOKUP(A5,'참조은 피벗(냉장 베이글)'!A:SD,4,FALSE),0) -> 20 | D5: =IFERROR(ROUNDDOWN(C5/B5,0),"") -> 0 | E5: 검단 | F5: =IFERROR(C5-(D5*B5),"") -> 20
A6: BGF로지스서인천1 | B6: =$B$4 -> 48 | C6: =IFERROR(VLOOKUP(A6,'참조은 피벗(냉장 베이글)'!A:SD,4,FALSE),0) -> 4 | D6: =IFERROR(ROUNDDOWN(C6/B6,0),"") -> 0 | E6: 서인천1 | F6: =IFERROR(C6-(D6*B6),"") -> 4
A7: BGF로지스서인천2 | B7: =$B$4 -> 48 | C7: =IFERROR(VLOOKUP(A7,'참조은 피벗(냉장 베이글)'!A:SD,4,FALSE),0) -> 8 | D7: =IFERROR(ROUNDDOWN(C7/B7,0),"") -> 0 | E7: 서인천2 | F7: =IFERROR(C7-(D7*B7),"") -> 8
A8: BGF로지스진천 | B8: =$B$4 -> 48 | C8: =IFERROR(VLOOKUP(A8,'참조은 피벗(냉장 베이글)'!A:SD,4,FALSE),0) -> 10 | D8: =IFERROR(ROUNDDOWN(C8/B8,0),"") -> 0 | E8: 진천 | F8: =IFERROR(C8-(D8*B8),"") -> 10
A9: BGF로지스안성 | B9: =$B$4 -> 48 | C9: =IFERROR(VLOOKUP(A9,'참조은 피벗(냉장 베이글)'!A:SD,4,FALSE),0) -> 14 | D9: =IFERROR(ROUNDDOWN(C9/B9,0),"") -> 0 | E9: 안성 | F9: =IFERROR(C9-(D9*B9),"") -> 14
A10: BGF로지스아산 | B10: =$B$4 -> 48 | C10: =IFERROR(VLOOKUP(A10,'참조은 피벗(냉장 베이글)'!A:SD,4,FALSE),0) -> 10 | D10: =IFERROR(ROUNDDOWN(C10/B10,0),"") -> 0 | E10: 아산 | F10: =IFERROR(C10-(D10*B10),"") -> 10
A11: 화인로지텍 | B11: =$B$4 -> 48 | C11: =IFERROR(VLOOKUP(A11,'참조은 피벗(냉장 베이글)'!A:SD,4,FALSE),0) -> 7 | D11: =IFERROR(ROUNDDOWN(C11/B11,0),"") -> 0 | E11: 화인 | F11: =IFERROR(C11-(D11*B11),"") -> 7
