Workbook

Sheet 대신피벗발주량1편
A1: 10/20 | B1: 열 레이블
A2: 행 레이블 | B2: 도)깐풍기&표고탕수1 | C2: 도)딥핑치즈맵닭강정1 | D2: 도)리얼모짜치즈돈까스1 | E2: 도)리얼치즈고구마돈까스1 | F2: 도)윙봉칠리탕수득템1 | G2: 도)찍먹윙봉1 | H2: 도)찍먹탕수육1 | I2: 도)치맥아보트러플치킨1 | J2: 도)치즈매콤닭강정감자1 | K2: 도)치즈청양간장닭강정1 | L2: 도)쿵야반반닭강정팩1
A3: BGF로지스강릉 | B3: 3 | C3: 37 | D3: 4 | E3: 6 | F3: 1 | G3: 1 | J3: 6 | K3: 6 | L3: 3 | M3: =SUM(B3:L3) -> 67
A4: BGF로지스검단 | B4: 12 | C4: 212 | D4: 28 | E4: 36 | F4: 4 | G4: 4 | H4: 8 | I4: 5 | J4: 30 | K4: 13 | L4: 13 | M4: =SUM(B4:L4) -> 365
A5: BGF로지스광주 | B5: 7 | C5: 127 | D5: 10 | E5: 25 | F5: 3 | G5: 5 | H5: 3 | I5: 4 | J5: 17 | K5: 5 | L5: 13 | M5: =SUM(B5:L5) -> 219
A6: BGF로지스나주 | B6: 2 | C6: 79 | D6: 14 | E6: 18 | F6: 3 | H6: 2 | J6: 11 | K6: 4 | L6: 15 | M6: =SUM(B6:L6) -> 148
A7: BGF로지스대구 | B7: 5 | C7: 107 | D7: 11 | E7: 27 | F7: 2 | G7: 3 | H7: 6 | I7: 2 | J7: 21 | K7: 7 | L7: 8 | M7: =SUM(B7:L7) -> 199
A8: BGF로지스부산 | B8: 4 | C8: 105 | D8: 7 | E8: 10 | F8: 2 | G8: 2 | H8: 2 | I8: 1 | J8: 9 | K8: 7 | L8: 12 | M8: =SUM(B8:L8) -> 161
A9: BGF로지스서귀포 | B9: 1 | C9: 64 | D9: 15 | E9: 21 | F9: 1 | G9: 1 | H9: 3 | I9: 1 | J9: 13 | K9: 3 | L9: 6 | M9: =SUM(B9:L9) -> 129
A10: BGF로지스서인천1 | B10: 6 | C10: 115 | D10: 16 | E10: 21 | F10: 2 | G10: 5 | H10: 9 | I10: 3 | J10: 19 | K10: 6 | L10: 12 | M10: =SUM(B10:L10) -> 214
A11: BGF로지스서인천2 | B11: 5 | C11: 138 | D11: 8 | E11: 27 | F11: 2 | G11: 1 | H11: 10 | I11: 2 | J11: 23 | K11: 11 | L11: 7 | M11: =SUM(B11:L11) -> 234
A12: BGF로지스아산 | B12: 2 | C12: 74 | D12: 10 | E12: 18 | F12: 2 | G12: 1 | H12: 4 | I12: 2 | J12: 6 | K12: 3 | L12: 4 | M12: =SUM(B12:L12) -> 126
A13: BGF로지스안성 | B13: 3 | C13: 92 | D13: 6 | E13: 15 | F13: 3 | G13: 2 | H13: 2 | I13: 1 | J13: 9 | K13: 6 | L13: 3 | M13: =SUM(B13:L13) -> 142
A14: BGF로지스양주 | B14: 1 | C14: 85 | D14: 7 | E14: 10 | F14: 1 | G14: 1 | H14: 4 | I14: 1 | J14: 9 | K14: 4 | L14: 2 | M14: =SUM(B14:L14) -> 125
A15: BGF로지스제주 | B15: 1 | C15: 74 | D15: 8 | E15: 23 | G15: 2 | I15: 2 | J15: 12 | K15: 7 | L15: 4 | M15: =SUM(B15:L15) -> 133
A16: BGF로지스진주 | B16: 2 | C16: 80 | D16: 6 | E16: 15 | G16: 4 | H16: 4 | I16: 1 | J16: 14 | K16: 4 | L16: 9 | M16: =SUM(B16:L16) -> 139
A17: BGF로지스진천 | C17: 103 | D17: 9 | E17: 12 | F17: 2 | H17: 3 | J17: 14 | K17: 1 | L17: 6 | M17: =SUM(B17:L17) -> 150
A18: BGF로지스화성 | B18: 1 | C18: 76 | D18: 3 | E18: 12 | F18: 3 | G18: 2 | H18: 3 | I18: 2 | J18: 12 | K18: 3 | L18: 6 | M18: =SUM(B18:L18) -> 123
A19: 극동로지스 | C19: 88 | D19: 6 | E19: 12 | F19: 1 | G19: 2 | I19: 1 | J19: 16 | K19: 3 | L19: 1 | M19: =SUM(B19:L19) -> 130
A20: 동부로지스 | B20: 1 | C20: 84 | D20: 10 | E20: 10 | F20: 2 | G20: 3 | H20: 3 | I20: 2 | J20: 14 | K20: 7 | L20: 9 | M20: =SUM(B20:L20) -> 145
A21: 씨제이경산 | B21: 2 | C21: 137 | D21: 11 | E21: 15 | G21: 1 | H21: 1 | I21: 2 | J21: 16 | K21: 5 | L21: 6 | M21: =SUM(B21:L21) -> 196
A22: 씨제이군포 | B22: 6 | C22: 110 | D22: 7 | E22: 19 | F22: 4 | G22: 5 | H22: 5 | I22: 2 | J22: 22 | K22: 8 | L22: 15 | M22: =SUM(B22:L22) -> 203
A23: 씨제이김제 | B23: 4 | C23: 69 | D23: 10 | E23: 14 | F23: 1 | H23: 1 | I23: 2 | J23: 15 | K23: 3 | L23: 16 | M23: =SUM(B23:L23) -> 135
A24: 씨제이오산 | B24: 5 | C24: 128 | D24: 16 | E24: 23 | F24: 7 | G24: 5 | H24: 7 | I24: 1 | J24: 25 | K24: 6 | L24: 12 | M24: =SUM(B24:L24) -> 235
A25: 아신 | B25: 6 | C25: 116 | D25: 9 | E25: 15 | F25: 5 | G25: 4 | H25: 6 | I25: 1 | J25: 18 | K25: 8 | L25: 7 | M25: =SUM(B25:L25) -> 195
A26: 엑소후레쉬양산 | B26: 5 | C26: 152 | D26: 16 | E26: 14 | F26: 3 | G26: 1 | H26: 8 | I26: 2 | J26: 15 | K26: 3 | L26: 4 | M26: =SUM(B26:L26) -> 223
A27: 하이로지스 | B27: 2 | C27: 69 | D27: 5 | E27: 8 | G27: 1 | J27: 8 | K27: 2 | L27: 4 | M27: =SUM(B27:L27) -> 99
A28: 화인로지텍 | B28: 3 | C28: 64 | D28: 11 | E28: 9 | F28: 1 | H28: 1 | I28: 1 | J28: 7 | K28: 6 | L28: 8 | M28: =SUM(B28:L28) -> 111
A29: 총합계 | B29: 89 | C29: 2585 | D29: 263 | E29: 435 | F29: 55 | G29: 56 | H29: 95 | I29: 41 | J29: 381 | K29: 141 | L29: 205 | M29: =SUM(B29:L29) -> 4346

Sheet BGF로지스_강릉_(더원)1편
B1: BGF로지스강릉
B2: 거 래 명 세 표 (공급받는자 보관용)
B4: 공 급 받 는 자 | C4: 등록번호 | Q4: 공 급 자 | R4: 등록번호 | V4: 397-85-00686
C6: 상 호 (법인명) | G6: CU (BGF) | L6: BGF로지스강릉 | R6: 상 호 (법인명) | V6: ㈜대신에프에스 | AB6: 성 명 | AD6: 신판철
C8: 사업장 주 소 | G8: 강원도 강릉시 사천면 과학단지로 137-49 | R8: 사업장 주 소 | V8: 전라북도 부안군 행안면 옥여길 32-76
C10: 합계금액 (VAT포함) | R10: 업 태 | V10: 도매및 소매업 | AB10: 종 목 | AD10: 빵 과자류
B12: 년 | C12: 월 | D12: 일 | E12: 품 목 | M12: 입수 | Q12: 총수량 | T12: 박스 | W12: 낱개수량 | AA12: 비고
B13: ='하이로지스(호남) 날짜번경★'!B13+1 -> 46316 | E13: 도)깐풍기&표고탕수1 | M13: 36 | Q13: =IFERROR(VLOOKUP($B$1,대신피벗발주량1편!$A:$ZZ,2,FALSE),0) -> 3 | T13: =IFERROR(ROUNDDOWN(Q13/M13,0),"") -> 0 | W13: =IFERROR(Q13-(T13*M13),"") -> 3 | AA13: =B13+6-1 -> 46321
E14: 도)딥핑치즈맵닭강정1 | Q14: =IFERROR(VLOOKUP($B$1,대신피벗발주량1편!$A:$ZZ,3,FALSE),0) -> 3 | T14: =IFERROR(ROUNDDOWN(Q14/M14,0),"") | W14: =IFERROR(Q14-(T14*M14),"") | AA14: =B12+5-1 -> #VALUE!
E15: 도)리얼모짜치즈돈까스1 | M15: 30 | Q15: =IFERROR(VLOOKUP($B$1,대신피벗발주량1편!$A:$ZZ,4,FALSE),0) -> 37 | T15: =IFERROR(ROUNDDOWN(Q15/M15,0),"") -> 1 | W15: =IFERROR(Q15-(T15*M15),"") -> 7 | AA15: =B13+5-1 -> 46320
E16: 도)리얼치즈고구마돈까스1 | M16: 30 | Q16: =IFERROR(VLOOKUP($B$1,대신피벗발주량1편!$A:$ZZ,5,FALSE),0) -> 4 | T16: =IFERROR(ROUNDDOWN(Q16/M16,0),"") -> 0 | W16: =IFERROR(Q16-(T16*M16),"") -> 4 | AA16: =B13+5-1 -> 46320
E17: 도)윙봉칠리탕수득템1 | M17: 36 | Q17: =IFERROR(VLOOKUP($B$1,대신피벗발주량1편!$A:$ZZ,6,FALSE),0) -> 6 | T17: =IFERROR(ROUNDDOWN(Q17/M17,0),"") -> 0 | W17: =IFERROR(Q17-(T17*M17),"") -> 6 | AA17: =B13+5-1 -> 46320
E18: 도)찍먹윙봉1 | M18: 36 | Q18: =IFERROR(VLOOKUP($B$1,대신피벗발주량1편!$A:$ZZ,7,FALSE),0) -> 1 | T18: =IFERROR(ROUNDDOWN(Q18/M18,0),"") -> 0 | W18: =IFERROR(Q18-(T18*M18),"") -> 1 | AA18: =B13+5-1 -> 46320
E19: 도)찍먹탕수육1 | M19: 36 | Q19: =IFERROR(VLOOKUP($B$1,대신피벗발주량1편!$A:$ZZ,8,FALSE),0) -> 1 | T19: =IFERROR(ROUNDDOWN(Q19/M19,0),"") -> 0 | W19: =IFERROR(Q19-(T19*M19),"") -> 1 | AA19: =B13+5-1 -> 46320
E20: 도)치맥아보트러플치킨1 | M20: 32 | Q20: =IFERROR(VLOOKUP($B$1,대신피벗발주량1편!$A:$ZZ,9,FALSE),0) -> 0 | T20: =IFERROR(ROUNDDOWN(Q20/M20,0),"") -> 0 | W20: =IFERROR(Q20-(T20*M20),"") -> 0 | AA20: =B13+5-1 -> 46320
E21: 도)치즈매콤닭강정감자1 | M21: 30 | Q21: =IFERROR(VLOOKUP($B$1,대신피벗발주량1편!$A:$ZZ,10,FALSE),0) -> 0 | T21: =IFERROR(ROUNDDOWN(Q21/M21,0),"") -> 0 | W21: =IFERROR(Q21-(T21*M21),"") -> 0 | AA21: =B13+5-1 -> 46320
E22: 도)치즈청양간장닭강정1 | M22: 30 | Q22: =IFERROR(VLOOKUP($B$1,대신피벗발주량1편!$A:$ZZ,11,FALSE),0) -> 6 | T22: =IFERROR(ROUNDDOWN(Q22/M22,0),"") -> 0 | W22: =IFERROR(Q22-(T22*M22),"") -> 6 | AA22: =B13+5-1 -> 46320
E23: 도)쿵야반반닭강정팩1 | M23: 36 | Q23: =IFERROR(VLOOKUP($B$1,대신피벗발주량1편!$A:$ZZ,12,FALSE),0) -> 6 | T23: =IFERROR(ROUNDDOWN(Q23/M23,0),"") -> 0 | W23: =IFERROR(Q23-(T23*M23),"") -> 6 | AA23: =B13+5-1 -> 46320
B25: 총수량 | M25: =SUM(Q13:S24) -> 67
B26: 3자물류 (더원물류) 담당자 박병선이사 010-4448-1456 | W26: =G8 -> 강원도 강릉시 사천면 과학단지로 137-49
B30: 거 래 명 세 표 (공급자 보관용)
B32: 공 급 받 는 자 | C32: =C4 -> 등록번호 | Q32: 공 급 자 | R32: 등록번호 | V32: =V4 -> 397-85-00686
C34: =C6 -> 상 호 (법인명) | G34: =G6 -> CU (BGF) | L34: =L6 -> BGF로지스강릉 | R34: 상 호 (법인명) | V34: =V6 -> ㈜대신에프에스 | AB34: 성 명 | AD34: =AD6 -> 신판철
C36: 사업장 주 소 | G36: =G8 -> 강원도 강릉시 사천면 과학단지로 137-49 | R36: 사업장 주 소 | V36: =V8 -> 전라북도 부안군 행안면 옥여길 32-76
C38: 합계금액 (VAT포함) | R38: 업 태 | V38: =V10 -> 도매및 소매업 | AB38: =AB10 -> 종 목 | AD38: =AD10 -> 빵 과자류
B40: 년 | C40: 월 | D40: 일 | E40: 품 목 | M40: 입수 | Q40: 총수량 | T40: 박스 | W40: 낱개수량 | AA40: 비고
B41: =B13 -> 46316 | E41: =E13 -> 도)깐풍기&표고탕수1 | M41: =M13 -> 36 | Q41: =Q13 -> 3 | T41: =T13 -> 0 | W41: =W13 -> 3 | AA41: =AA13 -> 46321
E42: =E14 -> 도)딥핑치즈맵닭강정1 | M42: =M14 -> 0 | Q42: =Q14 -> 3 | T42: =T14 | W42: =W14 | AA42: =AA14 -> #VALUE!
E43: =E15 -> 도)리얼모짜치즈돈까스1 | M43: =M15 -> 30 | Q43: =Q15 -> 37 | T43: =T15 -> 1 | W43: =W15 -> 7 | AA43: =AA15 -> 46320
E44: =E16 -> 도)리얼치즈고구마돈까스1 | M44: =M16 -> 30 | Q44: =Q16 -> 4 | T44: =T16 -> 0 | W44: =W16 -> 4 | AA44: =AA16 -> 46320
E45: =E17 -> 도)윙봉칠리탕수득템1 | M45: =M17 -> 36 | Q45: =Q17 -> 6 | T45: =T17 -> 0 | W45: =W17 -> 6 | AA45: =AA17 -> 46320
E46: =E18 -> 도)찍먹윙봉1 | M46: =M18 -> 36 | Q46: =Q18 -> 1 | T46: =T18 -> 0 | W46: =W18 -> 1 | AA46: =AA18 -> 46320
E47: =E19 -> 도)찍먹탕수육1 | M47: =M19 -> 36 | Q47: =Q19 -> 1 | T47: =T19 -> 0 | W47: =W19 -> 1 | AA47: =AA19 -> 46320
E48: =E20 -> 도)치맥아보트러플치킨1 | M48: =M20 -> 32 | Q48: =Q20 -> 0 | T48: =T20 -> 0 | W48: =W20 -> 0 | AA48: =AA20 -> 46320
E49: =E21 -> 도)치즈매콤닭강정감자1 | M49: =M21 -> 30 | Q49: =Q21 -> 0 | T49: =T21 -> 0 | W49: =W21 -> 0 | AA49: =AA21 -> 46320
E50: =E22 -> 도)치즈청양간장닭강정1 | M50: =M22 -> 30 | Q50: =Q22 -> 6 | T50: =T22 -> 0 | W50: =W22 -> 6 | AA50: =AA22 -> 46320
E51: =E23 -> 도)쿵야반반닭강정팩1 | M51: =M23 -> 36 | Q51: =Q23 -> 6 | T51: =T23 -> 0 | W51: =W23 -> 6 | AA51: =AA23 -> 46320
B53: =B25 -> 총수량 | M53: =M25 -> 67
B54: =B26 -> 3자물류 (더원물류) 담당자 박병선이사 010-4448-1456 | W54: =W26 -> 강원도 강릉시 사천면 과학단지로 137-49

Sheet BGF로지스_서귀포_(더원)1편
B1: BGF로지스서귀포
B2: 거 래 명 세 표 (공급받는자 보관용)
B4: 공 급 받 는 자 | C4: 등록번호 | Q4: 공 급 자 | R4: 등록번호 | V4: 397-85-00686
C6: 상 호 (법인명) | G6: CU (BGF) | L6: BGF로지스서귀포 | R6: 상 호 (법인명) | V6: ㈜대신에프에스 | AB6: 성 명 | AD6: 신판철
C8: 사업장 주 소 | G8: 제주특별자치도 서귀포시 토평공단로155번길 45 | R8: 사업장 주 소 | V8: 전라북도 부안군 행안면 옥여길 32-76
C10: 합계금액 (VAT포함) | R10: 업 태 | V10: 도매및 소매업 | AB10: 종 목 | AD10: 빵 과자류
B12: 년 | C12: 월 | D12: 일 | E12: 품 목 | M12: 입수 | Q12: 총수량 | T12: 박스 | W12: 낱개수량 | AA12: 비고
B13: ='하이로지스(호남) 날짜번경★'!B13 -> 46315 | E13: 도)깐풍기&표고탕수1 | M13: 36 | Q13: =IFERROR(VLOOKUP($B$1,대신피벗발주량1편!$A:$ZZ,2,FALSE),0) -> 1 | T13: =IFERROR(ROUNDDOWN(Q13/M13,0),"") -> 0 | W13: =IFERROR(Q13-(T13*M13),"") -> 1 | AA13: =B13+6 -> 46321
E14: 도)딥핑치즈맵닭강정1 | Q14: =IFERROR(VLOOKUP($B$1,대신피벗발주량1편!$A:$ZZ,3,FALSE),0) -> 1 | T14: =IFERROR(ROUNDDOWN(Q14/M14,0),"") | W14: =IFERROR(Q14-(T14*M14),"") | AA14: =B12+5 -> #VALUE!
E15: 도)리얼모짜치즈돈까스1 | M15: 30 | Q15: =IFERROR(VLOOKUP($B$1,대신피벗발주량1편!$A:$ZZ,4,FALSE),0) -> 64 | T15: =IFERROR(ROUNDDOWN(Q15/M15,0),"") -> 2 | W15: =IFERROR(Q15-(T15*M15),"") -> 4 | AA15: =B13+5 -> 46320
E16: 도)리얼치즈고구마돈까스1 | M16: 30 | Q16: =IFERROR(VLOOKUP($B$1,대신피벗발주량1편!$A:$ZZ,5,FALSE),0) -> 15 | T16: =IFERROR(ROUNDDOWN(Q16/M16,0),"") -> 0 | W16: =IFERROR(Q16-(T16*M16),"") -> 15 | AA16: =B13+5-1 -> 46319
E17: 도)윙봉칠리탕수득템1 | M17: 36 | Q17: =IFERROR(VLOOKUP($B$1,대신피벗발주량1편!$A:$ZZ,6,FALSE),0) -> 21 | T17: =IFERROR(ROUNDDOWN(Q17/M17,0),"") -> 0 | W17: =IFERROR(Q17-(T17*M17),"") -> 21 | AA17: =B13+5-1 -> 46319
E18: 도)찍먹윙봉1 | M18: 36 | Q18: =IFERROR(VLOOKUP($B$1,대신피벗발주량1편!$A:$ZZ,7,FALSE),0) -> 1 | T18: =IFERROR(ROUNDDOWN(Q18/M18,0),"") -> 0 | W18: =IFERROR(Q18-(T18*M18),"") -> 1 | AA18: =B13+5-1 -> 46319
E19: 도)찍먹탕수육1 | M19: 36 | Q19: =IFERROR(VLOOKUP($B$1,대신피벗발주량1편!$A:$ZZ,8,FALSE),0) -> 1 | T19: =IFERROR(ROUNDDOWN(Q19/M19,0),"") -> 0 | W19: =IFERROR(Q19-(T19*M19),"") -> 1 | AA19: =B13+5-1 -> 46319
E20: 도)치맥아보트러플치킨1 | M20: 32 | Q20: =IFERROR(VLOOKUP($B$1,대신피벗발주량1편!$A:$ZZ,9,FALSE),0) -> 3 | T20: =IFERROR(ROUNDDOWN(Q20/M20,0),"") -> 0 | W20: =IFERROR(Q20-(T20*M20),"") -> 3 | AA20: =B13+5 -> 46320
E21: 도)치즈매콤닭강정감자1 | M21: 30 | Q21: =IFERROR(VLOOKUP($B$1,대신피벗발주량1편!$A:$ZZ,10,FALSE),0) -> 1 | T21: =IFERROR(ROUNDDOWN(Q21/M21,0),"") -> 0 | W21: =IFERROR(Q21-(T21*M21),"") -> 1 | AA21: =B13+5-1 -> 46319
E22: 도)치즈청양간장닭강정1 | M22: 30 | Q22: =IFERROR(VLOOKUP($B$1,대신피벗발주량1편!$A:$ZZ,11,FALSE),0) -> 13 | T22: =IFERROR(ROUNDDOWN(Q22/M22,0),"") -> 0 | W22: =IFERROR(Q22-(T22*M22),"") -> 13 | AA22: =B13+5-1 -> 46319
E23: 도)쿵야반반닭강정팩1 | M23: 36 | Q23: =IFERROR(VLOOKUP($B$1,대신피벗발주량1편!$A:$ZZ,12,FALSE),0) -> 3 | T23: =IFERROR(ROUNDDOWN(Q23/M23,0),"") -> 0 | W23: =IFERROR(Q23-(T23*M23),"") -> 3 | AA23: =B13+5 -> 46320
B25: 총수량 | M25: =SUM(Q13:S24) -> 124
B26: 3자물류 (더원물류) 담당자 박병선이사 010-4448-1456 | W26: =G8 -> 제주특별자치도 서귀포시 토평공단로155번길 45
B30: 거 래 명 세 표 (공급자 보관용)
B32: 공 급 받 는 자 | C32: =C4 -> 등록번호 | Q32: 공 급 자 | R32: 등록번호 | V32: =V4 -> 397-85-00686
C34: =C6 -> 상 호 (법인명) | G34: =G6 -> CU (BGF) | L34: =L6 -> BGF로지스서귀포 | R34: 상 호 (법인명) | V34: =V6 -> ㈜대신에프에스 | AB34: 성 명 | AD34: =AD6 -> 신판철
C36: 사업장 주 소 | G36: =G8 -> 제주특별자치도 서귀포시 토평공단로155번길 45 | R36: 사업장 주 소 | V36: =V8 -> 전라북도 부안군 행안면 옥여길 32-76
C38: 합계금액 (VAT포함) | R38: 업 태 | V38: =V10 -> 도매및 소매업 | AB38: =AB10 -> 종 목 | AD38: =AD10 -> 빵 과자류
B40: 년 | C40: 월 | D40: 일 | E40: 품 목 | M40: 입수 | Q40: 총수량 | T40: 박스 | W40: 낱개수량 | AA40: 비고
B41: =B13 -> 46315 | E41: =E13 -> 도)깐풍기&표고탕수1 | M41: =M13 -> 36 | Q41: =Q13 -> 1 | T41: =T13 -> 0 | W41: =W13 -> 1 | AA41: =AA13 -> 46321
E42: =E14 -> 도)딥핑치즈맵닭강정1 | M42: =M14 -> 0 | Q42: =Q14 -> 1 | T42: =T14 | W42: =W14 | AA42: =AA14 -> #VALUE!
E43: =E15 -> 도)리얼모짜치즈돈까스1 | M43: =M15 -> 30 | Q43: =Q15 -> 64 | T43: =T15 -> 2 | W43: =W15 -> 4 | AA43: =AA15 -> 46320
E44: =E16 -> 도)리얼치즈고구마돈까스1 | M44: =M16 -> 30 | Q44: =Q16 -> 15 | T44: =T16 -> 0 | W44: =W16 -> 15 | AA44: =AA16 -> 46319
E45: =E17 -> 도)윙봉칠리탕수득템1 | M45: =M17 -> 36 | Q45: =Q17 -> 21 | T45: =T17 -> 0 | W45: =W17 -> 21 | AA45: =AA17 -> 46319
E46: =E18 -> 도)찍먹윙봉1 | M46: =M18 -> 36 | Q46: =Q18 -> 1 | T46: =T18 -> 0 | W46: =W18 -> 1 | AA46: =AA18 -> 46319
E47: =E19 -> 도)찍먹탕수육1 | M47: =M19 -> 36 | Q47: =Q19 -> 1 | T47: =T19 -> 0 | W47: =W19 -> 1 | AA47: =AA19 -> 46319
E48: =E20 -> 도)치맥아보트러플치킨1 | M48: =M20 -> 32 | Q48: =Q20 -> 3 | T48: =T20 -> 0 | W48: =W20 -> 3 | AA48: =AA20 -> 46320
E49: =E21 -> 도)치즈매콤닭강정감자1 | M49: =M21 -> 30 | Q49: =Q21 -> 1 | T49: =T21 -> 0 | W49: =W21 -> 1 | AA49: =AA21 -> 46319
E50: =E22 -> 도)치즈청양간장닭강정1 | M50: =M22 -> 30 | Q50: =Q22 -> 13 | T50: =T22 -> 0 | W50: =W22 -> 13 | AA50: =AA22 -> 46319
E51: =E23 -> 도)쿵야반반닭강정팩1 | M51: =M23 -> 36 | Q51: =Q23 -> 3 | T51: =T23 -> 0 | W51: =W23 -> 3 | AA51: =AA23 -> 46320
B53: =B25 -> 총수량 | M53: =M25 -> 124
B54: =B26 -> 3자물류 (더원물류) 담당자 박병선이사 010-4448-1456 | W54: =W26 -> 제주특별자치도 서귀포시 토평공단로155번길 45

Sheet BGF로지스_제주_(더원)1편
B1: BGF로지스제주
B2: 거 래 명 세 표 (공급받는자 보관용)
B4: 공 급 받 는 자 | C4: 등록번호 | Q4: 공 급 자 | R4: 등록번호 | V4: 397-85-00686
C6: 상 호 (법인명) | G6: CU (BGF) | L6: BGF로지스제주 | R6: 상 호 (법인명) | V6: ㈜대신에프에스 | AB6: 성 명 | AD6: 신판철
C8: 사업장 주 소 | G8: 제주특별자치도 제주시 우정로8길 16 | R8: 사업장 주 소 | V8: 전라북도 부안군 행안면 옥여길 32-76
C10: 합계금액 (VAT포함) | R10: 업 태 | V10: 도매및 소매업 | AB10: 종 목 | AD10: 빵 과자류
B12: 년 | C12: 월 | D12: 일 | E12: 품 목 | M12: 입수 | Q12: 총수량 | T12: 박스 | W12: 낱개수량 | AA12: 비고
B13: ='하이로지스(호남) 날짜번경★'!B13 -> 46315 | E13: 도)깐풍기&표고탕수1 | M13: 36 | Q13: =IFERROR(VLOOKUP($B$1,대신피벗발주량1편!$A:$ZZ,2,FALSE),0) -> 1 | T13: =IFERROR(ROUNDDOWN(Q13/M13,0),"") -> 0 | W13: =IFERROR(Q13-(T13*M13),"") -> 1 | AA13: =B13+6 -> 46321
E14: 도)딥핑치즈맵닭강정1 | Q14: =IFERROR(VLOOKUP($B$1,대신피벗발주량1편!$A:$ZZ,3,FALSE),0) -> 1 | T14: =IFERROR(ROUNDDOWN(Q14/M14,0),"") | W14: =IFERROR(Q14-(T14*M14),"") | AA14: =B12+5 -> #VALUE!
E15: 도)리얼모짜치즈돈까스1 | M15: 30 | Q15: =IFERROR(VLOOKUP($B$1,대신피벗발주량1편!$A:$ZZ,4,FALSE),0) -> 74 | T15: =IFERROR(ROUNDDOWN(Q15/M15,0),"") -> 2 | W15: =IFERROR(Q15-(T15*M15),"") -> 14 | AA15: =B13+5 -> 46320
E16: 도)리얼치즈고구마돈까스1 | M16: 30 | Q16: =IFERROR(VLOOKUP($B$1,대신피벗발주량1편!$A:$ZZ,5,FALSE),0) -> 8 | T16: =IFERROR(ROUNDDOWN(Q16/M16,0),"") -> 0 | W16: =IFERROR(Q16-(T16*M16),"") -> 8 | AA16: =B13+5-1 -> 46319
E17: 도)윙봉칠리탕수득템1 | M17: 36 | Q17: =IFERROR(VLOOKUP($B$1,대신피벗발주량1편!$A:$ZZ,6,FALSE),0) -> 23 | T17: =IFERROR(ROUNDDOWN(Q17/M17,0),"") -> 0 | W17: =IFERROR(Q17-(T17*M17),"") -> 23 | AA17: =B13+5-1 -> 46319
E18: 도)찍먹윙봉1 | M18: 36 | Q18: =IFERROR(VLOOKUP($B$1,대신피벗발주량1편!$A:$ZZ,7,FALSE),0) -> 0 | T18: =IFERROR(ROUNDDOWN(Q18/M18,0),"") -> 0 | W18: =IFERROR(Q18-(T18*M18),"") -> 0 | AA18: =B13+5-1 -> 46319
E19: 도)찍먹탕수육1 | M19: 36 | Q19: =IFERROR(VLOOKUP($B$1,대신피벗발주량1편!$A:$ZZ,8,FALSE),0) -> 2 | T19: =IFERROR(ROUNDDOWN(Q19/M19,0),"") -> 0 | W19: =IFERROR(Q19-(T19*M19),"") -> 2 | AA19: =B13+5-1 -> 46319
E20: 도)치맥아보트러플치킨1 | M20: 32 | Q20: =IFERROR(VLOOKUP($B$1,대신피벗발주량1편!$A:$ZZ,9,FALSE),0) -> 0 | T20: =IFERROR(ROUNDDOWN(Q20/M20,0),"") -> 0 | W20: =IFERROR(Q20-(T20*M20),"") -> 0 | AA20: =B13+5 -> 46320
E21: 도)치즈매콤닭강정감자1 | M21: 30 | Q21: =IFERROR(VLOOKUP($B$1,대신피벗발주량1편!$A:$ZZ,10,FALSE),0) -> 2 | T21: =IFERROR(ROUNDDOWN(Q21/M21,0),"") -> 0 | W21: =IFERROR(Q21-(T21*M21),"") -> 2 | AA21: =B13+5-1 -> 46319
E22: 도)치즈청양간장닭강정1 | M22: 30 | Q22: =IFERROR(VLOOKUP($B$1,대신피벗발주량1편!$A:$ZZ,11,FALSE),0) -> 12 | T22: =IFERROR(ROUNDDOWN(Q22/M22,0),"") -> 0 | W22: =IFERROR(Q22-(T22*M22),"") -> 12 | AA22: =B13+5-1 -> 46319
E23: 도)쿵야반반닭강정팩1 | M23: 36 | Q23: =IFERROR(VLOOKUP($B$1,대신피벗발주량1편!$A:$ZZ,12,FALSE),0) -> 7 | T23: =IFERROR(ROUNDDOWN(Q23/M23,0),"") -> 0 | W23: =IFERROR(Q23-(T23*M23),"") -> 7 | AA23: =B13+5 -> 46320
B25: 총수량 | M25: =SUM(Q13:S24) -> 130
B26: 3자물류 (더원물류) 담당자 박병선이사 010-4448-1456 | W26: =G8 -> 제주특별자치도 제주시 우정로8길 16
B30: 거 래 명 세 표 (공급자 보관용)
B32: 공 급 받 는 자 | C32: =C4 -> 등록번호 | Q32: 공 급 자 | R32: 등록번호 | V32: =V4 -> 397-85-00686
C34: =C6 -> 상 호 (법인명) | G34: =G6 -> CU (BGF) | L34: =L6 -> BGF로지스제주 | R34: 상 호 (법인명) | V34: =V6 -> ㈜대신에프에스 | AB34: 성 명 | AD34: =AD6 -> 신판철
C36: 사업장 주 소 | G36: =G8 -> 제주특별자치도 제주시 우정로8길 16 | R36: 사업장 주 소 | V36: =V8 -> 전라북도 부안군 행안면 옥여길 32-76
C38: 합계금액 (VAT포함) | R38: 업 태 | V38: =V10 -> 도매및 소매업 | AB38: =AB10 -> 종 목 | AD38: =AD10 -> 빵 과자류
B40: 년 | C40: 월 | D40: 일 | E40: 품 목 | M40: 입수 | Q40: 총수량 | T40: 박스 | W40: 낱개수량 | AA40: 비고
B41: =B13 -> 46315 | E41: =E13 -> 도)깐풍기&표고탕수1 | M41: =M13 -> 36 | Q41: =Q13 -> 1 | T41: =T13 -> 0 | W41: =W13 -> 1 | AA41: =AA13 -> 46321
E42: =E14 -> 도)딥핑치즈맵닭강정1 | M42: =M14 -> 0 | Q42: =Q14 -> 1 | T42: =T14 | W42: =W14 | AA42: =AA14 -> #VALUE!
E43: =E15 -> 도)리얼모짜치즈돈까스1 | M43: =M15 -> 30 | Q43: =Q15 -> 74 | T43: =T15 -> 2 | W43: =W15 -> 14 | AA43: =AA15 -> 46320
E44: =E16 -> 도)리얼치즈고구마돈까스1 | M44: =M16 -> 30 | Q44: =Q16 -> 8 | T44: =T16 -> 0 | W44: =W16 -> 8 | AA44: =AA16 -> 46319
E45: =E17 -> 도)윙봉칠리탕수득템1 | M45: =M17 -> 36 | Q45: =Q17 -> 23 | T45: =T17 -> 0 | W45: =W17 -> 23 | AA45: =AA17 -> 46319
E46: =E18 -> 도)찍먹윙봉1 | M46: =M18 -> 36 | Q46: =Q18 -> 0 | T46: =T18 -> 0 | W46: =W18 -> 0 | AA46: =AA18 -> 46319
E47: =E19 -> 도)찍먹탕수육1 | M47: =M19 -> 36 | Q47: =Q19 -> 2 | T47: =T19 -> 0 | W47: =W19 -> 2 | AA47: =AA19 -> 46319
E48: =E20 -> 도)치맥아보트러플치킨1 | M48: =M20 -> 32 | Q48: =Q20 -> 0 | T48: =T20 -> 0 | W48: =W20 -> 0 | AA48: =AA20 -> 46320
E49: =E21 -> 도)치즈매콤닭강정감자1 | M49: =M21 -> 30 | Q49: =Q21 -> 2 | T49: =T21 -> 0 | W49: =W21 -> 2 | AA49: =AA21 -> 46319
E50: =E22 -> 도)치즈청양간장닭강정1 | M50: =M22 -> 30 | Q50: =Q22 -> 12 | T50: =T22 -> 0 | W50: =W22 -> 12 | AA50: =AA22 -> 46319
E51: =E23 -> 도)쿵야반반닭강정팩1 | M51: =M23 -> 36 | Q51: =Q23 -> 7 | T51: =T23 -> 0 | W51: =W23 -> 7 | AA51: =AA23 -> 46320
B53: =B25 -> 총수량 | M53: =M25 -> 130
B54: =B26 -> 3자물류 (더원물류) 담당자 박병선이사 010-4448-1456 | W54: =W26 -> 제주특별자치도 제주시 우정로8길 16

Sheet 하이로지스(호남) 날짜번경★
B1: 하이로지스
B2: 거 래 명 세 표 (공급받는자 보관용)
B4: 공 급 받 는 자 | C4: 등록번호 | Q4: 공 급 자 | R4: 등록번호 | V4: 397-85-00686
C6: 상 호 (법인명) | G6: CU (BGF) | L6: 하이로지스 | R6: 상 호 (법인명) | V6: ㈜대신에프에스 | AB6: 성 명 | AD6: 신판철
C8: 사업장 주 소 | G8: 전라북도 완주군 봉동읍 완주산단2로 282-21 | R8: 사업장 주 소 | V8: 전라북도 부안군 행안면 옥여길 32-76
C10: 합계금액 (VAT포함) | R10: 업 태 | V10: 도매및 소매업 | AB10: 종 목 | AD10: 빵 과자류
B12: 년 | C12: 월 | D12: 일 | E12: 품 목 | M12: 입수 | Q12: 총수량 | T12: 박스 | W12: 낱개수량 | AA12: 비고
B13: 46315 | E13: 도)깐풍기&표고탕수1 | M13: 36 | Q13: =IFERROR(VLOOKUP($B$1,대신피벗발주량1편!$A:$ZZ,2,FALSE),0) -> 2 | T13: =IFERROR(ROUNDDOWN(Q13/M13,0),"") -> 0 | W13: =IFERROR(Q13-(T13*M13),"") -> 2 | AA13: =B13+6 -> 46321
E14: 도)딥핑치즈맵닭강정1 | Q14: =IFERROR(VLOOKUP($B$1,대신피벗발주량1편!$A:$ZZ,3,FALSE),0) -> 2 | T14: =IFERROR(ROUNDDOWN(Q14/M14,0),"") | W14: =IFERROR(Q14-(T14*M14),"") | AA14: =B12+5 -> #VALUE!
E15: 도)리얼모짜치즈돈까스1 | M15: 30 | Q15: =IFERROR(VLOOKUP($B$1,대신피벗발주량1편!$A:$ZZ,4,FALSE),0) -> 69 | T15: =IFERROR(ROUNDDOWN(Q15/M15,0),"") -> 2 | W15: =IFERROR(Q15-(T15*M15),"") -> 9 | AA15: =B13+5 -> 46320
E16: 도)리얼치즈고구마돈까스1 | M16: 30 | Q16: =IFERROR(VLOOKUP($B$1,대신피벗발주량1편!$A:$ZZ,5,FALSE),0) -> 5 | T16: =IFERROR(ROUNDDOWN(Q16/M16,0),"") -> 0 | W16: =IFERROR(Q16-(T16*M16),"") -> 5 | AA16: =B13+5-1 -> 46319
E17: 도)윙봉칠리탕수득템1 | M17: 36 | Q17: =IFERROR(VLOOKUP($B$1,대신피벗발주량1편!$A:$ZZ,6,FALSE),0) -> 8 | T17: =IFERROR(ROUNDDOWN(Q17/M17,0),"") -> 0 | W17: =IFERROR(Q17-(T17*M17),"") -> 8 | AA17: =B13+5-1 -> 46319
E18: 도)찍먹윙봉1 | M18: 36 | Q18: =IFERROR(VLOOKUP($B$1,대신피벗발주량1편!$A:$ZZ,7,FALSE),0) -> 0 | T18: =IFERROR(ROUNDDOWN(Q18/M18,0),"") -> 0 | W18: =IFERROR(Q18-(T18*M18),"") -> 0 | AA18: =B13+5-1 -> 46319
E19: 도)찍먹탕수육1 | M19: 36 | Q19: =IFERROR(VLOOKUP($B$1,대신피벗발주량1편!$A:$ZZ,8,FALSE),0) -> 1 | T19: =IFERROR(ROUNDDOWN(Q19/M19,0),"") -> 0 | W19: =IFERROR(Q19-(T19*M19),"") -> 1 | AA19: =B13+5-1 -> 46319
E20: 도)치맥아보트러플치킨1 | M20: 32 | Q20: =IFERROR(VLOOKUP($B$1,대신피벗발주량1편!$A:$ZZ,9,FALSE),0) -> 0 | T20: =IFERROR(ROUNDDOWN(Q20/M20,0),"") -> 0 | W20: =IFERROR(Q20-(T20*M20),"") -> 0 | AA20: =B13+5 -> 46320
E21: 도)치즈매콤닭강정감자1 | M21: 30 | Q21: =IFERROR(VLOOKUP($B$1,대신피벗발주량1편!$A:$ZZ,10,FALSE),0) -> 0 | T21: =IFERROR(ROUNDDOWN(Q21/M21,0),"") -> 0 | W21: =IFERROR(Q21-(T21*M21),"") -> 0 | AA21: =B13+4 -> 46319
E22: 도)치즈청양간장닭강정1 | M22: 30 | Q22: =IFERROR(VLOOKUP($B$1,대신피벗발주량1편!$A:$ZZ,11,FALSE),0) -> 8 | T22: =IFERROR(ROUNDDOWN(Q22/M22,0),"") -> 0 | W22: =IFERROR(Q22-(T22*M22),"") -> 8 | AA22: =B13+5-1 -> 46319
E23: 도)쿵야반반닭강정팩1 | M23: 36 | Q23: =IFERROR(VLOOKUP($B$1,대신피벗발주량1편!$A:$ZZ,12,FALSE),0) -> 2 | T23: =IFERROR(ROUNDDOWN(Q23/M23,0),"") -> 0 | W23: =IFERROR(Q23-(T23*M23),"") -> 2 | AA23: =B13+5 -> 46320
B25: 총수량 | M25: =SUM(Q13:S24) -> 97
B26: 3자물류 (더원물류) 담당자 박병선이사 010-4448-1456 | W26: 전라북도 완주군 봉동읍 완주산단2로282-21 063)262-8443
B30: 거 래 명 세 표 (공급자 보관용)
B32: 공 급 받 는 자 | C32: =C4 -> 등록번호 | Q32: 공 급 자 | R32: 등록번호 | V32: =V4 -> 397-85-00686
C34: =C6 -> 상 호 (법인명) | G34: =G6 -> CU (BGF) | L34: =L6 -> 하이로지스 | R34: 상 호 (법인명) | V34: =V6 -> ㈜대신에프에스 | AB34: 성 명 | AD34: =AD6 -> 신판철
C36: 사업장 주 소 | G36: =G8 -> 전라북도 완주군 봉동읍 완주산단2로 282-21 | R36: 사업장 주 소 | V36: =V8 -> 전라북도 부안군 행안면 옥여길 32-76
C38: 합계금액 (VAT포함) | R38: 업 태 | V38: =V10 -> 도매및 소매업 | AB38: =AB10 -> 종 목 | AD38: =AD10 -> 빵 과자류
B40: 년 | C40: 월 | D40: 일 | E40: 품 목 | M40: 입수 | Q40: 총수량 | T40: 박스 | W40: 낱개수량 | AA40: 비고
B41: =B13 -> 46315 | E41: =E13 -> 도)깐풍기&표고탕수1 | M41: =M13 -> 36 | Q41: =Q13 -> 2 | T41: =T13 -> 0 | W41: =W13 -> 2 | AA41: =AA13 -> 46321
E42: =E14 -> 도)딥핑치즈맵닭강정1 | M42: =M14 -> 0 | Q42: =Q14 -> 2 | T42: =T14 | W42: =W14 | AA42: =AA14 -> #VALUE!
E43: =E15 -> 도)리얼모짜치즈돈까스1 | M43: =M15 -> 30 | Q43: =Q15 -> 69 | T43: =T15 -> 2 | W43: =W15 -> 9 | AA43: =AA15 -> 46320
E44: =E16 -> 도)리얼치즈고구마돈까스1 | M44: =M16 -> 30 | Q44: =Q16 -> 5 | T44: =T16 -> 0 | W44: =W16 -> 5 | AA44: =AA16 -> 46319
E45: =E17 -> 도)윙봉칠리탕수득템1 | M45: =M17 -> 36 | Q45: =Q17 -> 8 | T45: =T17 -> 0 | W45: =W17 -> 8 | AA45: =AA17 -> 46319
E46: =E18 -> 도)찍먹윙봉1 | M46: =M18 -> 36 | Q46: =Q18 -> 0 | T46: =T18 -> 0 | W46: =W18 -> 0 | AA46: =AA18 -> 46319
E47: =E19 -> 도)찍먹탕수육1 | M47: =M19 -> 36 | Q47: =Q19 -> 1 | T47: =T19 -> 0 | W47: =W19 -> 1 | AA47: =AA19 -> 46319
E48: =E20 -> 도)치맥아보트러플치킨1 | M48: =M20 -> 32 | Q48: =Q20 -> 0 | T48: =T20 -> 0 | W48: =W20 -> 0 | AA48: =AA20 -> 46320
E49: =E21 -> 도)치즈매콤닭강정감자1 | M49: =M21 -> 30 | Q49: =Q21 -> 0 | T49: =T21 -> 0 | W49: =W21 -> 0 | AA49: =AA21 -> 46319
E50: =E22 -> 도)치즈청양간장닭강정1 | M50: =M22 -> 30 | Q50: =Q22 -> 8 | T50: =T22 -> 0 | W50: =W22 -> 8 | AA50: =AA22 -> 46319
E51: =E23 -> 도)쿵야반반닭강정팩1 | M51: =M23 -> 36 | Q51: =Q23 -> 2 | T51: =T23 -> 0 | W51: =W23 -> 2 | AA51: =AA23 -> 46320
B53: =B25 -> 총수량 | M53: =M25 -> 97
B54: =B26 -> 3자물류 (더원물류) 담당자 박병선이사 010-4448-1456 | W54: =W26 -> 전라북도 완주군 봉동읍 완주산단2로282-21 063)262-8443

Sheet BGF로지스나주(호남)
B1: BGF로지스나주
B2: 거 래 명 세 표 (공급받는자 보관용)
B4: 공 급 받 는 자 | C4: 등록번호 | Q4: 공 급 자 | R4: 등록번호 | V4: 397-85-00686
C6: 상 호 (법인명) | G6: CU (BGF) | L6: BGF로지스나주 | R6: 상 호 (법인명) | V6: ㈜대신에프에스 | AB6: 성 명 | AD6: 신판철
C8: 사업장 주 소 | G8: 전남 나주시 동수농공단지길 62-237 (운곡동) | R8: 사업장 주 소 | V8: 전라북도 부안군 행안면 옥여길 32-76
C10: 합계금액 (VAT포함) | R10: 업 태 | V10: 도매및 소매업 | AB10: 종 목 | AD10: 빵 과자류
B12: 년 | C12: 월 | D12: 일 | E12: 품 목 | M12: 입수 | Q12: 총수량 | T12: 박스 | W12: 낱개수량 | AA12: 비고
B13: ='하이로지스(호남) 날짜번경★'!B13 -> 46315 | E13: 도)깐풍기&표고탕수1 | M13: 36 | Q13: =IFERROR(VLOOKUP($B$1,대신피벗발주량1편!$A:$ZZ,2,FALSE),0) -> 2 | T13: =IFERROR(ROUNDDOWN(Q13/M13,0),"") -> 0 | W13: =IFERROR(Q13-(T13*M13),"") -> 2 | AA13: =B13+6 -> 46321
E14: 도)딥핑치즈맵닭강정1 | Q14: =IFERROR(VLOOKUP($B$1,대신피벗발주량1편!$A:$ZZ,3,FALSE),0) -> 2 | T14: =IFERROR(ROUNDDOWN(Q14/M14,0),"") | W14: =IFERROR(Q14-(T14*M14),"") | AA14: =B12+5 -> #VALUE!
E15: 도)리얼모짜치즈돈까스1 | M15: 30 | Q15: =IFERROR(VLOOKUP($B$1,대신피벗발주량1편!$A:$ZZ,4,FALSE),0) -> 79 | T15: =IFERROR(ROUNDDOWN(Q15/M15,0),"") -> 2 | W15: =IFERROR(Q15-(T15*M15),"") -> 19 | AA15: =B13+5 -> 46320
E16: 도)리얼치즈고구마돈까스1 | M16: 30 | Q16: =IFERROR(VLOOKUP($B$1,대신피벗발주량1편!$A:$ZZ,5,FALSE),0) -> 14 | T16: =IFERROR(ROUNDDOWN(Q16/M16,0),"") -> 0 | W16: =IFERROR(Q16-(T16*M16),"") -> 14 | AA16: =B13+5-1 -> 46319
E17: 도)윙봉칠리탕수득템1 | M17: 36 | Q17: =IFERROR(VLOOKUP($B$1,대신피벗발주량1편!$A:$ZZ,6,FALSE),0) -> 18 | T17: =IFERROR(ROUNDDOWN(Q17/M17,0),"") -> 0 | W17: =IFERROR(Q17-(T17*M17),"") -> 18 | AA17: =B13+5-1 -> 46319
E18: 도)찍먹윙봉1 | M18: 36 | Q18: =IFERROR(VLOOKUP($B$1,대신피벗발주량1편!$A:$ZZ,7,FALSE),0) -> 3 | T18: =IFERROR(ROUNDDOWN(Q18/M18,0),"") -> 0 | W18: =IFERROR(Q18-(T18*M18),"") -> 3 | AA18: =B13+5-1 -> 46319
E19: 도)찍먹탕수육1 | M19: 36 | Q19: =IFERROR(VLOOKUP($B$1,대신피벗발주량1편!$A:$ZZ,8,FALSE),0) -> 0 | T19: =IFERROR(ROUNDDOWN(Q19/M19,0),"") -> 0 | W19: =IFERROR(Q19-(T19*M19),"") -> 0 | AA19: =B13+5-1 -> 46319
E20: 도)치맥아보트러플치킨1 | M20: 32 | Q20: =IFERROR(VLOOKUP($B$1,대신피벗발주량1편!$A:$ZZ,9,FALSE),0) -> 2 | T20: =IFERROR(ROUNDDOWN(Q20/M20,0),"") -> 0 | W20: =IFERROR(Q20-(T20*M20),"") -> 2 | AA20: =B13+5 -> 46320
E21: 도)치즈매콤닭강정감자1 | M21: 30 | Q21: =IFERROR(VLOOKUP($B$1,대신피벗발주량1편!$A:$ZZ,10,FALSE),0) -> 0 | T21: =IFERROR(ROUNDDOWN(Q21/M21,0),"") -> 0 | W21: =IFERROR(Q21-(T21*M21),"") -> 0 | AA21: =B13+4 -> 46319
E22: 도)치즈청양간장닭강정1 | M22: 30 | Q22: =IFERROR(VLOOKUP($B$1,대신피벗발주량1편!$A:$ZZ,11,FALSE),0) -> 11 | T22: =IFERROR(ROUNDDOWN(Q22/M22,0),"") -> 0 | W22: =IFERROR(Q22-(T22*M22),"") -> 11 | AA22: =B13+5-1 -> 46319
E23: 도)쿵야반반닭강정팩1 | M23: 36 | Q23: =IFERROR(VLOOKUP($B$1,대신피벗발주량1편!$A:$ZZ,12,FALSE),0) -> 4 | T23: =IFERROR(ROUNDDOWN(Q23/M23,0),"") -> 0 | W23: =IFERROR(Q23-(T23*M23),"") -> 4 | AA23: =B13+5 -> 46320
B25: 총수량 | M25: =SUM(Q13:S24) -> 135
B26: 3자물류 (더원물류) 담당자 박병선이사 010-4448-1456 | W26: 전남 나주시 동수농공단지길 62-237 (운곡동) 061)334-3007
B30: 거 래 명 세 표 (공급자 보관용)
B32: 공 급 받 는 자 | C32: =C4 -> 등록번호 | Q32: 공 급 자 | R32: 등록번호 | V32: =V4 -> 397-85-00686
C34: =C6 -> 상 호 (법인명) | G34: =G6 -> CU (BGF) | L34: =L6 -> BGF로지스나주 | R34: 상 호 (법인명) | V34: =V6 -> ㈜대신에프에스 | AB34: 성 명 | AD34: =AD6 -> 신판철
C36: 사업장 주 소 | G36: =G8 -> 전남 나주시 동수농공단지길 62-237 (운곡동) | R36: 사업장 주 소 | V36: =V8 -> 전라북도 부안군 행안면 옥여길 32-76
C38: 합계금액 (VAT포함) | R38: 업 태 | V38: =V10 -> 도매및 소매업 | AB38: =AB10 -> 종 목 | AD38: =AD10 -> 빵 과자류
B40: 년 | C40: 월 | D40: 일 | E40: 품 목 | M40: 입수 | Q40: 총수량 | T40: 박스 | W40: 낱개수량 | AA40: 비고
B41: =B13 -> 46315 | E41: =E13 -> 도)깐풍기&표고탕수1 | M41: =M13 -> 36 | Q41: =Q13 -> 2 | T41: =T13 -> 0 | W41: =W13 -> 2 | AA41: =AA13 -> 46321
E42: =E14 -> 도)딥핑치즈맵닭강정1 | M42: =M14 -> 0 | Q42: =Q14 -> 2 | T42: =T14 | W42: =W14 | AA42: =AA14 -> #VALUE!
E43: =E15 -> 도)리얼모짜치즈돈까스1 | M43: =M15 -> 30 | Q43: =Q15 -> 79 | T43: =T15 -> 2 | W43: =W15 -> 19 | AA43: =AA15 -> 46320
E44: =E16 -> 도)리얼치즈고구마돈까스1 | M44: =M16 -> 30 | Q44: =Q16 -> 14 | T44: =T16 -> 0 | W44: =W16 -> 14 | AA44: =AA16 -> 46319
E45: =E17 -> 도)윙봉칠리탕수득템1 | M45: =M17 -> 36 | Q45: =Q17 -> 18 | T45: =T17 -> 0 | W45: =W17 -> 18 | AA45: =AA17 -> 46319
E46: =E18 -> 도)찍먹윙봉1 | M46: =M18 -> 36 | Q46: =Q18 -> 3 | T46: =T18 -> 0 | W46: =W18 -> 3 | AA46: =AA18 -> 46319
E47: =E19 -> 도)찍먹탕수육1 | M47: =M19 -> 36 | Q47: =Q19 -> 0 | T47: =T19 -> 0 | W47: =W19 -> 0 | AA47: =AA19 -> 46319
E48: =E20 -> 도)치맥아보트러플치킨1 | M48: =M20 -> 32 | Q48: =Q20 -> 2 | T48: =T20 -> 0 | W48: =W20 -> 2 | AA48: =AA20 -> 46320
E49: =E21 -> 도)치즈매콤닭강정감자1 | M49: =M21 -> 30 | Q49: =Q21 -> 0 | T49: =T21 -> 0 | W49: =W21 -> 0 | AA49: =AA21 -> 46319
E50: =E22 -> 도)치즈청양간장닭강정1 | M50: =M22 -> 30 | Q50: =Q22 -> 11 | T50: =T22 -> 0 | W50: =W22 -> 11 | AA50: =AA22 -> 46319
E51: =E23 -> 도)쿵야반반닭강정팩1 | M51: =M23 -> 36 | Q51: =Q23 -> 4 | T51: =T23 -> 0 | W51: =W23 -> 4 | AA51: =AA23 -> 46320
B53: =B25 -> 총수량 | M53: =M25 -> 135
B54: =B26 -> 3자물류 (더원물류) 담당자 박병선이사 010-4448-1456 | W54: =W26 -> 전남 나주시 동수농공단지길 62-237 (운곡동) 061)334-3007

Sheet 씨제이김제(호남)
B1: 씨제이김제
B2: 거 래 명 세 표 (공급받는자 보관용)
B4: 공 급 받 는 자 | C4: 등록번호 | Q4: 공 급 자 | R4: 등록번호 | V4: 397-85-00686
C6: 상 호 (법인명) | G6: CU (BGF) | L6: 씨제이김제 | R6: 상 호 (법인명) | V6: ㈜대신에프에스 | AB6: 성 명 | AD6: 신판철
C8: 사업장 주 소 | G8: 전북 김제시 금산면 금평로 313 | R8: 사업장 주 소 | V8: 전라북도 부안군 행안면 옥여길 32-76
C10: 합계금액 (VAT포함) | R10: 업 태 | V10: 도매및 소매업 | AB10: 종 목 | AD10: 빵 과자류
B12: 년 | C12: 월 | D12: 일 | E12: 품 목 | M12: 입수 | Q12: 총수량 | T12: 박스 | W12: 낱개수량 | AA12: 비고
B13: ='하이로지스(호남) 날짜번경★'!B13 -> 46315 | E13: 도)깐풍기&표고탕수1 | M13: 36 | Q13: =IFERROR(VLOOKUP($B$1,대신피벗발주량1편!$A:$ZZ,2,FALSE),0) -> 4 | T13: =IFERROR(ROUNDDOWN(Q13/M13,0),"") -> 0 | W13: =IFERROR(Q13-(T13*M13),"") -> 4 | AA13: =B13+6 -> 46321
E14: 도)딥핑치즈맵닭강정1 | Q14: =IFERROR(VLOOKUP($B$1,대신피벗발주량1편!$A:$ZZ,3,FALSE),0) -> 4 | T14: =IFERROR(ROUNDDOWN(Q14/M14,0),"") | W14: =IFERROR(Q14-(T14*M14),"") | AA14: =B12+5 -> #VALUE!
E15: 도)리얼모짜치즈돈까스1 | M15: 30 | Q15: =IFERROR(VLOOKUP($B$1,대신피벗발주량1편!$A:$ZZ,4,FALSE),0) -> 69 | T15: =IFERROR(ROUNDDOWN(Q15/M15,0),"") -> 2 | W15: =IFERROR(Q15-(T15*M15),"") -> 9 | AA15: =B13+5 -> 46320
E16: 도)리얼치즈고구마돈까스1 | M16: 30 | Q16: =IFERROR(VLOOKUP($B$1,대신피벗발주량1편!$A:$ZZ,5,FALSE),0) -> 10 | T16: =IFERROR(ROUNDDOWN(Q16/M16,0),"") -> 0 | W16: =IFERROR(Q16-(T16*M16),"") -> 10 | AA16: =B13+5-1 -> 46319
E17: 도)윙봉칠리탕수득템1 | M17: 36 | Q17: =IFERROR(VLOOKUP($B$1,대신피벗발주량1편!$A:$ZZ,6,FALSE),0) -> 14 | T17: =IFERROR(ROUNDDOWN(Q17/M17,0),"") -> 0 | W17: =IFERROR(Q17-(T17*M17),"") -> 14 | AA17: =B13+5-1 -> 46319
E18: 도)찍먹윙봉1 | M18: 36 | Q18: =IFERROR(VLOOKUP($B$1,대신피벗발주량1편!$A:$ZZ,7,FALSE),0) -> 1 | T18: =IFERROR(ROUNDDOWN(Q18/M18,0),"") -> 0 | W18: =IFERROR(Q18-(T18*M18),"") -> 1 | AA18: =B13+5-1 -> 46319
E19: 도)찍먹탕수육1 | M19: 36 | Q19: =IFERROR(VLOOKUP($B$1,대신피벗발주량1편!$A:$ZZ,8,FALSE),0) -> 0 | T19: =IFERROR(ROUNDDOWN(Q19/M19,0),"") -> 0 | W19: =IFERROR(Q19-(T19*M19),"") -> 0 | AA19: =B13+5-1 -> 46319
E20: 도)치맥아보트러플치킨1 | M20: 32 | Q20: =IFERROR(VLOOKUP($B$1,대신피벗발주량1편!$A:$ZZ,9,FALSE),0) -> 1 | T20: =IFERROR(ROUNDDOWN(Q20/M20,0),"") -> 0 | W20: =IFERROR(Q20-(T20*M20),"") -> 1 | AA20: =B13+5 -> 46320
E21: 도)치즈매콤닭강정감자1 | M21: 30 | Q21: =IFERROR(VLOOKUP($B$1,대신피벗발주량1편!$A:$ZZ,10,FALSE),0) -> 2 | T21: =IFERROR(ROUNDDOWN(Q21/M21,0),"") -> 0 | W21: =IFERROR(Q21-(T21*M21),"") -> 2 | AA21: =B13+4 -> 46319
E22: 도)치즈청양간장닭강정1 | M22: 30 | Q22: =IFERROR(VLOOKUP($B$1,대신피벗발주량1편!$A:$ZZ,11,FALSE),0) -> 15 | T22: =IFERROR(ROUNDDOWN(Q22/M22,0),"") -> 0 | W22: =IFERROR(Q22-(T22*M22),"") -> 15 | AA22: =B13+5-1 -> 46319
E23: 도)쿵야반반닭강정팩1 | M23: 36 | Q23: =IFERROR(VLOOKUP($B$1,대신피벗발주량1편!$A:$ZZ,12,FALSE),0) -> 3 | T23: =IFERROR(ROUNDDOWN(Q23/M23,0),"") -> 0 | W23: =IFERROR(Q23-(T23*M23),"") -> 3 | AA23: =B13+5 -> 46320
B25: 총수량 | M25: =SUM(Q13:S24) -> 123
B26: 3자물류 (더원물류) 담당자 박병선이사 010-4448-1456 | W26: 전북 김제시 금산면 금평로 313 063-472-1651
B30: 거 래 명 세 표 (공급자 보관용)
B32: 공 급 받 는 자 | C32: =C4 -> 등록번호 | Q32: 공 급 자 | R32: 등록번호 | V32: =V4 -> 397-85-00686
C34: =C6 -> 상 호 (법인명) | G34: =G6 -> CU (BGF) | L34: =L6 -> 씨제이김제 | R34: 상 호 (법인명) | V34: =V6 -> ㈜대신에프에스 | AB34: 성 명 | AD34: =AD6 -> 신판철
C36: 사업장 주 소 | G36: =G8 -> 전북 김제시 금산면 금평로 313 | R36: 사업장 주 소 | V36: =V8 -> 전라북도 부안군 행안면 옥여길 32-76
C38: 합계금액 (VAT포함) | R38: 업 태 | V38: =V10 -> 도매및 소매업 | AB38: =AB10 -> 종 목 | AD38: =AD10 -> 빵 과자류
B40: 년 | C40: 월 | D40: 일 | E40: 품 목 | M40: 입수 | Q40: 총수량 | T40: 박스 | W40: 낱개수량 | AA40: 비고
B41: =B13 -> 46315 | E41: =E13 -> 도)깐풍기&표고탕수1 | M41: =M13 -> 36 | Q41: =Q13 -> 4 | T41: =T13 -> 0 | W41: =W13 -> 4 | AA41: =AA13 -> 46321
E42: =E14 -> 도)딥핑치즈맵닭강정1 | M42: =M14 -> 0 | Q42: =Q14 -> 4 | T42: =T14 | W42: =W14 | AA42: =AA14 -> #VALUE!
E43: =E15 -> 도)리얼모짜치즈돈까스1 | M43: =M15 -> 30 | Q43: =Q15 -> 69 | T43: =T15 -> 2 | W43: =W15 -> 9 | AA43: =AA15 -> 46320
E44: =E16 -> 도)리얼치즈고구마돈까스1 | M44: =M16 -> 30 | Q44: =Q16 -> 10 | T44: =T16 -> 0 | W44: =W16 -> 10 | AA44: =AA16 -> 46319
E45: =E17 -> 도)윙봉칠리탕수득템1 | M45: =M17 -> 36 | Q45: =Q17 -> 14 | T45: =T17 -> 0 | W45: =W17 -> 14 | AA45: =AA17 -> 46319
E46: =E18 -> 도)찍먹윙봉1 | M46: =M18 -> 36 | Q46: =Q18 -> 1 | T46: =T18 -> 0 | W46: =W18 -> 1 | AA46: =AA18 -> 46319
E47: =E19 -> 도)찍먹탕수육1 | M47: =M19 -> 36 | Q47: =Q19 -> 0 | T47: =T19 -> 0 | W47: =W19 -> 0 | AA47: =AA19 -> 46319
E48: =E20 -> 도)치맥아보트러플치킨1 | M48: =M20 -> 32 | Q48: =Q20 -> 1 | T48: =T20 -> 0 | W48: =W20 -> 1 | AA48: =AA20 -> 46320
E49: =E21 -> 도)치즈매콤닭강정감자1 | M49: =M21 -> 30 | Q49: =Q21 -> 2 | T49: =T21 -> 0 | W49: =W21 -> 2 | AA49: =AA21 -> 46319
E50: =E22 -> 도)치즈청양간장닭강정1 | M50: =M22 -> 30 | Q50: =Q22 -> 15 | T50: =T22 -> 0 | W50: =W22 -> 15 | AA50: =AA22 -> 46319
E51: =E23 -> 도)쿵야반반닭강정팩1 | M51: =M23 -> 36 | Q51: =Q23 -> 3 | T51: =T23 -> 0 | W51: =W23 -> 3 | AA51: =AA23 -> 46320
B53: =B25 -> 총수량 | M53: =M25 -> 123
B54: =B26 -> 3자물류 (더원물류) 담당자 박병선이사 010-4448-1456 | W54: =W26 -> 전북 김제시 금산면 금평로 313 063-472-1651

Sheet BGF로지스대구(영남)
B1: BGF로지스대구
B2: 거 래 명 세 표 (공급받는자 보관용)
B4: 공 급 받 는 자 | C4: 등록번호 | Q4: 공 급 자 | R4: 등록번호 | V4: 397-85-00686
C6: 상 호 (법인명) | G6: CU (BGF) | L6: BGF로지스대구 | R6: 상 호 (법인명) | V6: ㈜대신에프에스 | AB6: 성 명 | AD6: 신판철
C8: 사업장 주 소 | G8: 경상북도 칠곡군 석적읍 호국로 608 | R8: 사업장 주 소 | V8: 전라북도 부안군 행안면 옥여길 32-76
C10: 합계금액 (VAT포함) | R10: 업 태 | V10: 도매및 소매업 | AB10: 종 목 | AD10: 빵 과자류
B12: 년 | C12: 월 | D12: 일 | E12: 품 목 | M12: 입수 | Q12: 총수량 | T12: 박스 | W12: 낱개수량 | AA12: 비고
B13: ='하이로지스(호남) 날짜번경★'!B13 -> 46315 | E13: 도)깐풍기&표고탕수1 | M13: 36 | Q13: =IFERROR(VLOOKUP($B$1,대신피벗발주량1편!$A:$ZZ,2,FALSE),0) -> 5 | T13: =IFERROR(ROUNDDOWN(Q13/M13,0),"") -> 0 | W13: =IFERROR(Q13-(T13*M13),"") -> 5 | AA13: =B13+6 -> 46321
E14: 도)딥핑치즈맵닭강정1 | Q14: =IFERROR(VLOOKUP($B$1,대신피벗발주량1편!$A:$ZZ,3,FALSE),0) -> 5 | T14: =IFERROR(ROUNDDOWN(Q14/M14,0),"") | W14: =IFERROR(Q14-(T14*M14),"") | AA14: =B12+5 -> #VALUE!
E15: 도)리얼모짜치즈돈까스1 | M15: 30 | Q15: =IFERROR(VLOOKUP($B$1,대신피벗발주량1편!$A:$ZZ,4,FALSE),0) -> 107 | T15: =IFERROR(ROUNDDOWN(Q15/M15,0),"") -> 3 | W15: =IFERROR(Q15-(T15*M15),"") -> 17 | AA15: =B13+5 -> 46320
E16: 도)리얼치즈고구마돈까스1 | M16: 30 | Q16: =IFERROR(VLOOKUP($B$1,대신피벗발주량1편!$A:$ZZ,5,FALSE),0) -> 11 | T16: =IFERROR(ROUNDDOWN(Q16/M16,0),"") -> 0 | W16: =IFERROR(Q16-(T16*M16),"") -> 11 | AA16: =B13+5-1 -> 46319
E17: 도)윙봉칠리탕수득템1 | M17: 36 | Q17: =IFERROR(VLOOKUP($B$1,대신피벗발주량1편!$A:$ZZ,6,FALSE),0) -> 27 | T17: =IFERROR(ROUNDDOWN(Q17/M17,0),"") -> 0 | W17: =IFERROR(Q17-(T17*M17),"") -> 27 | AA17: =B13+5-1 -> 46319
E18: 도)찍먹윙봉1 | M18: 36 | Q18: =IFERROR(VLOOKUP($B$1,대신피벗발주량1편!$A:$ZZ,7,FALSE),0) -> 2 | T18: =IFERROR(ROUNDDOWN(Q18/M18,0),"") -> 0 | W18: =IFERROR(Q18-(T18*M18),"") -> 2 | AA18: =B13+5-1 -> 46319
E19: 도)찍먹탕수육1 | M19: 36 | Q19: =IFERROR(VLOOKUP($B$1,대신피벗발주량1편!$A:$ZZ,8,FALSE),0) -> 3 | T19: =IFERROR(ROUNDDOWN(Q19/M19,0),"") -> 0 | W19: =IFERROR(Q19-(T19*M19),"") -> 3 | AA19: =B13+5-1 -> 46319
E20: 도)치맥아보트러플치킨1 | M20: 32 | Q20: =IFERROR(VLOOKUP($B$1,대신피벗발주량1편!$A:$ZZ,9,FALSE),0) -> 6 | T20: =IFERROR(ROUNDDOWN(Q20/M20,0),"") -> 0 | W20: =IFERROR(Q20-(T20*M20),"") -> 6 | AA20: =B13+5 -> 46320
E21: 도)치즈매콤닭강정감자1 | M21: 30 | Q21: =IFERROR(VLOOKUP($B$1,대신피벗발주량1편!$A:$ZZ,10,FALSE),0) -> 2 | T21: =IFERROR(ROUNDDOWN(Q21/M21,0),"") -> 0 | W21: =IFERROR(Q21-(T21*M21),"") -> 2 | AA21: =B13+4 -> 46319
E22: 도)치즈청양간장닭강정1 | M22: 30 | Q22: =IFERROR(VLOOKUP($B$1,대신피벗발주량1편!$A:$ZZ,11,FALSE),0) -> 21 | T22: =IFERROR(ROUNDDOWN(Q22/M22,0),"") -> 0 | W22: =IFERROR(Q22-(T22*M22),"") -> 21 | AA22: =B13+5-1 -> 46319
E23: 도)쿵야반반닭강정팩1 | M23: 36 | Q23: =IFERROR(VLOOKUP($B$1,대신피벗발주량1편!$A:$ZZ,12,FALSE),0) -> 7 | T23: =IFERROR(ROUNDDOWN(Q23/M23,0),"") -> 0 | W23: =IFERROR(Q23-(T23*M23),"") -> 7 | AA23: =B13+5 -> 46320
B25: 총수량 | M25: =SUM(Q13:S24) -> 196
B26: 3자물류 (더원물류) 담당자 박병선이사 010-4448-1456 | W26: 경상북도 칠곡군 석적읍 호국로 608 054)974-7443
B30: 거 래 명 세 표 (공급자 보관용)
B32: 공 급 받 는 자 | C32: =C4 -> 등록번호 | Q32: 공 급 자 | R32: 등록번호 | V32: =V4 -> 397-85-00686
C34: =C6 -> 상 호 (법인명) | G34: =G6 -> CU (BGF) | L34: =L6 -> BGF로지스대구 | R34: 상 호 (법인명) | V34: =V6 -> ㈜대신에프에스 | AB34: 성 명 | AD34: =AD6 -> 신판철
C36: 사업장 주 소 | G36: =G8 -> 경상북도 칠곡군 석적읍 호국로 608 | R36: 사업장 주 소 | V36: =V8 -> 전라북도 부안군 행안면 옥여길 32-76
C38: 합계금액 (VAT포함) | R38: 업 태 | V38: =V10 -> 도매및 소매업 | AB38: =AB10 -> 종 목 | AD38: =AD10 -> 빵 과자류
B40: 년 | C40: 월 | D40: 일 | E40: 품 목 | M40: 입수 | Q40: 총수량 | T40: 박스 | W40: 낱개수량 | AA40: 비고
B41: =B13 -> 46315 | E41: =E13 -> 도)깐풍기&표고탕수1 | M41: =M13 -> 36 | Q41: =Q13 -> 5 | T41: =T13 -> 0 | W41: =W13 -> 5 | AA41: =AA13 -> 46321
E42: =E14 -> 도)딥핑치즈맵닭강정1 | M42: =M14 -> 0 | Q42: =Q14 -> 5 | T42: =T14 | W42: =W14 | AA42: =AA14 -> #VALUE!
E43: =E15 -> 도)리얼모짜치즈돈까스1 | M43: =M15 -> 30 | Q43: =Q15 -> 107 | T43: =T15 -> 3 | W43: =W15 -> 17 | AA43: =AA15 -> 46320
E44: =E16 -> 도)리얼치즈고구마돈까스1 | M44: =M16 -> 30 | Q44: =Q16 -> 11 | T44: =T16 -> 0 | W44: =W16 -> 11 | AA44: =AA16 -> 46319
E45: =E17 -> 도)윙봉칠리탕수득템1 | M45: =M17 -> 36 | Q45: =Q17 -> 27 | T45: =T17 -> 0 | W45: =W17 -> 27 | AA45: =AA17 -> 46319
E46: =E18 -> 도)찍먹윙봉1 | M46: =M18 -> 36 | Q46: =Q18 -> 2 | T46: =T18 -> 0 | W46: =W18 -> 2 | AA46: =AA18 -> 46319
E47: =E19 -> 도)찍먹탕수육1 | M47: =M19 -> 36 | Q47: =Q19 -> 3 | T47: =T19 -> 0 | W47: =W19 -> 3 | AA47: =AA19 -> 46319
E48: =E20 -> 도)치맥아보트러플치킨1 | M48: =M20 -> 32 | Q48: =Q20 -> 6 | T48: =T20 -> 0 | W48: =W20 -> 6 | AA48: =AA20 -> 46320
E49: =E21 -> 도)치즈매콤닭강정감자1 | M49: =M21 -> 30 | Q49: =Q21 -> 2 | T49: =T21 -> 0 | W49: =W21 -> 2 | AA49: =AA21 -> 46319
E50: =E22 -> 도)치즈청양간장닭강정1 | M50: =M22 -> 30 | Q50: =Q22 -> 21 | T50: =T22 -> 0 | W50: =W22 -> 21 | AA50: =AA22 -> 46319
E51: =E23 -> 도)쿵야반반닭강정팩1 | M51: =M23 -> 36 | Q51: =Q23 -> 7 | T51: =T23 -> 0 | W51: =W23 -> 7 | AA51: =AA23 -> 46320
B53: =B25 -> 총수량 | M53: =M25 -> 196
B54: =B26 -> 3자물류 (더원물류) 담당자 박병선이사 010-4448-1456 | W54: =W26 -> 경상북도 칠곡군 석적읍 호국로 608 054)974-7443

Sheet 극동로지스(영남)
B1: 극동로지스
B2: 거 래 명 세 표 (공급받는자 보관용)
B4: 공 급 받 는 자 | C4: 등록번호 | Q4: 공 급 자 | R4: 등록번호 | V4: 397-85-00686
C6: 상 호 (법인명) | G6: CU (BGF) | L6: 극동로지스 | R6: 상 호 (법인명) | V6: ㈜대신에프에스 | AB6: 성 명 | AD6: 신판철
C8: 사업장 주 소 | G8: 경남 김해시 생림면 인제로 661 | R8: 사업장 주 소 | V8: 전라북도 부안군 행안면 옥여길 32-76
C10: 합계금액 (VAT포함) | R10: 업 태 | V10: 도매및 소매업 | AB10: 종 목 | AD10: 빵 과자류
B12: 년 | C12: 월 | D12: 일 | E12: 품 목 | M12: 입수 | Q12: 총수량 | T12: 박스 | W12: 낱개수량 | AA12: 비고
B13: ='하이로지스(호남) 날짜번경★'!B13 -> 46315 | E13: 도)깐풍기&표고탕수1 | M13: 36 | Q13: =IFERROR(VLOOKUP($B$1,대신피벗발주량1편!$A:$ZZ,2,FALSE),0) -> 0 | T13: =IFERROR(ROUNDDOWN(Q13/M13,0),"") -> 0 | W13: =IFERROR(Q13-(T13*M13),"") -> 0 | AA13: =B13+6 -> 46321
E14: 도)딥핑치즈맵닭강정1 | Q14: =IFERROR(VLOOKUP($B$1,대신피벗발주량1편!$A:$ZZ,3,FALSE),0) -> 0 | T14: =IFERROR(ROUNDDOWN(Q14/M14,0),"") | W14: =IFERROR(Q14-(T14*M14),"") | AA14: =B12+5 -> #VALUE!
E15: 도)리얼모짜치즈돈까스1 | M15: 30 | Q15: =IFERROR(VLOOKUP($B$1,대신피벗발주량1편!$A:$ZZ,4,FALSE),0) -> 88 | T15: =IFERROR(ROUNDDOWN(Q15/M15,0),"") -> 2 | W15: =IFERROR(Q15-(T15*M15),"") -> 28 | AA15: =B13+5 -> 46320
E16: 도)리얼치즈고구마돈까스1 | M16: 30 | Q16: =IFERROR(VLOOKUP($B$1,대신피벗발주량1편!$A:$ZZ,5,FALSE),0) -> 6 | T16: =IFERROR(ROUNDDOWN(Q16/M16,0),"") -> 0 | W16: =IFERROR(Q16-(T16*M16),"") -> 6 | AA16: =B13+5-1 -> 46319
E17: 도)윙봉칠리탕수득템1 | M17: 36 | Q17: =IFERROR(VLOOKUP($B$1,대신피벗발주량1편!$A:$ZZ,6,FALSE),0) -> 12 | T17: =IFERROR(ROUNDDOWN(Q17/M17,0),"") -> 0 | W17: =IFERROR(Q17-(T17*M17),"") -> 12 | AA17: =B13+5-1 -> 46319
E18: 도)찍먹윙봉1 | M18: 36 | Q18: =IFERROR(VLOOKUP($B$1,대신피벗발주량1편!$A:$ZZ,7,FALSE),0) -> 1 | T18: =IFERROR(ROUNDDOWN(Q18/M18,0),"") -> 0 | W18: =IFERROR(Q18-(T18*M18),"") -> 1 | AA18: =B13+5-1 -> 46319
E19: 도)찍먹탕수육1 | M19: 36 | Q19: =IFERROR(VLOOKUP($B$1,대신피벗발주량1편!$A:$ZZ,8,FALSE),0) -> 2 | T19: =IFERROR(ROUNDDOWN(Q19/M19,0),"") -> 0 | W19: =IFERROR(Q19-(T19*M19),"") -> 2 | AA19: =B13+5-1 -> 46319
E20: 도)치맥아보트러플치킨1 | M20: 32 | Q20: =IFERROR(VLOOKUP($B$1,대신피벗발주량1편!$A:$ZZ,9,FALSE),0) -> 0 | T20: =IFERROR(ROUNDDOWN(Q20/M20,0),"") -> 0 | W20: =IFERROR(Q20-(T20*M20),"") -> 0 | AA20: =B13+5 -> 46320
E21: 도)치즈매콤닭강정감자1 | M21: 30 | Q21: =IFERROR(VLOOKUP($B$1,대신피벗발주량1편!$A:$ZZ,10,FALSE),0) -> 1 | T21: =IFERROR(ROUNDDOWN(Q21/M21,0),"") -> 0 | W21: =IFERROR(Q21-(T21*M21),"") -> 1 | AA21: =B13+4 -> 46319
E22: 도)치즈청양간장닭강정1 | M22: 30 | Q22: =IFERROR(VLOOKUP($B$1,대신피벗발주량1편!$A:$ZZ,11,FALSE),0) -> 16 | T22: =IFERROR(ROUNDDOWN(Q22/M22,0),"") -> 0 | W22: =IFERROR(Q22-(T22*M22),"") -> 16 | AA22: =B13+5-1 -> 46319
E23: 도)쿵야반반닭강정팩1 | M23: 36 | Q23: =IFERROR(VLOOKUP($B$1,대신피벗발주량1편!$A:$ZZ,12,FALSE),0) -> 3 | T23: =IFERROR(ROUNDDOWN(Q23/M23,0),"") -> 0 | W23: =IFERROR(Q23-(T23*M23),"") -> 3 | AA23: =B13+5 -> 46320
B25: 총수량 | M25: =SUM(Q13:S24) -> 129
B26: 3자물류 (더원물류) 담당자 박병선이사 010-4448-1456 | W26: 경남 김해시 생림면 인제로 661 055)325-4064
B30: 거 래 명 세 표 (공급자 보관용)
B32: 공 급 받 는 자 | C32: =C4 -> 등록번호 | Q32: 공 급 자 | R32: 등록번호 | V32: =V4 -> 397-85-00686
C34: =C6 -> 상 호 (법인명) | G34: =G6 -> CU (BGF) | L34: =L6 -> 극동로지스 | R34: 상 호 (법인명) | V34: =V6 -> ㈜대신에프에스 | AB34: 성 명 | AD34: =AD6 -> 신판철
C36: 사업장 주 소 | G36: =G8 -> 경남 김해시 생림면 인제로 661 | R36: 사업장 주 소 | V36: =V8 -> 전라북도 부안군 행안면 옥여길 32-76
C38: 합계금액 (VAT포함) | R38: 업 태 | V38: =V10 -> 도매및 소매업 | AB38: =AB10 -> 종 목 | AD38: =AD10 -> 빵 과자류
B40: 년 | C40: 월 | D40: 일 | E40: 품 목 | M40: 입수 | Q40: 총수량 | T40: 박스 | W40: 낱개수량 | AA40: 비고
B41: =B13 -> 46315 | E41: =E13 -> 도)깐풍기&표고탕수1 | M41: =M13 -> 36 | Q41: =Q13 -> 0 | T41: =T13 -> 0 | W41: =W13 -> 0 | AA41: =AA13 -> 46321
E42: =E14 -> 도)딥핑치즈맵닭강정1 | M42: =M14 -> 0 | Q42: =Q14 -> 0 | T42: =T14 | W42: =W14 | AA42: =AA14 -> #VALUE!
E43: =E15 -> 도)리얼모짜치즈돈까스1 | M43: =M15 -> 30 | Q43: =Q15 -> 88 | T43: =T15 -> 2 | W43: =W15 -> 28 | AA43: =AA15 -> 46320
E44: =E16 -> 도)리얼치즈고구마돈까스1 | M44: =M16 -> 30 | Q44: =Q16 -> 6 | T44: =T16 -> 0 | W44: =W16 -> 6 | AA44: =AA16 -> 46319
E45: =E17 -> 도)윙봉칠리탕수득템1 | M45: =M17 -> 36 | Q45: =Q17 -> 12 | T45: =T17 -> 0 | W45: =W17 -> 12 | AA45: =AA17 -> 46319
E46: =E18 -> 도)찍먹윙봉1 | M46: =M18 -> 36 | Q46: =Q18 -> 1 | T46: =T18 -> 0 | W46: =W18 -> 1 | AA46: =AA18 -> 46319
E47: =E19 -> 도)찍먹탕수육1 | M47: =M19 -> 36 | Q47: =Q19 -> 2 | T47: =T19 -> 0 | W47: =W19 -> 2 | AA47: =AA19 -> 46319
E48: =E20 -> 도)치맥아보트러플치킨1 | M48: =M20 -> 32 | Q48: =Q20 -> 0 | T48: =T20 -> 0 | W48: =W20 -> 0 | AA48: =AA20 -> 46320
E49: =E21 -> 도)치즈매콤닭강정감자1 | M49: =M21 -> 30 | Q49: =Q21 -> 1 | T49: =T21 -> 0 | W49: =W21 -> 1 | AA49: =AA21 -> 46319
E50: =E22 -> 도)치즈청양간장닭강정1 | M50: =M22 -> 30 | Q50: =Q22 -> 16 | T50: =T22 -> 0 | W50: =W22 -> 16 | AA50: =AA22 -> 46319
E51: =E23 -> 도)쿵야반반닭강정팩1 | M51: =M23 -> 36 | Q51: =Q23 -> 3 | T51: =T23 -> 0 | W51: =W23 -> 3 | AA51: =AA23 -> 46320
B53: =B25 -> 총수량 | M53: =M25 -> 129
B54: =B26 -> 3자물류 (더원물류) 담당자 박병선이사 010-4448-1456 | W54: =W26 -> 경남 김해시 생림면 인제로 661 055)325-4064

Sheet BGF로지스진주(영남)
B1: BGF로지스진주
B2: 거 래 명 세 표 (공급받는자 보관용)
B4: 공 급 받 는 자 | C4: 등록번호 | Q4: 공 급 자 | R4: 등록번호 | V4: 397-85-00686
C6: 상 호 (법인명) | G6: CU (BGF) | L6: BGF로지스진주 | R6: 상 호 (법인명) | V6: ㈜대신에프에스 | AB6: 성 명 | AD6: 신판철
C8: 사업장 주 소 | G8: 경남 진주시 정촌면 화개천로 50 | R8: 사업장 주 소 | V8: 전라북도 부안군 행안면 옥여길 32-76
C10: 합계금액 (VAT포함) | R10: 업 태 | V10: 도매및 소매업 | AB10: 종 목 | AD10: 빵 과자류
B12: 년 | C12: 월 | D12: 일 | E12: 품 목 | M12: 입수 | Q12: 총수량 | T12: 박스 | W12: 낱개수량 | AA12: 비고
B13: ='하이로지스(호남) 날짜번경★'!B13 -> 46315 | E13: 도)깐풍기&표고탕수1 | M13: 36 | Q13: =IFERROR(VLOOKUP($B$1,대신피벗발주량1편!$A:$ZZ,2,FALSE),0) -> 2 | T13: =IFERROR(ROUNDDOWN(Q13/M13,0),"") -> 0 | W13: =IFERROR(Q13-(T13*M13),"") -> 2 | AA13: =B13+6 -> 46321
E14: 도)딥핑치즈맵닭강정1 | Q14: =IFERROR(VLOOKUP($B$1,대신피벗발주량1편!$A:$ZZ,3,FALSE),0) -> 2 | T14: =IFERROR(ROUNDDOWN(Q14/M14,0),"") | W14: =IFERROR(Q14-(T14*M14),"") | AA14: =B12+5 -> #VALUE!
E15: 도)리얼모짜치즈돈까스1 | M15: 30 | Q15: =IFERROR(VLOOKUP($B$1,대신피벗발주량1편!$A:$ZZ,4,FALSE),0) -> 80 | T15: =IFERROR(ROUNDDOWN(Q15/M15,0),"") -> 2 | W15: =IFERROR(Q15-(T15*M15),"") -> 20 | AA15: =B13+5 -> 46320
E16: 도)리얼치즈고구마돈까스1 | M16: 30 | Q16: =IFERROR(VLOOKUP($B$1,대신피벗발주량1편!$A:$ZZ,5,FALSE),0) -> 6 | T16: =IFERROR(ROUNDDOWN(Q16/M16,0),"") -> 0 | W16: =IFERROR(Q16-(T16*M16),"") -> 6 | AA16: =B13+5-1 -> 46319
E17: 도)윙봉칠리탕수득템1 | M17: 36 | Q17: =IFERROR(VLOOKUP($B$1,대신피벗발주량1편!$A:$ZZ,6,FALSE),0) -> 15 | T17: =IFERROR(ROUNDDOWN(Q17/M17,0),"") -> 0 | W17: =IFERROR(Q17-(T17*M17),"") -> 15 | AA17: =B13+5-1 -> 46319
E18: 도)찍먹윙봉1 | M18: 36 | Q18: =IFERROR(VLOOKUP($B$1,대신피벗발주량1편!$A:$ZZ,7,FALSE),0) -> 0 | T18: =IFERROR(ROUNDDOWN(Q18/M18,0),"") -> 0 | W18: =IFERROR(Q18-(T18*M18),"") -> 0 | AA18: =B13+5-1 -> 46319
E19: 도)찍먹탕수육1 | M19: 36 | Q19: =IFERROR(VLOOKUP($B$1,대신피벗발주량1편!$A:$ZZ,8,FALSE),0) -> 4 | T19: =IFERROR(ROUNDDOWN(Q19/M19,0),"") -> 0 | W19: =IFERROR(Q19-(T19*M19),"") -> 4 | AA19: =B13+5-1 -> 46319
E20: 도)치맥아보트러플치킨1 | M20: 32 | Q20: =IFERROR(VLOOKUP($B$1,대신피벗발주량1편!$A:$ZZ,9,FALSE),0) -> 4 | T20: =IFERROR(ROUNDDOWN(Q20/M20,0),"") -> 0 | W20: =IFERROR(Q20-(T20*M20),"") -> 4 | AA20: =B13+5 -> 46320
E21: 도)치즈매콤닭강정감자1 | M21: 30 | Q21: =IFERROR(VLOOKUP($B$1,대신피벗발주량1편!$A:$ZZ,10,FALSE),0) -> 1 | T21: =IFERROR(ROUNDDOWN(Q21/M21,0),"") -> 0 | W21: =IFERROR(Q21-(T21*M21),"") -> 1 | AA21: =B13+4 -> 46319
E22: 도)치즈청양간장닭강정1 | M22: 30 | Q22: =IFERROR(VLOOKUP($B$1,대신피벗발주량1편!$A:$ZZ,11,FALSE),0) -> 14 | T22: =IFERROR(ROUNDDOWN(Q22/M22,0),"") -> 0 | W22: =IFERROR(Q22-(T22*M22),"") -> 14 | AA22: =B13+5-1 -> 46319
E23: 도)쿵야반반닭강정팩1 | M23: 36 | Q23: =IFERROR(VLOOKUP($B$1,대신피벗발주량1편!$A:$ZZ,12,FALSE),0) -> 4 | T23: =IFERROR(ROUNDDOWN(Q23/M23,0),"") -> 0 | W23: =IFERROR(Q23-(T23*M23),"") -> 4 | AA23: =B13+5 -> 46320
B25: 총수량 | M25: =SUM(Q13:S24) -> 132
B26: 3자물류 (더원물류) 담당자 박병선이사 010-4448-1456 | W26: 경남 진주시 정촌면 화개천로 50 055)795-2500
B30: 거 래 명 세 표 (공급자 보관용)
B32: 공 급 받 는 자 | C32: =C4 -> 등록번호 | Q32: 공 급 자 | R32: 등록번호 | V32: =V4 -> 397-85-00686
C34: =C6 -> 상 호 (법인명) | G34: =G6 -> CU (BGF) | L34: =L6 -> BGF로지스진주 | R34: 상 호 (법인명) | V34: =V6 -> ㈜대신에프에스 | AB34: 성 명 | AD34: =AD6 -> 신판철
C36: 사업장 주 소 | G36: =G8 -> 경남 진주시 정촌면 화개천로 50 | R36: 사업장 주 소 | V36: =V8 -> 전라북도 부안군 행안면 옥여길 32-76
C38: 합계금액 (VAT포함) | R38: 업 태 | V38: =V10 -> 도매및 소매업 | AB38: =AB10 -> 종 목 | AD38: =AD10 -> 빵 과자류
B40: 년 | C40: 월 | D40: 일 | E40: 품 목 | M40: 입수 | Q40: 총수량 | T40: 박스 | W40: 낱개수량 | AA40: 비고
B41: =B13 -> 46315 | E41: =E13 -> 도)깐풍기&표고탕수1 | M41: =M13 -> 36 | Q41: =Q13 -> 2 | T41: =T13 -> 0 | W41: =W13 -> 2 | AA41: =AA13 -> 46321
E42: =E14 -> 도)딥핑치즈맵닭강정1 | M42: =M14 -> 0 | Q42: =Q14 -> 2 | T42: =T14 | W42: =W14 | AA42: =AA14 -> #VALUE!
E43: =E15 -> 도)리얼모짜치즈돈까스1 | M43: =M15 -> 30 | Q43: =Q15 -> 80 | T43: =T15 -> 2 | W43: =W15 -> 20 | AA43: =AA15 -> 46320
E44: =E16 -> 도)리얼치즈고구마돈까스1 | M44: =M16 -> 30 | Q44: =Q16 -> 6 | T44: =T16 -> 0 | W44: =W16 -> 6 | AA44: =AA16 -> 46319
E45: =E17 -> 도)윙봉칠리탕수득템1 | M45: =M17 -> 36 | Q45: =Q17 -> 15 | T45: =T17 -> 0 | W45: =W17 -> 15 | AA45: =AA17 -> 46319
E46: =E18 -> 도)찍먹윙봉1 | M46: =M18 -> 36 | Q46: =Q18 -> 0 | T46: =T18 -> 0 | W46: =W18 -> 0 | AA46: =AA18 -> 46319
E47: =E19 -> 도)찍먹탕수육1 | M47: =M19 -> 36 | Q47: =Q19 -> 4 | T47: =T19 -> 0 | W47: =W19 -> 4 | AA47: =AA19 -> 46319
E48: =E20 -> 도)치맥아보트러플치킨1 | M48: =M20 -> 32 | Q48: =Q20 -> 4 | T48: =T20 -> 0 | W48: =W20 -> 4 | AA48: =AA20 -> 46320
E49: =E21 -> 도)치즈매콤닭강정감자1 | M49: =M21 -> 30 | Q49: =Q21 -> 1 | T49: =T21 -> 0 | W49: =W21 -> 1 | AA49: =AA21 -> 46319
E50: =E22 -> 도)치즈청양간장닭강정1 | M50: =M22 -> 30 | Q50: =Q22 -> 14 | T50: =T22 -> 0 | W50: =W22 -> 14 | AA50: =AA22 -> 46319
E51: =E23 -> 도)쿵야반반닭강정팩1 | M51: =M23 -> 36 | Q51: =Q23 -> 4 | T51: =T23 -> 0 | W51: =W23 -> 4 | AA51: =AA23 -> 46320
B53: =B25 -> 총수량 | M53: =M25 -> 132
B54: =B26 -> 3자물류 (더원물류) 담당자 박병선이사 010-4448-1456 | W54: =W26 -> 경남 진주시 정촌면 화개천로 50 055)795-2500

Sheet 엑소후레쉬양산(영남)
B1: 엑소후레쉬양산
B2: 거 래 명 세 표 (공급받는자 보관용)
B4: 공 급 받 는 자 | C4: 등록번호 | Q4: 공 급 자 | R4: 등록번호 | V4: 397-85-00686
C6: 상 호 (법인명) | G6: CU (BGF) | L6: 엑소후레쉬양산 | R6: 상 호 (법인명) | V6: ㈜대신에프에스 | AB6: 성 명 | AD6: 신판철
C8: 사업장 주 소 | G8: 울산광역시 울주군 삼동면 조일리 1341-6번지 | R8: 사업장 주 소 | V8: 전라북도 부안군 행안면 옥여길 32-76
C10: 합계금액 (VAT포함) | R10: 업 태 | V10: 도매및 소매업 | AB10: 종 목 | AD10: 빵 과자류
B12: 년 | C12: 월 | D12: 일 | E12: 품 목 | M12: 입수 | Q12: 총수량 | T12: 박스 | W12: 낱개수량 | AA12: 비고
B13: ='하이로지스(호남) 날짜번경★'!B13 -> 46315 | E13: 도)깐풍기&표고탕수1 | M13: 36 | Q13: =IFERROR(VLOOKUP($B$1,대신피벗발주량1편!$A:$ZZ,2,FALSE),0) -> 5 | T13: =IFERROR(ROUNDDOWN(Q13/M13,0),"") -> 0 | W13: =IFERROR(Q13-(T13*M13),"") -> 5 | AA13: =B13+6 -> 46321
E14: 도)딥핑치즈맵닭강정1 | Q14: =IFERROR(VLOOKUP($B$1,대신피벗발주량1편!$A:$ZZ,3,FALSE),0) -> 5 | T14: =IFERROR(ROUNDDOWN(Q14/M14,0),"") | W14: =IFERROR(Q14-(T14*M14),"") | AA14: =B12+5 -> #VALUE!
E15: 도)리얼모짜치즈돈까스1 | M15: 30 | Q15: =IFERROR(VLOOKUP($B$1,대신피벗발주량1편!$A:$ZZ,4,FALSE),0) -> 152 | T15: =IFERROR(ROUNDDOWN(Q15/M15,0),"") -> 5 | W15: =IFERROR(Q15-(T15*M15),"") -> 2 | AA15: =B13+5 -> 46320
E16: 도)리얼치즈고구마돈까스1 | M16: 30 | Q16: =IFERROR(VLOOKUP($B$1,대신피벗발주량1편!$A:$ZZ,5,FALSE),0) -> 16 | T16: =IFERROR(ROUNDDOWN(Q16/M16,0),"") -> 0 | W16: =IFERROR(Q16-(T16*M16),"") -> 16 | AA16: =B13+5-1 -> 46319
E17: 도)윙봉칠리탕수득템1 | M17: 36 | Q17: =IFERROR(VLOOKUP($B$1,대신피벗발주량1편!$A:$ZZ,6,FALSE),0) -> 14 | T17: =IFERROR(ROUNDDOWN(Q17/M17,0),"") -> 0 | W17: =IFERROR(Q17-(T17*M17),"") -> 14 | AA17: =B13+5-1 -> 46319
E18: 도)찍먹윙봉1 | M18: 36 | Q18: =IFERROR(VLOOKUP($B$1,대신피벗발주량1편!$A:$ZZ,7,FALSE),0) -> 3 | T18: =IFERROR(ROUNDDOWN(Q18/M18,0),"") -> 0 | W18: =IFERROR(Q18-(T18*M18),"") -> 3 | AA18: =B13+5-1 -> 46319
E19: 도)찍먹탕수육1 | M19: 36 | Q19: =IFERROR(VLOOKUP($B$1,대신피벗발주량1편!$A:$ZZ,8,FALSE),0) -> 1 | T19: =IFERROR(ROUNDDOWN(Q19/M19,0),"") -> 0 | W19: =IFERROR(Q19-(T19*M19),"") -> 1 | AA19: =B13+5-1 -> 46319
E20: 도)치맥아보트러플치킨1 | M20: 32 | Q20: =IFERROR(VLOOKUP($B$1,대신피벗발주량1편!$A:$ZZ,9,FALSE),0) -> 8 | T20: =IFERROR(ROUNDDOWN(Q20/M20,0),"") -> 0 | W20: =IFERROR(Q20-(T20*M20),"") -> 8 | AA20: =B13+5 -> 46320
E21: 도)치즈매콤닭강정감자1 | M21: 30 | Q21: =IFERROR(VLOOKUP($B$1,대신피벗발주량1편!$A:$ZZ,10,FALSE),0) -> 2 | T21: =IFERROR(ROUNDDOWN(Q21/M21,0),"") -> 0 | W21: =IFERROR(Q21-(T21*M21),"") -> 2 | AA21: =B13+4 -> 46319
E22: 도)치즈청양간장닭강정1 | M22: 30 | Q22: =IFERROR(VLOOKUP($B$1,대신피벗발주량1편!$A:$ZZ,11,FALSE),0) -> 15 | T22: =IFERROR(ROUNDDOWN(Q22/M22,0),"") -> 0 | W22: =IFERROR(Q22-(T22*M22),"") -> 15 | AA22: =B13+5-1 -> 46319
E23: 도)쿵야반반닭강정팩1 | M23: 36 | Q23: =IFERROR(VLOOKUP($B$1,대신피벗발주량1편!$A:$ZZ,12,FALSE),0) -> 3 | T23: =IFERROR(ROUNDDOWN(Q23/M23,0),"") -> 0 | W23: =IFERROR(Q23-(T23*M23),"") -> 3 | AA23: =B13+5 -> 46320
B25: 총수량 | M25: =SUM(Q13:S24) -> 224
B26: 3자물류 (더원물류) 담당자 박병선이사 010-4448-1456 | W26: 울산광역시 울주군 삼동면 조일리 1341-6번지 070)7119-5178
B30: 거 래 명 세 표 (공급자 보관용)
B32: 공 급 받 는 자 | C32: =C4 -> 등록번호 | Q32: 공 급 자 | R32: 등록번호 | V32: =V4 -> 397-85-00686
C34: =C6 -> 상 호 (법인명) | G34: =G6 -> CU (BGF) | L34: =L6 -> 엑소후레쉬양산 | R34: 상 호 (법인명) | V34: =V6 -> ㈜대신에프에스 | AB34: 성 명 | AD34: =AD6 -> 신판철
C36: 사업장 주 소 | G36: =G8 -> 울산광역시 울주군 삼동면 조일리 1341-6번지 | R36: 사업장 주 소 | V36: =V8 -> 전라북도 부안군 행안면 옥여길 32-76
C38: 합계금액 (VAT포함) | R38: 업 태 | V38: =V10 -> 도매및 소매업 | AB38: =AB10 -> 종 목 | AD38: =AD10 -> 빵 과자류
B40: 년 | C40: 월 | D40: 일 | E40: 품 목 | M40: 입수 | Q40: 총수량 | T40: 박스 | W40: 낱개수량 | AA40: 비고
B41: =B13 -> 46315 | E41: =E13 -> 도)깐풍기&표고탕수1 | M41: =M13 -> 36 | Q41: =Q13 -> 5 | T41: =T13 -> 0 | W41: =W13 -> 5 | AA41: =AA13 -> 46321
E42: =E14 -> 도)딥핑치즈맵닭강정1 | M42: =M14 -> 0 | Q42: =Q14 -> 5 | T42: =T14 | W42: =W14 | AA42: =AA14 -> #VALUE!
E43: =E15 -> 도)리얼모짜치즈돈까스1 | M43: =M15 -> 30 | Q43: =Q15 -> 152 | T43: =T15 -> 5 | W43: =W15 -> 2 | AA43: =AA15 -> 46320
E44: =E16 -> 도)리얼치즈고구마돈까스1 | M44: =M16 -> 30 | Q44: =Q16 -> 16 | T44: =T16 -> 0 | W44: =W16 -> 16 | AA44: =AA16 -> 46319
E45: =E17 -> 도)윙봉칠리탕수득템1 | M45: =M17 -> 36 | Q45: =Q17 -> 14 | T45: =T17 -> 0 | W45: =W17 -> 14 | AA45: =AA17 -> 46319
E46: =E18 -> 도)찍먹윙봉1 | M46: =M18 -> 36 | Q46: =Q18 -> 3 | T46: =T18 -> 0 | W46: =W18 -> 3 | AA46: =AA18 -> 46319
E47: =E19 -> 도)찍먹탕수육1 | M47: =M19 -> 36 | Q47: =Q19 -> 1 | T47: =T19 -> 0 | W47: =W19 -> 1 | AA47: =AA19 -> 46319
E48: =E20 -> 도)치맥아보트러플치킨1 | M48: =M20 -> 32 | Q48: =Q20 -> 8 | T48: =T20 -> 0 | W48: =W20 -> 8 | AA48: =AA20 -> 46320
E49: =E21 -> 도)치즈매콤닭강정감자1 | M49: =M21 -> 30 | Q49: =Q21 -> 2 | T49: =T21 -> 0 | W49: =W21 -> 2 | AA49: =AA21 -> 46319
E50: =E22 -> 도)치즈청양간장닭강정1 | M50: =M22 -> 30 | Q50: =Q22 -> 15 | T50: =T22 -> 0 | W50: =W22 -> 15 | AA50: =AA22 -> 46319
E51: =E23 -> 도)쿵야반반닭강정팩1 | M51: =M23 -> 36 | Q51: =Q23 -> 3 | T51: =T23 -> 0 | W51: =W23 -> 3 | AA51: =AA23 -> 46320
B53: =B25 -> 총수량 | M53: =M25 -> 224
B54: =B26 -> 3자물류 (더원물류) 담당자 박병선이사 010-4448-1456 | W54: =W26 -> 울산광역시 울주군 삼동면 조일리 1341-6번지 070)7119-5178

Sheet 김해물류(영남)
B1: 김해물류
B2: 거 래 명 세 표 (공급받는자 보관용)
B4: 공 급 받 는 자 | C4: 등록번호 | Q4: 공 급 자 | R4: 등록번호 | V4: 397-85-00686
C6: 상 호 (법인명) | G6: CU (BGF) | L6: 김해물류 | R6: 상 호 (법인명) | V6: ㈜대신에프에스 | AB6: 성 명 | AD6: 신판철
C8: 사업장 주 소 | G8: 김해시 테크노밸리길 196 | R8: 사업장 주 소 | V8: 전라북도 부안군 행안면 옥여길 32-76
C10: 합계금액 (VAT포함) | R10: 업 태 | V10: 도매및 소매업 | AB10: 종 목 | AD10: 빵 과자류
B12: 년 | C12: 월 | D12: 일 | E12: 품 목 | M12: 입수 | Q12: 총수량 | T12: 박스 | W12: 낱개수량 | AA12: 비고
B13: ='하이로지스(호남) 날짜번경★'!B13 -> 46315 | E13: 도)깐풍기&표고탕수1 | M13: 36 | Q13: =IFERROR(VLOOKUP($B$1,대신피벗발주량1편!$A:$ZZ,2,FALSE),0) -> 0 | T13: =IFERROR(ROUNDDOWN(Q13/M13,0),"") -> 0 | W13: =IFERROR(Q13-(T13*M13),"") -> 0 | AA13: =B13+6 -> 46321
E14: 도)딥핑치즈맵닭강정1 | Q14: =IFERROR(VLOOKUP($B$1,대신피벗발주량1편!$A:$ZZ,3,FALSE),0) -> 0 | T14: =IFERROR(ROUNDDOWN(Q14/M14,0),"") | W14: =IFERROR(Q14-(T14*M14),"") | AA14: =B12+5 -> #VALUE!
E15: 도)리얼모짜치즈돈까스1 | M15: 30 | Q15: =IFERROR(VLOOKUP($B$1,대신피벗발주량1편!$A:$ZZ,4,FALSE),0) -> 0 | T15: =IFERROR(ROUNDDOWN(Q15/M15,0),"") -> 0 | W15: =IFERROR(Q15-(T15*M15),"") -> 0 | AA15: =B13+5 -> 46320
E16: 도)리얼치즈고구마돈까스1 | M16: 30 | Q16: =IFERROR(VLOOKUP($B$1,대신피벗발주량1편!$A:$ZZ,5,FALSE),0) -> 0 | T16: =IFERROR(ROUNDDOWN(Q16/M16,0),"") -> 0 | W16: =IFERROR(Q16-(T16*M16),"") -> 0 | AA16: =B13+5-1 -> 46319
E17: 도)윙봉칠리탕수득템1 | M17: 36 | Q17: =IFERROR(VLOOKUP($B$1,대신피벗발주량1편!$A:$ZZ,6,FALSE),0) -> 0 | T17: =IFERROR(ROUNDDOWN(Q17/M17,0),"") -> 0 | W17: =IFERROR(Q17-(T17*M17),"") -> 0 | AA17: =B13+5-1 -> 46319
E18: 도)찍먹윙봉1 | M18: 36 | Q18: =IFERROR(VLOOKUP($B$1,대신피벗발주량1편!$A:$ZZ,7,FALSE),0) -> 0 | T18: =IFERROR(ROUNDDOWN(Q18/M18,0),"") -> 0 | W18: =IFERROR(Q18-(T18*M18),"") -> 0 | AA18: =B13+5-1 -> 46319
E19: 도)찍먹탕수육1 | M19: 36 | Q19: =IFERROR(VLOOKUP($B$1,대신피벗발주량1편!$A:$ZZ,8,FALSE),0) -> 0 | T19: =IFERROR(ROUNDDOWN(Q19/M19,0),"") -> 0 | W19: =IFERROR(Q19-(T19*M19),"") -> 0 | AA19: =B13+5-1 -> 46319
E20: 도)치맥아보트러플치킨1 | M20: 32 | Q20: =IFERROR(VLOOKUP($B$1,대신피벗발주량1편!$A:$ZZ,9,FALSE),0) -> 0 | T20: =IFERROR(ROUNDDOWN(Q20/M20,0),"") -> 0 | W20: =IFERROR(Q20-(T20*M20),"") -> 0 | AA20: =B13+5 -> 46320
E21: 도)치즈매콤닭강정감자1 | M21: 30 | Q21: =IFERROR(VLOOKUP($B$1,대신피벗발주량1편!$A:$ZZ,10,FALSE),0) -> 0 | T21: =IFERROR(ROUNDDOWN(Q21/M21,0),"") -> 0 | W21: =IFERROR(Q21-(T21*M21),"") -> 0 | AA21: =B13+4 -> 46319
E22: 도)치즈청양간장닭강정1 | M22: 30 | Q22: =IFERROR(VLOOKUP($B$1,대신피벗발주량1편!$A:$ZZ,11,FALSE),0) -> 0 | T22: =IFERROR(ROUNDDOWN(Q22/M22,0),"") -> 0 | W22: =IFERROR(Q22-(T22*M22),"") -> 0 | AA22: =B13+5-1 -> 46319
E23: 도)쿵야반반닭강정팩1 | M23: 36 | Q23: =IFERROR(VLOOKUP($B$1,대신피벗발주량1편!$A:$ZZ,12,FALSE),0) -> 0 | T23: =IFERROR(ROUNDDOWN(Q23/M23,0),"") -> 0 | W23: =IFERROR(Q23-(T23*M23),"") -> 0 | AA23: =B13+5 -> 46320
B25: 총수량 | M25: =SUM(Q13:S24) -> 0
B26: 3자물류 (더원물류) 담당자 박병선이사 010-4448-1456 | W26: 김해시 테크노밸리길 196 055)724-2130
B30: 거 래 명 세 표 (공급자 보관용)
B32: 공 급 받 는 자 | C32: =C4 -> 등록번호 | Q32: 공 급 자 | R32: 등록번호 | V32: =V4 -> 397-85-00686
C34: =C6 -> 상 호 (법인명) | G34: =G6 -> CU (BGF) | L34: =L6 -> 김해물류 | R34: 상 호 (법인명) | V34: =V6 -> ㈜대신에프에스 | AB34: 성 명 | AD34: =AD6 -> 신판철
C36: 사업장 주 소 | G36: =G8 -> 김해시 테크노밸리길 196 | R36: 사업장 주 소 | V36: =V8 -> 전라북도 부안군 행안면 옥여길 32-76
C38: 합계금액 (VAT포함) | R38: 업 태 | V38: =V10 -> 도매및 소매업 | AB38: =AB10 -> 종 목 | AD38: =AD10 -> 빵 과자류
B40: 년 | C40: 월 | D40: 일 | E40: 품 목 | M40: 입수 | Q40: 총수량 | T40: 박스 | W40: 낱개수량 | AA40: 비고
B41: =B13 -> 46315 | E41: =E13 -> 도)깐풍기&표고탕수1 | M41: =M13 -> 36 | Q41: =Q13 -> 0 | T41: =T13 -> 0 | W41: =W13 -> 0 | AA41: =AA13 -> 46321
E42: =E14 -> 도)딥핑치즈맵닭강정1 | M42: =M14 -> 0 | Q42: =Q14 -> 0 | T42: =T14 | W42: =W14 | AA42: =AA14 -> #VALUE!
E43: =E15 -> 도)리얼모짜치즈돈까스1 | M43: =M15 -> 30 | Q43: =Q15 -> 0 | T43: =T15 -> 0 | W43: =W15 -> 0 | AA43: =AA15 -> 46320
E44: =E16 -> 도)리얼치즈고구마돈까스1 | M44: =M16 -> 30 | Q44: =Q16 -> 0 | T44: =T16 -> 0 | W44: =W16 -> 0 | AA44: =AA16 -> 46319
E45: =E17 -> 도)윙봉칠리탕수득템1 | M45: =M17 -> 36 | Q45: =Q17 -> 0 | T45: =T17 -> 0 | W45: =W17 -> 0 | AA45: =AA17 -> 46319
E46: =E18 -> 도)찍먹윙봉1 | M46: =M18 -> 36 | Q46: =Q18 -> 0 | T46: =T18 -> 0 | W46: =W18 -> 0 | AA46: =AA18 -> 46319
E47: =E19 -> 도)찍먹탕수육1 | M47: =M19 -> 36 | Q47: =Q19 -> 0 | T47: =T19 -> 0 | W47: =W19 -> 0 | AA47: =AA19 -> 46319
E48: =E20 -> 도)치맥아보트러플치킨1 | M48: =M20 -> 32 | Q48: =Q20 -> 0 | T48: =T20 -> 0 | W48: =W20 -> 0 | AA48: =AA20 -> 46320
E49: =E21 -> 도)치즈매콤닭강정감자1 | M49: =M21 -> 30 | Q49: =Q21 -> 0 | T49: =T21 -> 0 | W49: =W21 -> 0 | AA49: =AA21 -> 46319
E50: =E22 -> 도)치즈청양간장닭강정1 | M50: =M22 -> 30 | Q50: =Q22 -> 0 | T50: =T22 -> 0 | W50: =W22 -> 0 | AA50: =AA22 -> 46319
E51: =E23 -> 도)쿵야반반닭강정팩1 | M51: =M23 -> 36 | Q51: =Q23 -> 0 | T51: =T23 -> 0 | W51: =W23 -> 0 | AA51: =AA23 -> 46320
B53: =B25 -> 총수량 | M53: =M25 -> 0
B54: =B26 -> 3자물류 (더원물류) 담당자 박병선이사 010-4448-1456 | W54: =W26 -> 김해시 테크노밸리길 196 055)724-2130

Sheet BGF로지스부산(영남)
B1: BGF로지스부산
B2: 거 래 명 세 표 (공급받는자 보관용)
B4: 공 급 받 는 자 | C4: 등록번호 | Q4: 공 급 자 | R4: 등록번호 | V4: 397-85-00686
C6: 상 호 (법인명) | G6: CU (BGF) | L6: BGF로지스부산 | R6: 상 호 (법인명) | V6: ㈜대신에프에스 | AB6: 성 명 | AD6: 신판철
C8: 사업장 주 소 | G8: 부산광역시 강서구 송정국제1로 69 | R8: 사업장 주 소 | V8: 전라북도 부안군 행안면 옥여길 32-76
C10: 합계금액 (VAT포함) | R10: 업 태 | V10: 도매및 소매업 | AB10: 종 목 | AD10: 빵 과자류
B12: 년 | C12: 월 | D12: 일 | E12: 품 목 | M12: 입수 | Q12: 총수량 | T12: 박스 | W12: 낱개수량 | AA12: 비고
B13: ='하이로지스(호남) 날짜번경★'!B13 -> 46315 | E13: 도)깐풍기&표고탕수1 | M13: 36 | Q13: =IFERROR(VLOOKUP($B$1,대신피벗발주량1편!$A:$ZZ,2,FALSE),0) -> 4 | T13: =IFERROR(ROUNDDOWN(Q13/M13,0),"") -> 0 | W13: =IFERROR(Q13-(T13*M13),"") -> 4 | AA13: =B13+6 -> 46321
E14: 도)딥핑치즈맵닭강정1 | Q14: =IFERROR(VLOOKUP($B$1,대신피벗발주량1편!$A:$ZZ,3,FALSE),0) -> 4 | T14: =IFERROR(ROUNDDOWN(Q14/M14,0),"") | W14: =IFERROR(Q14-(T14*M14),"") | AA14: =B12+5 -> #VALUE!
E15: 도)리얼모짜치즈돈까스1 | M15: 30 | Q15: =IFERROR(VLOOKUP($B$1,대신피벗발주량1편!$A:$ZZ,4,FALSE),0) -> 105 | T15: =IFERROR(ROUNDDOWN(Q15/M15,0),"") -> 3 | W15: =IFERROR(Q15-(T15*M15),"") -> 15 | AA15: =B13+5 -> 46320
E16: 도)리얼치즈고구마돈까스1 | M16: 30 | Q16: =IFERROR(VLOOKUP($B$1,대신피벗발주량1편!$A:$ZZ,5,FALSE),0) -> 7 | T16: =IFERROR(ROUNDDOWN(Q16/M16,0),"") -> 0 | W16: =IFERROR(Q16-(T16*M16),"") -> 7 | AA16: =B13+5-1 -> 46319
E17: 도)윙봉칠리탕수득템1 | M17: 36 | Q17: =IFERROR(VLOOKUP($B$1,대신피벗발주량1편!$A:$ZZ,6,FALSE),0) -> 10 | T17: =IFERROR(ROUNDDOWN(Q17/M17,0),"") -> 0 | W17: =IFERROR(Q17-(T17*M17),"") -> 10 | AA17: =B13+5-1 -> 46319
E18: 도)찍먹윙봉1 | M18: 36 | Q18: =IFERROR(VLOOKUP($B$1,대신피벗발주량1편!$A:$ZZ,7,FALSE),0) -> 2 | T18: =IFERROR(ROUNDDOWN(Q18/M18,0),"") -> 0 | W18: =IFERROR(Q18-(T18*M18),"") -> 2 | AA18: =B13+5-1 -> 46319
E19: 도)찍먹탕수육1 | M19: 36 | Q19: =IFERROR(VLOOKUP($B$1,대신피벗발주량1편!$A:$ZZ,8,FALSE),0) -> 2 | T19: =IFERROR(ROUNDDOWN(Q19/M19,0),"") -> 0 | W19: =IFERROR(Q19-(T19*M19),"") -> 2 | AA19: =B13+5-1 -> 46319
E20: 도)치맥아보트러플치킨1 | M20: 32 | Q20: =IFERROR(VLOOKUP($B$1,대신피벗발주량1편!$A:$ZZ,9,FALSE),0) -> 2 | T20: =IFERROR(ROUNDDOWN(Q20/M20,0),"") -> 0 | W20: =IFERROR(Q20-(T20*M20),"") -> 2 | AA20: =B13+5 -> 46320
E21: 도)치즈매콤닭강정감자1 | M21: 30 | Q21: =IFERROR(VLOOKUP($B$1,대신피벗발주량1편!$A:$ZZ,10,FALSE),0) -> 1 | T21: =IFERROR(ROUNDDOWN(Q21/M21,0),"") -> 0 | W21: =IFERROR(Q21-(T21*M21),"") -> 1 | AA21: =B13+4 -> 46319
E22: 도)치즈청양간장닭강정1 | M22: 30 | Q22: =IFERROR(VLOOKUP($B$1,대신피벗발주량1편!$A:$ZZ,11,FALSE),0) -> 9 | T22: =IFERROR(ROUNDDOWN(Q22/M22,0),"") -> 0 | W22: =IFERROR(Q22-(T22*M22),"") -> 9 | AA22: =B13+5-1 -> 46319
E23: 도)쿵야반반닭강정팩1 | M23: 36 | Q23: =IFERROR(VLOOKUP($B$1,대신피벗발주량1편!$A:$ZZ,12,FALSE),0) -> 7 | T23: =IFERROR(ROUNDDOWN(Q23/M23,0),"") -> 0 | W23: =IFERROR(Q23-(T23*M23),"") -> 7 | AA23: =B13+5 -> 46320
B25: 총수량 | M25: =SUM(Q13:S24) -> 153
B26: 3자물류 (더원물류) 담당자 박병선이사 010-4448-1456 | W26: 부산광역시 강서구 송정국제1로 69
B30: 거 래 명 세 표 (공급자 보관용)
B32: 공 급 받 는 자 | C32: =C4 -> 등록번호 | Q32: 공 급 자 | R32: 등록번호 | V32: =V4 -> 397-85-00686
C34: =C6 -> 상 호 (법인명) | G34: =G6 -> CU (BGF) | L34: =L6 -> BGF로지스부산 | R34: 상 호 (법인명) | V34: =V6 -> ㈜대신에프에스 | AB34: 성 명 | AD34: =AD6 -> 신판철
C36: 사업장 주 소 | G36: =G8 -> 부산광역시 강서구 송정국제1로 69 | R36: 사업장 주 소 | V36: =V8 -> 전라북도 부안군 행안면 옥여길 32-76
C38: 합계금액 (VAT포함) | R38: 업 태 | V38: =V10 -> 도매및 소매업 | AB38: =AB10 -> 종 목 | AD38: =AD10 -> 빵 과자류
B40: 년 | C40: 월 | D40: 일 | E40: 품 목 | M40: 입수 | Q40: 총수량 | T40: 박스 | W40: 낱개수량 | AA40: 비고
B41: =B13 -> 46315 | E41: =E13 -> 도)깐풍기&표고탕수1 | M41: =M13 -> 36 | Q41: =Q13 -> 4 | T41: =T13 -> 0 | W41: =W13 -> 4 | AA41: =AA13 -> 46321
