Workbook
Name 정진: #REF!

Sheet 금토일피벗
A1: 10/13 | B1: 열 레이블
A2: 10/14 납품 | B2: 옐로우)달콤닭강정300g | C2: 옐로우)매콤닭강정300g | D2: 총합계
A3: 김해2(저온)
A4: 양산2(저온)
A5: 세종2(저온)
A6: 장성2(저온)
A7: 청라2(저온)
A8: 포천2(저온)
A9: 양지2(저온)
A10: 총합계

Sheet 옐로우)달콤닭강정300g
A2: =TODAY() -> 46309 | C2: 이마트24(냉동) - 금토일
A3: =금토일피벗!A2 -> 10/14 납품 | B3: 입수 | C3: 옐로우)달콤닭강정300g | D3: 박스 | E3: 센터명 | F3: 낱개
A4: 원주2(저온) | B4: 24 | C4: =IFERROR(VLOOKUP(A4,금토일피벗!A:AD,2,FALSE),0) -> 0 | D4: =IFERROR(ROUNDDOWN(C4/B4,0),"") -> 0 | E4: 원주 | F4: =IFERROR(C4-(D4*B4),"") -> 0
A5: 세종2(저온) | B5: =$B$4 -> 24 | C5: =IFERROR(VLOOKUP(A5,금토일피벗!A:AD,2,FALSE),0) -> 0 | D5: =IFERROR(ROUNDDOWN(C5/B5,0),"") -> 0 | E5: 세종 | F5: =IFERROR(C5-(D5*B5),"") -> 0
A6: 화성2(저온) | B6: =$B$4 -> 24 | C6: =IFERROR(VLOOKUP(A6,금토일피벗!A:AD,2,FALSE),0) -> 0 | D6: =IFERROR(ROUNDDOWN(C6/B6,0),"") -> 0 | E6: 화성 | F6: =IFERROR(C6-(D6*B6),"") -> 0
A7: 청라2(저온) | B7: =$B$4 -> 24 | C7: =IFERROR(VLOOKUP(A7,금토일피벗!A:AD,2,FALSE),0) -> 0 | D7: =IFERROR(ROUNDDOWN(C7/B7,0),"") -> 0 | E7: 청라 | F7: =IFERROR(C7-(D7*B7),"") -> 0
A8: 평택2(저온) | B8: =$B$4 -> 24 | C8: =IFERROR(VLOOKUP(A8,금토일피벗!A:AD,2,FALSE),0) -> 0 | D8: =IFERROR(ROUNDDOWN(C8/B8,0),"") -> 0 | E8: 평택 | F8: =IFERROR(C8-(D8*B8),"") -> 0
A9: 포천2(저온) | B9: =$B$4 -> 24 | C9: =IFERROR(VLOOKUP(A9,금토일피벗!A:AD,2,FALSE),0) -> 0 | D9: =IFERROR(ROUNDDOWN(C9/B9,0),"") -> 0 | E9: 포천 | F9: =IFERROR(C9-(D9*B9),"") -> 0
A10: 양지2(저온) | B10: =$B$4 -> 24 | C10: =IFERROR(VLOOKUP(A10,금토일피벗!A:AD,2,FALSE),0) -> 0 | D10: =IFERROR(ROUNDDOWN(C10/B10,0),"") -> 0 | E10: 양지 | F10: =IFERROR(C10-(D10*B10),"") -> 0
A11: 수도권 합계 | B11: =$B$4 -> 24 | C11: =SUM($C$4:$C$10) -> 0 | D11: =IFERROR(ROUNDDOWN(C11/B11,0),"") -> 0 | F11: =IFERROR(C11-(D11*B11),"") -> 0
A13: 김해2(저온) | B13: =$B$4 -> 24 | C13: =IFERROR(VLOOKUP(A13,금토일피벗!A:AD,2,FALSE),0) -> 0 | D13: =IFERROR(ROUNDDOWN(C13/B13,0),"") -> 0 | E13: 김해 | F13: =IFERROR(C13-(D13*B13),"") -> 0
A14: 양산2(저온) | B14: =$B$4 -> 24 | C14: =IFERROR(VLOOKUP(A14,금토일피벗!A:AD,2,FALSE),0) -> 0 | D14: =IFERROR(ROUNDDOWN(C14/B14,0),"") -> 0 | E14: 양산 | F14: =IFERROR(C14-(D14*B14),"") -> 0
A15: 경남(김해) 합계 | B15: 24 | C15: =SUM(C13:C14) -> 0 | D15: =IFERROR(ROUNDDOWN(C15/B15,0),"") -> 0 | F15: =IFERROR(C15-(D15*B15),"") -> 0
A17: 김천2(저온) | B17: =$B$4 -> 24 | C17: =IFERROR(VLOOKUP(A17,금토일피벗!A:AD,2,FALSE),0) -> 0 | D17: =IFERROR(ROUNDDOWN(C17/B17,0),"") -> 0 | E17: 김천 | F17: =IFERROR(C17-(D17*B17),"") -> 0
A18: 경산2(저온) | B18: =$B$4 -> 24 | C18: =IFERROR(VLOOKUP(A18,금토일피벗!A:AD,2,FALSE),0) -> 0 | D18: =IFERROR(ROUNDDOWN(C18/B18,0),"") -> 0 | E18: 경산 | F18: =IFERROR(C18-(D18*B18),"") -> 0
A19: 경북(칠곡) 합계 | B19: =$B$4 -> 24 | C19: =SUM(C17:C18) -> 0 | D19: =IFERROR(ROUNDDOWN(C19/B19,0),"") -> 0 | F19: =IFERROR(C19-(D19*B19),"") -> 0
A21: 장성2(저온) | B21: =$B$4 -> 24 | C21: =IFERROR(VLOOKUP(A21,금토일피벗!A:AD,2,FALSE),0) -> 0 | D21: =IFERROR(ROUNDDOWN(C21/B21,0),"") -> 0 | E21: 장성 | F21: =IFERROR(C21-(D21*B21),"") -> 0
A22: 호남 합계 | B22: =$B$4 -> 24 | C22: =SUM($C$21) -> 0 | D22: =IFERROR(ROUNDDOWN(C22/B22,0),"") -> 0 | F22: =IFERROR(C22-(D22*B22),"") -> 0
A24: 총합계 | B24: =B4 -> 24 | C24: =SUM($C$11,$C$15,$C$19,$C$22) -> 0 | D24: =IFERROR(ROUNDDOWN(C24/B24,0),"") -> 0 | F24: =IFERROR(C24-(D24*B24),"") -> 0
A25: 총 박스 수량 / 총 낱개 수량 | D25: =SUM(D4:D10,D13:D14,D17:D18,D21) -> 0 | F25: =SUM(F4:F10,F13:F18,F21) -> 0

Sheet 옐로우)매콤닭강정300g
A2: =TODAY() -> 46309 | C2: 이마트24(냉동) - 금토일
A3: =금토일피벗!A2 -> 10/14 납품 | B3: 입수 | C3: 옐로우)매콤닭강정300g | D3: 박스 | E3: 센터명 | F3: 낱개
A4: 원주2(저온) | B4: 24 | C4: =IFERROR(VLOOKUP(A4,금토일피벗!A:AD,3,FALSE),0) -> 0 | D4: =IFERROR(ROUNDDOWN(C4/B4,0),"") -> 0 | E4: 원주 | F4: =IFERROR(C4-(D4*B4),"") -> 0
A5: 세종2(저온) | B5: =$B$4 -> 24 | C5: =IFERROR(VLOOKUP(A5,금토일피벗!A:AD,3,FALSE),0) -> 0 | D5: =IFERROR(ROUNDDOWN(C5/B5,0),"") -> 0 | E5: 세종 | F5: =IFERROR(C5-(D5*B5),"") -> 0
A6: 화성2(저온) | B6: =$B$4 -> 24 | C6: =IFERROR(VLOOKUP(A6,금토일피벗!A:AD,3,FALSE),0) -> 0 | D6: =IFERROR(ROUNDDOWN(C6/B6,0),"") -> 0 | E6: 화성 | F6: =IFERROR(C6-(D6*B6),"") -> 0
A7: 청라2(저온) | B7: =$B$4 -> 24 | C7: =IFERROR(VLOOKUP(A7,금토일피벗!A:AD,3,FALSE),0) -> 0 | D7: =IFERROR(ROUNDDOWN(C7/B7,0),"") -> 0 | E7: 청라 | F7: =IFERROR(C7-(D7*B7),"") -> 0
A8: 평택2(저온) | B8: =$B$4 -> 24 | C8: =IFERROR(VLOOKUP(A8,금토일피벗!A:AD,3,FALSE),0) -> 0 | D8: =IFERROR(ROUNDDOWN(C8/B8,0),"") -> 0 | E8: 평택 | F8: =IFERROR(C8-(D8*B8),"") -> 0
A9: 포천2(저온) | B9: =$B$4 -> 24 | C9: =IFERROR(VLOOKUP(A9,금토일피벗!A:AD,3,FALSE),0) -> 0 | D9: =IFERROR(ROUNDDOWN(C9/B9,0),"") -> 0 | E9: 포천 | F9: =IFERROR(C9-(D9*B9),"") -> 0
A10: 양지2(저온) | B10: =$B$4 -> 24 | C10: =IFERROR(VLOOKUP(A10,금토일피벗!A:AD,3,FALSE),0) -> 0 | D10: =IFERROR(ROUNDDOWN(C10/B10,0),"") -> 0 | E10: 양지 | F10: =IFERROR(C10-(D10*B10),"") -> 0
A11: 수도권 합계 | B11: =$B$4 -> 24 | C11: =SUM($C$4:$C$10) -> 0 | D11: =IFERROR(ROUNDDOWN(C11/B11,0),"") -> 0 | F11: =IFERROR(C11-(D11*B11),"") -> 0
A13: 김해2(저온) | B13: =$B$4 -> 24 | C13: =IFERROR(VLOOKUP(A13,금토일피벗!A:AD,3,FALSE),0) -> 0 | D13: =IFERROR(ROUNDDOWN(C13/B13,0),"") -> 0 | E13: 김해 | F13: =IFERROR(C13-(D13*B13),"") -> 0
A14: 양산2(저온) | B14: =$B$4 -> 24 | C14: =IFERROR(VLOOKUP(A14,금토일피벗!A:AD,3,FALSE),0) -> 0 | D14: =IFERROR(ROUNDDOWN(C14/B14,0),"") -> 0 | E14: 양산 | F14: =IFERROR(C14-(D14*B14),"") -> 0
A15: 경남(김해) 합계 | B15: 24 | C15: =SUM(C13:C14) -> 0 | D15: =IFERROR(ROUNDDOWN(C15/B15,0),"") -> 0 | F15: =IFERROR(C15-(D15*B15),"") -> 0
A17: 김천2(저온) | B17: =$B$4 -> 24 | C17: =IFERROR(VLOOKUP(A17,금토일피벗!A:AD,3,FALSE),0) -> 0 | D17: =IFERROR(ROUNDDOWN(C17/B17,0),"") -> 0 | E17: 김천 | F17: =IFERROR(C17-(D17*B17),"") -> 0
A18: 경산2(저온) | B18: =$B$4 -> 24 | C18: =IFERROR(VLOOKUP(A18,금토일피벗!A:AD,3,FALSE),0) -> 0 | D18: =IFERROR(ROUNDDOWN(C18/B18,0),"") -> 0 | E18: 경산 | F18: =IFERROR(C18-(D18*B18),"") -> 0
A19: 경북(칠곡) 합계 | B19: =$B$4 -> 24 | C19: =SUM(C17:C18) -> 0 | D19: =IFERROR(ROUNDDOWN(C19/B19,0),"") -> 0 | F19: =IFERROR(C19-(D19*B19),"") -> 0
A21: 장성2(저온) | B21: =$B$4 -> 24 | C21: =IFERROR(VLOOKUP(A21,금토일피벗!A:AD,3,FALSE),0) -> 0 | D21: =IFERROR(ROUNDDOWN(C21/B21,0),"") -> 0 | E21: 장성 | F21: =IFERROR(C21-(D21*B21),"") -> 0
A22: 호남 합계 | B22: =$B$4 -> 24 | C22: =SUM($C$21) -> 0 | D22: =IFERROR(ROUNDDOWN(C22/B22,0),"") -> 0 | F22: =IFERROR(C22-(D22*B22),"") -> 0
A24: 총합계 | B24: =B4 -> 24 | C24: =SUM($C$11,$C$15,$C$19,$C$22) -> 0 | D24: =IFERROR(ROUNDDOWN(C24/B24,0),"") -> 0 | F24: =IFERROR(C24-(D24*B24),"") -> 0
A25: 총 박스 수량 / 총 낱개 수량 | D25: =SUM(D4:D10,D13:D14,D17:D18,D21) -> 0 | F25: =SUM(F4:F10,F13:F18,F21) -> 0

Sheet 이그니스 피벗

Sheet 한끼통살)바베큐닭가슴살100g
A2: =TODAY() -> 46309 | C2: 이마트24(냉동) - 이그니스
A3: ='이그니스 피벗'!A2 -> 0 | B3: 입수 | C3: 한끼통살)바비큐 닭가슴살100g | D3: 박스 | E3: 센터명 | F3: 낱개
A4: 원주2(저온) | B4: 60 | C4: =IFERROR(VLOOKUP(A4,'이그니스 피벗'!A:AM,2,FALSE),0) -> 0 | D4: =IFERROR(ROUNDDOWN(C4/B4,0),"") -> 0 | E4: 원주 | F4: =IFERROR(C4-(D4*B4),"") -> 0
A5: 세종2(저온) | B5: =$B$4 -> 60 | C5: =IFERROR(VLOOKUP(A5,'이그니스 피벗'!A:AM,2,FALSE),0) -> 0 | D5: =IFERROR(ROUNDDOWN(C5/B5,0),"") -> 0 | E5: 세종 | F5: =IFERROR(C5-(D5*B5),"") -> 0
A6: 화성2(저온) | B6: =$B$4 -> 60 | C6: =IFERROR(VLOOKUP(A6,'이그니스 피벗'!A:AM,2,FALSE),0) -> 0 | D6: =IFERROR(ROUNDDOWN(C6/B6,0),"") -> 0 | E6: 화성 | F6: =IFERROR(C6-(D6*B6),"") -> 0
A7: 청라2(저온) | B7: =$B$4 -> 60 | C7: =IFERROR(VLOOKUP(A7,'이그니스 피벗'!A:AM,2,FALSE),0) -> 0 | D7: =IFERROR(ROUNDDOWN(C7/B7,0),"") -> 0 | E7: 청라 | F7: =IFERROR(C7-(D7*B7),"") -> 0
A8: 평택2(저온) | B8: =$B$4 -> 60 | C8: =IFERROR(VLOOKUP(A8,'이그니스 피벗'!A:AM,2,FALSE),0) -> 0 | D8: =IFERROR(ROUNDDOWN(C8/B8,0),"") -> 0 | E8: 평택 | F8: =IFERROR(C8-(D8*B8),"") -> 0
A9: 포천2(저온) | B9: =$B$4 -> 60 | C9: =IFERROR(VLOOKUP(A9,'이그니스 피벗'!A:AM,2,FALSE),0) -> 0 | D9: =IFERROR(ROUNDDOWN(C9/B9,0),"") -> 0 | E9: 포천 | F9: =IFERROR(C9-(D9*B9),"") -> 0
A10: 양지2(저온) | B10: =$B$4 -> 60 | C10: =IFERROR(VLOOKUP(A10,'이그니스 피벗'!A:AM,2,FALSE),0) -> 0 | D10: =IFERROR(ROUNDDOWN(C10/B10,0),"") -> 0 | E10: 양지 | F10: =IFERROR(C10-(D10*B10),"") -> 0
A11: 수도권 합계 | B11: =$B$4 -> 60 | C11: =SUM($C$4:$C$10) -> 0 | D11: =IFERROR(ROUNDDOWN(C11/B11,0),"") -> 0 | F11: =IFERROR(C11-(D11*B11),"") -> 0
A13: 김해2(저온) | B13: =$B$4 -> 60 | C13: =IFERROR(VLOOKUP(A13,'이그니스 피벗'!A:AM,2,FALSE),0) -> 0 | D13: =IFERROR(ROUNDDOWN(C13/B13,0),"") -> 0 | E13: 김해 | F13: =IFERROR(C13-(D13*B13),"") -> 0
A14: 양산2(저온) | B14: =$B$4 -> 60 | C14: =IFERROR(VLOOKUP(A14,'이그니스 피벗'!A:AM,2,FALSE),0) -> 0 | D14: =IFERROR(ROUNDDOWN(C14/B14,0),"") -> 0 | E14: 양산 | F14: =IFERROR(C14-(D14*B14),"") -> 0
A15: 경남(김해) 합계 | B15: =$B$4 -> 60 | C15: =SUM($C$13:$C$14) -> 0 | D15: =IFERROR(ROUNDDOWN(C15/B15,0),"") -> 0 | F15: =IFERROR(C15-(D15*B15),"") -> 0
A17: 김천2(저온) | B17: =$B$4 -> 60 | C17: =IFERROR(VLOOKUP(A17,'이그니스 피벗'!A:AM,2,FALSE),0) -> 0 | D17: =IFERROR(ROUNDDOWN(C17/B17,0),"") -> 0 | E17: 김천 | F17: =IFERROR(C17-(D17*B17),"") -> 0
A18: 경산2(저온) | B18: =$B$4 -> 60 | C18: =IFERROR(VLOOKUP(A18,'이그니스 피벗'!A:AM,2,FALSE),0) -> 0 | D18: =IFERROR(ROUNDDOWN(C18/B18,0),"") -> 0 | E18: 경산 | F18: =IFERROR(C18-(D18*B18),"") -> 0
A19: 경북(칠곡) 합계 | B19: =$B$4 -> 60 | C19: =SUM($C$17:$C$18) -> 0 | D19: =IFERROR(ROUNDDOWN(C19/B19,0),"") -> 0 | F19: =IFERROR(C19-(D19*B19),"") -> 0
A21: 장성2(저온) | B21: =$B$4 -> 60 | C21: =IFERROR(VLOOKUP(A21,'이그니스 피벗'!A:AM,2,FALSE),0) -> 0 | D21: =IFERROR(ROUNDDOWN(C21/B21,0),"") -> 0 | E21: 장성 | F21: =IFERROR(C21-(D21*B21),"") -> 0
A22: 호남 합계 | B22: =$B$4 -> 60 | C22: =SUM($C$21) -> 0 | D22: =IFERROR(ROUNDDOWN(C22/B22,0),"") -> 0 | F22: =IFERROR(C22-(D22*B22),"") -> 0
A24: 총합계 | B24: =B4 -> 60 | C24: =SUM(C4:C10,C13:C14,C17:C18,C21) -> 0 | D24: =IFERROR(ROUNDDOWN(C24/B24,0),"") -> 0 | F24: =IFERROR(C24-(D24*B24),"") -> 0
A25: 총 박스 수량 / 총 낱개 수량 | D25: =SUM(D4:D10,D13:D14,D17:D18,D21) -> 0 | F25: =SUM(F4:F10,F13:F14,F17:F18,F21) -> 0

Sheet 한끼통살)볼케이노닭가슴살100g
A2: =TODAY() -> 46309 | C2: 이마트24(냉동) - 이그니스
A3: ='이그니스 피벗'!A2 -> 0 | B3: 입수 | C3: 한끼통살)볼케이노 닭가슴살100g | D3: 박스 | E3: 센터명 | F3: 낱개
A4: 원주2(저온) | B4: 60 | C4: =IFERROR(VLOOKUP(A4,'이그니스 피벗'!A:AM,3,FALSE),0) -> 0 | D4: =IFERROR(ROUNDDOWN(C4/B4,0),"") -> 0 | E4: 원주 | F4: =IFERROR(C4-(D4*B4),"") -> 0
A5: 세종2(저온) | B5: =$B$4 -> 60 | C5: =IFERROR(VLOOKUP(A5,'이그니스 피벗'!A:AM,3,FALSE),0) -> 0 | D5: =IFERROR(ROUNDDOWN(C5/B5,0),"") -> 0 | E5: 세종 | F5: =IFERROR(C5-(D5*B5),"") -> 0
A6: 화성2(저온) | B6: =$B$4 -> 60 | C6: =IFERROR(VLOOKUP(A6,'이그니스 피벗'!A:AM,3,FALSE),0) -> 0 | D6: =IFERROR(ROUNDDOWN(C6/B6,0),"") -> 0 | E6: 화성 | F6: =IFERROR(C6-(D6*B6),"") -> 0
A7: 청라2(저온) | B7: =$B$4 -> 60 | C7: =IFERROR(VLOOKUP(A7,'이그니스 피벗'!A:AM,3,FALSE),0) -> 0 | D7: =IFERROR(ROUNDDOWN(C7/B7,0),"") -> 0 | E7: 청라 | F7: =IFERROR(C7-(D7*B7),"") -> 0
A8: 평택2(저온) | B8: =$B$4 -> 60 | C8: =IFERROR(VLOOKUP(A8,'이그니스 피벗'!A:AM,3,FALSE),0) -> 0 | D8: =IFERROR(ROUNDDOWN(C8/B8,0),"") -> 0 | E8: 평택 | F8: =IFERROR(C8-(D8*B8),"") -> 0
A9: 포천2(저온) | B9: =$B$4 -> 60 | C9: =IFERROR(VLOOKUP(A9,'이그니스 피벗'!A:AM,3,FALSE),0) -> 0 | D9: =IFERROR(ROUNDDOWN(C9/B9,0),"") -> 0 | E9: 포천 | F9: =IFERROR(C9-(D9*B9),"") -> 0
A10: 양지2(저온) | B10: =$B$4 -> 60 | C10: =IFERROR(VLOOKUP(A10,'이그니스 피벗'!A:AM,3,FALSE),0) -> 0 | D10: =IFERROR(ROUNDDOWN(C10/B10,0),"") -> 0 | E10: 양지 | F10: =IFERROR(C10-(D10*B10),"") -> 0
A11: 수도권 합계 | B11: =$B$4 -> 60 | C11: =SUM($C$4:$C$10) -> 0 | D11: =IFERROR(ROUNDDOWN(C11/B11,0),"") -> 0 | F11: =IFERROR(C11-(D11*B11),"") -> 0
A13: 김해2(저온) | B13: =$B$4 -> 60 | C13: =IFERROR(VLOOKUP(A13,'이그니스 피벗'!A:AM,3,FALSE),0) -> 0 | D13: =IFERROR(ROUNDDOWN(C13/B13,0),"") -> 0 | E13: 김해 | F13: =IFERROR(C13-(D13*B13),"") -> 0
A14: 양산2(저온) | B14: =$B$4 -> 60 | C14: =IFERROR(VLOOKUP(A14,'이그니스 피벗'!A:AM,3,FALSE),0) -> 0 | D14: =IFERROR(ROUNDDOWN(C14/B14,0),"") -> 0 | E14: 양산 | F14: =IFERROR(C14-(D14*B14),"") -> 0
A15: 경남(김해) 합계 | B15: =$B$4 -> 60 | C15: =SUM($C$13:$C$14) -> 0 | D15: =IFERROR(ROUNDDOWN(C15/B15,0),"") -> 0 | F15: =IFERROR(C15-(D15*B15),"") -> 0
A17: 김천2(저온) | B17: =$B$4 -> 60 | C17: =IFERROR(VLOOKUP(A17,'이그니스 피벗'!A:AM,3,FALSE),0) -> 0 | D17: =IFERROR(ROUNDDOWN(C17/B17,0),"") -> 0 | E17: 김천 | F17: =IFERROR(C17-(D17*B17),"") -> 0
A18: 경산2(저온) | B18: =$B$4 -> 60 | C18: =IFERROR(VLOOKUP(A18,'이그니스 피벗'!A:AM,3,FALSE),0) -> 0 | D18: =IFERROR(ROUNDDOWN(C18/B18,0),"") -> 0 | E18: 경산 | F18: =IFERROR(C18-(D18*B18),"") -> 0
A19: 경북(칠곡) 합계 | B19: =$B$4 -> 60 | C19: =SUM($C$17:$C$18) -> 0 | D19: =IFERROR(ROUNDDOWN(C19/B19,0),"") -> 0 | F19: =IFERROR(C19-(D19*B19),"") -> 0
A21: 장성2(저온) | B21: =$B$4 -> 60 | C21: =IFERROR(VLOOKUP(A21,'이그니스 피벗'!A:AM,3,FALSE),0) -> 0 | D21: =IFERROR(ROUNDDOWN(C21/B21,0),"") -> 0 | E21: 장성 | F21: =IFERROR(C21-(D21*B21),"") -> 0
A22: 호남 합계 | B22: =$B$4 -> 60 | C22: =SUM($C$21) -> 0 | D22: =IFERROR(ROUNDDOWN(C22/B22,0),"") -> 0 | F22: =IFERROR(C22-(D22*B22),"") -> 0
A24: 총합계 | B24: =B4 -> 60 | C24: =SUM(C4:C10,C13:C14,C17:C18,C21) -> 0 | D24: =IFERROR(ROUNDDOWN(C24/B24,0),"") -> 0 | F24: =IFERROR(C24-(D24*B24),"") -> 0
A25: 총 박스 수량 / 총 낱개 수량 | D25: =SUM(D4:D10,D13:D14,D17:D18,D21) -> 0 | F25: =SUM(F4:F10,F13:F14,F17:F18,F21) -> 0

Sheet 한끼통살)소이갈릭닭가슴살100g
A2: =TODAY() -> 46309 | C2: 이마트24(냉동) - 이그니스
A3: ='이그니스 피벗'!A2 -> 0 | B3: 입수 | C3: 한끼통살)소이갈릭 닭가슴살100g | D3: 박스 | E3: 센터명 | F3: 낱개
A4: 원주2(저온) | B4: 60 | C4: =IFERROR(VLOOKUP(A4,'이그니스 피벗'!A:AM,4,FALSE),0) -> 0 | D4: =IFERROR(ROUNDDOWN(C4/B4,0),"") -> 0 | E4: 원주 | F4: =IFERROR(C4-(D4*B4),"") -> 0
A5: 세종2(저온) | B5: =$B$4 -> 60 | C5: =IFERROR(VLOOKUP(A5,'이그니스 피벗'!A:AM,4,FALSE),0) -> 0 | D5: =IFERROR(ROUNDDOWN(C5/B5,0),"") -> 0 | E5: 세종 | F5: =IFERROR(C5-(D5*B5),"") -> 0
A6: 화성2(저온) | B6: =$B$4 -> 60 | C6: =IFERROR(VLOOKUP(A6,'이그니스 피벗'!A:AM,4,FALSE),0) -> 0 | D6: =IFERROR(ROUNDDOWN(C6/B6,0),"") -> 0 | E6: 화성 | F6: =IFERROR(C6-(D6*B6),"") -> 0
A7: 청라2(저온) | B7: =$B$4 -> 60 | C7: =IFERROR(VLOOKUP(A7,'이그니스 피벗'!A:AM,4,FALSE),0) -> 0 | D7: =IFERROR(ROUNDDOWN(C7/B7,0),"") -> 0 | E7: 청라 | F7: =IFERROR(C7-(D7*B7),"") -> 0
A8: 평택2(저온) | B8: =$B$4 -> 60 | C8: =IFERROR(VLOOKUP(A8,'이그니스 피벗'!A:AM,4,FALSE),0) -> 0 | D8: =IFERROR(ROUNDDOWN(C8/B8,0),"") -> 0 | E8: 평택 | F8: =IFERROR(C8-(D8*B8),"") -> 0
A9: 포천2(저온) | B9: =$B$4 -> 60 | C9: =IFERROR(VLOOKUP(A9,'이그니스 피벗'!A:AM,4,FALSE),0) -> 0 | D9: =IFERROR(ROUNDDOWN(C9/B9,0),"") -> 0 | E9: 포천 | F9: =IFERROR(C9-(D9*B9),"") -> 0
A10: 양지2(저온) | B10: =$B$4 -> 60 | C10: =IFERROR(VLOOKUP(A10,'이그니스 피벗'!A:AM,4,FALSE),0) -> 0 | D10: =IFERROR(ROUNDDOWN(C10/B10,0),"") -> 0 | E10: 양지 | F10: =IFERROR(C10-(D10*B10),"") -> 0
A11: 수도권 합계 | B11: =$B$4 -> 60 | C11: =SUM($C$4:$C$10) -> 0 | D11: =IFERROR(ROUNDDOWN(C11/B11,0),"") -> 0 | F11: =IFERROR(C11-(D11*B11),"") -> 0
A13: 김해2(저온) | B13: =$B$4 -> 60 | C13: =IFERROR(VLOOKUP(A13,'이그니스 피벗'!A:AM,4,FALSE),0) -> 0 | D13: =IFERROR(ROUNDDOWN(C13/B13,0),"") -> 0 | E13: 김해 | F13: =IFERROR(C13-(D13*B13),"") -> 0
A14: 양산2(저온) | B14: =$B$4 -> 60 | C14: =IFERROR(VLOOKUP(A14,'이그니스 피벗'!A:AM,4,FALSE),0) -> 0 | D14: =IFERROR(ROUNDDOWN(C14/B14,0),"") -> 0 | E14: 양산 | F14: =IFERROR(C14-(D14*B14),"") -> 0
A15: 경남(김해) 합계 | B15: =$B$4 -> 60 | C15: =SUM($C$13:$C$14) -> 0 | D15: =IFERROR(ROUNDDOWN(C15/B15,0),"") -> 0 | F15: =IFERROR(C15-(D15*B15),"") -> 0
A17: 김천2(저온) | B17: =$B$4 -> 60 | C17: =IFERROR(VLOOKUP(A17,'이그니스 피벗'!A:AM,4,FALSE),0) -> 0 | D17: =IFERROR(ROUNDDOWN(C17/B17,0),"") -> 0 | E17: 김천 | F17: =IFERROR(C17-(D17*B17),"") -> 0
A18: 경산2(저온) | B18: =$B$4 -> 60 | C18: =IFERROR(VLOOKUP(A18,'이그니스 피벗'!A:AM,4,FALSE),0) -> 0 | D18: =IFERROR(ROUNDDOWN(C18/B18,0),"") -> 0 | E18: 경산 | F18: =IFERROR(C18-(D18*B18),"") -> 0
A19: 경북(칠곡) 합계 | B19: =$B$4 -> 60 | C19: =SUM($C$17:$C$18) -> 0 | D19: =IFERROR(ROUNDDOWN(C19/B19,0),"") -> 0 | F19: =IFERROR(C19-(D19*B19),"") -> 0
A21: 장성2(저온) | B21: =$B$4 -> 60 | C21: =IFERROR(VLOOKUP(A21,'이그니스 피벗'!A:AM,4,FALSE),0) -> 0 | D21: =IFERROR(ROUNDDOWN(C21/B21,0),"") -> 0 | E21: 장성 | F21: =IFERROR(C21-(D21*B21),"") -> 0
A22: 호남 합계 | B22: =$B$4 -> 60 | C22: =SUM($C$21) -> 0 | D22: =IFERROR(ROUNDDOWN(C22/B22,0),"") -> 0 | F22: =IFERROR(C22-(D22*B22),"") -> 0
A24: 총합계 | B24: =B4 -> 60 | C24: =SUM(C4:C10,C13:C14,C17:C18,C21) -> 0 | D24: =IFERROR(ROUNDDOWN(C24/B24,0),"") -> 0 | F24: =IFERROR(C24-(D24*B24),"") -> 0
A25: 총 박스 수량 / 총 낱개 수량 | D25: =SUM(D4:D10,D13:D14,D17:D18,D21) -> 0 | F25: =SUM(F4:F10,F13:F14,F17:F18,F21) -> 0

Sheet 한끼통살)오리지널닭가슴살100g
A2: =TODAY() -> 46309 | C2: 이마트24(냉동) - 이그니스
A3: ='이그니스 피벗'!A2 -> 0 | B3: 입수 | C3: 한끼통살)오리지널 닭가슴살100g | D3: 박스 | E3: 센터명 | F3: 낱개
A4: 원주2(저온) | B4: 60 | C4: =IFERROR(VLOOKUP(A4,'이그니스 피벗'!A:AM,5,FALSE),0) -> 0 | D4: =IFERROR(ROUNDDOWN(C4/B4,0),"") -> 0 | E4: 원주 | F4: =IFERROR(C4-(D4*B4),"") -> 0
A5: 세종2(저온) | B5: =$B$4 -> 60 | C5: =IFERROR(VLOOKUP(A5,'이그니스 피벗'!A:AM,5,FALSE),0) -> 0 | D5: =IFERROR(ROUNDDOWN(C5/B5,0),"") -> 0 | E5: 세종 | F5: =IFERROR(C5-(D5*B5),"") -> 0
A6: 화성2(저온) | B6: =$B$4 -> 60 | C6: =IFERROR(VLOOKUP(A6,'이그니스 피벗'!A:AM,5,FALSE),0) -> 0 | D6: =IFERROR(ROUNDDOWN(C6/B6,0),"") -> 0 | E6: 화성 | F6: =IFERROR(C6-(D6*B6),"") -> 0
A7: 청라2(저온) | B7: =$B$4 -> 60 | C7: =IFERROR(VLOOKUP(A7,'이그니스 피벗'!A:AM,5,FALSE),0) -> 0 | D7: =IFERROR(ROUNDDOWN(C7/B7,0),"") -> 0 | E7: 청라 | F7: =IFERROR(C7-(D7*B7),"") -> 0
A8: 평택2(저온) | B8: =$B$4 -> 60 | C8: =IFERROR(VLOOKUP(A8,'이그니스 피벗'!A:AM,5,FALSE),0) -> 0 | D8: =IFERROR(ROUNDDOWN(C8/B8,0),"") -> 0 | E8: 평택 | F8: =IFERROR(C8-(D8*B8),"") -> 0
A9: 포천2(저온) | B9: =$B$4 -> 60 | C9: =IFERROR(VLOOKUP(A9,'이그니스 피벗'!A:AM,5,FALSE),0) -> 0 | D9: =IFERROR(ROUNDDOWN(C9/B9,0),"") -> 0 | E9: 포천 | F9: =IFERROR(C9-(D9*B9),"") -> 0
A10: 양지2(저온) | B10: =$B$4 -> 60 | C10: =IFERROR(VLOOKUP(A10,'이그니스 피벗'!A:AM,5,FALSE),0) -> 0 | D10: =IFERROR(ROUNDDOWN(C10/B10,0),"") -> 0 | E10: 양지 | F10: =IFERROR(C10-(D10*B10),"") -> 0
A11: 수도권 합계 | B11: =$B$4 -> 60 | C11: =SUM($C$4:$C$10) -> 0 | D11: =IFERROR(ROUNDDOWN(C11/B11,0),"") -> 0 | F11: =IFERROR(C11-(D11*B11),"") -> 0
A13: 김해2(저온) | B13: =$B$4 -> 60 | C13: =IFERROR(VLOOKUP(A13,'이그니스 피벗'!A:AM,5,FALSE),0) -> 0 | D13: =IFERROR(ROUNDDOWN(C13/B13,0),"") -> 0 | E13: 김해 | F13: =IFERROR(C13-(D13*B13),"") -> 0
A14: 양산2(저온) | B14: =$B$4 -> 60 | C14: =IFERROR(VLOOKUP(A14,'이그니스 피벗'!A:AM,5,FALSE),0) -> 0 | D14: =IFERROR(ROUNDDOWN(C14/B14,0),"") -> 0 | E14: 양산 | F14: =IFERROR(C14-(D14*B14),"") -> 0
A15: 경남(김해) 합계 | B15: =$B$4 -> 60 | C15: =SUM($C$13:$C$14) -> 0 | D15: =IFERROR(ROUNDDOWN(C15/B15,0),"") -> 0 | F15: =IFERROR(C15-(D15*B15),"") -> 0
A17: 김천2(저온) | B17: =$B$4 -> 60 | C17: =IFERROR(VLOOKUP(A17,'이그니스 피벗'!A:AM,5,FALSE),0) -> 0 | D17: =IFERROR(ROUNDDOWN(C17/B17,0),"") -> 0 | E17: 김천 | F17: =IFERROR(C17-(D17*B17),"") -> 0
A18: 경산2(저온) | B18: =$B$4 -> 60 | C18: =IFERROR(VLOOKUP(A18,'이그니스 피벗'!A:AM,5,FALSE),0) -> 0 | D18: =IFERROR(ROUNDDOWN(C18/B18,0),"") -> 0 | E18: 경산 | F18: =IFERROR(C18-(D18*B18),"") -> 0
A19: 경북(칠곡) 합계 | B19: =$B$4 -> 60 | C19: =SUM($C$17:$C$18) -> 0 | D19: =IFERROR(ROUNDDOWN(C19/B19,0),"") -> 0 | F19: =IFERROR(C19-(D19*B19),"") -> 0
A21: 장성2(저온) | B21: =$B$4 -> 60 | C21: =IFERROR(VLOOKUP(A21,'이그니스 피벗'!A:AM,5,FALSE),0) -> 0 | D21: =IFERROR(ROUNDDOWN(C21/B21,0),"") -> 0 | E21: 장성 | F21: =IFERROR(C21-(D21*B21),"") -> 0
A22: 호남 합계 | B22: =$B$4 -> 60 | C22: =SUM($C$21) -> 0 | D22: =IFERROR(ROUNDDOWN(C22/B22,0),"") -> 0 | F22: =IFERROR(C22-(D22*B22),"") -> 0
A24: 총합계 | B24: =B4 -> 60 | C24: =SUM(C4:C10,C13:C14,C17:C18,C21) -> 0 | D24: =IFERROR(ROUNDDOWN(C24/B24,0),"") -> 0 | F24: =IFERROR(C24-(D24*B24),"") -> 0
A25: 총 박스 수량 / 총 낱개 수량 | D25: =SUM(D4:D10,D13:D14,D17:D18,D21) -> 0 | F25: =SUM(F4:F10,F13:F14,F17:F18,F21) -> 0

Sheet 미스터밀크피벗
A1: 10/14 | B1: 열 레이블
A2: 10/15 납품 | B2: 제주성이시돌목장)녹차젤라또미니컵100ml | D2: 제주성이시돌목장)요거트젤라또미니컵100ml | E2: 제주성이시돌목장)요거트젤라또파인트473ml | F2: 제주성이시돌목장)우유젤라또미니컵100ml | G2: 제주성이시돌목장)우유젤라또파인트473ml | H2: 제주성이시돌목장)초코젤라또미니컵100ml | J2: 총합계
A3: 장성2(저온) | G3: 8 | J3: 8
A4: 김천2(저온) | H4: 24 | J4: 24
A5: 경산2(저온) | H5: 24 | J5: 24
A6: 화성2(저온) | F6: 24 | H6: 24 | J6: 48
A7: 포천2(저온) | B7: 24 | D7: 24 | F7: 48 | J7: 96
A8: 양지2(저온) | E8: 8 | J8: 8
A9: 총합계 | B9: 24 | D9: 24 | E9: 8 | F9: 72 | G9: 8 | H9: 72 | J9: 208

Sheet 제주성이시돌목장)녹차젤라또미니컵
A2: =TODAY() -> 46309 | C2: 이마트24(냉동) - 미스터밀크
A3: =미스터밀크피벗!A2 -> 10/15 납품 | B3: 입수 | C3: 제주성이시돌목장)녹차젤라또미니컵100ml | D3: 박스 | E3: 센터명 | F3: 낱개
A4: 원주2(저온) | B4: 24 | C4: =IFERROR(VLOOKUP(A4,미스터밀크피벗!A:BL,2,FALSE),0) -> 0 | D4: =IFERROR(ROUNDDOWN(C4/B4,0),"") -> 0 | E4: 원주 | F4: =IFERROR(C4-(D4*B4),"") -> 0
A5: 세종2(저온) | B5: =$B$4 -> 24 | C5: =IFERROR(VLOOKUP(A5,미스터밀크피벗!A:BL,2,FALSE),0) -> 0 | D5: =IFERROR(ROUNDDOWN(C5/B5,0),"") -> 0 | E5: 세종 | F5: =IFERROR(C5-(D5*B5),"") -> 0
A6: 화성2(저온) | B6: =$B$4 -> 24 | C6: =IFERROR(VLOOKUP(A6,미스터밀크피벗!A:BL,2,FALSE),0) -> 0 | D6: =IFERROR(ROUNDDOWN(C6/B6,0),"") -> 0 | E6: 화성 | F6: =IFERROR(C6-(D6*B6),"") -> 0
A7: 청라2(저온) | B7: =$B$4 -> 24 | C7: =IFERROR(VLOOKUP(A7,미스터밀크피벗!A:BL,2,FALSE),0) -> 0 | D7: =IFERROR(ROUNDDOWN(C7/B7,0),"") -> 0 | E7: 청라 | F7: =IFERROR(C7-(D7*B7),"") -> 0
A8: 평택2(저온) | B8: =$B$4 -> 24 | C8: =IFERROR(VLOOKUP(A8,미스터밀크피벗!A:BL,2,FALSE),0) -> 0 | D8: =IFERROR(ROUNDDOWN(C8/B8,0),"") -> 0 | E8: 평택 | F8: =IFERROR(C8-(D8*B8),"") -> 0
A9: 포천2(저온) | B9: =$B$4 -> 24 | C9: =IFERROR(VLOOKUP(A9,미스터밀크피벗!A:BL,2,FALSE),0) -> 24 | D9: =IFERROR(ROUNDDOWN(C9/B9,0),"") -> 1 | E9: 포천 | F9: =IFERROR(C9-(D9*B9),"") -> 0
A10: 양지2(저온) | B10: =$B$4 -> 24 | C10: =IFERROR(VLOOKUP(A10,미스터밀크피벗!A:BL,2,FALSE),0) -> 0 | D10: =IFERROR(ROUNDDOWN(C10/B10,0),"") -> 0 | E10: 양지 | F10: =IFERROR(C10-(D10*B10),"") -> 0
A11: 수도권 합계 | B11: =$B$4 -> 24 | C11: =SUM($C$4:$C$10) -> 24 | D11: =IFERROR(ROUNDDOWN(C11/B11,0),"") -> 1 | F11: =IFERROR(C11-(D11*B11),"") -> 0
A13: 김해2(저온) | B13: =$B$4 -> 24 | C13: =IFERROR(VLOOKUP(A13,미스터밀크피벗!A:BL,2,FALSE),0) -> 0 | D13: =IFERROR(ROUNDDOWN(C13/B13,0),"") -> 0 | E13: 김해 | F13: =IFERROR(C13-(D13*B13),"") -> 0
A14: 양산2(저온) | B14: =$B$4 -> 24 | C14: =IFERROR(VLOOKUP(A14,미스터밀크피벗!A:BL,2,FALSE),0) -> 0 | D14: =IFERROR(ROUNDDOWN(C14/B14,0),"") -> 0 | E14: 양산 | F14: =IFERROR(C14-(D14*B14),"") -> 0
A15: 경남(김해) 합계 | B15: =$B$4 -> 24 | C15: =SUM($C$13:$C$14) -> 0 | D15: =IFERROR(ROUNDDOWN(C15/B15,0),"") -> 0 | F15: =IFERROR(C15-(D15*B15),"") -> 0
A17: 김천2(저온) | B17: =$B$4 -> 24 | C17: =IFERROR(VLOOKUP(A17,미스터밀크피벗!A:BL,2,FALSE),0) -> 0 | D17: =IFERROR(ROUNDDOWN(C17/B17,0),"") -> 0 | E17: 김천 | F17: =IFERROR(C17-(D17*B17),"") -> 0
A18: 경산2(저온) | B18: =$B$4 -> 24 | C18: =IFERROR(VLOOKUP(A18,미스터밀크피벗!A:BL,2,FALSE),0) -> 0 | D18: =IFERROR(ROUNDDOWN(C18/B18,0),"") -> 0 | E18: 경산 | F18: =IFERROR(C18-(D18*B18),"") -> 0
A19: 경북(칠곡) 합계 | B19: =$B$4 -> 24 | C19: =SUM($C$17:$C$18) -> 0 | D19: =IFERROR(ROUNDDOWN(C19/B19,0),"") -> 0 | F19: =IFERROR(C19-(D19*B19),"") -> 0
A21: 장성2(저온) | B21: =$B$4 -> 24 | C21: =IFERROR(VLOOKUP(A21,미스터밀크피벗!A:BL,2,FALSE),0) -> 0 | D21: =IFERROR(ROUNDDOWN(C21/B21,0),"") -> 0 | E21: 장성 | F21: =IFERROR(C21-(D21*B21),"") -> 0
A22: 호남 합계 | B22: =$B$4 -> 24 | C22: =SUM($C$21) -> 0 | D22: =IFERROR(ROUNDDOWN(C22/B22,0),"") -> 0 | F22: =IFERROR(C22-(D22*B22),"") -> 0
A24: 총합계 | B24: =B4 -> 24 | C24: =SUM(C11,C15,C19,C22) -> 24 | D24: =IFERROR(ROUNDDOWN(C24/B24,0),"") -> 1 | F24: =IFERROR(C24-(D24*B24),"") -> 0
A25: 총 박스 수량 / 총 낱개 수량 | D25: =SUM(D4:D10,D13:D14,D17:D18,D21) -> 1 | F25: =SUM(F11,F15,F19,F22) -> 0

Sheet 제주성이시돌목장)녹차젤라또파인트
A2: =TODAY() -> 46309 | C2: 이마트24(냉동) - 미스터밀크
A3: =미스터밀크피벗!A2 -> 10/15 납품 | B3: 입수 | C3: 제주성이시돌목장)녹차젤라또파인트473ml | D3: 박스 | E3: 센터명 | F3: 낱개
A4: 원주2(저온) | B4: 8 | C4: =IFERROR(VLOOKUP(A4,미스터밀크피벗!A:BL,3,FALSE),0) -> 0 | D4: =IFERROR(ROUNDDOWN(C4/B4,0),"") -> 0 | E4: 원주 | F4: =IFERROR(C4-(D4*B4),"") -> 0
A5: 세종2(저온) | B5: =$B$4 -> 8 | C5: =IFERROR(VLOOKUP(A5,미스터밀크피벗!A:BL,3,FALSE),0) -> 0 | D5: =IFERROR(ROUNDDOWN(C5/B5,0),"") -> 0 | E5: 세종 | F5: =IFERROR(C5-(D5*B5),"") -> 0
A6: 화성2(저온) | B6: =$B$4 -> 8 | C6: =IFERROR(VLOOKUP(A6,미스터밀크피벗!A:BL,3,FALSE),0) -> 0 | D6: =IFERROR(ROUNDDOWN(C6/B6,0),"") -> 0 | E6: 화성 | F6: =IFERROR(C6-(D6*B6),"") -> 0
A7: 청라2(저온) | B7: =$B$4 -> 8 | C7: =IFERROR(VLOOKUP(A7,미스터밀크피벗!A:BL,3,FALSE),0) -> 0 | D7: =IFERROR(ROUNDDOWN(C7/B7,0),"") -> 0 | E7: 청라 | F7: =IFERROR(C7-(D7*B7),"") -> 0
A8: 평택2(저온) | B8: =$B$4 -> 8 | C8: =IFERROR(VLOOKUP(A8,미스터밀크피벗!A:BL,3,FALSE),0) -> 0 | D8: =IFERROR(ROUNDDOWN(C8/B8,0),"") -> 0 | E8: 평택 | F8: =IFERROR(C8-(D8*B8),"") -> 0
A9: 포천2(저온) | B9: =$B$4 -> 8 | C9: =IFERROR(VLOOKUP(A9,미스터밀크피벗!A:BL,3,FALSE),0) -> 0 | D9: =IFERROR(ROUNDDOWN(C9/B9,0),"") -> 0 | E9: 포천 | F9: =IFERROR(C9-(D9*B9),"") -> 0
A10: 양지2(저온) | B10: =$B$4 -> 8 | C10: =IFERROR(VLOOKUP(A10,미스터밀크피벗!A:BL,3,FALSE),0) -> 0 | D10: =IFERROR(ROUNDDOWN(C10/B10,0),"") -> 0 | E10: 양지 | F10: =IFERROR(C10-(D10*B10),"") -> 0
A11: 수도권 합계 | B11: =$B$4 -> 8 | C11: =SUM($C$4:$C$10) -> 0 | D11: =IFERROR(ROUNDDOWN(C11/B11,0),"") -> 0 | F11: =IFERROR(C11-(D11*B11),"") -> 0
A13: 김해2(저온) | B13: =$B$4 -> 8 | C13: =IFERROR(VLOOKUP(A13,미스터밀크피벗!A:BL,3,FALSE),0) -> 0 | D13: =IFERROR(ROUNDDOWN(C13/B13,0),"") -> 0 | E13: 김해 | F13: =IFERROR(C13-(D13*B13),"") -> 0
A14: 양산2(저온) | B14: =$B$4 -> 8 | C14: =IFERROR(VLOOKUP(A14,미스터밀크피벗!A:BL,3,FALSE),0) -> 0 | D14: =IFERROR(ROUNDDOWN(C14/B14,0),"") -> 0 | E14: 양산 | F14: =IFERROR(C14-(D14*B14),"") -> 0
A15: 경남(김해) 합계 | B15: =$B$4 -> 8 | C15: =SUM($C$13:$C$14) -> 0 | D15: =IFERROR(ROUNDDOWN(C15/B15,0),"") -> 0 | F15: =IFERROR(C15-(D15*B15),"") -> 0
A17: 김천2(저온) | B17: =$B$4 -> 8 | C17: =IFERROR(VLOOKUP(A17,미스터밀크피벗!A:BL,3,FALSE),0) -> 0 | D17: =IFERROR(ROUNDDOWN(C17/B17,0),"") -> 0 | E17: 김천 | F17: =IFERROR(C17-(D17*B17),"") -> 0
A18: 경산2(저온) | B18: =$B$4 -> 8 | C18: =IFERROR(VLOOKUP(A18,미스터밀크피벗!A:BL,3,FALSE),0) -> 0 | D18: =IFERROR(ROUNDDOWN(C18/B18,0),"") -> 0 | E18: 경산 | F18: =IFERROR(C18-(D18*B18),"") -> 0
A19: 경북(칠곡) 합계 | B19: =$B$4 -> 8 | C19: =SUM($C$17:$C$18) -> 0 | D19: =IFERROR(ROUNDDOWN(C19/B19,0),"") -> 0 | F19: =IFERROR(C19-(D19*B19),"") -> 0
A21: 장성2(저온) | B21: =$B$4 -> 8 | C21: =IFERROR(VLOOKUP(A21,미스터밀크피벗!A:BL,3,FALSE),0) -> 0 | D21: =IFERROR(ROUNDDOWN(C21/B21,0),"") -> 0 | E21: 장성 | F21: =IFERROR(C21-(D21*B21),"") -> 0
A22: 호남 합계 | B22: =$B$4 -> 8 | C22: =SUM($C$21) -> 0 | D22: =IFERROR(ROUNDDOWN(C22/B22,0),"") -> 0 | F22: =IFERROR(C22-(D22*B22),"") -> 0
A24: 총합계 | B24: =B4 -> 8 | C24: =SUM(C11,C15,C19,C22) -> 0 | D24: =IFERROR(ROUNDDOWN(C24/B24,0),"") -> 0 | F24: =IFERROR(C24-(D24*B24),"") -> 0
A25: 총 박스 수량 / 총 낱개 수량 | D25: =SUM(D4:D10,D13:D14,D17:D18,D21) -> 0 | F25: =SUM(F11,F15,F19,F22) -> 0

Sheet 제주성이시돌목장)요거트젤라또미니컵
A2: =TODAY() -> 46309 | C2: 이마트24(냉동) - 미스터밀크
A3: =미스터밀크피벗!A2 -> 10/15 납품 | B3: 입수 | C3: 제주성이시돌목장)요거트젤라또미니컵100ml | D3: 박스 | E3: 센터명 | F3: 낱개
A4: 원주2(저온) | B4: 24 | C4: =IFERROR(VLOOKUP(A4,미스터밀크피벗!A:BL,4,FALSE),0) -> 0 | D4: =IFERROR(ROUNDDOWN(C4/B4,0),"") -> 0 | E4: 원주 | F4: =IFERROR(C4-(D4*B4),"") -> 0
A5: 세종2(저온) | B5: =$B$4 -> 24 | C5: =IFERROR(VLOOKUP(A5,미스터밀크피벗!A:BL,4,FALSE),0) -> 0 | D5: =IFERROR(ROUNDDOWN(C5/B5,0),"") -> 0 | E5: 세종 | F5: =IFERROR(C5-(D5*B5),"") -> 0
A6: 화성2(저온) | B6: =$B$4 -> 24 | C6: =IFERROR(VLOOKUP(A6,미스터밀크피벗!A:BL,4,FALSE),0) -> 0 | D6: =IFERROR(ROUNDDOWN(C6/B6,0),"") -> 0 | E6: 화성 | F6: =IFERROR(C6-(D6*B6),"") -> 0
A7: 청라2(저온) | B7: =$B$4 -> 24 | C7: =IFERROR(VLOOKUP(A7,미스터밀크피벗!A:BL,4,FALSE),0) -> 0 | D7: =IFERROR(ROUNDDOWN(C7/B7,0),"") -> 0 | E7: 청라 | F7: =IFERROR(C7-(D7*B7),"") -> 0
A8: 평택2(저온) | B8: =$B$4 -> 24 | C8: =IFERROR(VLOOKUP(A8,미스터밀크피벗!A:BL,4,FALSE),0) -> 0 | D8: =IFERROR(ROUNDDOWN(C8/B8,0),"") -> 0 | E8: 평택 | F8: =IFERROR(C8-(D8*B8),"") -> 0
A9: 포천2(저온) | B9: =$B$4 -> 24 | C9: =IFERROR(VLOOKUP(A9,미스터밀크피벗!A:BL,4,FALSE),0) -> 24 | D9: =IFERROR(ROUNDDOWN(C9/B9,0),"") -> 1 | E9: 포천 | F9: =IFERROR(C9-(D9*B9),"") -> 0
A10: 양지2(저온) | B10: =$B$4 -> 24 | C10: =IFERROR(VLOOKUP(A10,미스터밀크피벗!A:BL,4,FALSE),0) -> 0 | D10: =IFERROR(ROUNDDOWN(C10/B10,0),"") -> 0 | E10: 양지 | F10: =IFERROR(C10-(D10*B10),"") -> 0
A11: 수도권 합계 | B11: =$B$4 -> 24 | C11: =SUM($C$4:$C$10) -> 24 | D11: =IFERROR(ROUNDDOWN(C11/B11,0),"") -> 1 | F11: =IFERROR(C11-(D11*B11),"") -> 0
A13: 김해2(저온) | B13: =$B$4 -> 24 | C13: =IFERROR(VLOOKUP(A13,미스터밀크피벗!A:BL,4,FALSE),0) -> 0 | D13: =IFERROR(ROUNDDOWN(C13/B13,0),"") -> 0 | E13: 김해 | F13: =IFERROR(C13-(D13*B13),"") -> 0
A14: 양산2(저온) | B14: =$B$4 -> 24 | C14: =IFERROR(VLOOKUP(A14,미스터밀크피벗!A:BL,4,FALSE),0) -> 0 | D14: =IFERROR(ROUNDDOWN(C14/B14,0),"") -> 0 | E14: 양산 | F14: =IFERROR(C14-(D14*B14),"") -> 0
A15: 경남(김해) 합계 | B15: =$B$4 -> 24 | C15: =SUM($C$13:$C$14) -> 0 | D15: =IFERROR(ROUNDDOWN(C15/B15,0),"") -> 0 | F15: =IFERROR(C15-(D15*B15),"") -> 0
A17: 김천2(저온) | B17: =$B$4 -> 24 | C17: =IFERROR(VLOOKUP(A17,미스터밀크피벗!A:BL,4,FALSE),0) -> 0 | D17: =IFERROR(ROUNDDOWN(C17/B17,0),"") -> 0 | E17: 김천 | F17: =IFERROR(C17-(D17*B17),"") -> 0
A18: 경산2(저온) | B18: =$B$4 -> 24 | C18: =IFERROR(VLOOKUP(A18,미스터밀크피벗!A:BL,4,FALSE),0) -> 0 | D18: =IFERROR(ROUNDDOWN(C18/B18,0),"") -> 0 | E18: 경산 | F18: =IFERROR(C18-(D18*B18),"") -> 0
A19: 경북(칠곡) 합계 | B19: =$B$4 -> 24 | C19: =SUM($C$17:$C$18) -> 0 | D19: =IFERROR(ROUNDDOWN(C19/B19,0),"") -> 0 | F19: =IFERROR(C19-(D19*B19),"") -> 0
A21: 장성2(저온) | B21: =$B$4 -> 24 | C21: =IFERROR(VLOOKUP(A21,미스터밀크피벗!A:BL,4,FALSE),0) -> 0 | D21: =IFERROR(ROUNDDOWN(C21/B21,0),"") -> 0 | E21: 장성 | F21: =IFERROR(C21-(D21*B21),"") -> 0
A22: 호남 합계 | B22: =$B$4 -> 24 | C22: =SUM($C$21) -> 0 | D22: =IFERROR(ROUNDDOWN(C22/B22,0),"") -> 0 | F22: =IFERROR(C22-(D22*B22),"") -> 0
A24: 총합계 | B24: =B4 -> 24 | C24: =SUM(C11,C15,C19,C22) -> 24 | D24: =IFERROR(ROUNDDOWN(C24/B24,0),"") -> 1 | F24: =IFERROR(C24-(D24*B24),"") -> 0
A25: 총 박스 수량 / 총 낱개 수량 | D25: =SUM(D4:D10,D13:D14,D17:D18,D21) -> 1 | F25: =SUM(F11,F15,F19,F22) -> 0

Sheet 제주성이시돌목장)요거트젤라또파인트473ml
A2: =TODAY() -> 46309 | C2: 이마트24(냉동) - 미스터밀크
A3: =미스터밀크피벗!A2 -> 10/15 납품 | B3: 입수 | C3: 제주성이시돌목장) 요거트젤라또파인트473ml | D3: 박스 | E3: 센터명 | F3: 낱개
A4: 원주2(저온) | B4: 8 | C4: =IFERROR(VLOOKUP(A4,미스터밀크피벗!A:BL,5,FALSE),0) -> 0 | D4: =IFERROR(ROUNDDOWN(C4/B4,0),"") -> 0 | E4: 원주 | F4: =IFERROR(C4-(D4*B4),"") -> 0
A5: 세종2(저온) | B5: =$B$4 -> 8 | C5: =IFERROR(VLOOKUP(A5,미스터밀크피벗!A:BL,5,FALSE),0) -> 0 | D5: =IFERROR(ROUNDDOWN(C5/B5,0),"") -> 0 | E5: 세종 | F5: =IFERROR(C5-(D5*B5),"") -> 0
A6: 화성2(저온) | B6: =$B$4 -> 8 | C6: =IFERROR(VLOOKUP(A6,미스터밀크피벗!A:BL,5,FALSE),0) -> 0 | D6: =IFERROR(ROUNDDOWN(C6/B6,0),"") -> 0 | E6: 화성 | F6: =IFERROR(C6-(D6*B6),"") -> 0
A7: 청라2(저온) | B7: =$B$4 -> 8 | C7: =IFERROR(VLOOKUP(A7,미스터밀크피벗!A:BL,5,FALSE),0) -> 0 | D7: =IFERROR(ROUNDDOWN(C7/B7,0),"") -> 0 | E7: 청라 | F7: =IFERROR(C7-(D7*B7),"") -> 0
A8: 평택2(저온) | B8: =$B$4 -> 8 | C8: =IFERROR(VLOOKUP(A8,미스터밀크피벗!A:BL,5,FALSE),0) -> 0 | D8: =IFERROR(ROUNDDOWN(C8/B8,0),"") -> 0 | E8: 평택 | F8: =IFERROR(C8-(D8*B8),"") -> 0
A9: 포천2(저온) | B9: =$B$4 -> 8 | C9: =IFERROR(VLOOKUP(A9,미스터밀크피벗!A:BL,5,FALSE),0) -> 0 | D9: =IFERROR(ROUNDDOWN(C9/B9,0),"") -> 0 | E9: 포천 | F9: =IFERROR(C9-(D9*B9),"") -> 0
A10: 양지2(저온) | B10: =$B$4 -> 8 | C10: =IFERROR(VLOOKUP(A10,미스터밀크피벗!A:BL,5,FALSE),0) -> 8 | D10: =IFERROR(ROUNDDOWN(C10/B10,0),"") -> 1 | E10: 양지 | F10: =IFERROR(C10-(D10*B10),"") -> 0
A11: 수도권 합계 | B11: =$B$4 -> 8 | C11: =SUM($C$4:$C$10) -> 8 | D11: =IFERROR(ROUNDDOWN(C11/B11,0),"") -> 1 | F11: =IFERROR(C11-(D11*B11),"") -> 0
A13: 김해2(저온) | B13: =$B$4 -> 8 | C13: =IFERROR(VLOOKUP(A13,미스터밀크피벗!A:BL,5,FALSE),0) -> 0 | D13: =IFERROR(ROUNDDOWN(C13/B13,0),"") -> 0 | E13: 김해 | F13: =IFERROR(C13-(D13*B13),"") -> 0
A14: 양산2(저온) | B14: =$B$4 -> 8 | C14: =IFERROR(VLOOKUP(A14,미스터밀크피벗!A:BL,5,FALSE),0) -> 0 | D14: =IFERROR(ROUNDDOWN(C14/B14,0),"") -> 0 | E14: 양산 | F14: =IFERROR(C14-(D14*B14),"") -> 0
A15: 경남(김해) 합계 | B15: =$B$4 -> 8 | C15: =SUM($C$13:$C$14) -> 0 | D15: =IFERROR(ROUNDDOWN(C15/B15,0),"") -> 0 | F15: =IFERROR(C15-(D15*B15),"") -> 0
A17: 김천2(저온) | B17: =$B$4 -> 8 | C17: =IFERROR(VLOOKUP(A17,미스터밀크피벗!A:BL,5,FALSE),0) -> 0 | D17: =IFERROR(ROUNDDOWN(C17/B17,0),"") -> 0 | E17: 김천 | F17: =IFERROR(C17-(D17*B17),"") -> 0
A18: 경산2(저온) | B18: =$B$4 -> 8 | C18: =IFERROR(VLOOKUP(A18,미스터밀크피벗!A:BL,5,FALSE),0) -> 0 | D18: =IFERROR(ROUNDDOWN(C18/B18,0),"") -> 0 | E18: 경산 | F18: =IFERROR(C18-(D18*B18),"") -> 0
A19: 경북(칠곡) 합계 | B19: =$B$4 -> 8 | C19: =SUM($C$17:$C$18) -> 0 | D19: =IFERROR(ROUNDDOWN(C19/B19,0),"") -> 0 | F19: =IFERROR(C19-(D19*B19),"") -> 0
A21: 장성2(저온) | B21: =$B$4 -> 8 | C21: =IFERROR(VLOOKUP(A21,미스터밀크피벗!A:BL,5,FALSE),0) -> 0 | D21: =IFERROR(ROUNDDOWN(C21/B21,0),"") -> 0 | E21: 장성 | F21: =IFERROR(C21-(D21*B21),"") -> 0
A22: 호남 합계 | B22: =$B$4 -> 8 | C22: =SUM($C$21) -> 0 | D22: =IFERROR(ROUNDDOWN(C22/B22,0),"") -> 0 | F22: =IFERROR(C22-(D22*B22),"") -> 0
A24: 총합계 | B24: =B4 -> 8 | C24: =SUM(C11,C15,C19,C22) -> 8 | D24: =IFERROR(ROUNDDOWN(C24/B24,0),"") -> 1 | F24: =IFERROR(C24-(D24*B24),"") -> 0
A25: 총 박스 수량 / 총 낱개 수량 | D25: =SUM(D4:D10,D13:D14,D17:D18,D21) -> 1 | F25: =SUM(F11,F15,F19,F22) -> 0

Sheet 제주성이시돌목장)우유젤라또미니컵
A2: =TODAY() -> 46309 | C2: 이마트24(냉동) - 미스터밀크
A3: =미스터밀크피벗!A2 -> 10/15 납품 | B3: 입수 | C3: 제주성이시돌목장) 우유젤라또미니컵100ml | D3: 박스 | E3: 센터명 | F3: 낱개
A4: 원주2(저온) | B4: 24 | C4: =IFERROR(VLOOKUP(A4,미스터밀크피벗!A:BL,6,FALSE),0) -> 0 | D4: =IFERROR(ROUNDDOWN(C4/B4,0),"") -> 0 | E4: 원주 | F4: =IFERROR(C4-(D4*B4),"") -> 0
A5: 세종2(저온) | B5: =$B$4 -> 24 | C5: =IFERROR(VLOOKUP(A5,미스터밀크피벗!A:BL,6,FALSE),0) -> 0 | D5: =IFERROR(ROUNDDOWN(C5/B5,0),"") -> 0 | E5: 세종 | F5: =IFERROR(C5-(D5*B5),"") -> 0
A6: 화성2(저온) | B6: =$B$4 -> 24 | C6: =IFERROR(VLOOKUP(A6,미스터밀크피벗!A:BL,6,FALSE),0) -> 24 | D6: =IFERROR(ROUNDDOWN(C6/B6,0),"") -> 1 | E6: 화성 | F6: =IFERROR(C6-(D6*B6),"") -> 0
A7: 청라2(저온) | B7: =$B$4 -> 24 | C7: =IFERROR(VLOOKUP(A7,미스터밀크피벗!A:BL,6,FALSE),0) -> 0 | D7: =IFERROR(ROUNDDOWN(C7/B7,0),"") -> 0 | E7: 청라 | F7: =IFERROR(C7-(D7*B7),"") -> 0
A8: 평택2(저온) | B8: =$B$4 -> 24 | C8: =IFERROR(VLOOKUP(A8,미스터밀크피벗!A:BL,6,FALSE),0) -> 0 | D8: =IFERROR(ROUNDDOWN(C8/B8,0),"") -> 0 | E8: 평택 | F8: =IFERROR(C8-(D8*B8),"") -> 0
A9: 포천2(저온) | B9: =$B$4 -> 24 | C9: =IFERROR(VLOOKUP(A9,미스터밀크피벗!A:BL,6,FALSE),0) -> 48 | D9: =IFERROR(ROUNDDOWN(C9/B9,0),"") -> 2 | E9: 포천 | F9: =IFERROR(C9-(D9*B9),"") -> 0
A10: 양지2(저온) | B10: =$B$4 -> 24 | C10: =IFERROR(VLOOKUP(A10,미스터밀크피벗!A:BL,6,FALSE),0) -> 0 | D10: =IFERROR(ROUNDDOWN(C10/B10,0),"") -> 0 | E10: 양지 | F10: =IFERROR(C10-(D10*B10),"") -> 0
A11: 수도권 합계 | B11: =$B$4 -> 24 | C11: =SUM($C$4:$C$10) -> 72 | D11: =IFERROR(ROUNDDOWN(C11/B11,0),"") -> 3 | F11: =IFERROR(C11-(D11*B11),"") -> 0
A13: 김해2(저온) | B13: =$B$4 -> 24 | C13: =IFERROR(VLOOKUP(A13,미스터밀크피벗!A:BL,6,FALSE),0) -> 0 | D13: =IFERROR(ROUNDDOWN(C13/B13,0),"") -> 0 | E13: 김해 | F13: =IFERROR(C13-(D13*B13),"") -> 0
A14: 양산2(저온) | B14: =$B$4 -> 24 | C14: =IFERROR(VLOOKUP(A14,미스터밀크피벗!A:BL,6,FALSE),0) -> 0 | D14: =IFERROR(ROUNDDOWN(C14/B14,0),"") -> 0 | E14: 양산 | F14: =IFERROR(C14-(D14*B14),"") -> 0
A15: 경남(김해) 합계 | B15: =$B$4 -> 24 | C15: =SUM($C$13:$C$14) -> 0 | D15: =IFERROR(ROUNDDOWN(C15/B15,0),"") -> 0 | F15: =IFERROR(C15-(D15*B15),"") -> 0
A17: 김천2(저온) | B17: =$B$4 -> 24 | C17: =IFERROR(VLOOKUP(A17,미스터밀크피벗!A:BL,6,FALSE),0) -> 0 | D17: =IFERROR(ROUNDDOWN(C17/B17,0),"") -> 0 | E17: 김천 | F17: =IFERROR(C17-(D17*B17),"") -> 0
A18: 경산2(저온) | B18: =$B$4 -> 24 | C18: =IFERROR(VLOOKUP(A18,미스터밀크피벗!A:BL,6,FALSE),0) -> 0 | D18: =IFERROR(ROUNDDOWN(C18/B18,0),"") -> 0 | E18: 경산 | F18: =IFERROR(C18-(D18*B18),"") -> 0
A19: 경북(칠곡) 합계 | B19: =$B$4 -> 24 | C19: =SUM($C$17:$C$18) -> 0 | D19: =IFERROR(ROUNDDOWN(C19/B19,0),"") -> 0 | F19: =IFERROR(C19-(D19*B19),"") -> 0
A21: 장성2(저온) | B21: =$B$4 -> 24 | C21: =IFERROR(VLOOKUP(A21,미스터밀크피벗!A:BL,6,FALSE),0) -> 0 | D21: =IFERROR(ROUNDDOWN(C21/B21,0),"") -> 0 | E21: 장성 | F21: =IFERROR(C21-(D21*B21),"") -> 0
A22: 호남 합계 | B22: =$B$4 -> 24 | C22: =SUM($C$21) -> 0 | D22: =IFERROR(ROUNDDOWN(C22/B22,0),"") -> 0 | F22: =IFERROR(C22-(D22*B22),"") -> 0
A24: 총합계 | B24: =B4 -> 24 | C24: =SUM(C11,C15,C19,C22) -> 72 | D24: =IFERROR(ROUNDDOWN(C24/B24,0),"") -> 3 | F24: =IFERROR(C24-(D24*B24),"") -> 0
A25: 총 박스 수량 / 총 낱개 수량 | D25: =SUM(D4:D10,D13:D14,D17:D18,D21) -> 3 | F25: =SUM(F11,F15,F19,F22) -> 0

Sheet 제주성이시돌목장)우유젤라또파인트473ml
A2: =TODAY() -> 46309 | C2: 이마트24(냉동) - 미스터밀크
A3: =미스터밀크피벗!A2 -> 10/15 납품 | B3: 입수 | C3: 제주성이시돌목장) 우유젤라또파인트473ml | D3: 박스 | E3: 센터명 | F3: 낱개
A4: 원주2(저온) | B4: 8 | C4: =IFERROR(VLOOKUP(A4,미스터밀크피벗!A:BL,7,FALSE),0) -> 0 | D4: =IFERROR(ROUNDDOWN(C4/B4,0),"") -> 0 | E4: 원주 | F4: =IFERROR(C4-(D4*B4),"") -> 0
A5: 세종2(저온) | B5: =$B$4 -> 8 | C5: =IFERROR(VLOOKUP(A5,미스터밀크피벗!A:BL,7,FALSE),0) -> 0 | D5: =IFERROR(ROUNDDOWN(C5/B5,0),"") -> 0 | E5: 세종 | F5: =IFERROR(C5-(D5*B5),"") -> 0
A6: 화성2(저온) | B6: =$B$4 -> 8 | C6: =IFERROR(VLOOKUP(A6,미스터밀크피벗!A:BL,7,FALSE),0) -> 0 | D6: =IFERROR(ROUNDDOWN(C6/B6,0),"") -> 0 | E6: 화성 | F6: =IFERROR(C6-(D6*B6),"") -> 0
A7: 청라2(저온) | B7: =$B$4 -> 8 | C7: =IFERROR(VLOOKUP(A7,미스터밀크피벗!A:BL,7,FALSE),0) -> 0 | D7: =IFERROR(ROUNDDOWN(C7/B7,0),"") -> 0 | E7: 청라 | F7: =IFERROR(C7-(D7*B7),"") -> 0
A8: 평택2(저온) | B8: =$B$4 -> 8 | C8: =IFERROR(VLOOKUP(A8,미스터밀크피벗!A:BL,7,FALSE),0) -> 0 | D8: =IFERROR(ROUNDDOWN(C8/B8,0),"") -> 0 | E8: 평택 | F8: =IFERROR(C8-(D8*B8),"") -> 0
A9: 포천2(저온) | B9: =$B$4 -> 8 | C9: =IFERROR(VLOOKUP(A9,미스터밀크피벗!A:BL,7,FALSE),0) -> 0 | D9: =IFERROR(ROUNDDOWN(C9/B9,0),"") -> 0 | E9: 포천 | F9: =IFERROR(C9-(D9*B9),"") -> 0
A10: 양지2(저온) | B10: =$B$4 -> 8 | C10: =IFERROR(VLOOKUP(A10,미스터밀크피벗!A:BL,7,FALSE),0) -> 0 | D10: =IFERROR(ROUNDDOWN(C10/B10,0),"") -> 0 | E10: 양지 | F10: =IFERROR(C10-(D10*B10),"") -> 0
A11: 수도권 합계 | B11: =$B$4 -> 8 | C11: =SUM($C$4:$C$10) -> 0 | D11: =IFERROR(ROUNDDOWN(C11/B11,0),"") -> 0 | F11: =IFERROR(C11-(D11*B11),"") -> 0
A13: 김해2(저온) | B13: =$B$4 -> 8 | C13: =IFERROR(VLOOKUP(A13,미스터밀크피벗!A:BL,7,FALSE),0) -> 0 | D13: =IFERROR(ROUNDDOWN(C13/B13,0),"") -> 0 | E13: 김해 | F13: =IFERROR(C13-(D13*B13),"") -> 0
A14: 양산2(저온) | B14: =$B$4 -> 8 | C14: =IFERROR(VLOOKUP(A14,미스터밀크피벗!A:BL,7,FALSE),0) -> 0 | D14: =IFERROR(ROUNDDOWN(C14/B14,0),"") -> 0 | E14: 양산 | F14: =IFERROR(C14-(D14*B14),"") -> 0
A15: 경남(김해) 합계 | B15: =$B$4 -> 8 | C15: =SUM($C$13:$C$14) -> 0 | D15: =IFERROR(ROUNDDOWN(C15/B15,0),"") -> 0 | F15: =IFERROR(C15-(D15*B15),"") -> 0
A17: 김천2(저온) | B17: =$B$4 -> 8 | C17: =IFERROR(VLOOKUP(A17,미스터밀크피벗!A:BL,7,FALSE),0) -> 0 | D17: =IFERROR(ROUNDDOWN(C17/B17,0),"") -> 0 | E17: 김천 | F17: =IFERROR(C17-(D17*B17),"") -> 0
A18: 경산2(저온) | B18: =$B$4 -> 8 | C18: =IFERROR(VLOOKUP(A18,미스터밀크피벗!A:BL,7,FALSE),0) -> 0 | D18: =IFERROR(ROUNDDOWN(C18/B18,0),"") -> 0 | E18: 경산 | F18: =IFERROR(C18-(D18*B18),"") -> 0
A19: 경북(칠곡) 합계 | B19: =$B$4 -> 8 | C19: =SUM($C$17:$C$18) -> 0 | D19: =IFERROR(ROUNDDOWN(C19/B19,0),"") -> 0 | F19: =IFERROR(C19-(D19*B19),"") -> 0
A21: 장성2(저온) | B21: =$B$4 -> 8 | C21: =IFERROR(VLOOKUP(A21,미스터밀크피벗!A:BL,7,FALSE),0) -> 8 | D21: =IFERROR(ROUNDDOWN(C21/B21,0),"") -> 1 | E21: 장성 | F21: =IFERROR(C21-(D21*B21),"") -> 0
A22: 호남 합계 | B22: =$B$4 -> 8 | C22: =SUM($C$21) -> 8 | D22: =IFERROR(ROUNDDOWN(C22/B22,0),"") -> 1 | F22: =IFERROR(C22-(D22*B22),"") -> 0
A24: 총합계 | B24: =B4 -> 8 | C24: =SUM(C11,C15,C19,C22) -> 8 | D24: =IFERROR(ROUNDDOWN(C24/B24,0),"") -> 1 | F24: =IFERROR(C24-(D24*B24),"") -> 0
A25: 총 박스 수량 / 총 낱개 수량 | D25: =SUM(D4:D10,D13:D14,D17:D18,D21) -> 1 | F25: =SUM(F11,F15,F19,F22) -> 0

Sheet 제주성이시돌목장)초코젤라또미니컵100ml
A2: =TODAY() -> 46309 | C2: 이마트24(냉동) - 미스터밀크
A3: =미스터밀크피벗!A2 -> 10/15 납품 | B3: 입수 | C3: 제주성이시돌목장) 초코젤라또미니컵100ml | D3: 박스 | E3: 센터명 | F3: 낱개
A4: 원주2(저온) | B4: 24 | C4: =IFERROR(VLOOKUP(A4,미스터밀크피벗!A:BL,8,FALSE),0) -> 0 | D4: =IFERROR(ROUNDDOWN(C4/B4,0),"") -> 0 | E4: 원주 | F4: =IFERROR(C4-(D4*B4),"") -> 0
A5: 세종2(저온) | B5: =$B$4 -> 24 | C5: =IFERROR(VLOOKUP(A5,미스터밀크피벗!A:BL,8,FALSE),0) -> 0 | D5: =IFERROR(ROUNDDOWN(C5/B5,0),"") -> 0 | E5: 세종 | F5: =IFERROR(C5-(D5*B5),"") -> 0
A6: 화성2(저온) | B6: =$B$4 -> 24 | C6: =IFERROR(VLOOKUP(A6,미스터밀크피벗!A:BL,8,FALSE),0) -> 24 | D6: =IFERROR(ROUNDDOWN(C6/B6,0),"") -> 1 | E6: 화성 | F6: =IFERROR(C6-(D6*B6),"") -> 0
A7: 청라2(저온) | B7: =$B$4 -> 24 | C7: =IFERROR(VLOOKUP(A7,미스터밀크피벗!A:BL,8,FALSE),0) -> 0 | D7: =IFERROR(ROUNDDOWN(C7/B7,0),"") -> 0 | E7: 청라 | F7: =IFERROR(C7-(D7*B7),"") -> 0
A8: 평택2(저온) | B8: =$B$4 -> 24 | C8: =IFERROR(VLOOKUP(A8,미스터밀크피벗!A:BL,8,FALSE),0) -> 0 | D8: =IFERROR(ROUNDDOWN(C8/B8,0),"") -> 0 | E8: 평택 | F8: =IFERROR(C8-(D8*B8),"") -> 0
A9: 포천2(저온) | B9: =$B$4 -> 24 | C9: =IFERROR(VLOOKUP(A9,미스터밀크피벗!A:BL,8,FALSE),0) -> 0 | D9: =IFERROR(ROUNDDOWN(C9/B9,0),"") -> 0 | E9: 포천 | F9: =IFERROR(C9-(D9*B9),"") -> 0
A10: 양지2(저온) | B10: =$B$4 -> 24 | C10: =IFERROR(VLOOKUP(A10,미스터밀크피벗!A:BL,8,FALSE),0) -> 0 | D10: =IFERROR(ROUNDDOWN(C10/B10,0),"") -> 0 | E10: 양지 | F10: =IFERROR(C10-(D10*B10),"") -> 0
A11: 수도권 합계 | B11: =$B$4 -> 24 | C11: =SUM($C$4:$C$10) -> 24 | D11: =IFERROR(ROUNDDOWN(C11/B11,0),"") -> 1 | F11: =IFERROR(C11-(D11*B11),"") -> 0
A13: 김해2(저온) | B13: =$B$4 -> 24 | C13: =IFERROR(VLOOKUP(A13,미스터밀크피벗!A:BL,8,FALSE),0) -> 0 | D13: =IFERROR(ROUNDDOWN(C13/B13,0),"") -> 0 | E13: 김해 | F13: =IFERROR(C13-(D13*B13),"") -> 0
A14: 양산2(저온) | B14: =$B$4 -> 24 | C14: =IFERROR(VLOOKUP(A14,미스터밀크피벗!A:BL,8,FALSE),0) -> 0 | D14: =IFERROR(ROUNDDOWN(C14/B14,0),"") -> 0 | E14: 양산 | F14: =IFERROR(C14-(D14*B14),"") -> 0
A15: 경남(김해) 합계 | B15: =$B$4 -> 24 | C15: =SUM($C$13:$C$14) -> 0 | D15: =IFERROR(ROUNDDOWN(C15/B15,0),"") -> 0 | F15: =IFERROR(C15-(D15*B15),"") -> 0
A17: 김천2(저온) | B17: =$B$4 -> 24 | C17: =IFERROR(VLOOKUP(A17,미스터밀크피벗!A:BL,8,FALSE),0) -> 24 | D17: =IFERROR(ROUNDDOWN(C17/B17,0),"") -> 1 | E17: 김천 | F17: =IFERROR(C17-(D17*B17),"") -> 0
A18: 경산2(저온) | B18: =$B$4 -> 24 | C18: =IFERROR(VLOOKUP(A18,미스터밀크피벗!A:BL,8,FALSE),0) -> 24 | D18: =IFERROR(ROUNDDOWN(C18/B18,0),"") -> 1 | E18: 경산 | F18: =IFERROR(C18-(D18*B18),"") -> 0
A19: 경북(칠곡) 합계 | B19: =$B$4 -> 24 | C19: =SUM($C$17:$C$18) -> 48 | D19: =IFERROR(ROUNDDOWN(C19/B19,0),"") -> 2 | F19: =IFERROR(C19-(D19*B19),"") -> 0
A21: 장성2(저온) | B21: =$B$4 -> 24 | C21: =IFERROR(VLOOKUP(A21,미스터밀크피벗!A:BL,8,FALSE),0) -> 0 | D21: =IFERROR(ROUNDDOWN(C21/B21,0),"") -> 0 | E21: 장성 | F21: =IFERROR(C21-(D21*B21),"") -> 0
A22: 호남 합계 | B22: =$B$4 -> 24 | C22: =SUM($C$21) -> 0 | D22: =IFERROR(ROUNDDOWN(C22/B22,0),"") -> 0 | F22: =IFERROR(C22-(D22*B22),"") -> 0
A24: 총합계 | B24: =B4 -> 24 | C24: =SUM(C11,C15,C19,C22) -> 72 | D24: =IFERROR(ROUNDDOWN(C24/B24,0),"") -> 3 | F24: =IFERROR(C24-(D24*B24),"") -> 0
A25: 총 박스 수량 / 총 낱개 수량 | D25: =SUM(D4:D10,D13:D14,D17:D18,D21) -> 3 | F25: =SUM(F11,F15,F19,F22) -> 0

Sheet 제주성이시돌목장)초코젤라또파인트473ml
A2: =TODAY() -> 46309 | C2: 이마트24(냉동) - 미스터밀크
A3: =미스터밀크피벗!A2 -> 10/15 납품 | B3: 입수 | C3: 제주성이시돌목장) 초코젤라또파인트473ml | D3: 박스 | E3: 센터명 | F3: 낱개
A4: 원주2(저온) | B4: 8 | C4: =IFERROR(VLOOKUP(A4,미스터밀크피벗!A:BL,9,FALSE),0) -> 0 | D4: =IFERROR(ROUNDDOWN(C4/B4,0),"") -> 0 | E4: 원주 | F4: =IFERROR(C4-(D4*B4),"") -> 0
A5: 세종2(저온) | B5: =$B$4 -> 8 | C5: =IFERROR(VLOOKUP(A5,미스터밀크피벗!A:BL,9,FALSE),0) -> 0 | D5: =IFERROR(ROUNDDOWN(C5/B5,0),"") -> 0 | E5: 세종 | F5: =IFERROR(C5-(D5*B5),"") -> 0
A6: 화성2(저온) | B6: =$B$4 -> 8 | C6: =IFERROR(VLOOKUP(A6,미스터밀크피벗!A:BL,9,FALSE),0) -> 0 | D6: =IFERROR(ROUNDDOWN(C6/B6,0),"") -> 0 | E6: 화성 | F6: =IFERROR(C6-(D6*B6),"") -> 0
A7: 청라2(저온) | B7: =$B$4 -> 8 | C7: =IFERROR(VLOOKUP(A7,미스터밀크피벗!A:BL,9,FALSE),0) -> 0 | D7: =IFERROR(ROUNDDOWN(C7/B7,0),"") -> 0 | E7: 청라 | F7: =IFERROR(C7-(D7*B7),"") -> 0
A8: 평택2(저온) | B8: =$B$4 -> 8 | C8: =IFERROR(VLOOKUP(A8,미스터밀크피벗!A:BL,9,FALSE),0) -> 0 | D8: =IFERROR(ROUNDDOWN(C8/B8,0),"") -> 0 | E8: 평택 | F8: =IFERROR(C8-(D8*B8),"") -> 0
A9: 포천2(저온) | B9: =$B$4 -> 8 | C9: =IFERROR(VLOOKUP(A9,미스터밀크피벗!A:BL,9,FALSE),0) -> 0 | D9: =IFERROR(ROUNDDOWN(C9/B9,0),"") -> 0 | E9: 포천 | F9: =IFERROR(C9-(D9*B9),"") -> 0
A10: 양지2(저온) | B10: =$B$4 -> 8 | C10: =IFERROR(VLOOKUP(A10,미스터밀크피벗!A:BL,9,FALSE),0) -> 0 | D10: =IFERROR(ROUNDDOWN(C10/B10,0),"") -> 0 | E10: 양지 | F10: =IFERROR(C10-(D10*B10),"") -> 0
A11: 수도권 합계 | B11: =$B$4 -> 8 | C11: =SUM($C$4:$C$10) -> 0 | D11: =IFERROR(ROUNDDOWN(C11/B11,0),"") -> 0 | F11: =IFERROR(C11-(D11*B11),"") -> 0
A13: 김해2(저온) | B13: =$B$4 -> 8 | C13: =IFERROR(VLOOKUP(A13,미스터밀크피벗!A:BL,9,FALSE),0) -> 0 | D13: =IFERROR(ROUNDDOWN(C13/B13,0),"") -> 0 | E13: 김해 | F13: =IFERROR(C13-(D13*B13),"") -> 0
A14: 양산2(저온) | B14: =$B$4 -> 8 | C14: =IFERROR(VLOOKUP(A14,미스터밀크피벗!A:BL,9,FALSE),0) -> 0 | D14: =IFERROR(ROUNDDOWN(C14/B14,0),"") -> 0 | E14: 양산 | F14: =IFERROR(C14-(D14*B14),"") -> 0
A15: 경남(김해) 합계 | B15: =$B$4 -> 8 | C15: =SUM($C$13:$C$14) -> 0 | D15: =IFERROR(ROUNDDOWN(C15/B15,0),"") -> 0 | F15: =IFERROR(C15-(D15*B15),"") -> 0
A17: 김천2(저온) | B17: =$B$4 -> 8 | C17: =IFERROR(VLOOKUP(A17,미스터밀크피벗!A:BL,9,FALSE),0) -> 0 | D17: =IFERROR(ROUNDDOWN(C17/B17,0),"") -> 0 | E17: 김천 | F17: =IFERROR(C17-(D17*B17),"") -> 0
A18: 경산2(저온) | B18: =$B$4 -> 8 | C18: =IFERROR(VLOOKUP(A18,미스터밀크피벗!A:BL,9,FALSE),0) -> 0 | D18: =IFERROR(ROUNDDOWN(C18/B18,0),"") -> 0 | E18: 경산 | F18: =IFERROR(C18-(D18*B18),"") -> 0
A19: 경북(칠곡) 합계 | B19: =$B$4 -> 8 | C19: =SUM($C$17:$C$18) -> 0 | D19: =IFERROR(ROUNDDOWN(C19/B19,0),"") -> 0 | F19: =IFERROR(C19-(D19*B19),"") -> 0
A21: 장성2(저온) | B21: =$B$4 -> 8 | C21: =IFERROR(VLOOKUP(A21,미스터밀크피벗!A:BL,9,FALSE),0) -> 0 | D21: =IFERROR(ROUNDDOWN(C21/B21,0),"") -> 0 | E21: 장성 | F21: =IFERROR(C21-(D21*B21),"") -> 0
A22: 호남 합계 | B22: =$B$4 -> 8 | C22: =SUM($C$21) -> 0 | D22: =IFERROR(ROUNDDOWN(C22/B22,0),"") -> 0 | F22: =IFERROR(C22-(D22*B22),"") -> 0
A24: 총합계 | B24: =B4 -> 8 | C24: =SUM(C11,C15,C19,C22) -> 0 | D24: =IFERROR(ROUNDDOWN(C24/B24,0),"") -> 0 | F24: =IFERROR(C24-(D24*B24),"") -> 0
A25: 총 박스 수량 / 총 낱개 수량 | D25: =SUM(D4:D10,D13:D14,D17:D18,D21) -> 0 | F25: =SUM(F11,F15,F19,F22) -> 0

Sheet 미담롤피벗
A1: 10/14 | B1: 열 레이블
A2: 10/15 납품 | B2: 자망요)자망요크림모찌60g(냉동) | C2: 총합계
A3: 경산2(저온) | B3: 48 | C3: 48
A4: 청라2(저온) | B4: 48 | C4: 48
A5: 포천2(저온) | B5: 48 | C5: 48
A6: 양지2(저온) | B6: 48 | C6: 48
A7: 총합계 | B7: 192 | C7: 192

Sheet 자망요)자망요크림모찌60g(냉동)
A2: =TODAY() -> 46309 | B2: 이마트24(냉동) - 미담롤
A3: =미담롤피벗!A2 -> 10/15 납품 | B3: 입수 | C3: 자망요)자망요크림 모찌60g(냉동) | D3: 박스 | E3: 센터명 | F3: 낱개
A4: 원주2(저온) | B4: 48 | C4: =IFERROR(VLOOKUP(A4,미담롤피벗!A:AR,2,FALSE),0) -> 0 | D4: =IFERROR(ROUNDDOWN(C4/B4,0),"") -> 0 | E4: 원주 | F4: =IFERROR(C4-(D4*B4),"") -> 0
A5: 세종2(저온) | B5: =$B$4 -> 48 | C5: =IFERROR(VLOOKUP(A5,미담롤피벗!A:AR,2,FALSE),0) -> 0 | D5: =IFERROR(ROUNDDOWN(C5/B5,0),"") -> 0 | E5: 세종 | F5: =IFERROR(C5-(D5*B5),"") -> 0
A6: 화성2(저온) | B6: =$B$4 -> 48 | C6: =IFERROR(VLOOKUP(A6,미담롤피벗!A:AR,2,FALSE),0) -> 0 | D6: =IFERROR(ROUNDDOWN(C6/B6,0),"") -> 0 | E6: 화성 | F6: =IFERROR(C6-(D6*B6),"") -> 0
A7: 청라2(저온) | B7: =$B$4 -> 48 | C7: =IFERROR(VLOOKUP(A7,미담롤피벗!A:AR,2,FALSE),0) -> 48 | D7: =IFERROR(ROUNDDOWN(C7/B7,0),"") -> 1 | E7: 청라 | F7: =IFERROR(C7-(D7*B7),"") -> 0
A8: 평택2(저온) | B8: =$B$4 -> 48 | C8: =IFERROR(VLOOKUP(A8,미담롤피벗!A:AR,2,FALSE),0) -> 0 | D8: =IFERROR(ROUNDDOWN(C8/B8,0),"") -> 0 | E8: 평택 | F8: =IFERROR(C8-(D8*B8),"") -> 0
A9: 포천2(저온) | B9: =$B$4 -> 48 | C9: =IFERROR(VLOOKUP(A9,미담롤피벗!A:AR,2,FALSE),0) -> 48 | D9: =IFERROR(ROUNDDOWN(C9/B9,0),"") -> 1 | E9: 포천 | F9: =IFERROR(C9-(D9*B9),"") -> 0
A10: 양지2(저온) | B10: =$B$4 -> 48 | C10: =IFERROR(VLOOKUP(A10,미담롤피벗!A:AR,2,FALSE),0) -> 48 | D10: =IFERROR(ROUNDDOWN(C10/B10,0),"") -> 1 | E10: 양지 | F10: =IFERROR(C10-(D10*B10),"") -> 0
A11: 수도권 합계 | B11: =$B$4 -> 48 | C11: =SUM($C$4:$C$10) -> 144 | D11: =IFERROR(ROUNDDOWN(C11/B11,0),"") -> 3 | F11: =IFERROR(C11-(D11*B11),"") -> 0
A13: 김해2(저온) | B13: =$B$4 -> 48 | C13: =IFERROR(VLOOKUP(A13,미담롤피벗!A:AR,2,FALSE),0) -> 0 | D13: =IFERROR(ROUNDDOWN(C13/B13,0),"") -> 0 | E13: 김해 | F13: =IFERROR(C13-(D13*B13),"") -> 0
A14: 양산2(저온) | B14: =$B$4 -> 48 | C14: =IFERROR(VLOOKUP(A14,미담롤피벗!A:AR,2,FALSE),0) -> 0 | D14: =IFERROR(ROUNDDOWN(C14/B14,0),"") -> 0 | E14: 양산 | F14: =IFERROR(C14-(D14*B14),"") -> 0
A15: 경남(김해) 합계 | B15: =$B$4 -> 48 | C15: =SUM($C$13:$C$14) -> 0 | D15: =IFERROR(ROUNDDOWN(C15/B15,0),"") -> 0 | F15: =IFERROR(C15-(D15*B15),"") -> 0
A17: 김천2(저온) | B17: =$B$4 -> 48 | C17: =IFERROR(VLOOKUP(A17,미담롤피벗!A:AR,2,FALSE),0) -> 0 | D17: =IFERROR(ROUNDDOWN(C17/B17,0),"") -> 0 | E17: 김천 | F17: =IFERROR(C17-(D17*B17),"") -> 0
A18: 경산2(저온) | B18: =$B$4 -> 48 | C18: =IFERROR(VLOOKUP(A18,미담롤피벗!A:AR,2,FALSE),0) -> 48 | D18: =IFERROR(ROUNDDOWN(C18/B18,0),"") -> 1 | E18: 경산 | F18: =IFERROR(C18-(D18*B18),"") -> 0
A19: 경북(칠곡) 합계 | B19: =$B$4 -> 48 | C19: =SUM($C$17:$C$18) -> 48 | D19: =IFERROR(ROUNDDOWN(C19/B19,0),"") -> 1 | F19: =IFERROR(C19-(D19*B19),"") -> 0
A21: 장성2(저온) | B21: =$B$4 -> 48 | C21: =IFERROR(VLOOKUP(A21,미담롤피벗!A:AR,2,FALSE),0) -> 0 | D21: =IFERROR(ROUNDDOWN(C21/B21,0),"") -> 0 | E21: 장성 | F21: =IFERROR(C21-(D21*B21),"") -> 0
A22: 호남 합계 | B22: =$B$4 -> 48 | C22: =SUM($C$21) -> 0 | D22: =IFERROR(ROUNDDOWN(C22/B22,0),"") -> 0 | F22: =IFERROR(C22-(D22*B22),"") -> 0
A24: 총합계 | B24: =B4 -> 48 | C24: =SUM(C11,C15,C19,C22) -> 192 | D24: =IFERROR(ROUNDDOWN(C24/B24,0),"") -> 4 | F24: =IFERROR(C24-(D24*B24),"") -> 0
A25: 총 박스 수량 / 총 낱개 수량 | D25: =SUM(D4:D10,D13:D14,D17:D18,D21) -> 4 | F25: =SUM(F4:F10,F13:F14,F17:F18,F21) -> 0

Sheet 윈즈 피벗 
A1: 10/13 | B1: 열 레이블
A2: 10/14 납품 | B2: 티아이)크림브륄레90g | C2: 총합계
A3: 양산2(저온)
A4: 양지2(저온)
A5: 총합계

Sheet 티아이)크림브륄레90g
A2: =TODAY() -> 46309 | C2: 이마트24(냉동) - 윈즈
A3: ='윈즈 피벗 '!A2 -> 10/14 납품 | B3: 입수 | C3: 티아이)크림브륄레90g | D3: 박스 | E3: 센터명 | F3: 낱개
A4: 원주2(저온) | B4: 16 | C4: =IFERROR(VLOOKUP(A4,'윈즈 피벗 '!A:AH,2,FALSE),0) -> 0 | D4: =IFERROR(ROUNDDOWN(C4/B4,0),"") -> 0 | E4: 원주 | F4: =IFERROR(C4-(D4*B4),"") -> 0
A5: 세종2(저온) | B5: =$B$4 -> 16 | C5: =IFERROR(VLOOKUP(A5,'윈즈 피벗 '!A:AH,2,FALSE),0) -> 0 | D5: =IFERROR(ROUNDDOWN(C5/B5,0),"") -> 0 | E5: 세종 | F5: =IFERROR(C5-(D5*B5),"") -> 0
A6: 화성2(저온) | B6: =$B$4 -> 16 | C6: =IFERROR(VLOOKUP(A6,'윈즈 피벗 '!A:AH,2,FALSE),0) -> 0 | D6: =IFERROR(ROUNDDOWN(C6/B6,0),"") -> 0 | E6: 화성 | F6: =IFERROR(C6-(D6*B6),"") -> 0
A7: 청라2(저온) | B7: =$B$4 -> 16 | C7: =IFERROR(VLOOKUP(A7,'윈즈 피벗 '!A:AH,2,FALSE),0) -> 0 | D7: =IFERROR(ROUNDDOWN(C7/B7,0),"") -> 0 | E7: 청라 | F7: =IFERROR(C7-(D7*B7),"") -> 0
A8: 평택2(저온) | B8: =$B$4 -> 16 | C8: =IFERROR(VLOOKUP(A8,'윈즈 피벗 '!A:AH,2,FALSE),0) -> 0 | D8: =IFERROR(ROUNDDOWN(C8/B8,0),"") -> 0 | E8: 평택 | F8: =IFERROR(C8-(D8*B8),"") -> 0
A9: 포천2(저온) | B9: =$B$4 -> 16 | C9: =IFERROR(VLOOKUP(A9,'윈즈 피벗 '!A:AH,2,FALSE),0) -> 0 | D9: =IFERROR(ROUNDDOWN(C9/B9,0),"") -> 0 | E9: 포천 | F9: =IFERROR(C9-(D9*B9),"") -> 0
A10: 양지2(저온) | B10: =$B$4 -> 16 | C10: =IFERROR(VLOOKUP(A10,'윈즈 피벗 '!A:AH,2,FALSE),0) -> 0 | D10: =IFERROR(ROUNDDOWN(C10/B10,0),"") -> 0 | E10: 양지 | F10: =IFERROR(C10-(D10*B10),"") -> 0
A11: 수도권 합계 | B11: =$B$4 -> 16 | C11: =SUM($C$4:$C$10) -> 0 | D11: =IFERROR(ROUNDDOWN(C11/B11,0),"") -> 0 | F11: =IFERROR(C11-(D11*B11),"") -> 0
A13: 김해2(저온) | B13: =$B$4 -> 16 | C13: =IFERROR(VLOOKUP(A13,'윈즈 피벗 '!A:AH,2,FALSE),0) -> 0 | D13: =IFERROR(ROUNDDOWN(C13/B13,0),"") -> 0 | E13: 김해 | F13: =IFERROR(C13-(D13*B13),"") -> 0
A14: 양산2(저온) | B14: =$B$4 -> 16 | C14: =IFERROR(VLOOKUP(A14,'윈즈 피벗 '!A:AH,2,FALSE),0) -> 0 | D14: =IFERROR(ROUNDDOWN(C14/B14,0),"") -> 0 | E14: 양산 | F14: =IFERROR(C14-(D14*B14),"") -> 0
A15: 경남(김해) 합계 | B15: =$B$4 -> 16 | C15: =SUM($C$13:$C$14) -> 0 | D15: =IFERROR(ROUNDDOWN(C15/B15,0),"") -> 0 | F15: =IFERROR(C15-(D15*B15),"") -> 0
A17: 김천2(저온) | B17: =$B$4 -> 16 | C17: =IFERROR(VLOOKUP(A17,'윈즈 피벗 '!A:AH,2,FALSE),0) -> 0 | D17: =IFERROR(ROUNDDOWN(C17/B17,0),"") -> 0 | E17: 김천 | F17: =IFERROR(C17-(D17*B17),"") -> 0
A18: 경산2(저온) | B18: =$B$4 -> 16 | C18: =IFERROR(VLOOKUP(A18,'윈즈 피벗 '!A:AH,2,FALSE),0) -> 0 | D18: =IFERROR(ROUNDDOWN(C18/B18,0),"") -> 0 | E18: 경산 | F18: =IFERROR(C18-(D18*B18),"") -> 0
A19: 경북(칠곡) 합계 | B19: =$B$4 -> 16 | C19: =SUM($C$17:$C$18) -> 0 | D19: =IFERROR(ROUNDDOWN(C19/B19,0),"") -> 0 | F19: =IFERROR(C19-(D19*B19),"") -> 0
A21: 장성2(저온) | B21: =$B$4 -> 16 | C21: =IFERROR(VLOOKUP(A21,'윈즈 피벗 '!A:AH,2,FALSE),0) -> 0 | D21: =IFERROR(ROUNDDOWN(C21/B21,0),"") -> 0 | E21: 장성 | F21: =IFERROR(C21-(D21*B21),"") -> 0
A22: 호남 합계 | B22: =$B$4 -> 16 | C22: =SUM($C$21) -> 0 | D22: =IFERROR(ROUNDDOWN(C22/B22,0),"") -> 0 | F22: =IFERROR(C22-(D22*B22),"") -> 0
A24: 총합계 | B24: =B4 -> 16 | C24: =SUM(C11,C15,C19,C22) -> 0 | D24: =IFERROR(ROUNDDOWN(C24/B24,0),"") -> 0 | F24: =IFERROR(C24-(D24*B24),"") -> 0
A25: 총 박스 수량 / 총 낱개 수량 | D25: =SUM(D4:D10,D13:D14,D17:D18,D21) -> 0 | F25: =SUM(F4:F10,F13:F14,F17:F18,F21) -> 0

Sheet 조선호텔피벗
A1: 10/13 | B1: 열 레이블
A2: 10/16 납품 | B2: 조선호텔)꿔바로우450g | E2: 조선호텔)크림새우380g | F2: 총합계
A3: 원주2(저온)
A4: 김해2(저온)
A5: 경산2(저온)
A6: 화성2(저온)
A7: 청라2(저온)
A8: 총합계

Sheet 조선호텔)꿔바로우450g
A2: =TODAY() -> 46309 | C2: 이마트24(냉동) - 조선호텔
A3: =조선호텔피벗!A2 -> 10/16 납품 | B3: 입수 | C3: 조선호텔)꿔바로우450g | D3: 박스 | E3: 센터명 | F3: 낱개
A4: 원주2(저온) | B4: 12 | C4: =IFERROR(VLOOKUP(A4,조선호텔피벗!A:AS,2,FALSE),0) -> 0 | D4: =IFERROR(ROUNDDOWN(C4/B4,0),"") -> 0 | E4: 원주 | F4: =IFERROR(C4-(D4*B4),"") -> 0
A5: 세종2(저온) | B5: =$B$4 -> 12 | C5: =IFERROR(VLOOKUP(A5,조선호텔피벗!A:AS,2,FALSE),0) -> 0 | D5: =IFERROR(ROUNDDOWN(C5/B5,0),"") -> 0 | E5: 세종 | F5: =IFERROR(C5-(D5*B5),"") -> 0
A6: 화성2(저온) | B6: =$B$4 -> 12 | C6: =IFERROR(VLOOKUP(A6,조선호텔피벗!A:AS,2,FALSE),0) -> 0 | D6: =IFERROR(ROUNDDOWN(C6/B6,0),"") -> 0 | E6: 화성 | F6: =IFERROR(C6-(D6*B6),"") -> 0
A7: 청라2(저온) | B7: =$B$4 -> 12 | C7: =IFERROR(VLOOKUP(A7,조선호텔피벗!A:AS,2,FALSE),0) -> 0 | D7: =IFERROR(ROUNDDOWN(C7/B7,0),"") -> 0 | E7: 청라 | F7: =IFERROR(C7-(D7*B7),"") -> 0
A8: 평택2(저온) | B8: =$B$4 -> 12 | C8: =IFERROR(VLOOKUP(A8,조선호텔피벗!A:AS,2,FALSE),0) -> 0 | D8: =IFERROR(ROUNDDOWN(C8/B8,0),"") -> 0 | E8: 평택 | F8: =IFERROR(C8-(D8*B8),"") -> 0
A9: 포천2(저온) | B9: =$B$4 -> 12 | C9: =IFERROR(VLOOKUP(A9,조선호텔피벗!A:AS,2,FALSE),0) -> 0 | D9: =IFERROR(ROUNDDOWN(C9/B9,0),"") -> 0 | E9: 포천 | F9: =IFERROR(C9-(D9*B9),"") -> 0
A10: 양지2(저온) | B10: =$B$4 -> 12 | C10: =IFERROR(VLOOKUP(A10,조선호텔피벗!A:AS,2,FALSE),0) -> 0 | D10: =IFERROR(ROUNDDOWN(C10/B10,0),"") -> 0 | E10: 양지 | F10: =IFERROR(C10-(D10*B10),"") -> 0
A11: 수도권 합계 | B11: =$B$4 -> 12 | C11: =SUM($C$4:$C$10) -> 0 | D11: =IFERROR(ROUNDDOWN(C11/B11,0),"") -> 0 | F11: =IFERROR(C11-(D11*B11),"") -> 0
A13: 김해2(저온) | B13: =$B$4 -> 12 | C13: =IFERROR(VLOOKUP(A13,조선호텔피벗!A:AS,2,FALSE),0) -> 0 | D13: =IFERROR(ROUNDDOWN(C13/B13,0),"") -> 0 | E13: 김해 | F13: =IFERROR(C13-(D13*B13),"") -> 0
A14: 양산2(저온) | B14: =$B$4 -> 12 | C14: =IFERROR(VLOOKUP(A14,조선호텔피벗!A:AS,2,FALSE),0) -> 0 | D14: =IFERROR(ROUNDDOWN(C14/B14,0),"") -> 0 | E14: 양산 | F14: =IFERROR(C14-(D14*B14),"") -> 0
A15: 경남(김해) 합계 | B15: =$B$4 -> 12 | C15: =SUM($C$13:$C$14) -> 0 | D15: =IFERROR(ROUNDDOWN(C15/B15,0),"") -> 0 | F15: =IFERROR(C15-(D15*B15),"") -> 0
A17: 김천2(저온) | B17: =$B$4 -> 12 | C17: =IFERROR(VLOOKUP(A17,조선호텔피벗!A:AS,2,FALSE),0) -> 0 | D17: =IFERROR(ROUNDDOWN(C17/B17,0),"") -> 0 | E17: 김천 | F17: =IFERROR(C17-(D17*B17),"") -> 0
A18: 경산2(저온) | B18: =$B$4 -> 12 | C18: =IFERROR(VLOOKUP(A18,조선호텔피벗!A:AS,2,FALSE),0) -> 0 | D18: =IFERROR(ROUNDDOWN(C18/B18,0),"") -> 0 | E18: 경산 | F18: =IFERROR(C18-(D18*B18),"") -> 0
A19: 경북(칠곡) 합계 | B19: =$B$4 -> 12 | C19: =SUM($C$17:$C$18) -> 0 | D19: =IFERROR(ROUNDDOWN(C19/B19,0),"") -> 0 | F19: =IFERROR(C19-(D19*B19),"") -> 0
A21: 장성2(저온) | B21: =$B$4 -> 12 | C21: =IFERROR(VLOOKUP(A21,조선호텔피벗!A:AS,2,FALSE),0) -> 0 | D21: =IFERROR(ROUNDDOWN(C21/B21,0),"") -> 0 | E21: 장성 | F21: =IFERROR(C21-(D21*B21),"") -> 0
A22: 호남 합계 | B22: =$B$4 -> 12 | C22: =SUM($C$21) -> 0 | D22: =IFERROR(ROUNDDOWN(C22/B22,0),"") -> 0 | F22: =IFERROR(C22-(D22*B22),"") -> 0
A24: 총합계 | B24: =B4 -> 12 | C24: =SUM(C11,C15,C19,C22) -> 0 | D24: =IFERROR(ROUNDDOWN(C24/B24,0),"") -> 0 | F24: =IFERROR(C24-(D24*B24),"") -> 0
A25: 총 박스 수량 / 총 낱개 수량 | D25: =SUM(D4:D10,D13:D14,D17:D18,D21) -> 0 | F25: =SUM(F4:F10,F13:F14,F17:F18,F21:F22) -> 0

Sheet 조선호텔)떡갈비345g
A2: =TODAY() -> 46309 | C2: 이마트24(냉동) - 조선호텔
A3: =조선호텔피벗!A2 -> 10/16 납품 | B3: 입수 | C3: 조선호텔)떡갈비345g | D3: 박스 | E3: 센터명 | F3: 낱개
A4: 원주2(저온) | B4: 24 | C4: =IFERROR(VLOOKUP(A4,조선호텔피벗!A:AS,3,FALSE),0) -> 0 | D4: =IFERROR(ROUNDDOWN(C4/B4,0),"") -> 0 | E4: 원주 | F4: =IFERROR(C4-(D4*B4),"") -> 0
A5: 세종2(저온) | B5: =$B$4 -> 24 | C5: =IFERROR(VLOOKUP(A5,조선호텔피벗!A:AS,3,FALSE),0) -> 0 | D5: =IFERROR(ROUNDDOWN(C5/B5,0),"") -> 0 | E5: 세종 | F5: =IFERROR(C5-(D5*B5),"") -> 0
A6: 화성2(저온) | B6: =$B$4 -> 24 | C6: =IFERROR(VLOOKUP(A6,조선호텔피벗!A:AS,3,FALSE),0) -> 0 | D6: =IFERROR(ROUNDDOWN(C6/B6,0),"") -> 0 | E6: 화성 | F6: =IFERROR(C6-(D6*B6),"") -> 0
A7: 청라2(저온) | B7: =$B$4 -> 24 | C7: =IFERROR(VLOOKUP(A7,조선호텔피벗!A:AS,3,FALSE),0) -> 0 | D7: =IFERROR(ROUNDDOWN(C7/B7,0),"") -> 0 | E7: 청라 | F7: =IFERROR(C7-(D7*B7),"") -> 0
A8: 평택2(저온) | B8: =$B$4 -> 24 | C8: =IFERROR(VLOOKUP(A8,조선호텔피벗!A:AS,3,FALSE),0) -> 0 | D8: =IFERROR(ROUNDDOWN(C8/B8,0),"") -> 0 | E8: 평택 | F8: =IFERROR(C8-(D8*B8),"") -> 0
A9: 포천2(저온) | B9: =$B$4 -> 24 | C9: =IFERROR(VLOOKUP(A9,조선호텔피벗!A:AS,3,FALSE),0) -> 0 | D9: =IFERROR(ROUNDDOWN(C9/B9,0),"") -> 0 | E9: 포천 | F9: =IFERROR(C9-(D9*B9),"") -> 0
A10: 양지2(저온) | B10: =$B$4 -> 24 | C10: =IFERROR(VLOOKUP(A10,조선호텔피벗!A:AS,3,FALSE),0) -> 0 | D10: =IFERROR(ROUNDDOWN(C10/B10,0),"") -> 0 | E10: 양지 | F10: =IFERROR(C10-(D10*B10),"") -> 0
A11: 수도권 합계 | B11: =$B$4 -> 24 | C11: =SUM($C$4:$C$10) -> 0 | D11: =IFERROR(ROUNDDOWN(C11/B11,0),"") -> 0 | F11: =IFERROR(C11-(D11*B11),"") -> 0
A13: 김해2(저온) | B13: =$B$4 -> 24 | C13: =IFERROR(VLOOKUP(A13,조선호텔피벗!A:AS,3,FALSE),0) -> 0 | D13: =IFERROR(ROUNDDOWN(C13/B13,0),"") -> 0 | E13: 김해 | F13: =IFERROR(C13-(D13*B13),"") -> 0
A14: 양산2(저온) | B14: =$B$4 -> 24 | C14: =IFERROR(VLOOKUP(A14,조선호텔피벗!A:AS,3,FALSE),0) -> 0 | D14: =IFERROR(ROUNDDOWN(C14/B14,0),"") -> 0 | E14: 양산 | F14: =IFERROR(C14-(D14*B14),"") -> 0
A15: 경남(김해) 합계 | B15: =$B$4 -> 24 | C15: =SUM($C$13:$C$14) -> 0 | D15: =IFERROR(ROUNDDOWN(C15/B15,0),"") -> 0 | F15: =IFERROR(C15-(D15*B15),"") -> 0
A17: 김천2(저온) | B17: =$B$4 -> 24 | C17: =IFERROR(VLOOKUP(A17,조선호텔피벗!A:AS,3,FALSE),0) -> 0 | D17: =IFERROR(ROUNDDOWN(C17/B17,0),"") -> 0 | E17: 김천 | F17: =IFERROR(C17-(D17*B17),"") -> 0
A18: 경산2(저온) | B18: =$B$4 -> 24 | C18: =IFERROR(VLOOKUP(A18,조선호텔피벗!A:AS,3,FALSE),0) -> 0 | D18: =IFERROR(ROUNDDOWN(C18/B18,0),"") -> 0 | E18: 경산 | F18: =IFERROR(C18-(D18*B18),"") -> 0
A19: 경북(칠곡) 합계 | B19: =$B$4 -> 24 | C19: =SUM($C$17:$C$18) -> 0 | D19: =IFERROR(ROUNDDOWN(C19/B19,0),"") -> 0 | F19: =IFERROR(C19-(D19*B19),"") -> 0
A21: 장성2(저온) | B21: =$B$4 -> 24 | C21: =IFERROR(VLOOKUP(A21,조선호텔피벗!A:AS,3,FALSE),0) -> 0 | D21: =IFERROR(ROUNDDOWN(C21/B21,0),"") -> 0 | E21: 장성 | F21: =IFERROR(C21-(D21*B21),"") -> 0
A22: 호남 합계 | B22: =$B$4 -> 24 | C22: =SUM($C$21) -> 0 | D22: =IFERROR(ROUNDDOWN(C22/B22,0),"") -> 0 | F22: =IFERROR(C22-(D22*B22),"") -> 0
A24: 총합계 | B24: =B4 -> 24 | C24: =SUM(C11,C15,C19,C22) -> 0 | D24: =IFERROR(ROUNDDOWN(C24/B24,0),"") -> 0 | F24: =IFERROR(C24-(D24*B24),"") -> 0
A25: 총 박스 수량 / 총 낱개 수량 | D25: =SUM(D4:D10,D13:D14,D17:D18,D21) -> 0 | F25: =SUM(F4:F10,F13:F14,F17:F18,F21:F22) -> 0

Sheet 조선호텔)마카다미아치즈아이스크림케이크
A2: =TODAY() -> 46309 | C2: 이마트24(냉동) - 조선호텔
A3: =조선호텔피벗!A2 -> 10/16 납품 | B3: 입수 | C3: 조선호텔)마카다미아치즈아이스크림케이크 | D3: 박스 | E3: 센터명 | F3: 낱개
A4: 원주2(저온) | B4: 8 | C4: =IFERROR(VLOOKUP(A4,조선호텔피벗!A:AS,4,FALSE),0) -> 0 | D4: =IFERROR(ROUNDDOWN(C4/B4,0),"") -> 0 | E4: 원주 | F4: =IFERROR(C4-(D4*B4),"") -> 0
A5: 세종2(저온) | B5: =$B$4 -> 8 | C5: =IFERROR(VLOOKUP(A5,조선호텔피벗!A:AS,4,FALSE),0) -> 0 | D5: =IFERROR(ROUNDDOWN(C5/B5,0),"") -> 0 | E5: 세종 | F5: =IFERROR(C5-(D5*B5),"") -> 0
A6: 화성2(저온) | B6: =$B$4 -> 8 | C6: =IFERROR(VLOOKUP(A6,조선호텔피벗!A:AS,4,FALSE),0) -> 0 | D6: =IFERROR(ROUNDDOWN(C6/B6,0),"") -> 0 | E6: 화성 | F6: =IFERROR(C6-(D6*B6),"") -> 0
A7: 청라2(저온) | B7: =$B$4 -> 8 | C7: =IFERROR(VLOOKUP(A7,조선호텔피벗!A:AS,4,FALSE),0) -> 0 | D7: =IFERROR(ROUNDDOWN(C7/B7,0),"") -> 0 | E7: 청라 | F7: =IFERROR(C7-(D7*B7),"") -> 0
A8: 평택2(저온) | B8: =$B$4 -> 8 | C8: =IFERROR(VLOOKUP(A8,조선호텔피벗!A:AS,4,FALSE),0) -> 0 | D8: =IFERROR(ROUNDDOWN(C8/B8,0),"") -> 0 | E8: 평택 | F8: =IFERROR(C8-(D8*B8),"") -> 0
A9: 포천2(저온) | B9: =$B$4 -> 8 | C9: =IFERROR(VLOOKUP(A9,조선호텔피벗!A:AS,4,FALSE),0) -> 0 | D9: =IFERROR(ROUNDDOWN(C9/B9,0),"") -> 0 | E9: 포천 | F9: =IFERROR(C9-(D9*B9),"") -> 0
A10: 양지2(저온) | B10: =$B$4 -> 8 | C10: =IFERROR(VLOOKUP(A10,조선호텔피벗!A:AS,4,FALSE),0) -> 0 | D10: =IFERROR(ROUNDDOWN(C10/B10,0),"") -> 0 | E10: 양지 | F10: =IFERROR(C10-(D10*B10),"") -> 0
A11: 수도권 합계 | B11: =$B$4 -> 8 | C11: =SUM($C$4:$C$10) -> 0 | D11: =IFERROR(ROUNDDOWN(C11/B11,0),"") -> 0 | F11: =IFERROR(C11-(D11*B11),"") -> 0
A13: 김해2(저온) | B13: =$B$4 -> 8 | C13: =IFERROR(VLOOKUP(A13,조선호텔피벗!A:AS,4,FALSE),0) -> 0 | D13: =IFERROR(ROUNDDOWN(C13/B13,0),"") -> 0 | E13: 김해 | F13: =IFERROR(C13-(D13*B13),"") -> 0
A14: 양산2(저온) | B14: =$B$4 -> 8 | C14: =IFERROR(VLOOKUP(A14,조선호텔피벗!A:AS,4,FALSE),0) -> 0 | D14: =IFERROR(ROUNDDOWN(C14/B14,0),"") -> 0 | E14: 양산 | F14: =IFERROR(C14-(D14*B14),"") -> 0
A15: 경남(김해) 합계 | B15: =$B$4 -> 8 | C15: =SUM($C$13:$C$14) -> 0 | D15: =IFERROR(ROUNDDOWN(C15/B15,0),"") -> 0 | F15: =IFERROR(C15-(D15*B15),"") -> 0
A17: 김천2(저온) | B17: =$B$4 -> 8 | C17: =IFERROR(VLOOKUP(A17,조선호텔피벗!A:AS,4,FALSE),0) -> 0 | D17: =IFERROR(ROUNDDOWN(C17/B17,0),"") -> 0 | E17: 김천 | F17: =IFERROR(C17-(D17*B17),"") -> 0
