Workbook

Sheet 대광피벗(재고)
A1: 10/12 | B1: 열 레이블
A2: 행 레이블 | C2: 두바이)리얼두쫀쿠50g | D2: 두바이)리얼아쫀쿠50g | E2: 두바이)초코카다이프모찌60g | F2: 두바이)카다이프판초콜릿60g(냉장) | G2: 두바이)흑임자두쫀쿠50g(냉장) | H2: 총합계
A3: 원주2(저온) | C3: 18 | H3: 18
A4: 김해2(저온) | C4: 19 | D4: 3 | F4: 1 | H4: 23
A5: 양산2(저온) | C5: 57 | D5: 1 | E5: 3 | H5: 61
A6: 세종2(저온) | C6: 50 | D6: 2 | E6: 1 | F6: 3 | H6: 56
A7: 장성2(저온) | C7: 68 | D7: 6 | E7: 4 | F7: 2 | G7: 2 | H7: 82
A8: 김천2(저온) | C8: 26 | D8: 2 | E8: 2 | H8: 30
A9: 경산2(저온) | C9: 32 | D9: 3 | E9: 2 | H9: 37
A10: 화성2(저온) | C10: 49 | D10: 5 | E10: 2 | H10: 56
A11: 청라2(저온) | C11: 52 | D11: 7 | E11: 10 | F11: 2 | H11: 71
A12: 평택2(저온) | C12: 20 | D12: 5 | E12: 1 | G12: 3 | H12: 29
A13: 포천2(저온) | C13: 119 | D13: 13 | E13: 25 | F13: 10 | G13: 2 | H13: 169
A14: 양지2(저온) | C14: 57 | D14: 5 | E14: 2 | F14: 1 | H14: 65
A15: 총합계 | C15: 567 | D15: 52 | E15: 52 | F15: 19 | G15: 7 | H15: 697

Sheet 원주(날짜변경!!)
B1: 원주2(저온)
B2: 거 래 명 세 표 (공급받는자 보관용)
B4: 공 급 받 는 자 | C4: 등록번호 | Q4: 공 급 자 | R4: 등록번호 | V4: 206-86-55878
C6: 상 호 (법인명) | G6: (이마트24) | L6: 원주센터(저온) | R6: 상 호 (법인명) | V6: ㈜ 대광푸드 | AB6: 성명 | AD6: 한대훈
C8: 사업장 주 소 | G8: 강원특별자치도 원주시 호저면 주산리 298,1층 | R8: 사업장 주 소 | V8: 서울특별시 광진구 천호대로130길 22(구의동,필하임상가1호 에이호)
C10: 합계금액 (VAT포함) | R10: 업 태 | V10: 도소매 | AB10: 종목 | AD10: 빵,떡,과자류 외
B12: 년 | C12: 월 | D12: 일 | E12: 품 목 | M12: 입수 | Q12: 총수량 | T12: 박스 | W12: 낱개수량 | AA12: 비고
B13: 46307 | E13: 대광)생초코파이60g(냉장) | M13: 18 | Q13: =IFERROR(VLOOKUP($B$1,'대광피벗(재고)'!A:CF,2,FALSE),0) -> 0 | T13: =IFERROR(ROUNDDOWN(Q13/M13,0),"") -> 0 | W13: =IFERROR(Q13-(T13*M13),"") -> 0 | AA13: 26.09.28
E14: 두바이)리얼두쫀쿠50g | M14: 60 | Q14: =IFERROR(VLOOKUP($B$1,'대광피벗(재고)'!$A$1:$AC$119,3,FALSE),0) -> 18 | T14: =IFERROR(ROUNDDOWN(Q14/M14,0),"") -> 0 | W14: =IFERROR(Q14-(T14*M14),"") -> 18 | AA14: 26.11.07
E15: 두바이)리얼아쫀쿠50g | M15: 60 | Q15: =IFERROR(VLOOKUP($B$1,'대광피벗(재고)'!A:CF,4,FALSE),0) -> 0 | T15: =IFERROR(ROUNDDOWN(Q15/M15,0),"") -> 0 | W15: =IFERROR(Q15-(T15*M15),"") -> 0 | AA15: 26.10.28
E16: 두바이)초코카다이프모찌60g | M16: 48 | Q16: =IFERROR(VLOOKUP($B$1,'대광피벗(재고)'!A:CF,5,FALSE),0) -> 0 | T16: =IFERROR(ROUNDDOWN(Q16/M16,0),"") -> 0 | W16: =IFERROR(Q16-(T16*M16),"") -> 0 | AA16: 26.10.28
E17: 두바이)카다이프판초콜릿60g(냉장) | M17: 50 | Q17: =IFERROR(VLOOKUP($B$1,'대광피벗(재고)'!A:CF,6,FALSE),0) -> 0 | T17: =IFERROR(ROUNDDOWN(Q17/M17,0),"") -> 0 | W17: =IFERROR(Q17-(T17*M17),"") -> 0 | AA17: 26.11.03 / 11.10
E18: 두바이)흑임자두쫀쿠50g(냉장) | M18: 60 | Q18: =IFERROR(VLOOKUP($B$1,'대광피벗(재고)'!A:CF,7,FALSE),0) -> 0 | T18: =IFERROR(ROUNDDOWN(Q18/M18,0),"") -> 0 | W18: =IFERROR(Q18-(T18*M18),"") -> 0 | AA18: 26.11.07
B22: 총수량 | M22: =SUM(Q13:S21) -> 18
B23: 3자물류 (더원물류) 담당자 박병선이사 010-4448-1456 | W23: =G8 -> 강원특별자치도 원주시 호저면 주산리 298,1층
B27: 거 래 명 세 표 (공급자 보관용)
B29: 공 급 받 는 자 | C29: =C4 -> 등록번호 | Q29: 공 급 자 | R29: 등록번호 | V29: =V4 -> 206-86-55878
C31: =C6 -> 상 호 (법인명) | G31: =G6 -> (이마트24) | L31: =L6 -> 원주센터(저온) | R31: 상 호 (법인명) | V31: =V6 -> ㈜ 대광푸드 | AB31: 성 명 | AD31: =AD6 -> 한대훈
C33: 사업장 주 소 | G33: =G8 -> 강원특별자치도 원주시 호저면 주산리 298,1층 | R33: 사업장 주 소 | V33: =V8 -> 서울특별시 광진구 천호대로130길 22(구의동,필하임상가1호 에이호)
C35: 합계금액 (VAT포함) | R35: 업 태 | V35: =V10 -> 도소매 | AB35: 종 목 | AD35: =AD10 -> 빵,떡,과자류 외
B37: 년 | C37: 월 | D37: 일 | E37: 품 목 | M37: 입수 | Q37: 총수량 | T37: 박스 | W37: 낱개수량 | AA37: 비고
B38: =B13 -> 46307 | E38: =E13 -> 대광)생초코파이60g(냉장) | M38: =M13 -> 18 | Q38: =Q13 -> 0 | T38: =T13 -> 0 | W38: =W13 -> 0 | AA38: =IF(OR(Q13=0,AA13=""),"",AA13)
E39: =E14 -> 두바이)리얼두쫀쿠50g | M39: =M14 -> 60 | Q39: =Q14 -> 18 | T39: =T14 -> 0 | W39: =W14 -> 18 | AA39: =IF(OR(Q14=0,AA14=""),"",AA14) -> 26.11.07
E40: =E15 -> 두바이)리얼아쫀쿠50g | M40: =M15 -> 60 | Q40: =Q15 -> 0 | T40: =T15 -> 0 | W40: =W15 -> 0 | AA40: =IF(OR(Q15=0,AA15=""),"",AA15)
E41: =E16 -> 두바이)초코카다이프모찌60g | M41: =M16 -> 48 | Q41: =Q16 -> 0 | T41: =T16 -> 0 | W41: =W16 -> 0 | AA41: =IF(OR(Q16=0,AA16=""),"",AA16)
E42: =E17 -> 두바이)카다이프판초콜릿60g(냉장) | M42: =M17 -> 50 | Q42: =Q17 -> 0 | T42: =T17 -> 0 | W42: =W17 -> 0 | AA42: =IF(OR(Q17=0,AA17=""),"",AA17)
E43: =E18 -> 두바이)흑임자두쫀쿠50g(냉장) | M43: =M18 -> 60 | Q43: =Q18 -> 0 | T43: =T18 -> 0 | W43: =W18 -> 0 | AA43: =IF(OR(Q18=0,AA18=""),"",AA18)
AA44: =IF(OR(Q18=0,AA18=""),"",AA18)
AA45: ]
B47: =B22 -> 총수량 | M47: =M22 -> 18
B48: =B23 -> 3자물류 (더원물류) 담당자 박병선이사 010-4448-1456 | W48: =W23 -> 강원특별자치도 원주시 호저면 주산리 298,1층

Sheet 김해 (18)
B1: 김해2(저온)
B2: 거 래 명 세 표 (공급받는자 보관용)
B4: 공 급 받 는 자 | C4: 등록번호 | Q4: 공 급 자 | R4: 등록번호 | V4: 206-86-55878
C6: 상 호 (법인명) | G6: (이마트24) | L6: 김해센터(저온) | R6: 상 호 (법인명) | V6: ㈜ 대광푸드 | AB6: 성명 | AD6: 한대훈
C8: 사업장 주 소 | G8: 경상남도 김해시 진례면 테크노밸리로 193-28 | R8: 사업장 주 소 | V8: 서울특별시 광진구 천호대로130길 22(구의동,필하임상가1호 에이호)
C10: 합계금액 (VAT포함) | R10: 업 태 | V10: 도소매 | AB10: 종목 | AD10: 빵,떡,과자류 외
B12: 년 | C12: 월 | D12: 일 | E12: 품 목 | M12: 입수 | Q12: 총수량 | T12: 박스 | W12: 낱개수량 | AA12: 비고
B13: ='원주(날짜변경!!)'!$B$13 -> 46307 | E13: 대광)생초코파이60g(냉장) | M13: 18 | Q13: =IFERROR(VLOOKUP($B$1,'대광피벗(재고)'!A:CF,2,FALSE),0) -> 0 | T13: =IFERROR(ROUNDDOWN(Q13/M13,0),"") -> 0 | W13: =IFERROR(Q13-(T13*M13),"") -> 0 | AA13: 26.09.28
E14: 두바이)리얼두쫀쿠50g | M14: 60 | Q14: =IFERROR(VLOOKUP($B$1,'대광피벗(재고)'!$A$1:$AC$119,3,FALSE),0) -> 19 | T14: =IFERROR(ROUNDDOWN(Q14/M14,0),"") -> 0 | W14: =IFERROR(Q14-(T14*M14),"") -> 19 | AA14: 26.11.07
E15: 두바이)리얼아쫀쿠50g | M15: 60 | Q15: =IFERROR(VLOOKUP($B$1,'대광피벗(재고)'!A:CF,4,FALSE),0) -> 3 | T15: =IFERROR(ROUNDDOWN(Q15/M15,0),"") -> 0 | W15: =IFERROR(Q15-(T15*M15),"") -> 3 | AA15: 26.10.28
E16: 두바이)초코카다이프모찌60g | M16: 48 | Q16: =IFERROR(VLOOKUP($B$1,'대광피벗(재고)'!A:CF,5,FALSE),0) -> 0 | T16: =IFERROR(ROUNDDOWN(Q16/M16,0),"") -> 0 | W16: =IFERROR(Q16-(T16*M16),"") -> 0 | AA16: 26.10.28
E17: 두바이)카다이프판초콜릿60g(냉장) | M17: 50 | Q17: =IFERROR(VLOOKUP($B$1,'대광피벗(재고)'!A:CF,6,FALSE),0) -> 1 | T17: =IFERROR(ROUNDDOWN(Q17/M17,0),"") -> 0 | W17: =IFERROR(Q17-(T17*M17),"") -> 1 | AA17: 26.11.03 / 11.10
E18: 두바이)흑임자두쫀쿠50g(냉장) | M18: 60 | Q18: =IFERROR(VLOOKUP($B$1,'대광피벗(재고)'!A:CF,7,FALSE),0) -> 0 | T18: =IFERROR(ROUNDDOWN(Q18/M18,0),"") -> 0 | W18: =IFERROR(Q18-(T18*M18),"") -> 0 | AA18: 26.11.07
B22: 총수량 | M22: =SUM(Q13:S21) -> 23
B23: 3자물류 (더원물류) 담당자 박병선이사 010-4448-1456 | W23: 경상남도 김해시 진례면 테크노밸리로 193-28 TEL 070-4398-2825
B27: 거 래 명 세 표 (공급자 보관용)
B29: 공 급 받 는 자 | C29: =C4 -> 등록번호 | Q29: 공 급 자 | R29: 등록번호 | V29: =V4 -> 206-86-55878
C31: =C6 -> 상 호 (법인명) | G31: =G6 -> (이마트24) | L31: =L6 -> 김해센터(저온) | R31: 상 호 (법인명) | V31: =V6 -> ㈜ 대광푸드 | AB31: 성 명 | AD31: =AD6 -> 한대훈
C33: 사업장 주 소 | G33: =G8 -> 경상남도 김해시 진례면 테크노밸리로 193-28 | R33: 사업장 주 소 | V33: =V8 -> 서울특별시 광진구 천호대로130길 22(구의동,필하임상가1호 에이호)
C35: 합계금액 (VAT포함) | R35: 업 태 | V35: =V10 -> 도소매 | AB35: 종 목 | AD35: =AD10 -> 빵,떡,과자류 외
B37: 년 | C37: 월 | D37: 일 | E37: 품 목 | M37: 입수 | Q37: 총수량 | T37: 박스 | W37: 낱개수량 | AA37: 비고
B38: =B13 -> 46307 | E38: =E13 -> 대광)생초코파이60g(냉장) | M38: =M13 -> 18 | Q38: =Q13 -> 0 | T38: =T13 -> 0 | W38: =W13 -> 0 | AA38: =IF(OR(Q13=0,AA13=""),"",AA13)
E39: =E14 -> 두바이)리얼두쫀쿠50g | M39: =M14 -> 60 | Q39: =Q14 -> 19 | T39: =T14 -> 0 | W39: =W14 -> 19 | AA39: =IF(OR(Q14=0,AA14=""),"",AA14) -> 26.11.07
E40: =E15 -> 두바이)리얼아쫀쿠50g | M40: =M15 -> 60 | Q40: =Q15 -> 3 | T40: =T15 -> 0 | W40: =W15 -> 3 | AA40: =IF(OR(Q15=0,AA15=""),"",AA15) -> 26.10.28
E41: =E16 -> 두바이)초코카다이프모찌60g | M41: =M16 -> 48 | Q41: =Q16 -> 0 | T41: =T16 -> 0 | W41: =W16 -> 0 | AA41: =IF(OR(Q16=0,AA16=""),"",AA16)
E42: =E17 -> 두바이)카다이프판초콜릿60g(냉장) | M42: =M17 -> 50 | Q42: =Q17 -> 1 | T42: =T17 -> 0 | W42: =W17 -> 1 | AA42: =IF(OR(Q17=0,AA17=""),"",AA17) -> 26.11.03 / 11.10
E43: =E18 -> 두바이)흑임자두쫀쿠50g(냉장) | M43: =M18 -> 60 | Q43: =Q18 -> 0 | T43: =T18 -> 0 | W43: =W18 -> 0 | AA43: =IF(OR(Q18=0,AA18=""),"",AA18)
AA44: =IF(OR(Q18=0,AA18=""),"",AA18)
AA45: =IF(AA20="","",AA20)
B47: =B22 -> 총수량 | M47: =M22 -> 23
B48: =B23 -> 3자물류 (더원물류) 담당자 박병선이사 010-4448-1456 | W48: =W23 -> 경상남도 김해시 진례면 테크노밸리로 193-28 TEL 070-4398-2825

Sheet 양산 (18)
B1: 양산2(저온)
B2: 거 래 명 세 표 (공급받는자 보관용)
B4: 공 급 받 는 자 | C4: 등록번호 | Q4: 공 급 자 | R4: 등록번호 | V4: 206-86-55878
C6: 상 호 (법인명) | G6: (이마트24) | L6: 양산센터(저온) | R6: 상 호 (법인명) | V6: ㈜ 대광푸드 | AB6: 성명 | AD6: 한대훈
C8: 사업장 주 소 | G8: 경상남도 양산시 산막공단북3길 25(산막동 313-4) | R8: 사업장 주 소 | V8: 서울특별시 광진구 천호대로130길 22(구의동,필하임상가1호 에이호)
C10: 합계금액 (VAT포함) | R10: 업 태 | V10: 도소매 | AB10: 종목 | AD10: 빵,떡,과자류 외
B12: 년 | C12: 월 | D12: 일 | E12: 품 목 | M12: 입수 | Q12: 총수량 | T12: 박스 | W12: 낱개수량 | AA12: 비고
B13: ='원주(날짜변경!!)'!$B$13 -> 46307 | E13: 대광)생초코파이60g(냉장) | M13: 18 | Q13: =IFERROR(VLOOKUP($B$1,'대광피벗(재고)'!A:CF,2,FALSE),0) -> 0 | T13: =IFERROR(ROUNDDOWN(Q13/M13,0),"") -> 0 | W13: =IFERROR(Q13-(T13*M13),"") -> 0 | AA13: 26.09.28
E14: 두바이)리얼두쫀쿠50g | M14: 60 | Q14: =IFERROR(VLOOKUP($B$1,'대광피벗(재고)'!$A$1:$AC$119,3,FALSE),0) -> 57 | T14: =IFERROR(ROUNDDOWN(Q14/M14,0),"") -> 0 | W14: =IFERROR(Q14-(T14*M14),"") -> 57 | AA14: 26.11.07
E15: 두바이)리얼아쫀쿠50g | M15: 60 | Q15: =IFERROR(VLOOKUP($B$1,'대광피벗(재고)'!A:CF,4,FALSE),0) -> 1 | T15: =IFERROR(ROUNDDOWN(Q15/M15,0),"") -> 0 | W15: =IFERROR(Q15-(T15*M15),"") -> 1 | AA15: 26.10.28
E16: 두바이)초코카다이프모찌60g | M16: 48 | Q16: =IFERROR(VLOOKUP($B$1,'대광피벗(재고)'!A:CF,5,FALSE),0) -> 3 | T16: =IFERROR(ROUNDDOWN(Q16/M16,0),"") -> 0 | W16: =IFERROR(Q16-(T16*M16),"") -> 3 | AA16: 26.10.28
E17: 두바이)카다이프판초콜릿60g(냉장) | M17: 50 | Q17: =IFERROR(VLOOKUP($B$1,'대광피벗(재고)'!A:CF,6,FALSE),0) -> 0 | T17: =IFERROR(ROUNDDOWN(Q17/M17,0),"") -> 0 | W17: =IFERROR(Q17-(T17*M17),"") -> 0 | AA17: 26.11.03 / 11.10
E18: 두바이)흑임자두쫀쿠50g(냉장) | M18: 60 | Q18: =IFERROR(VLOOKUP($B$1,'대광피벗(재고)'!A:CF,7,FALSE),0) -> 0 | T18: =IFERROR(ROUNDDOWN(Q18/M18,0),"") -> 0 | W18: =IFERROR(Q18-(T18*M18),"") -> 0 | AA18: 26.11.07
B22: 총수량 | M22: =SUM(Q13:S21) -> 61
B23: 3자물류 (더원물류) 담당자 박병선이사 010-4448-1456 | W23: =G8 -> 경상남도 양산시 산막공단북3길 25(산막동 313-4)
B27: 거 래 명 세 표 (공급자 보관용)
B29: 공 급 받 는 자 | C29: =C4 -> 등록번호 | Q29: 공 급 자 | R29: 등록번호 | V29: =V4 -> 206-86-55878
C31: =C6 -> 상 호 (법인명) | G31: =G6 -> (이마트24) | L31: =L6 -> 양산센터(저온) | R31: 상 호 (법인명) | V31: =V6 -> ㈜ 대광푸드 | AB31: 성 명 | AD31: =AD6 -> 한대훈
C33: 사업장 주 소 | G33: =G8 -> 경상남도 양산시 산막공단북3길 25(산막동 313-4) | R33: 사업장 주 소 | V33: =V8 -> 서울특별시 광진구 천호대로130길 22(구의동,필하임상가1호 에이호)
C35: 합계금액 (VAT포함) | R35: 업 태 | V35: =V10 -> 도소매 | AB35: 종 목 | AD35: =AD10 -> 빵,떡,과자류 외
B37: 년 | C37: 월 | D37: 일 | E37: 품 목 | M37: 입수 | Q37: 총수량 | T37: 박스 | W37: 낱개수량 | AA37: 비고
B38: =B13 -> 46307 | E38: =E13 -> 대광)생초코파이60g(냉장) | M38: =M13 -> 18 | Q38: =Q13 -> 0 | T38: =T13 -> 0 | W38: =W13 -> 0 | AA38: =IF(OR(Q13=0,AA13=""),"",AA13)
E39: =E14 -> 두바이)리얼두쫀쿠50g | M39: =M14 -> 60 | Q39: =Q14 -> 57 | T39: =T14 -> 0 | W39: =W14 -> 57 | AA39: =IF(OR(Q14=0,AA14=""),"",AA14) -> 26.11.07
E40: =E15 -> 두바이)리얼아쫀쿠50g | M40: =M15 -> 60 | Q40: =Q15 -> 1 | T40: =T15 -> 0 | W40: =W15 -> 1 | AA40: =IF(OR(Q15=0,AA15=""),"",AA15) -> 26.10.28
E41: =E16 -> 두바이)초코카다이프모찌60g | M41: =M16 -> 48 | Q41: =Q16 -> 3 | T41: =T16 -> 0 | W41: =W16 -> 3 | AA41: =IF(OR(Q16=0,AA16=""),"",AA16) -> 26.10.28
E42: =E17 -> 두바이)카다이프판초콜릿60g(냉장) | M42: =M17 -> 50 | Q42: =Q17 -> 0 | T42: =T17 -> 0 | W42: =W17 -> 0 | AA42: =IF(OR(Q17=0,AA17=""),"",AA17)
E43: =E18 -> 두바이)흑임자두쫀쿠50g(냉장) | M43: =M18 -> 60 | Q43: =Q18 -> 0 | T43: =T18 -> 0 | W43: =W18 -> 0 | AA43: =IF(OR(Q18=0,AA18=""),"",AA18)
AA44: =IF(OR(Q18=0,AA18=""),"",AA18)
AA45: ]
B47: =B22 -> 총수량 | M47: =M22 -> 61
B48: =B23 -> 3자물류 (더원물류) 담당자 박병선이사 010-4448-1456 | W48: =W23 -> 경상남도 양산시 산막공단북3길 25(산막동 313-4)

Sheet 세종 (18)
B1: 세종2(저온)
B2: 거 래 명 세 표 (공급받는자 보관용)
B4: 공 급 받 는 자 | C4: 등록번호 | Q4: 공 급 자 | R4: 등록번호 | V4: 206-86-55878
C6: 상 호 (법인명) | G6: (이마트24) | L6: 세종센터(저온) | R6: 상 호 (법인명) | V6: ㈜ 대광푸드 | AB6: 성명 | AD6: 한대훈
C8: 사업장 주 소 | G8: 세종특별자치시 연동면 응암리 925 E동 | R8: 사업장 주 소 | V8: 서울특별시 광진구 천호대로130길 22(구의동,필하임상가1호 에이호)
C10: 합계금액 (VAT포함) | R10: 업 태 | V10: 도소매 | AB10: 종목 | AD10: 빵,떡,과자류 외
B12: 년 | C12: 월 | D12: 일 | E12: 품 목 | M12: 입수 | Q12: 총수량 | T12: 박스 | W12: 낱개수량 | AA12: 비고
B13: ='원주(날짜변경!!)'!$B$13 -> 46307 | E13: 대광)생초코파이60g(냉장) | M13: 18 | Q13: =IFERROR(VLOOKUP($B$1,'대광피벗(재고)'!A:CF,2,FALSE),0) -> 0 | T13: =IFERROR(ROUNDDOWN(Q13/M13,0),"") -> 0 | W13: =IFERROR(Q13-(T13*M13),"") -> 0 | AA13: 26.09.28
E14: 두바이)리얼두쫀쿠50g | M14: 60 | Q14: =IFERROR(VLOOKUP($B$1,'대광피벗(재고)'!$A$1:$AC$119,3,FALSE),0) -> 50 | T14: =IFERROR(ROUNDDOWN(Q14/M14,0),"") -> 0 | W14: =IFERROR(Q14-(T14*M14),"") -> 50 | AA14: 26.11.07
E15: 두바이)리얼아쫀쿠50g | M15: 60 | Q15: =IFERROR(VLOOKUP($B$1,'대광피벗(재고)'!A:CF,4,FALSE),0) -> 2 | T15: =IFERROR(ROUNDDOWN(Q15/M15,0),"") -> 0 | W15: =IFERROR(Q15-(T15*M15),"") -> 2 | AA15: 26.10.28
E16: 두바이)초코카다이프모찌60g | M16: 48 | Q16: =IFERROR(VLOOKUP($B$1,'대광피벗(재고)'!A:CF,5,FALSE),0) -> 1 | T16: =IFERROR(ROUNDDOWN(Q16/M16,0),"") -> 0 | W16: =IFERROR(Q16-(T16*M16),"") -> 1 | AA16: 26.10.28
E17: 두바이)카다이프판초콜릿60g(냉장) | M17: 50 | Q17: =IFERROR(VLOOKUP($B$1,'대광피벗(재고)'!A:CF,6,FALSE),0) -> 3 | T17: =IFERROR(ROUNDDOWN(Q17/M17,0),"") -> 0 | W17: =IFERROR(Q17-(T17*M17),"") -> 3 | AA17: 26.11.03 / 11.10
E18: 두바이)흑임자두쫀쿠50g(냉장) | M18: 60 | Q18: =IFERROR(VLOOKUP($B$1,'대광피벗(재고)'!A:CF,7,FALSE),0) -> 0 | T18: =IFERROR(ROUNDDOWN(Q18/M18,0),"") -> 0 | W18: =IFERROR(Q18-(T18*M18),"") -> 0 | AA18: 26.11.07
B22: 총수량 | M22: =SUM(Q13:S21) -> 56
B23: 3자물류 (더원물류) 담당자 박병선이사 010-4448-1456 | W23: 세종특별자치시 연동면 응암리 925 E동 허승현 대리 044-862-4400
B27: 거 래 명 세 표 (공급자 보관용)
B29: 공 급 받 는 자 | C29: =C4 -> 등록번호 | Q29: 공 급 자 | R29: 등록번호 | V29: =V4 -> 206-86-55878
C31: =C6 -> 상 호 (법인명) | G31: =G6 -> (이마트24) | L31: =L6 -> 세종센터(저온) | R31: 상 호 (법인명) | V31: =V6 -> ㈜ 대광푸드 | AB31: 성 명 | AD31: =AD6 -> 한대훈
C33: 사업장 주 소 | G33: =G8 -> 세종특별자치시 연동면 응암리 925 E동 | R33: 사업장 주 소 | V33: =V8 -> 서울특별시 광진구 천호대로130길 22(구의동,필하임상가1호 에이호)
C35: 합계금액 (VAT포함) | R35: 업 태 | V35: =V10 -> 도소매 | AB35: 종 목 | AD35: =AD10 -> 빵,떡,과자류 외
B37: 년 | C37: 월 | D37: 일 | E37: 품 목 | M37: 입수 | Q37: 총수량 | T37: 박스 | W37: 낱개수량 | AA37: 비고
B38: =B13 -> 46307 | E38: =E13 -> 대광)생초코파이60g(냉장) | M38: =M13 -> 18 | Q38: =Q13 -> 0 | T38: =T13 -> 0 | W38: =W13 -> 0 | AA38: =IF(OR(Q13=0,AA13=""),"",AA13)
E39: =E14 -> 두바이)리얼두쫀쿠50g | M39: =M14 -> 60 | Q39: =Q14 -> 50 | T39: =T14 -> 0 | W39: =W14 -> 50 | AA39: =IF(OR(Q14=0,AA14=""),"",AA14) -> 26.11.07
E40: =E15 -> 두바이)리얼아쫀쿠50g | M40: =M15 -> 60 | Q40: =Q15 -> 2 | T40: =T15 -> 0 | W40: =W15 -> 2 | AA40: =IF(OR(Q15=0,AA15=""),"",AA15) -> 26.10.28
E41: =E16 -> 두바이)초코카다이프모찌60g | M41: =M16 -> 48 | Q41: =Q16 -> 1 | T41: =T16 -> 0 | W41: =W16 -> 1 | AA41: 26.08.17
E42: =E17 -> 두바이)카다이프판초콜릿60g(냉장) | M42: =M17 -> 50 | Q42: =Q17 -> 3 | T42: =T17 -> 0 | W42: =W17 -> 3 | AA42: 26.09.05
E43: =E18 -> 두바이)흑임자두쫀쿠50g(냉장) | M43: =M18 -> 60 | Q43: =Q18 -> 0 | T43: =T18 -> 0 | W43: =W18 -> 0 | AA43: =IF(OR(Q18=0,AA18=""),"",AA18)
AA44: =IF(OR(Q18=0,AA18=""),"",AA18)
AA45: =IF(AA20="","",AA20)
B47: =B22 -> 총수량 | M47: =M22 -> 56
B48: =B23 -> 3자물류 (더원물류) 담당자 박병선이사 010-4448-1456 | W48: =W23 -> 세종특별자치시 연동면 응암리 925 E동 허승현 대리 044-862-4400

Sheet 장성 (25)
B1: 장성2(저온)
B2: 거 래 명 세 표 (공급받는자 보관용)
B4: 공 급 받 는 자 | C4: 등록번호 | Q4: 공 급 자 | R4: 등록번호 | V4: 206-86-55878
C6: 상 호 (법인명) | G6: (이마트24) | L6: 장성센터(저온) | R6: 상 호 (법인명) | V6: ㈜ 대광푸드 | AB6: 성명 | AD6: 한대훈
C8: 사업장 주 소 | G8: 전라남도 장성군 황룡면 황룡리 44-2 2층 | R8: 사업장 주 소 | V8: 서울특별시 광진구 천호대로130길 22(구의동,필하임상가1호 에이호)
C10: 합계금액 (VAT포함) | R10: 업 태 | V10: 도소매 | AB10: 종목 | AD10: 빵,떡,과자류 외
B12: 년 | C12: 월 | D12: 일 | E12: 품 목 | M12: 입수 | Q12: 총수량 | T12: 박스 | W12: 낱개수량 | AA12: 비고
B13: ='원주(날짜변경!!)'!$B$13 -> 46307 | E13: 대광)생초코파이60g(냉장) | M13: 18 | Q13: =IFERROR(VLOOKUP($B$1,'대광피벗(재고)'!A:CF,2,FALSE),0) -> 0 | T13: =IFERROR(ROUNDDOWN(Q13/M13,0),"") -> 0 | W13: =IFERROR(Q13-(T13*M13),"") -> 0 | AA13: 26.09.28
E14: 두바이)리얼두쫀쿠50g | M14: 60 | Q14: =IFERROR(VLOOKUP($B$1,'대광피벗(재고)'!$A$1:$AC$119,3,FALSE),0) -> 68 | T14: =IFERROR(ROUNDDOWN(Q14/M14,0),"") -> 1 | W14: =IFERROR(Q14-(T14*M14),"") -> 8 | AA14: 26.11.07
E15: 두바이)리얼아쫀쿠50g | M15: 60 | Q15: =IFERROR(VLOOKUP($B$1,'대광피벗(재고)'!A:CF,4,FALSE),0) -> 6 | T15: =IFERROR(ROUNDDOWN(Q15/M15,0),"") -> 0 | W15: =IFERROR(Q15-(T15*M15),"") -> 6 | AA15: 26.10.28
E16: 두바이)초코카다이프모찌60g | M16: 48 | Q16: =IFERROR(VLOOKUP($B$1,'대광피벗(재고)'!A:CF,5,FALSE),0) -> 4 | T16: =IFERROR(ROUNDDOWN(Q16/M16,0),"") -> 0 | W16: =IFERROR(Q16-(T16*M16),"") -> 4 | AA16: 26.10.28
E17: 두바이)카다이프판초콜릿60g(냉장) | M17: 50 | Q17: =IFERROR(VLOOKUP($B$1,'대광피벗(재고)'!A:CF,6,FALSE),0) -> 2 | T17: =IFERROR(ROUNDDOWN(Q17/M17,0),"") -> 0 | W17: =IFERROR(Q17-(T17*M17),"") -> 2 | AA17: 26.11.03 / 11.10
E18: 두바이)흑임자두쫀쿠50g(냉장) | M18: 60 | Q18: =IFERROR(VLOOKUP($B$1,'대광피벗(재고)'!A:CF,7,FALSE),0) -> 2 | T18: =IFERROR(ROUNDDOWN(Q18/M18,0),"") -> 0 | W18: =IFERROR(Q18-(T18*M18),"") -> 2 | AA18: 26.11.07
B22: 총수량 | M22: =SUM(Q13:S21) -> 82
B23: 3자물류 (더원물류) 담당자 박병선이사 010-4448-1456 | W23: =G8 -> 전라남도 장성군 황룡면 황룡리 44-2 2층
B27: 거 래 명 세 표 (공급자 보관용)
B29: 공 급 받 는 자 | C29: =C4 -> 등록번호 | Q29: 공 급 자 | R29: 등록번호 | V29: =V4 -> 206-86-55878
C31: =C6 -> 상 호 (법인명) | G31: =G6 -> (이마트24) | L31: =L6 -> 장성센터(저온) | R31: 상 호 (법인명) | V31: =V6 -> ㈜ 대광푸드 | AB31: 성 명 | AD31: =AD6 -> 한대훈
C33: 사업장 주 소 | G33: =G8 -> 전라남도 장성군 황룡면 황룡리 44-2 2층 | R33: 사업장 주 소 | V33: =V8 -> 서울특별시 광진구 천호대로130길 22(구의동,필하임상가1호 에이호)
C35: 합계금액 (VAT포함) | R35: 업 태 | V35: =V10 -> 도소매 | AB35: 종 목 | AD35: =AD10 -> 빵,떡,과자류 외
B37: 년 | C37: 월 | D37: 일 | E37: 품 목 | M37: 입수 | Q37: 총수량 | T37: 박스 | W37: 낱개수량 | AA37: 비고
B38: =B13 -> 46307 | E38: =E13 -> 대광)생초코파이60g(냉장) | M38: =M13 -> 18 | Q38: =Q13 -> 0 | T38: =T13 -> 0 | W38: =W13 -> 0 | AA38: =IF(OR(Q13=0,AA13=""),"",AA13)
E39: =E14 -> 두바이)리얼두쫀쿠50g | M39: =M14 -> 60 | Q39: =Q14 -> 68 | T39: =T14 -> 1 | W39: =W14 -> 8 | AA39: =IF(OR(Q14=0,AA14=""),"",AA14) -> 26.11.07
E40: =E15 -> 두바이)리얼아쫀쿠50g | M40: =M15 -> 60 | Q40: =Q15 -> 6 | T40: =T15 -> 0 | W40: =W15 -> 6 | AA40: =IF(OR(Q15=0,AA15=""),"",AA15) -> 26.10.28
E41: =E16 -> 두바이)초코카다이프모찌60g | M41: =M16 -> 48 | Q41: =Q16 -> 4 | T41: =T16 -> 0 | W41: =W16 -> 4 | AA41: 26.08.17
E42: =E17 -> 두바이)카다이프판초콜릿60g(냉장) | M42: =M17 -> 50 | Q42: =Q17 -> 2 | T42: =T17 -> 0 | W42: =W17 -> 2 | AA42: =IF(OR(Q17=0,AA17=""),"",AA17) -> 26.11.03 / 11.10
E43: =E18 -> 두바이)흑임자두쫀쿠50g(냉장) | M43: =M18 -> 60 | Q43: =Q18 -> 2 | T43: =T18 -> 0 | W43: =W18 -> 2 | AA43: =IF(OR(Q18=0,AA18=""),"",AA18) -> 26.11.07
AA44: =IF(OR(Q18=0,AA18=""),"",AA18) -> 26.11.07
AA45: =IF(AA20="","",AA20)
AA46: =IF(AA21="","",AA21)
B47: =B22 -> 총수량 | M47: =M22 -> 82
B48: =B23 -> 3자물류 (더원물류) 담당자 박병선이사 010-4448-1456 | W48: =W23 -> 전라남도 장성군 황룡면 황룡리 44-2 2층

Sheet 김천 (18)
B1: 김천2(저온)
B2: 거 래 명 세 표 (공급받는자 보관용)
B4: 공 급 받 는 자 | C4: 등록번호 | Q4: 공 급 자 | R4: 등록번호 | V4: 206-86-55878
C6: 상 호 (법인명) | G6: (이마트24) | L6: 김천센터(저온) | R6: 상 호 (법인명) | V6: ㈜ 대광푸드 | AB6: 성명 | AD6: 한대훈
C8: 사업장 주 소 | G8: 경상북도 김천시 어모면 옥율리 212 | R8: 사업장 주 소 | V8: 서울특별시 광진구 천호대로130길 22(구의동,필하임상가1호 에이호)
C10: 합계금액 (VAT포함) | R10: 업 태 | V10: 도소매 | AB10: 종목 | AD10: 빵,떡,과자류 외
B12: 년 | C12: 월 | D12: 일 | E12: 품 목 | M12: 입수 | Q12: 총수량 | T12: 박스 | W12: 낱개수량 | AA12: 비고
B13: ='원주(날짜변경!!)'!$B$13 -> 46307 | E13: 대광)생초코파이60g(냉장) | M13: 18 | Q13: =IFERROR(VLOOKUP($B$1,'대광피벗(재고)'!A:CF,2,FALSE),0) -> 0 | T13: =IFERROR(ROUNDDOWN(Q13/M13,0),"") -> 0 | W13: =IFERROR(Q13-(T13*M13),"") -> 0 | AA13: 26.09.28
E14: 두바이)리얼두쫀쿠50g | M14: 60 | Q14: =IFERROR(VLOOKUP($B$1,'대광피벗(재고)'!$A$1:$AC$119,3,FALSE),0) -> 26 | T14: =IFERROR(ROUNDDOWN(Q14/M14,0),"") -> 0 | W14: =IFERROR(Q14-(T14*M14),"") -> 26 | AA14: 26.11.07
E15: 두바이)리얼아쫀쿠50g | M15: 60 | Q15: =IFERROR(VLOOKUP($B$1,'대광피벗(재고)'!A:CF,4,FALSE),0) -> 2 | T15: =IFERROR(ROUNDDOWN(Q15/M15,0),"") -> 0 | W15: =IFERROR(Q15-(T15*M15),"") -> 2 | AA15: 26.10.28
E16: 두바이)초코카다이프모찌60g | M16: 48 | Q16: =IFERROR(VLOOKUP($B$1,'대광피벗(재고)'!A:CF,5,FALSE),0) -> 2 | T16: =IFERROR(ROUNDDOWN(Q16/M16,0),"") -> 0 | W16: =IFERROR(Q16-(T16*M16),"") -> 2 | AA16: 26.10.28
E17: 두바이)카다이프판초콜릿60g(냉장) | M17: 50 | Q17: =IFERROR(VLOOKUP($B$1,'대광피벗(재고)'!A:CF,6,FALSE),0) -> 0 | T17: =IFERROR(ROUNDDOWN(Q17/M17,0),"") -> 0 | W17: =IFERROR(Q17-(T17*M17),"") -> 0 | AA17: 26.11.03 / 11.10
E18: 두바이)흑임자두쫀쿠50g(냉장) | M18: 60 | Q18: =IFERROR(VLOOKUP($B$1,'대광피벗(재고)'!A:CF,7,FALSE),0) -> 0 | T18: =IFERROR(ROUNDDOWN(Q18/M18,0),"") -> 0 | W18: =IFERROR(Q18-(T18*M18),"") -> 0 | AA18: 26.11.07
B22: 총수량 | M22: =SUM(Q13:S21) -> 30
B23: 3자물류 (더원물류) 담당자 박병선이사 010-4448-1456 | W23: =G8 -> 경상북도 김천시 어모면 옥율리 212
B27: 거 래 명 세 표 (공급자 보관용)
B29: 공 급 받 는 자 | C29: =C4 -> 등록번호 | Q29: 공 급 자 | R29: 등록번호 | V29: =V4 -> 206-86-55878
C31: =C6 -> 상 호 (법인명) | G31: =G6 -> (이마트24) | L31: =L6 -> 김천센터(저온) | R31: 상 호 (법인명) | V31: =V6 -> ㈜ 대광푸드 | AB31: 성 명 | AD31: =AD6 -> 한대훈
C33: 사업장 주 소 | G33: =G8 -> 경상북도 김천시 어모면 옥율리 212 | R33: 사업장 주 소 | V33: =V8 -> 서울특별시 광진구 천호대로130길 22(구의동,필하임상가1호 에이호)
C35: 합계금액 (VAT포함) | R35: 업 태 | V35: =V10 -> 도소매 | AB35: 종 목 | AD35: =AD10 -> 빵,떡,과자류 외
B37: 년 | C37: 월 | D37: 일 | E37: 품 목 | M37: 입수 | Q37: 총수량 | T37: 박스 | W37: 낱개수량 | AA37: 비고
B38: =B13 -> 46307 | E38: =E13 -> 대광)생초코파이60g(냉장) | M38: =M13 -> 18 | Q38: =Q13 -> 0 | T38: =T13 -> 0 | W38: =W13 -> 0 | AA38: =IF(OR(Q13=0,AA13=""),"",AA13)
E39: =E14 -> 두바이)리얼두쫀쿠50g | M39: =M14 -> 60 | Q39: =Q14 -> 26 | T39: =T14 -> 0 | W39: =W14 -> 26 | AA39: =IF(OR(Q14=0,AA14=""),"",AA14) -> 26.11.07
E40: =E15 -> 두바이)리얼아쫀쿠50g | M40: =M15 -> 60 | Q40: =Q15 -> 2 | T40: =T15 -> 0 | W40: =W15 -> 2 | AA40: =IF(OR(Q15=0,AA15=""),"",AA15) -> 26.10.28
E41: =E16 -> 두바이)초코카다이프모찌60g | M41: =M16 -> 48 | Q41: =Q16 -> 2 | T41: =T16 -> 0 | W41: =W16 -> 2 | AA41: =IF(OR(Q16=0,AA16=""),"",AA16) -> 26.10.28
E42: =E17 -> 두바이)카다이프판초콜릿60g(냉장) | M42: =M17 -> 50 | Q42: =Q17 -> 0 | T42: =T17 -> 0 | W42: =W17 -> 0 | AA42: =IF(OR(Q17=0,AA17=""),"",AA17)
E43: =E18 -> 두바이)흑임자두쫀쿠50g(냉장) | M43: =M18 -> 60 | Q43: =Q18 -> 0 | T43: =T18 -> 0 | W43: =W18 -> 0 | AA43: =IF(OR(Q18=0,AA18=""),"",AA18)
AA44: =IF(OR(Q18=0,AA18=""),"",AA18)
AA45: =IF(AA20="","",AA20)
B47: =B22 -> 총수량 | M47: =M22 -> 30
B48: =B23 -> 3자물류 (더원물류) 담당자 박병선이사 010-4448-1456 | W48: =W23 -> 경상북도 김천시 어모면 옥율리 212

Sheet 경산(7)
B1: 경산2(저온)
B2: 거 래 명 세 표 (공급받는자 보관용)
B4: 공 급 받 는 자 | C4: 등록번호 | Q4: 공 급 자 | R4: 등록번호 | V4: 206-86-55878
C6: 상 호 (법인명) | G6: (이마트24) | L6: 경산센터(저온) | R6: 상 호 (법인명) | V6: ㈜ 대광푸드 | AB6: 성명 | AD6: 한대훈
C8: 사업장 주 소 | G8: 경상북도 경산시 압량읍 가야로 20 | R8: 사업장 주 소 | V8: 서울특별시 광진구 천호대로130길 22(구의동,필하임상가1호 에이호)
C10: 합계금액 (VAT포함) | R10: 업 태 | V10: 도소매 | AB10: 종목 | AD10: 빵,떡,과자류 외
B12: 년 | C12: 월 | D12: 일 | E12: 품 목 | M12: 입수 | Q12: 총수량 | T12: 박스 | W12: 낱개수량 | AA12: 비고
B13: ='원주(날짜변경!!)'!$B$13 -> 46307 | E13: 대광)생초코파이60g(냉장) | M13: 18 | Q13: =IFERROR(VLOOKUP($B$1,'대광피벗(재고)'!A:CF,2,FALSE),0) -> 0 | T13: =IFERROR(ROUNDDOWN(Q13/M13,0),"") -> 0 | W13: =IFERROR(Q13-(T13*M13),"") -> 0 | AA13: 26.09.28
E14: 두바이)리얼두쫀쿠50g | M14: 60 | Q14: =IFERROR(VLOOKUP($B$1,'대광피벗(재고)'!$A$1:$AC$119,3,FALSE),0) -> 32 | T14: =IFERROR(ROUNDDOWN(Q14/M14,0),"") -> 0 | W14: =IFERROR(Q14-(T14*M14),"") -> 32 | AA14: 26.11.07
E15: 두바이)리얼아쫀쿠50g | M15: 60 | Q15: =IFERROR(VLOOKUP($B$1,'대광피벗(재고)'!A:CF,4,FALSE),0) -> 3 | T15: =IFERROR(ROUNDDOWN(Q15/M15,0),"") -> 0 | W15: =IFERROR(Q15-(T15*M15),"") -> 3 | AA15: 26.10.28
E16: 두바이)초코카다이프모찌60g | M16: 48 | Q16: =IFERROR(VLOOKUP($B$1,'대광피벗(재고)'!A:CF,5,FALSE),0) -> 2 | T16: =IFERROR(ROUNDDOWN(Q16/M16,0),"") -> 0 | W16: =IFERROR(Q16-(T16*M16),"") -> 2 | AA16: 26.10.28
E17: 두바이)카다이프판초콜릿60g(냉장) | M17: 50 | Q17: =IFERROR(VLOOKUP($B$1,'대광피벗(재고)'!A:CF,6,FALSE),0) -> 0 | T17: =IFERROR(ROUNDDOWN(Q17/M17,0),"") -> 0 | W17: =IFERROR(Q17-(T17*M17),"") -> 0 | AA17: 26.11.03 / 11.10
E18: 두바이)흑임자두쫀쿠50g(냉장) | M18: 60 | Q18: =IFERROR(VLOOKUP($B$1,'대광피벗(재고)'!A:CF,7,FALSE),0) -> 0 | T18: =IFERROR(ROUNDDOWN(Q18/M18,0),"") -> 0 | W18: =IFERROR(Q18-(T18*M18),"") -> 0 | AA18: 26.11.07
B22: 총수량 | M22: =SUM(Q13:S21) -> 37
B23: 3자물류 (더원물류) 담당자 박병선이사 010-4448-1456 | W23: =G8 -> 경상북도 경산시 압량읍 가야로 20
B27: 거 래 명 세 표 (공급자 보관용)
B29: 공 급 받 는 자 | C29: =C4 -> 등록번호 | Q29: 공 급 자 | R29: 등록번호 | V29: =V4 -> 206-86-55878
C31: =C6 -> 상 호 (법인명) | G31: =G6 -> (이마트24) | L31: =L6 -> 경산센터(저온) | R31: 상 호 (법인명) | V31: =V6 -> ㈜ 대광푸드 | AB31: 성 명 | AD31: =AD6 -> 한대훈
C33: 사업장 주 소 | G33: =G8 -> 경상북도 경산시 압량읍 가야로 20 | R33: 사업장 주 소 | V33: =V8 -> 서울특별시 광진구 천호대로130길 22(구의동,필하임상가1호 에이호)
C35: 합계금액 (VAT포함) | R35: 업 태 | V35: =V10 -> 도소매 | AB35: 종 목 | AD35: =AD10 -> 빵,떡,과자류 외
B37: 년 | C37: 월 | D37: 일 | E37: 품 목 | M37: 입수 | Q37: 총수량 | T37: 박스 | W37: 낱개수량 | AA37: 비고
B38: =B13 -> 46307 | E38: =E13 -> 대광)생초코파이60g(냉장) | M38: =M13 -> 18 | Q38: =Q13 -> 0 | T38: =T13 -> 0 | W38: =W13 -> 0 | AA38: =IF(OR(Q13=0,AA13=""),"",AA13)
E39: =E14 -> 두바이)리얼두쫀쿠50g | M39: =M14 -> 60 | Q39: =Q14 -> 32 | T39: =T14 -> 0 | W39: =W14 -> 32 | AA39: =IF(OR(Q14=0,AA14=""),"",AA14) -> 26.11.07
E40: =E15 -> 두바이)리얼아쫀쿠50g | M40: =M15 -> 60 | Q40: =Q15 -> 3 | T40: =T15 -> 0 | W40: =W15 -> 3 | AA40: =IF(OR(Q15=0,AA15=""),"",AA15) -> 26.10.28
E41: =E16 -> 두바이)초코카다이프모찌60g | M41: =M16 -> 48 | Q41: =Q16 -> 2 | T41: =T16 -> 0 | W41: =W16 -> 2 | AA41: =IF(OR(Q16=0,AA16=""),"",AA16) -> 26.10.28
E42: =E17 -> 두바이)카다이프판초콜릿60g(냉장) | M42: =M17 -> 50 | Q42: =Q17 -> 0 | T42: =T17 -> 0 | W42: =W17 -> 0 | AA42: =IF(OR(Q17=0,AA17=""),"",AA17)
E43: =E18 -> 두바이)흑임자두쫀쿠50g(냉장) | M43: =M18 -> 60 | Q43: =Q18 -> 0 | T43: =T18 -> 0 | W43: =W18 -> 0 | AA43: =IF(OR(Q18=0,AA18=""),"",AA18)
AA44: =IF(OR(Q19=0,AA19=""),"",AA19)
AA45: =IF(OR(Q20=0,AA20=""),"",AA20)
AA46: =IF(OR(Q21=0,AA21=""),"",AA21)
B47: =B22 -> 총수량 | M47: =M22 -> 37
B48: =B23 -> 3자물류 (더원물류) 담당자 박병선이사 010-4448-1456 | W48: =W23 -> 경상북도 경산시 압량읍 가야로 20

Sheet 화성 (16)
B1: 화성2(저온)
B2: 거 래 명 세 표 (공급받는자 보관용)
B4: 공 급 받 는 자 | C4: 등록번호 | Q4: 공 급 자 | R4: 등록번호 | V4: 206-86-55878
C6: 상 호 (법인명) | G6: (이마트24) | L6: 화성센터(저온) | R6: 상 호 (법인명) | V6: ㈜ 대광푸드 | AB6: 성명 | AD6: 한대훈
C8: 사업장 주 소 | G8: 경기 화성시 초록로 103 | R8: 사업장 주 소 | V8: 서울특별시 광진구 천호대로130길 22(구의동,필하임상가1호 에이호)
C10: 합계금액 (VAT포함) | R10: 업 태 | V10: 도소매 | AB10: 종목 | AD10: 빵,떡,과자류 외
B12: 년 | C12: 월 | D12: 일 | E12: 품 목 | M12: 입수 | Q12: 총수량 | T12: 박스 | W12: 낱개수량 | AA12: 비고
B13: ='원주(날짜변경!!)'!$B$13 -> 46307 | E13: 대광)생초코파이60g(냉장) | M13: 18 | Q13: =IFERROR(VLOOKUP($B$1,'대광피벗(재고)'!A:CF,2,FALSE),0) -> 0 | T13: =IFERROR(ROUNDDOWN(Q13/M13,0),"") -> 0 | W13: =IFERROR(Q13-(T13*M13),"") -> 0 | AA13: 26.09.28
E14: 두바이)리얼두쫀쿠50g | M14: 60 | Q14: =IFERROR(VLOOKUP($B$1,'대광피벗(재고)'!$A$1:$AC$119,3,FALSE),0) -> 49 | T14: =IFERROR(ROUNDDOWN(Q14/M14,0),"") -> 0 | W14: =IFERROR(Q14-(T14*M14),"") -> 49 | AA14: 26.11.07
E15: 두바이)리얼아쫀쿠50g | M15: 60 | Q15: =IFERROR(VLOOKUP($B$1,'대광피벗(재고)'!A:CF,4,FALSE),0) -> 5 | T15: =IFERROR(ROUNDDOWN(Q15/M15,0),"") -> 0 | W15: =IFERROR(Q15-(T15*M15),"") -> 5 | AA15: 26.10.28
E16: 두바이)초코카다이프모찌60g | M16: 48 | Q16: =IFERROR(VLOOKUP($B$1,'대광피벗(재고)'!A:CF,5,FALSE),0) -> 2 | T16: =IFERROR(ROUNDDOWN(Q16/M16,0),"") -> 0 | W16: =IFERROR(Q16-(T16*M16),"") -> 2 | AA16: 26.10.28
E17: 두바이)카다이프판초콜릿60g(냉장) | M17: 50 | Q17: =IFERROR(VLOOKUP($B$1,'대광피벗(재고)'!A:CF,6,FALSE),0) -> 0 | T17: =IFERROR(ROUNDDOWN(Q17/M17,0),"") -> 0 | W17: =IFERROR(Q17-(T17*M17),"") -> 0 | AA17: 26.11.03 / 11.10
E18: 두바이)흑임자두쫀쿠50g(냉장) | M18: 60 | Q18: =IFERROR(VLOOKUP($B$1,'대광피벗(재고)'!A:CF,7,FALSE),0) -> 0 | T18: =IFERROR(ROUNDDOWN(Q18/M18,0),"") -> 0 | W18: =IFERROR(Q18-(T18*M18),"") -> 0 | AA18: 26.11.07
B22: 총수량 | M22: =SUM(Q13:S21) -> 56
B23: 3자물류 (더원물류) 담당자 박병선이사 010-4448-1456 | W23: 경기 화성시 초록로 103 오민수 대리 031-8077-2407
B27: 거 래 명 세 표 (공급자 보관용)
B29: 공 급 받 는 자 | C29: =C4 -> 등록번호 | Q29: 공 급 자 | R29: 등록번호 | V29: =V4 -> 206-86-55878
C31: =C6 -> 상 호 (법인명) | G31: =G6 -> (이마트24) | L31: =L6 -> 화성센터(저온) | R31: 상 호 (법인명) | V31: =V6 -> ㈜ 대광푸드 | AB31: 성 명 | AD31: =AD6 -> 한대훈
C33: 사업장 주 소 | G33: =G8 -> 경기 화성시 초록로 103 | R33: 사업장 주 소 | V33: =V8 -> 서울특별시 광진구 천호대로130길 22(구의동,필하임상가1호 에이호)
C35: 합계금액 (VAT포함) | R35: 업 태 | V35: =V10 -> 도소매 | AB35: 종 목 | AD35: =AD10 -> 빵,떡,과자류 외
B37: 년 | C37: 월 | D37: 일 | E37: 품 목 | M37: 입수 | Q37: 총수량 | T37: 박스 | W37: 낱개수량 | AA37: 비고
B38: =B13 -> 46307 | E38: =E13 -> 대광)생초코파이60g(냉장) | M38: =M13 -> 18 | Q38: =Q13 -> 0 | T38: =T13 -> 0 | W38: =W13 -> 0 | AA38: =IF(OR(Q13=0,AA13=""),"",AA13)
E39: =E14 -> 두바이)리얼두쫀쿠50g | M39: =M14 -> 60 | Q39: =Q14 -> 49 | T39: =T14 -> 0 | W39: =W14 -> 49 | AA39: =IF(OR(Q14=0,AA14=""),"",AA14) -> 26.11.07
E40: =E15 -> 두바이)리얼아쫀쿠50g | M40: =M15 -> 60 | Q40: =Q15 -> 5 | T40: =T15 -> 0 | W40: =W15 -> 5 | AA40: =IF(OR(Q15=0,AA15=""),"",AA15) -> 26.10.28
E41: =E16 -> 두바이)초코카다이프모찌60g | M41: =M16 -> 48 | Q41: =Q16 -> 2 | T41: =T16 -> 0 | W41: =W16 -> 2 | AA41: 26.08.17
E42: =E17 -> 두바이)카다이프판초콜릿60g(냉장) | M42: =M17 -> 50 | Q42: =Q17 -> 0 | T42: =T17 -> 0 | W42: =W17 -> 0 | AA42: =IF(OR(Q17=0,AA17=""),"",AA17)
E43: =E18 -> 두바이)흑임자두쫀쿠50g(냉장) | M43: =M18 -> 60 | Q43: =Q18 -> 0 | T43: =T18 -> 0 | W43: =W18 -> 0 | AA43: =IF(OR(Q18=0,AA18=""),"",AA18)
AA44: =IF(OR(Q18=0,AA18=""),"",AA18)
AA45: =IF(AA20="","",AA20)
B47: =B22 -> 총수량 | M47: =M22 -> 56
B48: =B23 -> 3자물류 (더원물류) 담당자 박병선이사 010-4448-1456 | W48: =W23 -> 경기 화성시 초록로 103 오민수 대리 031-8077-2407

Sheet 청라 (16)
B1: 청라2(저온)
B2: 거 래 명 세 표 (공급받는자 보관용)
B4: 공 급 받 는 자 | C4: 등록번호 | Q4: 공 급 자 | R4: 등록번호 | V4: 206-86-55878
C6: 상 호 (법인명) | G6: (이마트24) | L6: 청라센터(저온) | R6: 상 호 (법인명) | V6: ㈜ 대광푸드 | AB6: 성명 | AD6: 한대훈
C8: 사업장 주 소 | G8: 인천광역시 서구 북항로120번길 55, 청라로지스틱스센터3, 9층 | R8: 사업장 주 소 | V8: 서울특별시 광진구 천호대로130길 22(구의동,필하임상가1호 에이호)
C10: 합계금액 (VAT포함) | R10: 업 태 | V10: 도소매 | AB10: 종목 | AD10: 빵,떡,과자류 외
B12: 년 | C12: 월 | D12: 일 | E12: 품 목 | M12: 입수 | Q12: 총수량 | T12: 박스 | W12: 낱개수량 | AA12: 비고
B13: ='원주(날짜변경!!)'!$B$13 -> 46307 | E13: 대광)생초코파이60g(냉장) | M13: 18 | Q13: =IFERROR(VLOOKUP($B$1,'대광피벗(재고)'!A:CF,2,FALSE),0) -> 0 | T13: =IFERROR(ROUNDDOWN(Q13/M13,0),"") -> 0 | W13: =IFERROR(Q13-(T13*M13),"") -> 0 | AA13: 26.09.28
E14: 두바이)리얼두쫀쿠50g | M14: 60 | Q14: =IFERROR(VLOOKUP($B$1,'대광피벗(재고)'!$A$1:$AC$119,3,FALSE),0) -> 52 | T14: =IFERROR(ROUNDDOWN(Q14/M14,0),"") -> 0 | W14: =IFERROR(Q14-(T14*M14),"") -> 52 | AA14: 26.11.07
E15: 두바이)리얼아쫀쿠50g | M15: 60 | Q15: =IFERROR(VLOOKUP($B$1,'대광피벗(재고)'!A:CF,4,FALSE),0) -> 7 | T15: =IFERROR(ROUNDDOWN(Q15/M15,0),"") -> 0 | W15: =IFERROR(Q15-(T15*M15),"") -> 7 | AA15: 26.10.28
E16: 두바이)초코카다이프모찌60g | M16: 48 | Q16: =IFERROR(VLOOKUP($B$1,'대광피벗(재고)'!A:CF,5,FALSE),0) -> 10 | T16: =IFERROR(ROUNDDOWN(Q16/M16,0),"") -> 0 | W16: =IFERROR(Q16-(T16*M16),"") -> 10 | AA16: 26.10.28
E17: 두바이)카다이프판초콜릿60g(냉장) | M17: 50 | Q17: =IFERROR(VLOOKUP($B$1,'대광피벗(재고)'!A:CF,6,FALSE),0) -> 2 | T17: =IFERROR(ROUNDDOWN(Q17/M17,0),"") -> 0 | W17: =IFERROR(Q17-(T17*M17),"") -> 2 | AA17: 26.11.03 / 11.10
E18: 두바이)흑임자두쫀쿠50g(냉장) | M18: 60 | Q18: =IFERROR(VLOOKUP($B$1,'대광피벗(재고)'!A:CF,7,FALSE),0) -> 0 | T18: =IFERROR(ROUNDDOWN(Q18/M18,0),"") -> 0 | W18: =IFERROR(Q18-(T18*M18),"") -> 0 | AA18: 26.11.07
B22: 총수량 | M22: =SUM(Q13:S21) -> 71
B23: 3자물류 (더원물류) 담당자 박병선이사 010-4448-1456 | W23: 인천광역시 서구 북항로120번길 55, 청라로지스틱스센터3, 9층 02)437-0500
B27: 거 래 명 세 표 (공급자 보관용)
B29: 공 급 받 는 자 | C29: =C4 -> 등록번호 | Q29: 공 급 자 | R29: 등록번호 | V29: =V4 -> 206-86-55878
C31: =C6 -> 상 호 (법인명) | G31: =G6 -> (이마트24) | L31: =L6 -> 청라센터(저온) | R31: 상 호 (법인명) | V31: =V6 -> ㈜ 대광푸드 | AB31: 성 명 | AD31: =AD6 -> 한대훈
C33: 사업장 주 소 | G33: =G8 -> 인천광역시 서구 북항로120번길 55, 청라로지스틱스센터3, 9층 | R33: 사업장 주 소 | V33: =V8 -> 서울특별시 광진구 천호대로130길 22(구의동,필하임상가1호 에이호)
C35: 합계금액 (VAT포함) | R35: 업 태 | V35: =V10 -> 도소매 | AB35: 종 목 | AD35: =AD10 -> 빵,떡,과자류 외
B37: 년 | C37: 월 | D37: 일 | E37: 품 목 | M37: 입수 | Q37: 총수량 | T37: 박스 | W37: 낱개수량 | AA37: 비고
B38: =B13 -> 46307 | E38: =E13 -> 대광)생초코파이60g(냉장) | M38: =M13 -> 18 | Q38: =Q13 -> 0 | T38: =T13 -> 0 | W38: =W13 -> 0 | AA38: =IF(OR(Q13=0,AA13=""),"",AA13)
E39: =E14 -> 두바이)리얼두쫀쿠50g | M39: =M14 -> 60 | Q39: =Q14 -> 52 | T39: =T14 -> 0 | W39: =W14 -> 52 | AA39: =IF(OR(Q14=0,AA14=""),"",AA14) -> 26.11.07
E40: =E15 -> 두바이)리얼아쫀쿠50g | M40: =M15 -> 60 | Q40: =Q15 -> 7 | T40: =T15 -> 0 | W40: =W15 -> 7 | AA40: =IF(OR(Q15=0,AA15=""),"",AA15) -> 26.10.28
E41: =E16 -> 두바이)초코카다이프모찌60g | M41: =M16 -> 48 | Q41: =Q16 -> 10 | T41: =T16 -> 0 | W41: =W16 -> 10 | AA41: 26.08.17
E42: =E17 -> 두바이)카다이프판초콜릿60g(냉장) | M42: =M17 -> 50 | Q42: =Q17 -> 2 | T42: =T17 -> 0 | W42: =W17 -> 2 | AA42: =IF(OR(Q17=0,AA17=""),"",AA17) -> 26.11.03 / 11.10
E43: =E18 -> 두바이)흑임자두쫀쿠50g(냉장) | M43: =M18 -> 60 | Q43: =Q18 -> 0 | T43: =T18 -> 0 | W43: =W18 -> 0 | AA43: =IF(OR(Q18=0,AA18=""),"",AA18)
AA44: =IF(OR(Q19=0,AA19=""),"",AA19)
AA45: =IF(OR(Q20=0,AA20=""),"",AA20)
B47: =B22 -> 총수량 | M47: =M22 -> 71
B48: =B23 -> 3자물류 (더원물류) 담당자 박병선이사 010-4448-1456 | W48: =W23 -> 인천광역시 서구 북항로120번길 55, 청라로지스틱스센터3, 9층 02)437-0500

Sheet 평택 (16)
B1: 평택2(저온)
B2: 거 래 명 세 표 (공급받는자 보관용)
B4: 공 급 받 는 자 | C4: 등록번호 | Q4: 공 급 자 | R4: 등록번호 | V4: 206-86-55878
C6: 상 호 (법인명) | G6: (이마트24) | L6: 평택센터(저온) | R6: 상 호 (법인명) | V6: ㈜ 대광푸드 | AB6: 성명 | AD6: 한대훈
C8: 사업장 주 소 | G8: 경기도 평택시 진위면 마산8로10, 진위물류센터 창고동 1층 | R8: 사업장 주 소 | V8: 서울특별시 광진구 천호대로130길 22(구의동,필하임상가1호 에이호)
C10: 합계금액 (VAT포함) | R10: 업 태 | V10: 도소매 | AB10: 종목 | AD10: 빵,떡,과자류 외
B12: 년 | C12: 월 | D12: 일 | E12: 품 목 | M12: 입수 | Q12: 총수량 | T12: 박스 | W12: 낱개수량 | AA12: 비고
B13: ='원주(날짜변경!!)'!$B$13 -> 46307 | E13: 대광)생초코파이60g(냉장) | M13: 18 | Q13: =IFERROR(VLOOKUP($B$1,'대광피벗(재고)'!A:CF,2,FALSE),0) -> 0 | T13: =IFERROR(ROUNDDOWN(Q13/M13,0),"") -> 0 | W13: =IFERROR(Q13-(T13*M13),"") -> 0 | AA13: 26.09.28
E14: 두바이)리얼두쫀쿠50g | M14: 60 | Q14: =IFERROR(VLOOKUP($B$1,'대광피벗(재고)'!$A$1:$AC$119,3,FALSE),0) -> 20 | T14: =IFERROR(ROUNDDOWN(Q14/M14,0),"") -> 0 | W14: =IFERROR(Q14-(T14*M14),"") -> 20 | AA14: 26.11.07
E15: 두바이)리얼아쫀쿠50g | M15: 60 | Q15: =IFERROR(VLOOKUP($B$1,'대광피벗(재고)'!A:CF,4,FALSE),0) -> 5 | T15: =IFERROR(ROUNDDOWN(Q15/M15,0),"") -> 0 | W15: =IFERROR(Q15-(T15*M15),"") -> 5 | AA15: 26.10.28
E16: 두바이)초코카다이프모찌60g | M16: 48 | Q16: =IFERROR(VLOOKUP($B$1,'대광피벗(재고)'!A:CF,5,FALSE),0) -> 1 | T16: =IFERROR(ROUNDDOWN(Q16/M16,0),"") -> 0 | W16: =IFERROR(Q16-(T16*M16),"") -> 1 | AA16: 26.10.28
E17: 두바이)카다이프판초콜릿60g(냉장) | M17: 50 | Q17: =IFERROR(VLOOKUP($B$1,'대광피벗(재고)'!A:CF,6,FALSE),0) -> 0 | T17: =IFERROR(ROUNDDOWN(Q17/M17,0),"") -> 0 | W17: =IFERROR(Q17-(T17*M17),"") -> 0 | AA17: 26.11.03 / 11.10
E18: 두바이)흑임자두쫀쿠50g(냉장) | M18: 60 | Q18: =IFERROR(VLOOKUP($B$1,'대광피벗(재고)'!A:CF,7,FALSE),0) -> 3 | T18: =IFERROR(ROUNDDOWN(Q18/M18,0),"") -> 0 | W18: =IFERROR(Q18-(T18*M18),"") -> 3 | AA18: 26.11.07
W20: =IFERROR(Q20-(T20*M20),"") -> 0
B22: 총수량 | M22: =SUM(Q13:S21) -> 29
B23: 3자물류 (더원물류) 담당자 박병선이사 010-4448-1456 | W23: 경기도 평택시 진위면 마산8로10, 진위물류센터 창고동 1층 강민구 대리 031-663-9260
B27: 거 래 명 세 표 (공급자 보관용)
B29: 공 급 받 는 자 | C29: =C4 -> 등록번호 | Q29: 공 급 자 | R29: 등록번호 | V29: =V4 -> 206-86-55878
C31: =C6 -> 상 호 (법인명) | G31: =G6 -> (이마트24) | L31: =L6 -> 평택센터(저온) | R31: 상 호 (법인명) | V31: =V6 -> ㈜ 대광푸드 | AB31: 성 명 | AD31: =AD6 -> 한대훈
C33: 사업장 주 소 | G33: =G8 -> 경기도 평택시 진위면 마산8로10, 진위물류센터 창고동 1층 | R33: 사업장 주 소 | V33: =V8 -> 서울특별시 광진구 천호대로130길 22(구의동,필하임상가1호 에이호)
C35: 합계금액 (VAT포함) | R35: 업 태 | V35: =V10 -> 도소매 | AB35: 종 목 | AD35: =AD10 -> 빵,떡,과자류 외
B37: 년 | C37: 월 | D37: 일 | E37: 품 목 | M37: 입수 | Q37: 총수량 | T37: 박스 | W37: 낱개수량 | AA37: 비고
B38: =B13 -> 46307 | E38: =E13 -> 대광)생초코파이60g(냉장) | M38: =M13 -> 18 | Q38: =Q13 -> 0 | T38: =T13 -> 0 | W38: =IFERROR(Q38-(T38*M38),"") -> 0 | AA38: =IF(OR(Q13=0,AA13=""),"",AA13)
E39: =E14 -> 두바이)리얼두쫀쿠50g | M39: =M14 -> 60 | Q39: =Q14 -> 20 | T39: =T14 -> 0 | W39: =IFERROR(Q39-(T39*M39),"") -> 20 | AA39: =IF(OR(Q14=0,AA14=""),"",AA14) -> 26.11.07
E40: =E15 -> 두바이)리얼아쫀쿠50g | M40: =M15 -> 60 | Q40: =Q15 -> 5 | T40: =T15 -> 0 | W40: =IFERROR(Q40-(T40*M40),"") -> 5 | AA40: =IF(OR(Q15=0,AA15=""),"",AA15) -> 26.10.28
E41: =E16 -> 두바이)초코카다이프모찌60g | M41: =M16 -> 48 | Q41: =Q16 -> 1 | T41: =T16 -> 0 | W41: =IFERROR(Q41-(T41*M41),"") -> 1 | AA41: 26.08.17
E42: =E17 -> 두바이)카다이프판초콜릿60g(냉장) | M42: =M17 -> 50 | Q42: =Q17 -> 0 | T42: =T17 -> 0 | W42: =IFERROR(Q42-(T42*M42),"") -> 0 | AA42: =IF(OR(Q17=0,AA17=""),"",AA17)
E43: =E18 -> 두바이)흑임자두쫀쿠50g(냉장) | M43: =M18 -> 60 | Q43: =Q18 -> 3 | T43: =T18 -> 0 | W43: =IFERROR(Q43-(T43*M43),"") -> 3 | AA43: =IF(OR(Q18=0,AA18=""),"",AA18) -> 26.11.07
AA44: =IF(OR(Q19=0,AA19=""),"",AA19)
W45: =W20 -> 0 | AA45: =IF(OR(Q20=0,AA20=""),"",AA20)
W46: =W21 -> 0
B47: =B22 -> 총수량 | M47: =M22 -> 29
B48: =B23 -> 3자물류 (더원물류) 담당자 박병선이사 010-4448-1456 | W48: =W23 -> 경기도 평택시 진위면 마산8로10, 진위물류센터 창고동 1층 강민구 대리 031-663-9260

Sheet 포천(16)
B1: 포천2(저온)
B2: 거 래 명 세 표 (공급받는자 보관용)
B4: 공 급 받 는 자 | C4: 등록번호 | Q4: 공 급 자 | R4: 등록번호 | V4: 206-86-55878
C6: 상 호 (법인명) | G6: (이마트24) | L6: 포천센터(저온) | R6: 상 호 (법인명) | V6: ㈜ 대광푸드 | AB6: 성명 | AD6: 한대훈
C8: 사업장 주 소 | G8: 경기도 포천시 설운동 477,B2F | R8: 사업장 주 소 | V8: 서울특별시 광진구 천호대로130길 22(구의동,필하임상가1호 에이호)
C10: 합계금액 (VAT포함) | R10: 업 태 | V10: 도소매 | AB10: 종목 | AD10: 빵,떡,과자류 외
B12: 년 | C12: 월 | D12: 일 | E12: 품 목 | M12: 입수 | Q12: 총수량 | T12: 박스 | W12: 낱개수량 | AA12: 비고
B13: ='원주(날짜변경!!)'!$B$13 -> 46307 | E13: 대광)생초코파이60g(냉장) | M13: 18 | Q13: =IFERROR(VLOOKUP($B$1,'대광피벗(재고)'!A:CF,2,FALSE),0) -> 0 | T13: =IFERROR(ROUNDDOWN(Q13/M13,0),"") -> 0 | W13: =IFERROR(Q13-(T13*M13),"") -> 0 | AA13: 26.09.28
E14: 두바이)리얼두쫀쿠50g | M14: 60 | Q14: =IFERROR(VLOOKUP($B$1,'대광피벗(재고)'!$A$1:$AC$119,3,FALSE),0) -> 119 | T14: =IFERROR(ROUNDDOWN(Q14/M14,0),"") -> 1 | W14: =IFERROR(Q14-(T14*M14),"") -> 59 | AA14: 26.11.07
E15: 두바이)리얼아쫀쿠50g | M15: 60 | Q15: =IFERROR(VLOOKUP($B$1,'대광피벗(재고)'!A:CF,4,FALSE),0) -> 13 | T15: =IFERROR(ROUNDDOWN(Q15/M15,0),"") -> 0 | W15: =IFERROR(Q15-(T15*M15),"") -> 13 | AA15: 26.10.28
E16: 두바이)초코카다이프모찌60g | M16: 48 | Q16: =IFERROR(VLOOKUP($B$1,'대광피벗(재고)'!A:CF,5,FALSE),0) -> 25 | T16: =IFERROR(ROUNDDOWN(Q16/M16,0),"") -> 0 | W16: =IFERROR(Q16-(T16*M16),"") -> 25 | AA16: 26.10.28
E17: 두바이)카다이프판초콜릿60g(냉장) | M17: 50 | Q17: =IFERROR(VLOOKUP($B$1,'대광피벗(재고)'!A:CF,6,FALSE),0) -> 10 | T17: =IFERROR(ROUNDDOWN(Q17/M17,0),"") -> 0 | W17: =IFERROR(Q17-(T17*M17),"") -> 10 | AA17: 26.11.03 / 11.10
E18: 두바이)흑임자두쫀쿠50g(냉장) | M18: 60 | Q18: =IFERROR(VLOOKUP($B$1,'대광피벗(재고)'!A:CF,7,FALSE),0) -> 2 | T18: =IFERROR(ROUNDDOWN(Q18/M18,0),"") -> 0 | W18: =IFERROR(Q18-(T18*M18),"") -> 2 | AA18: 26.11.07
B22: 총수량 | M22: =SUM(Q13:S21) -> 169
B23: 3자물류 (더원물류) 담당자 박병선이사 010-4448-1456 | W23: 경기도 포천시 설운동 477,B2F 031-543-2486
B27: 거 래 명 세 표 (공급자 보관용)
B29: 공 급 받 는 자 | C29: =C4 -> 등록번호 | Q29: 공 급 자 | R29: 등록번호 | V29: =V4 -> 206-86-55878
C31: =C6 -> 상 호 (법인명) | G31: =G6 -> (이마트24) | L31: =L6 -> 포천센터(저온) | R31: 상 호 (법인명) | V31: =V6 -> ㈜ 대광푸드 | AB31: 성 명 | AD31: =AD6 -> 한대훈
C33: 사업장 주 소 | G33: =G8 -> 경기도 포천시 설운동 477,B2F | R33: 사업장 주 소 | V33: =V8 -> 서울특별시 광진구 천호대로130길 22(구의동,필하임상가1호 에이호)
C35: 합계금액 (VAT포함) | R35: 업 태 | V35: =V10 -> 도소매 | AB35: 종 목 | AD35: =AD10 -> 빵,떡,과자류 외
B37: 년 | C37: 월 | D37: 일 | E37: 품 목 | M37: 입수 | Q37: 총수량 | T37: 박스 | W37: 낱개수량 | AA37: 비고
B38: =B13 -> 46307 | E38: =E13 -> 대광)생초코파이60g(냉장) | M38: =M13 -> 18 | Q38: =Q13 -> 0 | T38: =T13 -> 0 | W38: =W13 -> 0 | AA38: =IF(OR(Q13=0,AA13=""),"",AA13)
E39: =E14 -> 두바이)리얼두쫀쿠50g | M39: =M14 -> 60 | Q39: =Q14 -> 119 | T39: =T14 -> 1 | W39: =W14 -> 59 | AA39: =IF(OR(Q14=0,AA14=""),"",AA14) -> 26.11.07
E40: =E15 -> 두바이)리얼아쫀쿠50g | M40: =M15 -> 60 | Q40: =Q15 -> 13 | T40: =T15 -> 0 | W40: =W15 -> 13 | AA40: =IF(OR(Q15=0,AA15=""),"",AA15) -> 26.10.28
E41: =E16 -> 두바이)초코카다이프모찌60g | M41: =M16 -> 48 | Q41: =Q16 -> 25 | T41: =T16 -> 0 | W41: =W16 -> 25 | AA41: =IF(OR(Q16=0,AA16=""),"",AA16) -> 26.10.28
E42: =E17 -> 두바이)카다이프판초콜릿60g(냉장) | M42: =M17 -> 50 | Q42: =Q17 -> 10 | T42: =T17 -> 0 | W42: =W17 -> 10 | AA42: =IF(OR(Q17=0,AA17=""),"",AA17) -> 26.11.03 / 11.10
E43: =E18 -> 두바이)흑임자두쫀쿠50g(냉장) | M43: =M18 -> 60 | Q43: =Q18 -> 2 | T43: =T18 -> 0 | W43: =W18 -> 2 | AA43: =IF(OR(Q18=0,AA18=""),"",AA18) -> 26.11.07
AA44: =IF(OR(Q19=0,AA19=""),"",AA19)
AA45: =IF(OR(Q20=0,AA20=""),"",AA20)
B47: =B22 -> 총수량 | M47: =M22 -> 169
B48: =B23 -> 3자물류 (더원물류) 담당자 박병선이사 010-4448-1456 | W48: =W23 -> 경기도 포천시 설운동 477,B2F 031-543-2486

Sheet 양지 (16)
B1: 양지2(저온)
B2: 거 래 명 세 표 (공급받는자 보관용)
B4: 공 급 받 는 자 | C4: 등록번호 | Q4: 공 급 자 | R4: 등록번호 | V4: 206-86-55878
C6: 상 호 (법인명) | G6: (이마트24) | L6: 양지센터(저온) | R6: 상 호 (법인명) | V6: ㈜ 대광푸드 | AB6: 성명 | AD6: 한대훈
C8: 사업장 주 소 | G8: 경기도 용인시 처인구 양지면 제일리 453-7 | R8: 사업장 주 소 | V8: 서울특별시 광진구 천호대로130길 22(구의동,필하임상가1호 에이호)
C10: 합계금액 (VAT포함) | R10: 업 태 | V10: 도소매 | AB10: 종목 | AD10: 빵,떡,과자류 외
B12: 년 | C12: 월 | D12: 일 | E12: 품 목 | M12: 입수 | Q12: 총수량 | T12: 박스 | W12: 낱개수량 | AA12: 비고
B13: ='원주(날짜변경!!)'!$B$13 -> 46307 | E13: 대광)생초코파이60g(냉장) | M13: 18 | Q13: =IFERROR(VLOOKUP($B$1,'대광피벗(재고)'!A:CF,2,FALSE),0) -> 0 | T13: =IFERROR(ROUNDDOWN(Q13/M13,0),"") -> 0 | W13: =IFERROR(Q13-(T13*M13),"") -> 0 | AA13: 26.09.28
E14: 두바이)리얼두쫀쿠50g | M14: 60 | Q14: =IFERROR(VLOOKUP($B$1,'대광피벗(재고)'!$A$1:$AC$119,3,FALSE),0) -> 57 | T14: =IFERROR(ROUNDDOWN(Q14/M14,0),"") -> 0 | W14: =IFERROR(Q14-(T14*M14),"") -> 57 | AA14: 26.11.07
E15: 두바이)리얼아쫀쿠50g | M15: 60 | Q15: =IFERROR(VLOOKUP($B$1,'대광피벗(재고)'!A:CF,4,FALSE),0) -> 5 | T15: =IFERROR(ROUNDDOWN(Q15/M15,0),"") -> 0 | W15: =IFERROR(Q15-(T15*M15),"") -> 5 | AA15: 26.10.28
E16: 두바이)초코카다이프모찌60g | M16: 48 | Q16: =IFERROR(VLOOKUP($B$1,'대광피벗(재고)'!A:CF,5,FALSE),0) -> 2 | T16: =IFERROR(ROUNDDOWN(Q16/M16,0),"") -> 0 | W16: =IFERROR(Q16-(T16*M16),"") -> 2 | AA16: 26.10.28
E17: 두바이)카다이프판초콜릿60g(냉장) | M17: 50 | Q17: =IFERROR(VLOOKUP($B$1,'대광피벗(재고)'!A:CF,6,FALSE),0) -> 1 | T17: =IFERROR(ROUNDDOWN(Q17/M17,0),"") -> 0 | W17: =IFERROR(Q17-(T17*M17),"") -> 1 | AA17: 26.11.03 / 11.10
E18: 두바이)흑임자두쫀쿠50g(냉장) | M18: 60 | Q18: =IFERROR(VLOOKUP($B$1,'대광피벗(재고)'!A:CF,7,FALSE),0) -> 0 | T18: =IFERROR(ROUNDDOWN(Q18/M18,0),"") -> 0 | W18: =IFERROR(Q18-(T18*M18),"") -> 0 | AA18: 26.11.07
B22: 총수량 | M22: =SUM(Q13:S21) -> 65
B23: 3자물류 (더원물류) 담당자 박병선이사 010-4448-1456 | W23: 경기도 용인시 처인구 양지면 제일리 453-7 박영범 주임 031-8027-2080
B27: 거 래 명 세 표 (공급자 보관용)
B29: 공 급 받 는 자 | C29: =C4 -> 등록번호 | Q29: 공 급 자 | R29: 등록번호 | V29: =V4 -> 206-86-55878
C31: =C6 -> 상 호 (법인명) | G31: =G6 -> (이마트24) | L31: =L6 -> 양지센터(저온) | R31: 상 호 (법인명) | V31: =V6 -> ㈜ 대광푸드 | AB31: 성 명 | AD31: =AD6 -> 한대훈
C33: 사업장 주 소 | G33: =G8 -> 경기도 용인시 처인구 양지면 제일리 453-7 | R33: 사업장 주 소 | V33: =V8 -> 서울특별시 광진구 천호대로130길 22(구의동,필하임상가1호 에이호)
C35: 합계금액 (VAT포함) | R35: 업 태 | V35: =V10 -> 도소매 | AB35: 종 목 | AD35: =AD10 -> 빵,떡,과자류 외
B37: 년 | C37: 월 | D37: 일 | E37: 품 목 | M37: 입수 | Q37: 총수량 | T37: 박스 | W37: 낱개수량 | AA37: 비고
B38: =B13 -> 46307 | E38: =E13 -> 대광)생초코파이60g(냉장) | M38: =M13 -> 18 | Q38: =Q13 -> 0 | T38: =T13 -> 0 | W38: =W13 -> 0 | AA38: =IF(OR(Q13=0,AA13=""),"",AA13)
E39: =E14 -> 두바이)리얼두쫀쿠50g | M39: =M14 -> 60 | Q39: =Q14 -> 57 | T39: =T14 -> 0 | W39: =W14 -> 57 | AA39: =IF(OR(Q14=0,AA14=""),"",AA14) -> 26.11.07
E40: =E15 -> 두바이)리얼아쫀쿠50g | M40: =M15 -> 60 | Q40: =Q15 -> 5 | T40: =T15 -> 0 | W40: =W15 -> 5 | AA40: =IF(OR(Q15=0,AA15=""),"",AA15) -> 26.10.28
E41: =E16 -> 두바이)초코카다이프모찌60g | M41: =M16 -> 48 | Q41: =Q16 -> 2 | T41: =T16 -> 0 | W41: =W16 -> 2 | AA41: =IF(OR(Q16=0,AA16=""),"",AA16) -> 26.10.28
E42: =E17 -> 두바이)카다이프판초콜릿60g(냉장) | M42: =M17 -> 50 | Q42: =Q17 -> 1 | T42: =T17 -> 0 | W42: =W17 -> 1 | AA42: =IF(OR(Q17=0,AA17=""),"",AA17) -> 26.11.03 / 11.10
E43: =E18 -> 두바이)흑임자두쫀쿠50g(냉장) | M43: =M18 -> 60 | Q43: =Q18 -> 0 | T43: =T18 -> 0 | W43: =W18 -> 0 | AA43: =IF(OR(Q18=0,AA18=""),"",AA18)
AA44: =IF(OR(Q19=0,AA19=""),"",AA19)
AA45: =IF(OR(Q20=0,AA20=""),"",AA20)
AA46: =IF(OR(Q21=0,AA21=""),"",AA21)
B47: =B22 -> 총수량 | M47: =M22 -> 65
B48: =B23 -> 3자물류 (더원물류) 담당자 박병선이사 010-4448-1456 | W48: =W23 -> 경기도 용인시 처인구 양지면 제일리 453-7 박영범 주임 031-8027-2080

Sheet 영진베이커리
A1: 10/12 | B1: 열 레이블
A2: 행 레이블 | B2: 성수310)우유사르르생크림빵130g(냉장) | C2: 성수310)초코칩쿠키바이츠80g | D2: 성수310)칸탈로프멜론사르르크림빵130g(냉장) | E2: 성수310)홋카이도푸딩사르르크림빵125g(냉장) | F2: 성수310)홋카이도푸딩크림카스테라130g(냉장) | G2: 총합계
A3: 원주2(저온) | B3: 33 | C3: 16 | D3: 4 | E3: 31 | F3: 19
A4: 김해2(저온) | B4: 60 | C4: 29 | D4: 17 | E4: 54 | F4: 27
A5: 양산2(저온) | B5: 120 | C5: 67 | D5: 36 | E5: 78 | F5: 58
A6: 세종2(저온) | B6: 115 | C6: 42 | D6: 45 | E6: 119 | F6: 87
A7: 장성2(저온) | B7: 102 | C7: 54 | D7: 32 | E7: 78 | F7: 70
A8: 김천2(저온) | B8: 69 | C8: 22 | D8: 12 | E8: 39 | F8: 34
A9: 경산2(저온) | B9: 51 | C9: 18 | D9: 13 | E9: 46 | F9: 23
A10: 화성2(저온) | B10: 79 | C10: 16 | D10: 19 | E10: 61 | F10: 47
A11: 청라2(저온) | B11: 108 | C11: 56 | D11: 29 | E11: 101 | F11: 70
A12: 평택2(저온) | B12: 55 | C12: 29 | D12: 19 | E12: 37 | F12: 23
A13: 포천2(저온) | B13: 178 | C13: 104 | D13: 50 | E13: 144 | F13: 108
A14: 양지2(저온) | B14: 149 | C14: 51 | D14: 54 | E14: 157 | F14: 89
A15: 총합계 | B15: 1119 | C15: 504 | D15: 330 | E15: 945 | F15: 655

Sheet 원주 (26)
B1: 원주2(저온)
B2: 거 래 명 세 표 (공급받는자 보관용)
B4: 공 급 받 는 자 | C4: 등록번호 | Q4: 공 급 자 | R4: 등록번호 | V4: 698-81-00072
C6: 상 호 (법인명) | G6: (이마트24) | L6: 원주센터(저온) | R6: 상 호 (법인명) | V6: ㈜영진베이커리 | AB6: 성명 | AD6: 오윤규
C8: 사업장 주 소 | G8: 강원특별자치도 원주시 호저면 주산리 298,1층 | R8: 사업장 주 소 | V8: 경기도 이천시 백사면 원적로970번길 86-29
C10: 합계금액 (VAT포함) | R10: 업 태 | V10: 제조업 | AB10: 종목 | AD10: 제과, 제빵
B12: 년 | C12: 월 | D12: 일 | E12: 품 목 | M12: 입수 | Q12: 총수량 | T12: 박스 | W12: 낱개수량 | AA12: 비고
B13: ='원주(날짜변경!!)'!$B$13 -> 46307 | E13: 성수310)우유사르르생크림빵130g(냉장) | M13: 24 | Q13: =IFERROR(VLOOKUP($B$1,영진베이커리!A:CX,2,FALSE),0) -> 33 | T13: =IFERROR(ROUNDDOWN(Q13/M13,0),"") -> 1 | W13: =IFERROR(Q13-(T13*M13),"") -> 9 | AA13: =B13+4 -> 46311
E14: 성수310)초코칩쿠키바이츠80g | M14: 40 | Q14: =IFERROR(VLOOKUP($B$1,영진베이커리!A:CX,3,FALSE),0) -> 16 | T14: =IFERROR(ROUNDDOWN(Q14/M14,0),"") -> 0 | W14: =IFERROR(Q14-(T14*M14),"") -> 16 | AA14: =$B$13+89 -> 46396
E15: 성수310)칸탈로프멜론사르르크림빵130g(냉장) | M15: 24 | Q15: =IFERROR(VLOOKUP($B$1,영진베이커리!A:CX,4,FALSE),0) -> 4 | T15: =IFERROR(ROUNDDOWN(Q15/M15,0),"") -> 0 | W15: =IFERROR(Q15-(T15*M15),"") -> 4 | AA15: =B13+4 -> 46311
E16: 성수310)홋카이도푸딩사르르크림빵125g(냉장) | M16: 24 | Q16: =IFERROR(VLOOKUP($B$1,영진베이커리!A:CX,5,FALSE),0) -> 31 | T16: =IFERROR(ROUNDDOWN(Q16/M16,0),"") -> 1 | W16: =IFERROR(Q16-(T16*M16),"") -> 7 | AA16: =B13+4 -> 46311
E17: 성수310)홋카이도푸딩크림카스테라130g(냉장) | M17: 24 | Q17: =IFERROR(VLOOKUP($B$1,영진베이커리!A:CX,6,FALSE),0) -> 19 | T17: =IFERROR(ROUNDDOWN(Q17/M17,0),"") -> 0 | W17: =IFERROR(Q17-(T17*M17),"") -> 19 | AA17: =B13+4 -> 46311
B19: 총수량 | M19: =SUM(Q13:S18) -> 103
B20: 3자물류 (더원물류) 담당자 박병선이사 010-4448-1456 | W20: =G8 -> 강원특별자치도 원주시 호저면 주산리 298,1층
B24: 거 래 명 세 표 (공급자 보관용)
B26: 공 급 받 는 자 | C26: =C4 -> 등록번호 | Q26: 공 급 자 | R26: 등록번호 | V26: =V4 -> 698-81-00072
C28: =C6 -> 상 호 (법인명) | G28: =G6 -> (이마트24) | L28: =L6 -> 원주센터(저온) | R28: 상 호 (법인명) | V28: =V6 -> ㈜영진베이커리 | AB28: 성 명 | AD28: =AD6 -> 오윤규
C30: 사업장 주 소 | G30: =G8 -> 강원특별자치도 원주시 호저면 주산리 298,1층 | R30: 사업장 주 소 | V30: =V8 -> 경기도 이천시 백사면 원적로970번길 86-29
C32: 합계금액 (VAT포함) | R32: 업 태 | V32: =V10 -> 제조업 | AB32: 종 목 | AD32: =AD10 -> 제과, 제빵
B34: 년 | C34: 월 | D34: 일 | E34: 품 목 | M34: 입수 | Q34: 총수량 | T34: 박스 | W34: 낱개수량 | AA34: 비고
B35: =B13 -> 46307 | E35: =E13 -> 성수310)우유사르르생크림빵130g(냉장) | M35: =M13 -> 24 | Q35: =Q13 -> 33 | T35: =T13 -> 1 | W35: =W13 -> 9 | AA35: =AA13 -> 46311
E36: =E14 -> 성수310)초코칩쿠키바이츠80g | M36: =M14 -> 40 | Q36: =Q14 -> 16 | T36: =T14 -> 0 | W36: =W14 -> 16 | AA36: =AA14 -> 46396
E37: =E15 -> 성수310)칸탈로프멜론사르르크림빵130g(냉장) | M37: =M15 -> 24 | Q37: =Q15 -> 4 | T37: =T15 -> 0 | W37: =W15 -> 4 | AA37: =AA15 -> 46311
E38: =E16 -> 성수310)홋카이도푸딩사르르크림빵125g(냉장) | M38: =M16 -> 24 | Q38: =Q16 -> 31 | T38: =T16 -> 1 | W38: =W16 -> 7 | AA38: =AA16 -> 46311
E39: =E17 -> 성수310)홋카이도푸딩크림카스테라130g(냉장) | M39: =M17 -> 24 | Q39: =Q17 -> 19 | T39: =T17 -> 0 | W39: =W17 -> 19 | AA39: =AA17 -> 46311
B41: =B19 -> 총수량 | M41: =M19 -> 103
B42: =B20 -> 3자물류 (더원물류) 담당자 박병선이사 010-4448-1456 | W42: =W20 -> 강원특별자치도 원주시 호저면 주산리 298,1층

Sheet 김해 (28)
B1: 김해2(저온)
B2: 거 래 명 세 표 (공급받는자 보관용)
B4: 공 급 받 는 자 | C4: 등록번호 | Q4: 공 급 자 | R4: 등록번호 | V4: 698-81-00072
C6: 상 호 (법인명) | G6: (이마트24) | L6: 김해센터(저온) | R6: 상 호 (법인명) | V6: ㈜영진베이커리 | AB6: 성명 | AD6: 오윤규
C8: 사업장 주 소 | G8: 경상남도 김해시 진례면 테크노밸리로 193-28 | R8: 사업장 주 소 | V8: 경기도 이천시 백사면 원적로970번길 86-29
C10: 합계금액 (VAT포함) | R10: 업 태 | V10: 제조업 | AB10: 종목 | AD10: 제과, 제빵
B12: 년 | C12: 월 | D12: 일 | E12: 품 목 | M12: 입수 | Q12: 총수량 | T12: 박스 | W12: 낱개수량 | AA12: 비고
B13: ='원주(날짜변경!!)'!$B$13 -> 46307 | E13: 성수310)우유사르르생크림빵130g(냉장) | M13: 24 | Q13: =IFERROR(VLOOKUP($B$1,영진베이커리!A:CX,2,FALSE),0) -> 60 | T13: =IFERROR(ROUNDDOWN(Q13/M13,0),"") -> 2 | W13: =IFERROR(Q13-(T13*M13),"") -> 12 | AA13: =B13+4 -> 46311
E14: 성수310)초코칩쿠키바이츠80g | M14: 40 | Q14: =IFERROR(VLOOKUP($B$1,영진베이커리!A:CX,3,FALSE),0) -> 29 | T14: =IFERROR(ROUNDDOWN(Q14/M14,0),"") -> 0 | W14: =IFERROR(Q14-(T14*M14),"") -> 29 | AA14: =$B$13+89 -> 46396
E15: 성수310)칸탈로프멜론사르르크림빵130g(냉장) | M15: 24 | Q15: =IFERROR(VLOOKUP($B$1,영진베이커리!A:CX,4,FALSE),0) -> 17 | T15: =IFERROR(ROUNDDOWN(Q15/M15,0),"") -> 0 | W15: =IFERROR(Q15-(T15*M15),"") -> 17 | AA15: =B13+4 -> 46311
E16: 성수310)홋카이도푸딩사르르크림빵125g(냉장) | M16: 24 | Q16: =IFERROR(VLOOKUP($B$1,영진베이커리!A:CX,5,FALSE),0) -> 54 | T16: =IFERROR(ROUNDDOWN(Q16/M16,0),"") -> 2 | W16: =IFERROR(Q16-(T16*M16),"") -> 6 | AA16: =B13+4 -> 46311
E17: 성수310)홋카이도푸딩크림카스테라130g(냉장) | M17: 24 | Q17: =IFERROR(VLOOKUP($B$1,영진베이커리!A:CX,6,FALSE),0) -> 27 | T17: =IFERROR(ROUNDDOWN(Q17/M17,0),"") -> 1 | W17: =IFERROR(Q17-(T17*M17),"") -> 3 | AA17: =B13+4 -> 46311
B19: 총수량 | M19: =SUM(Q13:S18) -> 187
B20: 3자물류 (더원물류) 담당자 박병선이사 010-4448-1456 | W20: 경상남도 김해시 진례면 테크노밸리로 193-28 TEL 070-4398-2825
B24: 거 래 명 세 표 (공급자 보관용)
B26: 공 급 받 는 자 | C26: =C4 -> 등록번호 | Q26: 공 급 자 | R26: 등록번호 | V26: =V4 -> 698-81-00072
C28: =C6 -> 상 호 (법인명) | G28: =G6 -> (이마트24) | L28: =L6 -> 김해센터(저온) | R28: 상 호 (법인명) | V28: =V6 -> ㈜영진베이커리 | AB28: 성 명 | AD28: =AD6 -> 오윤규
C30: 사업장 주 소 | G30: =G8 -> 경상남도 김해시 진례면 테크노밸리로 193-28 | R30: 사업장 주 소 | V30: =V8 -> 경기도 이천시 백사면 원적로970번길 86-29
C32: 합계금액 (VAT포함) | R32: 업 태 | V32: =V10 -> 제조업 | AB32: 종 목 | AD32: =AD10 -> 제과, 제빵
B34: 년 | C34: 월 | D34: 일 | E34: 품 목 | M34: 입수 | Q34: 총수량 | T34: 박스 | W34: 낱개수량 | AA34: 비고
B35: =B13 -> 46307 | E35: =E13 -> 성수310)우유사르르생크림빵130g(냉장) | M35: =M13 -> 24 | Q35: =Q13 -> 60 | T35: =T13 -> 2 | W35: =W13 -> 12 | AA35: =AA13 -> 46311
E36: =E14 -> 성수310)초코칩쿠키바이츠80g | M36: =M14 -> 40 | Q36: =Q14 -> 29 | T36: =T14 -> 0 | W36: =W14 -> 29 | AA36: =AA14 -> 46396
E37: =E15 -> 성수310)칸탈로프멜론사르르크림빵130g(냉장) | M37: =M15 -> 24 | Q37: =Q15 -> 17 | T37: =T15 -> 0 | W37: =W15 -> 17 | AA37: =AA15 -> 46311
E38: =E16 -> 성수310)홋카이도푸딩사르르크림빵125g(냉장) | M38: =M16 -> 24 | Q38: =Q16 -> 54 | T38: =T16 -> 2 | W38: =W16 -> 6 | AA38: =AA16 -> 46311
E39: =E17 -> 성수310)홋카이도푸딩크림카스테라130g(냉장) | M39: =M17 -> 24 | Q39: =Q17 -> 27 | T39: =T17 -> 1 | W39: =W17 -> 3 | AA39: =AA17 -> 46311
B41: =B19 -> 총수량 | M41: =M19 -> 187
B42: =B20 -> 3자물류 (더원물류) 담당자 박병선이사 010-4448-1456 | W42: =W20 -> 경상남도 김해시 진례면 테크노밸리로 193-28 TEL 070-4398-2825

Sheet 양산 (28)
B1: 양산2(저온)
B2: 거 래 명 세 표 (공급받는자 보관용)
B4: 공 급 받 는 자 | C4: 등록번호 | Q4: 공 급 자 | R4: 등록번호 | V4: 698-81-00072
C6: 상 호 (법인명) | G6: (이마트24) | L6: 양산센터(저온) | R6: 상 호 (법인명) | V6: ㈜영진베이커리 | AB6: 성명 | AD6: 오윤규
C8: 사업장 주 소 | G8: 경상남도 양산시 산막공단북3길 25(산막동 313-4) | R8: 사업장 주 소 | V8: 경기도 이천시 백사면 원적로970번길 86-29
C10: 합계금액 (VAT포함) | R10: 업 태 | V10: 제조업 | AB10: 종목 | AD10: 제과, 제빵
B12: 년 | C12: 월 | D12: 일 | E12: 품 목 | M12: 입수 | Q12: 총수량 | T12: 박스 | W12: 낱개수량 | AA12: 비고
B13: ='원주(날짜변경!!)'!$B$13 -> 46307 | E13: 성수310)우유사르르생크림빵130g(냉장) | M13: 24 | Q13: =IFERROR(VLOOKUP($B$1,영진베이커리!A:CX,2,FALSE),0) -> 120 | T13: =IFERROR(ROUNDDOWN(Q13/M13,0),"") -> 5 | W13: =IFERROR(Q13-(T13*M13),"") -> 0 | AA13: =B13+4 -> 46311
E14: 성수310)초코칩쿠키바이츠80g | M14: 40 | Q14: =IFERROR(VLOOKUP($B$1,영진베이커리!A:CX,3,FALSE),0) -> 67 | T14: =IFERROR(ROUNDDOWN(Q14/M14,0),"") -> 1 | W14: =IFERROR(Q14-(T14*M14),"") -> 27 | AA14: =$B$13+89 -> 46396
E15: 성수310)칸탈로프멜론사르르크림빵130g(냉장) | M15: 24 | Q15: =IFERROR(VLOOKUP($B$1,영진베이커리!A:CX,4,FALSE),0) -> 36 | T15: =IFERROR(ROUNDDOWN(Q15/M15,0),"") -> 1 | W15: =IFERROR(Q15-(T15*M15),"") -> 12 | AA15: =B13+4 -> 46311
E16: 성수310)홋카이도푸딩사르르크림빵125g(냉장) | M16: 24 | Q16: =IFERROR(VLOOKUP($B$1,영진베이커리!A:CX,5,FALSE),0) -> 78 | T16: =IFERROR(ROUNDDOWN(Q16/M16,0),"") -> 3 | W16: =IFERROR(Q16-(T16*M16),"") -> 6 | AA16: =B13+4 -> 46311
E17: 성수310)홋카이도푸딩크림카스테라130g(냉장) | M17: 24 | Q17: =IFERROR(VLOOKUP($B$1,영진베이커리!A:CX,6,FALSE),0) -> 58 | T17: =IFERROR(ROUNDDOWN(Q17/M17,0),"") -> 2 | W17: =IFERROR(Q17-(T17*M17),"") -> 10 | AA17: =B13+4 -> 46311
B19: 총수량 | M19: =SUM(Q13:S18) -> 359
B20: 3자물류 (더원물류) 담당자 박병선이사 010-4448-1456 | W20: =G8 -> 경상남도 양산시 산막공단북3길 25(산막동 313-4)
B24: 거 래 명 세 표 (공급자 보관용)
B26: 공 급 받 는 자 | C26: =C4 -> 등록번호 | Q26: 공 급 자 | R26: 등록번호 | V26: =V4 -> 698-81-00072
C28: =C6 -> 상 호 (법인명) | G28: =G6 -> (이마트24) | L28: =L6 -> 양산센터(저온) | R28: 상 호 (법인명) | V28: =V6 -> ㈜영진베이커리 | AB28: 성 명 | AD28: =AD6 -> 오윤규
C30: 사업장 주 소 | G30: =G8 -> 경상남도 양산시 산막공단북3길 25(산막동 313-4) | R30: 사업장 주 소 | V30: =V8 -> 경기도 이천시 백사면 원적로970번길 86-29
C32: 합계금액 (VAT포함) | R32: 업 태 | V32: =V10 -> 제조업 | AB32: 종 목 | AD32: =AD10 -> 제과, 제빵
B34: 년 | C34: 월 | D34: 일 | E34: 품 목 | M34: 입수 | Q34: 총수량 | T34: 박스 | W34: 낱개수량 | AA34: 비고
B35: =B13 -> 46307 | E35: =E13 -> 성수310)우유사르르생크림빵130g(냉장) | M35: =M13 -> 24 | Q35: =Q13 -> 120 | T35: =T13 -> 5 | W35: =W13 -> 0 | AA35: =AA13 -> 46311
E36: =E14 -> 성수310)초코칩쿠키바이츠80g | M36: =M14 -> 40 | Q36: =Q14 -> 67 | T36: =T14 -> 1 | W36: =W14 -> 27 | AA36: =AA14 -> 46396
E37: =E15 -> 성수310)칸탈로프멜론사르르크림빵130g(냉장) | M37: =M15 -> 24 | Q37: =Q15 -> 36 | T37: =T15 -> 1 | W37: =W15 -> 12 | AA37: =AA15 -> 46311
E38: =E16 -> 성수310)홋카이도푸딩사르르크림빵125g(냉장) | M38: =M16 -> 24 | Q38: =Q16 -> 78 | T38: =T16 -> 3 | W38: =W16 -> 6 | AA38: =AA16 -> 46311
E39: =E17 -> 성수310)홋카이도푸딩크림카스테라130g(냉장) | M39: =M17 -> 24 | Q39: =Q17 -> 58 | T39: =T17 -> 2 | W39: =W17 -> 10 | AA39: =AA17 -> 46311
B41: =B19 -> 총수량 | M41: =M19 -> 359
B42: =B20 -> 3자물류 (더원물류) 담당자 박병선이사 010-4448-1456 | W42: =W20 -> 경상남도 양산시 산막공단북3길 25(산막동 313-4)

Sheet 세종 (28)
B1: 세종2(저온)
B2: 거 래 명 세 표 (공급받는자 보관용)
B4: 공 급 받 는 자 | C4: 등록번호 | Q4: 공 급 자 | R4: 등록번호 | V4: 698-81-00072
C6: 상 호 (법인명) | G6: (이마트24) | L6: 세종센터(저온) | R6: 상 호 (법인명) | V6: ㈜영진베이커리 | AB6: 성명 | AD6: 오윤규
C8: 사업장 주 소 | G8: 세종특별자치시 연동면 응암리 925 E동 | R8: 사업장 주 소 | V8: 경기도 이천시 백사면 원적로970번길 86-29
C10: 합계금액 (VAT포함) | R10: 업 태 | V10: 제조업 | AB10: 종목 | AD10: 제과, 제빵
B12: 년 | C12: 월 | D12: 일 | E12: 품 목 | M12: 입수 | Q12: 총수량 | T12: 박스 | W12: 낱개수량 | AA12: 비고
B13: ='원주(날짜변경!!)'!$B$13 -> 46307 | E13: 성수310)우유사르르생크림빵130g(냉장) | M13: 24 | Q13: =IFERROR(VLOOKUP($B$1,영진베이커리!A:CX,2,FALSE),0) -> 115 | T13: =IFERROR(ROUNDDOWN(Q13/M13,0),"") -> 4 | W13: =IFERROR(Q13-(T13*M13),"") -> 19 | AA13: =B13+4 -> 46311
E14: 성수310)초코칩쿠키바이츠80g | M14: 40 | Q14: =IFERROR(VLOOKUP($B$1,영진베이커리!A:CX,3,FALSE),0) -> 42 | T14: =IFERROR(ROUNDDOWN(Q14/M14,0),"") -> 1 | W14: =IFERROR(Q14-(T14*M14),"") -> 2 | AA14: =$B$13+89 -> 46396
E15: 성수310)칸탈로프멜론사르르크림빵130g(냉장) | M15: 24 | Q15: =IFERROR(VLOOKUP($B$1,영진베이커리!A:CX,4,FALSE),0) -> 45 | T15: =IFERROR(ROUNDDOWN(Q15/M15,0),"") -> 1 | W15: =IFERROR(Q15-(T15*M15),"") -> 21 | AA15: =B13+4 -> 46311
E16: 성수310)홋카이도푸딩사르르크림빵125g(냉장) | M16: 24 | Q16: =IFERROR(VLOOKUP($B$1,영진베이커리!A:CX,5,FALSE),0) -> 119 | T16: =IFERROR(ROUNDDOWN(Q16/M16,0),"") -> 4 | W16: =IFERROR(Q16-(T16*M16),"") -> 23 | AA16: =B13+4 -> 46311
E17: 성수310)홋카이도푸딩크림카스테라130g(냉장) | M17: 24 | Q17: =IFERROR(VLOOKUP($B$1,영진베이커리!A:CX,6,FALSE),0) -> 87 | T17: =IFERROR(ROUNDDOWN(Q17/M17,0),"") -> 3 | W17: =IFERROR(Q17-(T17*M17),"") -> 15 | AA17: =B13+4 -> 46311
B19: 총수량 | M19: =SUM(Q13:S18) -> 408
B20: 3자물류 (더원물류) 담당자 박병선이사 010-4448-1456 | W20: 세종특별자치시 연동면 응암리 925 E동 허승현 대리 044-862-4400
B24: 거 래 명 세 표 (공급자 보관용)
B26: 공 급 받 는 자 | C26: =C4 -> 등록번호 | Q26: 공 급 자 | R26: 등록번호 | V26: =V4 -> 698-81-00072
C28: =C6 -> 상 호 (법인명) | G28: =G6 -> (이마트24) | L28: =L6 -> 세종센터(저온) | R28: 상 호 (법인명) | V28: =V6 -> ㈜영진베이커리 | AB28: 성 명 | AD28: =AD6 -> 오윤규
C30: 사업장 주 소 | G30: =G8 -> 세종특별자치시 연동면 응암리 925 E동 | R30: 사업장 주 소 | V30: =V8 -> 경기도 이천시 백사면 원적로970번길 86-29
C32: 합계금액 (VAT포함) | R32: 업 태 | V32: =V10 -> 제조업 | AB32: 종 목 | AD32: =AD10 -> 제과, 제빵
B34: 년 | C34: 월 | D34: 일 | E34: 품 목 | M34: 입수 | Q34: 총수량 | T34: 박스 | W34: 낱개수량 | AA34: 비고
B35: =B13 -> 46307 | E35: =E13 -> 성수310)우유사르르생크림빵130g(냉장) | M35: =M13 -> 24 | Q35: =Q13 -> 115 | T35: =T13 -> 4 | W35: =W13 -> 19 | AA35: =AA13 -> 46311
E36: =E14 -> 성수310)초코칩쿠키바이츠80g | M36: =M14 -> 40 | Q36: =Q14 -> 42 | T36: =T14 -> 1 | W36: =W14 -> 2 | AA36: =AA14 -> 46396
E37: =E15 -> 성수310)칸탈로프멜론사르르크림빵130g(냉장) | M37: =M15 -> 24 | Q37: =Q15 -> 45 | T37: =T15 -> 1 | W37: =W15 -> 21 | AA37: =AA15 -> 46311
E38: =E16 -> 성수310)홋카이도푸딩사르르크림빵125g(냉장) | M38: =M16 -> 24 | Q38: =Q16 -> 119 | T38: =T16 -> 4 | W38: =W16 -> 23 | AA38: =AA16 -> 46311
E39: =E17 -> 성수310)홋카이도푸딩크림카스테라130g(냉장) | M39: =M17 -> 24 | Q39: =Q17 -> 87 | T39: =T17 -> 3 | W39: =W17 -> 15 | AA39: =AA17 -> 46311
B41: =B19 -> 총수량 | M41: =M19 -> 408
B42: =B20 -> 3자물류 (더원물류) 담당자 박병선이사 010-4448-1456 | W42: =W20 -> 세종특별자치시 연동면 응암리 925 E동 허승현 대리 044-862-4400

Sheet 장성 (35)
B1: 장성2(저온)
B2: 거 래 명 세 표 (공급받는자 보관용)
B4: 공 급 받 는 자 | C4: 등록번호 | Q4: 공 급 자 | R4: 등록번호 | V4: 698-81-00072
C6: 상 호 (법인명) | G6: (이마트24) | L6: 장성센터(저온) | R6: 상 호 (법인명) | V6: ㈜영진베이커리 | AB6: 성명 | AD6: 오윤규
C8: 사업장 주 소 | G8: 전라남도 장성군 황룡면 황룡리 44-2 2층 | R8: 사업장 주 소 | V8: 경기도 이천시 백사면 원적로970번길 86-29
C10: 합계금액 (VAT포함) | R10: 업 태 | V10: 제조업 | AB10: 종목 | AD10: 제과, 제빵
B12: 년 | C12: 월 | D12: 일 | E12: 품 목 | M12: 입수 | Q12: 총수량 | T12: 박스 | W12: 낱개수량 | AA12: 비고
B13: ='원주(날짜변경!!)'!$B$13 -> 46307 | E13: 성수310)우유사르르생크림빵130g(냉장) | M13: 24 | Q13: =IFERROR(VLOOKUP($B$1,영진베이커리!A:CX,2,FALSE),0) -> 102 | T13: =IFERROR(ROUNDDOWN(Q13/M13,0),"") -> 4 | W13: =IFERROR(Q13-(T13*M13),"") -> 6 | AA13: =B13+4 -> 46311
E14: 성수310)초코칩쿠키바이츠80g | M14: 40 | Q14: =IFERROR(VLOOKUP($B$1,영진베이커리!A:CX,3,FALSE),0) -> 54 | T14: =IFERROR(ROUNDDOWN(Q14/M14,0),"") -> 1 | W14: =IFERROR(Q14-(T14*M14),"") -> 14 | AA14: =$B$13+89 -> 46396
E15: 성수310)칸탈로프멜론사르르크림빵130g(냉장) | M15: 24 | Q15: =IFERROR(VLOOKUP($B$1,영진베이커리!A:CX,4,FALSE),0) -> 32 | T15: =IFERROR(ROUNDDOWN(Q15/M15,0),"") -> 1 | W15: =IFERROR(Q15-(T15*M15),"") -> 8 | AA15: =B13+4 -> 46311
E16: 성수310)홋카이도푸딩사르르크림빵125g(냉장) | M16: 24 | Q16: =IFERROR(VLOOKUP($B$1,영진베이커리!A:CX,5,FALSE),0) -> 78 | T16: =IFERROR(ROUNDDOWN(Q16/M16,0),"") -> 3 | W16: =IFERROR(Q16-(T16*M16),"") -> 6 | AA16: =B13+4 -> 46311
E17: 성수310)홋카이도푸딩크림카스테라130g(냉장) | M17: 24 | Q17: =IFERROR(VLOOKUP($B$1,영진베이커리!A:CX,6,FALSE),0) -> 70 | T17: =IFERROR(ROUNDDOWN(Q17/M17,0),"") -> 2 | W17: =IFERROR(Q17-(T17*M17),"") -> 22 | AA17: =B13+4 -> 46311
B19: 총수량 | M19: =SUM(Q13:S18) -> 336
B20: 3자물류 (더원물류) 담당자 박병선이사 010-4448-1456 | W20: =G8 -> 전라남도 장성군 황룡면 황룡리 44-2 2층
B24: 거 래 명 세 표 (공급자 보관용)
B26: 공 급 받 는 자 | C26: =C4 -> 등록번호 | Q26: 공 급 자 | R26: 등록번호 | V26: =V4 -> 698-81-00072
C28: =C6 -> 상 호 (법인명) | G28: =G6 -> (이마트24) | L28: =L6 -> 장성센터(저온) | R28: 상 호 (법인명) | V28: =V6 -> ㈜영진베이커리 | AB28: 성 명 | AD28: =AD6 -> 오윤규
C30: 사업장 주 소 | G30: =G8 -> 전라남도 장성군 황룡면 황룡리 44-2 2층 | R30: 사업장 주 소 | V30: =V8 -> 경기도 이천시 백사면 원적로970번길 86-29
C32: 합계금액 (VAT포함) | R32: 업 태 | V32: =V10 -> 제조업 | AB32: 종 목 | AD32: =AD10 -> 제과, 제빵
B34: 년 | C34: 월 | D34: 일 | E34: 품 목 | M34: 입수 | Q34: 총수량 | T34: 박스 | W34: 낱개수량 | AA34: 비고
B35: =B13 -> 46307 | E35: =E13 -> 성수310)우유사르르생크림빵130g(냉장) | M35: =M13 -> 24 | Q35: =Q13 -> 102 | T35: =T13 -> 4 | W35: =W13 -> 6 | AA35: =AA13 -> 46311
E36: =E14 -> 성수310)초코칩쿠키바이츠80g | M36: =M14 -> 40 | Q36: =Q14 -> 54 | T36: =T14 -> 1 | W36: =W14 -> 14 | AA36: =AA14 -> 46396
E37: =E15 -> 성수310)칸탈로프멜론사르르크림빵130g(냉장) | M37: =M15 -> 24 | Q37: =Q15 -> 32 | T37: =T15 -> 1 | W37: =W15 -> 8 | AA37: =AA15 -> 46311
E38: =E16 -> 성수310)홋카이도푸딩사르르크림빵125g(냉장) | M38: =M16 -> 24 | Q38: =Q16 -> 78 | T38: =T16 -> 3 | W38: =W16 -> 6 | AA38: =AA16 -> 46311
E39: =E17 -> 성수310)홋카이도푸딩크림카스테라130g(냉장) | M39: =M17 -> 24 | Q39: =Q17 -> 70 | T39: =T17 -> 2 | W39: =W17 -> 22 | AA39: =AA17 -> 46311
B41: =B19 -> 총수량 | M41: =M19 -> 336
B42: =B20 -> 3자물류 (더원물류) 담당자 박병선이사 010-4448-1456 | W42: =W20 -> 전라남도 장성군 황룡면 황룡리 44-2 2층

Sheet 김천 (27)
B1: 김천2(저온)
B2: 거 래 명 세 표 (공급받는자 보관용)
B4: 공 급 받 는 자 | C4: 등록번호 | Q4: 공 급 자 | R4: 등록번호 | V4: 698-81-00072
C6: 상 호 (법인명) | G6: (이마트24) | L6: 김천센터(저온) | R6: 상 호 (법인명) | V6: ㈜영진베이커리 | AB6: 성명 | AD6: 오윤규
C8: 사업장 주 소 | G8: 경상북도 김천시 어모면 옥율리 212 | R8: 사업장 주 소 | V8: 경기도 이천시 백사면 원적로970번길 86-29
C10: 합계금액 (VAT포함) | R10: 업 태 | V10: 제조업 | AB10: 종목 | AD10: 제과, 제빵
B12: 년 | C12: 월 | D12: 일 | E12: 품 목 | M12: 입수 | Q12: 총수량 | T12: 박스 | W12: 낱개수량 | AA12: 비고
B13: ='원주(날짜변경!!)'!$B$13 -> 46307 | E13: 성수310)우유사르르생크림빵130g(냉장) | M13: 24 | Q13: =IFERROR(VLOOKUP($B$1,영진베이커리!A:CX,2,FALSE),0) -> 69 | T13: =IFERROR(ROUNDDOWN(Q13/M13,0),"") -> 2 | W13: =IFERROR(Q13-(T13*M13),"") -> 21 | AA13: =B13+4 -> 46311
E14: 성수310)초코칩쿠키바이츠80g | M14: 40 | Q14: =IFERROR(VLOOKUP($B$1,영진베이커리!A:CX,3,FALSE),0) -> 22 | T14: =IFERROR(ROUNDDOWN(Q14/M14,0),"") -> 0 | W14: =IFERROR(Q14-(T14*M14),"") -> 22 | AA14: =$B$13+89 -> 46396
E15: 성수310)칸탈로프멜론사르르크림빵130g(냉장) | M15: 24 | Q15: =IFERROR(VLOOKUP($B$1,영진베이커리!A:CX,4,FALSE),0) -> 12 | T15: =IFERROR(ROUNDDOWN(Q15/M15,0),"") -> 0 | W15: =IFERROR(Q15-(T15*M15),"") -> 12 | AA15: =B13+4 -> 46311
E16: 성수310)홋카이도푸딩사르르크림빵125g(냉장) | M16: 24 | Q16: =IFERROR(VLOOKUP($B$1,영진베이커리!A:CX,5,FALSE),0) -> 39 | T16: =IFERROR(ROUNDDOWN(Q16/M16,0),"") -> 1 | W16: =IFERROR(Q16-(T16*M16),"") -> 15 | AA16: =B13+4 -> 46311
