Workbook

Sheet 검수장
A1: 검수 리스트
A2: 행 레이블 | B2: 껍데기 | C2: 돼지갈비 | D2: 직화불닭발 | E2: 수제치즈돈까스 | F2: 족발 | G2: 반반족보세트 | H2: 소시지콘 치즈그라탕 | I2: 샐만사)리코타닭가슴살에그 | J2: 쉬림프레몬콥샐러드 | K2: 치킨에그콥 샐러드 | L2: 케이준치킨에그샐러드 | M2: 모서리족발 (냉장) | N2: 카카오)라이언초코케이크 | O2: 직화)모둠햄부대찌개 | P2: 직화)스팸김치찌개 | Q2: 진가쭈꾸미 짬뽕 | R2: 총합계
A3: VV52 (주)지에스리테일남양주일배 | B3: =VLOOKUP(A:A,#REF!,2,0) -> #REF! | C3: =VLOOKUP(A:A,#REF!,3,0) -> #REF! | D3: =VLOOKUP(A:A,#REF!,4,0) -> #REF! | E3: =VLOOKUP(A:A,#REF!,5,0) -> #REF! | F3: =VLOOKUP(A:A,#REF!,2,0) -> #REF! | G3: =VLOOKUP(A:A,#REF!,3,0) -> #REF! | H3: =VLOOKUP(A:A,#REF!,4,0) -> #REF! | I3: =VLOOKUP(A3,#REF!,2,0) -> #REF! | J3: =VLOOKUP(A3,#REF!,3,0) -> #REF! | K3: =VLOOKUP(A:A,#REF!,4,0) -> #REF! | L3: =VLOOKUP(A3,#REF!,5,0) -> #REF! | M3: =VLOOKUP(A:A,#REF!,2,0) -> #REF! | N3: =VLOOKUP(A:A,#REF!,3,0) -> #REF! | O3: =VLOOKUP(A:A,#REF!,2,0) -> #REF! | P3: =VLOOKUP(A:A,#REF!,2,0) -> #REF! | Q3: =VLOOKUP(A:A,#REF!,2,0) -> #REF! | R3: =SUM(B3:Q3) -> #REF!
A4: VV53 (주)지에스리테일송파일배 | B4: =VLOOKUP(A:A,#REF!,2,0) -> #REF! | C4: =VLOOKUP(A:A,#REF!,3,0) -> #REF! | D4: =VLOOKUP(A:A,#REF!,4,0) -> #REF! | E4: =VLOOKUP(A:A,#REF!,5,0) -> #REF! | F4: =VLOOKUP(A:A,#REF!,2,0) -> #REF! | G4: =VLOOKUP(A:A,#REF!,3,0) -> #REF! | H4: =VLOOKUP(A:A,#REF!,4,0) -> #REF! | I4: =VLOOKUP(A4,#REF!,2,0) -> #REF! | J4: =VLOOKUP(A4,#REF!,3,0) -> #REF! | K4: =VLOOKUP(A:A,#REF!,4,0) -> #REF! | L4: =VLOOKUP(A4,#REF!,5,0) -> #REF! | M4: =VLOOKUP(A:A,#REF!,2,0) -> #REF! | N4: =VLOOKUP(A:A,#REF!,3,0) -> #REF! | O4: =VLOOKUP(A:A,#REF!,2,0) -> #REF! | P4: =VLOOKUP(A:A,#REF!,3,0) -> #REF! | Q4: =VLOOKUP(A:A,#REF!,2,0) -> #REF! | R4: =SUM(B4:Q4) -> #REF!
A5: VV55 (주)지에스리테일송파2일배 | B5: =VLOOKUP(A:A,#REF!,2,0) -> #REF! | C5: =VLOOKUP(A:A,#REF!,3,0) -> #REF! | D5: =VLOOKUP(A:A,#REF!,4,0) -> #REF! | E5: =VLOOKUP(A:A,#REF!,5,0) -> #REF! | F5: =VLOOKUP(A:A,#REF!,2,0) -> #REF! | G5: =VLOOKUP(A:A,#REF!,3,0) -> #REF! | H5: =VLOOKUP(A:A,#REF!,4,0) -> #REF! | I5: =VLOOKUP(A5,#REF!,2,0) -> #REF! | J5: =VLOOKUP(A5,#REF!,3,0) -> #REF! | K5: =VLOOKUP(A:A,#REF!,4,0) -> #REF! | L5: =VLOOKUP(A5,#REF!,5,0) -> #REF! | M5: =VLOOKUP(A:A,#REF!,2,0) -> #REF! | N5: =VLOOKUP(A:A,#REF!,3,0) -> #REF! | O5: =VLOOKUP(A:A,#REF!,2,0) -> #REF! | P5: =VLOOKUP(A:A,#REF!,3,0) -> #REF! | Q5: =VLOOKUP(A:A,#REF!,2,0) -> #REF! | R5: =SUM(B5:Q5) -> #REF!
A6: VV63 ㈜지에스리테일고양일배센터 | B6: =VLOOKUP(A:A,#REF!,2,0) -> #REF! | C6: =VLOOKUP(A:A,#REF!,3,0) -> #REF! | D6: =VLOOKUP(A:A,#REF!,4,0) -> #REF! | E6: =VLOOKUP(A:A,#REF!,5,0) -> #REF! | F6: =VLOOKUP(A:A,#REF!,2,0) -> #REF! | G6: =VLOOKUP(A:A,#REF!,3,0) -> #REF! | H6: =VLOOKUP(A:A,#REF!,4,0) -> #REF! | I6: =VLOOKUP(A6,#REF!,2,0) -> #REF! | J6: =VLOOKUP(A6,#REF!,3,0) -> #REF! | K6: =VLOOKUP(A:A,#REF!,4,0) -> #REF! | L6: =VLOOKUP(A6,#REF!,5,0) -> #REF! | M6: =VLOOKUP(A:A,#REF!,2,0) -> #REF! | N6: =VLOOKUP(A:A,#REF!,3,0) -> #REF! | O6: =VLOOKUP(A:A,#REF!,2,0) -> #REF! | P6: =VLOOKUP(A:A,#REF!,3,0) -> #REF! | Q6: =VLOOKUP(A:A,#REF!,2,0) -> #REF! | R6: =SUM(B6:Q6) -> #REF!
A7: VV64 ㈜지에스리테일고양일배2 | B7: =VLOOKUP(A:A,#REF!,2,0) -> #REF! | C7: =VLOOKUP(A:A,#REF!,3,0) -> #REF! | D7: =VLOOKUP(A:A,#REF!,4,0) -> #REF! | E7: =VLOOKUP(A:A,#REF!,5,0) -> #REF! | F7: =VLOOKUP(A:A,#REF!,2,0) -> #REF! | G7: =VLOOKUP(A:A,#REF!,3,0) -> #REF! | H7: =VLOOKUP(A:A,#REF!,4,0) -> #REF! | I7: =VLOOKUP(A7,#REF!,2,0) -> #REF! | J7: =VLOOKUP(A7,#REF!,3,0) -> #REF! | K7: =VLOOKUP(A:A,#REF!,4,0) -> #REF! | L7: =VLOOKUP(A7,#REF!,5,0) -> #REF! | M7: =VLOOKUP(A:A,#REF!,2,0) -> #REF! | N7: =VLOOKUP(A:A,#REF!,3,0) -> #REF! | O7: =VLOOKUP(A:A,#REF!,2,0) -> #REF! | P7: =VLOOKUP(A:A,#REF!,3,0) -> #REF! | Q7: =VLOOKUP(A:A,#REF!,2,0) -> #REF! | R7: =SUM(B7:Q7) -> #REF!
A8: VV62 (주)지에스리테일김포2일배 | B8: =VLOOKUP(A:A,#REF!,2,0) -> #REF! | C8: =VLOOKUP(A:A,#REF!,3,0) -> #REF! | D8: =VLOOKUP(A:A,#REF!,4,0) -> #REF! | E8: =VLOOKUP(A:A,#REF!,5,0) -> #REF! | F8: =VLOOKUP(A:A,#REF!,2,0) -> #REF! | G8: =VLOOKUP(A:A,#REF!,3,0) -> #REF! | H8: =VLOOKUP(A:A,#REF!,4,0) -> #REF! | I8: =VLOOKUP(A8,#REF!,2,0) -> #REF! | J8: =VLOOKUP(A8,#REF!,3,0) -> #REF! | K8: =VLOOKUP(A:A,#REF!,4,0) -> #REF! | L8: =VLOOKUP(A8,#REF!,5,0) -> #REF! | M8: =VLOOKUP(A:A,#REF!,2,0) -> #REF! | N8: =VLOOKUP(A:A,#REF!,3,0) -> #REF! | O8: =VLOOKUP(A:A,#REF!,2,0) -> #REF! | P8: =VLOOKUP(A:A,#REF!,3,0) -> #REF! | Q8: =VLOOKUP(A:A,#REF!,2,0) -> #REF! | R8: =SUM(B8:Q8) -> #REF!
A9: VV70 ㈜지에스리테일김포3일배 | B9: =VLOOKUP(A:A,#REF!,2,0) -> #REF! | C9: =VLOOKUP(A:A,#REF!,3,0) -> #REF! | D9: =VLOOKUP(A:A,#REF!,4,0) -> #REF! | E9: =VLOOKUP(A:A,#REF!,5,0) -> #REF! | F9: =VLOOKUP(A:A,#REF!,2,0) -> #REF! | G9: =VLOOKUP(A:A,#REF!,3,0) -> #REF! | H9: =VLOOKUP(A:A,#REF!,4,0) -> #REF! | I9: =VLOOKUP(A9,#REF!,2,0) -> #REF! | J9: =VLOOKUP(A9,#REF!,3,0) -> #REF! | K9: =VLOOKUP(A:A,#REF!,4,0) -> #REF! | L9: =VLOOKUP(A9,#REF!,5,0) -> #REF! | M9: =VLOOKUP(A:A,#REF!,2,0) -> #REF! | N9: =VLOOKUP(A:A,#REF!,3,0) -> #REF! | O9: =VLOOKUP(A:A,#REF!,2,0) -> #REF! | P9: =VLOOKUP(A:A,#REF!,3,0) -> #REF! | Q9: =VLOOKUP(A:A,#REF!,2,0) -> #REF! | R9: =SUM(B9:Q9) -> #REF!
A10: VV66 지에스리테일인천도화일배 | B10: =VLOOKUP(A:A,#REF!,2,0) -> #REF! | C10: =VLOOKUP(A:A,#REF!,3,0) -> #REF! | D10: =VLOOKUP(A:A,#REF!,4,0) -> #REF! | E10: =VLOOKUP(A:A,#REF!,5,0) -> #REF! | F10: =VLOOKUP(A:A,#REF!,2,0) -> #REF! | G10: =VLOOKUP(A:A,#REF!,3,0) -> #REF! | H10: =VLOOKUP(A:A,#REF!,4,0) -> #REF! | I10: =VLOOKUP(A10,#REF!,2,0) -> #REF! | J10: =VLOOKUP(A10,#REF!,3,0) -> #REF! | K10: =VLOOKUP(A:A,#REF!,4,0) -> #REF! | L10: =VLOOKUP(A10,#REF!,5,0) -> #REF! | M10: =VLOOKUP(A:A,#REF!,2,0) -> #REF! | N10: =VLOOKUP(A:A,#REF!,3,0) -> #REF! | O10: =VLOOKUP(A:A,#REF!,2,0) -> #REF! | P10: =VLOOKUP(A:A,#REF!,3,0) -> #REF! | Q10: =VLOOKUP(A:A,#REF!,2,0) -> #REF! | R10: =SUM(B10:Q10) -> #REF!
A11: VV67 지에스리테일인천도화2일배 | B11: =VLOOKUP(A:A,#REF!,2,0) -> #REF! | C11: =VLOOKUP(A:A,#REF!,3,0) -> #REF! | D11: =VLOOKUP(A:A,#REF!,4,0) -> #REF! | E11: =VLOOKUP(A:A,#REF!,5,0) -> #REF! | F11: =VLOOKUP(A:A,#REF!,2,0) -> #REF! | G11: =VLOOKUP(A:A,#REF!,3,0) -> #REF! | H11: =VLOOKUP(A:A,#REF!,4,0) -> #REF! | I11: =VLOOKUP(A11,#REF!,2,0) -> #REF! | J11: =VLOOKUP(A11,#REF!,3,0) -> #REF! | K11: =VLOOKUP(A:A,#REF!,4,0) -> #REF! | L11: =VLOOKUP(A11,#REF!,5,0) -> #REF! | M11: =VLOOKUP(A:A,#REF!,2,0) -> #REF! | N11: =VLOOKUP(A:A,#REF!,3,0) -> #REF! | O11: =VLOOKUP(A:A,#REF!,2,0) -> #REF! | P11: =VLOOKUP(A:A,#REF!,3,0) -> #REF! | Q11: =VLOOKUP(A:A,#REF!,2,0) -> #REF! | R11: =SUM(B11:Q11) -> #REF!
A12: VV17 (주)지에스리테일발안일배 | B12: =VLOOKUP(A:A,#REF!,2,0) -> #REF! | C12: =VLOOKUP(A:A,#REF!,3,0) -> #REF! | D12: =VLOOKUP(A:A,#REF!,4,0) -> #REF! | E12: =VLOOKUP(A:A,#REF!,5,0) -> #REF! | F12: =VLOOKUP(A:A,#REF!,2,0) -> #REF! | G12: =VLOOKUP(A:A,#REF!,3,0) -> #REF! | H12: =VLOOKUP(A:A,#REF!,4,0) -> #REF! | I12: =VLOOKUP(A12,#REF!,2,0) -> #REF! | J12: =VLOOKUP(A12,#REF!,3,0) -> #REF! | K12: =VLOOKUP(A:A,#REF!,4,0) -> #REF! | L12: =VLOOKUP(A12,#REF!,5,0) -> #REF! | M12: =VLOOKUP(A:A,#REF!,2,0) -> #REF! | N12: =VLOOKUP(A:A,#REF!,3,0) -> #REF! | O12: =VLOOKUP(A:A,#REF!,2,0) -> #REF! | P12: =VLOOKUP(A:A,#REF!,3,0) -> #REF! | Q12: =VLOOKUP(A:A,#REF!,2,0) -> #REF! | R12: =SUM(B12:Q12) -> #REF!
A13: VV71 (주)지에스리테일발안2일배 | B13: =VLOOKUP(A:A,#REF!,2,0) -> #REF! | C13: =VLOOKUP(A:A,#REF!,3,0) -> #REF! | D13: =VLOOKUP(A:A,#REF!,4,0) -> #REF! | E13: =VLOOKUP(A:A,#REF!,5,0) -> #REF! | F13: =VLOOKUP(A:A,#REF!,2,0) -> #REF! | G13: =VLOOKUP(A:A,#REF!,3,0) -> #REF! | H13: =VLOOKUP(A:A,#REF!,4,0) -> #REF! | I13: =VLOOKUP(A13,#REF!,2,0) -> #REF! | J13: =VLOOKUP(A13,#REF!,3,0) -> #REF! | K13: =VLOOKUP(A:A,#REF!,4,0) -> #REF! | L13: =VLOOKUP(A13,#REF!,5,0) -> #REF! | M13: =VLOOKUP(A:A,#REF!,2,0) -> #REF! | N13: =VLOOKUP(A:A,#REF!,3,0) -> #REF! | O13: =VLOOKUP(A:A,#REF!,2,0) -> #REF! | P13: =VLOOKUP(A:A,#REF!,3,0) -> #REF! | Q13: =VLOOKUP(A:A,#REF!,2,0) -> #REF! | R13: =SUM(B13:Q13) -> #REF!
A14: VV60 ㈜지에스리테일오산일배 | B14: =VLOOKUP(A:A,#REF!,2,0) -> #REF! | C14: =VLOOKUP(A:A,#REF!,3,0) -> #REF! | D14: =VLOOKUP(A:A,#REF!,4,0) -> #REF! | E14: =VLOOKUP(A:A,#REF!,5,0) -> #REF! | F14: =VLOOKUP(A:A,#REF!,2,0) -> #REF! | G14: =VLOOKUP(A:A,#REF!,3,0) -> #REF! | H14: =VLOOKUP(A:A,#REF!,4,0) -> #REF! | I14: =VLOOKUP(A14,#REF!,2,0) -> #REF! | J14: =VLOOKUP(A14,#REF!,3,0) -> #REF! | K14: =VLOOKUP(A:A,#REF!,4,0) -> #REF! | L14: =VLOOKUP(A14,#REF!,5,0) -> #REF! | M14: =VLOOKUP(A:A,#REF!,2,0) -> #REF! | N14: =VLOOKUP(A:A,#REF!,3,0) -> #REF! | O14: =VLOOKUP(A:A,#REF!,2,0) -> #REF! | P14: =VLOOKUP(A:A,#REF!,3,0) -> #REF! | Q14: =VLOOKUP(A:A,#REF!,2,0) -> #REF! | R14: =SUM(B14:Q14) -> #REF!
A15: VV03 (주)지에스리테일(아신A) | B15: =VLOOKUP(A:A,#REF!,2,0) -> #REF! | C15: =VLOOKUP(A:A,#REF!,3,0) -> #REF! | D15: =VLOOKUP(A:A,#REF!,4,0) -> #REF! | E15: =VLOOKUP(A:A,#REF!,5,0) -> #REF! | F15: =VLOOKUP(A:A,#REF!,2,0) -> #REF! | G15: =VLOOKUP(A:A,#REF!,3,0) -> #REF! | H15: =VLOOKUP(A:A,#REF!,4,0) -> #REF! | I15: =VLOOKUP(A15,#REF!,2,0) -> #REF! | J15: =VLOOKUP(A15,#REF!,3,0) -> #REF! | K15: =VLOOKUP(A:A,#REF!,4,0) -> #REF! | L15: =VLOOKUP(A15,#REF!,5,0) -> #REF! | M15: =VLOOKUP(A:A,#REF!,2,0) -> #REF! | N15: =VLOOKUP(A:A,#REF!,3,0) -> #REF! | O15: =VLOOKUP(A:A,#REF!,2,0) -> #REF! | P15: =VLOOKUP(A:A,#REF!,3,0) -> #REF! | Q15: =VLOOKUP(A:A,#REF!,2,0) -> #REF! | R15: =SUM(B15:Q15) -> #REF!
... A22: VV57 (주)지에스리테일김해일배 | B22: =VLOOKUP(A:A,#REF!,2,0) -> #REF! | C22: =VLOOKUP(A:A,#REF!,3,0) -> #REF! | D22: =VLOOKUP(A:A,#REF!,4,0) -> #REF! | E22: =VLOOKUP(A:A,#REF!,5,0) -> #REF! | F22: =VLOOKUP(A:A,#REF!,2,0) -> #REF! | G22: =VLOOKUP(A:A,#REF!,3,0) -> #REF! | H22: =VLOOKUP(A:A,#REF!,4,0) -> #REF! | I22: =VLOOKUP(A22,#REF!,2,0) -> #REF! | J22: =VLOOKUP(A22,#REF!,3,0) -> #REF! | K22: =VLOOKUP(A:A,#REF!,4,0) -> #REF! | L22: =VLOOKUP(A22,#REF!,5,0) -> #REF! | M22: =VLOOKUP(A:A,#REF!,2,0) -> #REF! | N22: =VLOOKUP(A:A,#REF!,3,0) -> #REF! | O22: =VLOOKUP(A:A,#REF!,2,0) -> #REF! | P22: =VLOOKUP(A:A,#REF!,3,0) -> #REF! | Q22: =VLOOKUP(A:A,#REF!,2,0) -> #REF! | R22: =SUM(B22:Q22) -> #REF!
A23: VV23 (주)지에스리테일(해인FF) | B23: =VLOOKUP(A:A,#REF!,2,0) -> #REF! | C23: =VLOOKUP(A:A,#REF!,3,0) -> #REF! | D23: =VLOOKUP(A:A,#REF!,4,0) -> #REF! | E23: =VLOOKUP(A:A,#REF!,5,0) -> #REF! | F23: =VLOOKUP(A:A,#REF!,2,0) -> #REF! | G23: =VLOOKUP(A:A,#REF!,3,0) -> #REF! | H23: =VLOOKUP(A:A,#REF!,4,0) -> #REF! | I23: =VLOOKUP(A23,#REF!,2,0) -> #REF! | J23: =VLOOKUP(A23,#REF!,3,0) -> #REF! | K23: =VLOOKUP(A:A,#REF!,4,0) -> #REF! | L23: =VLOOKUP(A23,#REF!,5,0) -> #REF! | N23: =VLOOKUP(A:A,#REF!,3,0) -> #REF! | O23: =VLOOKUP(A:A,#REF!,2,0) -> #REF! | P23: =VLOOKUP(A:A,#REF!,3,0) -> #REF! | Q23: =VLOOKUP(A:A,#REF!,2,0) -> #REF! | R23: =SUM(B23:Q23) -> #REF!
A24: VV20 (주)지에스리테일(해인CVS) | M24: =VLOOKUP(A:A,#REF!,2,0) -> #REF! | N24: =VLOOKUP(A:A,#REF!,3,0) -> #REF! | R24: =SUM(B24:Q24) -> #REF!
A25: VV50 (주)지에스리테일(제성) | B25: =VLOOKUP(A:A,#REF!,2,0) -> #REF! | C25: =VLOOKUP(A:A,#REF!,3,0) -> #REF! | D25: =VLOOKUP(A:A,#REF!,4,0) -> #REF! | E25: =VLOOKUP(A:A,#REF!,5,0) -> #REF! | F25: =IFERROR(VLOOKUP(A:A,#REF!,2,0),"0") -> 0 | G25: =VLOOKUP(A:A,#REF!,3,0) -> #REF! | H25: =VLOOKUP(A:A,#REF!,4,0) -> #REF! | I25: =VLOOKUP(A25,#REF!,2,0) -> #REF! | J25: =VLOOKUP(A25,#REF!,3,0) -> #REF! | K25: =VLOOKUP(A:A,#REF!,4,0) -> #REF! | L25: =VLOOKUP(A25,#REF!,5,0) -> #REF! | M25: =VLOOKUP(A:A,#REF!,2,0) -> #REF! | N25: =VLOOKUP(A:A,#REF!,3,0) -> #REF! | O25: =VLOOKUP(A:A,#REF!,2,0) -> #REF! | P25: =VLOOKUP(A:A,#REF!,3,0) -> #REF! | Q25: =VLOOKUP(A:A,#REF!,2,0) -> #REF! | R25: =SUM(B25:Q25) -> #REF!
A26: VV65 ㈜지에스리테일익산일배 | B26: =VLOOKUP(A:A,#REF!,2,0) -> #REF! | C26: =VLOOKUP(A:A,#REF!,3,0) -> #REF! | D26: =VLOOKUP(A:A,#REF!,4,0) -> #REF! | E26: =VLOOKUP(A:A,#REF!,5,0) -> #REF! | F26: =VLOOKUP(A:A,#REF!,2,0) -> #REF! | G26: =VLOOKUP(A:A,#REF!,3,0) -> #REF! | H26: =VLOOKUP(A:A,#REF!,4,0) -> #REF! | I26: =VLOOKUP(A26,#REF!,2,0) -> #REF! | J26: =VLOOKUP(A26,#REF!,3,0) -> #REF! | K26: =VLOOKUP(A:A,#REF!,4,0) -> #REF! | L26: =VLOOKUP(A26,#REF!,5,0) -> #REF! | M26: =VLOOKUP(A:A,#REF!,2,0) -> #REF! | N26: =VLOOKUP(A:A,#REF!,3,0) -> #REF! | O26: =VLOOKUP(A:A,#REF!,2,0) -> #REF! | P26: =VLOOKUP(A:A,#REF!,3,0) -> #REF! | Q26: =VLOOKUP(A:A,#REF!,2,0) -> #REF! | R26: =SUM(B26:Q26) -> #REF!
A27: VV11 (주)지에스리테일장성일배 | B27: =VLOOKUP(A:A,#REF!,2,0) -> #REF! | C27: =VLOOKUP(A:A,#REF!,3,0) -> #REF! | D27: =VLOOKUP(A:A,#REF!,4,0) -> #REF! | E27: =VLOOKUP(A:A,#REF!,5,0) -> #REF! | F27: =VLOOKUP(A:A,#REF!,2,0) -> #REF! | G27: =VLOOKUP(A:A,#REF!,3,0) -> #REF! | H27: =VLOOKUP(A:A,#REF!,4,0) -> #REF! | I27: =VLOOKUP(A27,#REF!,2,0) -> #REF! | J27: =VLOOKUP(A27,#REF!,3,0) -> #REF! | K27: =VLOOKUP(A:A,#REF!,4,0) -> #REF! | L27: =VLOOKUP(A27,#REF!,5,0) -> #REF! | M27: =VLOOKUP(A:A,#REF!,2,0) -> #REF! | N27: =VLOOKUP(A:A,#REF!,3,0) -> #REF! | O27: =VLOOKUP(A:A,#REF!,2,0) -> #REF! | P27: =VLOOKUP(A:A,#REF!,3,0) -> #REF! | Q27: =VLOOKUP(A:A,#REF!,2,0) -> #REF! | R27: =SUM(B27:Q27) -> #REF!
A28: VV69 ㈜지에스리테일강릉일배센터 | B28: =VLOOKUP(A:A,#REF!,2,0) -> #REF! | C28: =VLOOKUP(A:A,#REF!,3,0) -> #REF! | D28: =VLOOKUP(A:A,#REF!,4,0) -> #REF! | E28: =VLOOKUP(A:A,#REF!,5,0) -> #REF! | F28: =VLOOKUP(A:A,#REF!,2,0) -> #REF! | G28: =VLOOKUP(A:A,#REF!,3,0) -> #REF! | H28: =VLOOKUP(A:A,#REF!,4,0) -> #REF! | I28: =VLOOKUP(A28,#REF!,2,0) -> #REF! | J28: =VLOOKUP(A28,#REF!,3,0) -> #REF! | K28: =VLOOKUP(A:A,#REF!,4,0) -> #REF! | L28: =VLOOKUP(A28,#REF!,5,0) -> #REF! | M28: =VLOOKUP(A:A,#REF!,2,0) -> #REF! | N28: =VLOOKUP(A:A,#REF!,3,0) -> #REF! | O28: =VLOOKUP(A:A,#REF!,2,0) -> #REF! | P28: =VLOOKUP(A:A,#REF!,3,0) -> #REF! | Q28: =VLOOKUP(A:A,#REF!,2,0) -> #REF! | R28: =SUM(B28:Q28) -> #REF!
A29: VV25 (주)지에스리테일진주일배 | B29: =VLOOKUP(A:A,#REF!,2,0) -> #REF! | C29: =VLOOKUP(A:A,#REF!,3,0) -> #REF! | D29: =VLOOKUP(A:A,#REF!,4,0) -> #REF! | E29: =VLOOKUP(A:A,#REF!,5,0) -> #REF! | F29: =VLOOKUP(A:A,#REF!,2,0) -> #REF! | G29: =VLOOKUP(A:A,#REF!,3,0) -> #REF! | H29: =VLOOKUP(A:A,#REF!,4,0) -> #REF! | I29: =VLOOKUP(A29,#REF!,2,0) -> #REF! | J29: =VLOOKUP(A29,#REF!,3,0) -> #REF! | K29: =VLOOKUP(A:A,#REF!,4,0) -> #REF! | L29: =VLOOKUP(A29,#REF!,5,0) -> #REF! | M29: =VLOOKUP(A:A,#REF!,2,0) -> #REF! | N29: =VLOOKUP(A:A,#REF!,3,0) -> #REF! | O29: =VLOOKUP(A:A,#REF!,2,0) -> #REF! | P29: =VLOOKUP(A:A,#REF!,3,0) -> #REF! | Q29: =VLOOKUP(A:A,#REF!,2,0) -> #REF! | R29: =SUM(B29:Q29) -> #REF!
A30: 총합계 | B30: =SUM(B3:B29) -> #REF! | C30: =SUM(C3:C29) -> #REF! | D30: =SUM(D3:D29) -> #REF! | E30: =SUM(E3:E29) -> #REF! | F30: =SUM(F3:F29) -> #REF! | G30: =SUM(G3:G29) -> #REF! | H30: =SUM(H3:H29) -> #REF! | I30: =SUM(I3:I29) -> #REF! | ... R30: =SUM(R3:R29) -> #REF!

Sheet 신라명과피벗
A1: 12/17 | B1: 열 레이블
A2: 행 레이블 | B2: 리얼)모닝롤208G | C2: 총합계
A3: VV16 (주)지에스리테일원주일배
A4: VV69 ㈜지에스리테일강릉일배센터
A5: VV57 (주)지에스리테일김해일배
A6: VV58 (주)지에스리테일김해2일배
A7: VV04 (주)지에스리테일공주일배
A8: VV75 (주)지에스리테일공주2일배
A9: VV34 (주)지에스리테일청주일배
A10: VV92 (주)지에스리테일신제주저온
A11: VV25 (주)지에스리테일진주일배
A12: VV20 (주)지에스리테일(해인CVS)
A13: VV95 (주)지에스리테일신광주저온
A14: VV96 (주)지에스리테일신광주2저
... A39: 총합계

Sheet 리얼)모닝롤
A1: 디저트
A2: =TODAY() -> 46309 | B2: 신라명과 | G2: 박스 | H2: 낱개
A3: 행 레이블 | B3: 입수 | C3: 리얼)모닝롤208G | D3: 박스 | E3: 센터명 | F3: 낱개
A4: VV57 (주)지에스리테일김해일배 | B4: 10 | C4: =IFERROR(VLOOKUP(A4,신라명과피벗!A:HN,2,FALSE),0) -> 0 | D4: =IFERROR(ROUNDDOWN(C4/B4,0),"") -> 0 | E4: 김해 | F4: =IFERROR(C4-(D4*B4),"") -> 0
A5: VV58 (주)지에스리테일김해2일배 | B5: =$B$4 -> 10 | C5: =IFERROR(VLOOKUP(A5,신라명과피벗!A:HN,2,FALSE),0) -> 0 | D5: =IFERROR(ROUNDDOWN(C5/B5,0),"") -> 0 | E5: 김해2 | F5: =IFERROR(C5-(D5*B5),"") -> 0
A6: VV92 (주)지에스리테일신제주저온 | B6: =$B$4 -> 10 | C6: =IFERROR(VLOOKUP(A6,신라명과피벗!A:HN,2,FALSE),0) -> 0 | D6: =IFERROR(ROUNDDOWN(C6/B6,0),"") -> 0 | E6: 신제주 | F6: =IFERROR(C6-(D6*B6),"") -> 0
A7: VV25 (주)지에스리테일진주일배 | B7: =$B$4 -> 10 | C7: =IFERROR(VLOOKUP(A7,신라명과피벗!A:HN,2,FALSE),0) -> 0 | D7: =IFERROR(ROUNDDOWN(C7/B7,0),"") -> 0 | E7: 진주 | F7: =IFERROR(C7-(D7*B7),"") -> 0
A8: VV20 (주)지에스리테일(해인CVS) | B8: =$B$4 -> 10 | C8: =IFERROR(VLOOKUP(A8,신라명과피벗!A:HN,2,FALSE),0) -> 0 | D8: =IFERROR(ROUNDDOWN(C8/B8,0),"") -> 0 | E8: CVS | F8: =IFERROR(C8-(D8*B8),"") -> 0
A9: VV83 지에스리테일경산저온 | B9: =$B$4 -> 10 | C9: =IFERROR(VLOOKUP(A9,신라명과피벗!A:HN,2,FALSE),0) -> 0 | D9: =IFERROR(ROUNDDOWN(C9/B9,0),"") -> 0 | E9: 경산 | F9: =IFERROR(C9-(D9*B9),"") -> 0
A10: VV84 ㈜지에스리테일경산2저온 | B10: =$B$4 -> 10 | C10: =IFERROR(VLOOKUP(A10,신라명과피벗!A:HN,2,FALSE),0) -> 0 | D10: =IFERROR(ROUNDDOWN(C10/B10,0),"") -> 0 | E10: 경산2 | F10: =IFERROR(C10-(D10*B10),"") -> 0
A11: VV97 (주)지에스리테일경산3저온 | B11: =$B$4 -> 10 | C11: =IFERROR(VLOOKUP(A11,신라명과피벗!A:HN,2,FALSE),0) -> 0 | D11: =IFERROR(ROUNDDOWN(C11/B11,0),"") -> 0 | E11: 경산3 | F11: =IFERROR(C11-(D11*B11),"") -> 0
A13: 영남 합계 | B13: =B4 -> 10 | C13: =SUM($C$4:$C$11) -> 0 | D13: =IFERROR(ROUNDDOWN(C13/B13,0),"") -> 0 | F13: =IFERROR(C13-(D13*B13),"") -> 0
A15: VV95 (주)지에스리테일신광주저온 | B15: =$B$4 -> 10 | C15: =IFERROR(VLOOKUP(A15,신라명과피벗!A:HN,2,FALSE),0) -> 0 | D15: =IFERROR(ROUNDDOWN(C15/B15,0),"") -> 0 | E15: 신광주 | F15: =IFERROR(C15-(D15*B15),"") -> 0
A16: VV96 (주)지에스리테일신광주2저 | B16: =$B$4 -> 10 | C16: =IFERROR(VLOOKUP(A16,신라명과피벗!A:HN,2,FALSE),0) -> 0 | D16: =IFERROR(ROUNDDOWN(C16/B16,0),"") -> 0 | E16: 신광주2 | F16: =IFERROR(C16-(D16*B16),"") -> 0
A17: VV65 ㈜지에스리테일익산일배 | B17: =$B$4 -> 10 | C17: =IFERROR(VLOOKUP(A17,신라명과피벗!A:HN,2,FALSE),0) -> 0 | D17: =IFERROR(ROUNDDOWN(C17/B17,0),"") -> 0 | E17: 익산 | F17: =IFERROR(C17-(D17*B17),"") -> 0
A19: 호남 합계 | B19: =$B$4 -> 10 | C19: =SUM(C15:C17) -> 0 | D19: =IFERROR(ROUNDDOWN(C19/B19,0),"") -> 0 | F19: =IFERROR(C19-(D19*B19),"") -> 0
A21: VV16 (주)지에스리테일원주일배 | B21: =$B$4 -> 10 | C21: =IFERROR(VLOOKUP(A21,신라명과피벗!A:HN,2,FALSE),0) -> 0 | D21: =IFERROR(ROUNDDOWN(C21/B21,0),"") -> 0 | E21: 원주 | F21: =IFERROR(C21-(D21*B21),"") -> 0
A22: VV69 ㈜지에스리테일강릉일배센터 | B22: =$B$4 -> 10 | C22: =IFERROR(VLOOKUP(A22,신라명과피벗!A:HN,2,FALSE),0) -> 0 | D22: =IFERROR(ROUNDDOWN(C22/B22,0),"") -> 0 | E22: 강릉 | F22: =IFERROR(C22-(D22*B22),"") -> 0
A23: VV04 (주)지에스리테일공주일배 | B23: =$B$4 -> 10 | C23: =IFERROR(VLOOKUP(A23,신라명과피벗!A:HN,2,FALSE),0) -> 0 | D23: =IFERROR(ROUNDDOWN(C23/B23,0),"") -> 0 | E23: 공주 | F23: =IFERROR(C23-(D23*B23),"") -> 0
A24: VV75 (주)지에스리테일공주2일배 | B24: =$B$4 -> 10 | C24: =IFERROR(VLOOKUP(A24,신라명과피벗!A:HN,2,FALSE),0) -> 0 | D24: =IFERROR(ROUNDDOWN(C24/B24,0),"") -> 0 | E24: 공주2 | F24: =IFERROR(C24-(D24*B24),"") -> 0
A25: VV34 (주)지에스리테일청주일배 | B25: =$B$4 -> 10 | C25: =IFERROR(VLOOKUP(A25,신라명과피벗!A:HN,2,FALSE),0) -> 0 | D25: =IFERROR(ROUNDDOWN(C25/B25,0),"") -> 0 | E25: 청주 | F25: =IFERROR(C25-(D25*B25),"") -> 0
A26: VV03 (주)지에스리테일(아신A) | B26: =$B$4 -> 10 | C26: =IFERROR(VLOOKUP(A26,신라명과피벗!A:HN,2,FALSE),0) -> 0 | D26: =IFERROR(ROUNDDOWN(C26/B26,0),"") -> 0 | E26: 아신A | F26: =IFERROR(C26-(D26*B26),"") -> 0
A27: VV90 (주)지에스리테일포천저온 | B27: =$B$4 -> 10 | C27: =IFERROR(VLOOKUP(A27,신라명과피벗!A:HN,2,FALSE),0) -> 0 | D27: =IFERROR(ROUNDDOWN(C27/B27,0),"") -> 0 | E27: 포천 | F27: =IFERROR(C27-(D27*B27),"") -> 0
A28: VV91 (주)지에스리테일포천2저온 | B28: =$B$4 -> 10 | C28: =IFERROR(VLOOKUP(A28,신라명과피벗!A:HN,2,FALSE),0) -> 0 | D28: =IFERROR(ROUNDDOWN(C28/B28,0),"") -> 0 | E28: 포천2 | F28: =IFERROR(C28-(D28*B28),"") -> 0 | G28: =IFERROR(ROUNDDOWN(SUM($F$29:$F$46)/$B$4,0),"") -> 0 | H28: =IFERROR(SUM($F$29:$F$46)-($G$28*$B$4),"") -> 0
A29: VV98 (주)지에스리테일고촌저온 | B29: =$B$4 -> 10 | C29: =IFERROR(VLOOKUP(A29,신라명과피벗!A:HN,2,FALSE),0) -> 0 | D29: =IFERROR(ROUNDDOWN(C29/B29,0),"") -> 0 | E29: 고촌 | F29: =IFERROR(C29-(D29*B29),"") -> 0
A30: VV99 (주)지에스리테일고촌2저온 | B30: =$B$4 -> 10 | C30: =IFERROR(VLOOKUP(A30,신라명과피벗!A:HN,2,FALSE),0) -> 0 | D30: =IFERROR(ROUNDDOWN(C30/B30,0),"") -> 0 | E30: 고촌2 | F30: =IFERROR(C30-(D30*B30),"") -> 0
A31: VV63 ㈜지에스리테일고양일배센터 | B31: =$B$4 -> 10 | C31: =IFERROR(VLOOKUP(A31,신라명과피벗!A:HN,2,FALSE),0) -> 0 | D31: =IFERROR(ROUNDDOWN(C31/B31,0),"") -> 0 | E31: 고양 | F31: =IFERROR(C31-(D31*B31),"") -> 0
A32: VV64 ㈜지에스리테일고양일배2 | B32: =$B$4 -> 10 | C32: =IFERROR(VLOOKUP(A32,신라명과피벗!A:HN,2,FALSE),0) -> 0 | D32: =IFERROR(ROUNDDOWN(C32/B32,0),"") -> 0 | E32: 고양2 | F32: =IFERROR(C32-(D32*B32),"") -> 0
A33: VV81 (주)지에스리테일고양저온3 | B33: =$B$4 -> 10 | C33: =IFERROR(VLOOKUP(A33,신라명과피벗!A:HN,2,FALSE),0) -> 0 | D33: =IFERROR(ROUNDDOWN(C33/B33,0),"") -> 0 | E33: 고양3 | F33: =IFERROR(C33-(D33*B33),"") -> 0
A34: VV62 (주)지에스리테일김포2일배 | B34: =$B$4 -> 10 | C34: =IFERROR(VLOOKUP(A34,신라명과피벗!A:HN,2,FALSE),0) -> 0 | D34: =IFERROR(ROUNDDOWN(C34/B34,0),"") -> 0 | E34: 김포2 | F34: =IFERROR(C34-(D34*B34),"") -> 0
A35: VV70 ㈜지에스리테일김포3일배 | B35: =$B$4 -> 10 | C35: =IFERROR(VLOOKUP(A35,신라명과피벗!A:HN,2,FALSE),0) -> 0 | D35: =IFERROR(ROUNDDOWN(C35/B35,0),"") -> 0 | E35: 김포3 | F35: =IFERROR(C35-(D35*B35),"") -> 0 | G35: =IFERROR(ROUNDDOWN(SUM($F$36:$F$46)/$B$4,0),"") -> 0 | H35: =IFERROR(SUM($F$36:$F$46)-($G$35*$B$4),"") -> 0
A36: VV66 지에스리테일인천도화일배 | B36: =$B$4 -> 10 | C36: =IFERROR(VLOOKUP(A36,신라명과피벗!A:HN,2,FALSE),0) -> 0 | D36: =IFERROR(ROUNDDOWN(C36/B36,0),"") -> 0 | E36: 도화 | F36: =IFERROR(C36-(D36*B36),"") -> 0
A37: VV67 지에스리테일인천도화2일배 | B37: =$B$4 -> 10 | C37: =IFERROR(VLOOKUP(A37,신라명과피벗!A:HN,2,FALSE),0) -> 0 | D37: =IFERROR(ROUNDDOWN(C37/B37,0),"") -> 0 | E37: 도화2 | F37: =IFERROR(C37-(D37*B37),"") -> 0
A38: VV17 (주)지에스리테일발안일배 | B38: =$B$4 -> 10 | C38: =IFERROR(VLOOKUP(A38,신라명과피벗!A:HN,2,FALSE),0) -> 0 | D38: =IFERROR(ROUNDDOWN(C38/B38,0),"") -> 0 | E38: 발안 | F38: =IFERROR(C38-(D38*B38),"") -> 0
A39: VV71 (주)지에스리테일발안2일배 | B39: =$B$4 -> 10 | C39: =IFERROR(VLOOKUP(A39,신라명과피벗!A:HN,2,FALSE),0) -> 0 | D39: =IFERROR(ROUNDDOWN(C39/B39,0),"") -> 0 | E39: 발안2 | F39: =IFERROR(C39-(D39*B39),"") -> 0
A40: VV53 (주)지에스리테일송파일배 | B40: =$B$4 -> 10 | C40: =IFERROR(VLOOKUP(A40,신라명과피벗!A:HN,2,FALSE),0) -> 0 | D40: =IFERROR(ROUNDDOWN(C40/B40,0),"") -> 0 | E40: 송파 | F40: =IFERROR(C40-(D40*B40),"") -> 0
A41: VV55 (주)지에스리테일송파2일배 | B41: =$B$4 -> 10 | C41: =IFERROR(VLOOKUP(A41,신라명과피벗!A:HN,2,FALSE),0) -> 0 | D41: =IFERROR(ROUNDDOWN(C41/B41,0),"") -> 0 | E41: 송파2 | F41: =IFERROR(C41-(D41*B41),"") -> 0 | G41: =IFERROR(ROUNDDOWN(SUM($F$42:$F$46)/$B$4,0),"") -> 0 | H41: =IFERROR(SUM($F$42:$F$46)-($G$41*$B$4),"") -> 0
A42: VV93 (주)지에스리테일곤지암센터 | B42: =$B$4 -> 10 | C42: =IFERROR(VLOOKUP(A42,신라명과피벗!A:HN,2,FALSE),0) -> 0 | D42: =IFERROR(ROUNDDOWN(C42/B42,0),"") -> 0 | E42: 곤지암 | F42: =IFERROR(C42-(D42*B42),"") -> 0
A43: VV94 (주)지에스리테일곤지암2센 | B43: =$B$4 -> 10 | C43: =IFERROR(VLOOKUP(A43,신라명과피벗!A:HN,2,FALSE),0) -> 0 | D43: =IFERROR(ROUNDDOWN(C43/B43,0),"") -> 0 | E43: 곤지암2 | F43: =IFERROR(C43-(D43*B43),"") -> 0
A44: VV85 지에스리테일신오산1저온 | B44: =$B$4 -> 10 | C44: =IFERROR(VLOOKUP(A44,신라명과피벗!A:HN,2,FALSE),0) -> 0 | D44: =IFERROR(ROUNDDOWN(C44/B44,0),"") -> 0 | E44: 신오산1 | F44: =IFERROR(C44-(D44*B44),"") -> 0
...

Sheet 리치푸드 피벗
A1: 10/14 | C1: 열 레이블
A2: 10/15납품 | C2: 네이쳐)수박스무디 | E2: 딸기바나나스무디 | F2: 딸기블루베리망고스무디 | G2: 망고바나나스무디 | H2: 총합계
A3: VV16 (주)지에스리테일원주일배 | E3: 15 | H3: 15
A4: VV95 (주)지에스리테일신광주저온 | F4: 15 | H4: 15
A5: VV83 지에스리테일경산저온 | C5: 36 | H5: 36
A6: VV63 ㈜지에스리테일고양일배센터 | G6: 15 | H6: 15
A7: VV62 (주)지에스리테일김포2일배 | F7: 15 | H7: 15
A8: VV85 지에스리테일신오산1저온 | G8: 15 | H8: 15
A9: VV53 (주)지에스리테일송파일배 | C9: 24 | E9: 15 | H9: 39
A10: 총합계 | C10: 60 | E10: 30 | F10: 30 | G10: 30 | H10: 150

Sheet 그린스무디
A2: =TODAY() -> 46309 | B2: GS 네이처 _냉동 □
A3: ='리치푸드 피벗'!A2 -> 10/15납품 | B3: 입수 | C3: 그린스무디 | D3: 박스 | E3: 센터명 | F3: 낱개
A4: VV98 (주)지에스리테일고촌저온 | B4: 15 | C4: =IFERROR(VLOOKUP(A4,'리치푸드 피벗'!A:SP,2,FALSE),0) -> 0 | D4: =IFERROR(ROUNDDOWN(C4/B4,0),"") -> 0 | E4: 고촌 | F4: =IFERROR(C4-(D4*B4),"") -> 0
A5: VV93 (주)지에스리테일곤지암센터 | B5: =$B$4 -> 15 | C5: =IFERROR(VLOOKUP(A5,'리치푸드 피벗'!A:SP,2,FALSE),0) -> 0 | D5: =IFERROR(ROUNDDOWN(C5/B5,0),"") -> 0 | E5: 곤지암 | F5: =IFERROR(C5-(D5*B5),"") -> 0
A6: VV90 (주)지에스리테일포천저온 | B6: =$B$4 -> 15 | C6: =IFERROR(VLOOKUP(A6,'리치푸드 피벗'!A:SP,2,FALSE),0) -> 0 | D6: =IFERROR(ROUNDDOWN(C6/B6,0),"") -> 0 | E6: 포천 | F6: =IFERROR(C6-(D6*B6),"") -> 0
A7: VV85 지에스리테일신오산1저온 | B7: =$B$4 -> 15 | C7: =IFERROR(VLOOKUP(A7,'리치푸드 피벗'!A:SP,2,FALSE),0) -> 0 | D7: =IFERROR(ROUNDDOWN(C7/B7,0),"") -> 0 | E7: 신오산1 | F7: =IFERROR(C7-(D7*B7),"") -> 0
A8: VV04 (주)지에스리테일공주일배 | B8: =$B$4 -> 15 | C8: =IFERROR(VLOOKUP(A8,'리치푸드 피벗'!A:SP,2,FALSE),0) -> 0 | D8: =IFERROR(ROUNDDOWN(C8/B8,0),"") -> 0 | E8: 공주 | F8: =IFERROR(C8-(D8*B8),"") -> 0
A9: VV69 ㈜지에스리테일강릉일배센터 | B9: =$B$4 -> 15 | C9: =IFERROR(VLOOKUP(A9,'리치푸드 피벗'!A:SP,2,FALSE),0) -> 0 | D9: =IFERROR(ROUNDDOWN(C9/B9,0),"") -> 0 | E9: 강릉 | F9: =IFERROR(C9-(D9*B9),"") -> 0 | H9: 네이처
A10: VV66 지에스리테일인천도화일배 | B10: =$B$4 -> 15 | C10: =IFERROR(VLOOKUP(A10,'리치푸드 피벗'!A:SP,2,FALSE),0) -> 0 | D10: =IFERROR(ROUNDDOWN(C10/B10,0),"") -> 0 | E10: 도화 | F10: =IFERROR(C10-(D10*B10),"") -> 0
A11: VV63 ㈜지에스리테일고양일배센터 | B11: =$B$4 -> 15 | C11: =IFERROR(VLOOKUP(A11,'리치푸드 피벗'!A:SP,2,FALSE),0) -> 0 | D11: =IFERROR(ROUNDDOWN(C11/B11,0),"") -> 0 | E11: 고양 | F11: =IFERROR(C11-(D11*B11),"") -> 0
A12: VV62 (주)지에스리테일김포2일배 | B12: =$B$4 -> 15 | C12: =IFERROR(VLOOKUP(A12,'리치푸드 피벗'!A:SP,2,FALSE),0) -> 0 | D12: =IFERROR(ROUNDDOWN(C12/B12,0),"") -> 0 | E12: 김포2 | F12: =IFERROR(C12-(D12*B12),"") -> 0
A13: VV53 (주)지에스리테일송파일배 | B13: =$B$4 -> 15 | C13: =IFERROR(VLOOKUP(A13,'리치푸드 피벗'!A:SP,2,FALSE),0) -> 0 | D13: =IFERROR(ROUNDDOWN(C13/B13,0),"") -> 0 | E13: 송파 | F13: =IFERROR(C13-(D13*B13),"") -> 0
A14: VV34 (주)지에스리테일청주일배 | B14: =$B$4 -> 15 | C14: =IFERROR(VLOOKUP(A14,'리치푸드 피벗'!A:SP,2,FALSE),0) -> 0 | D14: =IFERROR(ROUNDDOWN(C14/B14,0),"") -> 0 | E14: 청주 | F14: =IFERROR(C14-(D14*B14),"") -> 0
A15: VV17 (주)지에스리테일발안일배 | B15: =$B$4 -> 15 | C15: =IFERROR(VLOOKUP(A15,'리치푸드 피벗'!A:SP,2,FALSE),0) -> 0 | D15: =IFERROR(ROUNDDOWN(C15/B15,0),"") -> 0 | E15: 발안 | F15: =IFERROR(C15-(D15*B15),"") -> 0
A16: VV16 (주)지에스리테일원주일배 | B16: =$B$4 -> 15 | C16: =IFERROR(VLOOKUP(A16,'리치푸드 피벗'!A:SP,2,FALSE),0) -> 0 | D16: =IFERROR(ROUNDDOWN(C16/B16,0),"") -> 0 | E16: 원주 | F16: =IFERROR(C16-(D16*B16),"") -> 0
A17: VV03 (주)지에스리테일(아신A) | B17: =$B$4 -> 15 | C17: =IFERROR(VLOOKUP(A17,'리치푸드 피벗'!A:SP,2,FALSE),0) -> 0 | D17: =IFERROR(ROUNDDOWN(C17/B17,0),"") -> 0 | E17: 아신 | F17: =IFERROR(C17-(D17*B17),"") -> 0
A19: 수도권 합계 | B19: =$B$4 -> 15 | C19: =SUM(C4:C17) -> 0 | D19: =IFERROR(ROUNDDOWN(C19/B19,0),"") -> 0 | F19: =IFERROR(C19-(D19*B19),"") -> 0
A21: VV57 (주)지에스리테일김해일배 | B21: =$B$4 -> 15 | C21: =IFERROR(VLOOKUP(A21,'리치푸드 피벗'!A:SP,2,FALSE),0) -> 0 | D21: =IFERROR(ROUNDDOWN(C21/B21,0),"") -> 0 | E21: 김해 | F21: =IFERROR(C21-(D21*B21),"") -> 0
A22: VV25 (주)지에스리테일진주일배 | B22: =$B$4 -> 15 | C22: =IFERROR(VLOOKUP(A22,'리치푸드 피벗'!A:SP,2,FALSE),0) -> 0 | D22: =IFERROR(ROUNDDOWN(C22/B22,0),"") -> 0 | E22: 진주 | F22: =IFERROR(C22-(D22*B22),"") -> 0
A23: VV20 (주)지에스리테일(해인CVS) | B23: =$B$4 -> 15 | C23: =IFERROR(VLOOKUP(A23,'리치푸드 피벗'!A:SP,2,FALSE),0) -> 0 | D23: =IFERROR(ROUNDDOWN(C23/B23,0),"") -> 0 | E23: 해인 | F23: =IFERROR(C23-(D23*B23),"") -> 0
A25: 경남(김해)합계 | B25: =$B$4 -> 15 | C25: =SUM(C21:C23) -> 0 | D25: =IFERROR(ROUNDDOWN(C25/B25,0),"") -> 0 | F25: =IFERROR(C25-(D25*B25),"") -> 0
A27: VV83 지에스리테일경산저온 | B27: =$B$4 -> 15 | C27: =IFERROR(VLOOKUP(A27,'리치푸드 피벗'!A:SP,2,FALSE),0) -> 0 | D27: =IFERROR(ROUNDDOWN(C27/B27,0),"") -> 0 | E27: 경산 | F27: =IFERROR(C27-(D27*B27),"") -> 0
A29: 경북(칠곡)합계 | B29: =$B$4 -> 15 | C29: =SUM(C27:C27) -> 0 | D29: =IFERROR(ROUNDDOWN(C29/B29,0),"") -> 0 | F29: =IFERROR(C29-(D29*B29),"") -> 0
A31: VV95 (주)지에스리테일신광주저온 | B31: =$B$4 -> 15 | C31: =IFERROR(VLOOKUP(A31,'리치푸드 피벗'!A:SP,2,FALSE),0) -> 0 | D31: =IFERROR(ROUNDDOWN(C31/B31,0),"") -> 0 | E31: 신광주 | F31: =IFERROR(C31-(D31*B31),"") -> 0
A32: VV65 ㈜지에스리테일익산일배 | B32: =$B$4 -> 15 | C32: =IFERROR(VLOOKUP(A32,'리치푸드 피벗'!A:SP,2,FALSE),0) -> 0 | D32: =IFERROR(ROUNDDOWN(C32/B32,0),"") -> 0 | E32: 익산 | F32: =IFERROR(C32-(D32*B32),"") -> 0
A34: 호남권 합계 | B34: =$B$4 -> 15 | C34: =SUM(C31:C32) -> 0 | D34: =IFERROR(ROUNDDOWN(C34/B34,0),"") -> 0 | F34: =IFERROR(C34-(D34*B34),"") -> 0
A36: VV92 (주)지에스리테일신제주저온 | B36: =$B$4 -> 15 | C36: =IFERROR(VLOOKUP(A36,'리치푸드 피벗'!A:SP,2,FALSE),0) -> 0 | D36: =IFERROR(ROUNDDOWN(C36/B36,0),"") -> 0 | E36: 신제주 | F36: =IFERROR(C36-(D36*B36),"") -> 0
A38: 총합계 | B38: =$B$4 -> 15 | C38: =SUM(C4:C17,C31:C32,C27:C27,C21:C23,C36) -> 0 | D38: =IFERROR(ROUNDDOWN(C38/B38,0),"") -> 0 | F38: =IFERROR(C38-(D38*B38),"") -> 0
A39: 총 박스/총 낱개수량 | B39: □ | D39: =SUM(D4:D17,D31:D32,D27:D27,D21:D23,D36) -> 0 | F39: =SUM(F4:F17,F31:F32,F27:F27,F21:F23,F36) -> 0
C40: =C19+C25+C29+C34+C36 -> 0
C41: =C40=C38 -> TRUE

Sheet 아미)수박스무디
A2: =TODAY() -> 46309 | B2: GS 아미 _냉동 □
A3: ='리치푸드 피벗'!A2 -> 10/15납품 | B3: 입수 | C3: 네이쳐)수박스무디 | D3: 박스 | E3: 센터명 | F3: 낱개
A4: VV98 (주)지에스리테일고촌저온 | B4: 12 | C4: =IFERROR(VLOOKUP(A4,'리치푸드 피벗'!A:SP,3,FALSE),0) -> 0 | D4: =IFERROR(ROUNDDOWN(C4/B4,0),"") -> 0 | E4: 고촌 | F4: =IFERROR(C4-(D4*B4),"") -> 0
A5: VV93 (주)지에스리테일곤지암센터 | B5: =$B$4 -> 12 | C5: =IFERROR(VLOOKUP(A5,'리치푸드 피벗'!A:SP,3,FALSE),0) -> 0 | D5: =IFERROR(ROUNDDOWN(C5/B5,0),"") -> 0 | E5: 곤지암 | F5: =IFERROR(C5-(D5*B5),"") -> 0 | H5: 아미방
A6: VV90 (주)지에스리테일포천저온 | B6: =$B$4 -> 12 | C6: =IFERROR(VLOOKUP(A6,'리치푸드 피벗'!A:SP,3,FALSE),0) -> 0 | D6: =IFERROR(ROUNDDOWN(C6/B6,0),"") -> 0 | E6: 포천 | F6: =IFERROR(C6-(D6*B6),"") -> 0
A7: VV85 지에스리테일신오산1저온 | B7: =$B$4 -> 12 | C7: =IFERROR(VLOOKUP(A7,'리치푸드 피벗'!A:SP,3,FALSE),0) -> 0 | D7: =IFERROR(ROUNDDOWN(C7/B7,0),"") -> 0 | E7: 신오산1 | F7: =IFERROR(C7-(D7*B7),"") -> 0
A8: VV04 (주)지에스리테일공주일배 | B8: =$B$4 -> 12 | C8: =IFERROR(VLOOKUP(A8,'리치푸드 피벗'!A:SP,3,FALSE),0) -> 0 | D8: =IFERROR(ROUNDDOWN(C8/B8,0),"") -> 0 | E8: 공주 | F8: =IFERROR(C8-(D8*B8),"") -> 0
A9: VV69 ㈜지에스리테일강릉일배센터 | B9: =$B$4 -> 12 | C9: =IFERROR(VLOOKUP(A9,'리치푸드 피벗'!A:SP,3,FALSE),0) -> 0 | D9: =IFERROR(ROUNDDOWN(C9/B9,0),"") -> 0 | E9: 강릉 | F9: =IFERROR(C9-(D9*B9),"") -> 0
A10: VV66 지에스리테일인천도화일배 | B10: =$B$4 -> 12 | C10: =IFERROR(VLOOKUP(A10,'리치푸드 피벗'!A:SP,3,FALSE),0) -> 0 | D10: =IFERROR(ROUNDDOWN(C10/B10,0),"") -> 0 | E10: 도화 | F10: =IFERROR(C10-(D10*B10),"") -> 0
A11: VV63 ㈜지에스리테일고양일배센터 | B11: =$B$4 -> 12 | C11: =IFERROR(VLOOKUP(A11,'리치푸드 피벗'!A:SP,3,FALSE),0) -> 0 | D11: =IFERROR(ROUNDDOWN(C11/B11,0),"") -> 0 | E11: 고양 | F11: =IFERROR(C11-(D11*B11),"") -> 0
A12: VV62 (주)지에스리테일김포2일배 | B12: =$B$4 -> 12 | C12: =IFERROR(VLOOKUP(A12,'리치푸드 피벗'!A:SP,3,FALSE),0) -> 0 | D12: =IFERROR(ROUNDDOWN(C12/B12,0),"") -> 0 | E12: 김포2 | F12: =IFERROR(C12-(D12*B12),"") -> 0
A13: VV53 (주)지에스리테일송파일배 | B13: =$B$4 -> 12 | C13: =IFERROR(VLOOKUP(A13,'리치푸드 피벗'!A:SP,3,FALSE),0) -> 24 | D13: =IFERROR(ROUNDDOWN(C13/B13,0),"") -> 2 | E13: 송파 | F13: =IFERROR(C13-(D13*B13),"") -> 0
A14: VV34 (주)지에스리테일청주일배 | B14: =$B$4 -> 12 | C14: =IFERROR(VLOOKUP(A14,'리치푸드 피벗'!A:SP,3,FALSE),0) -> 0 | D14: =IFERROR(ROUNDDOWN(C14/B14,0),"") -> 0 | E14: 청주 | F14: =IFERROR(C14-(D14*B14),"") -> 0
A15: VV17 (주)지에스리테일발안일배 | B15: =$B$4 -> 12 | C15: =IFERROR(VLOOKUP(A15,'리치푸드 피벗'!A:SP,3,FALSE),0) -> 0 | D15: =IFERROR(ROUNDDOWN(C15/B15,0),"") -> 0 | E15: 발안 | F15: =IFERROR(C15-(D15*B15),"") -> 0
A16: VV16 (주)지에스리테일원주일배 | B16: =$B$4 -> 12 | C16: =IFERROR(VLOOKUP(A16,'리치푸드 피벗'!A:SP,3,FALSE),0) -> 0 | D16: =IFERROR(ROUNDDOWN(C16/B16,0),"") -> 0 | E16: 원주 | F16: =IFERROR(C16-(D16*B16),"") -> 0
A17: VV03 (주)지에스리테일(아신A) | B17: =$B$4 -> 12 | C17: =IFERROR(VLOOKUP(A17,'리치푸드 피벗'!A:SP,3,FALSE),0) -> 0 | D17: =IFERROR(ROUNDDOWN(C17/B17,0),"") -> 0 | E17: 아신 | F17: =IFERROR(C17-(D17*B17),"") -> 0
A19: 수도권 합계 | B19: =$B$4 -> 12 | C19: =SUM(C4:C17) -> 24 | D19: =IFERROR(ROUNDDOWN(C19/B19,0),"") -> 2 | F19: =IFERROR(C19-(D19*B19),"") -> 0
A21: VV57 (주)지에스리테일김해일배 | B21: =$B$4 -> 12 | C21: =IFERROR(VLOOKUP(A21,'리치푸드 피벗'!A:SP,3,FALSE),0) -> 0 | D21: =IFERROR(ROUNDDOWN(C21/B21,0),"") -> 0 | E21: 김해 | F21: =IFERROR(C21-(D21*B21),"") -> 0
A22: VV25 (주)지에스리테일진주일배 | B22: =$B$4 -> 12 | C22: =IFERROR(VLOOKUP(A22,'리치푸드 피벗'!A:SP,3,FALSE),0) -> 0 | D22: =IFERROR(ROUNDDOWN(C22/B22,0),"") -> 0 | E22: 진주 | F22: =IFERROR(C22-(D22*B22),"") -> 0
A23: VV20 (주)지에스리테일(해인CVS) | B23: =$B$4 -> 12 | C23: =IFERROR(VLOOKUP(A23,'리치푸드 피벗'!A:SP,3,FALSE),0) -> 0 | D23: =IFERROR(ROUNDDOWN(C23/B23,0),"") -> 0 | E23: 해인 | F23: =IFERROR(C23-(D23*B23),"") -> 0
A25: 경남(김해)합계 | B25: =$B$4 -> 12 | C25: =SUM(C21:C23) -> 0 | D25: =IFERROR(ROUNDDOWN(C25/B25,0),"") -> 0 | F25: =IFERROR(C25-(D25*B25),"") -> 0
A27: VV83 지에스리테일경산저온 | B27: =$B$4 -> 12 | C27: =IFERROR(VLOOKUP(A27,'리치푸드 피벗'!A:SP,3,FALSE),0) -> 36 | D27: =IFERROR(ROUNDDOWN(C27/B27,0),"") -> 3 | E27: 경산 | F27: =IFERROR(C27-(D27*B27),"") -> 0
A29: 경북(칠곡)합계 | B29: =$B$4 -> 12 | C29: =SUM(C27:C27) -> 36 | D29: =IFERROR(ROUNDDOWN(C29/B29,0),"") -> 3 | F29: =IFERROR(C29-(D29*B29),"") -> 0
A31: VV95 (주)지에스리테일신광주저온 | B31: =$B$4 -> 12 | C31: =IFERROR(VLOOKUP(A31,'리치푸드 피벗'!A:SP,3,FALSE),0) -> 0 | D31: =IFERROR(ROUNDDOWN(C31/B31,0),"") -> 0 | E31: 신광주 | F31: =IFERROR(C31-(D31*B31),"") -> 0
A32: VV65 ㈜지에스리테일익산일배 | B32: =$B$4 -> 12 | C32: =IFERROR(VLOOKUP(A32,'리치푸드 피벗'!A:SP,3,FALSE),0) -> 0 | D32: =IFERROR(ROUNDDOWN(C32/B32,0),"") -> 0 | E32: 익산 | F32: =IFERROR(C32-(D32*B32),"") -> 0
A34: 호남권 합계 | B34: =$B$4 -> 12 | C34: =SUM(C31:C32) -> 0 | D34: =IFERROR(ROUNDDOWN(C34/B34,0),"") -> 0 | F34: =IFERROR(C34-(D34*B34),"") -> 0
A36: VV92 (주)지에스리테일신제주저온 | B36: =$B$4 -> 12 | C36: =IFERROR(VLOOKUP(A36,'리치푸드 피벗'!A:SP,3,FALSE),0) -> 0 | D36: =IFERROR(ROUNDDOWN(C36/B36,0),"") -> 0 | E36: 신제주 | F36: =IFERROR(C36-(D36*B36),"") -> 0
A38: 총합계 | B38: =$B$4 -> 12 | C38: =SUM(C4:C17,C31:C32,C27:C27,C21:C23,C36) -> 60 | D38: =IFERROR(ROUNDDOWN(C38/B38,0),"") -> 5 | F38: =IFERROR(C38-(D38*B38),"") -> 0
A39: 총 박스/총 낱개수량 | B39: □ | D39: =SUM(D4:D17,D31:D32,D27:D27,D21:D23,D36) -> 5 | F39: =SUM(F4:F17,F31:F32,F27:F27,F21:F23,F36) -> 0
C40: =C19+C25+C29+C34+C36 -> 60
C41: =C40=C38 -> TRUE

Sheet 아미)카페라떼스무디
A2: =TODAY() -> 46309 | B2: GS 아미 _냉동 □
A3: ='리치푸드 피벗'!A2 -> 10/15납품 | B3: 입수 | C3: 네이쳐)카페라떼스무디 | D3: 박스 | E3: 센터명 | F3: 낱개
A4: VV98 (주)지에스리테일고촌저온 | B4: 12 | C4: =IFERROR(VLOOKUP(A4,'리치푸드 피벗'!A:SP,4,FALSE),0) -> 0 | D4: =IFERROR(ROUNDDOWN(C4/B4,0),"") -> 0 | E4: 고촌 | F4: =IFERROR(C4-(D4*B4),"") -> 0
A5: VV93 (주)지에스리테일곤지암센터 | B5: =$B$4 -> 12 | C5: =IFERROR(VLOOKUP(A5,'리치푸드 피벗'!A:SP,4,FALSE),0) -> 0 | D5: =IFERROR(ROUNDDOWN(C5/B5,0),"") -> 0 | E5: 곤지암 | F5: =IFERROR(C5-(D5*B5),"") -> 0 | H5: 아미방
A6: VV90 (주)지에스리테일포천저온 | B6: =$B$4 -> 12 | C6: =IFERROR(VLOOKUP(A6,'리치푸드 피벗'!A:SP,4,FALSE),0) -> 0 | D6: =IFERROR(ROUNDDOWN(C6/B6,0),"") -> 0 | E6: 포천 | F6: =IFERROR(C6-(D6*B6),"") -> 0
A7: VV85 지에스리테일신오산1저온 | B7: =$B$4 -> 12 | C7: =IFERROR(VLOOKUP(A7,'리치푸드 피벗'!A:SP,4,FALSE),0) -> 0 | D7: =IFERROR(ROUNDDOWN(C7/B7,0),"") -> 0 | E7: 신오산1 | F7: =IFERROR(C7-(D7*B7),"") -> 0
A8: VV04 (주)지에스리테일공주일배 | B8: =$B$4 -> 12 | C8: =IFERROR(VLOOKUP(A8,'리치푸드 피벗'!A:SP,4,FALSE),0) -> 0 | D8: =IFERROR(ROUNDDOWN(C8/B8,0),"") -> 0 | E8: 공주 | F8: =IFERROR(C8-(D8*B8),"") -> 0
A9: VV69 ㈜지에스리테일강릉일배센터 | B9: =$B$4 -> 12 | C9: =IFERROR(VLOOKUP(A9,'리치푸드 피벗'!A:SP,4,FALSE),0) -> 0 | D9: =IFERROR(ROUNDDOWN(C9/B9,0),"") -> 0 | E9: 강릉 | F9: =IFERROR(C9-(D9*B9),"") -> 0
A10: VV66 지에스리테일인천도화일배 | B10: =$B$4 -> 12 | C10: =IFERROR(VLOOKUP(A10,'리치푸드 피벗'!A:SP,4,FALSE),0) -> 0 | D10: =IFERROR(ROUNDDOWN(C10/B10,0),"") -> 0 | E10: 도화 | F10: =IFERROR(C10-(D10*B10),"") -> 0
A11: VV63 ㈜지에스리테일고양일배센터 | B11: =$B$4 -> 12 | C11: =IFERROR(VLOOKUP(A11,'리치푸드 피벗'!A:SP,4,FALSE),0) -> 0 | D11: =IFERROR(ROUNDDOWN(C11/B11,0),"") -> 0 | E11: 고양 | F11: =IFERROR(C11-(D11*B11),"") -> 0
A12: VV62 (주)지에스리테일김포2일배 | B12: =$B$4 -> 12 | C12: =IFERROR(VLOOKUP(A12,'리치푸드 피벗'!A:SP,4,FALSE),0) -> 0 | D12: =IFERROR(ROUNDDOWN(C12/B12,0),"") -> 0 | E12: 김포2 | F12: =IFERROR(C12-(D12*B12),"") -> 0
A13: VV53 (주)지에스리테일송파일배 | B13: =$B$4 -> 12 | C13: =IFERROR(VLOOKUP(A13,'리치푸드 피벗'!A:SP,4,FALSE),0) -> 0 | D13: =IFERROR(ROUNDDOWN(C13/B13,0),"") -> 0 | E13: 송파 | F13: =IFERROR(C13-(D13*B13),"") -> 0
A14: VV34 (주)지에스리테일청주일배 | B14: =$B$4 -> 12 | C14: =IFERROR(VLOOKUP(A14,'리치푸드 피벗'!A:SP,4,FALSE),0) -> 0 | D14: =IFERROR(ROUNDDOWN(C14/B14,0),"") -> 0 | E14: 청주 | F14: =IFERROR(C14-(D14*B14),"") -> 0
A15: VV17 (주)지에스리테일발안일배 | B15: =$B$4 -> 12 | C15: =IFERROR(VLOOKUP(A15,'리치푸드 피벗'!A:SP,4,FALSE),0) -> 0 | D15: =IFERROR(ROUNDDOWN(C15/B15,0),"") -> 0 | E15: 발안 | F15: =IFERROR(C15-(D15*B15),"") -> 0
A16: VV16 (주)지에스리테일원주일배 | B16: =$B$4 -> 12 | C16: =IFERROR(VLOOKUP(A16,'리치푸드 피벗'!A:SP,4,FALSE),0) -> 0 | D16: =IFERROR(ROUNDDOWN(C16/B16,0),"") -> 0 | E16: 원주 | F16: =IFERROR(C16-(D16*B16),"") -> 0
A17: VV03 (주)지에스리테일(아신A) | B17: =$B$4 -> 12 | C17: =IFERROR(VLOOKUP(A17,'리치푸드 피벗'!A:SP,4,FALSE),0) -> 0 | D17: =IFERROR(ROUNDDOWN(C17/B17,0),"") -> 0 | E17: 아신 | F17: =IFERROR(C17-(D17*B17),"") -> 0
A19: 수도권 합계 | B19: =$B$4 -> 12 | C19: =SUM(C4:C17) -> 0 | D19: =IFERROR(ROUNDDOWN(C19/B19,0),"") -> 0 | F19: =IFERROR(C19-(D19*B19),"") -> 0
A21: VV57 (주)지에스리테일김해일배 | B21: =$B$4 -> 12 | C21: =IFERROR(VLOOKUP(A21,'리치푸드 피벗'!A:SP,4,FALSE),0) -> 0 | D21: =IFERROR(ROUNDDOWN(C21/B21,0),"") -> 0 | E21: 김해 | F21: =IFERROR(C21-(D21*B21),"") -> 0
A22: VV25 (주)지에스리테일진주일배 | B22: =$B$4 -> 12 | C22: =IFERROR(VLOOKUP(A22,'리치푸드 피벗'!A:SP,4,FALSE),0) -> 0 | D22: =IFERROR(ROUNDDOWN(C22/B22,0),"") -> 0 | E22: 진주 | F22: =IFERROR(C22-(D22*B22),"") -> 0
A23: VV20 (주)지에스리테일(해인CVS) | B23: =$B$4 -> 12 | C23: =IFERROR(VLOOKUP(A23,'리치푸드 피벗'!A:SP,4,FALSE),0) -> 0 | D23: =IFERROR(ROUNDDOWN(C23/B23,0),"") -> 0 | E23: 해인 | F23: =IFERROR(C23-(D23*B23),"") -> 0
A25: 경남(김해)합계 | B25: =$B$4 -> 12 | C25: =SUM(C21:C23) -> 0 | D25: =IFERROR(ROUNDDOWN(C25/B25,0),"") -> 0 | F25: =IFERROR(C25-(D25*B25),"") -> 0
A27: VV83 지에스리테일경산저온 | B27: =$B$4 -> 12 | C27: =IFERROR(VLOOKUP(A27,'리치푸드 피벗'!A:SP,4,FALSE),0) -> 0 | D27: =IFERROR(ROUNDDOWN(C27/B27,0),"") -> 0 | E27: 경산 | F27: =IFERROR(C27-(D27*B27),"") -> 0
A29: 경북(칠곡)합계 | B29: =$B$4 -> 12 | C29: =SUM(C27:C27) -> 0 | D29: =IFERROR(ROUNDDOWN(C29/B29,0),"") -> 0 | F29: =IFERROR(C29-(D29*B29),"") -> 0
A31: VV95 (주)지에스리테일신광주저온 | B31: =$B$4 -> 12 | C31: =IFERROR(VLOOKUP(A31,'리치푸드 피벗'!A:SP,4,FALSE),0) -> 0 | D31: =IFERROR(ROUNDDOWN(C31/B31,0),"") -> 0 | E31: 신광주 | F31: =IFERROR(C31-(D31*B31),"") -> 0
A32: VV65 ㈜지에스리테일익산일배 | B32: =$B$4 -> 12 | C32: =IFERROR(VLOOKUP(A32,'리치푸드 피벗'!A:SP,4,FALSE),0) -> 0 | D32: =IFERROR(ROUNDDOWN(C32/B32,0),"") -> 0 | E32: 익산 | F32: =IFERROR(C32-(D32*B32),"") -> 0
A34: 호남권 합계 | B34: =$B$4 -> 12 | C34: =SUM(C31:C32) -> 0 | D34: =IFERROR(ROUNDDOWN(C34/B34,0),"") -> 0 | F34: =IFERROR(C34-(D34*B34),"") -> 0
A36: VV92 (주)지에스리테일신제주저온 | B36: =$B$4 -> 12 | C36: =IFERROR(VLOOKUP(A36,'리치푸드 피벗'!A:SP,4,FALSE),0) -> 0 | D36: =IFERROR(ROUNDDOWN(C36/B36,0),"") -> 0 | E36: 신제주 | F36: =IFERROR(C36-(D36*B36),"") -> 0
A38: 총합계 | B38: =$B$4 -> 12 | C38: =SUM(C4:C17,C31:C32,C27:C27,C21:C23,C36) -> 0 | D38: =IFERROR(ROUNDDOWN(C38/B38,0),"") -> 0 | F38: =IFERROR(C38-(D38*B38),"") -> 0
A39: 총 박스/총 낱개수량 | B39: □ | D39: =SUM(D4:D17,D31:D32,D27:D27,D21:D23,D36) -> 0 | F39: =SUM(F4:F17,F31:F32,F27:F27,F21:F23,F36) -> 0
C40: =C19+C25+C29+C34+C36 -> 0
C41: =C40=C38 -> TRUE

Sheet 딸기바나나스무디
A2: =TODAY() -> 46309 | B2: GS 네이처 _냉동 □
A3: ='리치푸드 피벗'!A2 -> 10/15납품 | B3: 입수 | C3: 딸기바나나스무디 | D3: 박스 | E3: 센터명 | F3: 낱개
A4: VV98 (주)지에스리테일고촌저온 | B4: 15 | C4: =IFERROR(VLOOKUP(A4,'리치푸드 피벗'!A:SP,5,FALSE),0) -> 0 | D4: =IFERROR(ROUNDDOWN(C4/B4,0),"") -> 0 | E4: 고촌 | F4: =IFERROR(C4-(D4*B4),"") -> 0
A5: VV93 (주)지에스리테일곤지암센터 | B5: =$B$4 -> 15 | C5: =IFERROR(VLOOKUP(A5,'리치푸드 피벗'!A:SP,5,FALSE),0) -> 0 | D5: =IFERROR(ROUNDDOWN(C5/B5,0),"") -> 0 | E5: 곤지암 | F5: =IFERROR(C5-(D5*B5),"") -> 0 | H5: 네이처
A6: VV90 (주)지에스리테일포천저온 | B6: =$B$4 -> 15 | C6: =IFERROR(VLOOKUP(A6,'리치푸드 피벗'!A:SP,5,FALSE),0) -> 0 | D6: =IFERROR(ROUNDDOWN(C6/B6,0),"") -> 0 | E6: 포천 | F6: =IFERROR(C6-(D6*B6),"") -> 0
A7: VV85 지에스리테일신오산1저온 | B7: =$B$4 -> 15 | C7: =IFERROR(VLOOKUP(A7,'리치푸드 피벗'!A:SP,5,FALSE),0) -> 0 | D7: =IFERROR(ROUNDDOWN(C7/B7,0),"") -> 0 | E7: 신오산1 | F7: =IFERROR(C7-(D7*B7),"") -> 0
A8: VV04 (주)지에스리테일공주일배 | B8: =$B$4 -> 15 | C8: =IFERROR(VLOOKUP(A8,'리치푸드 피벗'!A:SP,5,FALSE),0) -> 0 | D8: =IFERROR(ROUNDDOWN(C8/B8,0),"") -> 0 | E8: 공주 | F8: =IFERROR(C8-(D8*B8),"") -> 0
A9: VV69 ㈜지에스리테일강릉일배센터 | B9: =$B$4 -> 15 | C9: =IFERROR(VLOOKUP(A9,'리치푸드 피벗'!A:SP,5,FALSE),0) -> 0 | D9: =IFERROR(ROUNDDOWN(C9/B9,0),"") -> 0 | E9: 강릉 | F9: =IFERROR(C9-(D9*B9),"") -> 0
A10: VV66 지에스리테일인천도화일배 | B10: =$B$4 -> 15 | C10: =IFERROR(VLOOKUP(A10,'리치푸드 피벗'!A:SP,5,FALSE),0) -> 0 | D10: =IFERROR(ROUNDDOWN(C10/B10,0),"") -> 0 | E10: 도화 | F10: =IFERROR(C10-(D10*B10),"") -> 0
A11: VV63 ㈜지에스리테일고양일배센터 | B11: =$B$4 -> 15 | C11: =IFERROR(VLOOKUP(A11,'리치푸드 피벗'!A:SP,5,FALSE),0) -> 0 | D11: =IFERROR(ROUNDDOWN(C11/B11,0),"") -> 0 | E11: 고양 | F11: =IFERROR(C11-(D11*B11),"") -> 0
A12: VV62 (주)지에스리테일김포2일배 | B12: =$B$4 -> 15 | C12: =IFERROR(VLOOKUP(A12,'리치푸드 피벗'!A:SP,5,FALSE),0) -> 0 | D12: =IFERROR(ROUNDDOWN(C12/B12,0),"") -> 0 | E12: 김포2 | F12: =IFERROR(C12-(D12*B12),"") -> 0
A13: VV53 (주)지에스리테일송파일배 | B13: =$B$4 -> 15 | C13: =IFERROR(VLOOKUP(A13,'리치푸드 피벗'!A:SP,5,FALSE),0) -> 15 | D13: =IFERROR(ROUNDDOWN(C13/B13,0),"") -> 1 | E13: 송파 | F13: =IFERROR(C13-(D13*B13),"") -> 0
A14: VV34 (주)지에스리테일청주일배 | B14: =$B$4 -> 15 | C14: =IFERROR(VLOOKUP(A14,'리치푸드 피벗'!A:SP,5,FALSE),0) -> 0 | D14: =IFERROR(ROUNDDOWN(C14/B14,0),"") -> 0 | E14: 청주 | F14: =IFERROR(C14-(D14*B14),"") -> 0
A15: VV17 (주)지에스리테일발안일배 | B15: =$B$4 -> 15 | C15: =IFERROR(VLOOKUP(A15,'리치푸드 피벗'!A:SP,5,FALSE),0) -> 0 | D15: =IFERROR(ROUNDDOWN(C15/B15,0),"") -> 0 | E15: 발안 | F15: =IFERROR(C15-(D15*B15),"") -> 0
A16: VV16 (주)지에스리테일원주일배 | B16: =$B$4 -> 15 | C16: =IFERROR(VLOOKUP(A16,'리치푸드 피벗'!A:SP,5,FALSE),0) -> 15 | D16: =IFERROR(ROUNDDOWN(C16/B16,0),"") -> 1 | E16: 원주 | F16: =IFERROR(C16-(D16*B16),"") -> 0
A17: VV03 (주)지에스리테일(아신A) | B17: =$B$4 -> 15 | C17: =IFERROR(VLOOKUP(A17,'리치푸드 피벗'!A:SP,5,FALSE),0) -> 0 | D17: =IFERROR(ROUNDDOWN(C17/B17,0),"") -> 0 | E17: 아신 | F17: =IFERROR(C17-(D17*B17),"") -> 0
A19: 수도권 합계 | B19: =$B$4 -> 15 | C19: =SUM(C4:C17) -> 30 | D19: =IFERROR(ROUNDDOWN(C19/B19,0),"") -> 2 | F19: =IFERROR(C19-(D19*B19),"") -> 0
A21: VV57 (주)지에스리테일김해일배 | B21: =$B$4 -> 15 | C21: =IFERROR(VLOOKUP(A21,'리치푸드 피벗'!A:SP,5,FALSE),0) -> 0 | D21: =IFERROR(ROUNDDOWN(C21/B21,0),"") -> 0 | E21: 김해 | F21: =IFERROR(C21-(D21*B21),"") -> 0
A22: VV25 (주)지에스리테일진주일배 | B22: =$B$4 -> 15 | C22: =IFERROR(VLOOKUP(A22,'리치푸드 피벗'!A:SP,5,FALSE),0) -> 0 | D22: =IFERROR(ROUNDDOWN(C22/B22,0),"") -> 0 | E22: 진주 | F22: =IFERROR(C22-(D22*B22),"") -> 0
A23: VV20 (주)지에스리테일(해인CVS) | B23: =$B$4 -> 15 | C23: =IFERROR(VLOOKUP(A23,'리치푸드 피벗'!A:SP,5,FALSE),0) -> 0 | D23: =IFERROR(ROUNDDOWN(C23/B23,0),"") -> 0 | E23: 해인 | F23: =IFERROR(C23-(D23*B23),"") -> 0
A25: 경남(김해)합계 | B25: =$B$4 -> 15 | C25: =SUM(C21:C23) -> 0 | D25: =IFERROR(ROUNDDOWN(C25/B25,0),"") -> 0 | F25: =IFERROR(C25-(D25*B25),"") -> 0
A27: VV83 지에스리테일경산저온 | B27: =$B$4 -> 15 | C27: =IFERROR(VLOOKUP(A27,'리치푸드 피벗'!A:SP,5,FALSE),0) -> 0 | D27: =IFERROR(ROUNDDOWN(C27/B27,0),"") -> 0 | E27: 경산 | F27: =IFERROR(C27-(D27*B27),"") -> 0
A29: 경북(칠곡)합계 | B29: =$B$4 -> 15 | C29: =SUM(C27:C27) -> 0 | D29: =IFERROR(ROUNDDOWN(C29/B29,0),"") -> 0 | F29: =IFERROR(C29-(D29*B29),"") -> 0
A31: VV95 (주)지에스리테일신광주저온 | B31: =$B$4 -> 15 | C31: =IFERROR(VLOOKUP(A31,'리치푸드 피벗'!A:SP,5,FALSE),0) -> 0 | D31: =IFERROR(ROUNDDOWN(C31/B31,0),"") -> 0 | E31: 신광주 | F31: =IFERROR(C31-(D31*B31),"") -> 0
A32: VV65 ㈜지에스리테일익산일배 | B32: =$B$4 -> 15 | C32: =IFERROR(VLOOKUP(A32,'리치푸드 피벗'!A:SP,5,FALSE),0) -> 0 | D32: =IFERROR(ROUNDDOWN(C32/B32,0),"") -> 0 | E32: 익산 | F32: =IFERROR(C32-(D32*B32),"") -> 0
A34: 호남권 합계 | B34: =$B$4 -> 15 | C34: =SUM(C31:C32) -> 0 | D34: =IFERROR(ROUNDDOWN(C34/B34,0),"") -> 0 | F34: =IFERROR(C34-(D34*B34),"") -> 0
A36: VV92 (주)지에스리테일신제주저온 | B36: =$B$4 -> 15 | C36: =IFERROR(VLOOKUP(A36,'리치푸드 피벗'!A:SP,5,FALSE),0) -> 0 | D36: =IFERROR(ROUNDDOWN(C36/B36,0),"") -> 0 | E36: 신제주 | F36: =IFERROR(C36-(D36*B36),"") -> 0
A38: 총합계 | B38: =$B$4 -> 15 | C38: =SUM(C4:C17,C31:C32,C27:C27,C21:C23,C36) -> 30 | D38: =IFERROR(ROUNDDOWN(C38/B38,0),"") -> 2 | F38: =IFERROR(C38-(D38*B38),"") -> 0
A39: 총 박스/총 낱개수량 | B39: □ | D39: =SUM(D4:D17,D31:D32,D27:D27,D21:D23,D36) -> 2 | F39: =SUM(F4:F17,F31:F32,F27:F27,F21:F23,F36) -> 0
C40: =C19+C25+C29+C34+C36 -> 30
C41: =C40=C38 -> TRUE

Sheet 딸기블루베리망고스무디
A2: =TODAY() -> 46309 | B2: GS 네이처 _냉동 □
A3: ='리치푸드 피벗'!A2 -> 10/15납품 | B3: 입수 | C3: 딸기블루베리망고스무디 | D3: 박스 | E3: 센터명 | F3: 낱개
A4: VV98 (주)지에스리테일고촌저온 | B4: 15 | C4: =IFERROR(VLOOKUP(A4,'리치푸드 피벗'!A:SP,6,FALSE),0) -> 0 | D4: =IFERROR(ROUNDDOWN(C4/B4,0),"") -> 0 | E4: 고촌 | F4: =IFERROR(C4-(D4*B4),"") -> 0
A5: VV93 (주)지에스리테일곤지암센터 | B5: =$B$4 -> 15 | C5: =IFERROR(VLOOKUP(A5,'리치푸드 피벗'!A:SP,6,FALSE),0) -> 0 | D5: =IFERROR(ROUNDDOWN(C5/B5,0),"") -> 0 | E5: 곤지암 | F5: =IFERROR(C5-(D5*B5),"") -> 0 | H5: 네이처
A6: VV90 (주)지에스리테일포천저온 | B6: =$B$4 -> 15 | C6: =IFERROR(VLOOKUP(A6,'리치푸드 피벗'!A:SP,6,FALSE),0) -> 0 | D6: =IFERROR(ROUNDDOWN(C6/B6,0),"") -> 0 | E6: 포천 | F6: =IFERROR(C6-(D6*B6),"") -> 0
A7: VV85 지에스리테일신오산1저온 | B7: =$B$4 -> 15 | C7: =IFERROR(VLOOKUP(A7,'리치푸드 피벗'!A:SP,6,FALSE),0) -> 0 | D7: =IFERROR(ROUNDDOWN(C7/B7,0),"") -> 0 | E7: 신오산1 | F7: =IFERROR(C7-(D7*B7),"") -> 0
A8: VV04 (주)지에스리테일공주일배 | B8: =$B$4 -> 15 | C8: =IFERROR(VLOOKUP(A8,'리치푸드 피벗'!A:SP,6,FALSE),0) -> 0 | D8: =IFERROR(ROUNDDOWN(C8/B8,0),"") -> 0 | E8: 공주 | F8: =IFERROR(C8-(D8*B8),"") -> 0
A9: VV69 ㈜지에스리테일강릉일배센터 | B9: =$B$4 -> 15 | C9: =IFERROR(VLOOKUP(A9,'리치푸드 피벗'!A:SP,6,FALSE),0) -> 0 | D9: =IFERROR(ROUNDDOWN(C9/B9,0),"") -> 0 | E9: 강릉 | F9: =IFERROR(C9-(D9*B9),"") -> 0
A10: VV66 지에스리테일인천도화일배 | B10: =$B$4 -> 15 | C10: =IFERROR(VLOOKUP(A10,'리치푸드 피벗'!A:SP,6,FALSE),0) -> 0 | D10: =IFERROR(ROUNDDOWN(C10/B10,0),"") -> 0 | E10: 도화 | F10: =IFERROR(C10-(D10*B10),"") -> 0
A11: VV63 ㈜지에스리테일고양일배센터 | B11: =$B$4 -> 15 | C11: =IFERROR(VLOOKUP(A11,'리치푸드 피벗'!A:SP,6,FALSE),0) -> 0 | D11: =IFERROR(ROUNDDOWN(C11/B11,0),"") -> 0 | E11: 고양 | F11: =IFERROR(C11-(D11*B11),"") -> 0
A12: VV62 (주)지에스리테일김포2일배 | B12: =$B$4 -> 15 | C12: =IFERROR(VLOOKUP(A12,'리치푸드 피벗'!A:SP,6,FALSE),0) -> 15 | D12: =IFERROR(ROUNDDOWN(C12/B12,0),"") -> 1 | E12: 김포2 | F12: =IFERROR(C12-(D12*B12),"") -> 0
A13: VV53 (주)지에스리테일송파일배 | B13: =$B$4 -> 15 | C13: =IFERROR(VLOOKUP(A13,'리치푸드 피벗'!A:SP,6,FALSE),0) -> 0 | D13: =IFERROR(ROUNDDOWN(C13/B13,0),"") -> 0 | E13: 송파 | F13: =IFERROR(C13-(D13*B13),"") -> 0
A14: VV34 (주)지에스리테일청주일배 | B14: =$B$4 -> 15 | C14: =IFERROR(VLOOKUP(A14,'리치푸드 피벗'!A:SP,6,FALSE),0) -> 0 | D14: =IFERROR(ROUNDDOWN(C14/B14,0),"") -> 0 | E14: 청주 | F14: =IFERROR(C14-(D14*B14),"") -> 0
A15: VV17 (주)지에스리테일발안일배 | B15: =$B$4 -> 15 | C15: =IFERROR(VLOOKUP(A15,'리치푸드 피벗'!A:SP,6,FALSE),0) -> 0 | D15: =IFERROR(ROUNDDOWN(C15/B15,0),"") -> 0 | E15: 발안 | F15: =IFERROR(C15-(D15*B15),"") -> 0
A16: VV16 (주)지에스리테일원주일배 | B16: =$B$4 -> 15 | C16: =IFERROR(VLOOKUP(A16,'리치푸드 피벗'!A:SP,6,FALSE),0) -> 0 | D16: =IFERROR(ROUNDDOWN(C16/B16,0),"") -> 0 | E16: 원주 | F16: =IFERROR(C16-(D16*B16),"") -> 0
A17: VV03 (주)지에스리테일(아신A) | B17: =$B$4 -> 15 | C17: =IFERROR(VLOOKUP(A17,'리치푸드 피벗'!A:SP,6,FALSE),0) -> 0 | D17: =IFERROR(ROUNDDOWN(C17/B17,0),"") -> 0 | E17: 아신 | F17: =IFERROR(C17-(D17*B17),"") -> 0
A19: 수도권 합계 | B19: =$B$4 -> 15 | C19: =SUM(C4:C17) -> 15 | D19: =IFERROR(ROUNDDOWN(C19/B19,0),"") -> 1 | F19: =IFERROR(C19-(D19*B19),"") -> 0
A21: VV57 (주)지에스리테일김해일배 | B21: =$B$4 -> 15 | C21: =IFERROR(VLOOKUP(A21,'리치푸드 피벗'!A:SP,6,FALSE),0) -> 0 | D21: =IFERROR(ROUNDDOWN(C21/B21,0),"") -> 0 | E21: 김해 | F21: =IFERROR(C21-(D21*B21),"") -> 0
A22: VV25 (주)지에스리테일진주일배 | B22: =$B$4 -> 15 | C22: =IFERROR(VLOOKUP(A22,'리치푸드 피벗'!A:SP,6,FALSE),0) -> 0 | D22: =IFERROR(ROUNDDOWN(C22/B22,0),"") -> 0 | E22: 진주 | F22: =IFERROR(C22-(D22*B22),"") -> 0
A23: VV20 (주)지에스리테일(해인CVS) | B23: =$B$4 -> 15 | C23: =IFERROR(VLOOKUP(A23,'리치푸드 피벗'!A:SP,6,FALSE),0) -> 0 | D23: =IFERROR(ROUNDDOWN(C23/B23,0),"") -> 0 | E23: 해인 | F23: =IFERROR(C23-(D23*B23),"") -> 0
A25: 경남(김해)합계 | B25: =$B$4 -> 15 | C25: =SUM(C21:C23) -> 0 | D25: =IFERROR(ROUNDDOWN(C25/B25,0),"") -> 0 | F25: =IFERROR(C25-(D25*B25),"") -> 0
A27: VV83 지에스리테일경산저온 | B27: =$B$4 -> 15 | C27: =IFERROR(VLOOKUP(A27,'리치푸드 피벗'!A:SP,6,FALSE),0) -> 0 | D27: =IFERROR(ROUNDDOWN(C27/B27,0),"") -> 0 | E27: 경산 | F27: =IFERROR(C27-(D27*B27),"") -> 0
A29: 경북(칠곡)합계 | B29: =$B$4 -> 15 | C29: =SUM(C27:C27) -> 0 | D29: =IFERROR(ROUNDDOWN(C29/B29,0),"") -> 0 | F29: =IFERROR(C29-(D29*B29),"") -> 0
A31: VV95 (주)지에스리테일신광주저온 | B31: =$B$4 -> 15 | C31: =IFERROR(VLOOKUP(A31,'리치푸드 피벗'!A:SP,6,FALSE),0) -> 15 | D31: =IFERROR(ROUNDDOWN(C31/B31,0),"") -> 1 | E31: 신광주 | F31: =IFERROR(C31-(D31*B31),"") -> 0
A32: VV65 ㈜지에스리테일익산일배 | B32: =$B$4 -> 15 | C32: =IFERROR(VLOOKUP(A32,'리치푸드 피벗'!A:SP,6,FALSE),0) -> 0 | D32: =IFERROR(ROUNDDOWN(C32/B32,0),"") -> 0 | E32: 익산 | F32: =IFERROR(C32-(D32*B32),"") -> 0
A34: 호남권 합계 | B34: =$B$4 -> 15 | C34: =SUM(C31:C32) -> 15 | D34: =IFERROR(ROUNDDOWN(C34/B34,0),"") -> 1 | F34: =IFERROR(C34-(D34*B34),"") -> 0
A36: VV92 (주)지에스리테일신제주저온 | B36: =$B$4 -> 15 | C36: =IFERROR(VLOOKUP(A36,'리치푸드 피벗'!A:SP,6,FALSE),0) -> 0 | D36: =IFERROR(ROUNDDOWN(C36/B36,0),"") -> 0 | E36: 신제주 | F36: =IFERROR(C36-(D36*B36),"") -> 0
A38: 총합계 | B38: =$B$4 -> 15 | C38: =SUM(C4:C17,C31:C32,C27:C27,C21:C23,C36) -> 30 | D38: =IFERROR(ROUNDDOWN(C38/B38,0),"") -> 2 | F38: =IFERROR(C38-(D38*B38),"") -> 0
A39: 총 박스/총 낱개수량 | B39: □ | D39: =SUM(D4:D17,D31:D32,D27:D27,D21:D23,D36) -> 2 | F39: =SUM(F4:F17,F31:F32,F27:F27,F21:F23,F36) -> 0
C40: =C19+C25+C29+C34+C36 -> 30
C41: =C40=C38 -> TRUE

Sheet 망고바나나스무디
A2: =TODAY() -> 46309 | B2: GS 네이처 _냉동 □
A3: ='리치푸드 피벗'!A2 -> 10/15납품 | B3: 입수 | C3: 망고바나나스무디 | D3: 박스 | E3: 센터명 | F3: 낱개
A4: VV98 (주)지에스리테일고촌저온 | B4: 15 | C4: =IFERROR(VLOOKUP(A4,'리치푸드 피벗'!A:SP,7,FALSE),0) -> 0 | D4: =IFERROR(ROUNDDOWN(C4/B4,0),"") -> 0 | E4: 고촌 | F4: =IFERROR(C4-(D4*B4),"") -> 0
A5: VV93 (주)지에스리테일곤지암센터 | B5: =$B$4 -> 15 | C5: =IFERROR(VLOOKUP(A5,'리치푸드 피벗'!A:SP,7,FALSE),0) -> 0 | D5: =IFERROR(ROUNDDOWN(C5/B5,0),"") -> 0 | E5: 곤지암 | F5: =IFERROR(C5-(D5*B5),"") -> 0 | H5: 네이처
A6: VV90 (주)지에스리테일포천저온 | B6: =$B$4 -> 15 | C6: =IFERROR(VLOOKUP(A6,'리치푸드 피벗'!A:SP,7,FALSE),0) -> 0 | D6: =IFERROR(ROUNDDOWN(C6/B6,0),"") -> 0 | E6: 포천 | F6: =IFERROR(C6-(D6*B6),"") -> 0
A7: VV85 지에스리테일신오산1저온 | B7: =$B$4 -> 15 | C7: =IFERROR(VLOOKUP(A7,'리치푸드 피벗'!A:SP,7,FALSE),0) -> 15 | D7: =IFERROR(ROUNDDOWN(C7/B7,0),"") -> 1 | E7: 신오산1 | F7: =IFERROR(C7-(D7*B7),"") -> 0
A8: VV04 (주)지에스리테일공주일배 | B8: =$B$4 -> 15 | C8: =IFERROR(VLOOKUP(A8,'리치푸드 피벗'!A:SP,7,FALSE),0) -> 0 | D8: =IFERROR(ROUNDDOWN(C8/B8,0),"") -> 0 | E8: 공주 | F8: =IFERROR(C8-(D8*B8),"") -> 0
A9: VV69 ㈜지에스리테일강릉일배센터 | B9: =$B$4 -> 15 | C9: =IFERROR(VLOOKUP(A9,'리치푸드 피벗'!A:SP,7,FALSE),0) -> 0 | D9: =IFERROR(ROUNDDOWN(C9/B9,0),"") -> 0 | E9: 강릉 | F9: =IFERROR(C9-(D9*B9),"") -> 0
A10: VV66 지에스리테일인천도화일배 | B10: =$B$4 -> 15 | C10: =IFERROR(VLOOKUP(A10,'리치푸드 피벗'!A:SP,7,FALSE),0) -> 0 | D10: =IFERROR(ROUNDDOWN(C10/B10,0),"") -> 0 | E10: 도화 | F10: =IFERROR(C10-(D10*B10),"") -> 0
A11: VV63 ㈜지에스리테일고양일배센터 | B11: =$B$4 -> 15 | C11: =IFERROR(VLOOKUP(A11,'리치푸드 피벗'!A:SP,7,FALSE),0) -> 15 | D11: =IFERROR(ROUNDDOWN(C11/B11,0),"") -> 1 | E11: 고양 | F11: =IFERROR(C11-(D11*B11),"") -> 0
A12: VV62 (주)지에스리테일김포2일배 | B12: =$B$4 -> 15 | C12: =IFERROR(VLOOKUP(A12,'리치푸드 피벗'!A:SP,7,FALSE),0) -> 0 | D12: =IFERROR(ROUNDDOWN(C12/B12,0),"") -> 0 | E12: 김포2 | F12: =IFERROR(C12-(D12*B12),"") -> 0
A13: VV53 (주)지에스리테일송파일배 | B13: =$B$4 -> 15 | C13: =IFERROR(VLOOKUP(A13,'리치푸드 피벗'!A:SP,7,FALSE),0) -> 0 | D13: =IFERROR(ROUNDDOWN(C13/B13,0),"") -> 0 | E13: 송파 | F13: =IFERROR(C13-(D13*B13),"") -> 0
A14: VV34 (주)지에스리테일청주일배 | B14: =$B$4 -> 15 | C14: =IFERROR(VLOOKUP(A14,'리치푸드 피벗'!A:SP,7,FALSE),0) -> 0 | D14: =IFERROR(ROUNDDOWN(C14/B14,0),"") -> 0 | E14: 청주 | F14: =IFERROR(C14-(D14*B14),"") -> 0
A15: VV17 (주)지에스리테일발안일배 | B15: =$B$4 -> 15 | C15: =IFERROR(VLOOKUP(A15,'리치푸드 피벗'!A:SP,7,FALSE),0) -> 0 | D15: =IFERROR(ROUNDDOWN(C15/B15,0),"") -> 0 | E15: 발안 | F15: =IFERROR(C15-(D15*B15),"") -> 0
A16: VV16 (주)지에스리테일원주일배 | B16: =$B$4 -> 15 | C16: =IFERROR(VLOOKUP(A16,'리치푸드 피벗'!A:SP,7,FALSE),0) -> 0 | D16: =IFERROR(ROUNDDOWN(C16/B16,0),"") -> 0 | E16: 원주 | F16: =IFERROR(C16-(D16*B16),"") -> 0
A17: VV03 (주)지에스리테일(아신A) | B17: =$B$4 -> 15 | C17: =IFERROR(VLOOKUP(A17,'리치푸드 피벗'!A:SP,7,FALSE),0) -> 0 | D17: =IFERROR(ROUNDDOWN(C17/B17,0),"") -> 0 | E17: 아신 | F17: =IFERROR(C17-(D17*B17),"") -> 0
A19: 수도권 합계 | B19: =$B$4 -> 15 | C19: =SUM(C4:C17) -> 30 | D19: =IFERROR(ROUNDDOWN(C19/B19,0),"") -> 2 | F19: =IFERROR(C19-(D19*B19),"") -> 0
A21: VV57 (주)지에스리테일김해일배 | B21: =$B$4 -> 15 | C21: =IFERROR(VLOOKUP(A21,'리치푸드 피벗'!A:SP,7,FALSE),0) -> 0 | D21: =IFERROR(ROUNDDOWN(C21/B21,0),"") -> 0 | E21: 김해 | F21: =IFERROR(C21-(D21*B21),"") -> 0
A22: VV25 (주)지에스리테일진주일배 | B22: =$B$4 -> 15 | C22: =IFERROR(VLOOKUP(A22,'리치푸드 피벗'!A:SP,7,FALSE),0) -> 0 | D22: =IFERROR(ROUNDDOWN(C22/B22,0),"") -> 0 | E22: 진주 | F22: =IFERROR(C22-(D22*B22),"") -> 0
A23: VV20 (주)지에스리테일(해인CVS) | B23: =$B$4 -> 15 | C23: =IFERROR(VLOOKUP(A23,'리치푸드 피벗'!A:SP,7,FALSE),0) -> 0 | D23: =IFERROR(ROUNDDOWN(C23/B23,0),"") -> 0 | E23: 해인 | F23: =IFERROR(C23-(D23*B23),"") -> 0
A25: 경남(김해)합계 | B25: =$B$4 -> 15 | C25: =SUM(C21:C23) -> 0 | D25: =IFERROR(ROUNDDOWN(C25/B25,0),"") -> 0 | F25: =IFERROR(C25-(D25*B25),"") -> 0
A27: VV83 지에스리테일경산저온 | B27: =$B$4 -> 15 | C27: =IFERROR(VLOOKUP(A27,'리치푸드 피벗'!A:SP,7,FALSE),0) -> 0 | D27: =IFERROR(ROUNDDOWN(C27/B27,0),"") -> 0 | E27: 경산 | F27: =IFERROR(C27-(D27*B27),"") -> 0
A29: 경북(칠곡)합계 | B29: =$B$4 -> 15 | C29: =SUM(C27:C27) -> 0 | D29: =IFERROR(ROUNDDOWN(C29/B29,0),"") -> 0 | F29: =IFERROR(C29-(D29*B29),"") -> 0
A31: VV95 (주)지에스리테일신광주저온 | B31: =$B$4 -> 15 | C31: =IFERROR(VLOOKUP(A31,'리치푸드 피벗'!A:SP,7,FALSE),0) -> 0 | D31: =IFERROR(ROUNDDOWN(C31/B31,0),"") -> 0 | E31: 신광주 | F31: =IFERROR(C31-(D31*B31),"") -> 0
A32: VV65 ㈜지에스리테일익산일배 | B32: =$B$4 -> 15 | C32: =IFERROR(VLOOKUP(A32,'리치푸드 피벗'!A:SP,7,FALSE),0) -> 0 | D32: =IFERROR(ROUNDDOWN(C32/B32,0),"") -> 0 | E32: 익산 | F32: =IFERROR(C32-(D32*B32),"") -> 0
A34: 호남권 합계 | B34: =$B$4 -> 15 | C34: =SUM(C31:C32) -> 0 | D34: =IFERROR(ROUNDDOWN(C34/B34,0),"") -> 0 | F34: =IFERROR(C34-(D34*B34),"") -> 0
A36: VV92 (주)지에스리테일신제주저온 | B36: =$B$4 -> 15 | C36: =IFERROR(VLOOKUP(A36,'리치푸드 피벗'!A:SP,7,FALSE),0) -> 0 | D36: =IFERROR(ROUNDDOWN(C36/B36,0),"") -> 0 | E36: 신제주 | F36: =IFERROR(C36-(D36*B36),"") -> 0
A38: 총합계 | B38: =$B$4 -> 15 | C38: =SUM(C4:C17,C31:C32,C27:C27,C21:C23,C36) -> 30 | D38: =IFERROR(ROUNDDOWN(C38/B38,0),"") -> 2 | F38: =IFERROR(C38-(D38*B38),"") -> 0
A39: 총 박스/총 낱개수량 | B39: □ | D39: =SUM(D4:D17,D31:D32,D27:D27,D21:D23,D36) -> 2 | F39: =SUM(F4:F17,F31:F32,F27:F27,F21:F23,F36) -> 0
C40: =C19+C25+C29+C34+C36 -> 30
C41: =C40=C38 -> TRUE

Sheet H2 피벗
A1: 10/14 | B1: 열 레이블
A2: 10/15 납품 | B2: 태극당)우유팥바70ML | C2: 태극당)인절미콘150ML | D2: 총합계
A3: VV16 (주)지에스리테일원주일배 | C3: 192 | D3: 192
A4: VV69 ㈜지에스리테일강릉일배센터 | B4: 600 | C4: 48 | D4: 648
A5: VV57 (주)지에스리테일김해일배 | B5: 1000 | C5: 480 | D5: 1480
A6: VV25 (주)지에스리테일진주일배 | B6: 80 | C6: 192 | D6: 272
A7: VV95 (주)지에스리테일신광주저온 | B7: 120 | C7: 264 | D7: 384
A8: VV83 지에스리테일경산저온 | B8: 1200 | C8: 384 | D8: 1584
A9: VV34 (주)지에스리테일청주일배 | C9: 48 | D9: 48
A10: VV04 (주)지에스리테일공주일배 | B10: 480 | D10: 480
A11: VV65 ㈜지에스리테일익산일배 | B11: 120 | C11: 360 | D11: 480
A12: VV03 (주)지에스리테일(아신A) | B12: 1040 | C12: 24 | D12: 1064
A13: VV63 ㈜지에스리테일고양일배센터 | B13: 600 | C13: 672 | D13: 1272
A14: VV62 (주)지에스리테일김포2일배 | B14: 200 | C14: 192 | D14: 392
A15: VV98 (주)지에스리테일고촌저온 | B15: 280 | C15: 384 | D15: 664
A16: VV90 (주)지에스리테일포천저온 | C16: 288 | D16: 288
A17: VV85 지에스리테일신오산1저온 | B17: 680 | C17: 192 | D17: 872
A18: VV66 지에스리테일인천도화일배 | B18: 80 | C18: 96 | D18: 176
A19: VV17 (주)지에스리테일발안일배 | B19: 240 | C19: 120 | D19: 360
A20: VV53 (주)지에스리테일송파일배 | B20: 1880 | C20: 528 | D20: 2408
A21: VV93 (주)지에스리테일곤지암센터 | B21: 360 | C21: 192 | D21: 552
A22: 총합계 | B22: 8960 | C22: 4656 | D22: 13616

Sheet 태극당)우유팥바70ML
A2: =TODAY() -> 46309 | B2: GS냉동 H2 □
A3: ='H2 피벗'!A2 -> 10/15 납품 | B3: 입수 | C3: 태극당)우유팥바70ML | D3: 박스 | E3: 센터명 | F3: 낱개
A4: VV98 (주)지에스리테일고촌저온 | B4: 40 | C4: =IFERROR(VLOOKUP(A4,'H2 피벗'!A:SH,2,FALSE),0) -> 280 | D4: =IFERROR(ROUNDDOWN(C4/B4,0),"") -> 7 | E4: 고촌 | F4: =IFERROR(C4-(D4*B4),"") -> 0
A5: VV93 (주)지에스리테일곤지암센터 | B5: =$B$4 -> 40 | C5: =IFERROR(VLOOKUP(A5,'H2 피벗'!A:SH,2,FALSE),0) -> 360 | D5: =IFERROR(ROUNDDOWN(C5/B5,0),"") -> 9 | E5: 곤지암 | F5: =IFERROR(C5-(D5*B5),"") -> 0
A6: VV90 (주)지에스리테일포천저온 | B6: =$B$4 -> 40 | C6: =IFERROR(VLOOKUP(A6,'H2 피벗'!A:SH,2,FALSE),0) -> 0 | D6: =IFERROR(ROUNDDOWN(C6/B6,0),"") -> 0 | E6: 포천 | F6: =IFERROR(C6-(D6*B6),"") -> 0
A7: VV85 지에스리테일신오산1저온 | B7: =$B$4 -> 40 | C7: =IFERROR(VLOOKUP(A7,'H2 피벗'!A:SH,2,FALSE),0) -> 680 | D7: =IFERROR(ROUNDDOWN(C7/B7,0),"") -> 17 | E7: 신오산1 | F7: =IFERROR(C7-(D7*B7),"") -> 0
A8: VV04 (주)지에스리테일공주일배 | B8: =$B$4 -> 40 | C8: =IFERROR(VLOOKUP(A8,'H2 피벗'!A:SH,2,FALSE),0) -> 480 | D8: =IFERROR(ROUNDDOWN(C8/B8,0),"") -> 12 | E8: 공주 | F8: =IFERROR(C8-(D8*B8),"") -> 0
A9: VV69 ㈜지에스리테일강릉일배센터 | B9: =$B$4 -> 40 | C9: =IFERROR(VLOOKUP(A9,'H2 피벗'!A:SH,2,FALSE),0) -> 600 | D9: =IFERROR(ROUNDDOWN(C9/B9,0),"") -> 15 | E9: 강릉 | F9: =IFERROR(C9-(D9*B9),"") -> 0
A10: VV66 지에스리테일인천도화일배 | B10: =$B$4 -> 40 | C10: =IFERROR(VLOOKUP(A10,'H2 피벗'!A:SH,2,FALSE),0) -> 80 | D10: =IFERROR(ROUNDDOWN(C10/B10,0),"") -> 2 | E10: 도화 | F10: =IFERROR(C10-(D10*B10),"") -> 0
A11: VV63 ㈜지에스리테일고양일배센터 | B11: =$B$4 -> 40 | C11: =IFERROR(VLOOKUP(A11,'H2 피벗'!A:SH,2,FALSE),0) -> 600 | D11: =IFERROR(ROUNDDOWN(C11/B11,0),"") -> 15 | E11: 고양 | F11: =IFERROR(C11-(D11*B11),"") -> 0
A12: VV62 (주)지에스리테일김포2일배 | B12: =$B$4 -> 40 | C12: =IFERROR(VLOOKUP(A12,'H2 피벗'!A:SH,2,FALSE),0) -> 200 | D12: =IFERROR(ROUNDDOWN(C12/B12,0),"") -> 5 | E12: 김포2 | F12: =IFERROR(C12-(D12*B12),"") -> 0
A13: VV53 (주)지에스리테일송파일배 | B13: =$B$4 -> 40 | C13: =IFERROR(VLOOKUP(A13,'H2 피벗'!A:SH,2,FALSE),0) -> 1880 | D13: =IFERROR(ROUNDDOWN(C13/B13,0),"") -> 47 | E13: 송파 | F13: =IFERROR(C13-(D13*B13),"") -> 0
A14: VV34 (주)지에스리테일청주일배 | B14: =$B$4 -> 40 | C14: =IFERROR(VLOOKUP(A14,'H2 피벗'!A:SH,2,FALSE),0) -> 0 | D14: =IFERROR(ROUNDDOWN(C14/B14,0),"") -> 0 | E14: 청주 | F14: =IFERROR(C14-(D14*B14),"") -> 0
A15: VV17 (주)지에스리테일발안일배 | B15: =$B$4 -> 40 | C15: =IFERROR(VLOOKUP(A15,'H2 피벗'!A:SH,2,FALSE),0) -> 240 | D15: =IFERROR(ROUNDDOWN(C15/B15,0),"") -> 6 | E15: 발안 | F15: =IFERROR(C15-(D15*B15),"") -> 0
A16: VV16 (주)지에스리테일원주일배 | B16: =$B$4 -> 40 | C16: =IFERROR(VLOOKUP(A16,'H2 피벗'!A:SH,2,FALSE),0) -> 0 | D16: =IFERROR(ROUNDDOWN(C16/B16,0),"") -> 0 | E16: 원주 | F16: =IFERROR(C16-(D16*B16),"") -> 0
A17: VV03 (주)지에스리테일(아신A) | B17: =$B$4 -> 40 | C17: =IFERROR(VLOOKUP(A17,'H2 피벗'!A:SH,2,FALSE),0) -> 1040 | D17: =IFERROR(ROUNDDOWN(C17/B17,0),"") -> 26 | E17: 아신 | F17: =IFERROR(C17-(D17*B17),"") -> 0
A19: 수도권 합계 | B19: =$B$4 -> 40 | C19: =SUM(C4:C17) -> 6440 | D19: =IFERROR(ROUNDDOWN(C19/B19,0),"") -> 161 | F19: =IFERROR(C19-(D19*B19),"") -> 0
A21: VV57 (주)지에스리테일김해일배 | B21: =$B$4 -> 40 | C21: =IFERROR(VLOOKUP(A21,'H2 피벗'!A:SH,2,FALSE),0) -> 1000 | D21: =IFERROR(ROUNDDOWN(C21/B21,0),"") -> 25 | E21: 김해 | F21: =IFERROR(C21-(D21*B21),"") -> 0
A22: VV25 (주)지에스리테일진주일배 | B22: =$B$4 -> 40 | C22: =IFERROR(VLOOKUP(A22,'H2 피벗'!A:SH,2,FALSE),0) -> 80 | D22: =IFERROR(ROUNDDOWN(C22/B22,0),"") -> 2 | E22: 진주 | F22: =IFERROR(C22-(D22*B22),"") -> 0
A23: VV20 (주)지에스리테일(해인CVS) | B23: =$B$4 -> 40 | C23: =IFERROR(VLOOKUP(A23,'H2 피벗'!A:SH,2,FALSE),0) -> 0 | D23: =IFERROR(ROUNDDOWN(C23/B23,0),"") -> 0 | E23: 해인 | F23: =IFERROR(C23-(D23*B23),"") -> 0
A25: 경남(김해)합계 | B25: =$B$4 -> 40 | C25: =SUM(C21:C23) -> 1080 | D25: =IFERROR(ROUNDDOWN(C25/B25,0),"") -> 27 | F25: =IFERROR(C25-(D25*B25),"") -> 0
A27: VV83 지에스리테일경산저온 | B27: =$B$4 -> 40 | C27: =IFERROR(VLOOKUP(A27,'H2 피벗'!A:SH,2,FALSE),0) -> 1200 | D27: =IFERROR(ROUNDDOWN(C27/B27,0),"") -> 30 | E27: 경산 | F27: =IFERROR(C27-(D27*B27),"") -> 0
A29: 경북(칠곡)합계 | B29: =$B$4 -> 40 | C29: =SUM(C27:C27) -> 1200 | D29: =IFERROR(ROUNDDOWN(C29/B29,0),"") -> 30 | F29: =IFERROR(C29-(D29*B29),"") -> 0
A31: VV95 (주)지에스리테일신광주저온 | B31: =$B$4 -> 40 | C31: =IFERROR(VLOOKUP(A31,'H2 피벗'!A:SH,2,FALSE),0) -> 120 | D31: =IFERROR(ROUNDDOWN(C31/B31,0),"") -> 3 | E31: 신광주 | F31: =IFERROR(C31-(D31*B31),"") -> 0
A32: VV65 ㈜지에스리테일익산일배 | B32: =$B$4 -> 40 | C32: =IFERROR(VLOOKUP(A32,'H2 피벗'!A:SH,2,FALSE),0) -> 120 | D32: =IFERROR(ROUNDDOWN(C32/B32,0),"") -> 3 | E32: 익산 | F32: =IFERROR(C32-(D32*B32),"") -> 0
A34: 호남권 합계 | B34: =$B$4 -> 40 | C34: =SUM(C31:C32) -> 240 | D34: =IFERROR(ROUNDDOWN(C34/B34,0),"") -> 6 | F34: =IFERROR(C34-(D34*B34),"") -> 0
A36: VV92 (주)지에스리테일신제주저온 | B36: =$B$4 -> 40 | C36: =IFERROR(VLOOKUP(A36,'H2 피벗'!A:SH,2,FALSE),0) -> 0 | D36: =IFERROR(ROUNDDOWN(C36/B36,0),"") -> 0 | E36: 신제주 | F36: =IFERROR(C36-(D36*B36),"") -> 0
A38: 총합계 | B38: =$B$4 -> 40 | C38: =SUM(C4:C17,C31:C32,C27:C27,C21:C23,C36) -> 8960 | D38: =IFERROR(ROUNDDOWN(C38/B38,0),"") -> 224 | F38: =IFERROR(C38-(D38*B38),"") -> 0
