Workbook

Sheet 검수장
A1: 검수 리스트
A2: 행 레이블 | B2: 껍데기 | C2: 돼지갈비 | D2: 직화불닭발 | E2: 수제치즈돈까스 | F2: 족발 | G2: 반반족보세트 | H2: 소시지콘 치즈그라탕 | I2: 샐만사)리코타닭가슴살에그 | J2: 쉬림프레몬콥샐러드 | K2: 치킨에그콥 샐러드 | L2: 케이준치킨에그샐러드 | M2: 모서리족발 (냉장) | N2: 카카오)라이언초코케이크 | O2: 직화)모둠햄부대찌개 | P2: 직화)스팸김치찌개 | Q2: 진가쭈꾸미 짬뽕 | R2: 총합계
A3: VV52 (주)지에스리테일남양주일배 | B3: =VLOOKUP(A:A,#REF!,2,0) -> #REF! | C3: =VLOOKUP(A:A,#REF!,3,0) -> #REF! | D3: =VLOOKUP(A:A,#REF!,4,0) -> #REF! | E3: =VLOOKUP(A:A,#REF!,5,0) -> #REF! | F3: =VLOOKUP(A:A,#REF!,2,0) -> #REF! | G3: =VLOOKUP(A:A,#REF!,3,0) -> #REF! | H3: =VLOOKUP(A:A,#REF!,4,0) -> #REF! | I3: =VLOOKUP(A3,#REF!,2,0) -> #REF! | J3: =VLOOKUP(A3,#REF!,3,0) -> #REF! | K3: =VLOOKUP(A:A,#REF!,4,0) -> #REF! | L3: =VLOOKUP(A3,#REF!,5,0) -> #REF! | M3: =VLOOKUP(A:A,#REF!,2,0) -> #REF! | N3: =VLOOKUP(A:A,#REF!,3,0) -> #REF! | O3: =VLOOKUP(A:A,#REF!,2,0) -> #REF! | P3: =VLOOKUP(A:A,#REF!,2,0) -> #REF! | Q3: =VLOOKUP(A:A,#REF!,2,0) -> #REF! | R3: =SUM(B3:Q3) -> #REF!
A4: VV53 (주)지에스리테일송파일배 | B4: =VLOOKUP(A:A,#REF!,2,0) -> #REF! | C4: =VLOOKUP(A:A,#REF!,3,0) -> #REF! | D4: =VLOOKUP(A:A,#REF!,4,0) -> #REF! | E4: =VLOOKUP(A:A,#REF!,5,0) -> #REF! | F4: =VLOOKUP(A:A,#REF!,2,0) -> #REF! | G4: =VLOOKUP(A:A,#REF!,3,0) -> #REF! | H4: =VLOOKUP(A:A,#REF!,4,0) -> #REF! | I4: =VLOOKUP(A4,#REF!,2,0) -> #REF! | J4: =VLOOKUP(A4,#REF!,3,0) -> #REF! | K4: =VLOOKUP(A:A,#REF!,4,0) -> #REF! | L4: =VLOOKUP(A4,#REF!,5,0) -> #REF! | M4: =VLOOKUP(A:A,#REF!,2,0) -> #REF! | N4: =VLOOKUP(A:A,#REF!,3,0) -> #REF! | O4: =VLOOKUP(A:A,#REF!,2,0) -> #REF! | P4: =VLOOKUP(A:A,#REF!,3,0) -> #REF! | Q4: =VLOOKUP(A:A,#REF!,2,0) -> #REF! | R4: =SUM(B4:Q4) -> #REF!
A5: VV55 (주)지에스리테일송파2일배 | B5: =VLOOKUP(A:A,#REF!,2,0) -> #REF! | C5: =VLOOKUP(A:A,#REF!,3,0) -> #REF! | D5: =VLOOKUP(A:A,#REF!,4,0) -> #REF! | E5: =VLOOKUP(A:A,#REF!,5,0) -> #REF! | F5: =VLOOKUP(A:A,#REF!,2,0) -> #REF! | G5: =VLOOKUP(A:A,#REF!,3,0) -> #REF! | H5: =VLOOKUP(A:A,#REF!,4,0) -> #REF! | I5: =VLOOKUP(A5,#REF!,2,0) -> #REF! | J5: =VLOOKUP(A5,#REF!,3,0) -> #REF! | K5: =VLOOKUP(A:A,#REF!,4,0) -> #REF! | L5: =VLOOKUP(A5,#REF!,5,0) -> #REF! | M5: =VLOOKUP(A:A,#REF!,2,0) -> #REF! | N5: =VLOOKUP(A:A,#REF!,3,0) -> #REF! | O5: =VLOOKUP(A:A,#REF!,2,0) -> #REF! | P5: =VLOOKUP(A:A,#REF!,3,0) -> #REF! | Q5: =VLOOKUP(A:A,#REF!,2,0) -> #REF! | R5: =SUM(B5:Q5) -> #REF!
A6: VV63 ㈜지에스리테일고양일배센터 | B6: =VLOOKUP(A:A,#REF!,2,0) -> #REF! | C6: =VLOOKUP(A:A,#REF!,3,0) -> #REF! | D6: =VLOOKUP(A:A,#REF!,4,0) -> #REF! | E6: =VLOOKUP(A:A,#REF!,5,0) -> #REF! | F6: =VLOOKUP(A:A,#REF!,2,0) -> #REF! | G6: =VLOOKUP(A:A,#REF!,3,0) -> #REF! | H6: =VLOOKUP(A:A,#REF!,4,0) -> #REF! | I6: =VLOOKUP(A6,#REF!,2,0) -> #REF! | J6: =VLOOKUP(A6,#REF!,3,0) -> #REF! | K6: =VLOOKUP(A:A,#REF!,4,0) -> #REF! | L6: =VLOOKUP(A6,#REF!,5,0) -> #REF! | M6: =VLOOKUP(A:A,#REF!,2,0) -> #REF! | N6: =VLOOKUP(A:A,#REF!,3,0) -> #REF! | O6: =VLOOKUP(A:A,#REF!,2,0) -> #REF! | P6: =VLOOKUP(A:A,#REF!,3,0) -> #REF! | Q6: =VLOOKUP(A:A,#REF!,2,0) -> #REF! | R6: =SUM(B6:Q6) -> #REF!
A7: VV64 ㈜지에스리테일고양일배2 | B7: =VLOOKUP(A:A,#REF!,2,0) -> #REF! | C7: =VLOOKUP(A:A,#REF!,3,0) -> #REF! | D7: =VLOOKUP(A:A,#REF!,4,0) -> #REF! | E7: =VLOOKUP(A:A,#REF!,5,0) -> #REF! | F7: =VLOOKUP(A:A,#REF!,2,0) -> #REF! | G7: =VLOOKUP(A:A,#REF!,3,0) -> #REF! | H7: =VLOOKUP(A:A,#REF!,4,0) -> #REF! | I7: =VLOOKUP(A7,#REF!,2,0) -> #REF! | J7: =VLOOKUP(A7,#REF!,3,0) -> #REF! | K7: =VLOOKUP(A:A,#REF!,4,0) -> #REF! | L7: =VLOOKUP(A7,#REF!,5,0) -> #REF! | M7: =VLOOKUP(A:A,#REF!,2,0) -> #REF! | N7: =VLOOKUP(A:A,#REF!,3,0) -> #REF! | O7: =VLOOKUP(A:A,#REF!,2,0) -> #REF! | P7: =VLOOKUP(A:A,#REF!,3,0) -> #REF! | Q7: =VLOOKUP(A:A,#REF!,2,0) -> #REF! | R7: =SUM(B7:Q7) -> #REF!
A8: VV62 (주)지에스리테일김포2일배 | B8: =VLOOKUP(A:A,#REF!,2,0) -> #REF! | C8: =VLOOKUP(A:A,#REF!,3,0) -> #REF! | D8: =VLOOKUP(A:A,#REF!,4,0) -> #REF! | E8: =VLOOKUP(A:A,#REF!,5,0) -> #REF! | F8: =VLOOKUP(A:A,#REF!,2,0) -> #REF! | G8: =VLOOKUP(A:A,#REF!,3,0) -> #REF! | H8: =VLOOKUP(A:A,#REF!,4,0) -> #REF! | I8: =VLOOKUP(A8,#REF!,2,0) -> #REF! | J8: =VLOOKUP(A8,#REF!,3,0) -> #REF! | K8: =VLOOKUP(A:A,#REF!,4,0) -> #REF! | L8: =VLOOKUP(A8,#REF!,5,0) -> #REF! | M8: =VLOOKUP(A:A,#REF!,2,0) -> #REF! | N8: =VLOOKUP(A:A,#REF!,3,0) -> #REF! | O8: =VLOOKUP(A:A,#REF!,2,0) -> #REF! | P8: =VLOOKUP(A:A,#REF!,3,0) -> #REF! | Q8: =VLOOKUP(A:A,#REF!,2,0) -> #REF! | R8: =SUM(B8:Q8) -> #REF!
A9: VV70 ㈜지에스리테일김포3일배 | B9: =VLOOKUP(A:A,#REF!,2,0) -> #REF! | C9: =VLOOKUP(A:A,#REF!,3,0) -> #REF! | D9: =VLOOKUP(A:A,#REF!,4,0) -> #REF! | E9: =VLOOKUP(A:A,#REF!,5,0) -> #REF! | F9: =VLOOKUP(A:A,#REF!,2,0) -> #REF! | G9: =VLOOKUP(A:A,#REF!,3,0) -> #REF! | H9: =VLOOKUP(A:A,#REF!,4,0) -> #REF! | I9: =VLOOKUP(A9,#REF!,2,0) -> #REF! | J9: =VLOOKUP(A9,#REF!,3,0) -> #REF! | K9: =VLOOKUP(A:A,#REF!,4,0) -> #REF! | L9: =VLOOKUP(A9,#REF!,5,0) -> #REF! | M9: =VLOOKUP(A:A,#REF!,2,0) -> #REF! | N9: =VLOOKUP(A:A,#REF!,3,0) -> #REF! | O9: =VLOOKUP(A:A,#REF!,2,0) -> #REF! | P9: =VLOOKUP(A:A,#REF!,3,0) -> #REF! | Q9: =VLOOKUP(A:A,#REF!,2,0) -> #REF! | R9: =SUM(B9:Q9) -> #REF!
A10: VV66 지에스리테일인천도화일배 | B10: =VLOOKUP(A:A,#REF!,2,0) -> #REF! | C10: =VLOOKUP(A:A,#REF!,3,0) -> #REF! | D10: =VLOOKUP(A:A,#REF!,4,0) -> #REF! | E10: =VLOOKUP(A:A,#REF!,5,0) -> #REF! | F10: =VLOOKUP(A:A,#REF!,2,0) -> #REF! | G10: =VLOOKUP(A:A,#REF!,3,0) -> #REF! | H10: =VLOOKUP(A:A,#REF!,4,0) -> #REF! | I10: =VLOOKUP(A10,#REF!,2,0) -> #REF! | J10: =VLOOKUP(A10,#REF!,3,0) -> #REF! | K10: =VLOOKUP(A:A,#REF!,4,0) -> #REF! | L10: =VLOOKUP(A10,#REF!,5,0) -> #REF! | M10: =VLOOKUP(A:A,#REF!,2,0) -> #REF! | N10: =VLOOKUP(A:A,#REF!,3,0) -> #REF! | O10: =VLOOKUP(A:A,#REF!,2,0) -> #REF! | P10: =VLOOKUP(A:A,#REF!,3,0) -> #REF! | Q10: =VLOOKUP(A:A,#REF!,2,0) -> #REF! | R10: =SUM(B10:Q10) -> #REF!
A11: VV67 지에스리테일인천도화2일배 | B11: =VLOOKUP(A:A,#REF!,2,0) -> #REF! | C11: =VLOOKUP(A:A,#REF!,3,0) -> #REF! | D11: =VLOOKUP(A:A,#REF!,4,0) -> #REF! | E11: =VLOOKUP(A:A,#REF!,5,0) -> #REF! | F11: =VLOOKUP(A:A,#REF!,2,0) -> #REF! | G11: =VLOOKUP(A:A,#REF!,3,0) -> #REF! | H11: =VLOOKUP(A:A,#REF!,4,0) -> #REF! | I11: =VLOOKUP(A11,#REF!,2,0) -> #REF! | J11: =VLOOKUP(A11,#REF!,3,0) -> #REF! | K11: =VLOOKUP(A:A,#REF!,4,0) -> #REF! | L11: =VLOOKUP(A11,#REF!,5,0) -> #REF! | M11: =VLOOKUP(A:A,#REF!,2,0) -> #REF! | N11: =VLOOKUP(A:A,#REF!,3,0) -> #REF! | O11: =VLOOKUP(A:A,#REF!,2,0) -> #REF! | P11: =VLOOKUP(A:A,#REF!,3,0) -> #REF! | Q11: =VLOOKUP(A:A,#REF!,2,0) -> #REF! | R11: =SUM(B11:Q11) -> #REF!
A12: VV17 (주)지에스리테일발안일배 | B12: =VLOOKUP(A:A,#REF!,2,0) -> #REF! | C12: =VLOOKUP(A:A,#REF!,3,0) -> #REF! | D12: =VLOOKUP(A:A,#REF!,4,0) -> #REF! | E12: =VLOOKUP(A:A,#REF!,5,0) -> #REF! | F12: =VLOOKUP(A:A,#REF!,2,0) -> #REF! | G12: =VLOOKUP(A:A,#REF!,3,0) -> #REF! | H12: =VLOOKUP(A:A,#REF!,4,0) -> #REF! | I12: =VLOOKUP(A12,#REF!,2,0) -> #REF! | J12: =VLOOKUP(A12,#REF!,3,0) -> #REF! | K12: =VLOOKUP(A:A,#REF!,4,0) -> #REF! | L12: =VLOOKUP(A12,#REF!,5,0) -> #REF! | M12: =VLOOKUP(A:A,#REF!,2,0) -> #REF! | N12: =VLOOKUP(A:A,#REF!,3,0) -> #REF! | O12: =VLOOKUP(A:A,#REF!,2,0) -> #REF! | P12: =VLOOKUP(A:A,#REF!,3,0) -> #REF! | Q12: =VLOOKUP(A:A,#REF!,2,0) -> #REF! | R12: =SUM(B12:Q12) -> #REF!
A13: VV71 (주)지에스리테일발안2일배 | B13: =VLOOKUP(A:A,#REF!,2,0) -> #REF! | C13: =VLOOKUP(A:A,#REF!,3,0) -> #REF! | D13: =VLOOKUP(A:A,#REF!,4,0) -> #REF! | E13: =VLOOKUP(A:A,#REF!,5,0) -> #REF! | F13: =VLOOKUP(A:A,#REF!,2,0) -> #REF! | G13: =VLOOKUP(A:A,#REF!,3,0) -> #REF! | H13: =VLOOKUP(A:A,#REF!,4,0) -> #REF! | I13: =VLOOKUP(A13,#REF!,2,0) -> #REF! | J13: =VLOOKUP(A13,#REF!,3,0) -> #REF! | K13: =VLOOKUP(A:A,#REF!,4,0) -> #REF! | L13: =VLOOKUP(A13,#REF!,5,0) -> #REF! | M13: =VLOOKUP(A:A,#REF!,2,0) -> #REF! | N13: =VLOOKUP(A:A,#REF!,3,0) -> #REF! | O13: =VLOOKUP(A:A,#REF!,2,0) -> #REF! | P13: =VLOOKUP(A:A,#REF!,3,0) -> #REF! | Q13: =VLOOKUP(A:A,#REF!,2,0) -> #REF! | R13: =SUM(B13:Q13) -> #REF!
A14: VV60 ㈜지에스리테일오산일배 | B14: =VLOOKUP(A:A,#REF!,2,0) -> #REF! | C14: =VLOOKUP(A:A,#REF!,3,0) -> #REF! | D14: =VLOOKUP(A:A,#REF!,4,0) -> #REF! | E14: =VLOOKUP(A:A,#REF!,5,0) -> #REF! | F14: =VLOOKUP(A:A,#REF!,2,0) -> #REF! | G14: =VLOOKUP(A:A,#REF!,3,0) -> #REF! | H14: =VLOOKUP(A:A,#REF!,4,0) -> #REF! | I14: =VLOOKUP(A14,#REF!,2,0) -> #REF! | J14: =VLOOKUP(A14,#REF!,3,0) -> #REF! | K14: =VLOOKUP(A:A,#REF!,4,0) -> #REF! | L14: =VLOOKUP(A14,#REF!,5,0) -> #REF! | M14: =VLOOKUP(A:A,#REF!,2,0) -> #REF! | N14: =VLOOKUP(A:A,#REF!,3,0) -> #REF! | O14: =VLOOKUP(A:A,#REF!,2,0) -> #REF! | P14: =VLOOKUP(A:A,#REF!,3,0) -> #REF! | Q14: =VLOOKUP(A:A,#REF!,2,0) -> #REF! | R14: =SUM(B14:Q14) -> #REF!
A15: VV03 (주)지에스리테일(아신A) | B15: =VLOOKUP(A:A,#REF!,2,0) -> #REF! | C15: =VLOOKUP(A:A,#REF!,3,0) -> #REF! | D15: =VLOOKUP(A:A,#REF!,4,0) -> #REF! | E15: =VLOOKUP(A:A,#REF!,5,0) -> #REF! | F15: =VLOOKUP(A:A,#REF!,2,0) -> #REF! | G15: =VLOOKUP(A:A,#REF!,3,0) -> #REF! | H15: =VLOOKUP(A:A,#REF!,4,0) -> #REF! | I15: =VLOOKUP(A15,#REF!,2,0) -> #REF! | J15: =VLOOKUP(A15,#REF!,3,0) -> #REF! | K15: =VLOOKUP(A:A,#REF!,4,0) -> #REF! | L15: =VLOOKUP(A15,#REF!,5,0) -> #REF! | M15: =VLOOKUP(A:A,#REF!,2,0) -> #REF! | N15: =VLOOKUP(A:A,#REF!,3,0) -> #REF! | O15: =VLOOKUP(A:A,#REF!,2,0) -> #REF! | P15: =VLOOKUP(A:A,#REF!,3,0) -> #REF! | Q15: =VLOOKUP(A:A,#REF!,2,0) -> #REF! | R15: =SUM(B15:Q15) -> #REF!
... A22: VV57 (주)지에스리테일김해일배 | B22: =VLOOKUP(A:A,#REF!,2,0) -> #REF! | C22: =VLOOKUP(A:A,#REF!,3,0) -> #REF! | D22: =VLOOKUP(A:A,#REF!,4,0) -> #REF! | E22: =VLOOKUP(A:A,#REF!,5,0) -> #REF! | F22: =VLOOKUP(A:A,#REF!,2,0) -> #REF! | G22: =VLOOKUP(A:A,#REF!,3,0) -> #REF! | H22: =VLOOKUP(A:A,#REF!,4,0) -> #REF! | I22: =VLOOKUP(A22,#REF!,2,0) -> #REF! | J22: =VLOOKUP(A22,#REF!,3,0) -> #REF! | K22: =VLOOKUP(A:A,#REF!,4,0) -> #REF! | L22: =VLOOKUP(A22,#REF!,5,0) -> #REF! | M22: =VLOOKUP(A:A,#REF!,2,0) -> #REF! | N22: =VLOOKUP(A:A,#REF!,3,0) -> #REF! | O22: =VLOOKUP(A:A,#REF!,2,0) -> #REF! | P22: =VLOOKUP(A:A,#REF!,3,0) -> #REF! | Q22: =VLOOKUP(A:A,#REF!,2,0) -> #REF! | R22: =SUM(B22:Q22) -> #REF!
A23: VV23 (주)지에스리테일(해인FF) | B23: =VLOOKUP(A:A,#REF!,2,0) -> #REF! | C23: =VLOOKUP(A:A,#REF!,3,0) -> #REF! | D23: =VLOOKUP(A:A,#REF!,4,0) -> #REF! | E23: =VLOOKUP(A:A,#REF!,5,0) -> #REF! | F23: =VLOOKUP(A:A,#REF!,2,0) -> #REF! | G23: =VLOOKUP(A:A,#REF!,3,0) -> #REF! | H23: =VLOOKUP(A:A,#REF!,4,0) -> #REF! | I23: =VLOOKUP(A23,#REF!,2,0) -> #REF! | J23: =VLOOKUP(A23,#REF!,3,0) -> #REF! | K23: =VLOOKUP(A:A,#REF!,4,0) -> #REF! | L23: =VLOOKUP(A23,#REF!,5,0) -> #REF! | N23: =VLOOKUP(A:A,#REF!,3,0) -> #REF! | O23: =VLOOKUP(A:A,#REF!,2,0) -> #REF! | P23: =VLOOKUP(A:A,#REF!,3,0) -> #REF! | Q23: =VLOOKUP(A:A,#REF!,2,0) -> #REF! | R23: =SUM(B23:Q23) -> #REF!
A24: VV20 (주)지에스리테일(해인CVS) | M24: =VLOOKUP(A:A,#REF!,2,0) -> #REF! | N24: =VLOOKUP(A:A,#REF!,3,0) -> #REF! | R24: =SUM(B24:Q24) -> #REF!
A25: VV50 (주)지에스리테일(제성) | B25: =VLOOKUP(A:A,#REF!,2,0) -> #REF! | C25: =VLOOKUP(A:A,#REF!,3,0) -> #REF! | D25: =VLOOKUP(A:A,#REF!,4,0) -> #REF! | E25: =VLOOKUP(A:A,#REF!,5,0) -> #REF! | F25: =IFERROR(VLOOKUP(A:A,#REF!,2,0),"0") -> 0 | G25: =VLOOKUP(A:A,#REF!,3,0) -> #REF! | H25: =VLOOKUP(A:A,#REF!,4,0) -> #REF! | I25: =VLOOKUP(A25,#REF!,2,0) -> #REF! | J25: =VLOOKUP(A25,#REF!,3,0) -> #REF! | K25: =VLOOKUP(A:A,#REF!,4,0) -> #REF! | L25: =VLOOKUP(A25,#REF!,5,0) -> #REF! | M25: =VLOOKUP(A:A,#REF!,2,0) -> #REF! | N25: =VLOOKUP(A:A,#REF!,3,0) -> #REF! | O25: =VLOOKUP(A:A,#REF!,2,0) -> #REF! | P25: =VLOOKUP(A:A,#REF!,3,0) -> #REF! | Q25: =VLOOKUP(A:A,#REF!,2,0) -> #REF! | R25: =SUM(B25:Q25) -> #REF!
A26: VV65 ㈜지에스리테일익산일배 | B26: =VLOOKUP(A:A,#REF!,2,0) -> #REF! | C26: =VLOOKUP(A:A,#REF!,3,0) -> #REF! | D26: =VLOOKUP(A:A,#REF!,4,0) -> #REF! | E26: =VLOOKUP(A:A,#REF!,5,0) -> #REF! | F26: =VLOOKUP(A:A,#REF!,2,0) -> #REF! | G26: =VLOOKUP(A:A,#REF!,3,0) -> #REF! | H26: =VLOOKUP(A:A,#REF!,4,0) -> #REF! | I26: =VLOOKUP(A26,#REF!,2,0) -> #REF! | J26: =VLOOKUP(A26,#REF!,3,0) -> #REF! | K26: =VLOOKUP(A:A,#REF!,4,0) -> #REF! | L26: =VLOOKUP(A26,#REF!,5,0) -> #REF! | M26: =VLOOKUP(A:A,#REF!,2,0) -> #REF! | N26: =VLOOKUP(A:A,#REF!,3,0) -> #REF! | O26: =VLOOKUP(A:A,#REF!,2,0) -> #REF! | P26: =VLOOKUP(A:A,#REF!,3,0) -> #REF! | Q26: =VLOOKUP(A:A,#REF!,2,0) -> #REF! | R26: =SUM(B26:Q26) -> #REF!
A27: VV11 (주)지에스리테일장성일배 | B27: =VLOOKUP(A:A,#REF!,2,0) -> #REF! | C27: =VLOOKUP(A:A,#REF!,3,0) -> #REF! | D27: =VLOOKUP(A:A,#REF!,4,0) -> #REF! | E27: =VLOOKUP(A:A,#REF!,5,0) -> #REF! | F27: =VLOOKUP(A:A,#REF!,2,0) -> #REF! | G27: =VLOOKUP(A:A,#REF!,3,0) -> #REF! | H27: =VLOOKUP(A:A,#REF!,4,0) -> #REF! | I27: =VLOOKUP(A27,#REF!,2,0) -> #REF! | J27: =VLOOKUP(A27,#REF!,3,0) -> #REF! | K27: =VLOOKUP(A:A,#REF!,4,0) -> #REF! | L27: =VLOOKUP(A27,#REF!,5,0) -> #REF! | M27: =VLOOKUP(A:A,#REF!,2,0) -> #REF! | N27: =VLOOKUP(A:A,#REF!,3,0) -> #REF! | O27: =VLOOKUP(A:A,#REF!,2,0) -> #REF! | P27: =VLOOKUP(A:A,#REF!,3,0) -> #REF! | Q27: =VLOOKUP(A:A,#REF!,2,0) -> #REF! | R27: =SUM(B27:Q27) -> #REF!
A28: VV69 ㈜지에스리테일강릉일배센터 | B28: =VLOOKUP(A:A,#REF!,2,0) -> #REF! | C28: =VLOOKUP(A:A,#REF!,3,0) -> #REF! | D28: =VLOOKUP(A:A,#REF!,4,0) -> #REF! | E28: =VLOOKUP(A:A,#REF!,5,0) -> #REF! | F28: =VLOOKUP(A:A,#REF!,2,0) -> #REF! | G28: =VLOOKUP(A:A,#REF!,3,0) -> #REF! | H28: =VLOOKUP(A:A,#REF!,4,0) -> #REF! | I28: =VLOOKUP(A28,#REF!,2,0) -> #REF! | J28: =VLOOKUP(A28,#REF!,3,0) -> #REF! | K28: =VLOOKUP(A:A,#REF!,4,0) -> #REF! | L28: =VLOOKUP(A28,#REF!,5,0) -> #REF! | M28: =VLOOKUP(A:A,#REF!,2,0) -> #REF! | N28: =VLOOKUP(A:A,#REF!,3,0) -> #REF! | O28: =VLOOKUP(A:A,#REF!,2,0) -> #REF! | P28: =VLOOKUP(A:A,#REF!,3,0) -> #REF! | Q28: =VLOOKUP(A:A,#REF!,2,0) -> #REF! | R28: =SUM(B28:Q28) -> #REF!
A29: VV25 (주)지에스리테일진주일배 | B29: =VLOOKUP(A:A,#REF!,2,0) -> #REF! | C29: =VLOOKUP(A:A,#REF!,3,0) -> #REF! | D29: =VLOOKUP(A:A,#REF!,4,0) -> #REF! | E29: =VLOOKUP(A:A,#REF!,5,0) -> #REF! | F29: =VLOOKUP(A:A,#REF!,2,0) -> #REF! | G29: =VLOOKUP(A:A,#REF!,3,0) -> #REF! | H29: =VLOOKUP(A:A,#REF!,4,0) -> #REF! | I29: =VLOOKUP(A29,#REF!,2,0) -> #REF! | J29: =VLOOKUP(A29,#REF!,3,0) -> #REF! | K29: =VLOOKUP(A:A,#REF!,4,0) -> #REF! | L29: =VLOOKUP(A29,#REF!,5,0) -> #REF! | M29: =VLOOKUP(A:A,#REF!,2,0) -> #REF! | N29: =VLOOKUP(A:A,#REF!,3,0) -> #REF! | O29: =VLOOKUP(A:A,#REF!,2,0) -> #REF! | P29: =VLOOKUP(A:A,#REF!,3,0) -> #REF! | Q29: =VLOOKUP(A:A,#REF!,2,0) -> #REF! | R29: =SUM(B29:Q29) -> #REF!
A30: 총합계 | B30: =SUM(B3:B29) -> #REF! | C30: =SUM(C3:C29) -> #REF! | D30: =SUM(D3:D29) -> #REF! | E30: =SUM(E3:E29) -> #REF! | F30: =SUM(F3:F29) -> #REF! | G30: =SUM(G3:G29) -> #REF! | H30: =SUM(H3:H29) -> #REF! | I30: =SUM(I3:I29) -> #REF! | ... R30: =SUM(R3:R29) -> #REF!

Sheet 신라명과피벗
A1: 12/17 | B1: 열 레이블
A2: 행 레이블 | B2: 리얼)모닝롤208G | C2: 총합계
A3: VV16 (주)지에스리테일원주일배
A4: VV69 ㈜지에스리테일강릉일배센터
A5: VV57 (주)지에스리테일김해일배
A6: VV58 (주)지에스리테일김해2일배
A7: VV04 (주)지에스리테일공주일배
A8: VV75 (주)지에스리테일공주2일배
A9: VV34 (주)지에스리테일청주일배
A10: VV92 (주)지에스리테일신제주저온
A11: VV25 (주)지에스리테일진주일배
A12: VV20 (주)지에스리테일(해인CVS)
A13: VV95 (주)지에스리테일신광주저온
A14: VV96 (주)지에스리테일신광주2저
... A39: 총합계

Sheet 리얼)모닝롤
A1: 디저트
A2: =TODAY() -> 46310 | B2: 신라명과 | G2: 박스 | H2: 낱개
A3: 행 레이블 | B3: 입수 | C3: 리얼)모닝롤208G | D3: 박스 | E3: 센터명 | F3: 낱개
A4: VV57 (주)지에스리테일김해일배 | B4: 10 | C4: =IFERROR(VLOOKUP(A4,신라명과피벗!A:HN,2,FALSE),0) -> 0 | D4: =IFERROR(ROUNDDOWN(C4/B4,0),"") -> 0 | E4: 김해 | F4: =IFERROR(C4-(D4*B4),"") -> 0
A5: VV58 (주)지에스리테일김해2일배 | B5: =$B$4 -> 10 | C5: =IFERROR(VLOOKUP(A5,신라명과피벗!A:HN,2,FALSE),0) -> 0 | D5: =IFERROR(ROUNDDOWN(C5/B5,0),"") -> 0 | E5: 김해2 | F5: =IFERROR(C5-(D5*B5),"") -> 0
A6: VV92 (주)지에스리테일신제주저온 | B6: =$B$4 -> 10 | C6: =IFERROR(VLOOKUP(A6,신라명과피벗!A:HN,2,FALSE),0) -> 0 | D6: =IFERROR(ROUNDDOWN(C6/B6,0),"") -> 0 | E6: 신제주 | F6: =IFERROR(C6-(D6*B6),"") -> 0
A7: VV25 (주)지에스리테일진주일배 | B7: =$B$4 -> 10 | C7: =IFERROR(VLOOKUP(A7,신라명과피벗!A:HN,2,FALSE),0) -> 0 | D7: =IFERROR(ROUNDDOWN(C7/B7,0),"") -> 0 | E7: 진주 | F7: =IFERROR(C7-(D7*B7),"") -> 0
A8: VV20 (주)지에스리테일(해인CVS) | B8: =$B$4 -> 10 | C8: =IFERROR(VLOOKUP(A8,신라명과피벗!A:HN,2,FALSE),0) -> 0 | D8: =IFERROR(ROUNDDOWN(C8/B8,0),"") -> 0 | E8: CVS | F8: =IFERROR(C8-(D8*B8),"") -> 0
A9: VV83 지에스리테일경산저온 | B9: =$B$4 -> 10 | C9: =IFERROR(VLOOKUP(A9,신라명과피벗!A:HN,2,FALSE),0) -> 0 | D9: =IFERROR(ROUNDDOWN(C9/B9,0),"") -> 0 | E9: 경산 | F9: =IFERROR(C9-(D9*B9),"") -> 0
A10: VV84 ㈜지에스리테일경산2저온 | B10: =$B$4 -> 10 | C10: =IFERROR(VLOOKUP(A10,신라명과피벗!A:HN,2,FALSE),0) -> 0 | D10: =IFERROR(ROUNDDOWN(C10/B10,0),"") -> 0 | E10: 경산2 | F10: =IFERROR(C10-(D10*B10),"") -> 0
A11: VV97 (주)지에스리테일경산3저온 | B11: =$B$4 -> 10 | C11: =IFERROR(VLOOKUP(A11,신라명과피벗!A:HN,2,FALSE),0) -> 0 | D11: =IFERROR(ROUNDDOWN(C11/B11,0),"") -> 0 | E11: 경산3 | F11: =IFERROR(C11-(D11*B11),"") -> 0
A13: 영남 합계 | B13: =B4 -> 10 | C13: =SUM($C$4:$C$11) -> 0 | D13: =IFERROR(ROUNDDOWN(C13/B13,0),"") -> 0 | F13: =IFERROR(C13-(D13*B13),"") -> 0
A15: VV95 (주)지에스리테일신광주저온 | B15: =$B$4 -> 10 | C15: =IFERROR(VLOOKUP(A15,신라명과피벗!A:HN,2,FALSE),0) -> 0 | D15: =IFERROR(ROUNDDOWN(C15/B15,0),"") -> 0 | E15: 신광주 | F15: =IFERROR(C15-(D15*B15),"") -> 0
A16: VV96 (주)지에스리테일신광주2저 | B16: =$B$4 -> 10 | C16: =IFERROR(VLOOKUP(A16,신라명과피벗!A:HN,2,FALSE),0) -> 0 | D16: =IFERROR(ROUNDDOWN(C16/B16,0),"") -> 0 | E16: 신광주2 | F16: =IFERROR(C16-(D16*B16),"") -> 0
A17: VV65 ㈜지에스리테일익산일배 | B17: =$B$4 -> 10 | C17: =IFERROR(VLOOKUP(A17,신라명과피벗!A:HN,2,FALSE),0) -> 0 | D17: =IFERROR(ROUNDDOWN(C17/B17,0),"") -> 0 | E17: 익산 | F17: =IFERROR(C17-(D17*B17),"") -> 0
A19: 호남 합계 | B19: =$B$4 -> 10 | C19: =SUM(C15:C17) -> 0 | D19: =IFERROR(ROUNDDOWN(C19/B19,0),"") -> 0 | F19: =IFERROR(C19-(D19*B19),"") -> 0
A21: VV16 (주)지에스리테일원주일배 | B21: =$B$4 -> 10 | C21: =IFERROR(VLOOKUP(A21,신라명과피벗!A:HN,2,FALSE),0) -> 0 | D21: =IFERROR(ROUNDDOWN(C21/B21,0),"") -> 0 | E21: 원주 | F21: =IFERROR(C21-(D21*B21),"") -> 0
A22: VV69 ㈜지에스리테일강릉일배센터 | B22: =$B$4 -> 10 | C22: =IFERROR(VLOOKUP(A22,신라명과피벗!A:HN,2,FALSE),0) -> 0 | D22: =IFERROR(ROUNDDOWN(C22/B22,0),"") -> 0 | E22: 강릉 | F22: =IFERROR(C22-(D22*B22),"") -> 0
A23: VV04 (주)지에스리테일공주일배 | B23: =$B$4 -> 10 | C23: =IFERROR(VLOOKUP(A23,신라명과피벗!A:HN,2,FALSE),0) -> 0 | D23: =IFERROR(ROUNDDOWN(C23/B23,0),"") -> 0 | E23: 공주 | F23: =IFERROR(C23-(D23*B23),"") -> 0
A24: VV75 (주)지에스리테일공주2일배 | B24: =$B$4 -> 10 | C24: =IFERROR(VLOOKUP(A24,신라명과피벗!A:HN,2,FALSE),0) -> 0 | D24: =IFERROR(ROUNDDOWN(C24/B24,0),"") -> 0 | E24: 공주2 | F24: =IFERROR(C24-(D24*B24),"") -> 0
A25: VV34 (주)지에스리테일청주일배 | B25: =$B$4 -> 10 | C25: =IFERROR(VLOOKUP(A25,신라명과피벗!A:HN,2,FALSE),0) -> 0 | D25: =IFERROR(ROUNDDOWN(C25/B25,0),"") -> 0 | E25: 청주 | F25: =IFERROR(C25-(D25*B25),"") -> 0
A26: VV03 (주)지에스리테일(아신A) | B26: =$B$4 -> 10 | C26: =IFERROR(VLOOKUP(A26,신라명과피벗!A:HN,2,FALSE),0) -> 0 | D26: =IFERROR(ROUNDDOWN(C26/B26,0),"") -> 0 | E26: 아신A | F26: =IFERROR(C26-(D26*B26),"") -> 0
A27: VV90 (주)지에스리테일포천저온 | B27: =$B$4 -> 10 | C27: =IFERROR(VLOOKUP(A27,신라명과피벗!A:HN,2,FALSE),0) -> 0 | D27: =IFERROR(ROUNDDOWN(C27/B27,0),"") -> 0 | E27: 포천 | F27: =IFERROR(C27-(D27*B27),"") -> 0
A28: VV91 (주)지에스리테일포천2저온 | B28: =$B$4 -> 10 | C28: =IFERROR(VLOOKUP(A28,신라명과피벗!A:HN,2,FALSE),0) -> 0 | D28: =IFERROR(ROUNDDOWN(C28/B28,0),"") -> 0 | E28: 포천2 | F28: =IFERROR(C28-(D28*B28),"") -> 0 | G28: =IFERROR(ROUNDDOWN(SUM($F$29:$F$46)/$B$4,0),"") -> 0 | H28: =IFERROR(SUM($F$29:$F$46)-($G$28*$B$4),"") -> 0
A29: VV98 (주)지에스리테일고촌저온 | B29: =$B$4 -> 10 | C29: =IFERROR(VLOOKUP(A29,신라명과피벗!A:HN,2,FALSE),0) -> 0 | D29: =IFERROR(ROUNDDOWN(C29/B29,0),"") -> 0 | E29: 고촌 | F29: =IFERROR(C29-(D29*B29),"") -> 0
A30: VV99 (주)지에스리테일고촌2저온 | B30: =$B$4 -> 10 | C30: =IFERROR(VLOOKUP(A30,신라명과피벗!A:HN,2,FALSE),0) -> 0 | D30: =IFERROR(ROUNDDOWN(C30/B30,0),"") -> 0 | E30: 고촌2 | F30: =IFERROR(C30-(D30*B30),"") -> 0
A31: VV63 ㈜지에스리테일고양일배센터 | B31: =$B$4 -> 10 | C31: =IFERROR(VLOOKUP(A31,신라명과피벗!A:HN,2,FALSE),0) -> 0 | D31: =IFERROR(ROUNDDOWN(C31/B31,0),"") -> 0 | E31: 고양 | F31: =IFERROR(C31-(D31*B31),"") -> 0
A32: VV64 ㈜지에스리테일고양일배2 | B32: =$B$4 -> 10 | C32: =IFERROR(VLOOKUP(A32,신라명과피벗!A:HN,2,FALSE),0) -> 0 | D32: =IFERROR(ROUNDDOWN(C32/B32,0),"") -> 0 | E32: 고양2 | F32: =IFERROR(C32-(D32*B32),"") -> 0
A33: VV81 (주)지에스리테일고양저온3 | B33: =$B$4 -> 10 | C33: =IFERROR(VLOOKUP(A33,신라명과피벗!A:HN,2,FALSE),0) -> 0 | D33: =IFERROR(ROUNDDOWN(C33/B33,0),"") -> 0 | E33: 고양3 | F33: =IFERROR(C33-(D33*B33),"") -> 0
A34: VV62 (주)지에스리테일김포2일배 | B34: =$B$4 -> 10 | C34: =IFERROR(VLOOKUP(A34,신라명과피벗!A:HN,2,FALSE),0) -> 0 | D34: =IFERROR(ROUNDDOWN(C34/B34,0),"") -> 0 | E34: 김포2 | F34: =IFERROR(C34-(D34*B34),"") -> 0
A35: VV70 ㈜지에스리테일김포3일배 | B35: =$B$4 -> 10 | C35: =IFERROR(VLOOKUP(A35,신라명과피벗!A:HN,2,FALSE),0) -> 0 | D35: =IFERROR(ROUNDDOWN(C35/B35,0),"") -> 0 | E35: 김포3 | F35: =IFERROR(C35-(D35*B35),"") -> 0 | G35: =IFERROR(ROUNDDOWN(SUM($F$36:$F$46)/$B$4,0),"") -> 0 | H35: =IFERROR(SUM($F$36:$F$46)-($G$35*$B$4),"") -> 0
A36: VV66 지에스리테일인천도화일배 | B36: =$B$4 -> 10 | C36: =IFERROR(VLOOKUP(A36,신라명과피벗!A:HN,2,FALSE),0) -> 0 | D36: =IFERROR(ROUNDDOWN(C36/B36,0),"") -> 0 | E36: 도화 | F36: =IFERROR(C36-(D36*B36),"") -> 0
A37: VV67 지에스리테일인천도화2일배 | B37: =$B$4 -> 10 | C37: =IFERROR(VLOOKUP(A37,신라명과피벗!A:HN,2,FALSE),0) -> 0 | D37: =IFERROR(ROUNDDOWN(C37/B37,0),"") -> 0 | E37: 도화2 | F37: =IFERROR(C37-(D37*B37),"") -> 0
A38: VV17 (주)지에스리테일발안일배 | B38: =$B$4 -> 10 | C38: =IFERROR(VLOOKUP(A38,신라명과피벗!A:HN,2,FALSE),0) -> 0 | D38: =IFERROR(ROUNDDOWN(C38/B38,0),"") -> 0 | E38: 발안 | F38: =IFERROR(C38-(D38*B38),"") -> 0
A39: VV71 (주)지에스리테일발안2일배 | B39: =$B$4 -> 10 | C39: =IFERROR(VLOOKUP(A39,신라명과피벗!A:HN,2,FALSE),0) -> 0 | D39: =IFERROR(ROUNDDOWN(C39/B39,0),"") -> 0 | E39: 발안2 | F39: =IFERROR(C39-(D39*B39),"") -> 0
A40: VV53 (주)지에스리테일송파일배 | B40: =$B$4 -> 10 | C40: =IFERROR(VLOOKUP(A40,신라명과피벗!A:HN,2,FALSE),0) -> 0 | D40: =IFERROR(ROUNDDOWN(C40/B40,0),"") -> 0 | E40: 송파 | F40: =IFERROR(C40-(D40*B40),"") -> 0
A41: VV55 (주)지에스리테일송파2일배 | B41: =$B$4 -> 10 | C41: =IFERROR(VLOOKUP(A41,신라명과피벗!A:HN,2,FALSE),0) -> 0 | D41: =IFERROR(ROUNDDOWN(C41/B41,0),"") -> 0 | E41: 송파2 | F41: =IFERROR(C41-(D41*B41),"") -> 0 | G41: =IFERROR(ROUNDDOWN(SUM($F$42:$F$46)/$B$4,0),"") -> 0 | H41: =IFERROR(SUM($F$42:$F$46)-($G$41*$B$4),"") -> 0
A42: VV93 (주)지에스리테일곤지암센터 | B42: =$B$4 -> 10 | C42: =IFERROR(VLOOKUP(A42,신라명과피벗!A:HN,2,FALSE),0) -> 0 | D42: =IFERROR(ROUNDDOWN(C42/B42,0),"") -> 0 | E42: 곤지암 | F42: =IFERROR(C42-(D42*B42),"") -> 0
A43: VV94 (주)지에스리테일곤지암2센 | B43: =$B$4 -> 10 | C43: =IFERROR(VLOOKUP(A43,신라명과피벗!A:HN,2,FALSE),0) -> 0 | D43: =IFERROR(ROUNDDOWN(C43/B43,0),"") -> 0 | E43: 곤지암2 | F43: =IFERROR(C43-(D43*B43),"") -> 0
A44: VV85 지에스리테일신오산1저온 | B44: =$B$4 -> 10 | C44: =IFERROR(VLOOKUP(A44,신라명과피벗!A:HN,2,FALSE),0) -> 0 | D44: =IFERROR(ROUNDDOWN(C44/B44,0),"") -> 0 | E44: 신오산1 | F44: =IFERROR(C44-(D44*B44),"") -> 0
...

Sheet ★은성(주문일-당일)
A1: 10/15 | D1: 열 레이블
A2: 행 레이블 | D2: APP예약)밸런스푼에그듬뿍샐러드 | E2: APP예약)밸런스푼훈제오리듬뿍샐러드 | F2: APP예약)치킨텐더샐러드 | G2: 밸런스푼)꽃맛살듬뿍샐러드 235g | H2: 밸런스푼)새우듬뿍샐러드 185g | I2: 밸런스푼)에그듬뿍샐러드 230g | J2: 밸런스푼)훈제오리듬뿍샐러드 225g | K2: 은성)닭가슴살샐러드 155g | L2: 은성)치킨텐더샐러드 150g | M2: 총합계
A3: 광주B저온센터 | E3: 2 | F3: 1 | G3: 4 | H3: 13 | I3: 14 | J3: 11 | K3: 1 | L3: 1 | M3: 47 | O3: 광주B저온센터
A4: 광주냉장 | G4: 5 | H4: 6 | I4: 8 | J4: 8 | K4: 1 | L4: 2 | M4: 30 | O4: 광주냉장
A5: 대구냉장 | G5: 16 | H5: 18 | I5: 19 | J5: 17 | K5: 4 | L5: 3 | M5: 77 | O5: 대구냉장
A6: 부산냉장 | G6: 5 | H6: 5 | I6: 13 | J6: 10 | L6: 1 | M6: 34 | O6: 부산냉장
A7: 세종냉장센터 | G7: 13 | H7: 34 | I7: 19 | J7: 28 | K7: 12 | L7: 9 | M7: 115 | O7: 세종냉장센터
A8: 수원저온센터 | G8: 27 | H8: 39 | I8: 45 | J8: 36 | K8: 13 | L8: 19 | M8: 179 | O8: 수원저온센터
A9: 안성저온센터 | G9: 14 | H9: 19 | I9: 29 | J9: 20 | K9: 9 | L9: 4 | M9: 95 | O9: 안성저온센터
A10: 양산냉장 | G10: 11 | H10: 13 | I10: 14 | J10: 14 | K10: 2 | M10: 54 | O10: 양산냉장
A11: 양주저온 | G11: 33 | H11: 43 | I11: 67 | J11: 57 | K11: 21 | L11: 20 | M11: 241 | O11: 양주저온
A12: 오포저온 | D12: 1 | G12: 30 | H12: 46 | I12: 44 | J12: 51 | K12: 22 | L12: 23 | M12: 217 | O12: 오포저온
A13: 원주저온 | G13: 16 | H13: 25 | I13: 25 | J13: 24 | K13: 6 | L13: 11 | M13: 107 | O13: 원주저온
A14: 인천저온 | G14: 35 | H14: 36 | I14: 44 | J14: 36 | K14: 14 | L14: 6 | M14: 171 | O14: 인천저온
A15: 제주냉장센터 | G15: 6 | H15: 9 | I15: 5 | J15: 11 | K15: 3 | M15: 34 | O15: 제주냉장센터
A16: 칠곡저온 | G16: 13 | H16: 20 | I16: 11 | J16: 22 | K16: 7 | L16: 5 | M16: 78 | O16: 칠곡저온
A17: 해인기흥저온센터 | G17: 33 | H17: 59 | I17: 61 | J17: 49 | K17: 10 | L17: 11 | M17: 223 | O17: 해인기흥저온센터
A18: 총합계 | D18: 1 | E18: 2 | F18: 1 | G18: 261 | H18: 385 | I18: 418 | J18: 394 | K18: 125 | L18: 115 | M18: 1702

Sheet APP예약)닭가슴살샐러드
A2: =TODAY() -> 46310 | B2: 은성파머스_ 세븐 <2편> □
A3: 행 레이블 | B3: 입수 | C3: APP예약)닭가슴살샐러드 | D3: 박스 | E3: 센터명 | F3: 낱개
A4: 수도권냉장 | B4: 36 | C4: =IFERROR(VLOOKUP(A4,'★은성(주문일-당일)'!A:RV,2,FALSE),0) -> 0 | D4: =IFERROR(ROUNDDOWN(C4/B4,0),"") -> 0 | E4: 수도권 | F4: =IFERROR(C4-(D4*B4),"") -> 0
A5: 안성저온센터 | B5: =$B$4 -> 36 | C5: =IFERROR(VLOOKUP(A5,'★은성(주문일-당일)'!A:RV,2,FALSE),0) -> 0 | D5: =IFERROR(ROUNDDOWN(C5/B5,0),"") -> 0 | E5: 안성 | F5: =IFERROR(C5-(D5*B5),"") -> 0
A6: 세종냉장센터 | B6: =$B$4 -> 36 | C6: =IFERROR(VLOOKUP(A6,'★은성(주문일-당일)'!A:RV,2,FALSE),0) -> 0 | D6: =IFERROR(ROUNDDOWN(C6/B6,0),"") -> 0 | E6: 세종 | F6: =IFERROR(C6-(D6*B6),"") -> 0
A7: 인천저온 | B7: =$B$4 -> 36 | C7: =IFERROR(VLOOKUP(A7,'★은성(주문일-당일)'!A:RV,2,FALSE),0) -> 0 | D7: =IFERROR(ROUNDDOWN(C7/B7,0),"") -> 0 | E7: 인천 | F7: =IFERROR(C7-(D7*B7),"") -> 0
A8: 해인기흥저온센터 | B8: =$B$4 -> 36 | C8: =IFERROR(VLOOKUP(A8,'★은성(주문일-당일)'!A:RV,2,FALSE),0) -> 0 | D8: =IFERROR(ROUNDDOWN(C8/B8,0),"") -> 0 | E8: 해인기흥 | F8: =IFERROR(C8-(D8*B8),"") -> 0
A9: 수원저온센터 | B9: =$B$4 -> 36 | C9: =IFERROR(VLOOKUP(A9,'★은성(주문일-당일)'!A:RV,2,FALSE),0) -> 0 | D9: =IFERROR(ROUNDDOWN(C9/B9,0),"") -> 0 | E9: 수원 | F9: =IFERROR(C9-(D9*B9),"") -> 0
A10: 오포저온 | B10: =$B$4 -> 36 | C10: =IFERROR(VLOOKUP(A10,'★은성(주문일-당일)'!A:RV,2,FALSE),0) -> 0 | D10: =IFERROR(ROUNDDOWN(C10/B10,0),"") -> 0 | E10: 오포 | F10: =IFERROR(C10-(D10*B10),"") -> 0
A11: 양주저온 | B11: =$B$4 -> 36 | C11: =IFERROR(VLOOKUP(A11,'★은성(주문일-당일)'!A:RV,2,FALSE),0) -> 0 | D11: =IFERROR(ROUNDDOWN(C11/B11,0),"") -> 0 | E11: 양주 | F11: =IFERROR(C11-(D11*B11),"") -> 0
A12: 원주저온 | B12: =$B$4 -> 36 | C12: =IFERROR(VLOOKUP(A12,'★은성(주문일-당일)'!A:RV,2,FALSE),0) -> 0 | D12: =IFERROR(ROUNDDOWN(C12/B12,0),"") -> 0 | E12: 원주 | F12: =IFERROR(C12-(D12*B12),"") -> 0
A14: 수도권 합계 | B14: =$B$4 -> 36 | C14: =SUM(C4:C12) -> 0 | D14: =IFERROR(ROUNDDOWN(C14/B14,0),"") -> 0 | F14: =IFERROR(C14-(D14*B14),"") -> 0
A16: 부산냉장 | B16: =$B$4 -> 36 | C16: =IFERROR(VLOOKUP(A16,'★은성(주문일-당일)'!A:RV,2,FALSE),0) -> 0 | D16: =IFERROR(ROUNDDOWN(C16/B16,0),"") -> 0 | E16: 부산 | F16: =IFERROR(C16-(D16*B16),"") -> 0
A17: 양산냉장 | B17: =$B$4 -> 36 | C17: =IFERROR(VLOOKUP(A17,'★은성(주문일-당일)'!A:RV,2,FALSE),0) -> 0 | D17: =IFERROR(ROUNDDOWN(C17/B17,0),"") -> 0 | E17: 양산 | F17: =IFERROR(C17-(D17*B17),"") -> 0
A19: 경남(김해)합계 | B19: =$B$4 -> 36 | C19: =SUM(C16:C17) -> 0 | D19: =IFERROR(ROUNDDOWN(C19/B19,0),"") -> 0 | F19: =IFERROR(C19-(D19*B19),"") -> 0
A21: 대구냉장 | B21: =$B$4 -> 36 | C21: =IFERROR(VLOOKUP(A21,'★은성(주문일-당일)'!A:RV,2,FALSE),0) -> 0 | D21: =IFERROR(ROUNDDOWN(C21/B21,0),"") -> 0 | E21: 대구 | F21: =IFERROR(C21-(D21*B21),"") -> 0
A22: 칠곡저온 | B22: =$B$4 -> 36 | C22: =IFERROR(VLOOKUP(A22,'★은성(주문일-당일)'!A:RV,2,FALSE),0) -> 0 | D22: =IFERROR(ROUNDDOWN(C22/B22,0),"") -> 0 | E22: 칠곡 | F22: =IFERROR(C22-(D22*B22),"") -> 0
A24: 경북(칠곡)합계 | B24: =$B$4 -> 36 | C24: =SUM(C21:C22) -> 0 | D24: =IFERROR(ROUNDDOWN(C24/B24,0),"") -> 0 | F24: =IFERROR(C24-(D24*B24),"") -> 0
A26: 광주냉장 | B26: =$B$4 -> 36 | C26: =IFERROR(VLOOKUP(A26,'★은성(주문일-당일)'!A:RV,2,FALSE),0) -> 0 | D26: =IFERROR(ROUNDDOWN(C26/B26,0),"") -> 0 | E26: 광주 | F26: =IFERROR(C26-(D26*B26),"") -> 0
A27: 광주B저온센터 | B27: =$B$4 -> 36 | C27: =IFERROR(VLOOKUP(A27,'★은성(주문일-당일)'!A:RV,2,FALSE),0) -> 0 | D27: =IFERROR(ROUNDDOWN(C27/B27,0),"") -> 0 | E27: 광주B | F27: =IFERROR(C27-(D27*B27),"") -> 0
A29: 호남권 합계 | B29: =$B$4 -> 36 | C29: =SUM(C26:C27) -> 0 | D29: =IFERROR(ROUNDDOWN(C29/B29,0),"") -> 0 | F29: =IFERROR(C29-(D29*B29),"") -> 0
A31: 제주냉장센터 | B31: =$B$4 -> 36 | C31: =IFERROR(VLOOKUP(A31,'★은성(주문일-당일)'!A:RV,2,FALSE),0) -> 0 | D31: =IFERROR(ROUNDDOWN(C31/B31,0),"") -> 0 | E31: 제주 | F31: =IFERROR(C31-(D31*B31),"") -> 0
A33: 제주권 합계 | B33: =$B$4 -> 36 | C33: =SUM(C31:C31) -> 0 | D33: =IFERROR(ROUNDDOWN(C33/B33,0),"") -> 0 | F33: =IFERROR(C33-(D33*B33),"") -> 0
A35: 총합계 | B35: =$B$4 -> 36 | C35: =SUM(C4:C12,C26:C27,C21:C22,C16:C17,C31:C31) -> 0 | D35: =IFERROR(ROUNDDOWN(C35/B35,0),"") -> 0 | F35: =IFERROR(C35-(D35*B35),"") -> 0 | G35: 소분박스 | H35: 소분낱개
A36: 총 박스/총 낱개수량 | B36: □ | D36: =SUM(D4:D12,D26:D27,D21:D22,D16:D17,D31:D31) -> 0 | F36: =SUM(F4:F12,F26:F27,F21:F22,F16:F17,F31:F31) -> 0 | G36: =IFERROR(ROUNDDOWN(F36/B26,0),"") -> 0 | H36: =IFERROR(F36-(G36*B26),"") -> 0
C37: =C14+C19+C24+C29+C33 -> 0 | H37: □
C38: =C37=C35 -> TRUE

Sheet APP예약)밸런스푼꽃맛살듬뿍샐러드
A2: =TODAY() -> 46310 | B2: 은성파머스_ 세븐 <2편> □
A3: 행 레이블 | B3: 입수 | C3: APP예약)밸런스푼꽃맛살 듬뿍샐러드 | D3: 박스 | E3: 센터명 | F3: 낱개
A4: 수도권냉장 | B4: 30 | C4: =IFERROR(VLOOKUP(A4,'★은성(주문일-당일)'!A:RV,3,FALSE),0) -> 0 | D4: =IFERROR(ROUNDDOWN(C4/B4,0),"") -> 0 | E4: 수도권 | F4: =IFERROR(C4-(D4*B4),"") -> 0
A5: 안성저온센터 | B5: =$B$4 -> 30 | C5: =IFERROR(VLOOKUP(A5,'★은성(주문일-당일)'!A:RV,3,FALSE),0) -> 0 | D5: =IFERROR(ROUNDDOWN(C5/B5,0),"") -> 0 | E5: 안성 | F5: =IFERROR(C5-(D5*B5),"") -> 0
A6: 세종냉장센터 | B6: =$B$4 -> 30 | C6: =IFERROR(VLOOKUP(A6,'★은성(주문일-당일)'!A:RV,3,FALSE),0) -> 0 | D6: =IFERROR(ROUNDDOWN(C6/B6,0),"") -> 0 | E6: 세종 | F6: =IFERROR(C6-(D6*B6),"") -> 0
A7: 인천저온 | B7: =$B$4 -> 30 | C7: =IFERROR(VLOOKUP(A7,'★은성(주문일-당일)'!A:RV,3,FALSE),0) -> 0 | D7: =IFERROR(ROUNDDOWN(C7/B7,0),"") -> 0 | E7: 인천 | F7: =IFERROR(C7-(D7*B7),"") -> 0
A8: 해인기흥저온센터 | B8: =$B$4 -> 30 | C8: =IFERROR(VLOOKUP(A8,'★은성(주문일-당일)'!A:RV,3,FALSE),0) -> 0 | D8: =IFERROR(ROUNDDOWN(C8/B8,0),"") -> 0 | E8: 해인기흥 | F8: =IFERROR(C8-(D8*B8),"") -> 0
A9: 수원저온센터 | B9: =$B$4 -> 30 | C9: =IFERROR(VLOOKUP(A9,'★은성(주문일-당일)'!A:RV,3,FALSE),0) -> 0 | D9: =IFERROR(ROUNDDOWN(C9/B9,0),"") -> 0 | E9: 수원 | F9: =IFERROR(C9-(D9*B9),"") -> 0
A10: 오포저온 | B10: =$B$4 -> 30 | C10: =IFERROR(VLOOKUP(A10,'★은성(주문일-당일)'!A:RV,3,FALSE),0) -> 0 | D10: =IFERROR(ROUNDDOWN(C10/B10,0),"") -> 0 | E10: 오포 | F10: =IFERROR(C10-(D10*B10),"") -> 0
A11: 양주저온 | B11: =$B$4 -> 30 | C11: =IFERROR(VLOOKUP(A11,'★은성(주문일-당일)'!A:RV,3,FALSE),0) -> 0 | D11: =IFERROR(ROUNDDOWN(C11/B11,0),"") -> 0 | E11: 양주 | F11: =IFERROR(C11-(D11*B11),"") -> 0
A12: 원주저온 | B12: =$B$4 -> 30 | C12: =IFERROR(VLOOKUP(A12,'★은성(주문일-당일)'!A:RV,3,FALSE),0) -> 0 | D12: =IFERROR(ROUNDDOWN(C12/B12,0),"") -> 0 | E12: 원주 | F12: =IFERROR(C12-(D12*B12),"") -> 0
A14: 수도권 합계 | B14: =$B$4 -> 30 | C14: =SUM(C4:C12) -> 0 | D14: =IFERROR(ROUNDDOWN(C14/B14,0),"") -> 0 | F14: =IFERROR(C14-(D14*B14),"") -> 0
A16: 부산냉장 | B16: =$B$4 -> 30 | C16: =IFERROR(VLOOKUP(A16,'★은성(주문일-당일)'!A:RV,3,FALSE),0) -> 0 | D16: =IFERROR(ROUNDDOWN(C16/B16,0),"") -> 0 | E16: 부산 | F16: =IFERROR(C16-(D16*B16),"") -> 0
A17: 양산냉장 | B17: =$B$4 -> 30 | C17: =IFERROR(VLOOKUP(A17,'★은성(주문일-당일)'!A:RV,3,FALSE),0) -> 0 | D17: =IFERROR(ROUNDDOWN(C17/B17,0),"") -> 0 | E17: 양산 | F17: =IFERROR(C17-(D17*B17),"") -> 0
A19: 경남(김해)합계 | B19: =$B$4 -> 30 | C19: =SUM(C16:C17) -> 0 | D19: =IFERROR(ROUNDDOWN(C19/B19,0),"") -> 0 | F19: =IFERROR(C19-(D19*B19),"") -> 0
A21: 대구냉장 | B21: =$B$4 -> 30 | C21: =IFERROR(VLOOKUP(A21,'★은성(주문일-당일)'!A:RV,3,FALSE),0) -> 0 | D21: =IFERROR(ROUNDDOWN(C21/B21,0),"") -> 0 | E21: 대구 | F21: =IFERROR(C21-(D21*B21),"") -> 0
A22: 칠곡저온 | B22: =$B$4 -> 30 | C22: =IFERROR(VLOOKUP(A22,'★은성(주문일-당일)'!A:RV,3,FALSE),0) -> 0 | D22: =IFERROR(ROUNDDOWN(C22/B22,0),"") -> 0 | E22: 칠곡 | F22: =IFERROR(C22-(D22*B22),"") -> 0
A24: 경북(칠곡)합계 | B24: =$B$4 -> 30 | C24: =SUM(C21:C22) -> 0 | D24: =IFERROR(ROUNDDOWN(C24/B24,0),"") -> 0 | F24: =IFERROR(C24-(D24*B24),"") -> 0
A26: 광주냉장 | B26: =$B$4 -> 30 | C26: =IFERROR(VLOOKUP(A26,'★은성(주문일-당일)'!A:RV,3,FALSE),0) -> 0 | D26: =IFERROR(ROUNDDOWN(C26/B26,0),"") -> 0 | E26: 광주 | F26: =IFERROR(C26-(D26*B26),"") -> 0
A27: 광주B저온센터 | B27: =$B$4 -> 30 | C27: =IFERROR(VLOOKUP(A27,'★은성(주문일-당일)'!A:RV,3,FALSE),0) -> 0 | D27: =IFERROR(ROUNDDOWN(C27/B27,0),"") -> 0 | E27: 광주B | F27: =IFERROR(C27-(D27*B27),"") -> 0
A29: 호남권 합계 | B29: =$B$4 -> 30 | C29: =SUM(C26:C27) -> 0 | D29: =IFERROR(ROUNDDOWN(C29/B29,0),"") -> 0 | F29: =IFERROR(C29-(D29*B29),"") -> 0
A31: 제주냉장센터 | B31: =$B$4 -> 30 | C31: =IFERROR(VLOOKUP(A31,'★은성(주문일-당일)'!A:RV,3,FALSE),0) -> 0 | D31: =IFERROR(ROUNDDOWN(C31/B31,0),"") -> 0 | E31: 제주 | F31: =IFERROR(C31-(D31*B31),"") -> 0
A33: 제주권 합계 | B33: =$B$4 -> 30 | C33: =SUM(C31:C31) -> 0 | D33: =IFERROR(ROUNDDOWN(C33/B33,0),"") -> 0 | F33: =IFERROR(C33-(D33*B33),"") -> 0
A35: 총합계 | B35: =$B$4 -> 30 | C35: =SUM(C4:C12,C26:C27,C21:C22,C16:C17,C31:C31) -> 0 | D35: =IFERROR(ROUNDDOWN(C35/B35,0),"") -> 0 | F35: =IFERROR(C35-(D35*B35),"") -> 0 | G35: 소분박스 | H35: 소분낱개
A36: 총 박스/총 낱개수량 | B36: □ | D36: =SUM(D4:D12,D26:D27,D21:D22,D16:D17,D31:D31) -> 0 | F36: =SUM(F4:F12,F26:F27,F21:F22,F16:F17,F31:F31) -> 0 | G36: =IFERROR(ROUNDDOWN(F36/B26,0),"") -> 0 | H36: =IFERROR(F36-(G36*B26),"") -> 0
C37: =C14+C19+C24+C29+C33 -> 0 | H37: □
C38: =C37=C35 -> TRUE

Sheet APP예약)밸런스푼에그듬뿍샐러드
A2: =TODAY() -> 46310 | B2: 은성파머스_ 세븐 <2편> □
A3: 행 레이블 | B3: 입수 | C3: APP예약)밸런스푼에그 듬뿍샐러드 | D3: 박스 | E3: 센터명 | F3: 낱개
A4: 수도권냉장 | B4: 30 | C4: =IFERROR(VLOOKUP(A4,'★은성(주문일-당일)'!A:RV,4,FALSE),0) -> 0 | D4: =IFERROR(ROUNDDOWN(C4/B4,0),"") -> 0 | E4: 수도권 | F4: =IFERROR(C4-(D4*B4),"") -> 0
A5: 안성저온센터 | B5: =$B$4 -> 30 | C5: =IFERROR(VLOOKUP(A5,'★은성(주문일-당일)'!A:RV,4,FALSE),0) -> 0 | D5: =IFERROR(ROUNDDOWN(C5/B5,0),"") -> 0 | E5: 안성 | F5: =IFERROR(C5-(D5*B5),"") -> 0
A6: 세종냉장센터 | B6: =$B$4 -> 30 | C6: =IFERROR(VLOOKUP(A6,'★은성(주문일-당일)'!A:RV,4,FALSE),0) -> 0 | D6: =IFERROR(ROUNDDOWN(C6/B6,0),"") -> 0 | E6: 세종 | F6: =IFERROR(C6-(D6*B6),"") -> 0
A7: 인천저온 | B7: =$B$4 -> 30 | C7: =IFERROR(VLOOKUP(A7,'★은성(주문일-당일)'!A:RV,4,FALSE),0) -> 0 | D7: =IFERROR(ROUNDDOWN(C7/B7,0),"") -> 0 | E7: 인천 | F7: =IFERROR(C7-(D7*B7),"") -> 0
A8: 해인기흥저온센터 | B8: =$B$4 -> 30 | C8: =IFERROR(VLOOKUP(A8,'★은성(주문일-당일)'!A:RV,4,FALSE),0) -> 0 | D8: =IFERROR(ROUNDDOWN(C8/B8,0),"") -> 0 | E8: 해인기흥 | F8: =IFERROR(C8-(D8*B8),"") -> 0
A9: 수원저온센터 | B9: =$B$4 -> 30 | C9: =IFERROR(VLOOKUP(A9,'★은성(주문일-당일)'!A:RV,4,FALSE),0) -> 0 | D9: =IFERROR(ROUNDDOWN(C9/B9,0),"") -> 0 | E9: 수원 | F9: =IFERROR(C9-(D9*B9),"") -> 0
A10: 오포저온 | B10: =$B$4 -> 30 | C10: =IFERROR(VLOOKUP(A10,'★은성(주문일-당일)'!A:RV,4,FALSE),0) -> 1 | D10: =IFERROR(ROUNDDOWN(C10/B10,0),"") -> 0 | E10: 오포 | F10: =IFERROR(C10-(D10*B10),"") -> 1
A11: 양주저온 | B11: =$B$4 -> 30 | C11: =IFERROR(VLOOKUP(A11,'★은성(주문일-당일)'!A:RV,4,FALSE),0) -> 0 | D11: =IFERROR(ROUNDDOWN(C11/B11,0),"") -> 0 | E11: 양주 | F11: =IFERROR(C11-(D11*B11),"") -> 0
A12: 원주저온 | B12: =$B$4 -> 30 | C12: =IFERROR(VLOOKUP(A12,'★은성(주문일-당일)'!A:RV,4,FALSE),0) -> 0 | D12: =IFERROR(ROUNDDOWN(C12/B12,0),"") -> 0 | E12: 원주 | F12: =IFERROR(C12-(D12*B12),"") -> 0
A14: 수도권 합계 | B14: =$B$4 -> 30 | C14: =SUM(C4:C12) -> 1 | D14: =IFERROR(ROUNDDOWN(C14/B14,0),"") -> 0 | F14: =IFERROR(C14-(D14*B14),"") -> 1
A16: 부산냉장 | B16: =$B$4 -> 30 | C16: =IFERROR(VLOOKUP(A16,'★은성(주문일-당일)'!A:RV,4,FALSE),0) -> 0 | D16: =IFERROR(ROUNDDOWN(C16/B16,0),"") -> 0 | E16: 부산 | F16: =IFERROR(C16-(D16*B16),"") -> 0
A17: 양산냉장 | B17: =$B$4 -> 30 | C17: =IFERROR(VLOOKUP(A17,'★은성(주문일-당일)'!A:RV,4,FALSE),0) -> 0 | D17: =IFERROR(ROUNDDOWN(C17/B17,0),"") -> 0 | E17: 양산 | F17: =IFERROR(C17-(D17*B17),"") -> 0
A19: 경남(김해)합계 | B19: =$B$4 -> 30 | C19: =SUM(C16:C17) -> 0 | D19: =IFERROR(ROUNDDOWN(C19/B19,0),"") -> 0 | F19: =IFERROR(C19-(D19*B19),"") -> 0
A21: 대구냉장 | B21: =$B$4 -> 30 | C21: =IFERROR(VLOOKUP(A21,'★은성(주문일-당일)'!A:RV,4,FALSE),0) -> 0 | D21: =IFERROR(ROUNDDOWN(C21/B21,0),"") -> 0 | E21: 대구 | F21: =IFERROR(C21-(D21*B21),"") -> 0
A22: 칠곡저온 | B22: =$B$4 -> 30 | C22: =IFERROR(VLOOKUP(A22,'★은성(주문일-당일)'!A:RV,4,FALSE),0) -> 0 | D22: =IFERROR(ROUNDDOWN(C22/B22,0),"") -> 0 | E22: 칠곡 | F22: =IFERROR(C22-(D22*B22),"") -> 0
A24: 경북(칠곡)합계 | B24: =$B$4 -> 30 | C24: =SUM(C21:C22) -> 0 | D24: =IFERROR(ROUNDDOWN(C24/B24,0),"") -> 0 | F24: =IFERROR(C24-(D24*B24),"") -> 0
A26: 광주냉장 | B26: =$B$4 -> 30 | C26: =IFERROR(VLOOKUP(A26,'★은성(주문일-당일)'!A:RV,4,FALSE),0) -> 0 | D26: =IFERROR(ROUNDDOWN(C26/B26,0),"") -> 0 | E26: 광주 | F26: =IFERROR(C26-(D26*B26),"") -> 0
A27: 광주B저온센터 | B27: =$B$4 -> 30 | C27: =IFERROR(VLOOKUP(A27,'★은성(주문일-당일)'!A:RV,4,FALSE),0) -> 0 | D27: =IFERROR(ROUNDDOWN(C27/B27,0),"") -> 0 | E27: 광주B | F27: =IFERROR(C27-(D27*B27),"") -> 0
A29: 호남권 합계 | B29: =$B$4 -> 30 | C29: =SUM(C26:C27) -> 0 | D29: =IFERROR(ROUNDDOWN(C29/B29,0),"") -> 0 | F29: =IFERROR(C29-(D29*B29),"") -> 0
A31: 제주냉장센터 | B31: =$B$4 -> 30 | C31: =IFERROR(VLOOKUP(A31,'★은성(주문일-당일)'!A:RV,4,FALSE),0) -> 0 | D31: =IFERROR(ROUNDDOWN(C31/B31,0),"") -> 0 | E31: 제주 | F31: =IFERROR(C31-(D31*B31),"") -> 0
A33: 제주권 합계 | B33: =$B$4 -> 30 | C33: =SUM(C31:C31) -> 0 | D33: =IFERROR(ROUNDDOWN(C33/B33,0),"") -> 0 | F33: =IFERROR(C33-(D33*B33),"") -> 0
A35: 총합계 | B35: =$B$4 -> 30 | C35: =SUM(C4:C12,C26:C27,C21:C22,C16:C17,C31:C31) -> 1 | D35: =IFERROR(ROUNDDOWN(C35/B35,0),"") -> 0 | F35: =IFERROR(C35-(D35*B35),"") -> 1 | G35: 소분박스 | H35: 소분낱개
A36: 총 박스/총 낱개수량 | B36: □ | D36: =SUM(D4:D12,D26:D27,D21:D22,D16:D17,D31:D31) -> 0 | F36: =SUM(F4:F12,F26:F27,F21:F22,F16:F17,F31:F31) -> 1 | G36: =IFERROR(ROUNDDOWN(F36/B26,0),"") -> 0 | H36: =IFERROR(F36-(G36*B26),"") -> 1
C37: =C14+C19+C24+C29+C33 -> 1 | H37: □
C38: =C37=C35 -> TRUE

Sheet APP예약)밸런스푼훈제오리듬뿍샐러드
A2: =TODAY() -> 46310 | B2: 은성파머스_ 세븐 <2편> □
A3: 행 레이블 | B3: 입수 | C3: APP예약)밸런스푼훈제오리 듬뿍샐러드 | D3: 박스 | E3: 센터명 | F3: 낱개
A4: 수도권냉장 | B4: 30 | C4: =IFERROR(VLOOKUP(A4,'★은성(주문일-당일)'!A:RV,5,FALSE),0) -> 0 | D4: =IFERROR(ROUNDDOWN(C4/B4,0),"") -> 0 | E4: 수도권 | F4: =IFERROR(C4-(D4*B4),"") -> 0
A5: 안성저온센터 | B5: =$B$4 -> 30 | C5: =IFERROR(VLOOKUP(A5,'★은성(주문일-당일)'!A:RV,5,FALSE),0) -> 0 | D5: =IFERROR(ROUNDDOWN(C5/B5,0),"") -> 0 | E5: 안성 | F5: =IFERROR(C5-(D5*B5),"") -> 0
A6: 세종냉장센터 | B6: =$B$4 -> 30 | C6: =IFERROR(VLOOKUP(A6,'★은성(주문일-당일)'!A:RV,5,FALSE),0) -> 0 | D6: =IFERROR(ROUNDDOWN(C6/B6,0),"") -> 0 | E6: 세종 | F6: =IFERROR(C6-(D6*B6),"") -> 0
A7: 인천저온 | B7: =$B$4 -> 30 | C7: =IFERROR(VLOOKUP(A7,'★은성(주문일-당일)'!A:RV,5,FALSE),0) -> 0 | D7: =IFERROR(ROUNDDOWN(C7/B7,0),"") -> 0 | E7: 인천 | F7: =IFERROR(C7-(D7*B7),"") -> 0
A8: 해인기흥저온센터 | B8: =$B$4 -> 30 | C8: =IFERROR(VLOOKUP(A8,'★은성(주문일-당일)'!A:RV,5,FALSE),0) -> 0 | D8: =IFERROR(ROUNDDOWN(C8/B8,0),"") -> 0 | E8: 해인기흥 | F8: =IFERROR(C8-(D8*B8),"") -> 0
A9: 수원저온센터 | B9: =$B$4 -> 30 | C9: =IFERROR(VLOOKUP(A9,'★은성(주문일-당일)'!A:RV,5,FALSE),0) -> 0 | D9: =IFERROR(ROUNDDOWN(C9/B9,0),"") -> 0 | E9: 수원 | F9: =IFERROR(C9-(D9*B9),"") -> 0
A10: 오포저온 | B10: =$B$4 -> 30 | C10: =IFERROR(VLOOKUP(A10,'★은성(주문일-당일)'!A:RV,5,FALSE),0) -> 0 | D10: =IFERROR(ROUNDDOWN(C10/B10,0),"") -> 0 | E10: 오포 | F10: =IFERROR(C10-(D10*B10),"") -> 0
A11: 양주저온 | B11: =$B$4 -> 30 | C11: =IFERROR(VLOOKUP(A11,'★은성(주문일-당일)'!A:RV,5,FALSE),0) -> 0 | D11: =IFERROR(ROUNDDOWN(C11/B11,0),"") -> 0 | E11: 양주 | F11: =IFERROR(C11-(D11*B11),"") -> 0
A12: 원주저온 | B12: =$B$4 -> 30 | C12: =IFERROR(VLOOKUP(A12,'★은성(주문일-당일)'!A:RV,5,FALSE),0) -> 0 | D12: =IFERROR(ROUNDDOWN(C12/B12,0),"") -> 0 | E12: 원주 | F12: =IFERROR(C12-(D12*B12),"") -> 0
A14: 수도권 합계 | B14: =$B$4 -> 30 | C14: =SUM(C4:C12) -> 0 | D14: =IFERROR(ROUNDDOWN(C14/B14,0),"") -> 0 | F14: =IFERROR(C14-(D14*B14),"") -> 0
A16: 부산냉장 | B16: =$B$4 -> 30 | C16: =IFERROR(VLOOKUP(A16,'★은성(주문일-당일)'!A:RV,5,FALSE),0) -> 0 | D16: =IFERROR(ROUNDDOWN(C16/B16,0),"") -> 0 | E16: 부산 | F16: =IFERROR(C16-(D16*B16),"") -> 0
A17: 양산냉장 | B17: =$B$4 -> 30 | C17: =IFERROR(VLOOKUP(A17,'★은성(주문일-당일)'!A:RV,5,FALSE),0) -> 0 | D17: =IFERROR(ROUNDDOWN(C17/B17,0),"") -> 0 | E17: 양산 | F17: =IFERROR(C17-(D17*B17),"") -> 0
A19: 경남(김해)합계 | B19: =$B$4 -> 30 | C19: =SUM(C16:C17) -> 0 | D19: =IFERROR(ROUNDDOWN(C19/B19,0),"") -> 0 | F19: =IFERROR(C19-(D19*B19),"") -> 0
A21: 대구냉장 | B21: =$B$4 -> 30 | C21: =IFERROR(VLOOKUP(A21,'★은성(주문일-당일)'!A:RV,5,FALSE),0) -> 0 | D21: =IFERROR(ROUNDDOWN(C21/B21,0),"") -> 0 | E21: 대구 | F21: =IFERROR(C21-(D21*B21),"") -> 0
A22: 칠곡저온 | B22: =$B$4 -> 30 | C22: =IFERROR(VLOOKUP(A22,'★은성(주문일-당일)'!A:RV,5,FALSE),0) -> 0 | D22: =IFERROR(ROUNDDOWN(C22/B22,0),"") -> 0 | E22: 칠곡 | F22: =IFERROR(C22-(D22*B22),"") -> 0
A24: 경북(칠곡)합계 | B24: =$B$4 -> 30 | C24: =SUM(C21:C22) -> 0 | D24: =IFERROR(ROUNDDOWN(C24/B24,0),"") -> 0 | F24: =IFERROR(C24-(D24*B24),"") -> 0
A26: 광주냉장 | B26: =$B$4 -> 30 | C26: =IFERROR(VLOOKUP(A26,'★은성(주문일-당일)'!A:RV,5,FALSE),0) -> 0 | D26: =IFERROR(ROUNDDOWN(C26/B26,0),"") -> 0 | E26: 광주 | F26: =IFERROR(C26-(D26*B26),"") -> 0
A27: 광주B저온센터 | B27: =$B$4 -> 30 | C27: =IFERROR(VLOOKUP(A27,'★은성(주문일-당일)'!A:RV,5,FALSE),0) -> 2 | D27: =IFERROR(ROUNDDOWN(C27/B27,0),"") -> 0 | E27: 광주B | F27: =IFERROR(C27-(D27*B27),"") -> 2
A29: 호남권 합계 | B29: =$B$4 -> 30 | C29: =SUM(C26:C27) -> 2 | D29: =IFERROR(ROUNDDOWN(C29/B29,0),"") -> 0 | F29: =IFERROR(C29-(D29*B29),"") -> 2
A31: 제주냉장센터 | B31: =$B$4 -> 30 | C31: =IFERROR(VLOOKUP(A31,'★은성(주문일-당일)'!A:RV,5,FALSE),0) -> 0 | D31: =IFERROR(ROUNDDOWN(C31/B31,0),"") -> 0 | E31: 제주 | F31: =IFERROR(C31-(D31*B31),"") -> 0
A33: 제주권 합계 | B33: =$B$4 -> 30 | C33: =SUM(C31:C31) -> 0 | D33: =IFERROR(ROUNDDOWN(C33/B33,0),"") -> 0 | F33: =IFERROR(C33-(D33*B33),"") -> 0
A35: 총합계 | B35: =$B$4 -> 30 | C35: =SUM(C4:C12,C26:C27,C21:C22,C16:C17,C31:C31) -> 2 | D35: =IFERROR(ROUNDDOWN(C35/B35,0),"") -> 0 | F35: =IFERROR(C35-(D35*B35),"") -> 2 | G35: 소분박스 | H35: 소분낱개
A36: 총 박스/총 낱개수량 | B36: □ | D36: =SUM(D4:D12,D26:D27,D21:D22,D16:D17,D31:D31) -> 0 | F36: =SUM(F4:F12,F26:F27,F21:F22,F16:F17,F31:F31) -> 2 | G36: =IFERROR(ROUNDDOWN(F36/B26,0),"") -> 0 | H36: =IFERROR(F36-(G36*B26),"") -> 2
C37: =C14+C19+C24+C29+C33 -> 2 | H37: □
C38: =C37=C35 -> TRUE

Sheet APP예약)치킨텐더샐러드
A2: =TODAY() -> 46310 | B2: 은성파머스_ 세븐 <2편> □
A3: 행 레이블 | B3: 입수 | C3: APP예약)치킨텐더샐러드 | D3: 박스 | E3: 센터명 | F3: 낱개
A4: 수도권냉장 | B4: 36 | C4: =IFERROR(VLOOKUP(A4,'★은성(주문일-당일)'!A:RV,6,FALSE),0) -> 0 | D4: =IFERROR(ROUNDDOWN(C4/B4,0),"") -> 0 | E4: 수도권 | F4: =IFERROR(C4-(D4*B4),"") -> 0
A5: 안성저온센터 | B5: =$B$4 -> 36 | C5: =IFERROR(VLOOKUP(A5,'★은성(주문일-당일)'!A:RV,6,FALSE),0) -> 0 | D5: =IFERROR(ROUNDDOWN(C5/B5,0),"") -> 0 | E5: 안성 | F5: =IFERROR(C5-(D5*B5),"") -> 0
A6: 세종냉장센터 | B6: =$B$4 -> 36 | C6: =IFERROR(VLOOKUP(A6,'★은성(주문일-당일)'!A:RV,6,FALSE),0) -> 0 | D6: =IFERROR(ROUNDDOWN(C6/B6,0),"") -> 0 | E6: 세종 | F6: =IFERROR(C6-(D6*B6),"") -> 0
A7: 인천저온 | B7: =$B$4 -> 36 | C7: =IFERROR(VLOOKUP(A7,'★은성(주문일-당일)'!A:RV,6,FALSE),0) -> 0 | D7: =IFERROR(ROUNDDOWN(C7/B7,0),"") -> 0 | E7: 인천 | F7: =IFERROR(C7-(D7*B7),"") -> 0
A8: 해인기흥저온센터 | B8: =$B$4 -> 36 | C8: =IFERROR(VLOOKUP(A8,'★은성(주문일-당일)'!A:RV,6,FALSE),0) -> 0 | D8: =IFERROR(ROUNDDOWN(C8/B8,0),"") -> 0 | E8: 해인기흥 | F8: =IFERROR(C8-(D8*B8),"") -> 0
A9: 수원저온센터 | B9: =$B$4 -> 36 | C9: =IFERROR(VLOOKUP(A9,'★은성(주문일-당일)'!A:RV,6,FALSE),0) -> 0 | D9: =IFERROR(ROUNDDOWN(C9/B9,0),"") -> 0 | E9: 수원 | F9: =IFERROR(C9-(D9*B9),"") -> 0
A10: 오포저온 | B10: =$B$4 -> 36 | C10: =IFERROR(VLOOKUP(A10,'★은성(주문일-당일)'!A:RV,6,FALSE),0) -> 0 | D10: =IFERROR(ROUNDDOWN(C10/B10,0),"") -> 0 | E10: 오포 | F10: =IFERROR(C10-(D10*B10),"") -> 0
A11: 양주저온 | B11: =$B$4 -> 36 | C11: =IFERROR(VLOOKUP(A11,'★은성(주문일-당일)'!A:RV,6,FALSE),0) -> 0 | D11: =IFERROR(ROUNDDOWN(C11/B11,0),"") -> 0 | E11: 양주 | F11: =IFERROR(C11-(D11*B11),"") -> 0
A12: 원주저온 | B12: =$B$4 -> 36 | C12: =IFERROR(VLOOKUP(A12,'★은성(주문일-당일)'!A:RV,6,FALSE),0) -> 0 | D12: =IFERROR(ROUNDDOWN(C12/B12,0),"") -> 0 | E12: 원주 | F12: =IFERROR(C12-(D12*B12),"") -> 0
A14: 수도권 합계 | B14: =$B$4 -> 36 | C14: =SUM(C4:C12) -> 0 | D14: =IFERROR(ROUNDDOWN(C14/B14,0),"") -> 0 | F14: =IFERROR(C14-(D14*B14),"") -> 0
A16: 부산냉장 | B16: =$B$4 -> 36 | C16: =IFERROR(VLOOKUP(A16,'★은성(주문일-당일)'!A:RV,6,FALSE),0) -> 0 | D16: =IFERROR(ROUNDDOWN(C16/B16,0),"") -> 0 | E16: 부산 | F16: =IFERROR(C16-(D16*B16),"") -> 0
A17: 양산냉장 | B17: =$B$4 -> 36 | C17: =IFERROR(VLOOKUP(A17,'★은성(주문일-당일)'!A:RV,6,FALSE),0) -> 0 | D17: =IFERROR(ROUNDDOWN(C17/B17,0),"") -> 0 | E17: 양산 | F17: =IFERROR(C17-(D17*B17),"") -> 0
A19: 경남(김해)합계 | B19: =$B$4 -> 36 | C19: =SUM(C16:C17) -> 0 | D19: =IFERROR(ROUNDDOWN(C19/B19,0),"") -> 0 | F19: =IFERROR(C19-(D19*B19),"") -> 0
A21: 대구냉장 | B21: =$B$4 -> 36 | C21: =IFERROR(VLOOKUP(A21,'★은성(주문일-당일)'!A:RV,6,FALSE),0) -> 0 | D21: =IFERROR(ROUNDDOWN(C21/B21,0),"") -> 0 | E21: 대구 | F21: =IFERROR(C21-(D21*B21),"") -> 0
A22: 칠곡저온 | B22: =$B$4 -> 36 | C22: =IFERROR(VLOOKUP(A22,'★은성(주문일-당일)'!A:RV,6,FALSE),0) -> 0 | D22: =IFERROR(ROUNDDOWN(C22/B22,0),"") -> 0 | E22: 칠곡 | F22: =IFERROR(C22-(D22*B22),"") -> 0
A24: 경북(칠곡)합계 | B24: =$B$4 -> 36 | C24: =SUM(C21:C22) -> 0 | D24: =IFERROR(ROUNDDOWN(C24/B24,0),"") -> 0 | F24: =IFERROR(C24-(D24*B24),"") -> 0
A26: 광주냉장 | B26: =$B$4 -> 36 | C26: =IFERROR(VLOOKUP(A26,'★은성(주문일-당일)'!A:RV,6,FALSE),0) -> 0 | D26: =IFERROR(ROUNDDOWN(C26/B26,0),"") -> 0 | E26: 광주 | F26: =IFERROR(C26-(D26*B26),"") -> 0
A27: 광주B저온센터 | B27: =$B$4 -> 36 | C27: =IFERROR(VLOOKUP(A27,'★은성(주문일-당일)'!A:RV,6,FALSE),0) -> 1 | D27: =IFERROR(ROUNDDOWN(C27/B27,0),"") -> 0 | E27: 광주B | F27: =IFERROR(C27-(D27*B27),"") -> 1
A29: 호남권 합계 | B29: =$B$4 -> 36 | C29: =SUM(C26:C27) -> 1 | D29: =IFERROR(ROUNDDOWN(C29/B29,0),"") -> 0 | F29: =IFERROR(C29-(D29*B29),"") -> 1
A31: 제주냉장센터 | B31: =$B$4 -> 36 | C31: =IFERROR(VLOOKUP(A31,'★은성(주문일-당일)'!A:RV,6,FALSE),0) -> 0 | D31: =IFERROR(ROUNDDOWN(C31/B31,0),"") -> 0 | E31: 제주 | F31: =IFERROR(C31-(D31*B31),"") -> 0
A33: 제주권 합계 | B33: =$B$4 -> 36 | C33: =SUM(C31:C31) -> 0 | D33: =IFERROR(ROUNDDOWN(C33/B33,0),"") -> 0 | F33: =IFERROR(C33-(D33*B33),"") -> 0
A35: 총합계 | B35: =$B$4 -> 36 | C35: =SUM(C4:C12,C26:C27,C21:C22,C16:C17,C31:C31) -> 1 | D35: =IFERROR(ROUNDDOWN(C35/B35,0),"") -> 0 | F35: =IFERROR(C35-(D35*B35),"") -> 1 | G35: 소분박스 | H35: 소분낱개
A36: 총 박스/총 낱개수량 | B36: □ | D36: =SUM(D4:D12,D26:D27,D21:D22,D16:D17,D31:D31) -> 0 | F36: =SUM(F4:F12,F26:F27,F21:F22,F16:F17,F31:F31) -> 1 | G36: =IFERROR(ROUNDDOWN(F36/B26,0),"") -> 0 | H36: =IFERROR(F36-(G36*B26),"") -> 1
C37: =C14+C19+C24+C29+C33 -> 1 | H37: □
C38: =C37=C35 -> TRUE

Sheet 밸런스푼)꽃맛살듬뿍샐러드 235g
A2: =TODAY() -> 46310 | B2: 은성파머스_ 세븐 <2편> □
A3: 행 레이블 | B3: 입수 | C3: 밸런스푼)꽃맛살듬뿍샐러드 235g | D3: 박스 | E3: 센터명 | F3: 낱개
A4: 수도권냉장 | B4: 30 | C4: =IFERROR(VLOOKUP(A4,'★은성(주문일-당일)'!A:RV,7,FALSE),0) -> 0 | D4: =IFERROR(ROUNDDOWN(C4/B4,0),"") -> 0 | E4: 수도권 | F4: =IFERROR(C4-(D4*B4),"") -> 0
A5: 안성저온센터 | B5: =$B$4 -> 30 | C5: =IFERROR(VLOOKUP(A5,'★은성(주문일-당일)'!A:RV,7,FALSE),0) -> 14 | D5: =IFERROR(ROUNDDOWN(C5/B5,0),"") -> 0 | E5: 안성 | F5: =IFERROR(C5-(D5*B5),"") -> 14
A6: 세종냉장센터 | B6: =$B$4 -> 30 | C6: =IFERROR(VLOOKUP(A6,'★은성(주문일-당일)'!A:RV,7,FALSE),0) -> 13 | D6: =IFERROR(ROUNDDOWN(C6/B6,0),"") -> 0 | E6: 세종 | F6: =IFERROR(C6-(D6*B6),"") -> 13
A7: 인천저온 | B7: =$B$4 -> 30 | C7: =IFERROR(VLOOKUP(A7,'★은성(주문일-당일)'!A:RV,7,FALSE),0) -> 35 | D7: =IFERROR(ROUNDDOWN(C7/B7,0),"") -> 1 | E7: 인천 | F7: =IFERROR(C7-(D7*B7),"") -> 5
A8: 해인기흥저온센터 | B8: =$B$4 -> 30 | C8: =IFERROR(VLOOKUP(A8,'★은성(주문일-당일)'!A:RV,7,FALSE),0) -> 33 | D8: =IFERROR(ROUNDDOWN(C8/B8,0),"") -> 1 | E8: 해인기흥 | F8: =IFERROR(C8-(D8*B8),"") -> 3
A9: 수원저온센터 | B9: =$B$4 -> 30 | C9: =IFERROR(VLOOKUP(A9,'★은성(주문일-당일)'!A:RV,7,FALSE),0) -> 27 | D9: =IFERROR(ROUNDDOWN(C9/B9,0),"") -> 0 | E9: 수원 | F9: =IFERROR(C9-(D9*B9),"") -> 27
A10: 오포저온 | B10: =$B$4 -> 30 | C10: =IFERROR(VLOOKUP(A10,'★은성(주문일-당일)'!A:RV,7,FALSE),0) -> 30 | D10: =IFERROR(ROUNDDOWN(C10/B10,0),"") -> 1 | E10: 오포 | F10: =IFERROR(C10-(D10*B10),"") -> 0
A11: 양주저온 | B11: =$B$4 -> 30 | C11: =IFERROR(VLOOKUP(A11,'★은성(주문일-당일)'!A:RV,7,FALSE),0) -> 33 | D11: =IFERROR(ROUNDDOWN(C11/B11,0),"") -> 1 | E11: 양주 | F11: =IFERROR(C11-(D11*B11),"") -> 3
A12: 원주저온 | B12: =$B$4 -> 30 | C12: =IFERROR(VLOOKUP(A12,'★은성(주문일-당일)'!A:RV,7,FALSE),0) -> 16 | D12: =IFERROR(ROUNDDOWN(C12/B12,0),"") -> 0 | E12: 원주 | F12: =IFERROR(C12-(D12*B12),"") -> 16
A14: 수도권 합계 | B14: =$B$4 -> 30 | C14: =SUM(C4:C12) -> 201 | D14: =IFERROR(ROUNDDOWN(C14/B14,0),"") -> 6 | F14: =IFERROR(C14-(D14*B14),"") -> 21
A16: 부산냉장 | B16: =$B$4 -> 30 | C16: =IFERROR(VLOOKUP(A16,'★은성(주문일-당일)'!A:RV,7,FALSE),0) -> 5 | D16: =IFERROR(ROUNDDOWN(C16/B16,0),"") -> 0 | E16: 부산 | F16: =IFERROR(C16-(D16*B16),"") -> 5
A17: 양산냉장 | B17: =$B$4 -> 30 | C17: =IFERROR(VLOOKUP(A17,'★은성(주문일-당일)'!A:RV,7,FALSE),0) -> 11 | D17: =IFERROR(ROUNDDOWN(C17/B17,0),"") -> 0 | E17: 양산 | F17: =IFERROR(C17-(D17*B17),"") -> 11
A19: 경남(김해)합계 | B19: =$B$4 -> 30 | C19: =SUM(C16:C17) -> 16 | D19: =IFERROR(ROUNDDOWN(C19/B19,0),"") -> 0 | F19: =IFERROR(C19-(D19*B19),"") -> 16
A21: 대구냉장 | B21: =$B$4 -> 30 | C21: =IFERROR(VLOOKUP(A21,'★은성(주문일-당일)'!A:RV,7,FALSE),0) -> 16 | D21: =IFERROR(ROUNDDOWN(C21/B21,0),"") -> 0 | E21: 대구 | F21: =IFERROR(C21-(D21*B21),"") -> 16
A22: 칠곡저온 | B22: =$B$4 -> 30 | C22: =IFERROR(VLOOKUP(A22,'★은성(주문일-당일)'!A:RV,7,FALSE),0) -> 13 | D22: =IFERROR(ROUNDDOWN(C22/B22,0),"") -> 0 | E22: 칠곡 | F22: =IFERROR(C22-(D22*B22),"") -> 13
A24: 경북(칠곡)합계 | B24: =$B$4 -> 30 | C24: =SUM(C21:C22) -> 29 | D24: =IFERROR(ROUNDDOWN(C24/B24,0),"") -> 0 | F24: =IFERROR(C24-(D24*B24),"") -> 29
A26: 광주냉장 | B26: =$B$4 -> 30 | C26: =IFERROR(VLOOKUP(A26,'★은성(주문일-당일)'!A:RV,7,FALSE),0) -> 5 | D26: =IFERROR(ROUNDDOWN(C26/B26,0),"") -> 0 | E26: 광주 | F26: =IFERROR(C26-(D26*B26),"") -> 5
A27: 광주B저온센터 | B27: =$B$4 -> 30 | C27: =IFERROR(VLOOKUP(A27,'★은성(주문일-당일)'!A:RV,7,FALSE),0) -> 4 | D27: =IFERROR(ROUNDDOWN(C27/B27,0),"") -> 0 | E27: 광주B | F27: =IFERROR(C27-(D27*B27),"") -> 4
A29: 호남권 합계 | B29: =$B$4 -> 30 | C29: =SUM(C26:C27) -> 9 | D29: =IFERROR(ROUNDDOWN(C29/B29,0),"") -> 0 | F29: =IFERROR(C29-(D29*B29),"") -> 9
A31: 제주냉장센터 | B31: =$B$4 -> 30 | C31: =IFERROR(VLOOKUP(A31,'★은성(주문일-당일)'!A:RV,7,FALSE),0) -> 6 | D31: =IFERROR(ROUNDDOWN(C31/B31,0),"") -> 0 | E31: 제주 | F31: =IFERROR(C31-(D31*B31),"") -> 6
A33: 제주권 합계 | B33: =$B$4 -> 30 | C33: =SUM(C31:C31) -> 6 | D33: =IFERROR(ROUNDDOWN(C33/B33,0),"") -> 0 | F33: =IFERROR(C33-(D33*B33),"") -> 6
A35: 총합계 | B35: =$B$4 -> 30 | C35: =SUM(C4:C12,C26:C27,C21:C22,C16:C17,C31:C31) -> 261 | D35: =IFERROR(ROUNDDOWN(C35/B35,0),"") -> 8 | F35: =IFERROR(C35-(D35*B35),"") -> 21 | G35: 소분박스 | H35: 소분낱개
A36: 총 박스/총 낱개수량 | B36: □ | D36: =SUM(D4:D12,D26:D27,D21:D22,D16:D17,D31:D31) -> 4 | F36: =SUM(F4:F12,F26:F27,F21:F22,F16:F17,F31:F31) -> 141 | G36: =IFERROR(ROUNDDOWN(F36/B26,0),"") -> 4 | H36: =IFERROR(F36-(G36*B26),"") -> 21
C37: =C14+C19+C24+C29+C33 -> 261 | H37: □
C38: =C37=C35 -> TRUE

Sheet 밸런스푼)새우듬뿍샐러드 185g
A2: =TODAY() -> 46310 | B2: 은성파머스_ 세븐 <2편> □
A3: 행 레이블 | B3: 입수 | C3: 밸런스푼)새우듬뿍 샐러드 185g | D3: 박스 | E3: 센터명 | F3: 낱개
A4: 수도권냉장 | B4: 30 | C4: =IFERROR(VLOOKUP(A4,'★은성(주문일-당일)'!A:RV,8,FALSE),0) -> 0 | D4: =IFERROR(ROUNDDOWN(C4/B4,0),"") -> 0 | E4: 수도권 | F4: =IFERROR(C4-(D4*B4),"") -> 0
A5: 안성저온센터 | B5: =$B$4 -> 30 | C5: =IFERROR(VLOOKUP(A5,'★은성(주문일-당일)'!A:RV,8,FALSE),0) -> 19 | D5: =IFERROR(ROUNDDOWN(C5/B5,0),"") -> 0 | E5: 안성 | F5: =IFERROR(C5-(D5*B5),"") -> 19
A6: 세종냉장센터 | B6: =$B$4 -> 30 | C6: =IFERROR(VLOOKUP(A6,'★은성(주문일-당일)'!A:RV,8,FALSE),0) -> 34 | D6: =IFERROR(ROUNDDOWN(C6/B6,0),"") -> 1 | E6: 세종 | F6: =IFERROR(C6-(D6*B6),"") -> 4
A7: 인천저온 | B7: =$B$4 -> 30 | C7: =IFERROR(VLOOKUP(A7,'★은성(주문일-당일)'!A:RV,8,FALSE),0) -> 36 | D7: =IFERROR(ROUNDDOWN(C7/B7,0),"") -> 1 | E7: 인천 | F7: =IFERROR(C7-(D7*B7),"") -> 6
A8: 해인기흥저온센터 | B8: =$B$4 -> 30 | C8: =IFERROR(VLOOKUP(A8,'★은성(주문일-당일)'!A:RV,8,FALSE),0) -> 59 | D8: =IFERROR(ROUNDDOWN(C8/B8,0),"") -> 1 | E8: 해인기흥 | F8: =IFERROR(C8-(D8*B8),"") -> 29
A9: 수원저온센터 | B9: =$B$4 -> 30 | C9: =IFERROR(VLOOKUP(A9,'★은성(주문일-당일)'!A:RV,8,FALSE),0) -> 39 | D9: =IFERROR(ROUNDDOWN(C9/B9,0),"") -> 1 | E9: 수원 | F9: =IFERROR(C9-(D9*B9),"") -> 9
A10: 오포저온 | B10: =$B$4 -> 30 | C10: =IFERROR(VLOOKUP(A10,'★은성(주문일-당일)'!A:RV,8,FALSE),0) -> 46 | D10: =IFERROR(ROUNDDOWN(C10/B10,0),"") -> 1 | E10: 오포 | F10: =IFERROR(C10-(D10*B10),"") -> 16
A11: 양주저온 | B11: =$B$4 -> 30 | C11: =IFERROR(VLOOKUP(A11,'★은성(주문일-당일)'!A:RV,8,FALSE),0) -> 43 | D11: =IFERROR(ROUNDDOWN(C11/B11,0),"") -> 1 | E11: 양주 | F11: =IFERROR(C11-(D11*B11),"") -> 13
A12: 원주저온 | B12: =$B$4 -> 30 | C12: =IFERROR(VLOOKUP(A12,'★은성(주문일-당일)'!A:RV,8,FALSE),0) -> 25 | D12: =IFERROR(ROUNDDOWN(C12/B12,0),"") -> 0 | E12: 원주 | F12: =IFERROR(C12-(D12*B12),"") -> 25
A14: 수도권 합계 | B14: =$B$4 -> 30 | C14: =SUM(C4:C12) -> 301 | D14: =IFERROR(ROUNDDOWN(C14/B14,0),"") -> 10 | F14: =IFERROR(C14-(D14*B14),"") -> 1
A16: 부산냉장 | B16: =$B$4 -> 30 | C16: =IFERROR(VLOOKUP(A16,'★은성(주문일-당일)'!A:RV,8,FALSE),0) -> 5 | D16: =IFERROR(ROUNDDOWN(C16/B16,0),"") -> 0 | E16: 부산 | F16: =IFERROR(C16-(D16*B16),"") -> 5
A17: 양산냉장 | B17: =$B$4 -> 30 | C17: =IFERROR(VLOOKUP(A17,'★은성(주문일-당일)'!A:RV,8,FALSE),0) -> 13 | D17: =IFERROR(ROUNDDOWN(C17/B17,0),"") -> 0 | E17: 양산 | F17: =IFERROR(C17-(D17*B17),"") -> 13
A19: 경남(김해)합계 | B19: =$B$4 -> 30 | C19: =SUM(C16:C17) -> 18 | D19: =IFERROR(ROUNDDOWN(C19/B19,0),"") -> 0 | F19: =IFERROR(C19-(D19*B19),"") -> 18
A21: 대구냉장 | B21: =$B$4 -> 30 | C21: =IFERROR(VLOOKUP(A21,'★은성(주문일-당일)'!A:RV,8,FALSE),0) -> 18 | D21: =IFERROR(ROUNDDOWN(C21/B21,0),"") -> 0 | E21: 대구 | F21: =IFERROR(C21-(D21*B21),"") -> 18
A22: 칠곡저온 | B22: =$B$4 -> 30 | C22: =IFERROR(VLOOKUP(A22,'★은성(주문일-당일)'!A:RV,8,FALSE),0) -> 20 | D22: =IFERROR(ROUNDDOWN(C22/B22,0),"") -> 0 | E22: 칠곡 | F22: =IFERROR(C22-(D22*B22),"") -> 20
A24: 경북(칠곡)합계 | B24: =$B$4 -> 30 | C24: =SUM(C21:C22) -> 38 | D24: =IFERROR(ROUNDDOWN(C24/B24,0),"") -> 1 | F24: =IFERROR(C24-(D24*B24),"") -> 8
A26: 광주냉장 | B26: =$B$4 -> 30 | C26: =IFERROR(VLOOKUP(A26,'★은성(주문일-당일)'!A:RV,8,FALSE),0) -> 6 | D26: =IFERROR(ROUNDDOWN(C26/B26,0),"") -> 0 | E26: 광주 | F26: =IFERROR(C26-(D26*B26),"") -> 6
A27: 광주B저온센터 | B27: =$B$4 -> 30 | C27: =IFERROR(VLOOKUP(A27,'★은성(주문일-당일)'!A:RV,8,FALSE),0) -> 13 | D27: =IFERROR(ROUNDDOWN(C27/B27,0),"") -> 0 | E27: 광주B | F27: =IFERROR(C27-(D27*B27),"") -> 13
A29: 호남권 합계 | B29: =$B$4 -> 30 | C29: =SUM(C26:C27) -> 19 | D29: =IFERROR(ROUNDDOWN(C29/B29,0),"") -> 0 | F29: =IFERROR(C29-(D29*B29),"") -> 19
A31: 제주냉장센터 | B31: =$B$4 -> 30 | C31: =IFERROR(VLOOKUP(A31,'★은성(주문일-당일)'!A:RV,8,FALSE),0) -> 9 | D31: =IFERROR(ROUNDDOWN(C31/B31,0),"") -> 0 | E31: 제주 | F31: =IFERROR(C31-(D31*B31),"") -> 9
A33: 제주권 합계 | B33: =$B$4 -> 30 | C33: =SUM(C31:C31) -> 9 | D33: =IFERROR(ROUNDDOWN(C33/B33,0),"") -> 0 | F33: =IFERROR(C33-(D33*B33),"") -> 9
A35: 총합계 | B35: =$B$4 -> 30 | C35: =SUM(C4:C12,C26:C27,C21:C22,C16:C17,C31:C31) -> 385 | D35: =IFERROR(ROUNDDOWN(C35/B35,0),"") -> 12 | F35: =IFERROR(C35-(D35*B35),"") -> 25 | G35: 소분박스 | H35: 소분낱개
A36: 총 박스/총 낱개수량 | B36: □ | D36: =SUM(D4:D12,D26:D27,D21:D22,D16:D17,D31:D31) -> 6 | F36: =SUM(F4:F12,F26:F27,F21:F22,F16:F17,F31:F31) -> 205 | G36: =IFERROR(ROUNDDOWN(F36/B26,0),"") -> 6 | H36: =IFERROR(F36-(G36*B26),"") -> 25
C37: =C14+C19+C24+C29+C33 -> 385 | H37: □
C38: =C37=C35 -> TRUE

Sheet 밸런스푼)에그듬뿍샐러드 230g
A2: =TODAY() -> 46310 | B2: 은성파머스_ 세븐 <2편> □
A3: 행 레이블 | B3: 입수 | C3: 밸런스푼)에그듬뿍샐러드 230g | D3: 박스 | E3: 센터명 | F3: 낱개
A4: 수도권냉장 | B4: 30 | C4: =IFERROR(VLOOKUP(A4,'★은성(주문일-당일)'!A:RV,9,FALSE),0) -> 0 | D4: =IFERROR(ROUNDDOWN(C4/B4,0),"") -> 0 | E4: 수도권 | F4: =IFERROR(C4-(D4*B4),"") -> 0
A5: 안성저온센터 | B5: =$B$4 -> 30 | C5: =IFERROR(VLOOKUP(A5,'★은성(주문일-당일)'!A:RV,9,FALSE),0) -> 29 | D5: =IFERROR(ROUNDDOWN(C5/B5,0),"") -> 0 | E5: 안성 | F5: =IFERROR(C5-(D5*B5),"") -> 29
A6: 세종냉장센터 | B6: =$B$4 -> 30 | C6: =IFERROR(VLOOKUP(A6,'★은성(주문일-당일)'!A:RV,9,FALSE),0) -> 19 | D6: =IFERROR(ROUNDDOWN(C6/B6,0),"") -> 0 | E6: 세종 | F6: =IFERROR(C6-(D6*B6),"") -> 19
A7: 인천저온 | B7: =$B$4 -> 30 | C7: =IFERROR(VLOOKUP(A7,'★은성(주문일-당일)'!A:RV,9,FALSE),0) -> 44 | D7: =IFERROR(ROUNDDOWN(C7/B7,0),"") -> 1 | E7: 인천 | F7: =IFERROR(C7-(D7*B7),"") -> 14
A8: 해인기흥저온센터 | B8: =$B$4 -> 30 | C8: =IFERROR(VLOOKUP(A8,'★은성(주문일-당일)'!A:RV,9,FALSE),0) -> 61 | D8: =IFERROR(ROUNDDOWN(C8/B8,0),"") -> 2 | E8: 해인기흥 | F8: =IFERROR(C8-(D8*B8),"") -> 1
A9: 수원저온센터 | B9: =$B$4 -> 30 | C9: =IFERROR(VLOOKUP(A9,'★은성(주문일-당일)'!A:RV,9,FALSE),0) -> 45 | D9: =IFERROR(ROUNDDOWN(C9/B9,0),"") -> 1 | E9: 수원 | F9: =IFERROR(C9-(D9*B9),"") -> 15
A10: 오포저온 | B10: =$B$4 -> 30 | C10: =IFERROR(VLOOKUP(A10,'★은성(주문일-당일)'!A:RV,9,FALSE),0) -> 44 | D10: =IFERROR(ROUNDDOWN(C10/B10,0),"") -> 1 | E10: 오포 | F10: =IFERROR(C10-(D10*B10),"") -> 14
A11: 양주저온 | B11: =$B$4 -> 30 | C11: =IFERROR(VLOOKUP(A11,'★은성(주문일-당일)'!A:RV,9,FALSE),0) -> 67 | D11: =IFERROR(ROUNDDOWN(C11/B11,0),"") -> 2 | E11: 양주 | F11: =IFERROR(C11-(D11*B11),"") -> 7
A12: 원주저온 | B12: =$B$4 -> 30 | C12: =IFERROR(VLOOKUP(A12,'★은성(주문일-당일)'!A:RV,9,FALSE),0) -> 25 | D12: =IFERROR(ROUNDDOWN(C12/B12,0),"") -> 0 | E12: 원주 | F12: =IFERROR(C12-(D12*B12),"") -> 25
A14: 수도권 합계 | B14: =$B$4 -> 30 | C14: =SUM(C4:C12) -> 334 | D14: =IFERROR(ROUNDDOWN(C14/B14,0),"") -> 11 | F14: =IFERROR(C14-(D14*B14),"") -> 4
A16: 부산냉장 | B16: =$B$4 -> 30 | C16: =IFERROR(VLOOKUP(A16,'★은성(주문일-당일)'!A:RV,9,FALSE),0) -> 13 | D16: =IFERROR(ROUNDDOWN(C16/B16,0),"") -> 0 | E16: 부산 | F16: =IFERROR(C16-(D16*B16),"") -> 13
A17: 양산냉장 | B17: =$B$4 -> 30 | C17: =IFERROR(VLOOKUP(A17,'★은성(주문일-당일)'!A:RV,9,FALSE),0) -> 14 | D17: =IFERROR(ROUNDDOWN(C17/B17,0),"") -> 0 | E17: 양산 | F17: =IFERROR(C17-(D17*B17),"") -> 14
A19: 경남(김해)합계 | B19: =$B$4 -> 30 | C19: =SUM(C16:C17) -> 27 | D19: =IFERROR(ROUNDDOWN(C19/B19,0),"") -> 0 | F19: =IFERROR(C19-(D19*B19),"") -> 27
A21: 대구냉장 | B21: =$B$4 -> 30 | C21: =IFERROR(VLOOKUP(A21,'★은성(주문일-당일)'!A:RV,9,FALSE),0) -> 19 | D21: =IFERROR(ROUNDDOWN(C21/B21,0),"") -> 0 | E21: 대구 | F21: =IFERROR(C21-(D21*B21),"") -> 19
A22: 칠곡저온 | B22: =$B$4 -> 30 | C22: =IFERROR(VLOOKUP(A22,'★은성(주문일-당일)'!A:RV,9,FALSE),0) -> 11 | D22: =IFERROR(ROUNDDOWN(C22/B22,0),"") -> 0 | E22: 칠곡 | F22: =IFERROR(C22-(D22*B22),"") -> 11
A24: 경북(칠곡)합계 | B24: =$B$4 -> 30 | C24: =SUM(C21:C22) -> 30 | D24: =IFERROR(ROUNDDOWN(C24/B24,0),"") -> 1 | F24: =IFERROR(C24-(D24*B24),"") -> 0
A26: 광주냉장 | B26: =$B$4 -> 30 | C26: =IFERROR(VLOOKUP(A26,'★은성(주문일-당일)'!A:RV,9,FALSE),0) -> 8 | D26: =IFERROR(ROUNDDOWN(C26/B26,0),"") -> 0 | E26: 광주 | F26: =IFERROR(C26-(D26*B26),"") -> 8
A27: 광주B저온센터 | B27: =$B$4 -> 30 | C27: =IFERROR(VLOOKUP(A27,'★은성(주문일-당일)'!A:RV,9,FALSE),0) -> 14 | D27: =IFERROR(ROUNDDOWN(C27/B27,0),"") -> 0 | E27: 광주B | F27: =IFERROR(C27-(D27*B27),"") -> 14
A29: 호남권 합계 | B29: =$B$4 -> 30 | C29: =SUM(C26:C27) -> 22 | D29: =IFERROR(ROUNDDOWN(C29/B29,0),"") -> 0 | F29: =IFERROR(C29-(D29*B29),"") -> 22
A31: 제주냉장센터 | B31: =$B$4 -> 30 | C31: =IFERROR(VLOOKUP(A31,'★은성(주문일-당일)'!A:RV,9,FALSE),0) -> 5 | D31: =IFERROR(ROUNDDOWN(C31/B31,0),"") -> 0 | E31: 제주 | F31: =IFERROR(C31-(D31*B31),"") -> 5
A33: 제주권 합계 | B33: =$B$4 -> 30 | C33: =SUM(C31:C31) -> 5 | D33: =IFERROR(ROUNDDOWN(C33/B33,0),"") -> 0 | F33: =IFERROR(C33-(D33*B33),"") -> 5
A35: 총합계 | B35: =$B$4 -> 30 | C35: =SUM(C4:C12,C26:C27,C21:C22,C16:C17,C31:C31) -> 418 | D35: =IFERROR(ROUNDDOWN(C35/B35,0),"") -> 13 | F35: =IFERROR(C35-(D35*B35),"") -> 28 | G35: 소분박스 | H35: 소분낱개
A36: 총 박스/총 낱개수량 | B36: □ | D36: =SUM(D4:D12,D26:D27,D21:D22,D16:D17,D31:D31) -> 7 | F36: =SUM(F4:F12,F26:F27,F21:F22,F16:F17,F31:F31) -> 208 | G36: =IFERROR(ROUNDDOWN(F36/B26,0),"") -> 6 | H36: =IFERROR(F36-(G36*B26),"") -> 28
C37: =C14+C19+C24+C29+C33 -> 418 | H37: □
C38: =C37=C35 -> TRUE

Sheet 밸런스푼)훈제오리듬뿍샐러드 225g
A2: =TODAY() -> 46310 | B2: 은성파머스_ 세븐 <2편> □
A3: 행 레이블 | B3: 입수 | C3: 밸런스푼)훈제오리듬뿍 샐러드 225g | D3: 박스 | E3: 센터명 | F3: 낱개
A4: 수도권냉장 | B4: 30 | C4: =IFERROR(VLOOKUP(A4,'★은성(주문일-당일)'!A:RV,10,FALSE),0) -> 0 | D4: =IFERROR(ROUNDDOWN(C4/B4,0),"") -> 0 | E4: 수도권 | F4: =IFERROR(C4-(D4*B4),"") -> 0
A5: 안성저온센터 | B5: =$B$4 -> 30 | C5: =IFERROR(VLOOKUP(A5,'★은성(주문일-당일)'!A:RV,10,FALSE),0) -> 20 | D5: =IFERROR(ROUNDDOWN(C5/B5,0),"") -> 0 | E5: 안성 | F5: =IFERROR(C5-(D5*B5),"") -> 20
A6: 세종냉장센터 | B6: =$B$4 -> 30 | C6: =IFERROR(VLOOKUP(A6,'★은성(주문일-당일)'!A:RV,10,FALSE),0) -> 28 | D6: =IFERROR(ROUNDDOWN(C6/B6,0),"") -> 0 | E6: 세종 | F6: =IFERROR(C6-(D6*B6),"") -> 28
A7: 인천저온 | B7: =$B$4 -> 30 | C7: =IFERROR(VLOOKUP(A7,'★은성(주문일-당일)'!A:RV,10,FALSE),0) -> 36 | D7: =IFERROR(ROUNDDOWN(C7/B7,0),"") -> 1 | E7: 인천 | F7: =IFERROR(C7-(D7*B7),"") -> 6
A8: 해인기흥저온센터 | B8: =$B$4 -> 30 | C8: =IFERROR(VLOOKUP(A8,'★은성(주문일-당일)'!A:RV,10,FALSE),0) -> 49 | D8: =IFERROR(ROUNDDOWN(C8/B8,0),"") -> 1 | E8: 해인기흥 | F8: =IFERROR(C8-(D8*B8),"") -> 19
A9: 수원저온센터 | B9: =$B$4 -> 30 | C9: =IFERROR(VLOOKUP(A9,'★은성(주문일-당일)'!A:RV,10,FALSE),0) -> 36 | D9: =IFERROR(ROUNDDOWN(C9/B9,0),"") -> 1 | E9: 수원 | F9: =IFERROR(C9-(D9*B9),"") -> 6
A10: 오포저온 | B10: =$B$4 -> 30 | C10: =IFERROR(VLOOKUP(A10,'★은성(주문일-당일)'!A:RV,10,FALSE),0) -> 51 | D10: =IFERROR(ROUNDDOWN(C10/B10,0),"") -> 1 | E10: 오포 | F10: =IFERROR(C10-(D10*B10),"") -> 21
A11: 양주저온 | B11: =$B$4 -> 30 | C11: =IFERROR(VLOOKUP(A11,'★은성(주문일-당일)'!A:RV,10,FALSE),0) -> 57 | D11: =IFERROR(ROUNDDOWN(C11/B11,0),"") -> 1 | E11: 양주 | F11: =IFERROR(C11-(D11*B11),"") -> 27
