Workbook

Sheet 은성파머스피벗발주량
A1: 10/19 | C1: 열 레이블
A2: 행 레이블 | C2: APP예약)밸런스푼꽃맛살듬뿍샐러드 | D2: APP예약)밸런스푼에그듬뿍샐러드 | E2: APP예약)밸런스푼훈제오리듬뿍샐러드 | F2: APP예약)치킨텐더샐러드 | G2: 밸런스푼)꽃맛살듬뿍샐러드 235g | H2: 밸런스푼)새우듬뿍샐러드 185g | I2: 밸런스푼)에그듬뿍샐러드 230g | J2: 밸런스푼)훈제오리듬뿍샐러드 225g | K2: 은성)닭가슴살샐러드 155g | L2: 은성)치킨텐더샐러드 150g | M2: 총합계
A3: 광주B저온센터 | C3: 1 | E3: 1 | F3: 1 | G3: 9 | H3: 11 | I3: 9 | J3: 14 | K3: 1 | M3: 47
A4: 광주냉장 | G4: 10 | H4: 5 | I4: 8 | J4: 12 | K4: 2 | L4: 4 | M4: 41
A5: 대구냉장 | G5: 16 | H5: 14 | I5: 20 | J5: 16 | K5: 4 | L5: 3 | M5: 73
A6: 부산냉장 | G6: 8 | H6: 8 | I6: 17 | J6: 12 | K6: 4 | M6: 49
A7: 세종냉장센터 | F7: 2 | G7: 17 | H7: 28 | I7: 23 | J7: 24 | K7: 11 | L7: 7 | M7: 112
A8: 수원저온센터 | E8: 1 | G8: 26 | H8: 45 | I8: 55 | J8: 40 | K8: 24 | L8: 25 | M8: 216
A9: 안성저온센터 | G9: 16 | H9: 19 | I9: 25 | J9: 23 | K9: 10 | L9: 11 | M9: 104
A10: 양산냉장 | G10: 6 | H10: 13 | I10: 15 | J10: 11 | K10: 2 | L10: 1 | M10: 48
A11: 양주저온 | D11: 1 | E11: 3 | G11: 35 | H11: 61 | I11: 81 | J11: 55 | K11: 25 | L11: 20 | M11: 281
A12: 오포저온 | G12: 39 | H12: 53 | I12: 51 | J12: 54 | K12: 31 | L12: 24 | M12: 252
A13: 원주저온 | G13: 20 | H13: 31 | I13: 22 | J13: 28 | K13: 7 | L13: 9 | M13: 117
A14: 인천저온 | G14: 36 | H14: 35 | I14: 57 | J14: 41 | K14: 23 | L14: 20 | M14: 212
A15: 제주냉장센터 | G15: 4 | H15: 12 | I15: 10 | J15: 11 | K15: 5 | L15: 1 | M15: 43
A16: 칠곡저온 | G16: 14 | H16: 20 | I16: 14 | J16: 20 | K16: 2 | L16: 4 | M16: 74
A17: 해인기흥저온센터 | G17: 35 | H17: 51 | I17: 65 | J17: 53 | K17: 19 | L17: 16 | M17: 239
A18: 총합계 | C18: 1 | D18: 1 | E18: 5 | F18: 3 | G18: 291 | H18: 406 | I18: 472 | J18: 414 | K18: 170 | L18: 145 | M18: 1908

Sheet 제주냉장센터(더원)
B1: 제주냉장센터
B2: 거 래 명 세 표 (공급받는자 보관용)
B4: 공 급 받 는 자 | C4: 등록번호 | Q4: 공 급 자 | R4: 등록번호 | V4: 308-87-03289
C6: 상 호 (법인명) | G6: 세븐일레븐 | L6: 제주냉장센터 | R6: 상 호 (법인명) | V6: 주식회사 은성파머스 | AB6: 성 명 | AD6: 안은엽
C8: 사업장 주 소 | G8: 제주시 조천읍 와흘로 241 | R8: 사업장 주 소 | V8: 경기도 여주시 세종대왕면 매류1길 45
C10: 합계금액 (VAT포함) | R10: 업 태 | V10: 도소매 | AB10: 종 목 | AD10: 식품도소매
B12: 년 | C12: 월 | D12: 일 | E12: 품 목 | M12: 입수 | Q12: 총수량 | T12: 박스 | W12: 낱개수량 | AA12: 비고
B13: 46314 | E13: APP예약)닭가슴살샐러드 | M13: 36 | Q13: =IFERROR(VLOOKUP(B1,은성파머스피벗발주량!A:DC,2,FALSE),0) -> 0 | T13: =IFERROR(ROUNDDOWN(Q13/M13,0),"") -> 0 | W13: =IFERROR(Q13-(T13*M13),"") -> 0 | AA13: =B13+4 -> 46318
E14: APP예약)밸런스푼꽃맛살듬뿍샐러드 | M14: 30 | Q14: =IFERROR(VLOOKUP(B1,은성파머스피벗발주량!A:DC,3,FALSE),0) -> 0 | T14: =IFERROR(ROUNDDOWN(Q14/M14,0),"") -> 0 | W14: =IFERROR(Q14-(T14*M14),"") -> 0 | AA14: =B13+4 -> 46318
E15: APP예약)밸런스푼에그듬뿍샐러드 | M15: 30 | Q15: =IFERROR(VLOOKUP(B1,은성파머스피벗발주량!A:DC,4,FALSE),0) -> 0 | T15: =IFERROR(ROUNDDOWN(Q15/M15,0),"") -> 0 | W15: =IFERROR(Q15-(T15*M15),"") -> 0 | AA15: =B13+4 -> 46318
E16: APP예약)밸런스푼훈제오리듬뿍샐러드 | M16: 30 | Q16: =IFERROR(VLOOKUP(B1,은성파머스피벗발주량!A:DC,5,FALSE),0) -> 0 | T16: =IFERROR(ROUNDDOWN(Q16/M16,0),"") -> 0 | W16: =IFERROR(Q16-(T16*M16),"") -> 0 | AA16: =B13+4 -> 46318
E17: APP예약)치킨텐더샐러드 | M17: 36 | Q17: =IFERROR(VLOOKUP(B1,은성파머스피벗발주량!A:DC,6,FALSE),0) -> 0 | T17: =IFERROR(ROUNDDOWN(Q17/M17,0),"") -> 0 | W17: =IFERROR(Q17-(T17*M17),"") -> 0 | AA17: =B13+4 -> 46318
E18: 밸런스푼)꽃맛살듬뿍샐러드 235g | M18: 30 | Q18: =IFERROR(VLOOKUP(B1,은성파머스피벗발주량!A:DC,7,FALSE),0) -> 4 | T18: =IFERROR(ROUNDDOWN(Q18/M18,0),"") -> 0 | W18: =IFERROR(Q18-(T18*M18),"") -> 4 | AA18: =B13+4 -> 46318
E19: 밸런스푼)새우듬뿍샐러드 185g | M19: 30 | Q19: =IFERROR(VLOOKUP(B1,은성파머스피벗발주량!A:DC,8,FALSE),0) -> 12 | T19: =IFERROR(ROUNDDOWN(Q19/M19,0),"") -> 0 | W19: =IFERROR(Q19-(T19*M19),"") -> 12 | AA19: =B13+4 -> 46318
E20: 밸런스푼)에그듬뿍샐러드 230g | M20: 30 | Q20: =IFERROR(VLOOKUP(B1,은성파머스피벗발주량!A:DC,9,FALSE),0) -> 10 | T20: =IFERROR(ROUNDDOWN(Q20/M20,0),"") -> 0 | W20: =IFERROR(Q20-(T20*M20),"") -> 10 | AA20: =B13+4 -> 46318
E21: 밸런스푼)훈제오리듬뿍샐러드 225g | M21: 30 | Q21: =IFERROR(VLOOKUP(B1,은성파머스피벗발주량!A:DC,10,FALSE),0) -> 11 | T21: =IFERROR(ROUNDDOWN(Q21/M21,0),"") -> 0 | W21: =IFERROR(Q21-(T21*M21),"") -> 11 | AA21: =B13+4 -> 46318
E22: 은성)닭가슴살샐러드 155g | M22: 36 | Q22: =IFERROR(VLOOKUP(B1,은성파머스피벗발주량!A:DC,11,FALSE),0) -> 5 | T22: =IFERROR(ROUNDDOWN(Q22/M22,0),"") -> 0 | W22: =IFERROR(Q22-(T22*M22),"") -> 5 | AA22: =B13+4 -> 46318
E23: 은성)치킨텐더샐러드 150g | M23: 36 | Q23: =IFERROR(VLOOKUP(B1,은성파머스피벗발주량!A:DC,12,FALSE),0) -> 1 | T23: =IFERROR(ROUNDDOWN(Q23/M23,0),"") -> 0 | W23: =IFERROR(Q23-(T23*M23),"") -> 1 | AA23: =B13+4 -> 46318
B24: 총수량 | M24: =SUM(Q13:S23) -> 43
B25: 3자물류 (더원물류) 담당자 박병선이사 010-4448-1456 | W25: 제주시 조천읍 와흘로 241 064-784-9924
B29: 거 래 명 세 표 (공급자 보관용)
B31: 공 급 받 는 자 | C31: =C4 -> 등록번호 | Q31: 공 급 자 | R31: 등록번호 | V31: =V4 -> 308-87-03289
C33: =C6 -> 상 호 (법인명) | G33: =G6 -> 세븐일레븐 | L33: =L6 -> 제주냉장센터 | R33: 상 호 (법인명) | V33: =V6 -> 주식회사 은성파머스 | AB33: 성 명 | AD33: =AD6 -> 안은엽
C35: 사업장 주 소 | G35: =G8 -> 제주시 조천읍 와흘로 241 | R35: 사업장 주 소 | V35: =V8 -> 경기도 여주시 세종대왕면 매류1길 45
C37: 합계금액 (VAT포함) | R37: 업 태 | V37: =V10 -> 도소매 | AB37: =AB10 -> 종 목 | AD37: 농후발효유, 그릭요거트
B39: 년 | C39: 월 | D39: 일 | E39: 품 목 | M39: 입수 | Q39: 총수량 | T39: 박스 | W39: 낱개수량 | AA39: 비고
B40: =B13 -> 46314 | E40: =E13 -> APP예약)닭가슴살샐러드 | M40: =M13 -> 36 | Q40: =Q13 -> 0 | T40: =T13 -> 0 | W40: =W13 -> 0 | AA40: =AA13 -> 46318
E41: =E14 -> APP예약)밸런스푼꽃맛살듬뿍샐러드 | M41: =M14 -> 30 | Q41: =Q14 -> 0 | T41: =T14 -> 0 | W41: =W14 -> 0 | AA41: =AA14 -> 46318
E42: =E15 -> APP예약)밸런스푼에그듬뿍샐러드 | M42: =M15 -> 30 | Q42: =Q15 -> 0 | T42: =T15 -> 0 | W42: =W15 -> 0 | AA42: =AA15 -> 46318
E43: =E16 -> APP예약)밸런스푼훈제오리듬뿍샐러드 | M43: =M16 -> 30 | Q43: =Q16 -> 0 | T43: =T16 -> 0 | W43: =W16 -> 0 | AA43: =AA16 -> 46318
E44: =E17 -> APP예약)치킨텐더샐러드 | M44: =M17 -> 36 | Q44: =Q17 -> 0 | T44: =T17 -> 0 | W44: =W17 -> 0 | AA44: =AA17 -> 46318
E45: =E18 -> 밸런스푼)꽃맛살듬뿍샐러드 235g | M45: =M18 -> 30 | Q45: =Q18 -> 4 | T45: =T18 -> 0 | W45: =W18 -> 4 | AA45: =AA18 -> 46318
E46: =E19 -> 밸런스푼)새우듬뿍샐러드 185g | M46: =M19 -> 30 | Q46: =Q19 -> 12 | T46: =T19 -> 0 | W46: =W19 -> 12 | AA46: =AA19 -> 46318
E47: =E20 -> 밸런스푼)에그듬뿍샐러드 230g | M47: =M20 -> 30 | Q47: =Q20 -> 10 | T47: =T20 -> 0 | W47: =W20 -> 10 | AA47: =AA20 -> 46318
E48: =E21 -> 밸런스푼)훈제오리듬뿍샐러드 225g | M48: =M21 -> 30 | Q48: =Q21 -> 11 | T48: =T21 -> 0 | W48: =W21 -> 11 | AA48: =AA21 -> 46318
E49: =E22 -> 은성)닭가슴살샐러드 155g | M49: =M22 -> 36 | Q49: =Q22 -> 5 | T49: =T22 -> 0 | W49: =W22 -> 5 | AA49: =AA22 -> 46318
E50: =E23 -> 은성)치킨텐더샐러드 150g | M50: =M23 -> 36 | Q50: =Q23 -> 1 | T50: =T23 -> 0 | W50: =W23 -> 1 | AA50: =AA23 -> 46318
B51: =B24 -> 총수량 | M51: =SUM(Q40:S50) -> 43
B52: =B25 -> 3자물류 (더원물류) 담당자 박병선이사 010-4448-1456 | W52: =W25 -> 제주시 조천읍 와흘로 241 064-784-9924

Sheet 광주B저온센터(호남권)
B1: 광주B저온센터
B2: 거 래 명 세 표 (공급받는자 보관용)
B4: 공 급 받 는 자 | C4: 등록번호 | Q4: 공 급 자 | R4: 등록번호 | V4: 308-87-03289
C6: 상 호 (법인명) | G6: 세븐일레븐 | L6: 광주B저온센터 | R6: 상 호 (법인명) | V6: 주식회사 은성파머스 | AB6: 성 명 | AD6: 안은엽
C8: 사업장 주 소 | G8: 광주광역시 광산구 진곡산단5번로 69 | R8: 사업장 주 소 | V8: 경기도 여주시 세종대왕면 매류1길 45
C10: 합계금액 (VAT포함) | R10: 업 태 | V10: 도소매 | AB10: 종 목 | AD10: 식품도소매
B12: 년 | C12: 월 | D12: 일 | E12: 품 목 | M12: 입수 | Q12: 총수량 | T12: 박스 | W12: 낱개수량 | AA12: 비고
B13: ='제주냉장센터(더원)'!B13 -> 46314 | E13: APP예약)닭가슴살샐러드 | M13: 36 | Q13: =IFERROR(VLOOKUP(B1,은성파머스피벗발주량!A:DC,2,FALSE),0) -> 0 | T13: =IFERROR(ROUNDDOWN(Q13/M13,0),"") -> 0 | W13: =IFERROR(Q13-(T13*M13),"") -> 0 | AA13: =B13+4 -> 46318
E14: APP예약)밸런스푼꽃맛살듬뿍샐러드 | M14: 30 | Q14: =IFERROR(VLOOKUP(B1,은성파머스피벗발주량!A:DC,3,FALSE),0) -> 1 | T14: =IFERROR(ROUNDDOWN(Q14/M14,0),"") -> 0 | W14: =IFERROR(Q14-(T14*M14),"") -> 1 | AA14: =B13+4 -> 46318
E15: APP예약)밸런스푼에그듬뿍샐러드 | M15: 30 | Q15: =IFERROR(VLOOKUP(B1,은성파머스피벗발주량!A:DC,4,FALSE),0) -> 0 | T15: =IFERROR(ROUNDDOWN(Q15/M15,0),"") -> 0 | W15: =IFERROR(Q15-(T15*M15),"") -> 0 | AA15: =B13+4 -> 46318
E16: APP예약)밸런스푼훈제오리듬뿍샐러드 | M16: 30 | Q16: =IFERROR(VLOOKUP(B1,은성파머스피벗발주량!A:DC,5,FALSE),0) -> 1 | T16: =IFERROR(ROUNDDOWN(Q16/M16,0),"") -> 0 | W16: =IFERROR(Q16-(T16*M16),"") -> 1 | AA16: =B13+4 -> 46318
E17: APP예약)치킨텐더샐러드 | M17: 36 | Q17: =IFERROR(VLOOKUP(B1,은성파머스피벗발주량!A:DC,6,FALSE),0) -> 1 | T17: =IFERROR(ROUNDDOWN(Q17/M17,0),"") -> 0 | W17: =IFERROR(Q17-(T17*M17),"") -> 1 | AA17: =B13+4 -> 46318
E18: 밸런스푼)꽃맛살듬뿍샐러드 235g | M18: 30 | Q18: =IFERROR(VLOOKUP(B1,은성파머스피벗발주량!A:DC,7,FALSE),0) -> 9 | T18: =IFERROR(ROUNDDOWN(Q18/M18,0),"") -> 0 | W18: =IFERROR(Q18-(T18*M18),"") -> 9 | AA18: =B13+4 -> 46318
E19: 밸런스푼)새우듬뿍샐러드 185g | M19: 30 | Q19: =IFERROR(VLOOKUP(B1,은성파머스피벗발주량!A:DC,8,FALSE),0) -> 11 | T19: =IFERROR(ROUNDDOWN(Q19/M19,0),"") -> 0 | W19: =IFERROR(Q19-(T19*M19),"") -> 11 | AA19: =B13+4 -> 46318
E20: 밸런스푼)에그듬뿍샐러드 230g | M20: 30 | Q20: =IFERROR(VLOOKUP(B1,은성파머스피벗발주량!A:DC,9,FALSE),0) -> 9 | T20: =IFERROR(ROUNDDOWN(Q20/M20,0),"") -> 0 | W20: =IFERROR(Q20-(T20*M20),"") -> 9 | AA20: =B13+4 -> 46318
E21: 밸런스푼)훈제오리듬뿍샐러드 225g | M21: 30 | Q21: =IFERROR(VLOOKUP(B1,은성파머스피벗발주량!A:DC,10,FALSE),0) -> 14 | T21: =IFERROR(ROUNDDOWN(Q21/M21,0),"") -> 0 | W21: =IFERROR(Q21-(T21*M21),"") -> 14 | AA21: =B13+4 -> 46318
E22: 은성)닭가슴살샐러드 155g | M22: 36 | Q22: =IFERROR(VLOOKUP(B1,은성파머스피벗발주량!A:DC,11,FALSE),0) -> 1 | T22: =IFERROR(ROUNDDOWN(Q22/M22,0),"") -> 0 | W22: =IFERROR(Q22-(T22*M22),"") -> 1 | AA22: =B13+4 -> 46318
E23: 은성)치킨텐더샐러드 150g | M23: 36 | Q23: =IFERROR(VLOOKUP(B1,은성파머스피벗발주량!A:DC,12,FALSE),0) -> 0 | T23: =IFERROR(ROUNDDOWN(Q23/M23,0),"") -> 0 | W23: =IFERROR(Q23-(T23*M23),"") -> 0 | AA23: =B13+4 -> 46318
B24: 총수량 | M24: =SUM(Q13:S23) -> 47
B25: 3자물류 (더원물류) 담당자 박병선이사 010-4448-1456 | W25: 광주광역시 광산구 진곡산단5번로 69 062-959-7111
B29: 거 래 명 세 표 (공급자 보관용)
B31: 공 급 받 는 자 | C31: =C4 -> 등록번호 | Q31: 공 급 자 | R31: 등록번호 | V31: =V4 -> 308-87-03289
C33: =C6 -> 상 호 (법인명) | G33: =G6 -> 세븐일레븐 | L33: =L6 -> 광주B저온센터 | R33: 상 호 (법인명) | V33: =V6 -> 주식회사 은성파머스 | AB33: 성 명 | AD33: =AD6 -> 안은엽
C35: 사업장 주 소 | G35: =G8 -> 광주광역시 광산구 진곡산단5번로 69 | R35: 사업장 주 소 | V35: =V8 -> 경기도 여주시 세종대왕면 매류1길 45
C37: 합계금액 (VAT포함) | R37: 업 태 | V37: =V10 -> 도소매 | AB37: =AB10 -> 종 목 | AD37: 농후발효유, 그릭요거트
B39: 년 | C39: 월 | D39: 일 | E39: 품 목 | M39: 입수 | Q39: 총수량 | T39: 박스 | W39: 낱개수량 | AA39: 비고
B40: =B13 -> 46314 | E40: =E13 -> APP예약)닭가슴살샐러드 | M40: =M13 -> 36 | Q40: =Q13 -> 0 | T40: =T13 -> 0 | W40: =W13 -> 0 | AA40: =AA13 -> 46318
E41: =E14 -> APP예약)밸런스푼꽃맛살듬뿍샐러드 | M41: =M14 -> 30 | Q41: =Q14 -> 1 | T41: =T14 -> 0 | W41: =W14 -> 1 | AA41: =AA14 -> 46318
E42: =E15 -> APP예약)밸런스푼에그듬뿍샐러드 | M42: =M15 -> 30 | Q42: =Q15 -> 0 | T42: =T15 -> 0 | W42: =W15 -> 0 | AA42: =AA15 -> 46318
E43: =E16 -> APP예약)밸런스푼훈제오리듬뿍샐러드 | M43: =M16 -> 30 | Q43: =Q16 -> 1 | T43: =T16 -> 0 | W43: =W16 -> 1 | AA43: =AA16 -> 46318
E44: =E17 -> APP예약)치킨텐더샐러드 | M44: =M17 -> 36 | Q44: =Q17 -> 1 | T44: =T17 -> 0 | W44: =W17 -> 1 | AA44: =AA17 -> 46318
E45: =E18 -> 밸런스푼)꽃맛살듬뿍샐러드 235g | M45: =M18 -> 30 | Q45: =Q18 -> 9 | T45: =T18 -> 0 | W45: =W18 -> 9 | AA45: =AA18 -> 46318
E46: =E19 -> 밸런스푼)새우듬뿍샐러드 185g | M46: =M19 -> 30 | Q46: =Q19 -> 11 | T46: =T19 -> 0 | W46: =W19 -> 11 | AA46: =AA19 -> 46318
E47: =E20 -> 밸런스푼)에그듬뿍샐러드 230g | M47: =M20 -> 30 | Q47: =Q20 -> 9 | T47: =T20 -> 0 | W47: =W20 -> 9 | AA47: =AA20 -> 46318
E48: =E21 -> 밸런스푼)훈제오리듬뿍샐러드 225g | M48: =M21 -> 30 | Q48: =Q21 -> 14 | T48: =T21 -> 0 | W48: =W21 -> 14 | AA48: =AA21 -> 46318
E49: =E22 -> 은성)닭가슴살샐러드 155g | M49: =M22 -> 36 | Q49: =Q22 -> 1 | T49: =T22 -> 0 | W49: =W22 -> 1 | AA49: =AA22 -> 46318
E50: =E23 -> 은성)치킨텐더샐러드 150g | M50: =M23 -> 36 | Q50: =Q23 -> 0 | T50: =T23 -> 0 | W50: =W23 -> 0 | AA50: =AA23 -> 46318
B51: =B24 -> 총수량 | M51: =SUM(Q40:S50) -> 47
B52: =B25 -> 3자물류 (더원물류) 담당자 박병선이사 010-4448-1456 | W52: =W25 -> 광주광역시 광산구 진곡산단5번로 69 062-959-7111

Sheet 광주냉장(호남권)
B1: 광주냉장
B2: 거 래 명 세 표 (공급받는자 보관용)
B4: 공 급 받 는 자 | C4: 등록번호 | Q4: 공 급 자 | R4: 등록번호 | V4: 308-87-03289
C6: 상 호 (법인명) | G6: 세븐일레븐 | L6: 광주냉장 | R6: 상 호 (법인명) | V6: 주식회사 은성파머스 | AB6: 성 명 | AD6: 안은엽
C8: 사업장 주 소 | G8: 광주광역시 북구 양일로 111(양산동) | R8: 사업장 주 소 | V8: 경기도 여주시 세종대왕면 매류1길 45
C10: 합계금액 (VAT포함) | R10: 업 태 | V10: 도소매 | AB10: 종 목 | AD10: 식품도소매
B12: 년 | C12: 월 | D12: 일 | E12: 품 목 | M12: 입수 | Q12: 총수량 | T12: 박스 | W12: 낱개수량 | AA12: 비고
B13: ='제주냉장센터(더원)'!B13 -> 46314 | E13: APP예약)닭가슴살샐러드 | M13: 36 | Q13: =IFERROR(VLOOKUP(B1,은성파머스피벗발주량!A:DC,2,FALSE),0) -> 0 | T13: =IFERROR(ROUNDDOWN(Q13/M13,0),"") -> 0 | W13: =IFERROR(Q13-(T13*M13),"") -> 0 | AA13: =B13+4 -> 46318
E14: APP예약)밸런스푼꽃맛살듬뿍샐러드 | M14: 30 | Q14: =IFERROR(VLOOKUP(B1,은성파머스피벗발주량!A:DC,3,FALSE),0) -> 0 | T14: =IFERROR(ROUNDDOWN(Q14/M14,0),"") -> 0 | W14: =IFERROR(Q14-(T14*M14),"") -> 0 | AA14: =B13+4 -> 46318
E15: APP예약)밸런스푼에그듬뿍샐러드 | M15: 30 | Q15: =IFERROR(VLOOKUP(B1,은성파머스피벗발주량!A:DC,4,FALSE),0) -> 0 | T15: =IFERROR(ROUNDDOWN(Q15/M15,0),"") -> 0 | W15: =IFERROR(Q15-(T15*M15),"") -> 0 | AA15: =B13+4 -> 46318
E16: APP예약)밸런스푼훈제오리듬뿍샐러드 | M16: 30 | Q16: =IFERROR(VLOOKUP(B1,은성파머스피벗발주량!A:DC,5,FALSE),0) -> 0 | T16: =IFERROR(ROUNDDOWN(Q16/M16,0),"") -> 0 | W16: =IFERROR(Q16-(T16*M16),"") -> 0 | AA16: =B13+4 -> 46318
E17: APP예약)치킨텐더샐러드 | M17: 36 | Q17: =IFERROR(VLOOKUP(B1,은성파머스피벗발주량!A:DC,6,FALSE),0) -> 0 | T17: =IFERROR(ROUNDDOWN(Q17/M17,0),"") -> 0 | W17: =IFERROR(Q17-(T17*M17),"") -> 0 | AA17: =B13+4 -> 46318
E18: 밸런스푼)꽃맛살듬뿍샐러드 235g | M18: 30 | Q18: =IFERROR(VLOOKUP(B1,은성파머스피벗발주량!A:DC,7,FALSE),0) -> 10 | T18: =IFERROR(ROUNDDOWN(Q18/M18,0),"") -> 0 | W18: =IFERROR(Q18-(T18*M18),"") -> 10 | AA18: =B13+4 -> 46318
E19: 밸런스푼)새우듬뿍샐러드 185g | M19: 30 | Q19: =IFERROR(VLOOKUP(B1,은성파머스피벗발주량!A:DC,8,FALSE),0) -> 5 | T19: =IFERROR(ROUNDDOWN(Q19/M19,0),"") -> 0 | W19: =IFERROR(Q19-(T19*M19),"") -> 5 | AA19: =B13+4 -> 46318
E20: 밸런스푼)에그듬뿍샐러드 230g | M20: 30 | Q20: =IFERROR(VLOOKUP(B1,은성파머스피벗발주량!A:DC,9,FALSE),0) -> 8 | T20: =IFERROR(ROUNDDOWN(Q20/M20,0),"") -> 0 | W20: =IFERROR(Q20-(T20*M20),"") -> 8 | AA20: =B13+4 -> 46318
E21: 밸런스푼)훈제오리듬뿍샐러드 225g | M21: 30 | Q21: =IFERROR(VLOOKUP(B1,은성파머스피벗발주량!A:DC,10,FALSE),0) -> 12 | T21: =IFERROR(ROUNDDOWN(Q21/M21,0),"") -> 0 | W21: =IFERROR(Q21-(T21*M21),"") -> 12 | AA21: =B13+4 -> 46318
E22: 은성)닭가슴살샐러드 155g | M22: 36 | Q22: =IFERROR(VLOOKUP(B1,은성파머스피벗발주량!A:DC,11,FALSE),0) -> 2 | T22: =IFERROR(ROUNDDOWN(Q22/M22,0),"") -> 0 | W22: =IFERROR(Q22-(T22*M22),"") -> 2 | AA22: =B13+4 -> 46318
E23: 은성)치킨텐더샐러드 150g | M23: 36 | Q23: =IFERROR(VLOOKUP(B1,은성파머스피벗발주량!A:DC,12,FALSE),0) -> 4 | T23: =IFERROR(ROUNDDOWN(Q23/M23,0),"") -> 0 | W23: =IFERROR(Q23-(T23*M23),"") -> 4 | AA23: =B13+4 -> 46318
B24: 총수량 | M24: =SUM(Q13:S23) -> 41
B25: 3자물류 (더원물류) 담당자 박병선이사 010-4448-1456 | W25: 광주광역시 북구 양일로 111(양산동) 062-574-6333
B29: 거 래 명 세 표 (공급자 보관용)
B31: 공 급 받 는 자 | C31: =C4 -> 등록번호 | Q31: 공 급 자 | R31: 등록번호 | V31: =V4 -> 308-87-03289
C33: =C6 -> 상 호 (법인명) | G33: =G6 -> 세븐일레븐 | L33: =L6 -> 광주냉장 | R33: 상 호 (법인명) | V33: =V6 -> 주식회사 은성파머스 | AB33: 성 명 | AD33: =AD6 -> 안은엽
C35: 사업장 주 소 | G35: =G8 -> 광주광역시 북구 양일로 111(양산동) | R35: 사업장 주 소 | V35: =V8 -> 경기도 여주시 세종대왕면 매류1길 45
C37: 합계금액 (VAT포함) | R37: 업 태 | V37: =V10 -> 도소매 | AB37: =AB10 -> 종 목 | AD37: 농후발효유, 그릭요거트
B39: 년 | C39: 월 | D39: 일 | E39: 품 목 | M39: 입수 | Q39: 총수량 | T39: 박스 | W39: 낱개수량 | AA39: 비고
B40: =B13 -> 46314 | E40: =E13 -> APP예약)닭가슴살샐러드 | M40: =M13 -> 36 | Q40: =Q13 -> 0 | T40: =T13 -> 0 | W40: =W13 -> 0 | AA40: =AA13 -> 46318
E41: =E14 -> APP예약)밸런스푼꽃맛살듬뿍샐러드 | M41: =M14 -> 30 | Q41: =Q14 -> 0 | T41: =T14 -> 0 | W41: =W14 -> 0 | AA41: =AA14 -> 46318
E42: =E15 -> APP예약)밸런스푼에그듬뿍샐러드 | M42: =M15 -> 30 | Q42: =Q15 -> 0 | T42: =T15 -> 0 | W42: =W15 -> 0 | AA42: =AA15 -> 46318
E43: =E16 -> APP예약)밸런스푼훈제오리듬뿍샐러드 | M43: =M16 -> 30 | Q43: =Q16 -> 0 | T43: =T16 -> 0 | W43: =W16 -> 0 | AA43: =AA16 -> 46318
E44: =E17 -> APP예약)치킨텐더샐러드 | M44: =M17 -> 36 | Q44: =Q17 -> 0 | T44: =T17 -> 0 | W44: =W17 -> 0 | AA44: =AA17 -> 46318
E45: =E18 -> 밸런스푼)꽃맛살듬뿍샐러드 235g | M45: =M18 -> 30 | Q45: =Q18 -> 10 | T45: =T18 -> 0 | W45: =W18 -> 10 | AA45: =AA18 -> 46318
E46: =E19 -> 밸런스푼)새우듬뿍샐러드 185g | M46: =M19 -> 30 | Q46: =Q19 -> 5 | T46: =T19 -> 0 | W46: =W19 -> 5 | AA46: =AA19 -> 46318
E47: =E20 -> 밸런스푼)에그듬뿍샐러드 230g | M47: =M20 -> 30 | Q47: =Q20 -> 8 | T47: =T20 -> 0 | W47: =W20 -> 8 | AA47: =AA20 -> 46318
E48: =E21 -> 밸런스푼)훈제오리듬뿍샐러드 225g | M48: =M21 -> 30 | Q48: =Q21 -> 12 | T48: =T21 -> 0 | W48: =W21 -> 12 | AA48: =AA21 -> 46318
E49: =E22 -> 은성)닭가슴살샐러드 155g | M49: =M22 -> 36 | Q49: =Q22 -> 2 | T49: =T22 -> 0 | W49: =W22 -> 2 | AA49: =AA22 -> 46318
E50: =E23 -> 은성)치킨텐더샐러드 150g | M50: =M23 -> 36 | Q50: =Q23 -> 4 | T50: =T23 -> 0 | W50: =W23 -> 4 | AA50: =AA23 -> 46318
B51: =B24 -> 총수량 | M51: =SUM(Q40:S50) -> 41
B52: =B25 -> 3자물류 (더원물류) 담당자 박병선이사 010-4448-1456 | W52: =W25 -> 광주광역시 북구 양일로 111(양산동) 062-574-6333

Sheet 김제냉장(호남권)
B1: 김제냉장
B2: 거 래 명 세 표 (공급받는자 보관용)
B4: 공 급 받 는 자 | C4: 등록번호 | Q4: 공 급 자 | R4: 등록번호 | V4: 308-87-03289
C6: 상 호 (법인명) | G6: 세븐일레븐 | L6: 김제냉장 | R6: 상 호 (법인명) | V6: 주식회사 은성파머스 | AB6: 성 명 | AD6: 안은엽
C8: 사업장 주 소 | G8: 전북 김제시 금산면 금평로 313 | R8: 사업장 주 소 | V8: 경기도 여주시 세종대왕면 매류1길 45
C10: 합계금액 (VAT포함) | R10: 업 태 | V10: 도소매 | AB10: 종 목 | AD10: 식품도소매
B12: 년 | C12: 월 | D12: 일 | E12: 품 목 | M12: 입수 | Q12: 총수량 | T12: 박스 | W12: 낱개수량 | AA12: 비고
B13: ='제주냉장센터(더원)'!B13 -> 46314 | E13: APP예약)닭가슴살샐러드 | M13: 36 | Q13: =IFERROR(VLOOKUP(B1,은성파머스피벗발주량!A:DC,2,FALSE),0) -> 0 | T13: =IFERROR(ROUNDDOWN(Q13/M13,0),"") -> 0 | W13: =IFERROR(Q13-(T13*M13),"") -> 0 | AA13: =B13+4 -> 46318
E14: APP예약)밸런스푼꽃맛살듬뿍샐러드 | M14: 30 | Q14: =IFERROR(VLOOKUP(B1,은성파머스피벗발주량!A:DC,3,FALSE),0) -> 0 | T14: =IFERROR(ROUNDDOWN(Q14/M14,0),"") -> 0 | W14: =IFERROR(Q14-(T14*M14),"") -> 0 | AA14: =B13+4 -> 46318
E15: APP예약)밸런스푼에그듬뿍샐러드 | M15: 30 | Q15: =IFERROR(VLOOKUP(B1,은성파머스피벗발주량!A:DC,4,FALSE),0) -> 0 | T15: =IFERROR(ROUNDDOWN(Q15/M15,0),"") -> 0 | W15: =IFERROR(Q15-(T15*M15),"") -> 0 | AA15: =B13+4 -> 46318
E16: APP예약)밸런스푼훈제오리듬뿍샐러드 | M16: 30 | Q16: =IFERROR(VLOOKUP(B1,은성파머스피벗발주량!A:DC,5,FALSE),0) -> 0 | T16: =IFERROR(ROUNDDOWN(Q16/M16,0),"") -> 0 | W16: =IFERROR(Q16-(T16*M16),"") -> 0 | AA16: =B13+4 -> 46318
E17: APP예약)치킨텐더샐러드 | M17: 36 | Q17: =IFERROR(VLOOKUP(B1,은성파머스피벗발주량!A:DC,6,FALSE),0) -> 0 | T17: =IFERROR(ROUNDDOWN(Q17/M17,0),"") -> 0 | W17: =IFERROR(Q17-(T17*M17),"") -> 0 | AA17: =B13+4 -> 46318
E18: 밸런스푼)꽃맛살듬뿍샐러드 235g | M18: 30 | Q18: =IFERROR(VLOOKUP(B1,은성파머스피벗발주량!A:DC,7,FALSE),0) -> 0 | T18: =IFERROR(ROUNDDOWN(Q18/M18,0),"") -> 0 | W18: =IFERROR(Q18-(T18*M18),"") -> 0 | AA18: =B13+4 -> 46318
E19: 밸런스푼)새우듬뿍샐러드 185g | M19: 30 | Q19: =IFERROR(VLOOKUP(B1,은성파머스피벗발주량!A:DC,8,FALSE),0) -> 0 | T19: =IFERROR(ROUNDDOWN(Q19/M19,0),"") -> 0 | W19: =IFERROR(Q19-(T19*M19),"") -> 0 | AA19: =B13+4 -> 46318
E20: 밸런스푼)에그듬뿍샐러드 230g | M20: 30 | Q20: =IFERROR(VLOOKUP(B1,은성파머스피벗발주량!A:DC,9,FALSE),0) -> 0 | T20: =IFERROR(ROUNDDOWN(Q20/M20,0),"") -> 0 | W20: =IFERROR(Q20-(T20*M20),"") -> 0 | AA20: =B13+4 -> 46318
E21: 밸런스푼)훈제오리듬뿍샐러드 225g | M21: 30 | Q21: =IFERROR(VLOOKUP(B1,은성파머스피벗발주량!A:DC,10,FALSE),0) -> 0 | T21: =IFERROR(ROUNDDOWN(Q21/M21,0),"") -> 0 | W21: =IFERROR(Q21-(T21*M21),"") -> 0 | AA21: =B13+4 -> 46318
E22: 은성)닭가슴살샐러드 155g | M22: 36 | Q22: =IFERROR(VLOOKUP(B1,은성파머스피벗발주량!A:DC,11,FALSE),0) -> 0 | T22: =IFERROR(ROUNDDOWN(Q22/M22,0),"") -> 0 | W22: =IFERROR(Q22-(T22*M22),"") -> 0 | AA22: =B13+4 -> 46318
E23: 은성)치킨텐더샐러드 150g | M23: 36 | Q23: =IFERROR(VLOOKUP(B1,은성파머스피벗발주량!A:DC,12,FALSE),0) -> 0 | T23: =IFERROR(ROUNDDOWN(Q23/M23,0),"") -> 0 | W23: =IFERROR(Q23-(T23*M23),"") -> 0 | AA23: =B13+4 -> 46318
B24: 총수량 | M24: =SUM(Q13:S23) -> 0
B25: 3자물류 (더원물류) 담당자 박병선이사 010-4448-1456 | W25: 광주광역시 북구 양일로 111(양산동) 062-574-6333
B29: 거 래 명 세 표 (공급자 보관용)
B31: 공 급 받 는 자 | C31: =C4 -> 등록번호 | Q31: 공 급 자 | R31: 등록번호 | V31: =V4 -> 308-87-03289
C33: =C6 -> 상 호 (법인명) | G33: =G6 -> 세븐일레븐 | L33: =L6 -> 김제냉장 | R33: 상 호 (법인명) | V33: =V6 -> 주식회사 은성파머스 | AB33: 성 명 | AD33: =AD6 -> 안은엽
C35: 사업장 주 소 | G35: =G8 -> 전북 김제시 금산면 금평로 313 | R35: 사업장 주 소 | V35: =V8 -> 경기도 여주시 세종대왕면 매류1길 45
C37: 합계금액 (VAT포함) | R37: 업 태 | V37: =V10 -> 도소매 | AB37: =AB10 -> 종 목 | AD37: 농후발효유, 그릭요거트
B39: 년 | C39: 월 | D39: 일 | E39: 품 목 | M39: 입수 | Q39: 총수량 | T39: 박스 | W39: 낱개수량 | AA39: 비고
B40: =B13 -> 46314 | E40: =E13 -> APP예약)닭가슴살샐러드 | M40: =M13 -> 36 | Q40: =Q13 -> 0 | T40: =T13 -> 0 | W40: =W13 -> 0 | AA40: =AA13 -> 46318
E41: =E14 -> APP예약)밸런스푼꽃맛살듬뿍샐러드 | M41: =M14 -> 30 | Q41: =Q14 -> 0 | T41: =T14 -> 0 | W41: =W14 -> 0 | AA41: =AA14 -> 46318
E42: =E15 -> APP예약)밸런스푼에그듬뿍샐러드 | M42: =M15 -> 30 | Q42: =Q15 -> 0 | T42: =T15 -> 0 | W42: =W15 -> 0 | AA42: =AA15 -> 46318
E43: =E16 -> APP예약)밸런스푼훈제오리듬뿍샐러드 | M43: =M16 -> 30 | Q43: =Q16 -> 0 | T43: =T16 -> 0 | W43: =W16 -> 0 | AA43: =AA16 -> 46318
E44: =E17 -> APP예약)치킨텐더샐러드 | M44: =M17 -> 36 | Q44: =Q17 -> 0 | T44: =T17 -> 0 | W44: =W17 -> 0 | AA44: =AA17 -> 46318
E45: =E18 -> 밸런스푼)꽃맛살듬뿍샐러드 235g | M45: =M18 -> 30 | Q45: =Q18 -> 0 | T45: =T18 -> 0 | W45: =W18 -> 0 | AA45: =AA18 -> 46318
E46: =E19 -> 밸런스푼)새우듬뿍샐러드 185g | M46: =M19 -> 30 | Q46: =Q19 -> 0 | T46: =T19 -> 0 | W46: =W19 -> 0 | AA46: =AA19 -> 46318
E47: =E20 -> 밸런스푼)에그듬뿍샐러드 230g | M47: =M20 -> 30 | Q47: =Q20 -> 0 | T47: =T20 -> 0 | W47: =W20 -> 0 | AA47: =AA20 -> 46318
E48: =E21 -> 밸런스푼)훈제오리듬뿍샐러드 225g | M48: =M21 -> 30 | Q48: =Q21 -> 0 | T48: =T21 -> 0 | W48: =W21 -> 0 | AA48: =AA21 -> 46318
E49: =E22 -> 은성)닭가슴살샐러드 155g | M49: =M22 -> 36 | Q49: =Q22 -> 0 | T49: =T22 -> 0 | W49: =W22 -> 0 | AA49: =AA22 -> 46318
E50: =E23 -> 은성)치킨텐더샐러드 150g | M50: =M23 -> 36 | Q50: =Q23 -> 0 | T50: =T23 -> 0 | W50: =W23 -> 0 | AA50: =AA23 -> 46318
B51: =B24 -> 총수량 | M51: =SUM(Q40:S50) -> 0
B52: =B25 -> 3자물류 (더원물류) 담당자 박병선이사 010-4448-1456 | W52: =W25 -> 광주광역시 북구 양일로 111(양산동) 062-574-6333

Sheet 대구냉장A동(영남권)_롯데확인
B1: 대구냉장
B2: 거 래 명 세 표 (공급받는자 보관용)
B4: 공 급 받 는 자 | C4: 등록번호 | Q4: 공 급 자 | R4: 등록번호 | V4: 308-87-03289
C6: 상 호 (법인명) | G6: 세븐일레븐 | L6: 대구냉장A동 | R6: 상 호 (법인명) | V6: 주식회사 은성파머스 | AB6: 성 명 | AD6: 안은엽
C8: 사업장 주 소 | G8: 경북 경산시 압량읍 가야로20 (212-3, 216-3) | R8: 사업장 주 소 | V8: 경기도 여주시 세종대왕면 매류1길 45
C10: 합계금액 (VAT포함) | R10: 업 태 | V10: 도소매 | AB10: 종 목 | AD10: 식품도소매
B12: 년 | C12: 월 | D12: 일 | E12: 품 목 | M12: 입수 | Q12: 총수량 | T12: 박스 | W12: 낱개수량 | AA12: 비고
B13: ='제주냉장센터(더원)'!B13 -> 46314 | E13: APP예약)닭가슴살샐러드 | M13: 36 | Q13: =IFERROR(VLOOKUP(B1,은성파머스피벗발주량!A:DC,2,FALSE),0) -> 0 | T13: =IFERROR(ROUNDDOWN(Q13/M13,0),"") -> 0 | W13: =IFERROR(Q13-(T13*M13),"") -> 0 | AA13: =B13+4 -> 46318
E14: APP예약)밸런스푼꽃맛살듬뿍샐러드 | M14: 30 | Q14: =IFERROR(VLOOKUP(B1,은성파머스피벗발주량!A:DC,3,FALSE),0) -> 0 | T14: =IFERROR(ROUNDDOWN(Q14/M14,0),"") -> 0 | W14: =IFERROR(Q14-(T14*M14),"") -> 0 | AA14: =B13+4 -> 46318
E15: APP예약)밸런스푼에그듬뿍샐러드 | M15: 30 | Q15: =IFERROR(VLOOKUP(B1,은성파머스피벗발주량!A:DC,4,FALSE),0) -> 0 | T15: =IFERROR(ROUNDDOWN(Q15/M15,0),"") -> 0 | W15: =IFERROR(Q15-(T15*M15),"") -> 0 | AA15: =B13+4 -> 46318
E16: APP예약)밸런스푼훈제오리듬뿍샐러드 | M16: 30 | Q16: =IFERROR(VLOOKUP(B1,은성파머스피벗발주량!A:DC,5,FALSE),0) -> 0 | T16: =IFERROR(ROUNDDOWN(Q16/M16,0),"") -> 0 | W16: =IFERROR(Q16-(T16*M16),"") -> 0 | AA16: =B13+4 -> 46318
E17: APP예약)치킨텐더샐러드 | M17: 36 | Q17: =IFERROR(VLOOKUP(B1,은성파머스피벗발주량!A:DC,6,FALSE),0) -> 0 | T17: =IFERROR(ROUNDDOWN(Q17/M17,0),"") -> 0 | W17: =IFERROR(Q17-(T17*M17),"") -> 0 | AA17: =B13+4 -> 46318
E18: 밸런스푼)꽃맛살듬뿍샐러드 235g | M18: 30 | Q18: =IFERROR(VLOOKUP(B1,은성파머스피벗발주량!A:DC,7,FALSE),0) -> 14 | T18: =IFERROR(ROUNDDOWN(Q18/M18,0),"") -> 0 | W18: =IFERROR(Q18-(T18*M18),"") -> 14 | AA18: =B13+4 -> 46318
E19: 밸런스푼)새우듬뿍샐러드 185g | M19: 30 | Q19: =IFERROR(VLOOKUP(B1,은성파머스피벗발주량!A:DC,8,FALSE),0) -> 12 | T19: =IFERROR(ROUNDDOWN(Q19/M19,0),"") -> 0 | W19: =IFERROR(Q19-(T19*M19),"") -> 12 | AA19: =B13+4 -> 46318
E20: 밸런스푼)에그듬뿍샐러드 230g | M20: 30 | Q20: =IFERROR(VLOOKUP(B1,은성파머스피벗발주량!A:DC,9,FALSE),0) -> 19 | T20: =IFERROR(ROUNDDOWN(Q20/M20,0),"") -> 0 | W20: =IFERROR(Q20-(T20*M20),"") -> 19 | AA20: =B13+4 -> 46318
E21: 밸런스푼)훈제오리듬뿍샐러드 225g | M21: 30 | Q21: =IFERROR(VLOOKUP(B1,은성파머스피벗발주량!A:DC,10,FALSE),0) -> 14 | T21: =IFERROR(ROUNDDOWN(Q21/M21,0),"") -> 0 | W21: =IFERROR(Q21-(T21*M21),"") -> 14 | AA21: =B13+4 -> 46318
E22: 은성)닭가슴살샐러드 155g | M22: 36 | Q22: =IFERROR(VLOOKUP(B1,은성파머스피벗발주량!A:DC,11,FALSE),0) -> 3 | T22: =IFERROR(ROUNDDOWN(Q22/M22,0),"") -> 0 | W22: =IFERROR(Q22-(T22*M22),"") -> 3 | AA22: =B13+4 -> 46318
E23: 은성)치킨텐더샐러드 150g | M23: 36 | Q23: =IFERROR(VLOOKUP(B1,은성파머스피벗발주량!A:DC,12,FALSE),0) -> 2 | T23: =IFERROR(ROUNDDOWN(Q23/M23,0),"") -> 0 | W23: =IFERROR(Q23-(T23*M23),"") -> 2 | AA23: =B13+4 -> 46318
B24: 총수량 | M24: =SUM(Q13:S23) -> 64
B25: 3자물류 (더원물류) 담당자 박병선이사 010-4448-1456 | W25: 경북 경산시 압량읍 가야로 20 (212-3, 216-3) / 053-818-0285
B29: 거 래 명 세 표 (공급자 보관용)
B31: 공 급 받 는 자 | C31: =C4 -> 등록번호 | Q31: 공 급 자 | R31: 등록번호 | V31: =V4 -> 308-87-03289
C33: =C6 -> 상 호 (법인명) | G33: =G6 -> 세븐일레븐 | L33: =L6 -> 대구냉장A동 | R33: 상 호 (법인명) | V33: =V6 -> 주식회사 은성파머스 | AB33: 성 명 | AD33: =AD6 -> 안은엽
C35: 사업장 주 소 | G35: =G8 -> 경북 경산시 압량읍 가야로20 (212-3, 216-3) | R35: 사업장 주 소 | V35: =V8 -> 경기도 여주시 세종대왕면 매류1길 45
C37: 합계금액 (VAT포함) | R37: 업 태 | V37: =V10 -> 도소매 | AB37: =AB10 -> 종 목 | AD37: 농후발효유, 그릭요거트
B39: 년 | C39: 월 | D39: 일 | E39: 품 목 | M39: 입수 | Q39: 총수량 | T39: 박스 | W39: 낱개수량 | AA39: 비고
B40: =B13 -> 46314 | E40: =E13 -> APP예약)닭가슴살샐러드 | M40: =M13 -> 36 | Q40: =Q13 -> 0 | T40: =T13 -> 0 | W40: =W13 -> 0 | AA40: =AA13 -> 46318
E41: =E14 -> APP예약)밸런스푼꽃맛살듬뿍샐러드 | M41: =M14 -> 30 | Q41: =Q14 -> 0 | T41: =T14 -> 0 | W41: =W14 -> 0 | AA41: =AA14 -> 46318
E42: =E15 -> APP예약)밸런스푼에그듬뿍샐러드 | M42: =M15 -> 30 | Q42: =Q15 -> 0 | T42: =T15 -> 0 | W42: =W15 -> 0 | AA42: =AA15 -> 46318
E43: =E16 -> APP예약)밸런스푼훈제오리듬뿍샐러드 | M43: =M16 -> 30 | Q43: =Q16 -> 0 | T43: =T16 -> 0 | W43: =W16 -> 0 | AA43: =AA16 -> 46318
E44: =E17 -> APP예약)치킨텐더샐러드 | M44: =M17 -> 36 | Q44: =Q17 -> 0 | T44: =T17 -> 0 | W44: =W17 -> 0 | AA44: =AA17 -> 46318
E45: =E18 -> 밸런스푼)꽃맛살듬뿍샐러드 235g | M45: =M18 -> 30 | Q45: =Q18 -> 14 | T45: =T18 -> 0 | W45: =W18 -> 14 | AA45: =AA18 -> 46318
E46: =E19 -> 밸런스푼)새우듬뿍샐러드 185g | M46: =M19 -> 30 | Q46: =Q19 -> 12 | T46: =T19 -> 0 | W46: =W19 -> 12 | AA46: =AA19 -> 46318
E47: =E20 -> 밸런스푼)에그듬뿍샐러드 230g | M47: =M20 -> 30 | Q47: =Q20 -> 19 | T47: =T20 -> 0 | W47: =W20 -> 19 | AA47: =AA20 -> 46318
E48: =E21 -> 밸런스푼)훈제오리듬뿍샐러드 225g | M48: =M21 -> 30 | Q48: =Q21 -> 14 | T48: =T21 -> 0 | W48: =W21 -> 14 | AA48: =AA21 -> 46318
E49: =E22 -> 은성)닭가슴살샐러드 155g | M49: =M22 -> 36 | Q49: =Q22 -> 3 | T49: =T22 -> 0 | W49: =W22 -> 3 | AA49: =AA22 -> 46318
E50: =E23 -> 은성)치킨텐더샐러드 150g | M50: =M23 -> 36 | Q50: =Q23 -> 2 | T50: =T23 -> 0 | W50: =W23 -> 2 | AA50: =AA23 -> 46318
B51: =B24 -> 총수량 | M51: =SUM(Q40:S50) -> 64
B52: =B25 -> 3자물류 (더원물류) 담당자 박병선이사 010-4448-1456 | W52: =W25 -> 경북 경산시 압량읍 가야로 20 (212-3, 216-3) / 053-818-0285

Sheet 대구냉장B동(영남권)_롯데확인
B1: 대구냉장
B2: 거 래 명 세 표 (공급받는자 보관용)
B4: 공 급 받 는 자 | C4: 등록번호 | Q4: 공 급 자 | R4: 등록번호 | V4: 308-87-03289
C6: 상 호 (법인명) | G6: 세븐일레븐 | L6: 대구냉장B동 | R6: 상 호 (법인명) | V6: 주식회사 은성파머스 | AB6: 성 명 | AD6: 안은엽
C8: 사업장 주 소 | G8: 경북 경산시 압량읍 가야로20 (212-3, 216-3) | R8: 사업장 주 소 | V8: 경기도 여주시 세종대왕면 매류1길 45
C10: 합계금액 (VAT포함) | R10: 업 태 | V10: 도소매 | AB10: 종 목 | AD10: 식품도소매
B12: 년 | C12: 월 | D12: 일 | E12: 품 목 | M12: 입수 | Q12: 총수량 | T12: 박스 | W12: 낱개수량 | AA12: 비고
B13: ='제주냉장센터(더원)'!B13 -> 46314 | E13: APP예약)닭가슴살샐러드 | M13: 36 | T13: =IFERROR(ROUNDDOWN(Q13/M13,0),"") -> 0 | W13: =IFERROR(Q13-(T13*M13),"") -> 0 | AA13: =B13+4 -> 46318
E14: APP예약)밸런스푼꽃맛살듬뿍샐러드 | M14: 30 | T14: =IFERROR(ROUNDDOWN(Q14/M14,0),"") -> 0 | W14: =IFERROR(Q14-(T14*M14),"") -> 0 | AA14: =B13+4 -> 46318
E15: APP예약)밸런스푼에그듬뿍샐러드 | M15: 30 | T15: =IFERROR(ROUNDDOWN(Q15/M15,0),"") -> 0 | W15: =IFERROR(Q15-(T15*M15),"") -> 0 | AA15: =B13+4 -> 46318
E16: APP예약)밸런스푼훈제오리듬뿍샐러드 | M16: 30 | T16: =IFERROR(ROUNDDOWN(Q16/M16,0),"") -> 0 | W16: =IFERROR(Q16-(T16*M16),"") -> 0 | AA16: =B13+4 -> 46318
E17: APP예약)치킨텐더샐러드 | M17: 36 | T17: =IFERROR(ROUNDDOWN(Q17/M17,0),"") -> 0 | W17: =IFERROR(Q17-(T17*M17),"") -> 0 | AA17: =B13+4 -> 46318
E18: 밸런스푼)꽃맛살듬뿍샐러드 235g | M18: 30 | Q18: 2 | T18: =IFERROR(ROUNDDOWN(Q18/M18,0),"") -> 0 | W18: =IFERROR(Q18-(T18*M18),"") -> 2 | AA18: =B13+4 -> 46318
E19: 밸런스푼)새우듬뿍샐러드 185g | M19: 30 | Q19: 2 | T19: =IFERROR(ROUNDDOWN(Q19/M19,0),"") -> 0 | W19: =IFERROR(Q19-(T19*M19),"") -> 2 | AA19: =B13+4 -> 46318
E20: 밸런스푼)에그듬뿍샐러드 230g | M20: 30 | Q20: 1 | T20: =IFERROR(ROUNDDOWN(Q20/M20,0),"") -> 0 | W20: =IFERROR(Q20-(T20*M20),"") -> 1 | AA20: =B13+4 -> 46318
E21: 밸런스푼)훈제오리듬뿍샐러드 225g | M21: 30 | Q21: 2 | T21: =IFERROR(ROUNDDOWN(Q21/M21,0),"") -> 0 | W21: =IFERROR(Q21-(T21*M21),"") -> 2 | AA21: =B13+4 -> 46318
E22: 은성)닭가슴살샐러드 155g | M22: 36 | Q22: 1 | T22: =IFERROR(ROUNDDOWN(Q22/M22,0),"") -> 0 | W22: =IFERROR(Q22-(T22*M22),"") -> 1 | AA22: =B13+4 -> 46318
E23: 은성)치킨텐더샐러드 150g | M23: 36 | Q23: 1 | T23: =IFERROR(ROUNDDOWN(Q23/M23,0),"") -> 0 | W23: =IFERROR(Q23-(T23*M23),"") -> 1 | AA23: =B13+4 -> 46318
B24: 총수량 | M24: =SUM(Q13:S23) -> 9
B25: 3자물류 (더원물류) 담당자 박병선이사 010-4448-1456 | W25: 경북 경산시 압량읍 가야로 20 (212-3, 216-3) / 053-818-0285
B29: 거 래 명 세 표 (공급자 보관용)
B31: 공 급 받 는 자 | C31: =C4 -> 등록번호 | Q31: 공 급 자 | R31: 등록번호 | V31: =V4 -> 308-87-03289
C33: =C6 -> 상 호 (법인명) | G33: =G6 -> 세븐일레븐 | L33: =L6 -> 대구냉장B동 | R33: 상 호 (법인명) | V33: =V6 -> 주식회사 은성파머스 | AB33: 성 명 | AD33: =AD6 -> 안은엽
C35: 사업장 주 소 | G35: =G8 -> 경북 경산시 압량읍 가야로20 (212-3, 216-3) | R35: 사업장 주 소 | V35: =V8 -> 경기도 여주시 세종대왕면 매류1길 45
C37: 합계금액 (VAT포함) | R37: 업 태 | V37: =V10 -> 도소매 | AB37: =AB10 -> 종 목 | AD37: 농후발효유, 그릭요거트
B39: 년 | C39: 월 | D39: 일 | E39: 품 목 | M39: 입수 | Q39: 총수량 | T39: 박스 | W39: 낱개수량 | AA39: 비고
B40: =B13 -> 46314 | E40: =E13 -> APP예약)닭가슴살샐러드 | M40: =M13 -> 36 | Q40: =Q13 -> 0 | T40: =T13 -> 0 | W40: =W13 -> 0 | AA40: =AA13 -> 46318
E41: =E14 -> APP예약)밸런스푼꽃맛살듬뿍샐러드 | M41: =M14 -> 30 | Q41: =Q14 -> 0 | T41: =T14 -> 0 | W41: =W14 -> 0 | AA41: =AA14 -> 46318
E42: =E15 -> APP예약)밸런스푼에그듬뿍샐러드 | M42: =M15 -> 30 | Q42: =Q15 -> 0 | T42: =T15 -> 0 | W42: =W15 -> 0 | AA42: =AA15 -> 46318
E43: =E16 -> APP예약)밸런스푼훈제오리듬뿍샐러드 | M43: =M16 -> 30 | Q43: =Q16 -> 0 | T43: =T16 -> 0 | W43: =W16 -> 0 | AA43: =AA16 -> 46318
E44: =E17 -> APP예약)치킨텐더샐러드 | M44: =M17 -> 36 | Q44: =Q17 -> 0 | T44: =T17 -> 0 | W44: =W17 -> 0 | AA44: =AA17 -> 46318
E45: =E18 -> 밸런스푼)꽃맛살듬뿍샐러드 235g | M45: =M18 -> 30 | Q45: =Q18 -> 2 | T45: =T18 -> 0 | W45: =W18 -> 2 | AA45: =AA18 -> 46318
E46: =E19 -> 밸런스푼)새우듬뿍샐러드 185g | M46: =M19 -> 30 | Q46: =Q19 -> 2 | T46: =T19 -> 0 | W46: =W19 -> 2 | AA46: =AA19 -> 46318
E47: =E20 -> 밸런스푼)에그듬뿍샐러드 230g | M47: =M20 -> 30 | Q47: =Q20 -> 1 | T47: =T20 -> 0 | W47: =W20 -> 1 | AA47: =AA20 -> 46318
E48: =E21 -> 밸런스푼)훈제오리듬뿍샐러드 225g | M48: =M21 -> 30 | Q48: =Q21 -> 2 | T48: =T21 -> 0 | W48: =W21 -> 2 | AA48: =AA21 -> 46318
E49: =E22 -> 은성)닭가슴살샐러드 155g | M49: =M22 -> 36 | Q49: =Q22 -> 1 | T49: =T22 -> 0 | W49: =W22 -> 1 | AA49: =AA22 -> 46318
E50: =E23 -> 은성)치킨텐더샐러드 150g | M50: =M23 -> 36 | Q50: =Q23 -> 1 | T50: =T23 -> 0 | W50: =W23 -> 1 | AA50: =AA23 -> 46318
B51: =B24 -> 총수량 | M51: =SUM(Q40:S50) -> 9
B52: =B25 -> 3자물류 (더원물류) 담당자 박병선이사 010-4448-1456 | W52: =W25 -> 경북 경산시 압량읍 가야로 20 (212-3, 216-3) / 053-818-0285

Sheet 부산냉장(영남권)
B1: 부산냉장
B2: 거 래 명 세 표 (공급받는자 보관용)
B4: 공 급 받 는 자 | C4: 등록번호 | Q4: 공 급 자 | R4: 등록번호 | V4: 308-87-03289
C6: 상 호 (법인명) | G6: 세븐일레븐 | L6: 부산냉장 | R6: 상 호 (법인명) | V6: 주식회사 은성파머스 | AB6: 성 명 | AD6: 안은엽
C8: 사업장 주 소 | G8: 경남 양산시 물금읍 제방로 225 7단지 | R8: 사업장 주 소 | V8: 경기도 여주시 세종대왕면 매류1길 45
C10: 합계금액 (VAT포함) | R10: 업 태 | V10: 도소매 | AB10: 종 목 | AD10: 식품도소매
B12: 년 | C12: 월 | D12: 일 | E12: 품 목 | M12: 입수 | Q12: 총수량 | T12: 박스 | W12: 낱개수량 | AA12: 비고
B13: ='제주냉장센터(더원)'!B13 -> 46314 | E13: APP예약)닭가슴살샐러드 | M13: 36 | Q13: =IFERROR(VLOOKUP(B1,은성파머스피벗발주량!A:DC,2,FALSE),0) -> 0 | T13: =IFERROR(ROUNDDOWN(Q13/M13,0),"") -> 0 | W13: =IFERROR(Q13-(T13*M13),"") -> 0 | AA13: =B13+4 -> 46318
E14: APP예약)밸런스푼꽃맛살듬뿍샐러드 | M14: 30 | Q14: =IFERROR(VLOOKUP(B1,은성파머스피벗발주량!A:DC,3,FALSE),0) -> 0 | T14: =IFERROR(ROUNDDOWN(Q14/M14,0),"") -> 0 | W14: =IFERROR(Q14-(T14*M14),"") -> 0 | AA14: =B13+4 -> 46318
E15: APP예약)밸런스푼에그듬뿍샐러드 | M15: 30 | Q15: =IFERROR(VLOOKUP(B1,은성파머스피벗발주량!A:DC,4,FALSE),0) -> 0 | T15: =IFERROR(ROUNDDOWN(Q15/M15,0),"") -> 0 | W15: =IFERROR(Q15-(T15*M15),"") -> 0 | AA15: =B13+4 -> 46318
E16: APP예약)밸런스푼훈제오리듬뿍샐러드 | M16: 30 | Q16: =IFERROR(VLOOKUP(B1,은성파머스피벗발주량!A:DC,5,FALSE),0) -> 0 | T16: =IFERROR(ROUNDDOWN(Q16/M16,0),"") -> 0 | W16: =IFERROR(Q16-(T16*M16),"") -> 0 | AA16: =B13+4 -> 46318
E17: APP예약)치킨텐더샐러드 | M17: 36 | Q17: =IFERROR(VLOOKUP(B1,은성파머스피벗발주량!A:DC,6,FALSE),0) -> 0 | T17: =IFERROR(ROUNDDOWN(Q17/M17,0),"") -> 0 | W17: =IFERROR(Q17-(T17*M17),"") -> 0 | AA17: =B13+4 -> 46318
E18: 밸런스푼)꽃맛살듬뿍샐러드 235g | M18: 30 | Q18: =IFERROR(VLOOKUP(B1,은성파머스피벗발주량!A:DC,7,FALSE),0) -> 8 | T18: =IFERROR(ROUNDDOWN(Q18/M18,0),"") -> 0 | W18: =IFERROR(Q18-(T18*M18),"") -> 8 | AA18: =B13+4 -> 46318
E19: 밸런스푼)새우듬뿍샐러드 185g | M19: 30 | Q19: =IFERROR(VLOOKUP(B1,은성파머스피벗발주량!A:DC,8,FALSE),0) -> 8 | T19: =IFERROR(ROUNDDOWN(Q19/M19,0),"") -> 0 | W19: =IFERROR(Q19-(T19*M19),"") -> 8 | AA19: =B13+4 -> 46318
E20: 밸런스푼)에그듬뿍샐러드 230g | M20: 30 | Q20: =IFERROR(VLOOKUP(B1,은성파머스피벗발주량!A:DC,9,FALSE),0) -> 17 | T20: =IFERROR(ROUNDDOWN(Q20/M20,0),"") -> 0 | W20: =IFERROR(Q20-(T20*M20),"") -> 17 | AA20: =B13+4 -> 46318
E21: 밸런스푼)훈제오리듬뿍샐러드 225g | M21: 30 | Q21: =IFERROR(VLOOKUP(B1,은성파머스피벗발주량!A:DC,10,FALSE),0) -> 12 | T21: =IFERROR(ROUNDDOWN(Q21/M21,0),"") -> 0 | W21: =IFERROR(Q21-(T21*M21),"") -> 12 | AA21: =B13+4 -> 46318
E22: 은성)닭가슴살샐러드 155g | M22: 36 | Q22: =IFERROR(VLOOKUP(B1,은성파머스피벗발주량!A:DC,11,FALSE),0) -> 4 | T22: =IFERROR(ROUNDDOWN(Q22/M22,0),"") -> 0 | W22: =IFERROR(Q22-(T22*M22),"") -> 4 | AA22: =B13+4 -> 46318
E23: 은성)치킨텐더샐러드 150g | M23: 36 | Q23: =IFERROR(VLOOKUP(B1,은성파머스피벗발주량!A:DC,12,FALSE),0) -> 0 | T23: =IFERROR(ROUNDDOWN(Q23/M23,0),"") -> 0 | W23: =IFERROR(Q23-(T23*M23),"") -> 0 | AA23: =B13+4 -> 46318
B24: 총수량 | M24: =SUM(Q13:S23) -> 49
B25: 3자물류 (더원물류) 담당자 박병선이사 010-4448-1456 | W25: 경남 양산시 물금읍 제방로 225 7단지 070-4104-4413
B29: 거 래 명 세 표 (공급자 보관용)
B31: 공 급 받 는 자 | C31: =C4 -> 등록번호 | Q31: 공 급 자 | R31: 등록번호 | V31: =V4 -> 308-87-03289
C33: =C6 -> 상 호 (법인명) | G33: =G6 -> 세븐일레븐 | L33: =L6 -> 부산냉장 | R33: 상 호 (법인명) | V33: =V6 -> 주식회사 은성파머스 | AB33: 성 명 | AD33: =AD6 -> 안은엽
C35: 사업장 주 소 | G35: =G8 -> 경남 양산시 물금읍 제방로 225 7단지 | R35: 사업장 주 소 | V35: =V8 -> 경기도 여주시 세종대왕면 매류1길 45
C37: 합계금액 (VAT포함) | R37: 업 태 | V37: =V10 -> 도소매 | AB37: =AB10 -> 종 목 | AD37: 농후발효유, 그릭요거트
B39: 년 | C39: 월 | D39: 일 | E39: 품 목 | M39: 입수 | Q39: 총수량 | T39: 박스 | W39: 낱개수량 | AA39: 비고
B40: =B13 -> 46314 | E40: =E13 -> APP예약)닭가슴살샐러드 | M40: =M13 -> 36 | Q40: =Q13 -> 0 | T40: =T13 -> 0 | W40: =W13 -> 0 | AA40: =AA13 -> 46318
E41: =E14 -> APP예약)밸런스푼꽃맛살듬뿍샐러드 | M41: =M14 -> 30 | Q41: =Q14 -> 0 | T41: =T14 -> 0 | W41: =W14 -> 0 | AA41: =AA14 -> 46318
E42: =E15 -> APP예약)밸런스푼에그듬뿍샐러드 | M42: =M15 -> 30 | Q42: =Q15 -> 0 | T42: =T15 -> 0 | W42: =W15 -> 0 | AA42: =AA15 -> 46318
E43: =E16 -> APP예약)밸런스푼훈제오리듬뿍샐러드 | M43: =M16 -> 30 | Q43: =Q16 -> 0 | T43: =T16 -> 0 | W43: =W16 -> 0 | AA43: =AA16 -> 46318
E44: =E17 -> APP예약)치킨텐더샐러드 | M44: =M17 -> 36 | Q44: =Q17 -> 0 | T44: =T17 -> 0 | W44: =W17 -> 0 | AA44: =AA17 -> 46318
E45: =E18 -> 밸런스푼)꽃맛살듬뿍샐러드 235g | M45: =M18 -> 30 | Q45: =Q18 -> 8 | T45: =T18 -> 0 | W45: =W18 -> 8 | AA45: =AA18 -> 46318
E46: =E19 -> 밸런스푼)새우듬뿍샐러드 185g | M46: =M19 -> 30 | Q46: =Q19 -> 8 | T46: =T19 -> 0 | W46: =W19 -> 8 | AA46: =AA19 -> 46318
E47: =E20 -> 밸런스푼)에그듬뿍샐러드 230g | M47: =M20 -> 30 | Q47: =Q20 -> 17 | T47: =T20 -> 0 | W47: =W20 -> 17 | AA47: =AA20 -> 46318
E48: =E21 -> 밸런스푼)훈제오리듬뿍샐러드 225g | M48: =M21 -> 30 | Q48: =Q21 -> 12 | T48: =T21 -> 0 | W48: =W21 -> 12 | AA48: =AA21 -> 46318
E49: =E22 -> 은성)닭가슴살샐러드 155g | M49: =M22 -> 36 | Q49: =Q22 -> 4 | T49: =T22 -> 0 | W49: =W22 -> 4 | AA49: =AA22 -> 46318
E50: =E23 -> 은성)치킨텐더샐러드 150g | M50: =M23 -> 36 | Q50: =Q23 -> 0 | T50: =T23 -> 0 | W50: =W23 -> 0 | AA50: =AA23 -> 46318
B51: =B24 -> 총수량 | M51: =SUM(Q40:S50) -> 49
B52: =B25 -> 3자물류 (더원물류) 담당자 박병선이사 010-4448-1456 | W52: =W25 -> 경남 양산시 물금읍 제방로 225 7단지 070-4104-4413

Sheet 양산냉장(영남권)
B1: 양산냉장
B2: 거 래 명 세 표 (공급받는자 보관용)
B4: 공 급 받 는 자 | C4: 등록번호 | Q4: 공 급 자 | R4: 등록번호 | V4: 308-87-03289
C6: 상 호 (법인명) | G6: 세븐일레븐 | L6: 양산냉장 | R6: 상 호 (법인명) | V6: 주식회사 은성파머스 | AB6: 성 명 | AD6: 안은엽
C8: 사업장 주 소 | G8: 경남 양산시 충렬로 149(유산동) | R8: 사업장 주 소 | V8: 경기도 여주시 세종대왕면 매류1길 45
C10: 합계금액 (VAT포함) | R10: 업 태 | V10: 도소매 | AB10: 종 목 | AD10: 식품도소매
B12: 년 | C12: 월 | D12: 일 | E12: 품 목 | M12: 입수 | Q12: 총수량 | T12: 박스 | W12: 낱개수량 | AA12: 비고
B13: ='제주냉장센터(더원)'!B13 -> 46314 | E13: APP예약)닭가슴살샐러드 | M13: 36 | Q13: =IFERROR(VLOOKUP(B1,은성파머스피벗발주량!A:DC,2,FALSE),0) -> 0 | T13: =IFERROR(ROUNDDOWN(Q13/M13,0),"") -> 0 | W13: =IFERROR(Q13-(T13*M13),"") -> 0 | AA13: =B13+4 -> 46318
E14: APP예약)밸런스푼꽃맛살듬뿍샐러드 | M14: 30 | Q14: =IFERROR(VLOOKUP(B1,은성파머스피벗발주량!A:DC,3,FALSE),0) -> 0 | T14: =IFERROR(ROUNDDOWN(Q14/M14,0),"") -> 0 | W14: =IFERROR(Q14-(T14*M14),"") -> 0 | AA14: =B13+4 -> 46318
E15: APP예약)밸런스푼에그듬뿍샐러드 | M15: 30 | Q15: =IFERROR(VLOOKUP(B1,은성파머스피벗발주량!A:DC,4,FALSE),0) -> 0 | T15: =IFERROR(ROUNDDOWN(Q15/M15,0),"") -> 0 | W15: =IFERROR(Q15-(T15*M15),"") -> 0 | AA15: =B13+4 -> 46318
E16: APP예약)밸런스푼훈제오리듬뿍샐러드 | M16: 30 | Q16: =IFERROR(VLOOKUP(B1,은성파머스피벗발주량!A:DC,5,FALSE),0) -> 0 | T16: =IFERROR(ROUNDDOWN(Q16/M16,0),"") -> 0 | W16: =IFERROR(Q16-(T16*M16),"") -> 0 | AA16: =B13+4 -> 46318
E17: APP예약)치킨텐더샐러드 | M17: 36 | Q17: =IFERROR(VLOOKUP(B1,은성파머스피벗발주량!A:DC,6,FALSE),0) -> 0 | T17: =IFERROR(ROUNDDOWN(Q17/M17,0),"") -> 0 | W17: =IFERROR(Q17-(T17*M17),"") -> 0 | AA17: =B13+4 -> 46318
E18: 밸런스푼)꽃맛살듬뿍샐러드 235g | M18: 30 | Q18: =IFERROR(VLOOKUP(B1,은성파머스피벗발주량!A:DC,7,FALSE),0) -> 6 | T18: =IFERROR(ROUNDDOWN(Q18/M18,0),"") -> 0 | W18: =IFERROR(Q18-(T18*M18),"") -> 6 | AA18: =B13+4 -> 46318
E19: 밸런스푼)새우듬뿍샐러드 185g | M19: 30 | Q19: =IFERROR(VLOOKUP(B1,은성파머스피벗발주량!A:DC,8,FALSE),0) -> 13 | T19: =IFERROR(ROUNDDOWN(Q19/M19,0),"") -> 0 | W19: =IFERROR(Q19-(T19*M19),"") -> 13 | AA19: =B13+4 -> 46318
E20: 밸런스푼)에그듬뿍샐러드 230g | M20: 30 | Q20: =IFERROR(VLOOKUP(B1,은성파머스피벗발주량!A:DC,9,FALSE),0) -> 15 | T20: =IFERROR(ROUNDDOWN(Q20/M20,0),"") -> 0 | W20: =IFERROR(Q20-(T20*M20),"") -> 15 | AA20: =B13+4 -> 46318
E21: 밸런스푼)훈제오리듬뿍샐러드 225g | M21: 30 | Q21: =IFERROR(VLOOKUP(B1,은성파머스피벗발주량!A:DC,10,FALSE),0) -> 11 | T21: =IFERROR(ROUNDDOWN(Q21/M21,0),"") -> 0 | W21: =IFERROR(Q21-(T21*M21),"") -> 11 | AA21: =B13+4 -> 46318
E22: 은성)닭가슴살샐러드 155g | M22: 36 | Q22: =IFERROR(VLOOKUP(B1,은성파머스피벗발주량!A:DC,11,FALSE),0) -> 2 | T22: =IFERROR(ROUNDDOWN(Q22/M22,0),"") -> 0 | W22: =IFERROR(Q22-(T22*M22),"") -> 2 | AA22: =B13+4 -> 46318
E23: 은성)치킨텐더샐러드 150g | M23: 36 | Q23: =IFERROR(VLOOKUP(B1,은성파머스피벗발주량!A:DC,12,FALSE),0) -> 1 | T23: =IFERROR(ROUNDDOWN(Q23/M23,0),"") -> 0 | W23: =IFERROR(Q23-(T23*M23),"") -> 1 | AA23: =B13+4 -> 46318
B24: 총수량 | M24: =SUM(Q13:S23) -> 48
B25: 3자물류 (더원물류) 담당자 박병선이사 010-4448-1456 | W25: 경남 양산시 충렬로 149(유산동) 055-389-2647
B29: 거 래 명 세 표 (공급자 보관용)
B31: 공 급 받 는 자 | C31: =C4 -> 등록번호 | Q31: 공 급 자 | R31: 등록번호 | V31: =V4 -> 308-87-03289
C33: =C6 -> 상 호 (법인명) | G33: =G6 -> 세븐일레븐 | L33: =L6 -> 양산냉장 | R33: 상 호 (법인명) | V33: =V6 -> 주식회사 은성파머스 | AB33: 성 명 | AD33: =AD6 -> 안은엽
C35: 사업장 주 소 | G35: =G8 -> 경남 양산시 충렬로 149(유산동) | R35: 사업장 주 소 | V35: =V8 -> 경기도 여주시 세종대왕면 매류1길 45
C37: 합계금액 (VAT포함) | R37: 업 태 | V37: =V10 -> 도소매 | AB37: =AB10 -> 종 목 | AD37: 농후발효유, 그릭요거트
B39: 년 | C39: 월 | D39: 일 | E39: 품 목 | M39: 입수 | Q39: 총수량 | T39: 박스 | W39: 낱개수량 | AA39: 비고
B40: =B13 -> 46314 | E40: =E13 -> APP예약)닭가슴살샐러드 | M40: =M13 -> 36 | Q40: =Q13 -> 0 | T40: =T13 -> 0 | W40: =W13 -> 0 | AA40: =AA13 -> 46318
E41: =E14 -> APP예약)밸런스푼꽃맛살듬뿍샐러드 | M41: =M14 -> 30 | Q41: =Q14 -> 0 | T41: =T14 -> 0 | W41: =W14 -> 0 | AA41: =AA14 -> 46318
E42: =E15 -> APP예약)밸런스푼에그듬뿍샐러드 | M42: =M15 -> 30 | Q42: =Q15 -> 0 | T42: =T15 -> 0 | W42: =W15 -> 0 | AA42: =AA15 -> 46318
E43: =E16 -> APP예약)밸런스푼훈제오리듬뿍샐러드 | M43: =M16 -> 30 | Q43: =Q16 -> 0 | T43: =T16 -> 0 | W43: =W16 -> 0 | AA43: =AA16 -> 46318
E44: =E17 -> APP예약)치킨텐더샐러드 | M44: =M17 -> 36 | Q44: =Q17 -> 0 | T44: =T17 -> 0 | W44: =W17 -> 0 | AA44: =AA17 -> 46318
E45: =E18 -> 밸런스푼)꽃맛살듬뿍샐러드 235g | M45: =M18 -> 30 | Q45: =Q18 -> 6 | T45: =T18 -> 0 | W45: =W18 -> 6 | AA45: =AA18 -> 46318
E46: =E19 -> 밸런스푼)새우듬뿍샐러드 185g | M46: =M19 -> 30 | Q46: =Q19 -> 13 | T46: =T19 -> 0 | W46: =W19 -> 13 | AA46: =AA19 -> 46318
E47: =E20 -> 밸런스푼)에그듬뿍샐러드 230g | M47: =M20 -> 30 | Q47: =Q20 -> 15 | T47: =T20 -> 0 | W47: =W20 -> 15 | AA47: =AA20 -> 46318
E48: =E21 -> 밸런스푼)훈제오리듬뿍샐러드 225g | M48: =M21 -> 30 | Q48: =Q21 -> 11 | T48: =T21 -> 0 | W48: =W21 -> 11 | AA48: =AA21 -> 46318
E49: =E22 -> 은성)닭가슴살샐러드 155g | M49: =M22 -> 36 | Q49: =Q22 -> 2 | T49: =T22 -> 0 | W49: =W22 -> 2 | AA49: =AA22 -> 46318
E50: =E23 -> 은성)치킨텐더샐러드 150g | M50: =M23 -> 36 | Q50: =Q23 -> 1 | T50: =T23 -> 0 | W50: =W23 -> 1 | AA50: =AA23 -> 46318
B51: =B24 -> 총수량 | M51: =SUM(Q40:S50) -> 48
B52: =B25 -> 3자물류 (더원물류) 담당자 박병선이사 010-4448-1456 | W52: =W25 -> 경남 양산시 충렬로 149(유산동) 055-389-2647

Sheet 칠곡저온(영남권)
B1: 칠곡저온
B2: 거 래 명 세 표 (공급받는자 보관용)
B4: 공 급 받 는 자 | C4: 등록번호 | Q4: 공 급 자 | R4: 등록번호 | V4: 308-87-03289
C6: 상 호 (법인명) | G6: 세븐일레븐 | L6: 칠곡저온 | R6: 상 호 (법인명) | V6: 주식회사 은성파머스 | AB6: 성 명 | AD6: 안은엽
C8: 사업장 주 소 | G8: 경상북도 칠곡군 지천면 금호로 삼청5길 50-22 2층 | R8: 사업장 주 소 | V8: 경기도 여주시 세종대왕면 매류1길 45
C10: 합계금액 (VAT포함) | R10: 업 태 | V10: 도소매 | AB10: 종 목 | AD10: 식품도소매
B12: 년 | C12: 월 | D12: 일 | E12: 품 목 | M12: 입수 | Q12: 총수량 | T12: 박스 | W12: 낱개수량 | AA12: 비고
B13: ='제주냉장센터(더원)'!B13 -> 46314 | E13: APP예약)닭가슴살샐러드 | M13: 36 | Q13: =IFERROR(VLOOKUP(B1,은성파머스피벗발주량!A:DC,2,FALSE),0) -> 0 | T13: =IFERROR(ROUNDDOWN(Q13/M13,0),"") -> 0 | W13: =IFERROR(Q13-(T13*M13),"") -> 0 | AA13: =B13+4 -> 46318
E14: APP예약)밸런스푼꽃맛살듬뿍샐러드 | M14: 30 | Q14: =IFERROR(VLOOKUP(B1,은성파머스피벗발주량!A:DC,3,FALSE),0) -> 0 | T14: =IFERROR(ROUNDDOWN(Q14/M14,0),"") -> 0 | W14: =IFERROR(Q14-(T14*M14),"") -> 0 | AA14: =B13+4 -> 46318
E15: APP예약)밸런스푼에그듬뿍샐러드 | M15: 30 | Q15: =IFERROR(VLOOKUP(B1,은성파머스피벗발주량!A:DC,4,FALSE),0) -> 0 | T15: =IFERROR(ROUNDDOWN(Q15/M15,0),"") -> 0 | W15: =IFERROR(Q15-(T15*M15),"") -> 0 | AA15: =B13+4 -> 46318
E16: APP예약)밸런스푼훈제오리듬뿍샐러드 | M16: 30 | Q16: =IFERROR(VLOOKUP(B1,은성파머스피벗발주량!A:DC,5,FALSE),0) -> 0 | T16: =IFERROR(ROUNDDOWN(Q16/M16,0),"") -> 0 | W16: =IFERROR(Q16-(T16*M16),"") -> 0 | AA16: =B13+4 -> 46318
E17: APP예약)치킨텐더샐러드 | M17: 36 | Q17: =IFERROR(VLOOKUP(B1,은성파머스피벗발주량!A:DC,6,FALSE),0) -> 0 | T17: =IFERROR(ROUNDDOWN(Q17/M17,0),"") -> 0 | W17: =IFERROR(Q17-(T17*M17),"") -> 0 | AA17: =B13+4 -> 46318
E18: 밸런스푼)꽃맛살듬뿍샐러드 235g | M18: 30 | Q18: =IFERROR(VLOOKUP(B1,은성파머스피벗발주량!A:DC,7,FALSE),0) -> 14 | T18: =IFERROR(ROUNDDOWN(Q18/M18,0),"") -> 0 | W18: =IFERROR(Q18-(T18*M18),"") -> 14 | AA18: =B13+4 -> 46318
E19: 밸런스푼)새우듬뿍샐러드 185g | M19: 30 | Q19: =IFERROR(VLOOKUP(B1,은성파머스피벗발주량!A:DC,8,FALSE),0) -> 20 | T19: =IFERROR(ROUNDDOWN(Q19/M19,0),"") -> 0 | W19: =IFERROR(Q19-(T19*M19),"") -> 20 | AA19: =B13+4 -> 46318
E20: 밸런스푼)에그듬뿍샐러드 230g | M20: 30 | Q20: =IFERROR(VLOOKUP(B1,은성파머스피벗발주량!A:DC,9,FALSE),0) -> 14 | T20: =IFERROR(ROUNDDOWN(Q20/M20,0),"") -> 0 | W20: =IFERROR(Q20-(T20*M20),"") -> 14 | AA20: =B13+4 -> 46318
E21: 밸런스푼)훈제오리듬뿍샐러드 225g | M21: 30 | Q21: =IFERROR(VLOOKUP(B1,은성파머스피벗발주량!A:DC,10,FALSE),0) -> 20 | T21: =IFERROR(ROUNDDOWN(Q21/M21,0),"") -> 0 | W21: =IFERROR(Q21-(T21*M21),"") -> 20 | AA21: =B13+4 -> 46318
E22: 은성)닭가슴살샐러드 155g | M22: 36 | Q22: =IFERROR(VLOOKUP(B1,은성파머스피벗발주량!A:DC,11,FALSE),0) -> 2 | T22: =IFERROR(ROUNDDOWN(Q22/M22,0),"") -> 0 | W22: =IFERROR(Q22-(T22*M22),"") -> 2 | AA22: =B13+4 -> 46318
E23: 은성)치킨텐더샐러드 150g | M23: 36 | Q23: =IFERROR(VLOOKUP(B1,은성파머스피벗발주량!A:DC,12,FALSE),0) -> 4 | T23: =IFERROR(ROUNDDOWN(Q23/M23,0),"") -> 0 | W23: =IFERROR(Q23-(T23*M23),"") -> 4 | AA23: =B13+4 -> 46318
B24: 총수량 | M24: =SUM(Q13:S23) -> 74
B25: 3자물류 (더원물류) 담당자 박병선이사 010-4448-1456 | W25: 경상북도 칠곡군 지천면 금호로 삼청5길 50-22 2층 054-800-7031
B29: 거 래 명 세 표 (공급자 보관용)
B31: 공 급 받 는 자 | C31: =C4 -> 등록번호 | Q31: 공 급 자 | R31: 등록번호 | V31: =V4 -> 308-87-03289
C33: =C6 -> 상 호 (법인명) | G33: =G6 -> 세븐일레븐 | L33: =L6 -> 칠곡저온 | R33: 상 호 (법인명) | V33: =V6 -> 주식회사 은성파머스 | AB33: 성 명 | AD33: =AD6 -> 안은엽
C35: 사업장 주 소 | G35: =G8 -> 경상북도 칠곡군 지천면 금호로 삼청5길 50-22 2층 | R35: 사업장 주 소 | V35: =V8 -> 경기도 여주시 세종대왕면 매류1길 45
C37: 합계금액 (VAT포함) | R37: 업 태 | V37: =V10 -> 도소매 | AB37: =AB10 -> 종 목 | AD37: 농후발효유, 그릭요거트
B39: 년 | C39: 월 | D39: 일 | E39: 품 목 | M39: 입수 | Q39: 총수량 | T39: 박스 | W39: 낱개수량 | AA39: 비고
B40: =B13 -> 46314 | E40: =E13 -> APP예약)닭가슴살샐러드 | M40: =M13 -> 36 | Q40: =Q13 -> 0 | T40: =T13 -> 0 | W40: =W13 -> 0 | AA40: =AA13 -> 46318
E41: =E14 -> APP예약)밸런스푼꽃맛살듬뿍샐러드 | M41: =M14 -> 30 | Q41: =Q14 -> 0 | T41: =T14 -> 0 | W41: =W14 -> 0 | AA41: =AA14 -> 46318
E42: =E15 -> APP예약)밸런스푼에그듬뿍샐러드 | M42: =M15 -> 30 | Q42: =Q15 -> 0 | T42: =T15 -> 0 | W42: =W15 -> 0 | AA42: =AA15 -> 46318
E43: =E16 -> APP예약)밸런스푼훈제오리듬뿍샐러드 | M43: =M16 -> 30 | Q43: =Q16 -> 0 | T43: =T16 -> 0 | W43: =W16 -> 0 | AA43: =AA16 -> 46318
E44: =E17 -> APP예약)치킨텐더샐러드 | M44: =M17 -> 36 | Q44: =Q17 -> 0 | T44: =T17 -> 0 | W44: =W17 -> 0 | AA44: =AA17 -> 46318
E45: =E18 -> 밸런스푼)꽃맛살듬뿍샐러드 235g | M45: =M18 -> 30 | Q45: =Q18 -> 14 | T45: =T18 -> 0 | W45: =W18 -> 14 | AA45: =AA18 -> 46318
E46: =E19 -> 밸런스푼)새우듬뿍샐러드 185g | M46: =M19 -> 30 | Q46: =Q19 -> 20 | T46: =T19 -> 0 | W46: =W19 -> 20 | AA46: =AA19 -> 46318
E47: =E20 -> 밸런스푼)에그듬뿍샐러드 230g | M47: =M20 -> 30 | Q47: =Q20 -> 14 | T47: =T20 -> 0 | W47: =W20 -> 14 | AA47: =AA20 -> 46318
E48: =E21 -> 밸런스푼)훈제오리듬뿍샐러드 225g | M48: =M21 -> 30 | Q48: =Q21 -> 20 | T48: =T21 -> 0 | W48: =W21 -> 20 | AA48: =AA21 -> 46318
E49: =E22 -> 은성)닭가슴살샐러드 155g | M49: =M22 -> 36 | Q49: =Q22 -> 2 | T49: =T22 -> 0 | W49: =W22 -> 2 | AA49: =AA22 -> 46318
E50: =E23 -> 은성)치킨텐더샐러드 150g | M50: =M23 -> 36 | Q50: =Q23 -> 4 | T50: =T23 -> 0 | W50: =W23 -> 4 | AA50: =AA23 -> 46318
B51: =B24 -> 총수량 | M51: =SUM(Q40:S50) -> 74
B52: =B25 -> 3자물류 (더원물류) 담당자 박병선이사 010-4448-1456 | W52: =W25 -> 경상북도 칠곡군 지천면 금호로 삼청5길 50-22 2층 054-800-7031

Sheet 세종냉장센터
B1: 세종냉장센터
B2: 거 래 명 세 표 (공급받는자 보관용)
B4: 공 급 받 는 자 | C4: 등록번호 | Q4: 공 급 자 | R4: 등록번호 | V4: 308-87-03289
C6: 상 호 (법인명) | G6: 세븐일레븐 | L6: 세종냉장센터 | R6: 상 호 (법인명) | V6: 주식회사 은성파머스 | AB6: 성 명 | AD6: 안은엽
C8: 사업장 주 소 | G8: 세종특별자치시 부강면 산수리 105-3번지 | R8: 사업장 주 소 | V8: 경기도 여주시 세종대왕면 매류1길 45
C10: 합계금액 (VAT포함) | R10: 업 태 | V10: 도소매 | AB10: 종 목 | AD10: 식품도소매
B12: 년 | C12: 월 | D12: 일 | E12: 품 목 | M12: 입수 | Q12: 총수량 | T12: 박스 | W12: 낱개수량 | AA12: 비고
B13: ='제주냉장센터(더원)'!B13 -> 46314 | E13: APP예약)닭가슴살샐러드 | M13: 36 | Q13: =IFERROR(VLOOKUP(B1,은성파머스피벗발주량!A:DC,2,FALSE),0) -> 0 | T13: =IFERROR(ROUNDDOWN(Q13/M13,0),"") -> 0 | W13: =IFERROR(Q13-(T13*M13),"") -> 0 | AA13: =B13+4 -> 46318
E14: APP예약)밸런스푼꽃맛살듬뿍샐러드 | M14: 30 | Q14: =IFERROR(VLOOKUP(B1,은성파머스피벗발주량!A:DC,3,FALSE),0) -> 0 | T14: =IFERROR(ROUNDDOWN(Q14/M14,0),"") -> 0 | W14: =IFERROR(Q14-(T14*M14),"") -> 0 | AA14: =B13+4 -> 46318
E15: APP예약)밸런스푼에그듬뿍샐러드 | M15: 30 | Q15: =IFERROR(VLOOKUP(B1,은성파머스피벗발주량!A:DC,4,FALSE),0) -> 0 | T15: =IFERROR(ROUNDDOWN(Q15/M15,0),"") -> 0 | W15: =IFERROR(Q15-(T15*M15),"") -> 0 | AA15: =B13+4 -> 46318
E16: APP예약)밸런스푼훈제오리듬뿍샐러드 | M16: 30 | Q16: =IFERROR(VLOOKUP(B1,은성파머스피벗발주량!A:DC,5,FALSE),0) -> 0 | T16: =IFERROR(ROUNDDOWN(Q16/M16,0),"") -> 0 | W16: =IFERROR(Q16-(T16*M16),"") -> 0 | AA16: =B13+4 -> 46318
E17: APP예약)치킨텐더샐러드 | M17: 36 | Q17: =IFERROR(VLOOKUP(B1,은성파머스피벗발주량!A:DC,6,FALSE),0) -> 2 | T17: =IFERROR(ROUNDDOWN(Q17/M17,0),"") -> 0 | W17: =IFERROR(Q17-(T17*M17),"") -> 2 | AA17: =B13+4 -> 46318
E18: 밸런스푼)꽃맛살듬뿍샐러드 235g | M18: 30 | Q18: =IFERROR(VLOOKUP(B1,은성파머스피벗발주량!A:DC,7,FALSE),0) -> 17 | T18: =IFERROR(ROUNDDOWN(Q18/M18,0),"") -> 0 | W18: =IFERROR(Q18-(T18*M18),"") -> 17 | AA18: =B13+4 -> 46318
E19: 밸런스푼)새우듬뿍샐러드 185g | M19: 30 | Q19: =IFERROR(VLOOKUP(B1,은성파머스피벗발주량!A:DC,8,FALSE),0) -> 28 | T19: =IFERROR(ROUNDDOWN(Q19/M19,0),"") -> 0 | W19: =IFERROR(Q19-(T19*M19),"") -> 28 | AA19: =B13+4 -> 46318
E20: 밸런스푼)에그듬뿍샐러드 230g | M20: 30 | Q20: =IFERROR(VLOOKUP(B1,은성파머스피벗발주량!A:DC,9,FALSE),0) -> 23 | T20: =IFERROR(ROUNDDOWN(Q20/M20,0),"") -> 0 | W20: =IFERROR(Q20-(T20*M20),"") -> 23 | AA20: =B13+4 -> 46318
E21: 밸런스푼)훈제오리듬뿍샐러드 225g | M21: 30 | Q21: =IFERROR(VLOOKUP(B1,은성파머스피벗발주량!A:DC,10,FALSE),0) -> 24 | T21: =IFERROR(ROUNDDOWN(Q21/M21,0),"") -> 0 | W21: =IFERROR(Q21-(T21*M21),"") -> 24 | AA21: =B13+4 -> 46318
E22: 은성)닭가슴살샐러드 155g | M22: 36 | Q22: =IFERROR(VLOOKUP(B1,은성파머스피벗발주량!A:DC,11,FALSE),0) -> 11 | T22: =IFERROR(ROUNDDOWN(Q22/M22,0),"") -> 0 | W22: =IFERROR(Q22-(T22*M22),"") -> 11 | AA22: =B13+4 -> 46318
E23: 은성)치킨텐더샐러드 150g | M23: 36 | Q23: =IFERROR(VLOOKUP(B1,은성파머스피벗발주량!A:DC,12,FALSE),0) -> 7 | T23: =IFERROR(ROUNDDOWN(Q23/M23,0),"") -> 0 | W23: =IFERROR(Q23-(T23*M23),"") -> 7 | AA23: =B13+4 -> 46318
B24: 총수량 | M24: =SUM(Q13:S23) -> 112
B25: 3자물류 (더원물류) 담당자 박병선이사 010-4448-1456 | W25: 세종특별자치시 부강면 산수리 105-3번지 044-867-6830
B29: 거 래 명 세 표 (공급자 보관용)
B31: 공 급 받 는 자 | C31: =C4 -> 등록번호 | Q31: 공 급 자 | R31: 등록번호 | V31: =V4 -> 308-87-03289
C33: =C6 -> 상 호 (법인명) | G33: =G6 -> 세븐일레븐 | L33: =L6 -> 세종냉장센터 | R33: 상 호 (법인명) | V33: =V6 -> 주식회사 은성파머스 | AB33: 성 명 | AD33: =AD6 -> 안은엽
C35: 사업장 주 소 | G35: =G8 -> 세종특별자치시 부강면 산수리 105-3번지 | R35: 사업장 주 소 | V35: =V8 -> 경기도 여주시 세종대왕면 매류1길 45
C37: 합계금액 (VAT포함) | R37: 업 태 | V37: =V10 -> 도소매 | AB37: =AB10 -> 종 목 | AD37: 농후발효유, 그릭요거트
B39: 년 | C39: 월 | D39: 일 | E39: 품 목 | M39: 입수 | Q39: 총수량 | T39: 박스 | W39: 낱개수량 | AA39: 비고
B40: =B13 -> 46314 | E40: =E13 -> APP예약)닭가슴살샐러드 | M40: =M13 -> 36 | Q40: =Q13 -> 0 | T40: =T13 -> 0 | W40: =W13 -> 0 | AA40: =AA13 -> 46318
E41: =E14 -> APP예약)밸런스푼꽃맛살듬뿍샐러드 | M41: =M14 -> 30 | Q41: =Q14 -> 0 | T41: =T14 -> 0 | W41: =W14 -> 0 | AA41: =AA14 -> 46318
E42: =E15 -> APP예약)밸런스푼에그듬뿍샐러드 | M42: =M15 -> 30 | Q42: =Q15 -> 0 | T42: =T15 -> 0 | W42: =W15 -> 0 | AA42: =AA15 -> 46318
E43: =E16 -> APP예약)밸런스푼훈제오리듬뿍샐러드 | M43: =M16 -> 30 | Q43: =Q16 -> 0 | T43: =T16 -> 0 | W43: =W16 -> 0 | AA43: =AA16 -> 46318
E44: =E17 -> APP예약)치킨텐더샐러드 | M44: =M17 -> 36 | Q44: =Q17 -> 2 | T44: =T17 -> 0 | W44: =W17 -> 2 | AA44: =AA17 -> 46318
E45: =E18 -> 밸런스푼)꽃맛살듬뿍샐러드 235g | M45: =M18 -> 30 | Q45: =Q18 -> 17 | T45: =T18 -> 0 | W45: =W18 -> 17 | AA45: =AA18 -> 46318
E46: =E19 -> 밸런스푼)새우듬뿍샐러드 185g | M46: =M19 -> 30 | Q46: =Q19 -> 28 | T46: =T19 -> 0 | W46: =W19 -> 28 | AA46: =AA19 -> 46318
E47: =E20 -> 밸런스푼)에그듬뿍샐러드 230g | M47: =M20 -> 30 | Q47: =Q20 -> 23 | T47: =T20 -> 0 | W47: =W20 -> 23 | AA47: =AA20 -> 46318
E48: =E21 -> 밸런스푼)훈제오리듬뿍샐러드 225g | M48: =M21 -> 30 | Q48: =Q21 -> 24 | T48: =T21 -> 0 | W48: =W21 -> 24 | AA48: =AA21 -> 46318
E49: =E22 -> 은성)닭가슴살샐러드 155g | M49: =M22 -> 36 | Q49: =Q22 -> 11 | T49: =T22 -> 0 | W49: =W22 -> 11 | AA49: =AA22 -> 46318
E50: =E23 -> 은성)치킨텐더샐러드 150g | M50: =M23 -> 36 | Q50: =Q23 -> 7 | T50: =T23 -> 0 | W50: =W23 -> 7 | AA50: =AA23 -> 46318
B51: =B24 -> 총수량 | M51: =SUM(Q40:S50) -> 112
B52: =B25 -> 3자물류 (더원물류) 담당자 박병선이사 010-4448-1456 | W52: =W25 -> 세종특별자치시 부강면 산수리 105-3번지 044-867-6830

Sheet 수도권냉장
B1: 수도권냉장
B2: 거 래 명 세 표 (공급받는자 보관용)
B4: 공 급 받 는 자 | C4: 등록번호 | Q4: 공 급 자 | R4: 등록번호 | V4: 308-87-03289
C6: 상 호 (법인명) | G6: 세븐일레븐 | L6: 수도권냉장 | R6: 상 호 (법인명) | V6: 주식회사 은성파머스 | AB6: 성 명 | AD6: 안은엽
C8: 사업장 주 소 | G8: 경기도 광주시 오포로 614 | R8: 사업장 주 소 | V8: 경기도 여주시 세종대왕면 매류1길 45
C10: 합계금액 (VAT포함) | R10: 업 태 | V10: 도소매 | AB10: 종 목 | AD10: 식품도소매
B12: 년 | C12: 월 | D12: 일 | E12: 품 목 | M12: 입수 | Q12: 총수량 | T12: 박스 | W12: 낱개수량 | AA12: 비고
B13: ='제주냉장센터(더원)'!B13 -> 46314 | E13: APP예약)닭가슴살샐러드 | M13: 36 | Q13: =IFERROR(VLOOKUP(B1,은성파머스피벗발주량!A:DC,2,FALSE),0) -> 0 | T13: =IFERROR(ROUNDDOWN(Q13/M13,0),"") -> 0 | W13: =IFERROR(Q13-(T13*M13),"") -> 0 | AA13: =B13+4 -> 46318
E14: APP예약)밸런스푼꽃맛살듬뿍샐러드 | M14: 30 | Q14: =IFERROR(VLOOKUP(B1,은성파머스피벗발주량!A:DC,3,FALSE),0) -> 0 | T14: =IFERROR(ROUNDDOWN(Q14/M14,0),"") -> 0 | W14: =IFERROR(Q14-(T14*M14),"") -> 0 | AA14: =B13+4 -> 46318
E15: APP예약)밸런스푼에그듬뿍샐러드 | M15: 30 | Q15: =IFERROR(VLOOKUP(B1,은성파머스피벗발주량!A:DC,4,FALSE),0) -> 0 | T15: =IFERROR(ROUNDDOWN(Q15/M15,0),"") -> 0 | W15: =IFERROR(Q15-(T15*M15),"") -> 0 | AA15: =B13+4 -> 46318
E16: APP예약)밸런스푼훈제오리듬뿍샐러드 | M16: 30 | Q16: =IFERROR(VLOOKUP(B1,은성파머스피벗발주량!A:DC,5,FALSE),0) -> 0 | T16: =IFERROR(ROUNDDOWN(Q16/M16,0),"") -> 0 | W16: =IFERROR(Q16-(T16*M16),"") -> 0 | AA16: =B13+4 -> 46318
E17: APP예약)치킨텐더샐러드 | M17: 36 | Q17: =IFERROR(VLOOKUP(B1,은성파머스피벗발주량!A:DC,6,FALSE),0) -> 0 | T17: =IFERROR(ROUNDDOWN(Q17/M17,0),"") -> 0 | W17: =IFERROR(Q17-(T17*M17),"") -> 0 | AA17: =B13+4 -> 46318
E18: 밸런스푼)꽃맛살듬뿍샐러드 235g | M18: 30 | Q18: =IFERROR(VLOOKUP(B1,은성파머스피벗발주량!A:DC,7,FALSE),0) -> 0 | T18: =IFERROR(ROUNDDOWN(Q18/M18,0),"") -> 0 | W18: =IFERROR(Q18-(T18*M18),"") -> 0 | AA18: =B13+4 -> 46318
E19: 밸런스푼)새우듬뿍샐러드 185g | M19: 30 | Q19: =IFERROR(VLOOKUP(B1,은성파머스피벗발주량!A:DC,8,FALSE),0) -> 0 | T19: =IFERROR(ROUNDDOWN(Q19/M19,0),"") -> 0 | W19: =IFERROR(Q19-(T19*M19),"") -> 0 | AA19: =B13+4 -> 46318
E20: 밸런스푼)에그듬뿍샐러드 230g | M20: 30 | Q20: =IFERROR(VLOOKUP(B1,은성파머스피벗발주량!A:DC,9,FALSE),0) -> 0 | T20: =IFERROR(ROUNDDOWN(Q20/M20,0),"") -> 0 | W20: =IFERROR(Q20-(T20*M20),"") -> 0 | AA20: =B13+4 -> 46318
E21: 밸런스푼)훈제오리듬뿍샐러드 225g | M21: 30 | Q21: =IFERROR(VLOOKUP(B1,은성파머스피벗발주량!A:DC,10,FALSE),0) -> 0 | T21: =IFERROR(ROUNDDOWN(Q21/M21,0),"") -> 0 | W21: =IFERROR(Q21-(T21*M21),"") -> 0 | AA21: =B13+4 -> 46318
E22: 은성)닭가슴살샐러드 155g | M22: 36 | Q22: =IFERROR(VLOOKUP(B1,은성파머스피벗발주량!A:DC,11,FALSE),0) -> 0 | T22: =IFERROR(ROUNDDOWN(Q22/M22,0),"") -> 0 | W22: =IFERROR(Q22-(T22*M22),"") -> 0 | AA22: =B13+4 -> 46318
E23: 은성)치킨텐더샐러드 150g | M23: 36 | Q23: =IFERROR(VLOOKUP(B1,은성파머스피벗발주량!A:DC,12,FALSE),0) -> 0 | T23: =IFERROR(ROUNDDOWN(Q23/M23,0),"") -> 0 | W23: =IFERROR(Q23-(T23*M23),"") -> 0 | AA23: =B13+4 -> 46318
B24: 총수량 | M24: =SUM(Q13:S23) -> 0
B25: 3자물류 (더원물류) 담당자 박병선이사 010-4448-1456 | W25: 경기 광주시 오포로 614 도크
B29: 거 래 명 세 표 (공급자 보관용)
B31: 공 급 받 는 자 | C31: =C4 -> 등록번호 | Q31: 공 급 자 | R31: 등록번호 | V31: =V4 -> 308-87-03289
C33: =C6 -> 상 호 (법인명) | G33: =G6 -> 세븐일레븐 | L33: =L6 -> 수도권냉장 | R33: 상 호 (법인명) | V33: =V6 -> 주식회사 은성파머스 | AB33: 성 명 | AD33: =AD6 -> 안은엽
C35: 사업장 주 소 | G35: =G8 -> 경기도 광주시 오포로 614 | R35: 사업장 주 소 | V35: =V8 -> 경기도 여주시 세종대왕면 매류1길 45
C37: 합계금액 (VAT포함) | R37: 업 태 | V37: =V10 -> 도소매 | AB37: =AB10 -> 종 목 | AD37: 농후발효유, 그릭요거트
B39: 년 | C39: 월 | D39: 일 | E39: 품 목 | M39: 입수 | Q39: 총수량 | T39: 박스 | W39: 낱개수량 | AA39: 비고
B40: =B13 -> 46314 | E40: =E13 -> APP예약)닭가슴살샐러드 | M40: =M13 -> 36 | Q40: =Q13 -> 0 | T40: =T13 -> 0 | W40: =W13 -> 0 | AA40: =AA13 -> 46318
E41: =E14 -> APP예약)밸런스푼꽃맛살듬뿍샐러드 | M41: =M14 -> 30 | Q41: =Q14 -> 0 | T41: =T14 -> 0 | W41: =W14 -> 0 | AA41: =AA14 -> 46318
E42: =E15 -> APP예약)밸런스푼에그듬뿍샐러드 | M42: =M15 -> 30 | Q42: =Q15 -> 0 | T42: =T15 -> 0 | W42: =W15 -> 0 | AA42: =AA15 -> 46318
E43: =E16 -> APP예약)밸런스푼훈제오리듬뿍샐러드 | M43: =M16 -> 30 | Q43: =Q16 -> 0 | T43: =T16 -> 0 | W43: =W16 -> 0 | AA43: =AA16 -> 46318
E44: =E17 -> APP예약)치킨텐더샐러드 | M44: =M17 -> 36 | Q44: =Q17 -> 0 | T44: =T17 -> 0 | W44: =W17 -> 0 | AA44: =AA17 -> 46318
E45: =E18 -> 밸런스푼)꽃맛살듬뿍샐러드 235g | M45: =M18 -> 30 | Q45: =Q18 -> 0 | T45: =T18 -> 0 | W45: =W18 -> 0 | AA45: =AA18 -> 46318
E46: =E19 -> 밸런스푼)새우듬뿍샐러드 185g | M46: =M19 -> 30 | Q46: =Q19 -> 0 | T46: =T19 -> 0 | W46: =W19 -> 0 | AA46: =AA19 -> 46318
E47: =E20 -> 밸런스푼)에그듬뿍샐러드 230g | M47: =M20 -> 30 | Q47: =Q20 -> 0 | T47: =T20 -> 0 | W47: =W20 -> 0 | AA47: =AA20 -> 46318
E48: =E21 -> 밸런스푼)훈제오리듬뿍샐러드 225g | M48: =M21 -> 30 | Q48: =Q21 -> 0 | T48: =T21 -> 0 | W48: =W21 -> 0 | AA48: =AA21 -> 46318
E49: =E22 -> 은성)닭가슴살샐러드 155g | M49: =M22 -> 36 | Q49: =Q22 -> 0 | T49: =T22 -> 0 | W49: =W22 -> 0 | AA49: =AA22 -> 46318
E50: =E23 -> 은성)치킨텐더샐러드 150g | M50: =M23 -> 36 | Q50: =Q23 -> 0 | T50: =T23 -> 0 | W50: =W23 -> 0 | AA50: =AA23 -> 46318
B51: =B24 -> 총수량 | M51: =SUM(Q40:S50) -> 0
B52: =B25 -> 3자물류 (더원물류) 담당자 박병선이사 010-4448-1456 | W52: =W25 -> 경기 광주시 오포로 614 도크

Sheet 수원저온센터
B1: 수원저온센터
B2: 거 래 명 세 표 (공급받는자 보관용)
B4: 공 급 받 는 자 | C4: 등록번호 | Q4: 공 급 자 | R4: 등록번호 | V4: 308-87-03289
C6: 상 호 (법인명) | G6: 세븐일레븐 | L6: 수원저온센터 | R6: 상 호 (법인명) | V6: 주식회사 은성파머스 | AB6: 성 명 | AD6: 안은엽
C8: 사업장 주 소 | G8: 경기도 용인시 기흥구 하갈동 156-18 | R8: 사업장 주 소 | V8: 경기도 여주시 세종대왕면 매류1길 45
C10: 합계금액 (VAT포함) | R10: 업 태 | V10: 도소매 | AB10: 종 목 | AD10: 식품도소매
B12: 년 | C12: 월 | D12: 일 | E12: 품 목 | M12: 입수 | Q12: 총수량 | T12: 박스 | W12: 낱개수량 | AA12: 비고
B13: ='제주냉장센터(더원)'!B13 -> 46314 | E13: APP예약)닭가슴살샐러드 | M13: 36 | Q13: =IFERROR(VLOOKUP(B1,은성파머스피벗발주량!A:DC,2,FALSE),0) -> 0 | T13: =IFERROR(ROUNDDOWN(Q13/M13,0),"") -> 0 | W13: =IFERROR(Q13-(T13*M13),"") -> 0 | AA13: =B13+4 -> 46318
E14: APP예약)밸런스푼꽃맛살듬뿍샐러드 | M14: 30 | Q14: =IFERROR(VLOOKUP(B1,은성파머스피벗발주량!A:DC,3,FALSE),0) -> 0 | T14: =IFERROR(ROUNDDOWN(Q14/M14,0),"") -> 0 | W14: =IFERROR(Q14-(T14*M14),"") -> 0 | AA14: =B13+4 -> 46318
E15: APP예약)밸런스푼에그듬뿍샐러드 | M15: 30 | Q15: =IFERROR(VLOOKUP(B1,은성파머스피벗발주량!A:DC,4,FALSE),0) -> 0 | T15: =IFERROR(ROUNDDOWN(Q15/M15,0),"") -> 0 | W15: =IFERROR(Q15-(T15*M15),"") -> 0 | AA15: =B13+4 -> 46318
E16: APP예약)밸런스푼훈제오리듬뿍샐러드 | M16: 30 | Q16: =IFERROR(VLOOKUP(B1,은성파머스피벗발주량!A:DC,5,FALSE),0) -> 1 | T16: =IFERROR(ROUNDDOWN(Q16/M16,0),"") -> 0 | W16: =IFERROR(Q16-(T16*M16),"") -> 1 | AA16: =B13+4 -> 46318
E17: APP예약)치킨텐더샐러드 | M17: 36 | Q17: =IFERROR(VLOOKUP(B1,은성파머스피벗발주량!A:DC,6,FALSE),0) -> 0 | T17: =IFERROR(ROUNDDOWN(Q17/M17,0),"") -> 0 | W17: =IFERROR(Q17-(T17*M17),"") -> 0 | AA17: =B13+4 -> 46318
E18: 밸런스푼)꽃맛살듬뿍샐러드 235g | M18: 30 | Q18: =IFERROR(VLOOKUP(B1,은성파머스피벗발주량!A:DC,7,FALSE),0) -> 26 | T18: =IFERROR(ROUNDDOWN(Q18/M18,0),"") -> 0 | W18: =IFERROR(Q18-(T18*M18),"") -> 26 | AA18: =B13+4 -> 46318
E19: 밸런스푼)새우듬뿍샐러드 185g | M19: 30 | Q19: =IFERROR(VLOOKUP(B1,은성파머스피벗발주량!A:DC,8,FALSE),0) -> 45 | T19: =IFERROR(ROUNDDOWN(Q19/M19,0),"") -> 1 | W19: =IFERROR(Q19-(T19*M19),"") -> 15 | AA19: =B13+4 -> 46318
E20: 밸런스푼)에그듬뿍샐러드 230g | M20: 30 | Q20: =IFERROR(VLOOKUP(B1,은성파머스피벗발주량!A:DC,9,FALSE),0) -> 55 | T20: =IFERROR(ROUNDDOWN(Q20/M20,0),"") -> 1 | W20: =IFERROR(Q20-(T20*M20),"") -> 25 | AA20: =B13+4 -> 46318
E21: 밸런스푼)훈제오리듬뿍샐러드 225g | M21: 30 | Q21: =IFERROR(VLOOKUP(B1,은성파머스피벗발주량!A:DC,10,FALSE),0) -> 40 | T21: =IFERROR(ROUNDDOWN(Q21/M21,0),"") -> 1 | W21: =IFERROR(Q21-(T21*M21),"") -> 10 | AA21: =B13+4 -> 46318
E22: 은성)닭가슴살샐러드 155g | M22: 36 | Q22: =IFERROR(VLOOKUP(B1,은성파머스피벗발주량!A:DC,11,FALSE),0) -> 24 | T22: =IFERROR(ROUNDDOWN(Q22/M22,0),"") -> 0 | W22: =IFERROR(Q22-(T22*M22),"") -> 24 | AA22: =B13+4 -> 46318
E23: 은성)치킨텐더샐러드 150g | M23: 36 | Q23: =IFERROR(VLOOKUP(B1,은성파머스피벗발주량!A:DC,12,FALSE),0) -> 25 | T23: =IFERROR(ROUNDDOWN(Q23/M23,0),"") -> 0 | W23: =IFERROR(Q23-(T23*M23),"") -> 25 | AA23: =B13+4 -> 46318
B24: 총수량 | M24: =SUM(Q13:S23) -> 216
B25: 3자물류 (더원물류) 담당자 박병선이사 010-4448-1456 | W25: 경기도 용인시 기흥구 하갈동 156-18 031-8005-6200
B29: 거 래 명 세 표 (공급자 보관용)
B31: 공 급 받 는 자 | C31: =C4 -> 등록번호 | Q31: 공 급 자 | R31: 등록번호 | V31: =V4 -> 308-87-03289
C33: =C6 -> 상 호 (법인명) | G33: =G6 -> 세븐일레븐 | L33: =L6 -> 수원저온센터 | R33: 상 호 (법인명) | V33: =V6 -> 주식회사 은성파머스 | AB33: 성 명 | AD33: =AD6 -> 안은엽
C35: 사업장 주 소 | R35: 사업장 주 소 | V35: =V8 -> 경기도 여주시 세종대왕면 매류1길 45
C37: 합계금액 (VAT포함) | R37: 업 태 | V37: =V10 -> 도소매 | AB37: =AB10 -> 종 목 | AD37: 농후발효유, 그릭요거트
B39: 년 | C39: 월 | D39: 일 | E39: 품 목 | M39: 입수 | Q39: 총수량 | T39: 박스 | W39: 낱개수량 | AA39: 비고
B40: =B13 -> 46314 | E40: =E13 -> APP예약)닭가슴살샐러드 | M40: =M13 -> 36 | Q40: =Q13 -> 0 | T40: =T13 -> 0 | W40: =W13 -> 0 | AA40: =AA13 -> 46318
E41: =E14 -> APP예약)밸런스푼꽃맛살듬뿍샐러드 | M41: =M14 -> 30 | Q41: =Q14 -> 0 | T41: =T14 -> 0 | W41: =W14 -> 0 | AA41: =AA14 -> 46318
E42: =E15 -> APP예약)밸런스푼에그듬뿍샐러드 | M42: =M15 -> 30 | Q42: =Q15 -> 0 | T42: =T15 -> 0 | W42: =W15 -> 0 | AA42: =AA15 -> 46318
E43: =E16 -> APP예약)밸런스푼훈제오리듬뿍샐러드 | M43: =M16 -> 30 | Q43: =Q16 -> 1 | T43: =T16 -> 0 | W43: =W16 -> 1 | AA43: =AA16 -> 46318
E44: =E17 -> APP예약)치킨텐더샐러드 | M44: =M17 -> 36 | Q44: =Q17 -> 0 | T44: =T17 -> 0 | W44: =W17 -> 0 | AA44: =AA17 -> 46318
E45: =E18 -> 밸런스푼)꽃맛살듬뿍샐러드 235g | M45: =M18 -> 30 | Q45: =Q18 -> 26 | T45: =T18 -> 0 | W45: =W18 -> 26 | AA45: =AA18 -> 46318
E46: =E19 -> 밸런스푼)새우듬뿍샐러드 185g | M46: =M19 -> 30 | Q46: =Q19 -> 45 | T46: =T19 -> 1 | W46: =W19 -> 15 | AA46: =AA19 -> 46318
E47: =E20 -> 밸런스푼)에그듬뿍샐러드 230g | M47: =M20 -> 30 | Q47: =Q20 -> 55 | T47: =T20 -> 1 | W47: =W20 -> 25 | AA47: =AA20 -> 46318
E48: =E21 -> 밸런스푼)훈제오리듬뿍샐러드 225g | M48: =M21 -> 30 | Q48: =Q21 -> 40 | T48: =T21 -> 1 | W48: =W21 -> 10 | AA48: =AA21 -> 46318
E49: =E22 -> 은성)닭가슴살샐러드 155g | M49: =M22 -> 36 | Q49: =Q22 -> 24 | T49: =T22 -> 0 | W49: =W22 -> 24 | AA49: =AA22 -> 46318
E50: =E23 -> 은성)치킨텐더샐러드 150g | M50: =M23 -> 36 | Q50: =Q23 -> 25 | T50: =T23 -> 0 | W50: =W23 -> 25 | AA50: =AA23 -> 46318
B51: =B24 -> 총수량 | M51: =SUM(Q40:S50) -> 216
B52: =B25 -> 3자물류 (더원물류) 담당자 박병선이사 010-4448-1456 | W52: =W25 -> 경기도 용인시 기흥구 하갈동 156-18 031-8005-6200

Sheet 안성저온센터
B1: 안성저온센터
B2: 거 래 명 세 표 (공급받는자 보관용)
B4: 공 급 받 는 자 | C4: 등록번호 | Q4: 공 급 자 | R4: 등록번호 | V4: 308-87-03289
C6: 상 호 (법인명) | G6: 세븐일레븐 | L6: 안성저온센터 | R6: 상 호 (법인명) | V6: 주식회사 은성파머스 | AB6: 성 명 | AD6: 안은엽
C8: 사업장 주 소 | G8: 경기도 안성시 원곡면 청원로 1752-122 | R8: 사업장 주 소 | V8: 경기도 여주시 세종대왕면 매류1길 45
C10: 합계금액 (VAT포함) | R10: 업 태 | V10: 도소매 | AB10: 종 목 | AD10: 식품도소매
B12: 년 | C12: 월 | D12: 일 | E12: 품 목 | M12: 입수 | Q12: 총수량 | T12: 박스 | W12: 낱개수량 | AA12: 비고
